Workbook

Sheet ScenMap
A1: KS
A4: ~ScenMap | G4: ~ScenG
A5: Oname | B5: Name | C5: Desc | D5: Ldesc | G5: Scen
A6: =$A$1&"~"&TEXT(O6,"0000") -> KS~0000 | B6: Base | G6: =B6 -> Base
A7: =$A$1&"~"&TEXT(O7,"0000") -> KS~0000 | B7: ="CO2price-"&ROUND(L7/10,0)*10 -> CO2price-0 | G7: =B7 -> CO2price-0
A8: =$A$1&"~"&TEXT(O8,"0000") -> KS~0000 | B8: ="CO2price-"&ROUND(L8/10,0)*10 -> CO2price-0 | G8: =B8 -> CO2price-0
A9: =$A$1&"~"&TEXT(O9,"0000") -> KS~0000 | B9: ="CO2price-"&ROUND(L9/10,0)*10 -> CO2price-0 | G9: =B9 -> CO2price-0
A10: =$A$1&"~"&TEXT(O10,"0000") -> KS~0000 | B10: ="CO2price-"&ROUND(L10/10,0)*10 -> CO2price-0 | G10: =B10 -> CO2price-0
A11: =$A$1&"~"&TEXT(O11,"0000") -> KS~0000 | B11: ="CO2price-"&ROUND(L11/10,0)*10 -> CO2price-0 | G11: =B11 -> CO2price-0

Sheet TS_Defs
A1: ~TS_Defs
A2: Attribute | B2: WAttribute | C2: Vintage | D2: PSET_Set | E2: PSET_PN | F2: PSET_PD | G2: PSET_CI | H2: PSET_CO | I2: CSET_Set | J2: CSET_CN | K2: CSET_CD | L2: Unit | M2: TS | N2: UC_N | O2: Name | P2: Desc | Q2: Ldesc | R2: show_me | S2: ignore | T2: t_neg_andor | V2: TIAM | W2: World | AA2: Alt Description
A3: VAR_FIN | D3: =PSET_Map!H28 -> DMD_AGR,DMD_COM,DMD_RES,DMD_AUTOP,DMD_IND,DMD_Non-En,DMD_TRA-NR,DMD_TRA-R | I3: NRG | L3: PJ | O3: FinEnergy | P3: =O3 -> FinEnergy | Q3: Final energy consumption by sector and fuel
A4: VAR_FIN | I4: =$I$3 -> NRG | J4: SUP* | L4: PJ | O4: FinEnergy | P4: =O4 -> FinEnergy | Q4: Final energy consumption by sector and fuel
A5: \I: | E5: SUP_TBLAST*,SUP_TCOK* | I5: =$I$3 -> NRG | J5: -SUP* | L5: PJ | O5: FinEnergy | P5: =O5 -> FinEnergy | Q5: Final energy consumption by sector and fuel
A6: \I: | E6: SUP_TBLAST*,SUP_TCOK* | I6: =$I$3 -> NRG | J6: -SUP* | L6: PJneg | O6: FinEnergy | P6: =O6 -> FinEnergy | Q6: Final energy consumption by sector and fuel
A7: VAR_FOUT | D7: ELE,CHP,STG,IRE | E7: -TU_sup-dem*,-ElcAgg* | J7: ELC,INDELC,ELC_???-* | L7: PJe | O7: Elec_Prod | P7: =O7 -> Elec_Prod | Q7: Electricity production - including output from storage and trade
A8: VAR_FIN | D8: IRE,STG | E8: -TU_sup-dem* | J8: ELC | L8: PJeNeg | O8: Elec_Prod | Q8: Electricity production - including output from storage and trade
A9: VAR_FOUT | D9: ELE,PRE | J9: ELCCurt | L9: PJe | O9: Elec-int_Prod | P9: =O9 -> Elec-int_Prod | Q9: Intermittent electricity production - this is either curtailed or used for Hydrogen production
A10: VAR_ACT | D10: ELE,CHP,IRE | H10: ELC,INDELC,ELC_???-*,-TRDELC | L10: PJe | O10: Elec_act | P10: =O10 -> Elec_act | Q10: =P10 -> Elec_act
A11: VAR_FOUT | D11: -IRE,-STG | J11: HH2 | L11: PJ | O11: H2_Prod | P11: =O11 -> H2_Prod | Q11: Hydrogen production | R11: p
A12: VAR_CAP | D12: ELE,CHP,PRE,STG | E12: -ElcAgg* | H12: ELC,INDELC,ELC_???-*,-TRDELC | L12: GW | O12: Capacity_Elec | P12: =O12 -> Capacity_Elec | Q12: =P12 -> Capacity_Elec | T12: OR
A13: VAR_CAP | D13: IRE | E13: T?_ELC* | L13: GW | O13: Capacity_Elec | P13: =O13 -> Capacity_Elec | Q13: =P13 -> Capacity_Elec
A14: VAR_CAP | D14: -IRE | H14: HH2 | L14: <pc> | O14: Capacity_H2 | P14: =O14 -> Capacity_H2 | R14: p
A15: VAR_NCAP | D15: -IRE | L15: <pc> | O15: NewCap | P15: =O15 -> NewCap
A16: VAR_NCAP | D16: IRE | E16: T?_ELC* | L16: GW | O16: NewCap | P16: =O16 -> NewCap
A17: Cost_INV | D17: ELE,CHP,DMD,PRE,IRE | E17: -FT[_]*-ElcAgg* | L17: m$ | O17: CostINV | P17: =O17 -> CostINV | Q17: =P17 -> CostINV
A18: Cost_Act | D18: ELE,CHP,DMD,PRE | E18: -FT[_]*-ElcAgg* | L18: m$ | O18: CostVAR | P18: =O18 -> CostVAR | Q18: =P18 -> CostVAR
A19: Cost_Fom | D19: ELE,CHP,DMD,PRE | E19: -FT[_]*-ElcAgg* | L19: m$ | O19: CostFIX | P19: =O19 -> CostFIX | Q19: =P19 -> CostFIX
A20: Val_Flo | D20: ELE,CHP | E20: -FT[_]*-ElcAgg* | I20: NRG | J20: -ELC*,-HET,-INDELC,-INDHET | L20: m$ | O20: CostFue | P20: =O20 -> CostFue | Q20: =P20 -> CostFue
A21: Val_Flo | H21: HH2 | I21: NRG | J21: -HH2 | L21: m$ | O21: CostFue | P21: =O21 -> CostFue | Q21: =P21 -> CostFue
A22: Val_Flo | D22: DMD | E22: C*,R*,T* | I22: NRG | L22: m$ | O22: CostFue | P22: =O22 -> CostFue | Q22: =P22 -> CostFue
A23: Val_Flo | D23: DMD_IND,DMD_Non-En | I23: NRG | J23: -*[_]* | L23: m$ | O23: CostFue | P23: =O23 -> CostFue | Q23: =P23 -> CostFue
A24: VAR_FIN | D24: ELE,CHP,HPL,-STG | H24: ELC,HET,ELC_???-* | I24: NRG | J24: -*WHT,-ELCC,-ELC | L24: PJ | O24: Fuel_cons_power | P24: =O24 -> Fuel_cons_power | Q24: Energy consumed for producing electricity and heat | T24: OR
A25: VAR_FIN | D25: -IRE,-STG | H25: HH2 | I25: NRG | L25: PJ | O25: Fuel_cons_H2 | P25: =O25 -> Fuel_cons_H2 | Q25: Energy consumed for producing Hydrogen
A26: VAR_FIN | H26: CO2_DAC | I26: NRG | L26: PJ | O26: Fuel_cons_DAC | Q26: Energy consumed in Direct Air Capture of CO2
A27: VAR_CAP | D27: DMD | H27: Trd[_]* | L27: <pc> | O27: Capacity_roadtra | Q27: Road transport vehicles population
A28: VAR_FOUT | D28: DMD | I28: DEM | J28: -I??,-ONO | L28: <c> | O28: DMD_out | P28: =O28 -> DMD_out | Q28: End-use services produced - these are the exogenous demands
A29: VAR_FIN | D29: DMD | H29: -I*,-ONO | I29: NRG | L29: PJ | O29: DMD_in | P29: =O29 -> DMD_in | Q29: =P29 -> DMD_in
A30: VAR_POUT | E30: *,-FT[_]*,-TU_sup-dem* | J30: -TRDELC | L30: PJ2gw | O30: Power | P30: =O30 -> Power | Q30: =P30 -> Power | R30: t,c | T30: OR
A31: VAR_FOUT | D31: IRE | E31: MIN*,WB_sup* | I31: NRG | L31: PJ | O31: Pri_Prod | P31: =O31 -> Pri_Prod | Q31: =P31 -> Pri_Prod
A32: VAR_FOUT | E32: SUP_GasSupply | J32: OILNGL | L32: PJ | O32: Pri_Prod | P32: =O32 -> Pri_Prod | Q32: =P32 -> Pri_Prod
A33: VAR_FOUT | I33: ENV | J33: ???CO2??,-*CO2Nb | L33: kt CO2 | O33: CO2_emissions | P33: =O33 -> CO2_emissions | Q33: =P33 -> CO2_emissions | R33: c
A34: VAR_FOUT | J34: CO2Captured*,CO2_DAC | L34: kt CO2neg | O34: CO2_captured | P34: =O34 -> CO2_captured | Q34: =P34 -> CO2_captured | R34: p
A35: VAR_FIN | J35: TOTCO2 | L35: kt CO2neg | O35: CO2_captured | P35: =O35 -> CO2_captured | Q35: =P35 -> CO2_captured
A36: VAR_FIN | J36: CO2ForStorage | L36: kt CO2 | O36: CO2_Stored | P36: =O36 -> CO2_Stored | Q36: =P36 -> CO2_Stored | R36: p
A37: VAR_FOUT | D37: Trd_endo | I37: NRG | L37: PJ | O37: Pri_Import | P37: =O37 -> Pri_Import | Q37: =P37 -> Pri_Import
A38: VAR_FOUT | E38: LNG[_]* | J38: GASNGA | L38: PJ | O38: Pri_Import
A39: VAR_FIN | D39: Trd_endo | I39: NRG | L39: Pjneg | O39: Pri_Export | P39: =O39 -> Pri_Export | Q39: =P39 -> Pri_Export
A40: EQ_COMBALM | B40: VAR_COMPRD | I40: NRG | J40: OILDST,OILGSL,BIODST,BIOGSL,BIOBSL,COAHCO | L40: $/GJ | O40: Prices | P40: =O40 -> Prices | Q40: =P40 -> Prices | R40: c
...

Sheet TS_Defs Sankey
A1: ~TS_Defs: Snk_attr=SANKEY_all_sectors
A2: Attribute | B2: PSET_Set | C2: PSET_PN | D2: PSET_PD | E2: PSET_CI | F2: PSET_CO | G2: CSET_Set | H2: CSET_CN | I2: CSET_CD | J2: Unit | K2: TS | L2: UC_N | M2: Name | N2: Desc | O2: Ldesc | P2: show_me | Q2: ignore | R2: T_neg_andor
A3: VAR_FIN | B3: ELE,CHP | G3: =CSET_Map!H6 -> ALLSOL,ALLWIN,ALLHYD,ALLGEO | J3: PJ | M3: <cset>_src_Renewable
A4: VAR_FOUT | C4: MinBio* | G4: ALLBIO | J4: PJ | M4: <cset>_src_Renewable
A5: *
A6: VAR_FIN | B6: =PSET_Map!$H$28&","&PSET_Map!$H$56&","&PSET_Map!$H$30 -> DMD_AGR,DMD_COM,DMD_RES,DMD_AUTOP,DMD_IND,DMD_Non-En,DMD_TRA-NR,DMD_TRA-R,E_Thermal,E_Thermal-S,E_USHP,E_Renewable,FossilProc,IndProc,BioRef,H2_Exp_LH2,H2_Exp_Amm,H2_Exp_LOHC,H2_Imp_LH2,H2_Imp_Amm,H2_Imp_LOHC,H2_Thermal,H2_Bio,H2_Elec,s_DAC | C6: -EA_HH2* | G6: =CSET_Map!$H$19 -> ALLSOL,ALLWIN,ALLHYD,ALLGEO,ALLBIO,ALLNUC,ALLELC,ALLELCi,ALLH2,ALLCOAL,ALLCOALInd,ALLBIOFliq,ALLBIOFgas,ALLHEAT,ALLOILCrd,ALLOILPrd,ALLGAS | H6: -SUP*,-COAOVC,-COATAR,-*BFG,-ELCHH2 | J6: Pjneg | M6: <cset>_snk_<pset> | R6: OR
A7: VAR_FOUT | B7: =PSET_Map!$H$56&","&PSET_Map!$H$58 -> E_Thermal,E_Thermal-S,E_USHP,E_Renewable,FossilProc,IndProc,BioRef,H2_Exp_LH2,H2_Exp_Amm,H2_Exp_LOHC,H2_Imp_LH2,H2_Imp_Amm,H2_Imp_LOHC,H2_Thermal,H2_Bio,H2_Elec,s_Mining | C7: -MinRen*,-MinBio*,-MinNuc* | G7: =$G$6 -> ALLSOL,ALLWIN,ALLHYD,ALLGEO,ALLBIO,ALLNUC,ALLELC,ALLELCi,ALLH2,ALLCOAL,ALLCOALInd,ALLBIOFliq,ALLBIOFgas,ALLHEAT,ALLOILCrd,ALLOILPrd,ALLGAS | J7: PJ | M7: <cset>_src_<pset>
A8: =A6 -> VAR_FIN | B8: =B6 -> DMD_AGR,DMD_COM,DMD_RES,DMD_AUTOP,DMD_IND,DMD_Non-En,DMD_TRA-NR,DMD_TRA-R,E_Thermal,E_Thermal-S,E_USHP,E_Renewable,FossilProc,IndProc,BioRef,H2_Exp_LH2,H2_Exp_Amm,H2_Exp_LOHC,H2_Imp_LH2,H2_Imp_Amm,H2_Imp_LOHC,H2_Thermal,H2_Bio,H2_Elec,s_DAC | C8: =C6 -> -EA_HH2* | G8: ALLGAS | H8: =H6 -> -SUP*,-COAOVC,-COATAR,-*BFG,-ELCHH2 | J8: =J6 -> Pjneg | M8: =M6 -> <cset>_snk_<pset>
A9: =A7 -> VAR_FOUT | B9: =B7 -> E_Thermal,E_Thermal-S,E_USHP,E_Renewable,FossilProc,IndProc,BioRef,H2_Exp_LH2,H2_Exp_Amm,H2_Exp_LOHC,H2_Imp_LH2,H2_Imp_Amm,H2_Imp_LOHC,H2_Thermal,H2_Bio,H2_Elec,s_Mining | C9: =C7 -> -MinRen*,-MinBio*,-MinNuc* | G9: ALLGAS | J9: =J7 -> PJ | M9: =M7 -> <cset>_src_<pset>
A10: *
A11: VAR_FIN | B11: Trd_endo | G11: =CSET_Map!$H$19 -> ALLSOL,ALLWIN,ALLHYD,ALLGEO,ALLBIO,ALLNUC,ALLELC,ALLELCi,ALLH2,ALLCOAL,ALLCOALInd,ALLBIOFliq,ALLBIOFgas,ALLHEAT,ALLOILCrd,ALLOILPrd,ALLGAS | J11: Pjneg | M11: <cset>_snk_Export
A12: VAR_FOUT | B12: Trd_endo | G12: =CSET_Map!$H$19 -> ALLSOL,ALLWIN,ALLHYD,ALLGEO,ALLBIO,ALLNUC,ALLELC,ALLELCi,ALLH2,ALLCOAL,ALLCOALInd,ALLBIOFliq,ALLBIOFgas,ALLHEAT,ALLOILCrd,ALLOILPrd,ALLGAS | J12: PJ | M12: <cset>_src_Import
A13: *
A14: VAR_FIN | C14: LNG[_]* | H14: GASNGA | J14: Pjneg | M14: Gas_snk_Exp-LNG
A15: VAR_FOUT | C15: =C14 -> LNG[_]* | H15: GASNGA | J15: PJ | M15: Gas_src_Imp-LNG
A16: *
A17: VAR_FIN | G17: =CSET_Map!$H$18 -> 0 | H17: SUP* | J17: Pjneg | M17: <cset>_snk_Energy Sect
A18: VAR_FIN | G18: ALLGAS | H18: SUP* | J18: Pjneg | M18: <cset>_snk_Energy Sect
A19: *
A20: VAR_FOUT | H20: ELCHH2 | J20: Pjneg | M20: Hydrogen_snk_H2-to-ThermPow
A21: VAR_FOUT | H21: ELCHH2 | J21: Pjneg | M21: _H2-for-ThermPow_snk_Thermal Power
A25: ~TS_Defs: Snk_attr=SANKEY_gas_trade
A26: Attribute | B26: PSET_Set | C26: PSET_PN | D26: PSET_PD | E26: PSET_CI | F26: PSET_CO | G26: CSET_Set | H26: CSET_CN | I26: CSET_CD | J26: Unit | K26: TS | L26: UC_N | M26: Name | N26: Desc | O26: Ldesc | P26: show_me | Q26: ignore | R26: T_neg_andor | S26: downscale_option
A27: VAR_FIN | B27: IRE | C27: *gaspip* | H27: GASNGA | J27: Pjneg | M27: Nat Gas-<region>_Snk_<gen_pname> | O27: Pipeline exports | P27: c | S27: -1
A28: VAR_FOUT | B28: IRE | C28: *gaspip* | H28: GASNGA | J28: PJ | M28: Nat Gas-<region>_Src_<gen_pname> | O28: Pipeline imports | P28: c | S28: -1
A29: VAR_FIN | B29: PRE | F29: GASLNG | H29: GASNGA | J29: Pjneg | M29: Nat Gas-<region>_Snk_<gen_pname> | O29: LNG exports | P29: c | S29: -1
A30: VAR_FOUT | B30: PRE | E30: GASLNG | H30: GASNGA | J30: PJ | M30: Nat Gas-<region>_Src_<gen_pname> | O30: LNG imports | P30: c | S30: -1
A31: *
A32: VAR_FIN | B32: PRE | H32: GASLNG | J32: Pjneg | M32: L N G Imp_Snk_<gen_pname> | O32: LNG exports | P32: c | S32: -1
A33: VAR_FOUT | B33: PRE | H33: GASLNG | J33: PJ | M33: L N G Exp_Src_<gen_pname> | O33: LNG imports | P33: c | S33: -1
A37: ~TS_Defs: Snk_attr=SANKEY_elec_trade
A38: Attribute | B38: PSET_Set | C38: PSET_PN | D38: PSET_PD | E38: PSET_CI | F38: PSET_CO | G38: CSET_Set | H38: CSET_CN | I38: CSET_CD | J38: Unit | K38: TS | L38: UC_N | M38: Name | N38: Desc | O38: Ldesc | P38: show_me | Q38: ignore | R38: T_neg_andor | S38: downscale_option
A39: VAR_FIN | B39: IRE | C39: -*sup-dem* | H39: ELC | J39: Pjneg | M39: Electricity-<region>_Snk_<gen_pname> | S39: -1
A40: VAR_FOUT | B40: IRE | C40: -*sup-dem* | H40: ELC | J40: PJ | M40: Electricity-<region>_Src_<gen_pname> | S40: -1
A44: ~TS_Defs: snk_attr=SANKEY_Residential
A45: Attribute | B45: PSET_Set | C45: PSET_PN | D45: PSET_PD | E45: PSET_CI | F45: PSET_CO | G45: CSET_Set | H45: CSET_CN | I45: CSET_CD | J45: Unit | K45: TS | L45: UC_N | M45: Name | N45: Desc | O45: Ldesc | P45: show_me | Q45: ignore | R45: T_neg_andor
A46: * | B46: PRE | F46: RES* | G46: NRG | J46: PJ | M46: <gen_cname>_snk_<gen_pname> | O46: secondary fuels to sector
A47: * | B47: PRE | F47: RES* | G47: NRG | J47: PJ | M47: <gen_cname>_src_<gen_pname> | O47: production of sector fuels
A48: *
A49: VAR_FIN | B49: =PSET_Map!$H$96 -> DMD_AGR,DMD_CCK,DMD_CHW,DMD_CLA,DMD_CAP,DMD_CSC,DMD_CSH,DMD_ICH,DMD_ICH-fStock,IndSerT_STM,IndSerT_PRH,IndSerT_PRC,IndSerT_MDR,IndSerT_ECP,IndSerT_OTP,IndSerT_SPC,IndSerT_LIG,IndSerT_OTH,DMD_ONO,DMD_RAP,DMD_RCK,DMD_RHW,DMD_RLI,DMD_RSC,DMD_RSH,DMD_TAD,DMD_TAI,DMD_Trd_2w,DMD_Trd_3w,DMD_Trd_Bus,DMD_Trd_Car,DMD_Trd_Hdt,DMD_Trd_Lcv,DMD_TTF,DMD_TTP,DMD_TWD,DMD_TWI | E49: RES* | G49: NRG | J49: PJ | M49: <gen_cname>_snk_<pset> | O49: consumption in devices
...

Sheet Steel
A1: ~TS_Defs: Snk_attr=SANKEY_steel
A2: Attribute | B2: PSET_Set | C2: CSET_Set | D2: Unit | E2: Name | F2: Desc | G2: Ldesc | H2: show_me | I2: ignore | J2: T_neg_andor
A3: VAR_FIN | B3: =E12 -> BOF,EAF,BF,Gas-DRI,Coal-DRI,Domestic,t_BAT_BF-BOF,t_BAT_BF-BOF_ccs,t_BAT_BF-BOF_H2-PCI_ccs,t_DRI-EAF,t_DRI-EAF_ccs,t_H2-DRI-EAF,t_Smelt_Red-BOF,t_Smelt_Red-BOF_ccs,t_EAF,t_DRI-Melt-BOF,t_DRI-Melt-BOF_ccs,t_H2-DRI-Melt-BOF,t_Gas-DRI,t_Gas-DRI_ccs,t_H2-DRI,t_Melt-BOF | C3: =E38 -> hotmetal,spongeiron,ironore,scrap,crudesteel | D3: mtneg | E3: <cset>_snk_<pset> | I3: p
A4: VAR_FOUT | B4: =B3 -> BOF,EAF,BF,Gas-DRI,Coal-DRI,Domestic,t_BAT_BF-BOF,t_BAT_BF-BOF_ccs,t_BAT_BF-BOF_H2-PCI_ccs,t_DRI-EAF,t_DRI-EAF_ccs,t_H2-DRI-EAF,t_Smelt_Red-BOF,t_Smelt_Red-BOF_ccs,t_EAF,t_DRI-Melt-BOF,t_DRI-Melt-BOF_ccs,t_H2-DRI-Melt-BOF,t_Gas-DRI,t_Gas-DRI_ccs,t_H2-DRI,t_Melt-BOF | C4: hotmetal,spongeiron,ironore,scrap,crudesteel | D4: mt | E4: <cset>_src_<pset> | I4: p
A5: VAR_FIN | B5: Trade_endo | C5: hotmetal,spongeiron,ironore,scrap,crudesteel | D5: mtneg | E5: <cset>_snk_Export | I5: p
A6: VAR_FOUT | B6: Trade_endo | C6: hotmetal,spongeiron,ironore,scrap,crudesteel | D6: mt | E6: <cset>_src_Import | I6: p
A10: ~Pset_Map
A11: Pset | B11: Desc | C11: Ldesc
A12: BOF | B12: BOF | E12: =_xlfn.TEXTJOIN(",",TRUE,A12:A33) -> BOF,EAF,BF,Gas-DRI,Coal-DRI,Domestic,t_BAT_BF-BOF,t_BAT_BF-BOF_ccs,t_BAT_BF-BOF_H2-PCI_ccs,t_DRI-EAF,t_DRI-EAF_ccs,t_H2-DRI-EAF,t_Smelt_Red-BOF,t_Smelt_Red-BOF_ccs,t_EAF,t_DRI-Melt-BOF,t_DRI-Melt-BOF_ccs,t_H2-DRI-Melt-BOF,t_Gas-DRI,t_Gas-DRI_ccs,t_H2-DRI,t_Melt-BOF
A13: EAF | B13: EAF
A14: BF | B14: BF
A15: Gas-DRI | B15: Gas-DRI | L15: ~process_map
A16: Coal-DRI | B16: Coal-DRI | L16: dimension | M16: name | N16: description | O16: pset_set | P16: pset_ci | Q16: pset_co | R16: pset_pd
A17: Domestic | B17: Domestic | L17: Tech | N17: BOF | O17: BOF | Q17: mis_*
A18: t_BAT_BF-BOF | B18: BAT_BF-BOF | L18: Tech | N18: EAF | O18: EAF | Q18: mis_*
A19: t_BAT_BF-BOF_ccs | B19: BAT_BF-BOF_ccs | L19: Tech | N19: BF | O19: BF | Q19: mis_*
A20: t_BAT_BF-BOF_H2-PCI_ccs | B20: BAT_BF-BOF_H2-PCI_ccs | L20: Tech | N20: Gas-DRI | O20: Gas-DRI | Q20: mis_*
A21: t_DRI-EAF | B21: DRI-EAF | L21: Tech | N21: Coal-DRI | O21: Coal-DRI | Q21: mis_*
A22: t_DRI-EAF_ccs | B22: DRI-EAF_ccs | L22: Tech | N22: BAT_BF-BOF | O22: t_BAT_BF-BOF | Q22: mis_*
A23: t_H2-DRI-EAF | B23: H2-DRI-EAF | L23: Tech | N23: BAT_BF-BOF_ccs | O23: t_BAT_BF-BOF_ccs | Q23: mis_*
A24: t_Smelt_Red-BOF | B24: Smelt_Red-BOF | L24: Tech | N24: DRI-EAF | O24: t_DRI-EAF | Q24: mis_*
A25: t_Smelt_Red-BOF_ccs | B25: Smelt_Red-BOF_ccs | L25: Tech | N25: DRI-EAF_ccs | O25: t_DRI-EAF_ccs | Q25: mis_*
A26: t_EAF | B26: EAF | L26: Tech | N26: H2-DRI-EAF | O26: t_H2-DRI-EAF | Q26: mis_*
A27: t_DRI-Melt-BOF | B27: DRI-Melt-BOF | L27: Tech | N27: Smelt_Red-BOF | O27: t_Smelt_Red-BOF | Q27: mis_*
A28: t_DRI-Melt-BOF_ccs | B28: DRI-Melt-BOF_ccs | L28: Tech | N28: Smelt_Red-BOF_ccs | O28: t_Smelt_Red-BOF_ccs | Q28: mis_*
... A33: t_Melt-BOF | B33: Melt-BOF | L33: Tech | N33: Gas-DRI | O33: t_Gas-DRI | Q33: mis_*
L34: Tech | N34: Gas-DRI_ccs | O34: t_Gas-DRI_ccs | Q34: mis_*
L35: Tech | N35: H2-DRI | O35: t_H2-DRI | Q35: mis_*
A36: ~CSet_Map | L36: Tech | N36: Melt-BOF | O36: t_Melt-BOF | Q36: mis_*
A37: CSet | B37: Desc | C37: Ldesc | L37: Tech | N37: Trade | O37: Trade | Q37: mis_*
A38: hotmetal | B38: Hot Metal | E38: =_xlfn.TEXTJOIN(",",TRUE,A38:A42) -> hotmetal,spongeiron,ironore,scrap,crudesteel | L38: Tech | N38: Domestic | O38: Domestic | Q38: mis_*
A39: spongeiron | B39: Sponge Iron | L39: Tech | N39: BAT_BF-BOF_H2-PCI_ccs | O39: t_BAT_BF-BOF_H2-PCI_ccs | Q39: mis_*
A40: ironore | B40: Iron Ore | L40: Existing/New | M40: n[_]* | N40: New | Q40: mis_*
A41: scrap | B41: Scrap | L41: Existing/New | M41: *-rf | N41: Retrofit | Q41: mis_*
A42: crudesteel | B42: Crude Steel | L42: Existing/New | M42: *rf*-rf | N42: Retrofit of rft | Q42: mis_*
L43: Existing/New | M43: *[_]f[_]* | N43: Known Build | Q43: mis_*

Sheet TS_Defs repUCs
A1: ~TS_Defs
A2: IgnoreForRegAgg | B2: ProcOrd | C2: Attribute | D2: WAttribute | E2: Vintage | F2: PSET_Set | G2: PSET_PN | H2: PSET_PD | I2: PSET_CI | J2: PSET_CO | K2: CSET_Set | L2: CSET_CN | M2: CSET_CD | N2: Unit | O2: TS | P2: UC_N | Q2: Name | R2: Desc | S2: Ldesc | T2: show_me | U2: ignore
C3: User_con | N3: bvkm | P3: rep_tra_road_pass | Q3: =P3 -> rep_tra_road_pass | R3: =Q3 -> rep_tra_road_pass | S3: =R3 -> rep_tra_road_pass
C4: User_con | N4: bvkm | P4: rep_tra_road_frt | Q4: =P4 -> rep_tra_road_frt | R4: =Q4 -> rep_tra_road_frt | S4: =R4 -> rep_tra_road_frt
C5: User_con | N5: kt | P5: rep_totco2 | Q5: =P5 -> rep_totco2 | R5: =Q5 -> rep_totco2 | S5: =R5 -> rep_totco2
C6: User_con | N6: b$ | P6: rep_GDP | Q6: =P6 -> rep_GDP | R6: =Q6 -> rep_GDP | S6: =R6 -> rep_GDP
C7: User_con | N7: b$ | P7: rep_GDPAGR | Q7: =P7 -> rep_GDPAGR | R7: =Q7 -> rep_GDPAGR | S7: =R7 -> rep_GDPAGR
C8: User_con | N8: b$ | P8: rep_GDPIND | Q8: =P8 -> rep_GDPIND | R8: =Q8 -> rep_GDPIND | S8: =R8 -> rep_GDPIND
C9: User_con | N9: b$ | P9: rep_GDPSER | Q9: =P9 -> rep_GDPSER | R9: =Q9 -> rep_GDPSER | S9: =R9 -> rep_GDPSER
C10: User_con | N10: million | P10: rep_HOU | Q10: =P10 -> rep_HOU | R10: =Q10 -> rep_HOU | S10: =R10 -> rep_HOU
C11: User_con | N11: million | P11: rep_POP | Q11: =P11 -> rep_POP | R11: =Q11 -> rep_POP | S11: =R11 -> rep_POP
C12: User_con | N12: PJ | P12: rep_com_cookhw | Q12: =P12 -> rep_com_cookhw | R12: =Q12 -> rep_com_cookhw | S12: =R12 -> rep_com_cookhw
C13: User_con | N13: PJ | P13: rep_com_lightappl | Q13: =P13 -> rep_com_lightappl | R13: =Q13 -> rep_com_lightappl | S13: =R13 -> rep_com_lightappl
C14: User_con | N14: PJ | P14: rep_com_spcool | Q14: =P14 -> rep_com_spcool | R14: =Q14 -> rep_com_spcool | S14: =R14 -> rep_com_spcool
... C19: User_con | N19: PJ | P19: rep_res_spht | Q19: =P19 -> rep_res_spht | R19: =Q19 -> rep_res_spht | S19: =R19 -> rep_res_spht

Sheet TS_ratios
C1: ~TS_Ratios
C2: var_num | D2: var_den | E2: Name | F2: Unit | G2: show_me | H2: ignore | I2: include_null | J2: include_dim | L2: rep_GDP
C3: Elec_act | D3: Capacity_Elec | E3: Capacity_factor | F3: PJ/GW | I3: y | J3: p | L3: rep_GDPAGR
C4: H2_Prod | D4: Capacity_H2 | E4: Capacity_factor | F4: PJ/GW | I4: y | J4: p | L4: rep_GDPIND
C5: Elec_Prod | D5: Fuel_cons_power | E5: Efficiency | F5: % | I5: y | J5: p | L5: rep_GDPSER
C6: H2_Prod | D6: Fuel_cons_H2 | E6: Efficiency | F6: % | I6: y | J6: p | L6: rep_HOU
C7: DMD_out | D7: DMD_in | E7: Efficiency | F7: % | I7: y | J7: p | L7: rep_POP
C8: CO2_emissions | D8: H2_Prod | E8: CO2 intensity | F8: t/TJ | I8: y | J8: p
C9: CO2_emissions | D9: Elec_Prod | E9: CO2 intensity | F9: t/TJ | I9: y | J9: p
C10: CO2_emissions | D10: DMD_out | E10: CO2 intensity | F10: kt/DemU | I10: y | J10: p
C11: rep_tra_road_pass | D11: rep_POP | E11: Road pass/Population | F11: 000 vkm pcap
C12: rep_tra_road_frt | D12: rep_GDP | E12: Road frt/GDP | F12: vkm/$
C13: rep_totco2 | D13: rep_POP | E13: CO2 percapita | F13: kg pcap
C14: rep_totco2 | D14: rep_GDP | E14: CO2/GDP | F14: kt/b$
C15: rep_com_cookhw | D15: rep_GDPSER | E15: =MID(C15,5,22)&" / GDPSER" -> com_cookhw / GDPSER | F15: MJ/$
C16: rep_com_lightappl | D16: rep_GDPSER | E16: =MID(C16,5,22)&" / GDPSER" -> com_lightappl / GDPSER | F16: MJ/$
C17: rep_com_spcool | D17: rep_GDPSER | E17: =MID(C17,5,22)&" / GDPSER" -> com_spcool / GDPSER | F17: MJ/$
C18: rep_com_spht | D18: rep_GDPSER | E18: =MID(C18,5,22)&" / GDPSER" -> com_spht / GDPSER | F18: MJ/$
C19: rep_res_cookhw | D19: rep_HOU | E19: =MID(C19,5,22)&" / household" -> res_cookhw / household | F19: GJ/HH
C20: rep_res_lightappl | D20: rep_HOU | E20: =MID(C20,5,22)&" / household" -> res_lightappl / household | F20: GJ/HH
C21: rep_res_spcool | D21: rep_HOU | E21: =MID(C21,5,22)&" / household" -> res_spcool / household | F21: GJ/HH
C22: rep_res_spht | D22: rep_HOU | E22: =MID(C22,5,22)&" / household" -> res_spht / household | F22: GJ/HH
C23: zz_TFC_steelprod | D23: mat_prod-crudesteel | E23: Efficiency_steelprod | F23: GJ/t | H23: p,c
C35: CO2_captured | E35: CO2 intensity | F35: t/Tjneg
C36: CO2_captured | E36: CO2 intensity | F36: t/Mwhneg

Sheet PSET_Map
A1: ~Pset_Map
A2: Pset | B2: Desc | C2: Ldesc
A3: E_Bio | B3: Bio | C3: =B3 -> Bio
A4: E_Coal | B4: Coal | C4: =B4 -> Coal
A5: E_Gas | B5: Gas | C5: =B5 -> Gas
A6: E_Lignite | B6: Lignite | C6: =B6 -> Lignite
A7: E_Geothermal | B7: Geothermal | C7: =B7 -> Geothermal
A8: E_Nuclear | B8: Nuclear | C8: =B8 -> Nuclear
A9: E_Oil | B9: Oil | C9: =B9 -> Oil
A10: E_Crude | B10: Crude | C10: =B10 -> Crude
A11: E_Diesel | B11: Diesel | C11: =B11 -> Diesel
A12: E_Waste | B12: Waste | C12: =B12 -> Waste
A13: E_Hydro | B13: Hydro | C13: =B13 -> Hydro
A14: E_Solar | B14: Solar | C14: =B14 -> Solar
... A18: E_Coal-S | B18: Coal (CCS) | C18: =B18 -> Coal (CCS)
A19: E_Gas-S | B19: Gas (CCS) | C19: =B19 -> Gas (CCS) | H19: =_xlfn.TEXTJOIN(",",TRUE,A3:A19) -> E_Bio,E_Coal,E_Gas,E_Lignite,E_Geothermal,E_Nuclear,E_Oil,E_Crude,E_Diesel,E_Waste,E_Hydro,E_Solar,E_Tidal,E_Wind,E_Bio-S,E_Coal-S,E_Gas-S
A20: * | B20: Final energy
A21: DMD_AGR | B21: Agri | C21: =B21 -> Agri
A22: DMD_COM | B22: Commercial | C22: =B22 -> Commercial
A23: DMD_RES | B23: Residential | C23: =B23 -> Residential
A24: DMD_AUTOP | B24: Industry | C24: =B24 -> Industry
A25: DMD_IND | B25: Industry | C25: =B25 -> Industry
A26: DMD_Non-En | B26: Non-Energy | C26: =B26 -> Non-Energy
A27: DMD_TRA-NR | B27: Tra Non-Road | C27: =B27 -> Tra Non-Road
A28: DMD_TRA-R | B28: Tra Road | C28: =B28 -> Tra Road | G28: SNK | H28: =_xlfn.TEXTJOIN(",",TRUE,A21:A28) -> DMD_AGR,DMD_COM,DMD_RES,DMD_AUTOP,DMD_IND,DMD_Non-En,DMD_TRA-NR,DMD_TRA-R
A29: * | B29: NETs
A30: s_DAC | B30: Direct Air Cap | C30: =B30 -> Direct Air Cap | H30: =A30 -> s_DAC
A31: Snk_Avo_For | B31: Avoided Forest Conv | C31: =B31 -> Avoided Forest Conv
A32: Snk_Ref_-_T | B32: Reforestation | C32: =B32 -> Reforestation
A33: Snk_Nat_For | B33: Nat Forest Mgmt | C33: =B33 -> Nat Forest Mgmt
A34: Snk_Bio_-_T | B34: Biochar | C34: =B34 -> Biochar
A35: Snk_Cro_Nut | B35: Crplnd Nutrient Mgmt | C35: =B35 -> Crplnd Nutrient Mgmt
A36: Snk_Tre_In_ | B36: Trees in Cropland | C36: =B36 -> Trees in Cropland
A37: Snk_Avo_Pet | B37: Avoided Peatland | C37: =B37 -> Avoided Peatland
A38: Snk_Coa_Wet | B38: Cstal Wetland Rstrn | C38: =B38 -> Cstal Wetland Rstrn
A39: Snk_Pet_Res | B39: Peatland Restoration | C39: =B39 -> Peatland Restoration | H39: =_xlfn.TEXTJOIN(",",TRUE,A31:A39) -> Snk_Avo_For,Snk_Ref_-_T,Snk_Nat_For,Snk_Bio_-_T,Snk_Cro_Nut,Snk_Tre_In_,Snk_Avo_Pet,Snk_Coa_Wet,Snk_Pet_Res
A40: *
A41: E_Thermal | B41: Thermal Power | C41: =B41 -> Thermal Power
A42: E_Thermal-S | B42: Thermal CCS | C42: =B42 -> Thermal CCS
A43: E_USHP | B43: Utility Heat Pump | C43: =B43 -> Utility Heat Pump
...

Sheet CSET_Map
A1: ~Cset_Map
A2: Cset | B2: Desc | C2: Ldesc
A3: ALLSOL | B3: Solar | C3: =B3 -> Solar
A4: ALLWIN | B4: Wind | C4: =B4 -> Wind
A5: ALLHYD | B5: Hydro | C5: =B5 -> Hydro
A6: ALLGEO | B6: Geotherm | C6: =B6 -> Geotherm | H6: =_xlfn.TEXTJOIN(",",TRUE,A3:A6) -> ALLSOL,ALLWIN,ALLHYD,ALLGEO
A7: ALLBIO | B7: Biomass | C7: =B7 -> Biomass
A8: ALLNUC | B8: Nuclear | C8: =B8 -> Nuclear
A9: ALLELC | B9: Grid Elec | C9: =B9 -> Grid Elec
A10: ALLELCi | B10: Int. Elec | C10: =B10 -> Int. Elec
A11: ALLH2 | B11: Hydrogen | C11: =B11 -> Hydrogen
A12: ALLCOAL | B12: Coal | C12: =B12 -> Coal
A13: ALLCOALInd | B13: Coal Ind. | C13: =B13 -> Coal Ind.
A14: ALLBIOFliq | B14: Biofuels liq | C14: =B14 -> Biofuels liq
A15: ALLBIOFgas | B15: Biofuels gas | C15: =B15 -> Biofuels gas
A16: ALLHEAT | B16: Heat | C16: =B16 -> Heat
A17: ALLOILCrd | B17: Oil Crude | C17: =B17 -> Oil Crude
A18: ALLOILPrd | B18: Oil Prod. | C18: =B18 -> Oil Prod.
A19: ALLGAS | B19: Gas | C19: =B19 -> Gas | H19: =_xlfn.TEXTJOIN(",",TRUE,A3:A19) -> ALLSOL,ALLWIN,ALLHYD,ALLGEO,ALLBIO,ALLNUC,ALLELC,ALLELCi,ALLH2,ALLCOAL,ALLCOALInd,ALLBIOFliq,ALLBIOFgas,ALLHEAT,ALLOILCrd,ALLOILPrd,ALLGAS
A20: * | B20: for industry sector SANKEY
A21: IndSer_STM | B21: -Steam
A22: IndSer_PRH | B22: -Proc. heat
A23: IndSer_PRC | B23: -Proc. Cool
A24: IndSer_MDR | B24: -Mch drive
A25: IndSer_ECP | B25: -Electrochem
A26: IndSer_OTP | B26: -Oth. Proc. Use
A27: IndSer_SPC | B27: -Space cond.
A28: IndSer_LIG | B28: -Lighting
A29: IndSer_OTH | B29: -Other | H29: =_xlfn.TEXTJOIN(",",TRUE,A21:A29) -> IndSer_STM,IndSer_PRH,IndSer_PRC,IndSer_MDR,IndSer_ECP,IndSer_OTP,IndSer_SPC,IndSer_LIG,IndSer_OTH

Sheet cname_map
A1: ~CName_Map
A2: Cname | B2: Desc | C2: Ldesc
A3: HYD | B3: Hydro | C3: =B3 -> Hydro
A4: SOL | B4: Solar | C4: =B4 -> Solar
A5: WIN | B5: Wind | C5: =B5 -> Wind
A6: GEO | B6: Geothermal | C6: =B6 -> Geothermal
A7: TID | B7: Tidal | C7: =B7 -> Tidal

Sheet pname_map
A1: ~PName_Map
A2: Pname | B2: Desc | C2: Ldesc
A5: TU_GasPip--Austria-Hungary | B5: =F5&IF(G5="",""," - "&G5) -> gp_aut-hun | F5: gp_aut-hun | H5: [0.0 km]
A6: TU_GasPip--Hungary-Serbia | B6: =F6&IF(G6="",""," - "&G6) -> gp_hun-srb | F6: gp_hun-srb | H6: [0.0 km]
A7: TU_GasPip--Lithuania-Poland | B7: =F7&IF(G7="",""," - "&G7) -> gp_ltu-pol | F7: gp_ltu-pol | H7: [0.0 km]
A8: TU_GasPip--Serbia-Bosnia_Herz | B8: =F8&IF(G8="",""," - "&G8) -> gp_srb-bih | F8: gp_srb-bih | H8: [0.0 km]
A9: TU_GasPip--Slovak-Poland | B9: =F9&IF(G9="",""," - "&G9) -> gp_svk-pol | F9: gp_svk-pol | H9: [0.0 km]
A10: TU_GasPip--Ukraine-Poland | B10: =F10&IF(G10="",""," - "&G10) -> gp_ukr-pol | F10: gp_ukr-pol | H10: [0.0 km]
A11: TU_GasPip--Uzbekistan-Tajikistan | B11: =F11&IF(G11="",""," - "&G11) -> gp_uzb-tjk | F11: gp_uzb-tjk | H11: [0.0 km]
A12: TU_GasPip--Moldova-Romania | B12: =F12&IF(G12="",""," - "&G12) -> gp_mda-rou | F12: gp_mda-rou | H12: anan^iv-tiraspol-izmail [257.0 km]
A13: TU_GasPip--Ukraine-Moldova | B13: =F13&IF(G13="",""," - "&G13) -> gp_ukr-mda | F13: gp_ukr-mda | H13: anan^iv-tiraspol-izmail [257.0 km]
A14: TU_GasPip--France-Switzerland | B14: =F14&IF(G14="",""," - "&G14) -> gp_fra-che | F14: gp_fra-che | H14: annecy-la gabiule+etrez-vernier+morelmaison-rodersdorf [276.0 km]
A15: TU_GasPip--Egypt-Other_MidEast | B15: =F15&IF(G15="",""," - "&G15) -> gp_egy-jor | F15: gp_egy-jor | H15: arab [1200.0 km]
A16: TU_GasPip--Romania-Hungary | B16: =F16&IF(G16="",""," - "&G16) -> gp_rou-hun | F16: gp_rou-hun | H16: arad-szeged [109.0 km]
... A24: TU_GasPip--Canada-USA | B24: =F24&IF(G24="",""," - "&G24) -> gp_can-usa | F24: gp_can-usa | H24: bc+gas transmission northwest+great lakestransmission+northern border+transgas+empire+vikingtransmission+alliance+maritimes and northeast [31596.0 km]
A25: TU_GasPip--Russia-Turkey | B25: =F25&IF(G25="",""," - "&G25) -> gp_rus-tur - bluestream | F25: gp_rus-tur | G25: bluestream | H25: blue stream+turkstream [2143.0 km]
A26: TU_GasPip--Kyrgyzstan-Kazakhstan | B26: =F26&IF(G26="",""," - "&G26) -> gp_kgz-kaz | F26: gp_kgz-kaz | H26: bukhara-tashkent-bishkek-almaty [1585.0 km]
A27: TU_GasPip--Uzbekistan-Kyrgyzstan | B27: =F27&IF(G27="",""," - "&G27) -> gp_uzb-kgz | F27: gp_uzb-kgz | H27: bukhara-tashkent-bishkek-almaty [1585.0 km]
A28: TU_GasPip--Turkmenistan-Kazakhstan | B28: =F28&IF(G28="",""," - "&G28) -> gp_tkm-kaz | F28: gp_tkm-kaz | H28: bukhara-ural [2382.0 km]
A29: TU_GasPip--Uzbekistan-Russia | B29: =F29&IF(G29="",""," - "&G29) -> gp_uzb-rus | F29: gp_uzb-rus | H29: bukhara-ural [4537.0 km]
A30: TU_GasPip--Uzbekistan-Turkmenistan | B30: =F30&IF(G30="",""," - "&G30) -> gp_uzb-tkm | F30: gp_uzb-tkm | H30: bukhara-ural [2382.0 km]
A31: TU_GasPip--Kazakhstan-Russia | B31: =F31&IF(G31="",""," - "&G31) -> gp_kaz-rus | F31: gp_kaz-rus | H31: bukhara-ural+central asia–center+central asia–center+makat–north caucasus [9775.0 km]
A32: TU_GasPip--Germany-Netherlands | B32: =F32&IF(G32="",""," - "&G32) -> gp_deu-nld | F32: gp_deu-nld | H32: bunde-etzel [60.0 km]
A33: TU_GasPip--Turkmenistan-Uzbekistan | B33: =F33&IF(G33="",""," - "&G33) -> gp_tkm-uzb | F33: gp_tkm-uzb | H33: central asia–center+central asia–center+central asia–china [8282.0 km]
A34: TU_GasPip--Uzbekistan-Kazakhstan | B34: =F34&IF(G34="",""," - "&G34) -> gp_uzb-kaz | F34: gp_uzb-kaz | H34: central asia–center+central asia–center+central asia–china+gazli-shymkent [9159.0 km]
A35: TU_GasPip--Kazakhstan-China | B35: =F35&IF(G35="",""," - "&G35) -> gp_kaz-chn | F35: gp_kaz-chn | H35: central asia–china [1833.0 km]
A36: TU_GasPip--Turkmenistan-China | B36: =F36&IF(G36="",""," - "&G36) -> gp_tkm-chn | F36: gp_tkm-chn | H36: central asia–china+central asia–china [3666.0 km]
A37: TU_GasPip--Turkmenistan-Russia | B37: =F37&IF(G37="",""," - "&G37) -> gp_tkm-rus | F37: gp_tkm-rus | H37: central asia-center+central asia-center [5399.0 km]
... A42: TU_GasPip--Algeria-Tunisia | B42: =F42&IF(G42="",""," - "&G42) -> gp_dza-tun | F42: gp_dza-tun | H42: el borma-gabes+trans-mediterranean [2769.0 km]
A43: TU_GasPip--Norway-France | B43: =F43&IF(G43="",""," - "&G43) -> gp_nor-fra - franpipe | F43: gp_nor-fra | G43: franpipe | H43: franpipe [840.0 km]
A44: TU_GasPip--Poland-Lithuania | B44: =F44&IF(G44="",""," - "&G44) -> gp_pol-ltu | F44: gp_pol-ltu | H44: gas interconnection poland-lithuania+gas interconnection poland-lithuania [508.0 km]
A45: TU_GasPip--Greece-Bulgaria | B45: =F45&IF(G45="",""," - "&G45) -> gp_grc-bgr | F45: gp_grc-bgr | H45: gas interconnector greece–bulgaria (igb) [184.0 km]
A46: TU_GasPip--Argentina-Chile | B46: =F46&IF(G46="",""," - "&G46) -> gp_arg-chl | F46: gp_arg-chl | H46: gasandes+norandino+atacama+gasoducto del pacifico+gasoducto del pacifico [3440.0 km]
A47: TU_GasPip--Other_LatAm-Brazil | B47: =F47&IF(G47="",""," - "&G47) -> gp_bol-bra | F47: gp_bol-bra | H47: gasbol+cuiabá [3795.0 km]
A48: TU_GasPip--Argentina-Other_LatAm | B48: =F48&IF(G48="",""," - "&G48) -> gp_arg-ury | F48: gp_arg-ury | H48: gasoducto del litoral+southern cross [427.0 km]
A49: TU_GasPip--Czech-Germany | B49: =F49&IF(G49="",""," - "&G49) -> gp_cze-deu | F49: gp_cze-deu | H49: gazela+kateřinský potok junction point–přimda junction point [316.0 km]
A50: TU_GasPip--Romania-Bulgaria | B50: =F50&IF(G50="",""," - "&G50) -> gp_rou-bgr | F50: gp_rou-bgr | H50: giurgiu-ruse [26.0 km]
A51: TU_GasPip--Belgium-Netherlands | B51: =F51&IF(G51="",""," - "&G51) -> gp_bel-nld | F51: gp_bel-nld | H51: gravenvoeren–bemelen+maastricht-paris [293.0 km]
A52: TU_GasPip--Greece-Italy | B52: =F52&IF(G52="",""," - "&G52) -> gp_grc-ita | F52: gp_grc-ita | H52: greece-italy interconnector [800.0 km]
A53: TU_GasPip--Libya-Italy | B53: =F53&IF(G53="",""," - "&G53) -> gp_lby-ita - greenstream | F53: gp_lby-ita | G53: greenstream | H53: greenstream [520.0 km]
...

Sheet varbl map
A1: ~varbl_map
A2: dimension | B2: name | C2: description
A3: attribute | B3: *GDP*,*popu*,*percap*,*househo*,-rep* | C3: Macro Indices
A4: attribute | B4: rep_hou,rep_pop,rep_gdp* | C4: Macro drivers
A5: attribute | B5: TFC[_]*,*[_]FE[_]*,Fin E[_]*,-*[_]IND[_]*,-*[_]Fuels[_]*,FinE*,*[_]Fuels | C5: Final energy
A6: attribute | B6: Pri_Prod*,Pri_Imp*,Pri_Exp*,PE[_]*,PriE*,Pri E* | C6: Primary En and Trade
A7: attribute | B7: Elec*_Prod | C7: Elec Generation
A8: attribute | B8: Fuel_con* | C8: Fuel Consumption
A9: attribute | B9: Capacity* | C9: Capacity
A10: attribute | B10: zz_sprun_* | C10: zz_single-period run data
A11: attribute | B11: CO2_emi*,CO2_cap* | C11: Emissions
A12: attribute | B12: Power* | C12: Power
A13: attribute | B13: Prices | C13: Prices
... A16: attribute | B16: LCOE | C16: LCOE
A17: attribute | B17: Storage operation | C17: stg[_]* | G17: attribute | H17: =L17&"[_]s*" -> Solar[_]s* | I17: =L17&" source/use" -> Solar source/use | L17: Solar
A18: attribute | B18: Eprod_ELAUTO*,Efuel_AUTO* | C18: Final energy | G18: attribute | H18: =L18&"[_]s*" -> Wind[_]s* | I18: =L18&" source/use" -> Wind source/use | L18: Wind
A19: CostType | B19: *ELS | C19: WelfareLoss | G19: attribute | H19: =L19&"[_]s*" -> Hydro[_]s* | I19: =L19&" source/use" -> Hydro source/use | L19: Hydro
A20: CostType | B20: *FIX | C20: FixOM | G20: attribute | H20: =L20&"[_]s*" -> Geotherm[_]s* | I20: =L20&" source/use" -> Geotherm source/use | L20: Geotherm
A21: CostType | B21: *INV | C21: Investment | G21: attribute | H21: =L21&"[_]s*" -> Biomass[_]s* | I21: =L21&" source/use" -> Biomass source/use | L21: Biomass
A22: CostType | B22: *IRE | C22: Trade | G22: attribute | H22: =L22&"[_]s*" -> Nuclear[_]s* | I22: =L22&" source/use" -> Nuclear source/use | L22: Nuclear
A23: CostType | B23: *VAR | C23: Variable | G23: attribute | H23: =L23&"[_]s*" -> Grid Elec[_]s* | I23: =L23&" source/use" -> Grid Elec source/use | L23: Grid Elec
A24: CostType | B24: *VARX | C24: Tax/Subsidy | G24: attribute | H24: =L24&"[_]s*" -> Int. Elec[_]s* | I24: =L24&" source/use" -> Int. Elec source/use | L24: Int. Elec
A25: CostType | B25: Act | C25: Variable | G25: attribute | H25: =L25&"[_]s*" -> Gas[_]s* | I25: =L25&" source/use" -> Gas source/use | L25: Gas
A26: CostType | B26: Deliv | C26: Delivery | G26: attribute | H26: =L26&"[_]s*" -> Coal[_]s* | I26: =L26&" source/use" -> Coal source/use | L26: Coal
A27: CostType | B27: FOM | C27: FixOM | G27: attribute | H27: =L27&"[_]s*" -> Biofuels[_]s* | I27: =L27&" source/use" -> Biofuels source/use | L27: Biofuels
A28: CostType | B28: *Fue* | C28: Fuel | G28: attribute | H28: =L28&"[_]s*" -> Heat[_]s* | I28: =L28&" source/use" -> Heat source/use | L28: Heat
G29: attribute | H29: =L29&"[_]s*" -> Oil[_]s* | I29: =L29&" source/use" -> Oil source/use | L29: Oil
G30: attribute | H30: =L30&"[_]s*" -> Hydrogen[_]s* | I30: =L30&" source/use" -> Hydrogen source/use | L30: Hydrogen
A32: Emi/Cap | B32: Emi* | C32: Emission
A33: Emi/Cap | B33: CapCO2* | C33: Capture
A34: source/use | B34: ="*[_]"&C34 -> *[_]Agri | C34: Agri
A35: source/use | B35: ="*[_]"&C35 -> *[_]Commercial | C35: Commercial
A36: source/use | B36: ="*[_]"&C36 -> *[_]Residential | C36: Residential
A37: source/use | B37: ="*[_]"&C37 -> *[_]Industry | C37: Industry
A38: source/use | B38: ="*[_]"&C38 -> *[_]Transport | C38: Transport
A39: source/use | B39: ="*[_]"&C39 -> *[_]Thermal Elec | C39: Thermal Elec
A40: source/use | B40: ="*[_]"&C40 -> *[_]Thermal CCS | C40: Thermal CCS
A41: source/use | B41: ="*[_]"&C41 -> *[_]Ren Elec | C41: Ren Elec
A42: source/use | B42: ="*[_]"&C42 -> *[_]Fossil proc | C42: Fossil proc
A43: source/use | B43: ="*[_]"&C43 -> *[_]BF and CokeOv | C43: BF and CokeOv
...

Sheet process map
A1: ~process_map
A2: dimension | B2: name | C2: description | D2: pset_set | E2: pset_ci | F2: pset_co
A3: sector_weo | C3: PriSup | D3: s_Imports
A4: sector_weo | C4: PriSup | D4: s_Mining
A5: sector_weo | C5: PriSup | D5: s_Trade
A6: sector_weo | C6: Power | D6: s_Utility
A7: sector_weo | C7: Power | D7: s_Autoprod
A8: sector_weo | C8: Energy | D8: s_Energy
A9: sector_weo | C9: Industry | D9: s_Industry
A10: sector_weo | C10: Transport | D10: s_Transport
A11: sector_weo | C11: Buildings | D11: s_Commercial
A12: sector_weo | C12: Buildings | D12: s_Residential
A13: sector_weo | C13: Buildings | D13: s_Agriculture
A14: sector_weo | C14: Hydrogen | D14: s_Hydrogen
... A18: sector_weo | C18: CO2Storage | D18: s_CO2Storage
A19: sector_weo | C19: Storage | D19: s_Storage | F19: -TRDELC
A20: sector_weo | C20: Nat Grid (RE) | D20: s_NatGrids
A21: sector_weo | C21: Direct Air Cap | D21: s_DAC
A22: Sector | C22: Import (exo) | D22: s_Imports
A23: Sector | C23: Industry | D23: s_Mining
A24: Sector | C24: Trade | D24: s_Trade
A25: Sector | C25: Power-util | D25: s_Utility
A26: Sector | C26: Power-util | F26: ELC_???-*
A27: Sector | C27: Industry | D27: s_Autoprod
A28: Sector | C28: Energy | D28: s_Energy
A29: Sector | C29: Industry | D29: s_Industry
A30: Sector | C30: Transport | D30: s_Transport
A31: Sector | C31: Commercial | D31: s_Commercial
A32: Sector | C32: Residential | D32: s_Residential
A33: Sector | C33: Agriculture | D33: s_Agriculture
A34: Sector | C34: Hydrogen | D34: s_Hydrogen
A35: Sector | C35: Industry | D35: s_Industry_NE
A36: Sector | C36: Transport | D36: s_Transport_NE
A37: Sector | C37: Natural Sinks | D37: s_NatSinks
A38: Sector | C38: CO2Storage | D38: s_CO2Storage
A39: Sector | C39: Storage | D39: s_Storage | F39: -TRDELC
A40: Sector | C40: Nat Grid (RE) | D40: s_NatGrids
A41: Sector | C41: Direct Air Cap | D41: s_DAC
A42: Sector | B42: IND_CCS | C42: Ind CCS
A43: Sector | B43: TU_sup-dem* | C43: Trades_sup-dem
...

Sheet commodity map
A1: ~commodity_map
A2: dimension | B2: name | C2: description | D2: cset_set | E2: cset_cd | F2: ldesc
A3: Fuel | B3: *ELC* | C3: Electricity
A4: Fuel | B4: ELCCurt | C4: Int. Elec
A5: Fuel | B5: *H2*,-[_]* | C5: Hydrogen
A6: Fuel | B6: LOHC | C6: =B6 -> LOHC
A7: Fuel | B7: Ammonia | C7: =B7 -> Ammonia
A8: Fuel | B8: *HET* | C8: Heat
A9: Fuel | B9: *OIL*,???RPP,???RFG | C9: Oil
A10: Fuel | B10: *GAS*,*NGA* | C10: Gas
A11: Fuel | B11: *COA* | C11: Coal
A12: Fuel | B12: *COB*,*BCO* | C12: Coal bro
A13: Fuel | C13: Biomass | D13: ALLBIO
A14: Fuel | B14: ???DST | C14: Diesel
A15: Fuel | B15: ???GSL* | C15: Gasoline
A16: Fuel | B16: ???LNG | C16: LNG
A17: Fuel | B17: TRANGA | C17: CNG
A18: Fuel | B18: ???LPG | C18: LPG
A19: Fuel | B19: *SOL*,*SPV*,*STH* | C19: Solar
A20: Fuel | B20: ???JTK | C20: Jet kero
A21: Fuel | B21: ???HFO | C21: Heavy oil
A22: Fuel | B22: ???KER | C22: Kerosene
A23: Fuel | B23: ???Nap | C23: Naphtha
A24: Fuel | B24: ???PTC | C24: Petcoke
A25: Fuel | B25: *HYD* | C25: Hydro
... A44: Fuel | B44: *CO2Nb | C44: Bio
A45: Fuel_Agg | C45: Solar | D45: ALLSOL
A46: Fuel_Agg | C46: Wind | D46: ALLWIN
A47: Fuel_Agg | C47: Hydro | D47: ALLHYD
A48: Fuel_Agg | C48: Geotherm | D48: ALLGEO
A49: Fuel_Agg | C49: Biomass | D49: ALLBIO
A50: Fuel_Agg | C50: Nuclear | D50: ALLNUC
A51: Fuel_Agg | C51: Grid Elec | D51: ALLELC
A52: Fuel_Agg | C52: Int. Elec | D52: ALLELCi
A53: Fuel_Agg | C53: Gas | D53: ALLGAS
A54: Fuel_Agg | C54: Coal | D54: ALLCOAL
A55: Fuel_Agg | C55: Coal Ind. | D55: ALLCOALInd
A56: Fuel_Agg | C56: Biofuels liq | D56: ALLBIOFliq
... A60: Fuel_Agg | C60: Oil prod. | D60: ALLOILprd
A61: Fuel_Agg | B61: -[_]* | C61: Hydrogen+ | D61: ALLH2
...

Sheet UnitConv_TIAM
A1: ~UnitConv
A2: Model | B2: Unit1 | C2: Unit2 | D2: MultFact
A3: KINESYS | B3: GW | C3: GW | D3: 1 | G3: $2000 to 2005 | H3: 1.13 | J3: EMF27 Units | L3: =218/172.2 -> 1.2659698 | M3: =1/L3 -> 0.78990826
A4: KINESYS | B4: $/GJ | C4: US$2020/GJ | D4: =H5 -> 1 | G4: $2000 to 2010 | H4: =1/0.81 -> 1.2345679 | J4: °C
A5: KINESYS | B5: kt CH4 | C5: Mt CH4/yr | D5: 0.001 | G5: $2015 to 2015 | H5: 1 | J5: $/kW
A6: KINESYS | B6: kt CO2 | C6: Mt CO2/yr | D6: 0.001 | G6: $2015 to 2010 | H6: 0.92207698 | J6: %
A7: KINESYS | B7: kt CO2neg | C7: Mt CO2/yr | D7: -0.001 | J7: billion US$2005/yr
A8: KINESYS | B8: kt N2O | C8: kt N2O/yr | D8: 1 | J8: bn m2/yr
A9: KINESYS | B9: m$ | C9: billion US$2020/yr | D9: =0.001*H5 -> 0.001 | J9: bn pkm/yr
A10: KINESYS | B10: $/t CO2 | C10: US$2020/t CO2 | D10: =D4 -> 1 | J10: bn tkm/yr | L10: PJ | M10: quadrillion Btu | N10: =947800*10^-9 -> 0.0009478
A11: KINESYS | B11: ppb | C11: ppb | D11: 1 | J11: EJ
A12: KINESYS | B12: ppm | C12: ppm | D12: 1 | J12: EJ/yr
A13: KINESYS | B13: W/m2 | C13: W/m2 | D13: 1 | J13: GW
A14: KINESYS | B14: PJ-Cum | C14: EJ | D14: 0.001 | J14: Index (2005 = 1)
A15: KINESYS | B15: $/GJe | C15: US$2020/MWh | D15: 3.6 | J15: kt N2O/yr
A16: KINESYS | B16: $/kw | C16: US$2020/kW | D16: =D4 -> 1 | J16: ktU
A17: KINESYS | B17: m$npv | C17: billion US$2020 | D17: =D9 -> 0.001 | J17: million
A18: KINESYS | B18: PJe | C18: Twh | D18: =1/3.6 -> 0.27777778 | J18: million Ha/yr
A19: KINESYS | B19: PJNeg | C19: PJ | D19: -1 | J19: Mt BC/yr
A20: KINESYS | B20: PJ2gw | C20: GW | D20: =1/31.536 -> 0.031709792 | J20: Mt CH4/yr
A21: KINESYS | B21: 000$/tneg | C21: US$2020/t CO2 | D21: -1000 | J21: Mt CO/yr
A22: KINESYS | B22: $/000vkm | C22: US$2020/vkm | D22: 0.001 | J22: Mt CO2/yr
A23: KINESYS | B23: PJ/GW | C23: % | D23: =1/31.536 -> 0.031709792 | G23: CF | J23: Mt CO2-equiv/yr
A24: KINESYS | B24: t/TJ | C24: kg/Mwh | D24: =3.6 -> 3.6 | G24: CO2 int | J24: Mt NO2/yr
A25: KINESYS | B25: kg pcap | C25: tons per capita | D25: 0.001 | J25: Mt OC/yr
A26: KINESYS | B26: kt/b$ | C26: kg per PPP $ | D26: 0.001 | J26: Mt SO2/yr
A27: KINESYS | B27: $/GJo | C27: $/bbl | D27: 6.1 | J27: ppb
A28: KINESYS | B28: $/GJg | C28: $/MMBTU | D28: 1.055 | J28: ppm
A29: KINESYS | B29: $/GJh | C29: $/kg | D29: =120/1000 -> 0.12 | J29: US$2005/GJ
A30: KINESYS | B30: PJeNeg | C30: Twh | D30: =-1/3.6 -> -0.27777778 | J30: US$2005/MWh
A31: KINESYS | B31: mtneg | C31: mt | D31: -1 | J31: US$2005/t CO2
J32: W/m2

Sheet lang
A1: name | S1: https://www.loc.gov/standards/iso639-2/php/code_list.php
A2: 2-wheelers | B2: SRP | C2: ALB | D2: HUN | E2: BOS | F2: GRE | G2: UKR | H2: BUL | I2: RUM | J2: FRA | K2: DEU | L2: ESP | M2: ARA | N2: CHI | O2: JPN
A3: 3-wheelers | B3: 2-точка | C3: 2-rrota | D3: 2 kerekűek | E3: 2-točka | F3: 2-τροχα | G3: 2-колісні | H3: 2-колесни | I3: 2 roti | J3: 2-roues | K3: Zweiräder | L3: 2 ruedas | M3: 2 عجلات | N3: 两轮车 | O3: 二輪車
A4: Africa | B4: 3-точкаши | C4: 3-rrota | D4: 3 kerekűek | E4: 3-točkaši | F4: 3τροχα | G4: 3-колісні | H4: 3-колесни | I4: vehicule cu 3 roti | J4: 3 roues | K4: 3-Räder | L4: vehículos de 3 ruedas | M4: 3 عجلات | N4: 三轮车 | O4: 三輪車
A5: Agri | B5: Африка | C5: Afrika | D5: Afrika | E5: Afrika | F5: Αφρική | G5: Африка | H5: Африка | I5: Africa | J5: Afrique | K5: Afrika | L5: África | M5: أفريقيا | N5: 非洲 | O5: アフリカ
A6: Agriculture | B6: Агри | C6: Agri | D6: Agri | E6: Agri | F6: Αγρι | G6: Agri | H6: Agri | I6: Agri | J6: Agri | K6: Landwirtschaft | L6: agrícola | M6: الزراعية | N6: 农业 | O6: アグリ
A7: Appliances-Com | B7: Пољопривреда | C7: Bujqësia | D7: Mezőgazdaság | E7: Poljoprivreda | F7: Γεωργία | G7: Сільське господарство | H7: селско стопанство | I7: Agricultură | J7: Agriculture | K7: Landwirtschaft | L7: Agricultura | M7: زراعة | N7: 农业 | O7: 農業
A8: Appliances-Rsd | B8: Апплианцес-Цом | C8: Pajisje shtëpiake-Com | D8: Appliances-Com | E8: Appliances-Com | F8: Συσκευές-Κομ | G8: Техніка-Ком | H8: Техника-Ком | I8: Electrocasnice-Com | J8: Électroménagers-Com | K8: Appliances-Com | L8: Electrodomésticos-Com | M8: اجهزة منزلية كوم | N8: 家电通讯 | O8: 家電コム
A9: Asia Pacific | B9: Апарати-Рсд | C9: Pajisjet-Rsd | D9: Készülékek-Rsd | E9: Aparati-Rsd | F9: Συσκευές-Rsd | G9: Техніка-Rsd | H9: Техника-Rsd | I9: Electrocasnice-Rsd | J9: Électroménagers-Rsd | K9: Haushaltsgeräte-Rsd | L9: Electrodomésticos-Rsd | M9: الأجهزة- Rsd | N9: 电器-Rsd | O9: アプライアンス-RSD
A10: Avoided Forest Conv | B10: Асиа Пацифиц | C10: Azia Paqësori | D10: Ázsia csendes-óceáni | E10: Asia Pacific | F10: Ασία-Ειρηνικός | G10: Азіатсько-Тихоокеанський регіон | H10: Азия и Тихия океан | I10: Asia Pacific | J10: Asie-Pacifique | K10: Asien-Pazifik | L10: Asia Pacífico | M10: آسيا والمحيط الهادئ | N10: 亚太地区 | O10: アジア太平洋地域
A11: Avoided Peatland | B11: Избегаване шумске конв | C11: Konvertimi i pyllit të shmangur | D11: Elkerült erdő konv | E11: Izbjegavane šumske konv | F11: Αποφευγόμενο δάσος μετατρ | G11: Уникнення лісу Conv | H11: Избягната конв. в гората | I11: Pădure evitată Conv | J11: Conv forêt évitée | K11: Waldconv. vermieden | L11: Conv bosque evitado | M11: تجنب تحويل الغابة | N11: 避免森林转换 | O11: 回避された森の変換
A12: BF and CokOv | B12: Избегао тресетиште | C12: Peatland i shmangur | D12: Elkerülte a tőzeglápot | E12: Izbjegavao tresetište | F12: Αποφεύχθηκε Peatland | G12: Уникнув торфовищ | H12: Избягвано торфище | I12: Turbă evitată | J12: Tourbière évitée | K12: Moorland gemieden | L12: Turbera evitada | M12: تجنب الخث | N12: 避开泥炭地 | O12: 泥炭地を回避
A13: BF gas | B13: БФ и ЦокОв | C13: BF dhe CokOv | D13: BF és CokOv | E13: BF i CokOv | F13: BF και CokOv | G13: BF і CokOv | H13: BF и CokOv | I13: BF și CokOv | J13: BF et CokOv | K13: BF und CokOv | L13: BF y CokOv | M13: BF و CokOv | N13: BF 和 Cokov | O13: BFとCokOv
... A196: Wind | B196: Западни Балкан | C196: Ballkani Perëndimor | D196: Nyugat-Balkán | E196: Zapadni Balkan | F196: Δυτικά Βαλκάνια | G196: Західні Балкани | H196: Западни Балкани | I196: Balcanii de Vest | J196: Balkans occidentaux | K196: Westbalkan | L196: Balcanes Occidentales | M196: غرب البلقان | N196: 西巴尔干地区 | O196: 西バルカン半島
B197: Ветар | C197: Era | D197: Szél | E197: Vjetar | F197: Ανεμος | G197: Вітер | H197: Вятър | I197: Vânt | J197: Vent | K197: Wind | L197: Viento | M197: رياح | N197: 风 | O197: 風
