Workbook

Sheet TRA balance
A1: 0.041868 | B1: ktoe to PJ
L2: =SUM(L16:L24) -> 11358.936 | Z2: =SUM(Z16:Z24) -> 26443.057 | AA2: =Z2/L2 -> 2.3279519
B4: Sector | C4: Sub-Sector | D4: sectfuel | E4: Africa_North | F4: Africa_Other | G4: Australia | H4: Austria | I4: Baltics | J4: BeNeLux | K4: Brazil | L4: China | M4: CroSloven | N4: CzechSlovak | O4: France | P4: Germany | Q4: GreeceCyp | R4: HunRomBul | S4: Iceland | T4: India | U4: Ireland | V4: ItalyMal | W4: Japan | X4: LatAm | Y4: MidEast | Z4: NorthAm | AA4: Norway | AB4: Poland | AC4: ROW | AD4: Russia | AE4: SaudiArabia | AF4: SouthAfrica | AG4: SpainPor | AH4: SweFinDen | AI4: Switzerland | AJ4: Turkey | AK4: UK | AL4: Ukraine | AM4: WestBalkans | AN4: \I: | AO4: \I: | AP4: \I: | AQ4: \I: | AR4: \I: | AS4: \I: | AT4: \I: | AU4: \I: | AV4: \I: | AW4: \I: | AX4: \I:
A5: =IF(OR(C5="TT",C5="TR"),"RR","") | B5: TRA | C5: NEU | D5: COACOK | K5: 6.1607004 | Z5: 2.5819619 | AB5: 0.023990364 | BA5: Bio Diesel | BB5: TRABDS | BC5: bdl
A6: =IF(OR(C6="TT",C6="TR"),"RR","") | B6: TRA | C6: NEU | D6: OILASP | F6: 2.3701893 | L6: 1314.758 | Q6: 0.011388096 | R6: 0.04711406 | X6: 0.37424549 | Y6: 1.7316019 | Z6: 22.480001 | AA6: 0.079440343 | AB6: 0.011036405 | AC6: 0.50052775 | AF6: 3.601925 | AL6: 15.369902 | BA6: Bio Gasoline | BB6: TRABGS | BC6: eth
A7: =IF(OR(C7="TT",C7="TR"),"RR","") | B7: TRA | C7: NEU | D7: OILKER | E7: 0.27722059 | J7: 0.075379147 | R7: 0.0033159456 | X7: 0.23994969 | AC7: 0.69119881 | BA7: Biogas | BB7: TRANGA | BC7: nga
A8: =IF(OR(C8="TT",C8="TR"),"RR","") | B8: TRA | C8: NEU | D8: OILLUB | E8: 2.5678105 | F8: 2.1184789 | H8: 0.61794237 | I8: 2.2514098 | J8: 5.7442561 | L8: 99.093555 | M8: 0.77719987 | N8: 8.4419998 | O8: 12.396298 | P8: 13.188001 | Q8: 0.84525212 | R8: 5.9773855 | S8: 0.14898309 | U8: 1.2904513 | V8: 9.2316009 | W8: 56.685228 | X8: 2.2883667 | Y8: 8.2227203 | Z8: 126.706 | AA8: 1.894033 | AB8: 16.821855 | AC8: 41.817867 | AF8: 6.0861251 | AG8: 10.991359 | AH8: 1.7354412 | AI8: 1.237907 | AJ8: 7.5179981 | AK8: 5.7178709 | AL8: 2.0426644 | AM8: 1.3844157 | BA8: Coal | BB8: TRACOA | BC8: coa
A9: =IF(OR(C9="TT",C9="TR"),"RR","") | B9: TRA | C9: NEU | D9: OILNSP | F9: 0.14324718 | Z9: 261.44 | AC9: 3.0110796 | AL9: 0.035998106 | BA9: Diesel | BB9: TRADST | BC9: dsl
A10: =IF(OR(C10="TT",C10="TR"),"RR","") | B10: TRA | C10: TAD | D10: TRADST | F10: 0.046243206 | X10: 0.30864252 | AC10: 0.068814245 | AF10: 0.74616312 | BA10: Electricity | BB10: TRAELC | BC10: elc
A11: =IF(OR(C11="TT",C11="TR"),"RR","") | B11: TRA | C11: TAD | D11: TRAGSL | U11: 0.030932078 | X11: 0.6908848 | AC11: 0.008959752 | AH11: 4.60548e-05 | BA11: Gasoline | BB11: TRAGSL | BC11: gsl
A12: =IF(OR(C12="TT",C12="TR"),"RR","") | B12: TRA | C12: TAD | D12: TRAHFO | E12: 0.011999369 | AC12: 0.0005945256 | AL12: 7.6400015 | BA12: Heavy Fuel Oil | BB12: TRAHFO | BC12: hfo
A13: =IF(OR(C13="TT",C13="TR"),"RR","") | B13: TRA | C13: TAD | D13: TRAJTK | E13: 28.892667 | F13: 22.625924 | G13: 123.7187 | H13: 1.3079814 | I13: 0.088663864 | J13: 0.552532 | K13: 140.16919 | L13: 1141.751 | M13: 0.46967522 | N13: 1.9810012 | O13: 67.799231 | P13: 30.753001 | Q13: 9.4633277 | R13: 3.1982965 | S13: 0.37972601 | T13: 179.28629 | U13: 0.2140962 | V13: 37.984525 | W13: 147.59977 | X13: 89.066462 | Y13: 60.200674 | Z13: 2814.8465 | AA13: 14.700114 | AB13: 1.416206 | AC13: 364.07691 | AD13: 245.7902 | AE13: 40.847534 | AF13: 51.997134 | AG13: 104.06785 | AH13: 10.771347 | AI13: 2.7698194 | AJ13: 50.438999 | AK13: 37.125494 | BA13: Liquified Petroleum Gases | BB13: TRALPG | BC13: lpg
A14: =IF(OR(C14="TT",C14="TR"),"RR","") | B14: TRA | C14: TAI | D14: TRAHFO | AL14: -5.0799994 | BA14: Natural Gas | BB14: TRANGA | BC14: nga
A15: =IF(OR(C15="TT",C15="TR"),"RR","") | B15: TRA | C15: TAI | D15: TRAJTK | E15: -99.12303 | F15: -192.0928 | G15: -211.35653 | H15: -39.679409 | I15: -14.533446 | J15: -260.82317 | K15: -101.44622 | L15: -449.18389 | M15: -9.49395 | N15: -19.306997 | O15: -260.04602 | P15: -409.876 | Q15: -60.35572 | R15: -28.180049 | S15: -13.042242 | T15: -177.46911 | U15: -45.331459 | V15: -173.05438 | W15: -305.52365 | X15: -322.41766 | Y15: -762.82424 | Z15: -1284.859 | AA15: -22.942529 | AB15: -45.054661 | AC15: -1737.5926 | AD15: -253.11288 | AE15: -153.09619 | AF15: -46.072598 | AG15: -260.69911 | AH15: -115.46579 | AI15: -77.950186 | AJ15: -184.427 | AK15: -493.23921 | AL15: -2.2117399 | AM15: -9.5715565
A16: =IF(OR(C16="TT",C16="TR"),"RR","") -> RR | B16: TRA | C16: TR | D16: TRABDS | G16: 0.036801972 | H16: 17.82448 | I16: 4.5833402 | J16: 36.929908 | K16: 651.02992 | L16: 37.904001 | M16: 6.3832958 | N16: 16.72985 | O16: 105.70326 | P16: 79.09389 | Q16: 7.1657333 | R16: 25.91164 | S16: 0.64893307 | T16: 1.6369383 | U16: 6.7818205 | V16: 52.609281 | W16: 0.51924694 | X16: 74.263528 | Z16: 204.23943 | AA16: 17.542525 | AB16: 35.076408 | AC16: 285.06459 | AD16: 0.0720004 | AG16: 73.584672 | AH16: 71.665049 | AI16: 6.2732499 | AJ16: 4.7795002 | AK16: 52.885602 | AM16: 5.0352592
A17: =IF(OR(C17="TT",C17="TR"),"RR","") -> RR | B17: TRA | C17: TR | D17: TRABGS | F17: 1.9221473 | G17: 5.3332003 | H17: 2.3656341 | I17: 1.0224877 | J17: 14.558935 | K17: 235.95355 | L17: 85.76 | M17: 0.21750426 | N17: 3.9087002 | O17: 27.351933 | P17: 30.097494 | Q17: 1.0531602 | R17: 7.3426089 | S17: 0.16850614 | T17: 36.820817 | U17: 1.096703 | V17: 1.2742944 | W17: 16.636849 | X17: 53.089533 | Z17: 1435.2023 | AA17: 1.7838866 | AB17: 7.8426342 | AC17: 53.43862 | AG17: 5.7976587 | AH17: 9.3798262 | AI17: 1.3390098 | AJ17: 2.2267998 | AK17: 16.015121 | AL17: 3.6889769
A18: =IF(OR(C18="TT",C18="TR"),"RR","") -> RR | B18: TRA | C18: TR | D18: TRADST | E18: 1112.0205 | F18: 988.22762 | G18: 575.63791 | H18: 258.65054 | I18: 121.27005 | J18: 548.23218 | K18: 1435.9916 | L18: 3881.3716 | M18: 120.49403 | N18: 258.1986 | O18: 1286.4001 | P18: 1389.2712 | Q18: 112.34776 | R18: 402.84348 | S18: 7.7045954 | T18: 2433.6589 | U18: 123.34464 | V18: 900.04498 | W18: 913.27098 | X18: 1474.3679 | Y18: 1497.7659 | Z18: 6300.1461 | AA18: 88.600161 | AB18: 592.79821 | AC18: 4015.3714 | AD18: 701.32953 | AE18: 851.79872 | AF18: 347.12819 | AG18: 1074.1823 | AH18: 322.46291 | AI18: 113.81519 | AJ18: 822.3504 | AK18: 1014.1394 | AL18: 181.7944 | AM18: 187.7206 | BA18: =31536000/10^9 -> 0.031536 | BB18: GJ/lt Gasoline | BD18: =1/BA18 -> 31.709792 | BE18: km/l | BF18: equivalent to Bvkm/PJ = 1 | BJ18: =100/BD18 -> 3.1536 | BK18: l/100km
A19: =IF(OR(C19="TT",C19="TR"),"RR","") -> RR | B19: TRA | C19: TR | D19: TRAELC | G19: 0.086398805 | H19: 0.051355289 | I19: 0.29186601 | J19: 2.3190267 | L19: 245.36301 | M19: 0.01288697 | N19: 0.33488538 | O19: 1.1790573 | P19: 1.2096 | Q19: 0.073859339 | R19: 0.42334828 | S19: 0.081198799 | U19: 0.097590121 | V19: 0.49744627 | X19: 2.9411098 | Z19: 28.044514 | AA19: 3.0923998 | AB19: 0.11810544 | AC19: 1.767265 | AD19: 0.55079866 | AF19: 0.19335061 | AG19: 0.60042061 | AH19: 1.3584366 | AK19: 1.3193653 | AM19: 0.013138178 | BA19: 0.038 | BB19: GJ/lt Diesel | BD19: =1/BA19 -> 26.315789 | BE19: km/l | BF19: equivalent to Bvkm/PJ = 1 | BJ19: =100/BD19 -> 3.8 | BK19: l/100km
A20: =IF(OR(C20="TT",C20="TR"),"RR","") -> RR | B20: TRA | C20: TR | D20: TRAGSL | E20: 715.67029 | F20: 1242.7522 | G20: 568.92184 | H20: 69.244171 | I20: 28.915921 | J20: 267.91204 | K20: 898.18184 | L20: 6001.8947 | M20: 37.58546 | N20: 89.100003 | O20: 329.10323 | P20: 722.612 | Q20: 113.01532 | R20: 138.86752 | S20: 5.224737 | T20: 1342.88 | U20: 32.232683 | V20: 326.47973 | W20: 1584.5382 | X20: 1707.7906 | Y20: 2359.6239 | Z20: 18347.249 | AA20: 27.89587 | AB20: 194.31689 | AC20: 4523.0065 | AD20: 1546.967 | AE20: 1019.3707 | AF20: 316.57445 | AG20: 271.13869 | AH20: 190.16307 | AI20: 99.873313 | AJ20: 99.307999 | AK20: 515.39092 | AL20: 77.150482 | AM20: 39.119211
A21: =IF(OR(C21="TT",C21="TR"),"RR","") -> RR | B21: TRA | C21: TR | D21: TRAHFO | Q21: 0.0020808396 | T21: 0.064200391 | X21: 0.090451627 | AC21: 0.35676141 | AF21: 0.7493116
A22: =IF(OR(C22="TT",C22="TR"),"RR","") -> RR | B22: TRA | C22: TR | D22: TRAJTK | X22: 0.32455655 | AC22: 0.028315328 | AF22: 2.5273995 | BJ22: =BJ18/7.96 -> 0.3961809
A23: =IF(OR(C23="TT",C23="TR"),"RR","") -> RR | B23: TRA | C23: TR | D23: TRALPG | E23: 42.939992 | F23: 0.024643505 | G23: 15.20776 | H23: 0.21937576 | I23: 6.9182599 | J23: 8.1889663 | L23: 78.302157 | M23: 3.6899357 | N23: 4.0479992 | O23: 2.4205649 | P23: 15.594 | Q23: 10.084603 | R23: 23.316779 | T23: 8.1308703 | U23: 0.066515692 | V23: 76.071765 | W23: 29.848275 | X23: 34.59714 | Y23: 2.8085347 | Z23: 73.826506 | AA23: 0.21472841 | AB23: 89.009999 | AC23: 232.23175 | AD23: 59.523082 | AF23: 0.65408283 | AG23: 5.6658625 | AI23: 0.070748546 | AJ23: 154.284 | AK23: 2.8979983 | AL23: 83.334339 | AM23: 10.48134
A24: =IF(OR(C24="TT",C24="TR"),"RR","") -> RR | B24: TRA | C24: TR | D24: TRANGA | E24: 20.348053 | F24: 0.074688325 | G24: 3.1234533 | H24: 0.78398667 | I24: 0.80425079 | J24: 3.8368882 | K24: 84.173068 | L24: 1028.3403 | M24: 0.35124321 | N24: 3.1564536 | O24: 6.8120701 | P24: 8.336551 | Q24: 0.74906039 | R24: 4.0482462 | S24: 0.074441304 | T24: 123.38074 | V24: 40.18888 | W24: 1.3990067 | X24: 161.88196 | Y24: 279.44311 | Z24: 54.348445 | AA24: 2.3698251 | AB24: 0.71836696 | AC24: 364.89504 | AD24: 8.9056167 | AF24: 0.0073310868 | AG24: 8.8681657 | AH24: 5.276063 | AI24: 0.58408791 | AJ24: 3.343591 | AK24: 0.56970206 | AL24: 1.3454994 | AM24: 0.54971847 | BA24: mtoe | BB24: 41.868 | BC24: PJ | BJ24: =BJ18/14.35 -> 0.21976307
A25: =IF(OR(C25="TT",C25="TR"),"RR","") -> RR | B25: TRA | C25: TT | D25: TRABDS | H25: 0.077011999 | I25: 0.12838822 | J25: 0.069345968 | K25: 4.392284 | N25: 0.18499794 | O25: 0.34193177 | P25: 0.59372592 | Z25: 17.209033 | AC25: 0.0012602268 | AI25: 0.012983267
A26: =IF(OR(C26="TT",C26="TR"),"RR","") -> RR | B26: TRA | C26: TT | D26: TRACOA | F26: 0.146157 | H26: 0.0042998436 | J26: 0.0026293104 | M26: 0.0042998436 | N26: 0.013163299 | W26: 0.035989733 | AC26: 1.4617459 | AD26: 0.24252458 | AK26: 0.41068321 | AL26: 0.19784723
A27: =IF(OR(C27="TT",C27="TR"),"RR","") -> RR | B27: TRA | C27: TT | D27: TRADST | E27: 2.6678206 | F27: 15.084555 | G27: 47.668292 | H27: 1.3269476 | I27: 4.6106423 | J27: 1.8967628 | K27: 40.785771 | L27: 114.11818 | M27: 0.92079455 | N27: 3.2801987 | O27: 4.9130172 | P27: 10.735198 | Q27: 0.4441483 | R27: 7.4542708 | T27: 109.95602 | U27: 1.6395048 | V27: 1.8318004 | W27: 6.6902008 | X27: 1.9532134 | Y27: 3.4297931 | Z27: 683.88749 | AA27: 0.56947598 | AB27: 3.5821926 | AC27: 77.80904 | AD27: 172.01398 | AF27: 5.0480499 | AG27: 3.8659069 | AH27: 4.553258 | AI27: 0.37943712 | AJ27: 4.8563991 | AK27: 27.030977 | AL27: 1.4202295 | AM27: 0.78320793 | BA27: 1489
A28: =IF(OR(C28="TT",C28="TR"),"RR","") -> RR | B28: TRA | C28: TT | D28: TRAELC | E28: 7.7860747 | F28: 0.18188715 | G28: 11.664002 | H28: 7.1522058 | I28: 0.3407176 | J28: 12.159903 | K28: 8.1020442 | L28: 351.09232 | M28: 1.663558 | N28: 7.4760924 | O28: 30.492908 | P28: 40.568401 | Q28: 0.65615948 | R28: 8.8579374 | T28: 68.932798 | U28: 0.18660986 | V28: 19.979468 | W28: 62.294204 | X28: 5.2044101 | Z28: 30.383122 | AA28: 2.1131994 | AB28: 11.327773 | AC28: 50.950467 | AD28: 192.82644 | AF28: 9.3600017 | AG28: 14.232742 | AH28: 13.254643 | AI28: 10.950002 | AJ28: 4.6356208 | AK28: 20.356774 | AL28: 19.267557 | AM28: 1.6868575
A29: =IF(OR(C29="TT",C29="TR"),"RR","") -> RR | B29: TRA | C29: TT | D29: TRAGSL | G29: 0.044555926 | Q29: 0.010111122 | X29: 0.022219348 | AC29: 0.08267674 | AD29: 1.196801 | AF29: 1.3372053 | AH29: 8.79228e-05 | BA29: 6344
A30: =IF(OR(C30="TT",C30="TR"),"RR","") -> RR | B30: TRA | C30: TT | D30: TRAHFO | E30: 4.2400017 | G30: 0.0017040276 | AC30: 0.022303084 | AD30: 0.087198484 | AF30: 3.0902729 | BA30: 39.45
A31: =IF(OR(C31="TT",C31="TR"),"RR","") | B31: TRA | C31: TWD | D31: TRABDS | J31: 0.11824779 | O31: 0.1783828 | Q31: 0.016964914 | S31: 4.1868e-05 | Z31: 4.5131527 | AC31: 0.25656292 | AG31: 0.10596372 | AH31: 0.16820469 | AI31: 0.028968469 | BA31: 14164
A32: =IF(OR(C32="TT",C32="TR"),"RR","") | B32: TRA | C32: TWD | D32: TRADST | E32: 2.2515982 | F32: 20.462294 | G32: 12.196211 | H32: 1.0391428 | I32: 0.51737544 | J32: 17.810082 | K32: 13.32218 | L32: 622.70791 | M32: 2.0970593 | N32: 0.21299926 | O32: 7.330823 | P32: 11.246398 | Q32: 12.483463 | R32: 2.0379668 | S32: 0.50608782 | T32: 35.081662 | U32: 3.6805991 | V32: 10.836217 | W32: 42.246633 | X32: 34.985403 | Z32: 204.48558 | AA32: 36.0773 | AB32: 0.077958216 | AC32: 246.6528 | AD32: 17.148957 | AF32: 11.016965 | AG32: 20.691115 | AH32: 10.993741 | AI32: 0.99500977 | AJ32: 14.824801 | AK32: 36.848575 | AL32: 5.6338711 | AM32: 1.5225466
A33: =IF(OR(C33="TT",C33="TR"),"RR","") | B33: TRA | C33: TWD | D33: TRAGSL | F33: 2.8287654 | G33: 11.24232 | H33: 0.098561459 | I33: 0.0038267352 | J33: 0.0018463788 | O33: 13.110286 | Q33: 0.0027716616 | V33: 0.01746733 | X33: 0.33602838 | Z33: 198.209 | AA33: 2.6370978 | AC33: 9.0982597 | AD33: 0.5852016 | AF33: 0.038229671 | AH33: 1.3640008 | AI33: 0.52469815 | AM33: 0.29920129
A34: =IF(OR(C34="TT",C34="TR"),"RR","") | B34: TRA | C34: TWD | D34: TRAHFO | E34: 9.7814743 | F34: 0.26331623 | G34: 5.748401 | J34: 0.028001318 | K34: 40.989354 | L34: 395.31816 | O34: 0.47387877 | Q34: 14.360243 | S34: 0.19288169 | T34: 29.293742 | V34: 15.08628 | W34: 88.755182 | X34: 16.624213 | Z34: 38.472564 | AA34: 0.13216053 | AC34: 24.92101 | AD34: 7.8600011 | AG34: 25.903359 | AH34: 3.9209173 | AJ34: 1.3999989 | AK34: 0.33040132
A35: =IF(OR(C35="TT",C35="TR"),"RR","") | B35: TRA | C35: TWD | D35: TRANGA | AA35: 3.1542221 | BA35: 89.6
A36: =IF(OR(C36="TT",C36="TR"),"RR","") | B36: TRA | C36: TWI | D36: TRABDS | J36: -1.9816836 | Q36: -0.0015449292 | Z36: -8.5687467
A37: =IF(OR(C37="TT",C37="TR"),"RR","") | B37: TRA | C37: TWI | D37: TRADST | E37: -9.1431003 | F37: -35.018965 | G37: -3.2613707 | H37: -0.61301451 | I37: -16.595299 | J37: -133.05518 | K37: -19.71809 | L37: -32.562561 | M37: -2.0533784 | O37: -5.9298779 | P37: -30.075601 | Q37: -21.637881 | R37: -3.9072557 | S37: -1.9252204 | T37: -2.3815021 | U37: -5.4310332 | V37: -38.059729 | W37: -5.2803126 | X37: -69.303602 | Y37: -35.604874 | Z37: -461.73995 | AA37: -10.150599 | AB37: -8.1779215 | AC37: -407.61819 | AD37: -364.01444 | AF37: -68.67503 | AG37: -74.435618 | AH37: -38.84979 | AI37: -0.11148611 | AJ37: -6.1769996 | AK37: -67.570501 | AM37: -2.0118118
A38: =IF(OR(C38="TT",C38="TR"),"RR","") | B38: TRA | C38: TWI | D38: TRAHFO | E38: -26.703469 | F38: -53.407918 | G38: -28.83594 | I38: -10.737241 | J38: -673.11487 | K38: -119.43586 | L38: -443.04395 | M38: -6.7915506 | O38: -65.158239 | P38: -26.719999 | Q38: -95.445018 | R38: -0.70021718 | S38: -0.77315961 | T38: -65.767439 | U38: -0.4159209 | V38: -167.76879 | W38: -182.88818 | X38: -291.7926 | Y38: -833.70405 | Z38: -544.79755 | AA38: -1.4256012 | AB38: -3.2242003 | AC38: -2460.6436 | AD38: -88.48 | AE38: -135.01029 | AF38: -57.689934 | AG38: -261.79841 | AH38: -88.967679 | AJ38: -30.72 | AK38: -27.651319
A39: =IF(OR(C39="TT",C39="TR"),"RR","") | B39: TRA | C39: TWI | D39: TRAJTK | AC39: -6.9025134
A40: =IF(OR(C40="TT",C40="TR"),"RR","") | B40: TRA | C40: TWI | D40: TRANGA | I40: -0.8522985 | J40: -2.8695364 | AA40: -2.2015199 | AG40: -1.4913005 | AH40: -0.74190096
E42: =SUMIF($A$5:$A$40,"RR",E$5:E$40) -> 1905.6728 | F42: =SUMIF($A$5:$A$40,"RR",F$5:F$40) -> 2248.4139 | G42: =SUMIF($A$5:$A$40,"RR",G$5:G$40) -> 1227.7259 | H42: =SUMIF($A$5:$A$40,"RR",H$5:H$40) -> 357.70001 | I42: =SUMIF($A$5:$A$40,"RR",I$5:I$40) -> 168.88593 | J42: =SUMIF($A$5:$A$40,"RR",J$5:J$40) -> 896.10659 | K42: =SUMIF($A$5:$A$40,"RR",K$5:K$40) -> 3358.6101 | L42: =SUMIF($A$5:$A$40,"RR",L$5:L$40) -> 11824.146 | ... AY42: =SUMIF($A$5:$A$40,"RR",AY$5:AY$40) -> 0
...

Sheet 2-w
AY2: ~FI_T | BD2: ~FI_Process
C3: comm-in | D3: ='TRA balance'!E4 -> Africa_North | E3: ='TRA balance'!F4 -> Africa_Other | F3: ='TRA balance'!G4 -> Australia | G3: ='TRA balance'!H4 -> Austria | H3: ='TRA balance'!I4 -> Baltics | I3: ='TRA balance'!J4 -> BeNeLux | J3: ='TRA balance'!K4 -> Brazil | K3: ='TRA balance'!L4 -> China | ... AW3: ='TRA balance'!AX4 -> \I: | AX3: * | AY3: attribute | AZ3: process | BA3: comm-out | BB3: LIFE | BD3: Sets | BE3: TechName | BF3: TechDesc | BG3: Tact | BH3: Tcap | BI3: Vintage
A4: TR | C4: TRABDS | D4: {=SUM(SUMIFS(Assumptions!BD$3:BD$102,Assumptions!$B$3:$B$102,'2-w'!$C4,Assumptions!$G$3:$G$102,{"TRW"}))} -> 0 | E4: {=SUM(SUMIFS(Assumptions!BE$3:BE$102,Assumptions!$B$3:$B$102,'2-w'!$C4,Assumptions!$G$3:$G$102,{"TRW"}))} -> 0 | F4: {=SUM(SUMIFS(Assumptions!BF$3:BF$102,Assumptions!$B$3:$B$102,'2-w'!$C4,Assumptions!$G$3:$G$102,{"TRW"}))} -> 0 | G4: {=SUM(SUMIFS(Assumptions!BG$3:BG$102,Assumptions!$B$3:$B$102,'2-w'!$C4,Assumptions!$G$3:$G$102,{"TRW"}))} -> 0 | H4: {=SUM(SUMIFS(Assumptions!BH$3:BH$102,Assumptions!$B$3:$B$102,'2-w'!$C4,Assumptions!$G$3:$G$102,{"TRW"}))} -> 0 | I4: {=SUM(SUMIFS(Assumptions!BI$3:BI$102,Assumptions!$B$3:$B$102,'2-w'!$C4,Assumptions!$G$3:$G$102,{"TRW"}))} -> 0 | J4: {=SUM(SUMIFS(Assumptions!BJ$3:BJ$102,Assumptions!$B$3:$B$102,'2-w'!$C4,Assumptions!$G$3:$G$102,{"TRW"}))} -> 0 | K4: {=SUM(SUMIFS(Assumptions!BK$3:BK$102,Assumptions!$B$3:$B$102,'2-w'!$C4,Assumptions!$G$3:$G$102,{"TRW"}))} -> 0 | ... AW4: {=SUM(SUMIFS(Assumptions!CW$3:CW$102,Assumptions!$B$3:$B$102,'2-w'!$C4,Assumptions!$G$3:$G$102,{"TRW"}))} -> 0 | AX4: =IF(SUM(D4:AW4)=0,"zero","") -> zero | AY4: * | BA4: =IF($AZ4="","",$BA$45) | BB4: =IF($AZ4="","",25) | BD4: =IF($AZ4="","*","DMD") -> * | BE4: =AZ4 -> 0 | BG4: Bvkm | BH4: million Vehicles | BI4: yes
A5: TR | C5: TRABGS | D5: {=SUM(SUMIFS(Assumptions!BD$3:BD$102,Assumptions!$B$3:$B$102,'2-w'!$C5,Assumptions!$G$3:$G$102,{"TRW"}))} -> 0 | E5: {=SUM(SUMIFS(Assumptions!BE$3:BE$102,Assumptions!$B$3:$B$102,'2-w'!$C5,Assumptions!$G$3:$G$102,{"TRW"}))} -> 0 | F5: {=SUM(SUMIFS(Assumptions!BF$3:BF$102,Assumptions!$B$3:$B$102,'2-w'!$C5,Assumptions!$G$3:$G$102,{"TRW"}))} -> 0 | G5: {=SUM(SUMIFS(Assumptions!BG$3:BG$102,Assumptions!$B$3:$B$102,'2-w'!$C5,Assumptions!$G$3:$G$102,{"TRW"}))} -> 0 | H5: {=SUM(SUMIFS(Assumptions!BH$3:BH$102,Assumptions!$B$3:$B$102,'2-w'!$C5,Assumptions!$G$3:$G$102,{"TRW"}))} -> 0 | I5: {=SUM(SUMIFS(Assumptions!BI$3:BI$102,Assumptions!$B$3:$B$102,'2-w'!$C5,Assumptions!$G$3:$G$102,{"TRW"}))} -> 0 | J5: {=SUM(SUMIFS(Assumptions!BJ$3:BJ$102,Assumptions!$B$3:$B$102,'2-w'!$C5,Assumptions!$G$3:$G$102,{"TRW"}))} -> 0 | K5: {=SUM(SUMIFS(Assumptions!BK$3:BK$102,Assumptions!$B$3:$B$102,'2-w'!$C5,Assumptions!$G$3:$G$102,{"TRW"}))} -> 0 | ... AW5: {=SUM(SUMIFS(Assumptions!CW$3:CW$102,Assumptions!$B$3:$B$102,'2-w'!$C5,Assumptions!$G$3:$G$102,{"TRW"}))} -> 0 | AX5: =IF(SUM(D5:AW5)=0,"zero","") -> zero | AY5: * | BA5: =IF($AZ5="","",$BA$45) | BB5: =IF($AZ5="","",25) | BD5: =IF(AZ5="","*","DMD") -> * | BE5: =AZ5 -> 0 | BG5: Bvkm | BH5: million Vehicles | BI5: yes
A6: TR | C6: TRADST | D6: {=SUM(SUMIFS(Assumptions!BD$3:BD$102,Assumptions!$B$3:$B$102,'2-w'!$C6,Assumptions!$G$3:$G$102,{"TRW"}))} -> 0 | E6: {=SUM(SUMIFS(Assumptions!BE$3:BE$102,Assumptions!$B$3:$B$102,'2-w'!$C6,Assumptions!$G$3:$G$102,{"TRW"}))} -> 0 | F6: {=SUM(SUMIFS(Assumptions!BF$3:BF$102,Assumptions!$B$3:$B$102,'2-w'!$C6,Assumptions!$G$3:$G$102,{"TRW"}))} -> 0 | G6: {=SUM(SUMIFS(Assumptions!BG$3:BG$102,Assumptions!$B$3:$B$102,'2-w'!$C6,Assumptions!$G$3:$G$102,{"TRW"}))} -> 0 | H6: {=SUM(SUMIFS(Assumptions!BH$3:BH$102,Assumptions!$B$3:$B$102,'2-w'!$C6,Assumptions!$G$3:$G$102,{"TRW"}))} -> 0 | I6: {=SUM(SUMIFS(Assumptions!BI$3:BI$102,Assumptions!$B$3:$B$102,'2-w'!$C6,Assumptions!$G$3:$G$102,{"TRW"}))} -> 0 | J6: {=SUM(SUMIFS(Assumptions!BJ$3:BJ$102,Assumptions!$B$3:$B$102,'2-w'!$C6,Assumptions!$G$3:$G$102,{"TRW"}))} -> 0 | K6: {=SUM(SUMIFS(Assumptions!BK$3:BK$102,Assumptions!$B$3:$B$102,'2-w'!$C6,Assumptions!$G$3:$G$102,{"TRW"}))} -> 0 | ... AW6: {=SUM(SUMIFS(Assumptions!CW$3:CW$102,Assumptions!$B$3:$B$102,'2-w'!$C6,Assumptions!$G$3:$G$102,{"TRW"}))} -> 0 | AX6: =IF(SUM(D6:AW6)=0,"zero","") -> zero | AY6: * | BA6: =IF($AZ6="","",$BA$45) | BB6: =IF($AZ6="","",25) | BD6: =IF(AZ6="","*","DMD") -> * | BE6: =AZ6 -> 0 | BG6: Bvkm | BH6: million Vehicles | BI6: yes
A7: TR | C7: TRAELC | D7: {=SUM(SUMIFS(Assumptions!BD$3:BD$102,Assumptions!$B$3:$B$102,'2-w'!$C7,Assumptions!$G$3:$G$102,{"TRW"}))} -> 0 | E7: {=SUM(SUMIFS(Assumptions!BE$3:BE$102,Assumptions!$B$3:$B$102,'2-w'!$C7,Assumptions!$G$3:$G$102,{"TRW"}))} -> 0 | F7: {=SUM(SUMIFS(Assumptions!BF$3:BF$102,Assumptions!$B$3:$B$102,'2-w'!$C7,Assumptions!$G$3:$G$102,{"TRW"}))} -> 0.064799104 | G7: {=SUM(SUMIFS(Assumptions!BG$3:BG$102,Assumptions!$B$3:$B$102,'2-w'!$C7,Assumptions!$G$3:$G$102,{"TRW"}))} -> 0.038516467 | H7: {=SUM(SUMIFS(Assumptions!BH$3:BH$102,Assumptions!$B$3:$B$102,'2-w'!$C7,Assumptions!$G$3:$G$102,{"TRW"}))} -> 0 | I7: {=SUM(SUMIFS(Assumptions!BI$3:BI$102,Assumptions!$B$3:$B$102,'2-w'!$C7,Assumptions!$G$3:$G$102,{"TRW"}))} -> 1.73927 | J7: {=SUM(SUMIFS(Assumptions!BJ$3:BJ$102,Assumptions!$B$3:$B$102,'2-w'!$C7,Assumptions!$G$3:$G$102,{"TRW"}))} -> 0 | K7: {=SUM(SUMIFS(Assumptions!BK$3:BK$102,Assumptions!$B$3:$B$102,'2-w'!$C7,Assumptions!$G$3:$G$102,{"TRW"}))} -> 147.21781 | ... AW7: {=SUM(SUMIFS(Assumptions!CW$3:CW$102,Assumptions!$B$3:$B$102,'2-w'!$C7,Assumptions!$G$3:$G$102,{"TRW"}))} -> 0 | AX7: =IF(SUM(D7:AW7)=0,"zero","") | AY7: * | BA7: =IF($AZ7="","",$BA$45) | BB7: =IF($AZ7="","",25) | BD7: =IF(AZ7="","*","DMD") -> * | BE7: =AZ7 -> 0 | BG7: Bvkm | BH7: million Vehicles | BI7: yes
A8: TR | C8: TRAGSL | D8: {=SUM(SUMIFS(Assumptions!BD$3:BD$102,Assumptions!$B$3:$B$102,'2-w'!$C8,Assumptions!$G$3:$G$102,{"TRW"}))} -> 250.4846 | E8: {=SUM(SUMIFS(Assumptions!BE$3:BE$102,Assumptions!$B$3:$B$102,'2-w'!$C8,Assumptions!$G$3:$G$102,{"TRW"}))} -> 434.96326 | F8: {=SUM(SUMIFS(Assumptions!BF$3:BF$102,Assumptions!$B$3:$B$102,'2-w'!$C8,Assumptions!$G$3:$G$102,{"TRW"}))} -> 10.240593 | G8: {=SUM(SUMIFS(Assumptions!BG$3:BG$102,Assumptions!$B$3:$B$102,'2-w'!$C8,Assumptions!$G$3:$G$102,{"TRW"}))} -> 0.33583423 | H8: {=SUM(SUMIFS(Assumptions!BH$3:BH$102,Assumptions!$B$3:$B$102,'2-w'!$C8,Assumptions!$G$3:$G$102,{"TRW"}))} -> 0.30361717 | I8: {=SUM(SUMIFS(Assumptions!BI$3:BI$102,Assumptions!$B$3:$B$102,'2-w'!$C8,Assumptions!$G$3:$G$102,{"TRW"}))} -> 1.2993734 | J8: {=SUM(SUMIFS(Assumptions!BJ$3:BJ$102,Assumptions!$B$3:$B$102,'2-w'!$C8,Assumptions!$G$3:$G$102,{"TRW"}))} -> 12.125455 | K8: {=SUM(SUMIFS(Assumptions!BK$3:BK$102,Assumptions!$B$3:$B$102,'2-w'!$C8,Assumptions!$G$3:$G$102,{"TRW"}))} -> 540.17053 | ... AW8: {=SUM(SUMIFS(Assumptions!CW$3:CW$102,Assumptions!$B$3:$B$102,'2-w'!$C8,Assumptions!$G$3:$G$102,{"TRW"}))} -> 0 | AX8: =IF(SUM(D8:AW8)=0,"zero","") | AY8: * | BA8: =IF($AZ8="","",$BA$45) | BB8: =IF($AZ8="","",25) | BD8: =IF(AZ8="","*","DMD") -> * | BE8: =AZ8 -> 0 | BG8: Bvkm | BH8: million Vehicles | BI8: yes
A9: TR | C9: TRALPG | D9: {=SUM(SUMIFS(Assumptions!BD$3:BD$102,Assumptions!$B$3:$B$102,'2-w'!$C9,Assumptions!$G$3:$G$102,{"TRW"}))} -> 0 | E9: {=SUM(SUMIFS(Assumptions!BE$3:BE$102,Assumptions!$B$3:$B$102,'2-w'!$C9,Assumptions!$G$3:$G$102,{"TRW"}))} -> 0 | F9: {=SUM(SUMIFS(Assumptions!BF$3:BF$102,Assumptions!$B$3:$B$102,'2-w'!$C9,Assumptions!$G$3:$G$102,{"TRW"}))} -> 0 | G9: {=SUM(SUMIFS(Assumptions!BG$3:BG$102,Assumptions!$B$3:$B$102,'2-w'!$C9,Assumptions!$G$3:$G$102,{"TRW"}))} -> 0 | H9: {=SUM(SUMIFS(Assumptions!BH$3:BH$102,Assumptions!$B$3:$B$102,'2-w'!$C9,Assumptions!$G$3:$G$102,{"TRW"}))} -> 0 | I9: {=SUM(SUMIFS(Assumptions!BI$3:BI$102,Assumptions!$B$3:$B$102,'2-w'!$C9,Assumptions!$G$3:$G$102,{"TRW"}))} -> 0 | J9: {=SUM(SUMIFS(Assumptions!BJ$3:BJ$102,Assumptions!$B$3:$B$102,'2-w'!$C9,Assumptions!$G$3:$G$102,{"TRW"}))} -> 0 | K9: {=SUM(SUMIFS(Assumptions!BK$3:BK$102,Assumptions!$B$3:$B$102,'2-w'!$C9,Assumptions!$G$3:$G$102,{"TRW"}))} -> 0 | ... AW9: {=SUM(SUMIFS(Assumptions!CW$3:CW$102,Assumptions!$B$3:$B$102,'2-w'!$C9,Assumptions!$G$3:$G$102,{"TRW"}))} -> 0 | AX9: =IF(SUM(D9:AW9)=0,"zero","") -> zero | AY9: * | BA9: =IF($AZ9="","",$BA$45) | BB9: =IF($AZ9="","",25) | BD9: =IF(AZ9="","*","DMD") -> * | BE9: =AZ9 -> 0 | BG9: Bvkm | BH9: million Vehicles | BI9: yes
A10: TR | C10: TRANGA | D10: {=SUM(SUMIFS(Assumptions!BD$3:BD$102,Assumptions!$B$3:$B$102,'2-w'!$C10,Assumptions!$G$3:$G$102,{"TRW"}))} -> 0 | E10: {=SUM(SUMIFS(Assumptions!BE$3:BE$102,Assumptions!$B$3:$B$102,'2-w'!$C10,Assumptions!$G$3:$G$102,{"TRW"}))} -> 0 | F10: {=SUM(SUMIFS(Assumptions!BF$3:BF$102,Assumptions!$B$3:$B$102,'2-w'!$C10,Assumptions!$G$3:$G$102,{"TRW"}))} -> 0 | G10: {=SUM(SUMIFS(Assumptions!BG$3:BG$102,Assumptions!$B$3:$B$102,'2-w'!$C10,Assumptions!$G$3:$G$102,{"TRW"}))} -> 0 | H10: {=SUM(SUMIFS(Assumptions!BH$3:BH$102,Assumptions!$B$3:$B$102,'2-w'!$C10,Assumptions!$G$3:$G$102,{"TRW"}))} -> 0 | I10: {=SUM(SUMIFS(Assumptions!BI$3:BI$102,Assumptions!$B$3:$B$102,'2-w'!$C10,Assumptions!$G$3:$G$102,{"TRW"}))} -> 0 | J10: {=SUM(SUMIFS(Assumptions!BJ$3:BJ$102,Assumptions!$B$3:$B$102,'2-w'!$C10,Assumptions!$G$3:$G$102,{"TRW"}))} -> 0 | K10: {=SUM(SUMIFS(Assumptions!BK$3:BK$102,Assumptions!$B$3:$B$102,'2-w'!$C10,Assumptions!$G$3:$G$102,{"TRW"}))} -> 0 | ... AW10: {=SUM(SUMIFS(Assumptions!CW$3:CW$102,Assumptions!$B$3:$B$102,'2-w'!$C10,Assumptions!$G$3:$G$102,{"TRW"}))} -> 0 | AX10: =IF(SUM(D10:AW10)=0,"zero","") -> zero | AY10: * | BA10: =IF($AZ10="","",$BA$45) | BB10: =IF($AZ10="","",25) | BD10: =IF(AZ10="","*","DMD") -> * | BE10: =AZ10 -> 0 | BG10: Bvkm | BH10: million Vehicles | BI10: yes
A11: Share of PJ | D11: =SUM(D$4:D$10)/SUM($D$4:$AJ$10) -> 0.065977858 | E11: =SUM(E$4:E$10)/SUM($D$4:$AJ$10) -> 0.11456969 | F11: =SUM(F$4:F$10)/SUM($D$4:$AJ$10) -> 0.0027144491 | G11: =SUM(G$4:G$10)/SUM($D$4:$AJ$10) -> 9.8604292e-05 | H11: =SUM(H$4:H$10)/SUM($D$4:$AJ$10) -> 7.9973021e-05 | I11: =SUM(I$4:I$10)/SUM($D$4:$AJ$10) -> 0.00080038126 | J11: =SUM(J$4:J$10)/SUM($D$4:$AJ$10) -> 0.0031938552 | K11: =SUM(K$4:K$10)/SUM($D$4:$AJ$10) -> 0.18105867 | ... AW11: =SUM(AW$4:AW$10)/SUM($D$4:$AJ$10) -> 0 | AY11: * | BA11: =IF($AZ11="","",$BA$45) | BB11: =IF($AZ11="","",25) | BD11: =IF(AZ11="","*","DMD") -> * | BE11: =AZ11 -> 0 | BG11: Bvkm | BH11: million Vehicles | BI11: yes
AY12: * | BA12: =IF($AZ12="","",$BA$45) | BB12: =IF($AZ12="","",12) | BD12: =IF(AZ12="","*","DMD") -> * | BE12: =AZ12 -> 0 | BG12: Bvkm | BH12: million Vehicles | BI12: yes
A13: m Vehicles | C13: =SUM(D13:AJ13) -> 596.338 | D13: =SUM(D19:D25) -> 35.426 | E13: =SUM(E19:E25) -> 61.516 | F13: =SUM(F19:F25) -> 1.476 | G13: =SUM(G19:G25) -> 0.064 | H13: =SUM(H19:H25) -> 0.043 | I13: =SUM(I19:I25) -> 0.929 | J13: =SUM(J19:J25) -> 1.715 | K13: =SUM(K19:K25) -> 139.489 | ... AW13: =SUM(AW19:AW25) -> 0 | AY13: * | BA13: =IF($AZ13="","",$BA$45) | BB13: =IF($AZ13="","",12) | BD13: =IF(AZ13="","*","DMD") -> * | BE13: =AZ13 -> 0 | BG13: Bvkm | BH13: million Vehicles | BI13: yes
A14: Share of Veh | D14: =D13/SUM($D$13:$AJ$13) -> 0.059405907 | E14: =E13/SUM($D$13:$AJ$13) -> 0.10315626 | F14: =F13/SUM($D$13:$AJ$13) -> 0.0024751064 | G14: =G13/SUM($D$13:$AJ$13) -> 0.00010732169 | H14: =H13/SUM($D$13:$AJ$13) -> 7.2106758e-05 | I14: =I13/SUM($D$13:$AJ$13) -> 0.0015578414 | J14: =J13/SUM($D$13:$AJ$13) -> 0.0028758858 | K14: =K13/SUM($D$13:$AJ$13) -> 0.23390929 | ... AW14: =AW13/SUM($D$13:$AJ$13) -> 0 | AY14: * | BA14: =IF($AZ14="","",$BA$45) | BB14: =IF($AZ14="","",12) | BD14: =IF(AZ14="","*","DMD") -> * | BE14: =AZ14 -> 0 | BG14: Bvkm | BH14: million Vehicles | BI14: yes
AY15: * | BA15: =IF($AZ15="","",$BA$45) | BB15: =IF($AZ15="","",12) | BD15: =IF(AZ15="","*","DMD") -> * | BE15: =AZ15 -> 0 | BG15: Bvkm | BH15: million Vehicles | BI15: yes
AY16: * | BA16: =IF($AZ16="","",$BA$45) | BB16: =IF($AZ16="","",12) | BD16: =IF(AZ16="","*","DMD") -> * | BE16: =AZ16 -> 0 | BG16: Bvkm | BH16: million Vehicles | BI16: yes
A17: PJ share/Veh share | D17: =IFERROR(D11/D14,"") -> 1.1106279 | E17: =IFERROR(E11/E14,"") -> 1.1106422 | F17: =IFERROR(F11/F14,"") -> 1.0967 | G17: =IFERROR(G11/G14,"") -> 0.91877323 | H17: =IFERROR(H11/H14,"") -> 1.1090919 | I17: =IFERROR(I11/I14,"") -> 0.51377584 | J17: =IFERROR(J11/J14,"") -> 1.110564 | K17: =IFERROR(K11/K14,"") -> 0.77405507 | ... AW17: =IFERROR(AW11/AW14,"") | AY17: * | BA17: =IF($AZ17="","",$BA$45) | BB17: =IF($AZ17="","",12) | BD17: =IF(AZ17="","*","DMD") -> * | BE17: =AZ17 -> 0 | BG17: Bvkm | BH17: million Vehicles | BI17: yes
AY18: * | BA18: =IF($AZ18="","",$BA$45) | BB18: =IF($AZ18="","",12) | BD18: =IF(AZ18="","*","DMD") -> * | BE18: =AZ18 -> 0 | BG18: Bvkm | BH18: million Vehicles | BI18: yes
A19: mVeh | C19: =C4 -> TRABDS | D19: =ROUND(D4*D28/D36,3) -> 0 | E19: =ROUND(E4*E28/E36,3) -> 0 | F19: =ROUND(F4*F28/F36,3) -> 0 | G19: =ROUND(G4*G28/G36,3) -> 0 | H19: =ROUND(H4*H28/H36,3) -> 0 | I19: =ROUND(I4*I28/I36,3) -> 0 | J19: =ROUND(J4*J28/J36,3) -> 0 | K19: =ROUND(K4*K28/K36,3) -> 0 | ... AW19: =ROUND(AW4*AW28/AW36,3) -> 0 | AY19: PASTI | AZ19: =IF(AX4="zero","\I:",$BA$45&"_"&VLOOKUP(C19,'TRA balance'!$BB$5:$BC$15,2,FALSE)) -> \I: | BA19: =IF($AZ19="","",$BA$45) -> Trd_2w | BB19: =IF($AZ19="","",25) -> 25 | BD19: =IF(AZ19="","*","DMD") -> DMD | BE19: =AZ19 -> \I: | BG19: Bvkm | BH19: million Vehicles | BI19: yes
C20: =C5 -> TRABGS | D20: =ROUND(D5*D29/D37,3) -> 0 | E20: =ROUND(E5*E29/E37,3) -> 0 | F20: =ROUND(F5*F29/F37,3) -> 0 | G20: =ROUND(G5*G29/G37,3) -> 0 | H20: =ROUND(H5*H29/H37,3) -> 0 | I20: =ROUND(I5*I29/I37,3) -> 0 | J20: =ROUND(J5*J29/J37,3) -> 0 | K20: =ROUND(K5*K29/K37,3) -> 0 | ... AW20: =ROUND(AW5*AW29/AW37,3) -> 0 | AY20: PASTI | AZ20: =IF(AX5="zero","\I:",$BA$45&"_"&VLOOKUP(C20,'TRA balance'!$BB$5:$BC$15,2,FALSE)) -> \I: | BA20: =IF($AZ20="","",$BA$45) -> Trd_2w | BB20: =IF($AZ20="","",25) -> 25 | BD20: =IF(AZ20="","*","DMD") -> DMD | BE20: =AZ20 -> \I: | BG20: Bvkm | BH20: million Vehicles | BI20: yes
C21: =C6 -> TRADST | D21: =ROUND(D6*D30/D38,3) -> 0 | E21: =ROUND(E6*E30/E38,3) -> 0 | F21: =ROUND(F6*F30/F38,3) -> 0 | G21: =ROUND(G6*G30/G38,3) -> 0 | H21: =ROUND(H6*H30/H38,3) -> 0 | I21: =ROUND(I6*I30/I38,3) -> 0 | J21: =ROUND(J6*J30/J38,3) -> 0 | K21: =ROUND(K6*K30/K38,3) -> 0 | ... AW21: =ROUND(AW6*AW30/AW38,3) -> 0 | AY21: PASTI | AZ21: =IF(AX6="zero","\I:",$BA$45&"_"&VLOOKUP(C21,'TRA balance'!$BB$5:$BC$15,2,FALSE)) -> \I: | BA21: =IF($AZ21="","",$BA$45) -> Trd_2w | BB21: =IF($AZ21="","",25) -> 25 | BD21: =IF(AZ21="","*","DMD") -> DMD | BE21: =AZ21 -> \I: | BG21: Bvkm | BH21: million Vehicles | BI21: yes
C22: =C7 -> TRAELC | D22: =ROUND(D7*D31/D39,3) -> 0 | E22: =ROUND(E7*E31/E39,3) -> 0 | F22: =ROUND(F7*F31/F39,3) -> 0.028 | G22: =ROUND(G7*G31/G39,3) -> 0.017 | H22: =ROUND(H7*H31/H39,3) -> 0 | I22: =ROUND(I7*I31/I39,3) -> 0.745 | J22: =ROUND(J7*J31/J39,3) -> 0 | K22: =ROUND(K7*K31/K39,3) -> 63.093 | ... AW22: =ROUND(AW7*AW31/AW39,3) -> 0 | AY22: PASTI | AZ22: =IF(AX7="zero","\I:",$BA$45&"_"&VLOOKUP(C22,'TRA balance'!$BB$5:$BC$15,2,FALSE)) -> Trd_2w_elc | BA22: =IF($AZ22="","",$BA$45) -> Trd_2w | BB22: =IF($AZ22="","",25) -> 25 | BD22: =IF(AZ22="","*","DMD") -> DMD | BE22: =AZ22 -> Trd_2w_elc | BG22: Bvkm | BH22: million Vehicles | BI22: yes
C23: =C8 -> TRAGSL | D23: =ROUND(D8*D32/D40,3) -> 35.426 | E23: =ROUND(E8*E32/E40,3) -> 61.516 | F23: =ROUND(F8*F32/F40,3) -> 1.448 | G23: =ROUND(G8*G32/G40,3) -> 0.047 | H23: =ROUND(H8*H32/H40,3) -> 0.043 | I23: =ROUND(I8*I32/I40,3) -> 0.184 | J23: =ROUND(J8*J32/J40,3) -> 1.715 | K23: =ROUND(K8*K32/K40,3) -> 76.396 | ... AW23: =ROUND(AW8*AW32/AW40,3) -> 0 | AY23: PASTI | AZ23: =IF(AX8="zero","\I:",$BA$45&"_"&VLOOKUP(C23,'TRA balance'!$BB$5:$BC$15,2,FALSE)) -> Trd_2w_gsl | BA23: =IF($AZ23="","",$BA$45) -> Trd_2w | BB23: =IF($AZ23="","",25) -> 25 | BD23: =IF(AZ23="","*","DMD") -> DMD | BE23: =AZ23 -> Trd_2w_gsl | BG23: Bvkm | BH23: million Vehicles | BI23: yes
C24: =C9 -> TRALPG | D24: =ROUND(D9*D33/D41,3) -> 0 | E24: =ROUND(E9*E33/E41,3) -> 0 | F24: =ROUND(F9*F33/F41,3) -> 0 | G24: =ROUND(G9*G33/G41,3) -> 0 | H24: =ROUND(H9*H33/H41,3) -> 0 | I24: =ROUND(I9*I33/I41,3) -> 0 | J24: =ROUND(J9*J33/J41,3) -> 0 | K24: =ROUND(K9*K33/K41,3) -> 0 | ... AW24: =ROUND(AW9*AW33/AW41,3) -> 0 | AY24: PASTI | AZ24: =IF(AX9="zero","\I:",$BA$45&"_"&VLOOKUP(C24,'TRA balance'!$BB$5:$BC$15,2,FALSE)) -> \I: | BA24: =IF($AZ24="","",$BA$45) -> Trd_2w | BB24: =IF($AZ24="","",25) -> 25 | BD24: =IF(AZ24="","*","DMD") -> DMD | BE24: =AZ24 -> \I: | BG24: Bvkm | BH24: million Vehicles | BI24: yes
C25: =C10 -> TRANGA | D25: =ROUND(D10*D34/D42,3) -> 0 | E25: =ROUND(E10*E34/E42,3) -> 0 | F25: =ROUND(F10*F34/F42,3) -> 0 | G25: =ROUND(G10*G34/G42,3) -> 0 | H25: =ROUND(H10*H34/H42,3) -> 0 | I25: =ROUND(I10*I34/I42,3) -> 0 | J25: =ROUND(J10*J34/J42,3) -> 0 | K25: =ROUND(K10*K34/K42,3) -> 0 | ... AW25: =ROUND(AW10*AW34/AW42,3) -> 0 | AY25: PASTI | AZ25: =IF(AX10="zero","\I:",$BA$45&"_"&VLOOKUP(C25,'TRA balance'!$BB$5:$BC$15,2,FALSE)) -> \I: | BA25: =IF($AZ25="","",$BA$45) -> Trd_2w | BB25: =IF($AZ25="","",25) -> 25 | BD25: =IF(AZ25="","*","DMD") -> DMD | BE25: =AZ25 -> \I: | BG25: Bvkm | BH25: million Vehicles | BI25: yes
AY26: * | BA26: =IF($AZ26="","",$BA$45) | BB26: =IF($AZ26="","",25) | BD26: =IF(AZ26="","*","DMD") -> * | BE26: =AZ26 -> 0 | BG26: Bvkm | BH26: million Vehicles | BI26: yes
D27: 1 | E27: 1 | F27: 1 | G27: 1 | H27: 1 | I27: 1 | J27: 1 | K27: 1 | L27: 1 | M27: 1 | N27: 1 | O27: 1 | P27: 1 | Q27: 1 | R27: 1 | S27: 1 | T27: 1 | U27: 1 | V27: 1 | W27: 1 | X27: 1 | Y27: 1 | Z27: 1 | AA27: 1 | AB27: 1 | AC27: 1 | AD27: 1 | AE27: 1 | AF27: 1 | AG27: 1 | AH27: 1 | AI27: 1 | AJ27: 1 | AK27: 1 | AL27: 1 | AM27: 1 | AN27: 1 | AO27: 1 | AP27: 1 | AQ27: 1 | AR27: 1 | AS27: 1 | AT27: 1 | AU27: 1 | AV27: 1 | AW27: 1 | AY27: * | BA27: =IF($AZ27="","",$BA$45) | BB27: =IF($AZ27="","",25) | BD27: =IF(AZ27="","*","DMD") -> * | BE27: =AZ27 -> 0 | BG27: Bvkm | BH27: million Vehicles | BI27: yes
A28: Efficiency | C28: =C19 -> TRABDS | D28: =$AX28*D$27 -> 0.99 | E28: =$AX28*E$27 -> 0.99 | F28: =$AX28*F$27 -> 0.99 | G28: =$AX28*G$27 -> 0.99 | H28: =$AX28*H$27 -> 0.99 | I28: =$AX28*I$27 -> 0.99 | J28: =$AX28*J$27 -> 0.99 | K28: =$AX28*K$27 -> 0.99 | ... AW28: =$AX28*AW$27 -> 0.99 | AX28: 0.99 | AY28: EFF | AZ28: =AZ19 -> \I: | BA28: =IF($AZ28="","",$BA$45) -> Trd_2w | BB28: =IF($AZ28="","",25) -> 25 | BD28: =IF(AZ28="","*","DMD") -> DMD | BE28: =AZ28 -> \I: | BG28: Bvkm | BH28: million Vehicles | BI28: yes
C29: =C20 -> TRABGS | D29: =$AX29*D$27 -> 0.99 | E29: =$AX29*E$27 -> 0.99 | F29: =$AX29*F$27 -> 0.99 | G29: =$AX29*G$27 -> 0.99 | H29: =$AX29*H$27 -> 0.99 | I29: =$AX29*I$27 -> 0.99 | J29: =$AX29*J$27 -> 0.99 | K29: =$AX29*K$27 -> 0.99 | ... AW29: =$AX29*AW$27 -> 0.99 | AX29: 0.99 | AY29: EFF | AZ29: =AZ20 -> \I: | BA29: =IF($AZ29="","",$BA$45) -> Trd_2w | BB29: =IF($AZ29="","",25) -> 25 | BD29: =IF(AZ29="","*","DMD") -> DMD | BE29: =AZ29 -> \I: | BG29: Bvkm | BH29: million Vehicles | BI29: yes
C30: =C21 -> TRADST | D30: =$AX30*D$27 -> 0.99 | E30: =$AX30*E$27 -> 0.99 | F30: =$AX30*F$27 -> 0.99 | G30: =$AX30*G$27 -> 0.99 | H30: =$AX30*H$27 -> 0.99 | I30: =$AX30*I$27 -> 0.99 | J30: =$AX30*J$27 -> 0.99 | K30: =$AX30*K$27 -> 0.99 | ... AW30: =$AX30*AW$27 -> 0.99 | AX30: 0.99 | AY30: EFF | AZ30: =AZ21 -> \I: | BA30: =IF($AZ30="","",$BA$45) -> Trd_2w | BB30: =IF($AZ30="","",25) -> 25 | BD30: =IF(AZ30="","*","DMD") -> DMD | BE30: =AZ30 -> \I: | BG30: Bvkm | BH30: million Vehicles | BI30: yes
C31: =C22 -> TRAELC | D31: =$AX31*D$27 -> 3 | E31: =$AX31*E$27 -> 3 | F31: =$AX31*F$27 -> 3 | G31: =$AX31*G$27 -> 3 | H31: =$AX31*H$27 -> 3 | I31: =$AX31*I$27 -> 3 | J31: =$AX31*J$27 -> 3 | K31: =$AX31*K$27 -> 3 | ... AW31: =$AX31*AW$27 -> 3 | AX31: 3 | AY31: EFF | AZ31: =AZ22 -> Trd_2w_elc | BA31: =IF($AZ31="","",$BA$45) -> Trd_2w | BB31: =IF($AZ31="","",25) -> 25 | BD31: =IF(AZ31="","*","DMD") -> DMD | BE31: =AZ31 -> Trd_2w_elc | BG31: Bvkm | BH31: million Vehicles | BI31: yes
C32: =C23 -> TRAGSL | D32: =$AX32*D$27 -> 0.99 | E32: =$AX32*E$27 -> 0.99 | F32: =$AX32*F$27 -> 0.99 | G32: =$AX32*G$27 -> 0.99 | H32: =$AX32*H$27 -> 0.99 | I32: =$AX32*I$27 -> 0.99 | J32: =$AX32*J$27 -> 0.99 | K32: =$AX32*K$27 -> 0.99 | ... AW32: =$AX32*AW$27 -> 0.99 | AX32: 0.99 | AY32: EFF | AZ32: =AZ23 -> Trd_2w_gsl | BA32: =IF($AZ32="","",$BA$45) -> Trd_2w | BB32: =IF($AZ32="","",25) -> 25 | BD32: =IF(AZ32="","*","DMD") -> DMD | BE32: =AZ32 -> Trd_2w_gsl | BG32: Bvkm | BH32: million Vehicles | BI32: yes
C33: =C24 -> TRALPG | D33: =$AX33*D$27 -> 0.99 | E33: =$AX33*E$27 -> 0.99 | F33: =$AX33*F$27 -> 0.99 | G33: =$AX33*G$27 -> 0.99 | H33: =$AX33*H$27 -> 0.99 | I33: =$AX33*I$27 -> 0.99 | J33: =$AX33*J$27 -> 0.99 | K33: =$AX33*K$27 -> 0.99 | ... AW33: =$AX33*AW$27 -> 0.99 | AX33: 0.99 | AY33: EFF | AZ33: =AZ24 -> \I: | BA33: =IF($AZ33="","",$BA$45) -> Trd_2w | BB33: =IF($AZ33="","",25) -> 25 | BD33: =IF(AZ33="","*","DMD") -> DMD | BE33: =AZ33 -> \I: | BG33: Bvkm | BH33: million Vehicles | BI33: yes
C34: =C25 -> TRANGA | D34: =$AX34*D$27 -> 0.99 | E34: =$AX34*E$27 -> 0.99 | F34: =$AX34*F$27 -> 0.99 | G34: =$AX34*G$27 -> 0.99 | H34: =$AX34*H$27 -> 0.99 | I34: =$AX34*I$27 -> 0.99 | J34: =$AX34*J$27 -> 0.99 | K34: =$AX34*K$27 -> 0.99 | ... AW34: =$AX34*AW$27 -> 0.99 | AX34: 0.99 | AY34: EFF | AZ34: =AZ25 -> \I: | BA34: =IF($AZ34="","",$BA$45) -> Trd_2w | BB34: =IF($AZ34="","",25) -> 25 | BD34: =IF(AZ34="","*","DMD") -> DMD | BE34: =AZ34 -> \I: | BG34: Bvkm | BH34: million Vehicles | BI34: yes
AY35: * | BA35: =IF($AZ35="","",$BA$45) | BB35: =IF($AZ35="","",25) | BD35: =IF(AZ35="","*","DMD") -> * | BE35: =AZ35 -> 0 | BG35: Bvkm | BH35: million Vehicles | BI35: yes
A36: 000km/veh | C36: =C28 -> TRABDS | D36: 7 | E36: 7 | F36: 7 | G36: 7 | H36: 7 | I36: 7 | J36: 7 | K36: 7 | L36: 7 | M36: 7 | N36: 7 | O36: 7 | P36: 7 | Q36: 7 | R36: 7 | S36: 7 | T36: 7 | U36: 7 | V36: 4 | W36: 7 | X36: 5 | Y36: 7 | Z36: 4 | AA36: 7 | AB36: 7 | AC36: 3 | AD36: 7 | AE36: 7 | AF36: 6.5 | AG36: 7 | AH36: 7 | AI36: 7 | AJ36: 4 | AK36: 4 | AL36: 4 | AM36: 4 | AN36: 4 | AO36: 4 | AP36: 4 | AQ36: 4 | AR36: 4 | AS36: 4 | AT36: 4 | AU36: 4 | AV36: 4 | AW36: 4 | AY36: AF | AZ36: =AZ28 -> \I: | BA36: =IF($AZ36="","",$BA$45) -> Trd_2w | BB36: =IF($AZ36="","",25) -> 25 | BD36: =IF(AZ36="","*","DMD") -> DMD | BE36: =AZ36 -> \I: | BG36: Bvkm | BH36: million Vehicles | BI36: yes
C37: =C29 -> TRABGS | D37: 7 | E37: 7 | F37: 7 | G37: 7 | H37: 7 | I37: 7 | J37: 7 | K37: 7 | L37: 7 | M37: 7 | N37: 7 | O37: 7 | P37: 7 | Q37: 7 | R37: 7 | S37: 7 | T37: 7 | U37: 7 | V37: 4 | W37: 7 | X37: 5 | Y37: 7 | Z37: 4 | AA37: 7 | AB37: 7 | AC37: 3 | AD37: 7 | AE37: 7 | AF37: 6.5 | AG37: 7 | AH37: 7 | AI37: 7 | AJ37: 4 | AK37: 4 | AL37: 4 | AM37: 4 | AN37: 4 | AO37: 4 | AP37: 4 | AQ37: 4 | AR37: 4 | AS37: 4 | AT37: 4 | AU37: 4 | AV37: 4 | AW37: 4 | AY37: AF | AZ37: =AZ29 -> \I: | BA37: =IF($AZ37="","",$BA$45) -> Trd_2w | BB37: =IF($AZ37="","",25) -> 25 | BD37: =IF(AZ37="","*","DMD") -> DMD | BE37: =AZ37 -> \I: | BG37: Bvkm | BH37: million Vehicles | BI37: yes
C38: =C30 -> TRADST | D38: 7 | E38: 7 | F38: 7 | G38: 7 | H38: 7 | I38: 7 | J38: 7 | K38: 7 | L38: 7 | M38: 7 | N38: 7 | O38: 7 | P38: 7 | Q38: 7 | R38: 7 | S38: 7 | T38: 7 | U38: 7 | V38: 4 | W38: 7 | X38: 5 | Y38: 7 | Z38: 4 | AA38: 7 | AB38: 7 | AC38: 3 | AD38: 7 | AE38: 7 | AF38: 6.5 | AG38: 7 | AH38: 7 | AI38: 7 | AJ38: 4 | AK38: 4 | AL38: 4 | AM38: 4 | AN38: 4 | AO38: 4 | AP38: 4 | AQ38: 4 | AR38: 4 | AS38: 4 | AT38: 4 | AU38: 4 | AV38: 4 | AW38: 4 | AY38: AF | AZ38: =AZ30 -> \I: | BA38: =IF($AZ38="","",$BA$45) -> Trd_2w | BB38: =IF($AZ38="","",25) -> 25 | BD38: =IF(AZ38="","*","DMD") -> DMD | BE38: =AZ38 -> \I: | BG38: Bvkm | BH38: million Vehicles | BI38: yes
C39: =C31 -> TRAELC | D39: 7 | E39: 7 | F39: 7 | G39: 7 | H39: 7 | I39: 7 | J39: 7 | K39: 7 | L39: 7 | M39: 7 | N39: 7 | O39: 7 | P39: 7 | Q39: 7 | R39: 7 | S39: 7 | T39: 7 | U39: 7 | V39: 4 | W39: 7 | X39: 5 | Y39: 7 | Z39: 4 | AA39: 7 | AB39: 7 | AC39: 3 | AD39: 7 | AE39: 7 | AF39: 6.5 | AG39: 7 | AH39: 7 | AI39: 7 | AJ39: 4 | AK39: 4 | AL39: 4 | AM39: 4 | AN39: 4 | AO39: 4 | AP39: 4 | AQ39: 4 | AR39: 4 | AS39: 4 | AT39: 4 | AU39: 4 | AV39: 4 | AW39: 4 | AY39: AF | AZ39: =AZ31 -> Trd_2w_elc | BA39: =IF($AZ39="","",$BA$45) -> Trd_2w | BB39: =IF($AZ39="","",25) -> 25 | BD39: =IF(AZ39="","*","DMD") -> DMD | BE39: =AZ39 -> Trd_2w_elc | BG39: Bvkm | BH39: million Vehicles | BI39: yes
C40: =C32 -> TRAGSL | D40: 7 | E40: 7 | F40: 7 | G40: 7 | H40: 7 | I40: 7 | J40: 7 | K40: 7 | L40: 7 | M40: 7 | N40: 7 | O40: 7 | P40: 7 | Q40: 7 | R40: 7 | S40: 7 | T40: 7 | U40: 7 | V40: 4 | W40: 7 | X40: 5 | Y40: 7 | Z40: 4 | AA40: 7 | AB40: 7 | AC40: 3 | AD40: 7 | AE40: 7 | AF40: 6.5 | AG40: 7 | AH40: 7 | AI40: 7 | AJ40: 4 | AK40: 4 | AL40: 4 | AM40: 4 | AN40: 4 | AO40: 4 | AP40: 4 | AQ40: 4 | AR40: 4 | AS40: 4 | AT40: 4 | AU40: 4 | AV40: 4 | AW40: 4 | AY40: AF | AZ40: =AZ32 -> Trd_2w_gsl | BA40: =IF($AZ40="","",$BA$45) -> Trd_2w | BB40: =IF($AZ40="","",25) -> 25 | BD40: =IF(AZ40="","*","DMD") -> DMD | BE40: =AZ40 -> Trd_2w_gsl | BG40: Bvkm | BH40: million Vehicles | BI40: yes
C41: =C33 -> TRALPG | D41: 7 | E41: 7 | F41: 7 | G41: 7 | H41: 7 | I41: 7 | J41: 7 | K41: 7 | L41: 7 | M41: 7 | N41: 7 | O41: 7 | P41: 7 | Q41: 7 | R41: 7 | S41: 7 | T41: 7 | U41: 7 | V41: 4 | W41: 7 | X41: 5 | Y41: 7 | Z41: 4 | AA41: 7 | AB41: 7 | AC41: 3 | AD41: 7 | AE41: 7 | AF41: 6.5 | AG41: 7 | AH41: 7 | AI41: 7 | AJ41: 4 | AK41: 4 | AL41: 4 | AM41: 4 | AN41: 4 | AO41: 4 | AP41: 4 | AQ41: 4 | AR41: 4 | AS41: 4 | AT41: 4 | AU41: 4 | AV41: 4 | AW41: 4 | AY41: AF | AZ41: =AZ33 -> \I: | BA41: =IF($AZ41="","",$BA$45) -> Trd_2w | BB41: =IF($AZ41="","",25) -> 25 | BD41: =IF(AZ41="","*","DMD") -> DMD | BE41: =AZ41 -> \I: | BG41: Bvkm | BH41: million Vehicles | BI41: yes
...

Sheet 3-w
AY2: ~FI_T | BD2: ~FI_Process
C3: comm-in | D3: ='TRA balance'!E4 -> Africa_North | E3: ='TRA balance'!F4 -> Africa_Other | F3: ='TRA balance'!G4 -> Australia | G3: ='TRA balance'!H4 -> Austria | H3: ='TRA balance'!I4 -> Baltics | I3: ='TRA balance'!J4 -> BeNeLux | J3: ='TRA balance'!K4 -> Brazil | K3: ='TRA balance'!L4 -> China | ... AW3: ='TRA balance'!AX4 -> \I: | AX3: * | AY3: attribute | AZ3: process | BA3: comm-out | BB3: LIFE | BD3: Sets | BE3: TechName | BF3: TechDesc | BG3: Tact | BH3: Tcap | BI3: Vintage
A4: TR | C4: TRABDS | D4: {=SUM(SUMIFS(Assumptions!BD$3:BD$102,Assumptions!$B$3:$B$102,'3-w'!$C4,Assumptions!$G$3:$G$102,{"TRE"}))} -> 0 | E4: {=SUM(SUMIFS(Assumptions!BE$3:BE$102,Assumptions!$B$3:$B$102,'3-w'!$C4,Assumptions!$G$3:$G$102,{"TRE"}))} -> 0 | F4: {=SUM(SUMIFS(Assumptions!BF$3:BF$102,Assumptions!$B$3:$B$102,'3-w'!$C4,Assumptions!$G$3:$G$102,{"TRE"}))} -> 0 | G4: {=SUM(SUMIFS(Assumptions!BG$3:BG$102,Assumptions!$B$3:$B$102,'3-w'!$C4,Assumptions!$G$3:$G$102,{"TRE"}))} -> 0 | H4: {=SUM(SUMIFS(Assumptions!BH$3:BH$102,Assumptions!$B$3:$B$102,'3-w'!$C4,Assumptions!$G$3:$G$102,{"TRE"}))} -> 0 | I4: {=SUM(SUMIFS(Assumptions!BI$3:BI$102,Assumptions!$B$3:$B$102,'3-w'!$C4,Assumptions!$G$3:$G$102,{"TRE"}))} -> 0 | J4: {=SUM(SUMIFS(Assumptions!BJ$3:BJ$102,Assumptions!$B$3:$B$102,'3-w'!$C4,Assumptions!$G$3:$G$102,{"TRE"}))} -> 0.45572095 | K4: {=SUM(SUMIFS(Assumptions!BK$3:BK$102,Assumptions!$B$3:$B$102,'3-w'!$C4,Assumptions!$G$3:$G$102,{"TRE"}))} -> 2.27424 | ... AW4: {=SUM(SUMIFS(Assumptions!CW$3:CW$102,Assumptions!$B$3:$B$102,'3-w'!$C4,Assumptions!$G$3:$G$102,{"TRE"}))} -> 0 | AX4: =IF(SUM(D4:AW4)=0,"zero","") | AY4: * | BA4: =IF($AZ4="","",$BA$45) | BB4: =IF($AZ4="","",25) | BD4: =IF($AZ4="","*","DMD") -> * | BE4: =AZ4 -> 0 | BG4: Bvkm | BH4: million Vehicles | BI4: yes
A5: TR | C5: TRABGS | D5: {=SUM(SUMIFS(Assumptions!BD$3:BD$102,Assumptions!$B$3:$B$102,'3-w'!$C5,Assumptions!$G$3:$G$102,{"TRE"}))} -> 0 | E5: {=SUM(SUMIFS(Assumptions!BE$3:BE$102,Assumptions!$B$3:$B$102,'3-w'!$C5,Assumptions!$G$3:$G$102,{"TRE"}))} -> 0 | F5: {=SUM(SUMIFS(Assumptions!BF$3:BF$102,Assumptions!$B$3:$B$102,'3-w'!$C5,Assumptions!$G$3:$G$102,{"TRE"}))} -> 0 | G5: {=SUM(SUMIFS(Assumptions!BG$3:BG$102,Assumptions!$B$3:$B$102,'3-w'!$C5,Assumptions!$G$3:$G$102,{"TRE"}))} -> 0 | H5: {=SUM(SUMIFS(Assumptions!BH$3:BH$102,Assumptions!$B$3:$B$102,'3-w'!$C5,Assumptions!$G$3:$G$102,{"TRE"}))} -> 0 | I5: {=SUM(SUMIFS(Assumptions!BI$3:BI$102,Assumptions!$B$3:$B$102,'3-w'!$C5,Assumptions!$G$3:$G$102,{"TRE"}))} -> 0 | J5: {=SUM(SUMIFS(Assumptions!BJ$3:BJ$102,Assumptions!$B$3:$B$102,'3-w'!$C5,Assumptions!$G$3:$G$102,{"TRE"}))} -> 0 | K5: {=SUM(SUMIFS(Assumptions!BK$3:BK$102,Assumptions!$B$3:$B$102,'3-w'!$C5,Assumptions!$G$3:$G$102,{"TRE"}))} -> 0 | ... AW5: {=SUM(SUMIFS(Assumptions!CW$3:CW$102,Assumptions!$B$3:$B$102,'3-w'!$C5,Assumptions!$G$3:$G$102,{"TRE"}))} -> 0 | AX5: =IF(SUM(D5:AW5)=0,"zero","") -> zero | AY5: * | BA5: =IF($AZ5="","",$BA$45) | BB5: =IF($AZ5="","",25) | BD5: =IF(AZ5="","*","DMD") -> * | BE5: =AZ5 -> 0 | BG5: Bvkm | BH5: million Vehicles | BI5: yes
A6: TR | C6: TRADST | D6: {=SUM(SUMIFS(Assumptions!BD$3:BD$102,Assumptions!$B$3:$B$102,'3-w'!$C6,Assumptions!$G$3:$G$102,{"TRE"}))} -> 0 | E6: {=SUM(SUMIFS(Assumptions!BE$3:BE$102,Assumptions!$B$3:$B$102,'3-w'!$C6,Assumptions!$G$3:$G$102,{"TRE"}))} -> 0 | F6: {=SUM(SUMIFS(Assumptions!BF$3:BF$102,Assumptions!$B$3:$B$102,'3-w'!$C6,Assumptions!$G$3:$G$102,{"TRE"}))} -> 0 | G6: {=SUM(SUMIFS(Assumptions!BG$3:BG$102,Assumptions!$B$3:$B$102,'3-w'!$C6,Assumptions!$G$3:$G$102,{"TRE"}))} -> 0 | H6: {=SUM(SUMIFS(Assumptions!BH$3:BH$102,Assumptions!$B$3:$B$102,'3-w'!$C6,Assumptions!$G$3:$G$102,{"TRE"}))} -> 0 | I6: {=SUM(SUMIFS(Assumptions!BI$3:BI$102,Assumptions!$B$3:$B$102,'3-w'!$C6,Assumptions!$G$3:$G$102,{"TRE"}))} -> 0 | J6: {=SUM(SUMIFS(Assumptions!BJ$3:BJ$102,Assumptions!$B$3:$B$102,'3-w'!$C6,Assumptions!$G$3:$G$102,{"TRE"}))} -> 1.0051941 | K6: {=SUM(SUMIFS(Assumptions!BK$3:BK$102,Assumptions!$B$3:$B$102,'3-w'!$C6,Assumptions!$G$3:$G$102,{"TRE"}))} -> 232.8823 | ... AW6: {=SUM(SUMIFS(Assumptions!CW$3:CW$102,Assumptions!$B$3:$B$102,'3-w'!$C6,Assumptions!$G$3:$G$102,{"TRE"}))} -> 0 | AX6: =IF(SUM(D6:AW6)=0,"zero","") | AY6: * | BA6: =IF($AZ6="","",$BA$45) | BB6: =IF($AZ6="","",25) | BD6: =IF(AZ6="","*","DMD") -> * | BE6: =AZ6 -> 0 | BG6: Bvkm | BH6: million Vehicles | BI6: yes
A7: TR | C7: TRAELC | D7: {=SUM(SUMIFS(Assumptions!BD$3:BD$102,Assumptions!$B$3:$B$102,'3-w'!$C7,Assumptions!$G$3:$G$102,{"TRE"}))} -> 0 | E7: {=SUM(SUMIFS(Assumptions!BE$3:BE$102,Assumptions!$B$3:$B$102,'3-w'!$C7,Assumptions!$G$3:$G$102,{"TRE"}))} -> 0 | F7: {=SUM(SUMIFS(Assumptions!BF$3:BF$102,Assumptions!$B$3:$B$102,'3-w'!$C7,Assumptions!$G$3:$G$102,{"TRE"}))} -> 0 | G7: {=SUM(SUMIFS(Assumptions!BG$3:BG$102,Assumptions!$B$3:$B$102,'3-w'!$C7,Assumptions!$G$3:$G$102,{"TRE"}))} -> 0 | H7: {=SUM(SUMIFS(Assumptions!BH$3:BH$102,Assumptions!$B$3:$B$102,'3-w'!$C7,Assumptions!$G$3:$G$102,{"TRE"}))} -> 0 | I7: {=SUM(SUMIFS(Assumptions!BI$3:BI$102,Assumptions!$B$3:$B$102,'3-w'!$C7,Assumptions!$G$3:$G$102,{"TRE"}))} -> 0 | J7: {=SUM(SUMIFS(Assumptions!BJ$3:BJ$102,Assumptions!$B$3:$B$102,'3-w'!$C7,Assumptions!$G$3:$G$102,{"TRE"}))} -> 0 | K7: {=SUM(SUMIFS(Assumptions!BK$3:BK$102,Assumptions!$B$3:$B$102,'3-w'!$C7,Assumptions!$G$3:$G$102,{"TRE"}))} -> 0 | ... AW7: {=SUM(SUMIFS(Assumptions!CW$3:CW$102,Assumptions!$B$3:$B$102,'3-w'!$C7,Assumptions!$G$3:$G$102,{"TRE"}))} -> 0 | AX7: =IF(SUM(D7:AW7)=0,"zero","") -> zero | AY7: * | BA7: =IF($AZ7="","",$BA$45) | BB7: =IF($AZ7="","",25) | BD7: =IF(AZ7="","*","DMD") -> * | BE7: =AZ7 -> 0 | BG7: Bvkm | BH7: million Vehicles | BI7: yes
A8: TR | C8: TRAGSL | D8: {=SUM(SUMIFS(Assumptions!BD$3:BD$102,Assumptions!$B$3:$B$102,'3-w'!$C8,Assumptions!$G$3:$G$102,{"TRE"}))} -> 71.567029 | E8: {=SUM(SUMIFS(Assumptions!BE$3:BE$102,Assumptions!$B$3:$B$102,'3-w'!$C8,Assumptions!$G$3:$G$102,{"TRE"}))} -> 124.27522 | F8: {=SUM(SUMIFS(Assumptions!BF$3:BF$102,Assumptions!$B$3:$B$102,'3-w'!$C8,Assumptions!$G$3:$G$102,{"TRE"}))} -> 0 | G8: {=SUM(SUMIFS(Assumptions!BG$3:BG$102,Assumptions!$B$3:$B$102,'3-w'!$C8,Assumptions!$G$3:$G$102,{"TRE"}))} -> 0.33583423 | H8: {=SUM(SUMIFS(Assumptions!BH$3:BH$102,Assumptions!$B$3:$B$102,'3-w'!$C8,Assumptions!$G$3:$G$102,{"TRE"}))} -> 0.10120572 | I8: {=SUM(SUMIFS(Assumptions!BI$3:BI$102,Assumptions!$B$3:$B$102,'3-w'!$C8,Assumptions!$G$3:$G$102,{"TRE"}))} -> 1.2993734 | J8: {=SUM(SUMIFS(Assumptions!BJ$3:BJ$102,Assumptions!$B$3:$B$102,'3-w'!$C8,Assumptions!$G$3:$G$102,{"TRE"}))} -> 4.0418183 | K8: {=SUM(SUMIFS(Assumptions!BK$3:BK$102,Assumptions!$B$3:$B$102,'3-w'!$C8,Assumptions!$G$3:$G$102,{"TRE"}))} -> 0 | ... AW8: {=SUM(SUMIFS(Assumptions!CW$3:CW$102,Assumptions!$B$3:$B$102,'3-w'!$C8,Assumptions!$G$3:$G$102,{"TRE"}))} -> 0 | AX8: =IF(SUM(D8:AW8)=0,"zero","") | AY8: * | BA8: =IF($AZ8="","",$BA$45) | BB8: =IF($AZ8="","",25) | BD8: =IF(AZ8="","*","DMD") -> * | BE8: =AZ8 -> 0 | BG8: Bvkm | BH8: million Vehicles | BI8: yes
A9: TR | C9: TRALPG | D9: {=SUM(SUMIFS(Assumptions!BD$3:BD$102,Assumptions!$B$3:$B$102,'3-w'!$C9,Assumptions!$G$3:$G$102,{"TRE"}))} -> 0 | E9: {=SUM(SUMIFS(Assumptions!BE$3:BE$102,Assumptions!$B$3:$B$102,'3-w'!$C9,Assumptions!$G$3:$G$102,{"TRE"}))} -> 0 | F9: {=SUM(SUMIFS(Assumptions!BF$3:BF$102,Assumptions!$B$3:$B$102,'3-w'!$C9,Assumptions!$G$3:$G$102,{"TRE"}))} -> 0 | G9: {=SUM(SUMIFS(Assumptions!BG$3:BG$102,Assumptions!$B$3:$B$102,'3-w'!$C9,Assumptions!$G$3:$G$102,{"TRE"}))} -> 0 | H9: {=SUM(SUMIFS(Assumptions!BH$3:BH$102,Assumptions!$B$3:$B$102,'3-w'!$C9,Assumptions!$G$3:$G$102,{"TRE"}))} -> 0 | I9: {=SUM(SUMIFS(Assumptions!BI$3:BI$102,Assumptions!$B$3:$B$102,'3-w'!$C9,Assumptions!$G$3:$G$102,{"TRE"}))} -> 0 | J9: {=SUM(SUMIFS(Assumptions!BJ$3:BJ$102,Assumptions!$B$3:$B$102,'3-w'!$C9,Assumptions!$G$3:$G$102,{"TRE"}))} -> 0 | K9: {=SUM(SUMIFS(Assumptions!BK$3:BK$102,Assumptions!$B$3:$B$102,'3-w'!$C9,Assumptions!$G$3:$G$102,{"TRE"}))} -> 0 | ... AW9: {=SUM(SUMIFS(Assumptions!CW$3:CW$102,Assumptions!$B$3:$B$102,'3-w'!$C9,Assumptions!$G$3:$G$102,{"TRE"}))} -> 0 | AX9: =IF(SUM(D9:AW9)=0,"zero","") -> zero | AY9: * | BA9: =IF($AZ9="","",$BA$45) | BB9: =IF($AZ9="","",25) | BD9: =IF(AZ9="","*","DMD") -> * | BE9: =AZ9 -> 0 | BG9: Bvkm | BH9: million Vehicles | BI9: yes
A10: TR | C10: TRANGA | D10: {=SUM(SUMIFS(Assumptions!BD$3:BD$102,Assumptions!$B$3:$B$102,'3-w'!$C10,Assumptions!$G$3:$G$102,{"TRE"}))} -> 0 | E10: {=SUM(SUMIFS(Assumptions!BE$3:BE$102,Assumptions!$B$3:$B$102,'3-w'!$C10,Assumptions!$G$3:$G$102,{"TRE"}))} -> 0 | F10: {=SUM(SUMIFS(Assumptions!BF$3:BF$102,Assumptions!$B$3:$B$102,'3-w'!$C10,Assumptions!$G$3:$G$102,{"TRE"}))} -> 0 | G10: {=SUM(SUMIFS(Assumptions!BG$3:BG$102,Assumptions!$B$3:$B$102,'3-w'!$C10,Assumptions!$G$3:$G$102,{"TRE"}))} -> 0 | H10: {=SUM(SUMIFS(Assumptions!BH$3:BH$102,Assumptions!$B$3:$B$102,'3-w'!$C10,Assumptions!$G$3:$G$102,{"TRE"}))} -> 0 | I10: {=SUM(SUMIFS(Assumptions!BI$3:BI$102,Assumptions!$B$3:$B$102,'3-w'!$C10,Assumptions!$G$3:$G$102,{"TRE"}))} -> 0 | J10: {=SUM(SUMIFS(Assumptions!BJ$3:BJ$102,Assumptions!$B$3:$B$102,'3-w'!$C10,Assumptions!$G$3:$G$102,{"TRE"}))} -> 0 | K10: {=SUM(SUMIFS(Assumptions!BK$3:BK$102,Assumptions!$B$3:$B$102,'3-w'!$C10,Assumptions!$G$3:$G$102,{"TRE"}))} -> 0 | ... AW10: {=SUM(SUMIFS(Assumptions!CW$3:CW$102,Assumptions!$B$3:$B$102,'3-w'!$C10,Assumptions!$G$3:$G$102,{"TRE"}))} -> 0 | AX10: =IF(SUM(D10:AW10)=0,"zero","") -> zero | AY10: * | BA10: =IF($AZ10="","",$BA$45) | BB10: =IF($AZ10="","",25) | BD10: =IF(AZ10="","*","DMD") -> * | BE10: =AZ10 -> 0 | BG10: Bvkm | BH10: million Vehicles | BI10: yes
A11: Share of PJ | D11: =SUM(D$4:D$10)/SUM($D$4:$AJ$10) -> 0.055723378 | E11: =SUM(E$4:E$10)/SUM($D$4:$AJ$10) -> 0.096762923 | F11: =SUM(F$4:F$10)/SUM($D$4:$AJ$10) -> 0 | G11: =SUM(G$4:G$10)/SUM($D$4:$AJ$10) -> 0.00026148658 | H11: =SUM(H$4:H$10)/SUM($D$4:$AJ$10) -> 7.8800598e-05 | I11: =SUM(I$4:I$10)/SUM($D$4:$AJ$10) -> 0.0010117155 | J11: =SUM(J$4:J$10)/SUM($D$4:$AJ$10) -> 0.0042845273 | K11: =SUM(K$4:K$10)/SUM($D$4:$AJ$10) -> 0.18309711 | ... AW11: =SUM(AW$4:AW$10)/SUM($D$4:$AJ$10) -> 0 | AY11: * | BA11: =IF($AZ11="","",$BA$45) | BB11: =IF($AZ11="","",25) | BD11: =IF(AZ11="","*","DMD") -> * | BE11: =AZ11 -> 0 | BG11: Bvkm | BH11: million Vehicles | BI11: yes
AY12: * | BA12: =IF($AZ12="","",$BA$45) | BB12: =IF($AZ12="","",25) | BD12: =IF(AZ12="","*","DMD") -> * | BE12: =AZ12 -> 0 | BG12: Bvkm | BH12: million Vehicles | BI12: yes
A13: m Vehicles | C13: =SUM(D13:AJ13) -> 50.243 | D13: =SUM(D19:D25) -> 2.801 | E13: =SUM(E19:E25) -> 4.863 | F13: =SUM(F19:F25) -> 0 | G13: =SUM(G19:G25) -> 0.013 | H13: =SUM(H19:H25) -> 0.004 | I13: =SUM(I19:I25) -> 0.051 | J13: =SUM(J19:J25) -> 0.215 | K13: =SUM(K19:K25) -> 9.202 | ... AW13: =SUM(AW19:AW25) -> 0 | AY13: * | BA13: =IF($AZ13="","",$BA$45) | BB13: =IF($AZ13="","",25) | BD13: =IF(AZ13="","*","DMD") -> * | BE13: =AZ13 -> 0 | BG13: Bvkm | BH13: million Vehicles | BI13: yes
A14: Share of Veh | D14: =D13/SUM($D$13:$AJ$13) -> 0.05574906 | E14: =E13/SUM($D$13:$AJ$13) -> 0.096789603 | F14: =F13/SUM($D$13:$AJ$13) -> 0 | G14: =G13/SUM($D$13:$AJ$13) -> 0.00025874251 | H14: =H13/SUM($D$13:$AJ$13) -> 7.961308e-05 | I14: =I13/SUM($D$13:$AJ$13) -> 0.0010150668 | J14: =J13/SUM($D$13:$AJ$13) -> 0.0042792031 | K14: =K13/SUM($D$13:$AJ$13) -> 0.18314989 | ... AW14: =AW13/SUM($D$13:$AJ$13) -> 0 | AY14: * | BA14: =IF($AZ14="","",$BA$45) | BB14: =IF($AZ14="","",25) | BD14: =IF(AZ14="","*","DMD") -> * | BE14: =AZ14 -> 0 | BG14: Bvkm | BH14: million Vehicles | BI14: yes
AY15: * | BA15: =IF($AZ15="","",$BA$45) | BB15: =IF($AZ15="","",25) | BD15: =IF(AZ15="","*","DMD") -> * | BE15: =AZ15 -> 0 | BG15: Bvkm | BH15: million Vehicles | BI15: yes
AY16: * | BA16: =IF($AZ16="","",$BA$45) | BB16: =IF($AZ16="","",25) | BD16: =IF(AZ16="","*","DMD") -> * | BE16: =AZ16 -> 0 | BG16: Bvkm | BH16: million Vehicles | BI16: yes
A17: PJ share/Veh share | D17: =IFERROR(D11/D14,"") -> 0.99953934 | E17: =IFERROR(E11/E14,"") -> 0.99972435 | F17: =IFERROR(F11/F14,"") | G17: =IFERROR(G11/G14,"") -> 1.0106054 | H17: =IFERROR(H11/H14,"") -> 0.98979461 | I17: =IFERROR(I11/I14,"") -> 0.99669849 | J17: =IFERROR(J11/J14,"") -> 1.0012442 | K17: =IFERROR(K11/K14,"") -> 0.99971184 | ... AW17: =IFERROR(AW11/AW14,"") | AY17: * | BA17: =IF($AZ17="","",$BA$45) | BB17: =IF($AZ17="","",25) | BD17: =IF(AZ17="","*","DMD") -> * | BE17: =AZ17 -> 0 | BG17: Bvkm | BH17: million Vehicles | BI17: yes
AY18: * | BA18: =IF($AZ18="","",$BA$45) | BB18: =IF($AZ18="","",25) | BD18: =IF(AZ18="","*","DMD") -> * | BE18: =AZ18 -> 0 | BG18: Bvkm | BH18: million Vehicles | BI18: yes
A19: mVeh | C19: =C4 -> TRABDS | D19: =ROUND(D4*D28/D36,3) -> 0 | E19: =ROUND(E4*E28/E36,3) -> 0 | F19: =ROUND(F4*F28/F36,3) -> 0 | G19: =ROUND(G4*G28/G36,3) -> 0 | H19: =ROUND(H4*H28/H36,3) -> 0 | I19: =ROUND(I4*I28/I36,3) -> 0 | J19: =ROUND(J4*J28/J36,3) -> 0.018 | K19: =ROUND(K4*K28/K36,3) -> 0.089 | ... AW19: =ROUND(AW4*AW28/AW36,3) -> 0 | AY19: PASTI | AZ19: =IF(AX4="zero","\I:",$BA$45&"_"&VLOOKUP(C19,'TRA balance'!$BB$5:$BC$15,2,FALSE)) -> Trd_3w_bdl | BA19: =IF($AZ19="","",$BA$45) -> Trd_3w | BB19: =IF($AZ19="","",25) -> 25 | BD19: =IF(AZ19="","*","DMD") -> DMD | BE19: =AZ19 -> Trd_3w_bdl | BG19: Bvkm | BH19: million Vehicles | BI19: yes
C20: =C5 -> TRABGS | D20: =ROUND(D5*D29/D37,3) -> 0 | E20: =ROUND(E5*E29/E37,3) -> 0 | F20: =ROUND(F5*F29/F37,3) -> 0 | G20: =ROUND(G5*G29/G37,3) -> 0 | H20: =ROUND(H5*H29/H37,3) -> 0 | I20: =ROUND(I5*I29/I37,3) -> 0 | J20: =ROUND(J5*J29/J37,3) -> 0 | K20: =ROUND(K5*K29/K37,3) -> 0 | ... AW20: =ROUND(AW5*AW29/AW37,3) -> 0 | AY20: PASTI | AZ20: =IF(AX5="zero","\I:",$BA$45&"_"&VLOOKUP(C20,'TRA balance'!$BB$5:$BC$15,2,FALSE)) -> \I: | BA20: =IF($AZ20="","",$BA$45) -> Trd_3w | BB20: =IF($AZ20="","",25) -> 25 | BD20: =IF(AZ20="","*","DMD") -> DMD | BE20: =AZ20 -> \I: | BG20: Bvkm | BH20: million Vehicles | BI20: yes
C21: =C6 -> TRADST | D21: =ROUND(D6*D30/D38,3) -> 0 | E21: =ROUND(E6*E30/E38,3) -> 0 | F21: =ROUND(F6*F30/F38,3) -> 0 | G21: =ROUND(G6*G30/G38,3) -> 0 | H21: =ROUND(H6*H30/H38,3) -> 0 | I21: =ROUND(I6*I30/I38,3) -> 0 | J21: =ROUND(J6*J30/J38,3) -> 0.039 | K21: =ROUND(K6*K30/K38,3) -> 9.113 | ... AW21: =ROUND(AW6*AW30/AW38,3) -> 0 | AY21: PASTI | AZ21: =IF(AX6="zero","\I:",$BA$45&"_"&VLOOKUP(C21,'TRA balance'!$BB$5:$BC$15,2,FALSE)) -> Trd_3w_dsl | BA21: =IF($AZ21="","",$BA$45) -> Trd_3w | BB21: =IF($AZ21="","",25) -> 25 | BD21: =IF(AZ21="","*","DMD") -> DMD | BE21: =AZ21 -> Trd_3w_dsl | BG21: Bvkm | BH21: million Vehicles | BI21: yes
C22: =C7 -> TRAELC | D22: =ROUND(D7*D31/D39,3) -> 0 | E22: =ROUND(E7*E31/E39,3) -> 0 | F22: =ROUND(F7*F31/F39,3) -> 0 | G22: =ROUND(G7*G31/G39,3) -> 0 | H22: =ROUND(H7*H31/H39,3) -> 0 | I22: =ROUND(I7*I31/I39,3) -> 0 | J22: =ROUND(J7*J31/J39,3) -> 0 | K22: =ROUND(K7*K31/K39,3) -> 0 | ... AW22: =ROUND(AW7*AW31/AW39,3) -> 0 | AY22: PASTI | AZ22: =IF(AX7="zero","\I:",$BA$45&"_"&VLOOKUP(C22,'TRA balance'!$BB$5:$BC$15,2,FALSE)) -> \I: | BA22: =IF($AZ22="","",$BA$45) -> Trd_3w | BB22: =IF($AZ22="","",25) -> 25 | BD22: =IF(AZ22="","*","DMD") -> DMD | BE22: =AZ22 -> \I: | BG22: Bvkm | BH22: million Vehicles | BI22: yes
C23: =C8 -> TRAGSL | D23: =ROUND(D8*D32/D40,3) -> 2.801 | E23: =ROUND(E8*E32/E40,3) -> 4.863 | F23: =ROUND(F8*F32/F40,3) -> 0 | G23: =ROUND(G8*G32/G40,3) -> 0.013 | H23: =ROUND(H8*H32/H40,3) -> 0.004 | I23: =ROUND(I8*I32/I40,3) -> 0.051 | J23: =ROUND(J8*J32/J40,3) -> 0.158 | K23: =ROUND(K8*K32/K40,3) -> 0 | ... AW23: =ROUND(AW8*AW32/AW40,3) -> 0 | AY23: PASTI | AZ23: =IF(AX8="zero","\I:",$BA$45&"_"&VLOOKUP(C23,'TRA balance'!$BB$5:$BC$15,2,FALSE)) -> Trd_3w_gsl | BA23: =IF($AZ23="","",$BA$45) -> Trd_3w | BB23: =IF($AZ23="","",25) -> 25 | BD23: =IF(AZ23="","*","DMD") -> DMD | BE23: =AZ23 -> Trd_3w_gsl | BG23: Bvkm | BH23: million Vehicles | BI23: yes
C24: =C9 -> TRALPG | D24: =ROUND(D9*D33/D41,3) -> 0 | E24: =ROUND(E9*E33/E41,3) -> 0 | F24: =ROUND(F9*F33/F41,3) -> 0 | G24: =ROUND(G9*G33/G41,3) -> 0 | H24: =ROUND(H9*H33/H41,3) -> 0 | I24: =ROUND(I9*I33/I41,3) -> 0 | J24: =ROUND(J9*J33/J41,3) -> 0 | K24: =ROUND(K9*K33/K41,3) -> 0 | ... AW24: =ROUND(AW9*AW33/AW41,3) -> 0 | AY24: PASTI | AZ24: =IF(AX9="zero","\I:",$BA$45&"_"&VLOOKUP(C24,'TRA balance'!$BB$5:$BC$15,2,FALSE)) -> \I: | BA24: =IF($AZ24="","",$BA$45) -> Trd_3w | BB24: =IF($AZ24="","",25) -> 25 | BD24: =IF(AZ24="","*","DMD") -> DMD | BE24: =AZ24 -> \I: | BG24: Bvkm | BH24: million Vehicles | BI24: yes
C25: =C10 -> TRANGA | D25: =ROUND(D10*D34/D42,3) -> 0 | E25: =ROUND(E10*E34/E42,3) -> 0 | F25: =ROUND(F10*F34/F42,3) -> 0 | G25: =ROUND(G10*G34/G42,3) -> 0 | H25: =ROUND(H10*H34/H42,3) -> 0 | I25: =ROUND(I10*I34/I42,3) -> 0 | J25: =ROUND(J10*J34/J42,3) -> 0 | K25: =ROUND(K10*K34/K42,3) -> 0 | ... AW25: =ROUND(AW10*AW34/AW42,3) -> 0 | AY25: PASTI | AZ25: =IF(AX10="zero","\I:",$BA$45&"_"&VLOOKUP(C25,'TRA balance'!$BB$5:$BC$15,2,FALSE)) -> \I: | BA25: =IF($AZ25="","",$BA$45) -> Trd_3w | BB25: =IF($AZ25="","",25) -> 25 | BD25: =IF(AZ25="","*","DMD") -> DMD | BE25: =AZ25 -> \I: | BG25: Bvkm | BH25: million Vehicles | BI25: yes
AY26: * | BA26: =IF($AZ26="","",$BA$45) | BB26: =IF($AZ26="","",25) | BD26: =IF(AZ26="","*","DMD") -> * | BE26: =AZ26 -> 0 | BG26: Bvkm | BH26: million Vehicles | BI26: yes
D27: 1 | E27: 1 | F27: 1 | G27: 1 | H27: 1 | I27: 1 | J27: 1 | K27: 1 | L27: 1 | M27: 1 | N27: 1 | O27: 1 | P27: 1 | Q27: 1 | R27: 1 | S27: 1 | T27: 1 | U27: 1 | V27: 1 | W27: 1 | X27: 1 | Y27: 1 | Z27: 1 | AA27: 1 | AB27: 1 | AC27: 1 | AD27: 1 | AE27: 1 | AF27: 1 | AG27: 1 | AH27: 1 | AI27: 1 | AJ27: 1 | AK27: 1 | AL27: 1 | AM27: 1 | AN27: 1 | AO27: 1 | AP27: 1 | AQ27: 1 | AR27: 1 | AS27: 1 | AT27: 1 | AU27: 1 | AV27: 1 | AW27: 1 | AY27: * | BA27: =IF($AZ27="","",$BA$45) | BB27: =IF($AZ27="","",25) | BD27: =IF(AZ27="","*","DMD") -> * | BE27: =AZ27 -> 0 | BG27: Bvkm | BH27: million Vehicles | BI27: yes
A28: Efficiency | C28: =C19 -> TRABDS | D28: =$AX28*D$27 -> 0.58697 | E28: =$AX28*E$27 -> 0.58697 | F28: =$AX28*F$27 -> 0.58697 | G28: =$AX28*G$27 -> 0.58697 | H28: =$AX28*H$27 -> 0.58697 | I28: =$AX28*I$27 -> 0.58697 | J28: =$AX28*J$27 -> 0.58697 | K28: =$AX28*K$27 -> 0.58697 | ... AW28: =$AX28*AW$27 -> 0.58697 | AX28: 0.58697 | AY28: EFF | AZ28: =AZ19 -> Trd_3w_bdl | BA28: =IF($AZ28="","",$BA$45) -> Trd_3w | BB28: =IF($AZ28="","",25) -> 25 | BD28: =IF(AZ28="","*","DMD") -> DMD | BE28: =AZ28 -> Trd_3w_bdl | BG28: Bvkm | BH28: million Vehicles | BI28: yes
