Workbook
Name FID_1: [1]AGR_Fuels!$A$2
Name GROWTH: '[2]TechRep-Doc'!#REF!

Sheet TechSelection
A3: ~TFM_AVA
A4: Region | B4: Process
A5: Africa_North | B5: *
A6: Africa_Other | B6: *
A7: Australia | B7: *
A8: Austria | B8: *
A9: Baltics | B9: *
A10: BeNeLux | B10: *
A11: Brazil | B11: *
A12: China | B12: *
A13: CroSloven | B13: *
A14: CzechSlovak | B14: *
A15: France | B15: *
... A39: WestBalkans | B39: *

Sheet Road transport
B2: ~TFM_FILL-R:w=RoadTra_BY; hcol=region | K2: ~TFM_TOPINS | P2: ~TFM_TOPINS
B3: Scenario | C3: Attribute | D3: PSET_CO | E3: AllRegions | K3: process | L3: IO | M3: commodity | P3: pset_ci | Q3: pset_co | R3: cset_cn | S3: IO
B4: BASE | C4: AF | D4: Trd[_]* | E4: *1 | K4: Trd[_]*gsl* | L4: IN | M4: TRAGSL,TRABGS | P4: TRAELC | Q4: TRDELC | R4: ELC | S4: Out
B5: BASE | C5: EFF | D5: Trd[_]* | E5: *1 | K5: Trd[_]*dsl* | L5: IN | M5: TRADST,TRABDS
K6: Trd[_]*hh2* | L6: IN | M6: TRAGH2
K7: Trd[_]*cng* | L7: IN | M7: TRANGA
B8: ~TFM_INS | K8: Trd[_]*elc* | L8: IN | M8: TRDELC
B9: attribute | C9: PSET_PN | D9: PSET_CI | E9: CSET_CN | F9: value | G9: limtype | H9: year | K9: Trd[_]*lng* | L9: IN | M9: TRANGA
B10: Share | C10: Trd[_]*-pih* | E10: TRDELC | F10: 0.25 | G10: FX | K10: Trd[_]*-pih* | L10: IN | M10: TRDELC
B11: Share | C11: Trd[_]*-pih* | E11: TRDELC | F11: 3 | G11: FX | H11: 0
B12: CEFF | D12: TRAGSL | E12: TRABGS | F12: 0.93 | K12: ~TFM_MIG
B13: LIFE | C13: Trd[_]* | F13: 25 | K13: attribute | L13: value | M13: attribute2 | N13: pset_pn
B14: *START | C14: Trd[_]* | E14: -TRDELC | F14: 2020 | K14: INVCOST | L14: *.03 | M14: FIXOM | N14: Trd[_]*
K15: INVCOST | L15: *.02 | M15: FIXOM | N15: Trd[_]*elc*
B16: ~TFM_INS-TS: attribute=FLO_MARK
B17: pset_ci | C17: 2020 | D17: 0 | E17: attrib_cond | F17: commodity | G17: top_check
B18: -TRDELC | C18: 0.2 | D18: 3 | E18: -FLO_MARK | F18: Trd[_]* | G18: OUT
C21: ~TFM_INS
C22: attribute | D22: =IF(RoadTra_BY!L$1="","\I:",RoadTra_BY!L$1) -> valfield | E22: =IF(RoadTra_BY!M$1="","\I:",RoadTra_BY!M$1) -> \I: | F22: =IF(RoadTra_BY!N$1="","\I:",RoadTra_BY!N$1) -> \I: | G22: =IF(RoadTra_BY!O$1="","\I:",RoadTra_BY!O$1) -> \I: | H22: =IF(RoadTra_BY!P$1="","\I:",RoadTra_BY!P$1) -> \I: | I22: =IF(RoadTra_BY!Q$1="","\I:",RoadTra_BY!Q$1) -> \I: | J22: =IF(RoadTra_BY!R$1="","\I:",RoadTra_BY!R$1) -> \I: | K22: =IF(RoadTra_BY!S$1="","\I:",RoadTra_BY!S$1) -> \I: | ... AW22: =IF(RoadTra_BY!BE$1="","\I:",RoadTra_BY!BE$1) -> \I: | AX22: process
C23: AF | D23: =AVERAGEIFS(RoadTra_BY!L$2:L$999,RoadTra_BY!$B$2:$B$999,'Road transport'!$C23,RoadTra_BY!$C$2:$C$999,'Road transport'!$AX23) -> #DIV/0! | E23: =AVERAGEIFS(RoadTra_BY!M$2:M$999,RoadTra_BY!$B$2:$B$999,'Road transport'!$C23,RoadTra_BY!$C$2:$C$999,'Road transport'!$AX23) -> #DIV/0! | F23: =AVERAGEIFS(RoadTra_BY!N$2:N$999,RoadTra_BY!$B$2:$B$999,'Road transport'!$C23,RoadTra_BY!$C$2:$C$999,'Road transport'!$AX23) -> #DIV/0! | G23: =AVERAGEIFS(RoadTra_BY!O$2:O$999,RoadTra_BY!$B$2:$B$999,'Road transport'!$C23,RoadTra_BY!$C$2:$C$999,'Road transport'!$AX23) -> #DIV/0! | H23: =AVERAGEIFS(RoadTra_BY!P$2:P$999,RoadTra_BY!$B$2:$B$999,'Road transport'!$C23,RoadTra_BY!$C$2:$C$999,'Road transport'!$AX23) -> #DIV/0! | I23: =AVERAGEIFS(RoadTra_BY!Q$2:Q$999,RoadTra_BY!$B$2:$B$999,'Road transport'!$C23,RoadTra_BY!$C$2:$C$999,'Road transport'!$AX23) -> #DIV/0! | J23: =AVERAGEIFS(RoadTra_BY!R$2:R$999,RoadTra_BY!$B$2:$B$999,'Road transport'!$C23,RoadTra_BY!$C$2:$C$999,'Road transport'!$AX23) -> #DIV/0! | K23: =AVERAGEIFS(RoadTra_BY!S$2:S$999,RoadTra_BY!$B$2:$B$999,'Road transport'!$C23,RoadTra_BY!$C$2:$C$999,'Road transport'!$AX23) -> #DIV/0! | ... AW23: =AVERAGEIFS(RoadTra_BY!BE$2:BE$999,RoadTra_BY!$B$2:$B$999,'Road transport'!$C23,RoadTra_BY!$C$2:$C$999,'Road transport'!$AX23) -> #DIV/0! | AX23: Trd_2w_*
C24: AF | D24: =AVERAGEIFS(RoadTra_BY!L$2:L$999,RoadTra_BY!$B$2:$B$999,'Road transport'!$C24,RoadTra_BY!$C$2:$C$999,'Road transport'!$AX24) -> #DIV/0! | E24: =AVERAGEIFS(RoadTra_BY!M$2:M$999,RoadTra_BY!$B$2:$B$999,'Road transport'!$C24,RoadTra_BY!$C$2:$C$999,'Road transport'!$AX24) -> #DIV/0! | F24: =AVERAGEIFS(RoadTra_BY!N$2:N$999,RoadTra_BY!$B$2:$B$999,'Road transport'!$C24,RoadTra_BY!$C$2:$C$999,'Road transport'!$AX24) -> #DIV/0! | G24: =AVERAGEIFS(RoadTra_BY!O$2:O$999,RoadTra_BY!$B$2:$B$999,'Road transport'!$C24,RoadTra_BY!$C$2:$C$999,'Road transport'!$AX24) -> #DIV/0! | H24: =AVERAGEIFS(RoadTra_BY!P$2:P$999,RoadTra_BY!$B$2:$B$999,'Road transport'!$C24,RoadTra_BY!$C$2:$C$999,'Road transport'!$AX24) -> #DIV/0! | I24: =AVERAGEIFS(RoadTra_BY!Q$2:Q$999,RoadTra_BY!$B$2:$B$999,'Road transport'!$C24,RoadTra_BY!$C$2:$C$999,'Road transport'!$AX24) -> #DIV/0! | J24: =AVERAGEIFS(RoadTra_BY!R$2:R$999,RoadTra_BY!$B$2:$B$999,'Road transport'!$C24,RoadTra_BY!$C$2:$C$999,'Road transport'!$AX24) -> #DIV/0! | K24: =AVERAGEIFS(RoadTra_BY!S$2:S$999,RoadTra_BY!$B$2:$B$999,'Road transport'!$C24,RoadTra_BY!$C$2:$C$999,'Road transport'!$AX24) -> #DIV/0! | ... AW24: =AVERAGEIFS(RoadTra_BY!BE$2:BE$999,RoadTra_BY!$B$2:$B$999,'Road transport'!$C24,RoadTra_BY!$C$2:$C$999,'Road transport'!$AX24) -> #DIV/0! | AX24: Trd_3w_*
C25: AF | D25: =AVERAGEIFS(RoadTra_BY!L$2:L$999,RoadTra_BY!$B$2:$B$999,'Road transport'!$C25,RoadTra_BY!$C$2:$C$999,'Road transport'!$AX25) -> #DIV/0! | E25: =AVERAGEIFS(RoadTra_BY!M$2:M$999,RoadTra_BY!$B$2:$B$999,'Road transport'!$C25,RoadTra_BY!$C$2:$C$999,'Road transport'!$AX25) -> #DIV/0! | F25: =AVERAGEIFS(RoadTra_BY!N$2:N$999,RoadTra_BY!$B$2:$B$999,'Road transport'!$C25,RoadTra_BY!$C$2:$C$999,'Road transport'!$AX25) -> #DIV/0! | G25: =AVERAGEIFS(RoadTra_BY!O$2:O$999,RoadTra_BY!$B$2:$B$999,'Road transport'!$C25,RoadTra_BY!$C$2:$C$999,'Road transport'!$AX25) -> #DIV/0! | H25: =AVERAGEIFS(RoadTra_BY!P$2:P$999,RoadTra_BY!$B$2:$B$999,'Road transport'!$C25,RoadTra_BY!$C$2:$C$999,'Road transport'!$AX25) -> #DIV/0! | I25: =AVERAGEIFS(RoadTra_BY!Q$2:Q$999,RoadTra_BY!$B$2:$B$999,'Road transport'!$C25,RoadTra_BY!$C$2:$C$999,'Road transport'!$AX25) -> #DIV/0! | J25: =AVERAGEIFS(RoadTra_BY!R$2:R$999,RoadTra_BY!$B$2:$B$999,'Road transport'!$C25,RoadTra_BY!$C$2:$C$999,'Road transport'!$AX25) -> #DIV/0! | K25: =AVERAGEIFS(RoadTra_BY!S$2:S$999,RoadTra_BY!$B$2:$B$999,'Road transport'!$C25,RoadTra_BY!$C$2:$C$999,'Road transport'!$AX25) -> #DIV/0! | ... AW25: =AVERAGEIFS(RoadTra_BY!BE$2:BE$999,RoadTra_BY!$B$2:$B$999,'Road transport'!$C25,RoadTra_BY!$C$2:$C$999,'Road transport'!$AX25) -> #DIV/0! | AX25: Trd_bus*
C26: AF | D26: =AVERAGEIFS(RoadTra_BY!L$2:L$999,RoadTra_BY!$B$2:$B$999,'Road transport'!$C26,RoadTra_BY!$C$2:$C$999,'Road transport'!$AX26) -> #DIV/0! | E26: =AVERAGEIFS(RoadTra_BY!M$2:M$999,RoadTra_BY!$B$2:$B$999,'Road transport'!$C26,RoadTra_BY!$C$2:$C$999,'Road transport'!$AX26) -> #DIV/0! | F26: =AVERAGEIFS(RoadTra_BY!N$2:N$999,RoadTra_BY!$B$2:$B$999,'Road transport'!$C26,RoadTra_BY!$C$2:$C$999,'Road transport'!$AX26) -> #DIV/0! | G26: =AVERAGEIFS(RoadTra_BY!O$2:O$999,RoadTra_BY!$B$2:$B$999,'Road transport'!$C26,RoadTra_BY!$C$2:$C$999,'Road transport'!$AX26) -> #DIV/0! | H26: =AVERAGEIFS(RoadTra_BY!P$2:P$999,RoadTra_BY!$B$2:$B$999,'Road transport'!$C26,RoadTra_BY!$C$2:$C$999,'Road transport'!$AX26) -> #DIV/0! | I26: =AVERAGEIFS(RoadTra_BY!Q$2:Q$999,RoadTra_BY!$B$2:$B$999,'Road transport'!$C26,RoadTra_BY!$C$2:$C$999,'Road transport'!$AX26) -> #DIV/0! | J26: =AVERAGEIFS(RoadTra_BY!R$2:R$999,RoadTra_BY!$B$2:$B$999,'Road transport'!$C26,RoadTra_BY!$C$2:$C$999,'Road transport'!$AX26) -> #DIV/0! | K26: =AVERAGEIFS(RoadTra_BY!S$2:S$999,RoadTra_BY!$B$2:$B$999,'Road transport'!$C26,RoadTra_BY!$C$2:$C$999,'Road transport'!$AX26) -> #DIV/0! | ... AW26: =AVERAGEIFS(RoadTra_BY!BE$2:BE$999,RoadTra_BY!$B$2:$B$999,'Road transport'!$C26,RoadTra_BY!$C$2:$C$999,'Road transport'!$AX26) -> #DIV/0! | AX26: Trd_car*
C27: AF | D27: =AVERAGEIFS(RoadTra_BY!L$2:L$999,RoadTra_BY!$B$2:$B$999,'Road transport'!$C27,RoadTra_BY!$C$2:$C$999,'Road transport'!$AX27) -> #DIV/0! | E27: =AVERAGEIFS(RoadTra_BY!M$2:M$999,RoadTra_BY!$B$2:$B$999,'Road transport'!$C27,RoadTra_BY!$C$2:$C$999,'Road transport'!$AX27) -> #DIV/0! | F27: =AVERAGEIFS(RoadTra_BY!N$2:N$999,RoadTra_BY!$B$2:$B$999,'Road transport'!$C27,RoadTra_BY!$C$2:$C$999,'Road transport'!$AX27) -> #DIV/0! | G27: =AVERAGEIFS(RoadTra_BY!O$2:O$999,RoadTra_BY!$B$2:$B$999,'Road transport'!$C27,RoadTra_BY!$C$2:$C$999,'Road transport'!$AX27) -> #DIV/0! | H27: =AVERAGEIFS(RoadTra_BY!P$2:P$999,RoadTra_BY!$B$2:$B$999,'Road transport'!$C27,RoadTra_BY!$C$2:$C$999,'Road transport'!$AX27) -> #DIV/0! | I27: =AVERAGEIFS(RoadTra_BY!Q$2:Q$999,RoadTra_BY!$B$2:$B$999,'Road transport'!$C27,RoadTra_BY!$C$2:$C$999,'Road transport'!$AX27) -> #DIV/0! | J27: =AVERAGEIFS(RoadTra_BY!R$2:R$999,RoadTra_BY!$B$2:$B$999,'Road transport'!$C27,RoadTra_BY!$C$2:$C$999,'Road transport'!$AX27) -> #DIV/0! | K27: =AVERAGEIFS(RoadTra_BY!S$2:S$999,RoadTra_BY!$B$2:$B$999,'Road transport'!$C27,RoadTra_BY!$C$2:$C$999,'Road transport'!$AX27) -> #DIV/0! | ... AW27: =AVERAGEIFS(RoadTra_BY!BE$2:BE$999,RoadTra_BY!$B$2:$B$999,'Road transport'!$C27,RoadTra_BY!$C$2:$C$999,'Road transport'!$AX27) -> #DIV/0! | AX27: Trd_hdt*
C28: AF | D28: =AVERAGEIFS(RoadTra_BY!L$2:L$999,RoadTra_BY!$B$2:$B$999,'Road transport'!$C28,RoadTra_BY!$C$2:$C$999,'Road transport'!$AX28) -> #DIV/0! | E28: =AVERAGEIFS(RoadTra_BY!M$2:M$999,RoadTra_BY!$B$2:$B$999,'Road transport'!$C28,RoadTra_BY!$C$2:$C$999,'Road transport'!$AX28) -> #DIV/0! | F28: =AVERAGEIFS(RoadTra_BY!N$2:N$999,RoadTra_BY!$B$2:$B$999,'Road transport'!$C28,RoadTra_BY!$C$2:$C$999,'Road transport'!$AX28) -> #DIV/0! | G28: =AVERAGEIFS(RoadTra_BY!O$2:O$999,RoadTra_BY!$B$2:$B$999,'Road transport'!$C28,RoadTra_BY!$C$2:$C$999,'Road transport'!$AX28) -> #DIV/0! | H28: =AVERAGEIFS(RoadTra_BY!P$2:P$999,RoadTra_BY!$B$2:$B$999,'Road transport'!$C28,RoadTra_BY!$C$2:$C$999,'Road transport'!$AX28) -> #DIV/0! | I28: =AVERAGEIFS(RoadTra_BY!Q$2:Q$999,RoadTra_BY!$B$2:$B$999,'Road transport'!$C28,RoadTra_BY!$C$2:$C$999,'Road transport'!$AX28) -> #DIV/0! | J28: =AVERAGEIFS(RoadTra_BY!R$2:R$999,RoadTra_BY!$B$2:$B$999,'Road transport'!$C28,RoadTra_BY!$C$2:$C$999,'Road transport'!$AX28) -> #DIV/0! | K28: =AVERAGEIFS(RoadTra_BY!S$2:S$999,RoadTra_BY!$B$2:$B$999,'Road transport'!$C28,RoadTra_BY!$C$2:$C$999,'Road transport'!$AX28) -> #DIV/0! | ... AW28: =AVERAGEIFS(RoadTra_BY!BE$2:BE$999,RoadTra_BY!$B$2:$B$999,'Road transport'!$C28,RoadTra_BY!$C$2:$C$999,'Road transport'!$AX28) -> #DIV/0! | AX28: Trd_lcv*
C31: ~TFM_UPD
C32: attribute | D32: =IF(RoadTra_BY!L$1="","\I:",RoadTra_BY!L$1) -> valfield | E32: =IF(RoadTra_BY!M$1="","\I:",RoadTra_BY!M$1) -> \I: | F32: =IF(RoadTra_BY!N$1="","\I:",RoadTra_BY!N$1) -> \I: | G32: =IF(RoadTra_BY!O$1="","\I:",RoadTra_BY!O$1) -> \I: | H32: =IF(RoadTra_BY!P$1="","\I:",RoadTra_BY!P$1) -> \I: | I32: =IF(RoadTra_BY!Q$1="","\I:",RoadTra_BY!Q$1) -> \I: | J32: =IF(RoadTra_BY!R$1="","\I:",RoadTra_BY!R$1) -> \I: | K32: =IF(RoadTra_BY!S$1="","\I:",RoadTra_BY!S$1) -> \I: | ... AW32: =IF(RoadTra_BY!BE$1="","\I:",RoadTra_BY!BE$1) -> \I: | AX32: process
C33: EFF | D33: ="*"&ROUND(SUMIFS(RoadTra_BY!L$2:L$79,RoadTra_BY!$B$2:$B$79,'Road transport'!$C33,RoadTra_BY!$C$2:$C$79,'Road transport'!$BA33),3) -> *0 | E33: ="*"&ROUND(SUMIFS(RoadTra_BY!M$2:M$79,RoadTra_BY!$B$2:$B$79,'Road transport'!$C33,RoadTra_BY!$C$2:$C$79,'Road transport'!$BA33),3) -> *0 | F33: ="*"&ROUND(SUMIFS(RoadTra_BY!N$2:N$79,RoadTra_BY!$B$2:$B$79,'Road transport'!$C33,RoadTra_BY!$C$2:$C$79,'Road transport'!$BA33),3) -> *0 | G33: ="*"&ROUND(SUMIFS(RoadTra_BY!O$2:O$79,RoadTra_BY!$B$2:$B$79,'Road transport'!$C33,RoadTra_BY!$C$2:$C$79,'Road transport'!$BA33),3) -> *0 | H33: ="*"&ROUND(SUMIFS(RoadTra_BY!P$2:P$79,RoadTra_BY!$B$2:$B$79,'Road transport'!$C33,RoadTra_BY!$C$2:$C$79,'Road transport'!$BA33),3) -> *0 | I33: ="*"&ROUND(SUMIFS(RoadTra_BY!Q$2:Q$79,RoadTra_BY!$B$2:$B$79,'Road transport'!$C33,RoadTra_BY!$C$2:$C$79,'Road transport'!$BA33),3) -> *0 | J33: ="*"&ROUND(SUMIFS(RoadTra_BY!R$2:R$79,RoadTra_BY!$B$2:$B$79,'Road transport'!$C33,RoadTra_BY!$C$2:$C$79,'Road transport'!$BA33),3) -> *0 | K33: ="*"&ROUND(SUMIFS(RoadTra_BY!S$2:S$79,RoadTra_BY!$B$2:$B$79,'Road transport'!$C33,RoadTra_BY!$C$2:$C$79,'Road transport'!$BA33),3) -> *0 | ... AW33: ="*"&ROUND(SUMIFS(RoadTra_BY!BE$2:BE$79,RoadTra_BY!$B$2:$B$79,'Road transport'!$C33,RoadTra_BY!$C$2:$C$79,'Road transport'!$BA33),3) -> *0 | AX33: =SUBSTITUTE(SUBSTITUTE(BA33,"gsl",""),"dsl","")&"*" -> Trd_2w_* | AZ33: =IFERROR(IF(FIND("gsl",BA33)>0,1,0),2) -> 1 | BA33: Trd_2w_gsl
C34: EFF | D34: ="*"&ROUND(SUMIFS(RoadTra_BY!L$2:L$79,RoadTra_BY!$B$2:$B$79,'Road transport'!$C34,RoadTra_BY!$C$2:$C$79,'Road transport'!$BA34),3) -> *0 | E34: ="*"&ROUND(SUMIFS(RoadTra_BY!M$2:M$79,RoadTra_BY!$B$2:$B$79,'Road transport'!$C34,RoadTra_BY!$C$2:$C$79,'Road transport'!$BA34),3) -> *0 | F34: ="*"&ROUND(SUMIFS(RoadTra_BY!N$2:N$79,RoadTra_BY!$B$2:$B$79,'Road transport'!$C34,RoadTra_BY!$C$2:$C$79,'Road transport'!$BA34),3) -> *0 | G34: ="*"&ROUND(SUMIFS(RoadTra_BY!O$2:O$79,RoadTra_BY!$B$2:$B$79,'Road transport'!$C34,RoadTra_BY!$C$2:$C$79,'Road transport'!$BA34),3) -> *0 | H34: ="*"&ROUND(SUMIFS(RoadTra_BY!P$2:P$79,RoadTra_BY!$B$2:$B$79,'Road transport'!$C34,RoadTra_BY!$C$2:$C$79,'Road transport'!$BA34),3) -> *0 | I34: ="*"&ROUND(SUMIFS(RoadTra_BY!Q$2:Q$79,RoadTra_BY!$B$2:$B$79,'Road transport'!$C34,RoadTra_BY!$C$2:$C$79,'Road transport'!$BA34),3) -> *0 | J34: ="*"&ROUND(SUMIFS(RoadTra_BY!R$2:R$79,RoadTra_BY!$B$2:$B$79,'Road transport'!$C34,RoadTra_BY!$C$2:$C$79,'Road transport'!$BA34),3) -> *0 | K34: ="*"&ROUND(SUMIFS(RoadTra_BY!S$2:S$79,RoadTra_BY!$B$2:$B$79,'Road transport'!$C34,RoadTra_BY!$C$2:$C$79,'Road transport'!$BA34),3) -> *0 | ... AW34: ="*"&ROUND(SUMIFS(RoadTra_BY!BE$2:BE$79,RoadTra_BY!$B$2:$B$79,'Road transport'!$C34,RoadTra_BY!$C$2:$C$79,'Road transport'!$BA34),3) -> *0 | AX34: =SUBSTITUTE(SUBSTITUTE(BA34,"gsl",""),"dsl","")&"*" -> Trd_3w_* | AZ34: =IFERROR(IF(FIND("gsl",BA34)>0,1,0),2) -> 1 | BA34: Trd_3w_gsl
C35: EFF | D35: ="*"&ROUND(SUMIFS(RoadTra_BY!L$2:L$79,RoadTra_BY!$B$2:$B$79,'Road transport'!$C35,RoadTra_BY!$C$2:$C$79,'Road transport'!$BA35),3) -> *0 | E35: ="*"&ROUND(SUMIFS(RoadTra_BY!M$2:M$79,RoadTra_BY!$B$2:$B$79,'Road transport'!$C35,RoadTra_BY!$C$2:$C$79,'Road transport'!$BA35),3) -> *0 | F35: ="*"&ROUND(SUMIFS(RoadTra_BY!N$2:N$79,RoadTra_BY!$B$2:$B$79,'Road transport'!$C35,RoadTra_BY!$C$2:$C$79,'Road transport'!$BA35),3) -> *0 | G35: ="*"&ROUND(SUMIFS(RoadTra_BY!O$2:O$79,RoadTra_BY!$B$2:$B$79,'Road transport'!$C35,RoadTra_BY!$C$2:$C$79,'Road transport'!$BA35),3) -> *0 | H35: ="*"&ROUND(SUMIFS(RoadTra_BY!P$2:P$79,RoadTra_BY!$B$2:$B$79,'Road transport'!$C35,RoadTra_BY!$C$2:$C$79,'Road transport'!$BA35),3) -> *0 | I35: ="*"&ROUND(SUMIFS(RoadTra_BY!Q$2:Q$79,RoadTra_BY!$B$2:$B$79,'Road transport'!$C35,RoadTra_BY!$C$2:$C$79,'Road transport'!$BA35),3) -> *0 | J35: ="*"&ROUND(SUMIFS(RoadTra_BY!R$2:R$79,RoadTra_BY!$B$2:$B$79,'Road transport'!$C35,RoadTra_BY!$C$2:$C$79,'Road transport'!$BA35),3) -> *0 | K35: ="*"&ROUND(SUMIFS(RoadTra_BY!S$2:S$79,RoadTra_BY!$B$2:$B$79,'Road transport'!$C35,RoadTra_BY!$C$2:$C$79,'Road transport'!$BA35),3) -> *0 | ... AW35: ="*"&ROUND(SUMIFS(RoadTra_BY!BE$2:BE$79,RoadTra_BY!$B$2:$B$79,'Road transport'!$C35,RoadTra_BY!$C$2:$C$79,'Road transport'!$BA35),3) -> *0 | AX35: =SUBSTITUTE(SUBSTITUTE(BA35,"gsl",""),"dsl","")&"*" -> Trd_bus_* | AZ35: =IFERROR(IF(FIND("gsl",BA35)>0,1,0),2) -> 2 | BA35: Trd_bus_dsl
C36: EFF | D36: ="*"&ROUND(SUMIFS(RoadTra_BY!L$2:L$79,RoadTra_BY!$B$2:$B$79,'Road transport'!$C36,RoadTra_BY!$C$2:$C$79,'Road transport'!$BA36),3) -> *0 | E36: ="*"&ROUND(SUMIFS(RoadTra_BY!M$2:M$79,RoadTra_BY!$B$2:$B$79,'Road transport'!$C36,RoadTra_BY!$C$2:$C$79,'Road transport'!$BA36),3) -> *0 | F36: ="*"&ROUND(SUMIFS(RoadTra_BY!N$2:N$79,RoadTra_BY!$B$2:$B$79,'Road transport'!$C36,RoadTra_BY!$C$2:$C$79,'Road transport'!$BA36),3) -> *0 | G36: ="*"&ROUND(SUMIFS(RoadTra_BY!O$2:O$79,RoadTra_BY!$B$2:$B$79,'Road transport'!$C36,RoadTra_BY!$C$2:$C$79,'Road transport'!$BA36),3) -> *0 | H36: ="*"&ROUND(SUMIFS(RoadTra_BY!P$2:P$79,RoadTra_BY!$B$2:$B$79,'Road transport'!$C36,RoadTra_BY!$C$2:$C$79,'Road transport'!$BA36),3) -> *0 | I36: ="*"&ROUND(SUMIFS(RoadTra_BY!Q$2:Q$79,RoadTra_BY!$B$2:$B$79,'Road transport'!$C36,RoadTra_BY!$C$2:$C$79,'Road transport'!$BA36),3) -> *0 | J36: ="*"&ROUND(SUMIFS(RoadTra_BY!R$2:R$79,RoadTra_BY!$B$2:$B$79,'Road transport'!$C36,RoadTra_BY!$C$2:$C$79,'Road transport'!$BA36),3) -> *0 | K36: ="*"&ROUND(SUMIFS(RoadTra_BY!S$2:S$79,RoadTra_BY!$B$2:$B$79,'Road transport'!$C36,RoadTra_BY!$C$2:$C$79,'Road transport'!$BA36),3) -> *0 | ... AW36: ="*"&ROUND(SUMIFS(RoadTra_BY!BE$2:BE$79,RoadTra_BY!$B$2:$B$79,'Road transport'!$C36,RoadTra_BY!$C$2:$C$79,'Road transport'!$BA36),3) -> *0 | AX36: =SUBSTITUTE(SUBSTITUTE(BA36,"gsl",""),"dsl","")&"*" -> Trd_car_* | AZ36: =IFERROR(IF(FIND("gsl",BA36)>0,1,0),2) -> 1 | BA36: Trd_car_gsl
C37: EFF | D37: ="*"&ROUND(SUMIFS(RoadTra_BY!L$2:L$79,RoadTra_BY!$B$2:$B$79,'Road transport'!$C37,RoadTra_BY!$C$2:$C$79,'Road transport'!$BA37),3) -> *0 | E37: ="*"&ROUND(SUMIFS(RoadTra_BY!M$2:M$79,RoadTra_BY!$B$2:$B$79,'Road transport'!$C37,RoadTra_BY!$C$2:$C$79,'Road transport'!$BA37),3) -> *0 | F37: ="*"&ROUND(SUMIFS(RoadTra_BY!N$2:N$79,RoadTra_BY!$B$2:$B$79,'Road transport'!$C37,RoadTra_BY!$C$2:$C$79,'Road transport'!$BA37),3) -> *0 | G37: ="*"&ROUND(SUMIFS(RoadTra_BY!O$2:O$79,RoadTra_BY!$B$2:$B$79,'Road transport'!$C37,RoadTra_BY!$C$2:$C$79,'Road transport'!$BA37),3) -> *0 | H37: ="*"&ROUND(SUMIFS(RoadTra_BY!P$2:P$79,RoadTra_BY!$B$2:$B$79,'Road transport'!$C37,RoadTra_BY!$C$2:$C$79,'Road transport'!$BA37),3) -> *0 | I37: ="*"&ROUND(SUMIFS(RoadTra_BY!Q$2:Q$79,RoadTra_BY!$B$2:$B$79,'Road transport'!$C37,RoadTra_BY!$C$2:$C$79,'Road transport'!$BA37),3) -> *0 | J37: ="*"&ROUND(SUMIFS(RoadTra_BY!R$2:R$79,RoadTra_BY!$B$2:$B$79,'Road transport'!$C37,RoadTra_BY!$C$2:$C$79,'Road transport'!$BA37),3) -> *0 | K37: ="*"&ROUND(SUMIFS(RoadTra_BY!S$2:S$79,RoadTra_BY!$B$2:$B$79,'Road transport'!$C37,RoadTra_BY!$C$2:$C$79,'Road transport'!$BA37),3) -> *0 | ... AW37: ="*"&ROUND(SUMIFS(RoadTra_BY!BE$2:BE$79,RoadTra_BY!$B$2:$B$79,'Road transport'!$C37,RoadTra_BY!$C$2:$C$79,'Road transport'!$BA37),3) -> *0 | AX37: =SUBSTITUTE(SUBSTITUTE(BA37,"gsl",""),"dsl","")&"*" -> Trd_hdt_* | AZ37: =IFERROR(IF(FIND("gsl",BA37)>0,1,0),2) -> 2 | BA37: Trd_hdt_dsl
C38: EFF | D38: ="*"&ROUND(SUMIFS(RoadTra_BY!L$2:L$79,RoadTra_BY!$B$2:$B$79,'Road transport'!$C38,RoadTra_BY!$C$2:$C$79,'Road transport'!$BA38),3) -> *0 | E38: ="*"&ROUND(SUMIFS(RoadTra_BY!M$2:M$79,RoadTra_BY!$B$2:$B$79,'Road transport'!$C38,RoadTra_BY!$C$2:$C$79,'Road transport'!$BA38),3) -> *0 | F38: ="*"&ROUND(SUMIFS(RoadTra_BY!N$2:N$79,RoadTra_BY!$B$2:$B$79,'Road transport'!$C38,RoadTra_BY!$C$2:$C$79,'Road transport'!$BA38),3) -> *0 | G38: ="*"&ROUND(SUMIFS(RoadTra_BY!O$2:O$79,RoadTra_BY!$B$2:$B$79,'Road transport'!$C38,RoadTra_BY!$C$2:$C$79,'Road transport'!$BA38),3) -> *0 | H38: ="*"&ROUND(SUMIFS(RoadTra_BY!P$2:P$79,RoadTra_BY!$B$2:$B$79,'Road transport'!$C38,RoadTra_BY!$C$2:$C$79,'Road transport'!$BA38),3) -> *0 | I38: ="*"&ROUND(SUMIFS(RoadTra_BY!Q$2:Q$79,RoadTra_BY!$B$2:$B$79,'Road transport'!$C38,RoadTra_BY!$C$2:$C$79,'Road transport'!$BA38),3) -> *0 | J38: ="*"&ROUND(SUMIFS(RoadTra_BY!R$2:R$79,RoadTra_BY!$B$2:$B$79,'Road transport'!$C38,RoadTra_BY!$C$2:$C$79,'Road transport'!$BA38),3) -> *0 | K38: ="*"&ROUND(SUMIFS(RoadTra_BY!S$2:S$79,RoadTra_BY!$B$2:$B$79,'Road transport'!$C38,RoadTra_BY!$C$2:$C$79,'Road transport'!$BA38),3) -> *0 | ... AW38: ="*"&ROUND(SUMIFS(RoadTra_BY!BE$2:BE$79,RoadTra_BY!$B$2:$B$79,'Road transport'!$C38,RoadTra_BY!$C$2:$C$79,'Road transport'!$BA38),3) -> *0 | AX38: =SUBSTITUTE(SUBSTITUTE(BA38,"gsl",""),"dsl","")&"*" -> Trd_lcv_* | AZ38: =IFERROR(IF(FIND("gsl",BA38)>0,1,0),2) -> 2 | BA38: Trd_lcv_dsl
B48: ~TFM_UPD
B49: attribute | C49: value | D49: pset_ci | E49: pset_co | I49: tempering the Eff improvement in smaller Evs
B50: EFF | C50: *.5 | D50: TRDELC | E50: Trd_2w,Trd_3w
B53: ~TFM_INS
B54: attribute | C54: value | D54: pset_set | E54: attrib_cond | F54: cset_cn | G54: other_indexes | H54: pset_co
B55: INVCOST | C55: 10 | D55: ELE | E55: -INVCOST
B56: FLO_FUNC | C56: 1 | F56: AuxStoIN | G56: TRAELC | H56: =F56 -> AuxStoIN
...

Sheet RoadTra_BY
A1: scenario | B1: attribute | C1: process | D1: commodity | E1: lim_type | F1: time_slice | G1: year | H1: commodity_group | I1: currency | J1: stage | K1: sow | L1: valfield

Sheet added_EnergyUse_for_Manu_Recy
L4: ~TFM_UPD: attribute= NCAP_ICOM | R4: ~TFM_UPD: attribute= NCAP_ICOM | X4: ~TFM_UPD: attribute= NCAP_ICOM | AD4: ~TFM_UPD: attribute= NCAP_ICOM | AJ4: ~TFM_UPD: attribute= NCAP_ICOM | AP4: ~TFM_UPD: attribute= NCAP_ICOM | AV4: ~TFM_UPD: attribute= NCAP_ICOM
J5: limtype | K5: process | L5: cset_cn | M5: NorthAm | P5: limtype | Q5: process | R5: cset_cn | S5: NorthAm | V5: limtype | W5: process | X5: cset_cn | Y5: NorthAm | AB5: limtype | AC5: process | AD5: cset_cn | AE5: NorthAm | AH5: limtype | AI5: process | AJ5: cset_cn | AK5: NorthAm | AN5: limtype | AO5: process | AP5: cset_cn | AQ5: NorthAm | AT5: limtype | AU5: process | AV5: cset_cn | AW5: NorthAm
J6: FX | K6: Tra_EV_Batt-NMC 111 | L6: ELC | M6: =T65 -> 76.8 | P6: FX | Q6: Tra_EV_Batt-NMC 532 | R6: ELC | S6: =U65 -> 71.3 | V6: FX | W6: Tra_EV_Batt-NMC 622 | X6: ELC | Y6: =V65 -> 71.2 | AB6: FX | AC6: Tra_EV_Batt-NMC 811 | AD6: ELC | AE6: =W65 -> 72.5 | AH6: FX | AI6: Tra_EV_Batt-NCA | AJ6: ELC | AK6: =X65 -> 77 | AN6: FX | AO6: Tra_EV_Batt-LMO | AP6: ELC | AQ6: =Y65 -> 42.4 | AT6: FX | AU6: Tra_EV_Batt-LFP | AV6: ELC | AW6: =Z65 -> 47.2
J7: FX | K7: Tra_EV_Batt-NMC 111 | L7: COAHCO | M7: =T66 -> 202.6 | P7: FX | Q7: Tra_EV_Batt-NMC 532 | R7: COAHCO | S7: =U66 -> 191.3 | V7: FX | W7: Tra_EV_Batt-NMC 622 | X7: COAHCO | Y7: =V66 -> 191.5 | AB7: FX | AC7: Tra_EV_Batt-NMC 811 | AD7: COAHCO | AE7: =W66 -> 185.9 | AH7: FX | AI7: Tra_EV_Batt-NCA | AJ7: COAHCO | AK7: =X66 -> 198.2 | AN7: FX | AO7: Tra_EV_Batt-LMO | AP7: COAHCO | AQ7: =Y66 -> 76.8 | AT7: FX | AU7: Tra_EV_Batt-LFP | AV7: COAHCO | AW7: =Z66 -> 155.5
J8: FX | K8: Tra_EV_Batt-NMC 111 | L8: GASNGA | M8: =T67 -> 583.8 | P8: FX | Q8: Tra_EV_Batt-NMC 532 | R8: GASNGA | S8: =U67 -> 556.1 | V8: FX | W8: Tra_EV_Batt-NMC 622 | X8: GASNGA | Y8: =V67 -> 557.9 | AB8: FX | AC8: Tra_EV_Batt-NMC 811 | AD8: GASNGA | AE8: =W67 -> 550.5 | AH8: FX | AI8: Tra_EV_Batt-NCA | AJ8: GASNGA | AK8: =X67 -> 594.2 | AN8: FX | AO8: Tra_EV_Batt-LMO | AP8: GASNGA | AQ8: =Y67 -> 409.9 | AT8: FX | AU8: Tra_EV_Batt-LFP | AV8: GASNGA | AW8: =Z67 -> 477
J9: FX | K9: Tra_EV_Batt-NMC 111 | L9: OILDST | M9: =T68 -> 127.5 | P9: FX | Q9: Tra_EV_Batt-NMC 532 | R9: OILDST | S9: =U68 -> 133.7 | V9: FX | W9: Tra_EV_Batt-NMC 622 | X9: OILDST | Y9: =V68 -> 140.3 | AB9: FX | AC9: Tra_EV_Batt-NMC 811 | AD9: OILDST | AE9: =W68 -> 149.9 | AH9: FX | AI9: Tra_EV_Batt-NCA | AJ9: OILDST | AK9: =X68 -> 160.8 | AN9: FX | AO9: Tra_EV_Batt-LMO | AP9: OILDST | AQ9: =Y68 -> 57 | AT9: FX | AU9: Tra_EV_Batt-LFP | AV9: OILDST | AW9: =Z68 -> 95.2
L24: ~TFM_UPD: attribute= NCAP_ICOM | R24: ~TFM_UPD: attribute= NCAP_ICOM | X24: ~TFM_UPD: attribute= NCAP_ICOM | AD24: ~TFM_UPD: attribute= NCAP_ICOM | AJ24: ~TFM_UPD: attribute= NCAP_ICOM | AP24: ~TFM_UPD: attribute= NCAP_ICOM | AV24: ~TFM_UPD: attribute= NCAP_ICOM
J25: limtype | K25: process | L25: cset_cn | M25: China | P25: limtype | Q25: process | R25: cset_cn | S25: China | V25: limtype | W25: process | X25: cset_cn | Y25: China | AB25: limtype | AC25: process | AD25: cset_cn | AE25: China | AH25: limtype | AI25: process | AJ25: cset_cn | AK25: China | AN25: limtype | AO25: process | AP25: cset_cn | AQ25: China | AT25: limtype | AU25: process | AV25: cset_cn | AW25: China
J26: FX | K26: Tra_EV_Batt-NMC 111 | L26: ELC | M26: =T73 -> 77.4 | P26: FX | Q26: Tra_EV_Batt-NMC 532 | R26: ELC | S26: =U73 -> 72 | V26: FX | W26: Tra_EV_Batt-NMC 622 | X26: ELC | Y26: =V73 -> 71.9 | AB26: FX | AC26: Tra_EV_Batt-NMC 811 | AD26: ELC | AE26: =W73 -> 73.1 | AH26: FX | AI26: Tra_EV_Batt-NCA | AJ26: ELC | AK26: =X73 -> 77.7 | AN26: FX | AO26: Tra_EV_Batt-LMO | AP26: ELC | AQ26: =Y73 -> 43.1 | AT26: FX | AU26: Tra_EV_Batt-LFP | AV26: ELC | AW26: =Z73 -> 47.8
J27: FX | K27: Tra_EV_Batt-NMC 111 | L27: COAHCO | M27: =T74 -> 236.6 | P27: FX | Q27: Tra_EV_Batt-NMC 532 | R27: COAHCO | S27: =U74 -> 225.2 | V27: FX | W27: Tra_EV_Batt-NMC 622 | X27: COAHCO | Y27: =V74 -> 225.5 | AB27: FX | AC27: Tra_EV_Batt-NMC 811 | AD27: COAHCO | AE27: =W74 -> 219.8 | AH27: FX | AI27: Tra_EV_Batt-NCA | AJ27: COAHCO | AK27: =X74 -> 232.2 | AN27: FX | AO27: Tra_EV_Batt-LMO | AP27: COAHCO | AQ27: =Y74 -> 110.8 | AT27: FX | AU27: Tra_EV_Batt-LFP | AV27: COAHCO | AW27: =Z74 -> 189.5
J28: FX | K28: Tra_EV_Batt-NMC 111 | L28: GASNGA | M28: =T75 -> 559.8 | P28: FX | Q28: Tra_EV_Batt-NMC 532 | R28: GASNGA | S28: =U75 -> 532.1 | V28: FX | W28: Tra_EV_Batt-NMC 622 | X28: GASNGA | Y28: =V75 -> 533.9 | AB28: FX | AC28: Tra_EV_Batt-NMC 811 | AD28: GASNGA | AE28: =W75 -> 526.4 | AH28: FX | AI28: Tra_EV_Batt-NCA | AJ28: GASNGA | AK28: =X75 -> 570.2 | AN28: FX | AO28: Tra_EV_Batt-LMO | AP28: GASNGA | AQ28: =Y75 -> 385.8 | AT28: FX | AU28: Tra_EV_Batt-LFP | AV28: GASNGA | AW28: =Z75 -> 453
J29: FX | K29: Tra_EV_Batt-NMC 111 | L29: OILDST | M29: =T76 -> 127.7 | P29: FX | Q29: Tra_EV_Batt-NMC 532 | R29: OILDST | S29: =U76 -> 134 | V29: FX | W29: Tra_EV_Batt-NMC 622 | X29: OILDST | Y29: =V76 -> 140.6 | AB29: FX | AC29: Tra_EV_Batt-NMC 811 | AD29: OILDST | AE29: =W76 -> 150.2 | AH29: FX | AI29: Tra_EV_Batt-NCA | AJ29: OILDST | AK29: =X76 -> 161.1 | AN29: FX | AO29: Tra_EV_Batt-LMO | AP29: OILDST | AQ29: =Y76 -> 57.2 | AT29: FX | AU29: Tra_EV_Batt-LFP | AV29: OILDST | AW29: =Z76 -> 95.5
Q42: Original data_provided by Anna
Q43: Location | R43: Energy use (MJ/kWh battery produced) | S43: Chemistry
S44: LCO | T44: NMC111 | U44: NMC532 | V44: NMC622 | W44: NMC811 | X44: NCA | Y44: LMO | Z44: LFP
Q45: US | R45: Total Energy | S45: 1211.3 | T45: 990.7 | U45: 952.4 | V45: 961 | W45: 958.7 | X45: 1030.2 | Y45: 586.1 | Z45: 775
R46: Fossil fuels | S46: 1103.7 | T46: 913.9 | U46: 881.1 | V46: 889.8 | W46: 886.2 | X46: 953.2 | Y46: 543.7 | Z46: 727.8
R47: Coal | S47: 267.3 | T47: 202.6 | U47: 191.3 | V47: 191.5 | W47: 185.9 | X47: 198.2 | Y47: 76.8 | Z47: 155.5
R48: Natural gas | S48: 692.5 | T48: 583.8 | U48: 556.1 | V48: 557.9 | W48: 550.5 | X48: 594.2 | Y48: 409.9 | Z48: 477
R49: Petroleum | S49: 144 | T49: 127.5 | U49: 133.7 | V49: 140.3 | W49: 149.9 | X49: 160.8 | Y49: 57 | Z49: 95.2
Q50: Korea | R50: Total Energy | S50: 1217.1 | T50: 996.4 | U50: 958.2 | V50: 966.8 | W50: 964.4 | X50: 1036 | Y50: 591.9 | Z50: 780.8
R51: Fossil fuels | S51: 1109.8 | T51: 920 | U51: 887.2 | V51: 895.9 | W51: 892.3 | X51: 959.3 | Y51: 549.8 | Z51: 733.9
R52: Coal | S52: 280.2 | T52: 215.6 | U52: 204.2 | V52: 204.5 | W52: 198.8 | X52: 211.1 | Y52: 89.8 | Z52: 168.5
R53: Natural gas | S53: 684.6 | T53: 575.9 | U53: 548.2 | V53: 550 | W53: 542.6 | X53: 586.3 | Y53: 402 | Z53: 469.1
R54: Petroleum | S54: 145 | T54: 128.5 | U54: 134.7 | V54: 141.3 | W54: 150.9 | X54: 161.9 | Y54: 58 | Z54: 96.3
Q55: China | R55: Total Energy | S55: 1222.2 | T55: 1001.5 | U55: 963.3 | V55: 971.9 | W55: 969.5 | X55: 1041.1 | Y55: 597 | Z55: 785.8
R56: Fossil fuels | S56: 1113.9 | T56: 924.1 | U56: 891.3 | V56: 900 | W56: 896.4 | X56: 963.4 | Y56: 553.9 | Z56: 738
R57: Coal | S57: 301.2 | T57: 236.6 | U57: 225.2 | V57: 225.5 | W57: 219.8 | X57: 232.2 | Y57: 110.8 | Z57: 189.5
R58: Natural gas | S58: 668.4 | T58: 559.8 | U58: 532.1 | V58: 533.9 | W58: 526.4 | X58: 570.2 | Y58: 385.8 | Z58: 453
R59: Petroleum | S59: 144.2 | T59: 127.7 | U59: 134 | V59: 140.6 | W59: 150.2 | X59: 161.1 | Y59: 57.2 | Z59: 95.5
Q61: ** Assumed to be cell manufacturing
S64: LCO | T64: NMC111 | U64: NMC532 | V64: NMC622 | W64: NMC811 | X64: NCA | Y64: LMO | Z64: LFP
Q65: US | R65: ELC | S65: =S45-S46 -> 107.6 | T65: =T45-T46 -> 76.8 | U65: =U45-U46 -> 71.3 | V65: =V45-V46 -> 71.2 | W65: =W45-W46 -> 72.5 | X65: =X45-X46 -> 77 | Y65: =Y45-Y46 -> 42.4 | Z65: =Z45-Z46 -> 47.2
R66: Coal | S66: =S47 -> 267.3 | T66: =T47 -> 202.6 | U66: =U47 -> 191.3 | V66: =V47 -> 191.5 | W66: =W47 -> 185.9 | X66: =X47 -> 198.2 | Y66: =Y47 -> 76.8 | Z66: =Z47 -> 155.5
R67: Natural gas | S67: =S48 -> 692.5 | T67: =T48 -> 583.8 | U67: =U48 -> 556.1 | V67: =V48 -> 557.9 | W67: =W48 -> 550.5 | X67: =X48 -> 594.2 | Y67: =Y48 -> 409.9 | Z67: =Z48 -> 477
R68: Petroleum | S68: =S49 -> 144 | T68: =T49 -> 127.5 | U68: =U49 -> 133.7 | V68: =V49 -> 140.3 | W68: =W49 -> 149.9 | X68: =X49 -> 160.8 | Y68: =Y49 -> 57 | Z68: =Z49 -> 95.2
Q69: Korea | R69: ELC | S69: =S50-S51 -> 107.3 | T69: =T50-T51 -> 76.4 | U69: =U50-U51 -> 71 | V69: =V50-V51 -> 70.9 | W69: =W50-W51 -> 72.1 | X69: =X50-X51 -> 76.7 | Y69: =Y50-Y51 -> 42.1 | Z69: =Z50-Z51 -> 46.9
R70: Coal | S70: =S52 -> 280.2 | T70: =T52 -> 215.6 | U70: =U52 -> 204.2 | V70: =V52 -> 204.5 | W70: =W52 -> 198.8 | X70: =X52 -> 211.1 | Y70: =Y52 -> 89.8 | Z70: =Z52 -> 168.5
R71: Natural gas | S71: =S53 -> 684.6 | T71: =T53 -> 575.9 | U71: =U53 -> 548.2 | V71: =V53 -> 550 | W71: =W53 -> 542.6 | X71: =X53 -> 586.3 | Y71: =Y53 -> 402 | Z71: =Z53 -> 469.1
R72: Petroleum | S72: =S54 -> 145 | T72: =T54 -> 128.5 | U72: =U54 -> 134.7 | V72: =V54 -> 141.3 | W72: =W54 -> 150.9 | X72: =X54 -> 161.9 | Y72: =Y54 -> 58 | Z72: =Z54 -> 96.3
...
