Workbook
Name FID_1: [1]AGR_Fuels!$A$2
Name GROWTH: '[2]TechRep-Doc'!#REF!
Name GROWTH_TID: '[2]TechRep-Doc'!#REF!

Sheet TechSelection
A3: ~TFM_AVA
A4: Region | B4: Process
A5: Africa_North | B5: *
A6: Africa_Other | B6: *
A7: Australia | B7: *
A8: Austria | B8: *
A9: Baltics | B9: *
A10: BeNeLux | B10: *
A11: Brazil | B11: *
A12: China | B12: *
A13: CroSloven | B13: *
A14: CzechSlovak | B14: *
A15: France | B15: *
... A39: WestBalkans | B39: *

Sheet Road transport
B2: ~TFM_FILL-R:w=RoadTra_BY; hcol=region | K2: ~TFM_TOPINS | P2: ~TFM_TOPINS
B3: Scenario | C3: Attribute | D3: PSET_CO | E3: AllRegions | K3: process | L3: IO | M3: commodity | P3: pset_ci | Q3: pset_co | R3: cset_cn | S3: IO
B4: BASE | C4: AF | D4: Trd[_]* | E4: *1 | K4: Trd[_]*gsl* | L4: IN | M4: TRAGSL,TRABGS | P4: TRAELC | Q4: TRDELC | R4: ELC | S4: Out
B5: BASE | C5: EFF | D5: Trd[_]* | E5: *1 | K5: Trd[_]*dsl* | L5: IN | M5: TRADST,TRABDS
K6: Trd[_]*hh2* | L6: IN | M6: TRAGH2
K7: Trd[_]*cng* | L7: IN | M7: TRANGA
B8: ~TFM_INS | K8: Trd[_]*elc* | L8: IN | M8: TRDELC
B9: attribute | C9: PSET_PN | D9: PSET_CI | E9: CSET_CN | F9: value | G9: limtype | H9: year | K9: Trd[_]*lng* | L9: IN | M9: TRANGA
B10: Share | C10: Trd[_]*-pih* | E10: TRDELC | F10: 0.25 | G10: FX | K10: Trd[_]*-pih* | L10: IN | M10: TRDELC
B11: Share | C11: Trd[_]*-pih* | E11: TRDELC | F11: 3 | G11: FX | H11: 0
B12: CEFF | D12: TRAGSL | E12: TRABGS | F12: 0.93 | K12: ~TFM_MIG
B13: LIFE | C13: Trd[_]* | F13: 25 | K13: attribute | L13: value | M13: attribute2 | N13: pset_pn
B14: *START | C14: Trd[_]* | E14: -TRDELC | F14: 2020 | K14: INVCOST | L14: *.03 | M14: FIXOM | N14: Trd[_]*
K15: INVCOST | L15: *.02 | M15: FIXOM | N15: Trd[_]*elc*
B16: ~TFM_INS-TS: attribute=FLO_MARK
B17: pset_ci | C17: 2020 | D17: 0 | E17: attrib_cond | F17: commodity | G17: top_check
B18: -TRDELC | C18: 0.2 | D18: 3 | E18: -FLO_MARK | F18: Trd[_]* | G18: OUT
C21: ~TFM_INS
C22: attribute | D22: =IF(RoadTra_BY!L$1="","\I:",RoadTra_BY!L$1) -> valfield | E22: =IF(RoadTra_BY!M$1="","\I:",RoadTra_BY!M$1) -> \I: | F22: =IF(RoadTra_BY!N$1="","\I:",RoadTra_BY!N$1) -> \I: | G22: =IF(RoadTra_BY!O$1="","\I:",RoadTra_BY!O$1) -> \I: | H22: =IF(RoadTra_BY!P$1="","\I:",RoadTra_BY!P$1) -> \I: | I22: =IF(RoadTra_BY!Q$1="","\I:",RoadTra_BY!Q$1) -> \I: | J22: =IF(RoadTra_BY!R$1="","\I:",RoadTra_BY!R$1) -> \I: | K22: =IF(RoadTra_BY!S$1="","\I:",RoadTra_BY!S$1) -> \I: | ... AW22: =IF(RoadTra_BY!BE$1="","\I:",RoadTra_BY!BE$1) -> \I: | AX22: process
C23: AF | D23: =AVERAGEIFS(RoadTra_BY!L$2:L$999,RoadTra_BY!$B$2:$B$999,'Road transport'!$C23,RoadTra_BY!$C$2:$C$999,'Road transport'!$AX23) -> #DIV/0! | E23: =AVERAGEIFS(RoadTra_BY!M$2:M$999,RoadTra_BY!$B$2:$B$999,'Road transport'!$C23,RoadTra_BY!$C$2:$C$999,'Road transport'!$AX23) -> #DIV/0! | F23: =AVERAGEIFS(RoadTra_BY!N$2:N$999,RoadTra_BY!$B$2:$B$999,'Road transport'!$C23,RoadTra_BY!$C$2:$C$999,'Road transport'!$AX23) -> #DIV/0! | G23: =AVERAGEIFS(RoadTra_BY!O$2:O$999,RoadTra_BY!$B$2:$B$999,'Road transport'!$C23,RoadTra_BY!$C$2:$C$999,'Road transport'!$AX23) -> #DIV/0! | H23: =AVERAGEIFS(RoadTra_BY!P$2:P$999,RoadTra_BY!$B$2:$B$999,'Road transport'!$C23,RoadTra_BY!$C$2:$C$999,'Road transport'!$AX23) -> #DIV/0! | I23: =AVERAGEIFS(RoadTra_BY!Q$2:Q$999,RoadTra_BY!$B$2:$B$999,'Road transport'!$C23,RoadTra_BY!$C$2:$C$999,'Road transport'!$AX23) -> #DIV/0! | J23: =AVERAGEIFS(RoadTra_BY!R$2:R$999,RoadTra_BY!$B$2:$B$999,'Road transport'!$C23,RoadTra_BY!$C$2:$C$999,'Road transport'!$AX23) -> #DIV/0! | K23: =AVERAGEIFS(RoadTra_BY!S$2:S$999,RoadTra_BY!$B$2:$B$999,'Road transport'!$C23,RoadTra_BY!$C$2:$C$999,'Road transport'!$AX23) -> #DIV/0! | ... AW23: =AVERAGEIFS(RoadTra_BY!BE$2:BE$999,RoadTra_BY!$B$2:$B$999,'Road transport'!$C23,RoadTra_BY!$C$2:$C$999,'Road transport'!$AX23) -> #DIV/0! | AX23: Trd_2w_*
C24: AF | D24: =AVERAGEIFS(RoadTra_BY!L$2:L$999,RoadTra_BY!$B$2:$B$999,'Road transport'!$C24,RoadTra_BY!$C$2:$C$999,'Road transport'!$AX24) -> #DIV/0! | E24: =AVERAGEIFS(RoadTra_BY!M$2:M$999,RoadTra_BY!$B$2:$B$999,'Road transport'!$C24,RoadTra_BY!$C$2:$C$999,'Road transport'!$AX24) -> #DIV/0! | F24: =AVERAGEIFS(RoadTra_BY!N$2:N$999,RoadTra_BY!$B$2:$B$999,'Road transport'!$C24,RoadTra_BY!$C$2:$C$999,'Road transport'!$AX24) -> #DIV/0! | G24: =AVERAGEIFS(RoadTra_BY!O$2:O$999,RoadTra_BY!$B$2:$B$999,'Road transport'!$C24,RoadTra_BY!$C$2:$C$999,'Road transport'!$AX24) -> #DIV/0! | H24: =AVERAGEIFS(RoadTra_BY!P$2:P$999,RoadTra_BY!$B$2:$B$999,'Road transport'!$C24,RoadTra_BY!$C$2:$C$999,'Road transport'!$AX24) -> #DIV/0! | I24: =AVERAGEIFS(RoadTra_BY!Q$2:Q$999,RoadTra_BY!$B$2:$B$999,'Road transport'!$C24,RoadTra_BY!$C$2:$C$999,'Road transport'!$AX24) -> #DIV/0! | J24: =AVERAGEIFS(RoadTra_BY!R$2:R$999,RoadTra_BY!$B$2:$B$999,'Road transport'!$C24,RoadTra_BY!$C$2:$C$999,'Road transport'!$AX24) -> #DIV/0! | K24: =AVERAGEIFS(RoadTra_BY!S$2:S$999,RoadTra_BY!$B$2:$B$999,'Road transport'!$C24,RoadTra_BY!$C$2:$C$999,'Road transport'!$AX24) -> #DIV/0! | ... AW24: =AVERAGEIFS(RoadTra_BY!BE$2:BE$999,RoadTra_BY!$B$2:$B$999,'Road transport'!$C24,RoadTra_BY!$C$2:$C$999,'Road transport'!$AX24) -> #DIV/0! | AX24: Trd_3w_*
C25: AF | D25: =AVERAGEIFS(RoadTra_BY!L$2:L$999,RoadTra_BY!$B$2:$B$999,'Road transport'!$C25,RoadTra_BY!$C$2:$C$999,'Road transport'!$AX25) -> #DIV/0! | E25: =AVERAGEIFS(RoadTra_BY!M$2:M$999,RoadTra_BY!$B$2:$B$999,'Road transport'!$C25,RoadTra_BY!$C$2:$C$999,'Road transport'!$AX25) -> #DIV/0! | F25: =AVERAGEIFS(RoadTra_BY!N$2:N$999,RoadTra_BY!$B$2:$B$999,'Road transport'!$C25,RoadTra_BY!$C$2:$C$999,'Road transport'!$AX25) -> #DIV/0! | G25: =AVERAGEIFS(RoadTra_BY!O$2:O$999,RoadTra_BY!$B$2:$B$999,'Road transport'!$C25,RoadTra_BY!$C$2:$C$999,'Road transport'!$AX25) -> #DIV/0! | H25: =AVERAGEIFS(RoadTra_BY!P$2:P$999,RoadTra_BY!$B$2:$B$999,'Road transport'!$C25,RoadTra_BY!$C$2:$C$999,'Road transport'!$AX25) -> #DIV/0! | I25: =AVERAGEIFS(RoadTra_BY!Q$2:Q$999,RoadTra_BY!$B$2:$B$999,'Road transport'!$C25,RoadTra_BY!$C$2:$C$999,'Road transport'!$AX25) -> #DIV/0! | J25: =AVERAGEIFS(RoadTra_BY!R$2:R$999,RoadTra_BY!$B$2:$B$999,'Road transport'!$C25,RoadTra_BY!$C$2:$C$999,'Road transport'!$AX25) -> #DIV/0! | K25: =AVERAGEIFS(RoadTra_BY!S$2:S$999,RoadTra_BY!$B$2:$B$999,'Road transport'!$C25,RoadTra_BY!$C$2:$C$999,'Road transport'!$AX25) -> #DIV/0! | ... AW25: =AVERAGEIFS(RoadTra_BY!BE$2:BE$999,RoadTra_BY!$B$2:$B$999,'Road transport'!$C25,RoadTra_BY!$C$2:$C$999,'Road transport'!$AX25) -> #DIV/0! | AX25: Trd_bus*
C26: AF | D26: =AVERAGEIFS(RoadTra_BY!L$2:L$999,RoadTra_BY!$B$2:$B$999,'Road transport'!$C26,RoadTra_BY!$C$2:$C$999,'Road transport'!$AX26) -> #DIV/0! | E26: =AVERAGEIFS(RoadTra_BY!M$2:M$999,RoadTra_BY!$B$2:$B$999,'Road transport'!$C26,RoadTra_BY!$C$2:$C$999,'Road transport'!$AX26) -> #DIV/0! | F26: =AVERAGEIFS(RoadTra_BY!N$2:N$999,RoadTra_BY!$B$2:$B$999,'Road transport'!$C26,RoadTra_BY!$C$2:$C$999,'Road transport'!$AX26) -> #DIV/0! | G26: =AVERAGEIFS(RoadTra_BY!O$2:O$999,RoadTra_BY!$B$2:$B$999,'Road transport'!$C26,RoadTra_BY!$C$2:$C$999,'Road transport'!$AX26) -> #DIV/0! | H26: =AVERAGEIFS(RoadTra_BY!P$2:P$999,RoadTra_BY!$B$2:$B$999,'Road transport'!$C26,RoadTra_BY!$C$2:$C$999,'Road transport'!$AX26) -> #DIV/0! | I26: =AVERAGEIFS(RoadTra_BY!Q$2:Q$999,RoadTra_BY!$B$2:$B$999,'Road transport'!$C26,RoadTra_BY!$C$2:$C$999,'Road transport'!$AX26) -> #DIV/0! | J26: =AVERAGEIFS(RoadTra_BY!R$2:R$999,RoadTra_BY!$B$2:$B$999,'Road transport'!$C26,RoadTra_BY!$C$2:$C$999,'Road transport'!$AX26) -> #DIV/0! | K26: =AVERAGEIFS(RoadTra_BY!S$2:S$999,RoadTra_BY!$B$2:$B$999,'Road transport'!$C26,RoadTra_BY!$C$2:$C$999,'Road transport'!$AX26) -> #DIV/0! | ... AW26: =AVERAGEIFS(RoadTra_BY!BE$2:BE$999,RoadTra_BY!$B$2:$B$999,'Road transport'!$C26,RoadTra_BY!$C$2:$C$999,'Road transport'!$AX26) -> #DIV/0! | AX26: Trd_car*
C27: AF | D27: =AVERAGEIFS(RoadTra_BY!L$2:L$999,RoadTra_BY!$B$2:$B$999,'Road transport'!$C27,RoadTra_BY!$C$2:$C$999,'Road transport'!$AX27) -> #DIV/0! | E27: =AVERAGEIFS(RoadTra_BY!M$2:M$999,RoadTra_BY!$B$2:$B$999,'Road transport'!$C27,RoadTra_BY!$C$2:$C$999,'Road transport'!$AX27) -> #DIV/0! | F27: =AVERAGEIFS(RoadTra_BY!N$2:N$999,RoadTra_BY!$B$2:$B$999,'Road transport'!$C27,RoadTra_BY!$C$2:$C$999,'Road transport'!$AX27) -> #DIV/0! | G27: =AVERAGEIFS(RoadTra_BY!O$2:O$999,RoadTra_BY!$B$2:$B$999,'Road transport'!$C27,RoadTra_BY!$C$2:$C$999,'Road transport'!$AX27) -> #DIV/0! | H27: =AVERAGEIFS(RoadTra_BY!P$2:P$999,RoadTra_BY!$B$2:$B$999,'Road transport'!$C27,RoadTra_BY!$C$2:$C$999,'Road transport'!$AX27) -> #DIV/0! | I27: =AVERAGEIFS(RoadTra_BY!Q$2:Q$999,RoadTra_BY!$B$2:$B$999,'Road transport'!$C27,RoadTra_BY!$C$2:$C$999,'Road transport'!$AX27) -> #DIV/0! | J27: =AVERAGEIFS(RoadTra_BY!R$2:R$999,RoadTra_BY!$B$2:$B$999,'Road transport'!$C27,RoadTra_BY!$C$2:$C$999,'Road transport'!$AX27) -> #DIV/0! | K27: =AVERAGEIFS(RoadTra_BY!S$2:S$999,RoadTra_BY!$B$2:$B$999,'Road transport'!$C27,RoadTra_BY!$C$2:$C$999,'Road transport'!$AX27) -> #DIV/0! | ... AW27: =AVERAGEIFS(RoadTra_BY!BE$2:BE$999,RoadTra_BY!$B$2:$B$999,'Road transport'!$C27,RoadTra_BY!$C$2:$C$999,'Road transport'!$AX27) -> #DIV/0! | AX27: Trd_hdt*
C28: AF | D28: =AVERAGEIFS(RoadTra_BY!L$2:L$999,RoadTra_BY!$B$2:$B$999,'Road transport'!$C28,RoadTra_BY!$C$2:$C$999,'Road transport'!$AX28) -> #DIV/0! | E28: =AVERAGEIFS(RoadTra_BY!M$2:M$999,RoadTra_BY!$B$2:$B$999,'Road transport'!$C28,RoadTra_BY!$C$2:$C$999,'Road transport'!$AX28) -> #DIV/0! | F28: =AVERAGEIFS(RoadTra_BY!N$2:N$999,RoadTra_BY!$B$2:$B$999,'Road transport'!$C28,RoadTra_BY!$C$2:$C$999,'Road transport'!$AX28) -> #DIV/0! | G28: =AVERAGEIFS(RoadTra_BY!O$2:O$999,RoadTra_BY!$B$2:$B$999,'Road transport'!$C28,RoadTra_BY!$C$2:$C$999,'Road transport'!$AX28) -> #DIV/0! | H28: =AVERAGEIFS(RoadTra_BY!P$2:P$999,RoadTra_BY!$B$2:$B$999,'Road transport'!$C28,RoadTra_BY!$C$2:$C$999,'Road transport'!$AX28) -> #DIV/0! | I28: =AVERAGEIFS(RoadTra_BY!Q$2:Q$999,RoadTra_BY!$B$2:$B$999,'Road transport'!$C28,RoadTra_BY!$C$2:$C$999,'Road transport'!$AX28) -> #DIV/0! | J28: =AVERAGEIFS(RoadTra_BY!R$2:R$999,RoadTra_BY!$B$2:$B$999,'Road transport'!$C28,RoadTra_BY!$C$2:$C$999,'Road transport'!$AX28) -> #DIV/0! | K28: =AVERAGEIFS(RoadTra_BY!S$2:S$999,RoadTra_BY!$B$2:$B$999,'Road transport'!$C28,RoadTra_BY!$C$2:$C$999,'Road transport'!$AX28) -> #DIV/0! | ... AW28: =AVERAGEIFS(RoadTra_BY!BE$2:BE$999,RoadTra_BY!$B$2:$B$999,'Road transport'!$C28,RoadTra_BY!$C$2:$C$999,'Road transport'!$AX28) -> #DIV/0! | AX28: Trd_lcv*
C31: ~TFM_UPD
C32: attribute | D32: =IF(RoadTra_BY!L$1="","\I:",RoadTra_BY!L$1) -> valfield | E32: =IF(RoadTra_BY!M$1="","\I:",RoadTra_BY!M$1) -> \I: | F32: =IF(RoadTra_BY!N$1="","\I:",RoadTra_BY!N$1) -> \I: | G32: =IF(RoadTra_BY!O$1="","\I:",RoadTra_BY!O$1) -> \I: | H32: =IF(RoadTra_BY!P$1="","\I:",RoadTra_BY!P$1) -> \I: | I32: =IF(RoadTra_BY!Q$1="","\I:",RoadTra_BY!Q$1) -> \I: | J32: =IF(RoadTra_BY!R$1="","\I:",RoadTra_BY!R$1) -> \I: | K32: =IF(RoadTra_BY!S$1="","\I:",RoadTra_BY!S$1) -> \I: | ... AW32: =IF(RoadTra_BY!BE$1="","\I:",RoadTra_BY!BE$1) -> \I: | AX32: process
C33: EFF | D33: ="*"&ROUND(SUMIFS(RoadTra_BY!L$2:L$79,RoadTra_BY!$B$2:$B$79,'Road transport'!$C33,RoadTra_BY!$C$2:$C$79,'Road transport'!$BA33),3) -> *0 | E33: ="*"&ROUND(SUMIFS(RoadTra_BY!M$2:M$79,RoadTra_BY!$B$2:$B$79,'Road transport'!$C33,RoadTra_BY!$C$2:$C$79,'Road transport'!$BA33),3) -> *0 | F33: ="*"&ROUND(SUMIFS(RoadTra_BY!N$2:N$79,RoadTra_BY!$B$2:$B$79,'Road transport'!$C33,RoadTra_BY!$C$2:$C$79,'Road transport'!$BA33),3) -> *0 | G33: ="*"&ROUND(SUMIFS(RoadTra_BY!O$2:O$79,RoadTra_BY!$B$2:$B$79,'Road transport'!$C33,RoadTra_BY!$C$2:$C$79,'Road transport'!$BA33),3) -> *0 | H33: ="*"&ROUND(SUMIFS(RoadTra_BY!P$2:P$79,RoadTra_BY!$B$2:$B$79,'Road transport'!$C33,RoadTra_BY!$C$2:$C$79,'Road transport'!$BA33),3) -> *0 | I33: ="*"&ROUND(SUMIFS(RoadTra_BY!Q$2:Q$79,RoadTra_BY!$B$2:$B$79,'Road transport'!$C33,RoadTra_BY!$C$2:$C$79,'Road transport'!$BA33),3) -> *0 | J33: ="*"&ROUND(SUMIFS(RoadTra_BY!R$2:R$79,RoadTra_BY!$B$2:$B$79,'Road transport'!$C33,RoadTra_BY!$C$2:$C$79,'Road transport'!$BA33),3) -> *0 | K33: ="*"&ROUND(SUMIFS(RoadTra_BY!S$2:S$79,RoadTra_BY!$B$2:$B$79,'Road transport'!$C33,RoadTra_BY!$C$2:$C$79,'Road transport'!$BA33),3) -> *0 | ... AW33: ="*"&ROUND(SUMIFS(RoadTra_BY!BE$2:BE$79,RoadTra_BY!$B$2:$B$79,'Road transport'!$C33,RoadTra_BY!$C$2:$C$79,'Road transport'!$BA33),3) -> *0 | AX33: =SUBSTITUTE(SUBSTITUTE(BA33,"gsl",""),"dsl","")&"*" -> Trd_2w_* | AZ33: =IFERROR(IF(FIND("gsl",BA33)>0,1,0),2) -> 1 | BA33: Trd_2w_gsl
C34: EFF | D34: ="*"&ROUND(SUMIFS(RoadTra_BY!L$2:L$79,RoadTra_BY!$B$2:$B$79,'Road transport'!$C34,RoadTra_BY!$C$2:$C$79,'Road transport'!$BA34),3) -> *0 | E34: ="*"&ROUND(SUMIFS(RoadTra_BY!M$2:M$79,RoadTra_BY!$B$2:$B$79,'Road transport'!$C34,RoadTra_BY!$C$2:$C$79,'Road transport'!$BA34),3) -> *0 | F34: ="*"&ROUND(SUMIFS(RoadTra_BY!N$2:N$79,RoadTra_BY!$B$2:$B$79,'Road transport'!$C34,RoadTra_BY!$C$2:$C$79,'Road transport'!$BA34),3) -> *0 | G34: ="*"&ROUND(SUMIFS(RoadTra_BY!O$2:O$79,RoadTra_BY!$B$2:$B$79,'Road transport'!$C34,RoadTra_BY!$C$2:$C$79,'Road transport'!$BA34),3) -> *0 | H34: ="*"&ROUND(SUMIFS(RoadTra_BY!P$2:P$79,RoadTra_BY!$B$2:$B$79,'Road transport'!$C34,RoadTra_BY!$C$2:$C$79,'Road transport'!$BA34),3) -> *0 | I34: ="*"&ROUND(SUMIFS(RoadTra_BY!Q$2:Q$79,RoadTra_BY!$B$2:$B$79,'Road transport'!$C34,RoadTra_BY!$C$2:$C$79,'Road transport'!$BA34),3) -> *0 | J34: ="*"&ROUND(SUMIFS(RoadTra_BY!R$2:R$79,RoadTra_BY!$B$2:$B$79,'Road transport'!$C34,RoadTra_BY!$C$2:$C$79,'Road transport'!$BA34),3) -> *0 | K34: ="*"&ROUND(SUMIFS(RoadTra_BY!S$2:S$79,RoadTra_BY!$B$2:$B$79,'Road transport'!$C34,RoadTra_BY!$C$2:$C$79,'Road transport'!$BA34),3) -> *0 | ... AW34: ="*"&ROUND(SUMIFS(RoadTra_BY!BE$2:BE$79,RoadTra_BY!$B$2:$B$79,'Road transport'!$C34,RoadTra_BY!$C$2:$C$79,'Road transport'!$BA34),3) -> *0 | AX34: =SUBSTITUTE(SUBSTITUTE(BA34,"gsl",""),"dsl","")&"*" -> Trd_3w_* | AZ34: =IFERROR(IF(FIND("gsl",BA34)>0,1,0),2) -> 1 | BA34: Trd_3w_gsl
C35: EFF | D35: ="*"&ROUND(SUMIFS(RoadTra_BY!L$2:L$79,RoadTra_BY!$B$2:$B$79,'Road transport'!$C35,RoadTra_BY!$C$2:$C$79,'Road transport'!$BA35),3) -> *0 | E35: ="*"&ROUND(SUMIFS(RoadTra_BY!M$2:M$79,RoadTra_BY!$B$2:$B$79,'Road transport'!$C35,RoadTra_BY!$C$2:$C$79,'Road transport'!$BA35),3) -> *0 | F35: ="*"&ROUND(SUMIFS(RoadTra_BY!N$2:N$79,RoadTra_BY!$B$2:$B$79,'Road transport'!$C35,RoadTra_BY!$C$2:$C$79,'Road transport'!$BA35),3) -> *0 | G35: ="*"&ROUND(SUMIFS(RoadTra_BY!O$2:O$79,RoadTra_BY!$B$2:$B$79,'Road transport'!$C35,RoadTra_BY!$C$2:$C$79,'Road transport'!$BA35),3) -> *0 | H35: ="*"&ROUND(SUMIFS(RoadTra_BY!P$2:P$79,RoadTra_BY!$B$2:$B$79,'Road transport'!$C35,RoadTra_BY!$C$2:$C$79,'Road transport'!$BA35),3) -> *0 | I35: ="*"&ROUND(SUMIFS(RoadTra_BY!Q$2:Q$79,RoadTra_BY!$B$2:$B$79,'Road transport'!$C35,RoadTra_BY!$C$2:$C$79,'Road transport'!$BA35),3) -> *0 | J35: ="*"&ROUND(SUMIFS(RoadTra_BY!R$2:R$79,RoadTra_BY!$B$2:$B$79,'Road transport'!$C35,RoadTra_BY!$C$2:$C$79,'Road transport'!$BA35),3) -> *0 | K35: ="*"&ROUND(SUMIFS(RoadTra_BY!S$2:S$79,RoadTra_BY!$B$2:$B$79,'Road transport'!$C35,RoadTra_BY!$C$2:$C$79,'Road transport'!$BA35),3) -> *0 | ... AW35: ="*"&ROUND(SUMIFS(RoadTra_BY!BE$2:BE$79,RoadTra_BY!$B$2:$B$79,'Road transport'!$C35,RoadTra_BY!$C$2:$C$79,'Road transport'!$BA35),3) -> *0 | AX35: =SUBSTITUTE(SUBSTITUTE(BA35,"gsl",""),"dsl","")&"*" -> Trd_bus_* | AZ35: =IFERROR(IF(FIND("gsl",BA35)>0,1,0),2) -> 2 | BA35: Trd_bus_dsl
C36: EFF | D36: ="*"&ROUND(SUMIFS(RoadTra_BY!L$2:L$79,RoadTra_BY!$B$2:$B$79,'Road transport'!$C36,RoadTra_BY!$C$2:$C$79,'Road transport'!$BA36),3) -> *0 | E36: ="*"&ROUND(SUMIFS(RoadTra_BY!M$2:M$79,RoadTra_BY!$B$2:$B$79,'Road transport'!$C36,RoadTra_BY!$C$2:$C$79,'Road transport'!$BA36),3) -> *0 | F36: ="*"&ROUND(SUMIFS(RoadTra_BY!N$2:N$79,RoadTra_BY!$B$2:$B$79,'Road transport'!$C36,RoadTra_BY!$C$2:$C$79,'Road transport'!$BA36),3) -> *0 | G36: ="*"&ROUND(SUMIFS(RoadTra_BY!O$2:O$79,RoadTra_BY!$B$2:$B$79,'Road transport'!$C36,RoadTra_BY!$C$2:$C$79,'Road transport'!$BA36),3) -> *0 | H36: ="*"&ROUND(SUMIFS(RoadTra_BY!P$2:P$79,RoadTra_BY!$B$2:$B$79,'Road transport'!$C36,RoadTra_BY!$C$2:$C$79,'Road transport'!$BA36),3) -> *0 | I36: ="*"&ROUND(SUMIFS(RoadTra_BY!Q$2:Q$79,RoadTra_BY!$B$2:$B$79,'Road transport'!$C36,RoadTra_BY!$C$2:$C$79,'Road transport'!$BA36),3) -> *0 | J36: ="*"&ROUND(SUMIFS(RoadTra_BY!R$2:R$79,RoadTra_BY!$B$2:$B$79,'Road transport'!$C36,RoadTra_BY!$C$2:$C$79,'Road transport'!$BA36),3) -> *0 | K36: ="*"&ROUND(SUMIFS(RoadTra_BY!S$2:S$79,RoadTra_BY!$B$2:$B$79,'Road transport'!$C36,RoadTra_BY!$C$2:$C$79,'Road transport'!$BA36),3) -> *0 | ... AW36: ="*"&ROUND(SUMIFS(RoadTra_BY!BE$2:BE$79,RoadTra_BY!$B$2:$B$79,'Road transport'!$C36,RoadTra_BY!$C$2:$C$79,'Road transport'!$BA36),3) -> *0 | AX36: =SUBSTITUTE(SUBSTITUTE(BA36,"gsl",""),"dsl","")&"*" -> Trd_car_* | AZ36: =IFERROR(IF(FIND("gsl",BA36)>0,1,0),2) -> 1 | BA36: Trd_car_gsl
C37: EFF | D37: ="*"&ROUND(SUMIFS(RoadTra_BY!L$2:L$79,RoadTra_BY!$B$2:$B$79,'Road transport'!$C37,RoadTra_BY!$C$2:$C$79,'Road transport'!$BA37),3) -> *0 | E37: ="*"&ROUND(SUMIFS(RoadTra_BY!M$2:M$79,RoadTra_BY!$B$2:$B$79,'Road transport'!$C37,RoadTra_BY!$C$2:$C$79,'Road transport'!$BA37),3) -> *0 | F37: ="*"&ROUND(SUMIFS(RoadTra_BY!N$2:N$79,RoadTra_BY!$B$2:$B$79,'Road transport'!$C37,RoadTra_BY!$C$2:$C$79,'Road transport'!$BA37),3) -> *0 | G37: ="*"&ROUND(SUMIFS(RoadTra_BY!O$2:O$79,RoadTra_BY!$B$2:$B$79,'Road transport'!$C37,RoadTra_BY!$C$2:$C$79,'Road transport'!$BA37),3) -> *0 | H37: ="*"&ROUND(SUMIFS(RoadTra_BY!P$2:P$79,RoadTra_BY!$B$2:$B$79,'Road transport'!$C37,RoadTra_BY!$C$2:$C$79,'Road transport'!$BA37),3) -> *0 | I37: ="*"&ROUND(SUMIFS(RoadTra_BY!Q$2:Q$79,RoadTra_BY!$B$2:$B$79,'Road transport'!$C37,RoadTra_BY!$C$2:$C$79,'Road transport'!$BA37),3) -> *0 | J37: ="*"&ROUND(SUMIFS(RoadTra_BY!R$2:R$79,RoadTra_BY!$B$2:$B$79,'Road transport'!$C37,RoadTra_BY!$C$2:$C$79,'Road transport'!$BA37),3) -> *0 | K37: ="*"&ROUND(SUMIFS(RoadTra_BY!S$2:S$79,RoadTra_BY!$B$2:$B$79,'Road transport'!$C37,RoadTra_BY!$C$2:$C$79,'Road transport'!$BA37),3) -> *0 | ... AW37: ="*"&ROUND(SUMIFS(RoadTra_BY!BE$2:BE$79,RoadTra_BY!$B$2:$B$79,'Road transport'!$C37,RoadTra_BY!$C$2:$C$79,'Road transport'!$BA37),3) -> *0 | AX37: =SUBSTITUTE(SUBSTITUTE(BA37,"gsl",""),"dsl","")&"*" -> Trd_hdt_* | AZ37: =IFERROR(IF(FIND("gsl",BA37)>0,1,0),2) -> 2 | BA37: Trd_hdt_dsl
C38: EFF | D38: ="*"&ROUND(SUMIFS(RoadTra_BY!L$2:L$79,RoadTra_BY!$B$2:$B$79,'Road transport'!$C38,RoadTra_BY!$C$2:$C$79,'Road transport'!$BA38),3) -> *0 | E38: ="*"&ROUND(SUMIFS(RoadTra_BY!M$2:M$79,RoadTra_BY!$B$2:$B$79,'Road transport'!$C38,RoadTra_BY!$C$2:$C$79,'Road transport'!$BA38),3) -> *0 | F38: ="*"&ROUND(SUMIFS(RoadTra_BY!N$2:N$79,RoadTra_BY!$B$2:$B$79,'Road transport'!$C38,RoadTra_BY!$C$2:$C$79,'Road transport'!$BA38),3) -> *0 | G38: ="*"&ROUND(SUMIFS(RoadTra_BY!O$2:O$79,RoadTra_BY!$B$2:$B$79,'Road transport'!$C38,RoadTra_BY!$C$2:$C$79,'Road transport'!$BA38),3) -> *0 | H38: ="*"&ROUND(SUMIFS(RoadTra_BY!P$2:P$79,RoadTra_BY!$B$2:$B$79,'Road transport'!$C38,RoadTra_BY!$C$2:$C$79,'Road transport'!$BA38),3) -> *0 | I38: ="*"&ROUND(SUMIFS(RoadTra_BY!Q$2:Q$79,RoadTra_BY!$B$2:$B$79,'Road transport'!$C38,RoadTra_BY!$C$2:$C$79,'Road transport'!$BA38),3) -> *0 | J38: ="*"&ROUND(SUMIFS(RoadTra_BY!R$2:R$79,RoadTra_BY!$B$2:$B$79,'Road transport'!$C38,RoadTra_BY!$C$2:$C$79,'Road transport'!$BA38),3) -> *0 | K38: ="*"&ROUND(SUMIFS(RoadTra_BY!S$2:S$79,RoadTra_BY!$B$2:$B$79,'Road transport'!$C38,RoadTra_BY!$C$2:$C$79,'Road transport'!$BA38),3) -> *0 | ... AW38: ="*"&ROUND(SUMIFS(RoadTra_BY!BE$2:BE$79,RoadTra_BY!$B$2:$B$79,'Road transport'!$C38,RoadTra_BY!$C$2:$C$79,'Road transport'!$BA38),3) -> *0 | AX38: =SUBSTITUTE(SUBSTITUTE(BA38,"gsl",""),"dsl","")&"*" -> Trd_lcv_* | AZ38: =IFERROR(IF(FIND("gsl",BA38)>0,1,0),2) -> 2 | BA38: Trd_lcv_dsl
B48: ~TFM_UPD
B49: attribute | C49: value | D49: pset_ci | E49: pset_co | I49: tempering the Eff improvement in smaller Evs
B50: EFF | C50: *.5 | D50: TRDELC | E50: Trd_2w,Trd_3w
B53: ~TFM_INS
B54: attribute | C54: value | D54: pset_set | E54: attrib_cond | F54: cset_cn | G54: other_indexes | H54: pset_co
B55: INVCOST | C55: 10 | D55: ELE | E55: -INVCOST
B59: FLO_FUNC | C59: 1 | F59: AuxStoIN | G59: TRAELC | H59: =F59 -> AuxStoIN
...

Sheet RoadTra_BY
A1: scenario | B1: attribute | C1: process | D1: commodity | E1: lim_type | F1: time_slice | G1: year | H1: commodity_group | I1: currency | J1: stage | K1: sow | L1: valfield

Sheet added_EnergyUse_for_Manu
L4: ~TFM_UPD: attribute= INPUT | R4: ~TFM_UPD: attribute= INPUT | X4: ~TFM_UPD: attribute= INPUT | AD4: ~TFM_UPD: attribute= INPUT | AJ4: ~TFM_UPD: attribute= INPUT | AP4: ~TFM_UPD: attribute= INPUT | AV4: ~TFM_UPD: attribute= INPUT
J5: limtype | K5: process | L5: cset_cn | M5: NorthAm | P5: limtype | Q5: process | R5: cset_cn | S5: NorthAm | V5: limtype | W5: process | X5: cset_cn | Y5: NorthAm | AB5: limtype | AC5: process | AD5: cset_cn | AE5: NorthAm | AH5: limtype | AI5: process | AJ5: cset_cn | AK5: NorthAm | AN5: limtype | AO5: process | AP5: cset_cn | AQ5: NorthAm | AT5: limtype | AU5: process | AV5: cset_cn | AW5: NorthAm
J6: FX | K6: Tra_EV_Batt-NMC 111_virgin | L6: ELC | M6: =M16/1000 -> 0.0768 | P6: FX | Q6: Tra_EV_Batt-NMC532_virgin | R6: ELC | S6: =S16/1000 -> 0.0713 | V6: FX | W6: Tra_EV_Batt-NMC 622_virgin | X6: ELC | Y6: =Y16/1000 -> 0.0712 | AB6: FX | AC6: Tra_EV_Batt-NMC 811_virgin | AD6: ELC | AE6: =AE16/1000 -> 0.0725 | AH6: FX | AI6: Tra_EV_Batt-NCA_virgin | AJ6: ELC | AK6: =AK16/1000 -> 0.077 | AN6: FX | AO6: Tra_EV_Batt-LMO_virgin | AP6: ELC | AQ6: =AQ16/1000 -> 0.0424 | AT6: FX | AU6: Tra_EV_Batt-LFP_virgin | AV6: ELC | AW6: =AW16/1000 -> 0.0472
J7: FX | K7: Tra_EV_Batt-NMC 111_virgin | L7: TRACOA | M7: =M17/1000 -> 0.2026 | P7: FX | Q7: Tra_EV_Batt-NMC532_virgin | R7: TRACOA | S7: =S17/1000 -> 0.1913 | V7: FX | W7: Tra_EV_Batt-NMC 622_virgin | X7: TRACOA | Y7: =Y17/1000 -> 0.1915 | AB7: FX | AC7: Tra_EV_Batt-NMC 811_virgin | AD7: TRACOA | AE7: =AE17/1000 -> 0.1859 | AH7: FX | AI7: Tra_EV_Batt-NCA_virgin | AJ7: TRACOA | AK7: =AK17/1000 -> 0.1982 | AN7: FX | AO7: Tra_EV_Batt-LMO_virgin | AP7: TRACOA | AQ7: =AQ17/1000 -> 0.0768 | AT7: FX | AU7: Tra_EV_Batt-LFP_virgin | AV7: TRACOA | AW7: =AW17/1000 -> 0.1555
J8: FX | K8: Tra_EV_Batt-NMC 111_virgin | L8: TRANGA | M8: =M18/1000 -> 0.5838 | P8: FX | Q8: Tra_EV_Batt-NMC532_virgin | R8: TRANGA | S8: =S18/1000 -> 0.5561 | V8: FX | W8: Tra_EV_Batt-NMC 622_virgin | X8: TRANGA | Y8: =Y18/1000 -> 0.5579 | AB8: FX | AC8: Tra_EV_Batt-NMC 811_virgin | AD8: TRANGA | AE8: =AE18/1000 -> 0.5505 | AH8: FX | AI8: Tra_EV_Batt-NCA_virgin | AJ8: TRANGA | AK8: =AK18/1000 -> 0.5942 | AN8: FX | AO8: Tra_EV_Batt-LMO_virgin | AP8: TRANGA | AQ8: =AQ18/1000 -> 0.4099 | AT8: FX | AU8: Tra_EV_Batt-LFP_virgin | AV8: TRANGA | AW8: =AW18/1000 -> 0.477
J9: FX | K9: Tra_EV_Batt-NMC 111_virgin | L9: TRADST | M9: =M19/1000 -> 0.1275 | P9: FX | Q9: Tra_EV_Batt-NMC532_virgin | R9: TRADST | S9: =S19/1000 -> 0.1337 | V9: FX | W9: Tra_EV_Batt-NMC 622_virgin | X9: TRADST | Y9: =Y19/1000 -> 0.1403 | AB9: FX | AC9: Tra_EV_Batt-NMC 811_virgin | AD9: TRADST | AE9: =AE19/1000 -> 0.1499 | AH9: FX | AI9: Tra_EV_Batt-NCA_virgin | AJ9: TRADST | AK9: =AK19/1000 -> 0.1608 | AN9: FX | AO9: Tra_EV_Batt-LMO_virgin | AP9: TRADST | AQ9: =AQ19/1000 -> 0.057 | AT9: FX | AU9: Tra_EV_Batt-LFP_virgin | AV9: TRADST | AW9: =AW19/1000 -> 0.0952
M16: =T65 -> 76.8 | S16: =U65 -> 71.3 | Y16: =V65 -> 71.2 | AE16: =W65 -> 72.5 | AK16: =X65 -> 77 | AQ16: =Y65 -> 42.4 | AW16: =Z65 -> 47.2
M17: =T66 -> 202.6 | S17: =U66 -> 191.3 | Y17: =V66 -> 191.5 | AE17: =W66 -> 185.9 | AK17: =X66 -> 198.2 | AQ17: =Y66 -> 76.8 | AW17: =Z66 -> 155.5
M18: =T67 -> 583.8 | S18: =U67 -> 556.1 | Y18: =V67 -> 557.9 | AE18: =W67 -> 550.5 | AK18: =X67 -> 594.2 | AQ18: =Y67 -> 409.9 | AW18: =Z67 -> 477
M19: =T68 -> 127.5 | S19: =U68 -> 133.7 | Y19: =V68 -> 140.3 | AE19: =W68 -> 149.9 | AK19: =X68 -> 160.8 | AQ19: =Y68 -> 57 | AW19: =Z68 -> 95.2
L24: ~TFM_UPD: attribute= INPUT | R24: ~TFM_UPD: attribute= INPUT | X24: ~TFM_UPD: attribute= INPUT | AD24: ~TFM_UPD: attribute= INPUT | AJ24: ~TFM_UPD: attribute= INPUT | AP24: ~TFM_UPD: attribute= INPUT | AV24: ~TFM_UPD: attribute= INPUT
J25: limtype | K25: process | L25: cset_cn | M25: China | P25: limtype | Q25: process | R25: cset_cn | S25: China | V25: limtype | W25: process | X25: cset_cn | Y25: China | AB25: limtype | AC25: process | AD25: cset_cn | AE25: China | AH25: limtype | AI25: process | AJ25: cset_cn | AK25: China | AN25: limtype | AO25: process | AP25: cset_cn | AQ25: China | AT25: limtype | AU25: process | AV25: cset_cn | AW25: China
J26: FX | K26: =K6 -> Tra_EV_Batt-NMC 111_virgin | L26: ELC | M26: =T73/1000 -> 0.0774 | P26: FX | Q26: =Q6 -> Tra_EV_Batt-NMC532_virgin | R26: ELC | S26: =S32/1000 -> 0.072 | V26: FX | W26: =W6 -> Tra_EV_Batt-NMC 622_virgin | X26: ELC | Y26: =Y32/1000 -> 0.0719 | AB26: FX | AC26: =AC6 -> Tra_EV_Batt-NMC 811_virgin | AD26: ELC | AE26: =AE32/1000 -> 0.0731 | AH26: FX | AI26: =AI6 -> Tra_EV_Batt-NCA_virgin | AJ26: ELC | AK26: =AK32/1000 -> 0.0777 | AN26: FX | AO26: =AO6 -> Tra_EV_Batt-LMO_virgin | AP26: ELC | AQ26: =AQ32/1000 -> 0.0431 | AT26: FX | AU26: =AU6 -> Tra_EV_Batt-LFP_virgin | AV26: ELC | AW26: =AW32/1000 -> 0.0478
J27: FX | K27: =K7 -> Tra_EV_Batt-NMC 111_virgin | L27: TRACOA | M27: =T74/1000 -> 0.2366 | P27: FX | Q27: =Q7 -> Tra_EV_Batt-NMC532_virgin | R27: TRACOA | S27: =S33/1000 -> 0.2252 | V27: FX | W27: =W7 -> Tra_EV_Batt-NMC 622_virgin | X27: TRACOA | Y27: =Y33/1000 -> 0.2255 | AB27: FX | AC27: =AC7 -> Tra_EV_Batt-NMC 811_virgin | AD27: TRACOA | AE27: =AE33/1000 -> 0.2198 | AH27: FX | AI27: =AI7 -> Tra_EV_Batt-NCA_virgin | AJ27: TRACOA | AK27: =AK33/1000 -> 0.2322 | AN27: FX | AO27: =AO7 -> Tra_EV_Batt-LMO_virgin | AP27: TRACOA | AQ27: =AQ33/1000 -> 0.1108 | AT27: FX | AU27: =AU7 -> Tra_EV_Batt-LFP_virgin | AV27: TRACOA | AW27: =AW33/1000 -> 0.1895
J28: FX | K28: =K8 -> Tra_EV_Batt-NMC 111_virgin | L28: TRANGA | M28: =T75/1000 -> 0.5598 | P28: FX | Q28: =Q8 -> Tra_EV_Batt-NMC532_virgin | R28: TRANGA | S28: =S34/1000 -> 0.5321 | V28: FX | W28: =W8 -> Tra_EV_Batt-NMC 622_virgin | X28: TRANGA | Y28: =Y34/1000 -> 0.5339 | AB28: FX | AC28: =AC8 -> Tra_EV_Batt-NMC 811_virgin | AD28: TRANGA | AE28: =AE34/1000 -> 0.5264 | AH28: FX | AI28: =AI8 -> Tra_EV_Batt-NCA_virgin | AJ28: TRANGA | AK28: =AK34/1000 -> 0.5702 | AN28: FX | AO28: =AO8 -> Tra_EV_Batt-LMO_virgin | AP28: TRANGA | AQ28: =AQ34/1000 -> 0.3858 | AT28: FX | AU28: =AU8 -> Tra_EV_Batt-LFP_virgin | AV28: TRANGA | AW28: =AW34/1000 -> 0.453
J29: FX | K29: =K9 -> Tra_EV_Batt-NMC 111_virgin | L29: TRADST | M29: =T76/1000 -> 0.1277 | P29: FX | Q29: =Q9 -> Tra_EV_Batt-NMC532_virgin | R29: TRADST | S29: =S35/1000 -> 0.134 | V29: FX | W29: =W9 -> Tra_EV_Batt-NMC 622_virgin | X29: TRADST | Y29: =Y35/1000 -> 0.1406 | AB29: FX | AC29: =AC9 -> Tra_EV_Batt-NMC 811_virgin | AD29: TRADST | AE29: =AE35/1000 -> 0.1502 | AH29: FX | AI29: =AI9 -> Tra_EV_Batt-NCA_virgin | AJ29: TRADST | AK29: =AK35/1000 -> 0.1611 | AN29: FX | AO29: =AO9 -> Tra_EV_Batt-LMO_virgin | AP29: TRADST | AQ29: =AQ35/1000 -> 0.0572 | AT29: FX | AU29: =AU9 -> Tra_EV_Batt-LFP_virgin | AV29: TRADST | AW29: =AW35/1000 -> 0.0955
S32: =U73 -> 72 | Y32: =V73 -> 71.9 | AE32: =W73 -> 73.1 | AK32: =X73 -> 77.7 | AQ32: =Y73 -> 43.1 | AW32: =Z73 -> 47.8
S33: =U74 -> 225.2 | Y33: =V74 -> 225.5 | AE33: =W74 -> 219.8 | AK33: =X74 -> 232.2 | AQ33: =Y74 -> 110.8 | AW33: =Z74 -> 189.5
S34: =U75 -> 532.1 | Y34: =V75 -> 533.9 | AE34: =W75 -> 526.4 | AK34: =X75 -> 570.2 | AQ34: =Y75 -> 385.8 | AW34: =Z75 -> 453
S35: =U76 -> 134 | Y35: =V76 -> 140.6 | AE35: =W76 -> 150.2 | AK35: =X76 -> 161.1 | AQ35: =Y76 -> 57.2 | AW35: =Z76 -> 95.5
Q42: Original data_provided by Anna
Q43: Location | R43: Energy use (MJ/kWh battery produced) | S43: Chemistry
S44: LCO | T44: NMC111 | U44: NMC532 | V44: NMC622 | W44: NMC811 | X44: NCA | Y44: LMO | Z44: LFP
Q45: US | R45: Total Energy | S45: 1211.3 | T45: 990.7 | U45: 952.4 | V45: 961 | W45: 958.7 | X45: 1030.2 | Y45: 586.1 | Z45: 775
R46: Fossil fuels | S46: 1103.7 | T46: 913.9 | U46: 881.1 | V46: 889.8 | W46: 886.2 | X46: 953.2 | Y46: 543.7 | Z46: 727.8
R47: Coal | S47: 267.3 | T47: 202.6 | U47: 191.3 | V47: 191.5 | W47: 185.9 | X47: 198.2 | Y47: 76.8 | Z47: 155.5
R48: Natural gas | S48: 692.5 | T48: 583.8 | U48: 556.1 | V48: 557.9 | W48: 550.5 | X48: 594.2 | Y48: 409.9 | Z48: 477
R49: Petroleum | S49: 144 | T49: 127.5 | U49: 133.7 | V49: 140.3 | W49: 149.9 | X49: 160.8 | Y49: 57 | Z49: 95.2
Q50: Korea | R50: Total Energy | S50: 1217.1 | T50: 996.4 | U50: 958.2 | V50: 966.8 | W50: 964.4 | X50: 1036 | Y50: 591.9 | Z50: 780.8
R51: Fossil fuels | S51: 1109.8 | T51: 920 | U51: 887.2 | V51: 895.9 | W51: 892.3 | X51: 959.3 | Y51: 549.8 | Z51: 733.9
R52: Coal | S52: 280.2 | T52: 215.6 | U52: 204.2 | V52: 204.5 | W52: 198.8 | X52: 211.1 | Y52: 89.8 | Z52: 168.5
R53: Natural gas | S53: 684.6 | T53: 575.9 | U53: 548.2 | V53: 550 | W53: 542.6 | X53: 586.3 | Y53: 402 | Z53: 469.1
R54: Petroleum | S54: 145 | T54: 128.5 | U54: 134.7 | V54: 141.3 | W54: 150.9 | X54: 161.9 | Y54: 58 | Z54: 96.3
Q55: China | R55: Total Energy | S55: 1222.2 | T55: 1001.5 | U55: 963.3 | V55: 971.9 | W55: 969.5 | X55: 1041.1 | Y55: 597 | Z55: 785.8
R56: Fossil fuels | S56: 1113.9 | T56: 924.1 | U56: 891.3 | V56: 900 | W56: 896.4 | X56: 963.4 | Y56: 553.9 | Z56: 738
R57: Coal | S57: 301.2 | T57: 236.6 | U57: 225.2 | V57: 225.5 | W57: 219.8 | X57: 232.2 | Y57: 110.8 | Z57: 189.5
R58: Natural gas | S58: 668.4 | T58: 559.8 | U58: 532.1 | V58: 533.9 | W58: 526.4 | X58: 570.2 | Y58: 385.8 | Z58: 453
R59: Petroleum | S59: 144.2 | T59: 127.7 | U59: 134 | V59: 140.6 | W59: 150.2 | X59: 161.1 | Y59: 57.2 | Z59: 95.5
Q61: ** Assumed to be cell manufacturing
S64: LCO | T64: NMC111 | U64: NMC532 | V64: NMC622 | W64: NMC811 | X64: NCA | Y64: LMO | Z64: LFP
...

Sheet added_energyUse_for_US_1.0
A1: Pyrometallurgical | L1: ktonne/GWh | W1: if energy use for LFP and LMO=1.0*that for NMC611 | AB1: Fill the data gap of EverBatt, by using a sensitivity analysis | AF1: if energy use for LFP and LMO=1.15*that for NMC611 | AO1: if energy use for LFP and LMO=0.85*that for NMC611 | AZ1: Pyrometallurgical
A2: Location | B2: Energy use (PJ/GWh battery produced) | C2: Chemistry | V2: INPUT | AZ2: Location | BA2: Energy use (PJ/GWh battery produced) | BB2: Chemistry
C3: LCO | D3: NMC111 | E3: NMC532 | F3: NMC622 | G3: NMC811 | H3: NCA | I3: LMO | J3: LFP | L3: LCO | M3: NMC111 | N3: NMC532 | O3: NMC622 | P3: NMC811 | Q3: NCA | R3: LMO | S3: LFP | V3: PJ/ktonne | W3: NMC111 | X3: NMC532 | Y3: NMC622 | Z3: NMC811 | AA3: NCA | AB3: LMO | AC3: LFP | AF3: NMC111 | AG3: NMC532 | AH3: NMC622 | AI3: NMC811 | AJ3: NCA | AK3: LMO | AL3: LFP | AO3: NMC111 | AP3: NMC532 | AQ3: NMC622 | AR3: NMC811 | AS3: NCA | AT3: LMO | AU3: LFP | BB3: LCO | BC3: NMC111 | BD3: NMC532 | BE3: NMC622 | BF3: NMC811 | BG3: NCA | BH3: LMO | BI3: LFP
A4: US | B4: Total Energy | C4: =BB4/1000 -> 0.8374 | D4: =BC4/1000 -> 0.8081 | E4: =BD4/1000 -> 0.7705 | F4: =BE4/1000 -> 0.76 | G4: =BF4/1000 -> 0.7551 | H4: =BG4/1000 -> 0.796 | I4: =BH4/1000 -> 0.76 | J4: =BI4/1000 -> 0.76 | M4: 5.937 | N4: 5.845 | O4: 5.575 | P4: 5.276 | Q4: 5.363 | R4: 6.645 | S4: 5.654 | U4: US | V4: Total Energy | W4: =D4/M4 -> 0.13611251 | X4: =E4/N4 -> 0.13182207 | Y4: =F4/O4 -> 0.13632287 | Z4: =G4/P4 -> 0.14311979 | AA4: =H4/Q4 -> 0.14842439 | AB4: =I4/R4 -> 0.11437171 | AC4: =J4/S4 -> 0.13441811 | AF4: =W4 -> 0.13611251 | AG4: =X4 -> 0.13182207 | AH4: =Y4 -> 0.13632287 | AI4: =Z4 -> 0.14311979 | AJ4: =AA4 -> 0.14842439 | AK4: =AB4*1.15 -> 0.13152746 | AL4: =AC4*1.15 -> 0.15458083 | AO4: =W4 -> 0.13611251 | AP4: =X4 -> 0.13182207 | AQ4: =Y4 -> 0.13632287 | AR4: =Z4 -> 0.14311979 | AS4: =AA4 -> 0.14842439 | AT4: =AB4*0.85 -> 0.097215952 | AU4: =AC4*0.85 -> 0.11425539 | AZ4: US | BA4: Total Energy | BB4: 837.4 | BC4: 808.1 | BD4: 770.5 | BE4: 760 | BF4: 755.1 | BG4: 796 | BH4: 760 | BI4: 760
B5: Fossil fuels | C5: =BB5/1000 -> 0.7701 | D5: =BC5/1000 -> 0.7457 | E5: =BD5/1000 -> 0.7115 | F5: =BE5/1000 -> 0.7021 | G5: =BF5/1000 -> 0.6948 | H5: =BG5/1000 -> 0.7338 | I5: =BH5/1000 -> 0.7021 | J5: =BI5/1000 -> 0.7021 | M5: 5.937 | N5: 5.845 | O5: 5.575 | P5: 5.276 | Q5: 5.363 | R5: 6.645 | S5: 5.654 | V5: Fossil fuels | W5: =D5/M5 -> 0.12560216 | X5: =E5/N5 -> 0.12172797 | Y5: =F5/O5 -> 0.12593722 | Z5: =G5/P5 -> 0.13169067 | AA5: =H5/Q5 -> 0.1368264 | AB5: =I5/R5 -> 0.10565839 | AC5: =J5/S5 -> 0.12417757 | AF5: =W5 -> 0.12560216 | AG5: =X5 -> 0.12172797 | AH5: =Y5 -> 0.12593722 | AI5: =Z5 -> 0.13169067 | AJ5: =AA5 -> 0.1368264 | AK5: =AB5*1.15 -> 0.12150715 | AL5: =AC5*1.15 -> 0.14280421 | AO5: =W5 -> 0.12560216 | AP5: =X5 -> 0.12172797 | AQ5: =Y5 -> 0.12593722 | AR5: =Z5 -> 0.13169067 | AS5: =AA5 -> 0.1368264 | AT5: =AB5*0.85 -> 0.089809631 | AU5: =AC5*0.85 -> 0.10555094 | BA5: Fossil fuels | BB5: 770.1 | BC5: 745.7 | BD5: 711.5 | BE5: 702.1 | BF5: 694.8 | BG5: 733.8 | BH5: 702.1 | BI5: 702.1
B6: Coal | C6: =BB6/1000 -> 0.1986 | D6: =BC6/1000 -> 0.1717 | E6: =BD6/1000 -> 0.1611 | F6: =BE6/1000 -> 0.1579 | G6: =BF6/1000 -> 0.1521 | H6: =BG6/1000 -> 0.1588 | I6: =BH6/1000 -> 0.1579 | J6: =BI6/1000 -> 0.1579 | M6: 5.937 | N6: 5.845 | O6: 5.575 | P6: 5.276 | Q6: 5.363 | R6: 6.645 | S6: 5.654 | V6: Coal | W6: =D6/M6 -> 0.02892033 | X6: =E6/N6 -> 0.027562019 | Y6: =F6/O6 -> 0.02832287 | Z6: =G6/P6 -> 0.028828658 | AA6: =H6/Q6 -> 0.029610293 | AB6: =I6/R6 -> 0.023762227 | AC6: =J6/S6 -> 0.027927131 | AF6: =W6 -> 0.02892033 | AG6: =X6 -> 0.027562019 | AH6: =Y6 -> 0.02832287 | AI6: =Z6 -> 0.028828658 | AJ6: =AA6 -> 0.029610293 | AK6: =AB6*1.15 -> 0.027326561 | AL6: =AC6*1.15 -> 0.032116201 | AO6: =W6 -> 0.02892033 | AP6: =X6 -> 0.027562019 | AQ6: =Y6 -> 0.02832287 | AR6: =Z6 -> 0.028828658 | AS6: =AA6 -> 0.029610293 | AT6: =AB6*0.85 -> 0.020197893 | AU6: =AC6*0.85 -> 0.023738062 | BA6: Coal | BB6: 198.6 | BC6: 171.7 | BD6: 161.1 | BE6: 157.9 | BF6: 152.1 | BG6: 158.8 | BH6: 157.9 | BI6: 157.9
B7: Natural gas | C7: =BB7/1000 -> 0.487 | D7: =BC7/1000 -> 0.4967 | E7: =BD7/1000 -> 0.4758 | F7: =BE7/1000 -> 0.4705 | G7: =BF7/1000 -> 0.4665 | H7: =BG7/1000 -> 0.496 | I7: =BH7/1000 -> 0.4705 | J7: =BI7/1000 -> 0.4705 | M7: 5.937 | N7: 5.845 | O7: 5.575 | P7: 5.276 | Q7: 5.363 | R7: 6.645 | S7: 5.654 | V7: Natural gas | W7: =D7/M7 -> 0.083661782 | X7: =E7/N7 -> 0.081402908 | Y7: =F7/O7 -> 0.084394619 | Z7: =G7/P7 -> 0.088419257 | AA7: =H7/Q7 -> 0.092485549 | AB7: =I7/R7 -> 0.070805117 | AC7: =J7/S7 -> 0.083215423 | AF7: =W7 -> 0.083661782 | AG7: =X7 -> 0.081402908 | AH7: =Y7 -> 0.084394619 | AI7: =Z7 -> 0.088419257 | AJ7: =AA7 -> 0.092485549 | AK7: =AB7*1.15 -> 0.081425884 | AL7: =AC7*1.15 -> 0.095697736 | AO7: =W7 -> 0.083661782 | AP7: =X7 -> 0.081402908 | AQ7: =Y7 -> 0.084394619 | AR7: =Z7 -> 0.088419257 | AS7: =AA7 -> 0.092485549 | AT7: =AB7*0.85 -> 0.060184349 | AU7: =AC7*0.85 -> 0.070733109 | BA7: Natural gas | BB7: 487 | BC7: 496.7 | BD7: 475.8 | BE7: 470.5 | BF7: 466.5 | BG7: 496 | BH7: 470.5 | BI7: 470.5
B8: Petroleum | C8: =BB8/1000 -> 0.0845 | D8: =BC8/1000 -> 0.0773 | E8: =BD8/1000 -> 0.0745 | F8: =BE8/1000 -> 0.0736 | G8: =BF8/1000 -> 0.0761 | H8: =BG8/1000 -> 0.0789 | I8: =BH8/1000 -> 0.0736 | J8: =BI8/1000 -> 0.0736 | M8: 5.937 | N8: 5.845 | O8: 5.575 | P8: 5.276 | Q8: 5.363 | R8: 6.645 | S8: 5.654 | V8: Petroleum | W8: =D8/M8 -> 0.013020044 | X8: =E8/N8 -> 0.012745937 | Y8: =F8/O8 -> 0.013201794 | Z8: =G8/P8 -> 0.014423806 | AA8: =H8/Q8 -> 0.014711915 | AB8: =I8/R8 -> 0.011075997 | AC8: =J8/S8 -> 0.013017333 | AF8: =W8 -> 0.013020044 | AG8: =X8 -> 0.012745937 | AH8: =Y8 -> 0.013201794 | AI8: =Z8 -> 0.014423806 | AJ8: =AA8 -> 0.014711915 | AK8: =AB8*1.15 -> 0.012737397 | AL8: =AC8*1.15 -> 0.014969933 | AO8: =W8 -> 0.013020044 | AP8: =X8 -> 0.012745937 | AQ8: =Y8 -> 0.013201794 | AR8: =Z8 -> 0.014423806 | AS8: =AA8 -> 0.014711915 | AT8: =AB8*0.85 -> 0.0094145974 | AU8: =AC8*0.85 -> 0.011064733 | BA8: Petroleum | BB8: 84.5 | BC8: 77.3 | BD8: 74.5 | BE8: 73.6 | BF8: 76.1 | BG8: 78.9 | BH8: 73.6 | BI8: 73.6
A9: Korea | B9: Total Energy | C9: =BB9/1000 -> 0.855 | D9: =BC9/1000 -> 0.8241 | E9: =BD9/1000 -> 0.7857 | F9: =BE9/1000 -> 0.775 | G9: =BF9/1000 -> 0.7702 | H9: =BG9/1000 -> 0.8116 | I9: =BH9/1000 -> 0.775 | J9: =BI9/1000 -> 0.775 | M9: 5.937 | N9: 5.845 | O9: 5.575 | P9: 5.276 | Q9: 5.363 | R9: 6.645 | S9: 5.654 | U9: Korea | V9: Total Energy | W9: =D9/M9 -> 0.13880748 | X9: =E9/N9 -> 0.13442258 | Y9: =F9/O9 -> 0.13901345 | Z9: =G9/P9 -> 0.1459818 | AA9: =H9/Q9 -> 0.15133321 | AB9: =I9/R9 -> 0.11662904 | AC9: =J9/S9 -> 0.1370711 | AF9: =W9 -> 0.13880748 | AG9: =X9 -> 0.13442258 | AH9: =Y9 -> 0.13901345 | AI9: =Z9 -> 0.1459818 | AJ9: =AA9 -> 0.15133321 | AK9: =AB9*1.15 -> 0.1341234 | AL9: =AC9*1.15 -> 0.15763177 | AO9: =W9 -> 0.13880748 | AP9: =X9 -> 0.13442258 | AQ9: =Y9 -> 0.13901345 | AR9: =Z9 -> 0.1459818 | AS9: =AA9 -> 0.15133321 | AT9: =AB9*0.85 -> 0.099134688 | AU9: =AC9*0.85 -> 0.11651044 | AZ9: Korea | BA9: Total Energy | BB9: 855 | BC9: 824.1 | BD9: 785.7 | BE9: 775 | BF9: 770.2 | BG9: 811.6 | BH9: 775 | BI9: 775
B10: Fossil fuels | C10: =BB10/1000 -> 0.7888 | D10: =BC10/1000 -> 0.7626 | E10: =BD10/1000 -> 0.7275 | F10: =BE10/1000 -> 0.7179 | G10: =BF10/1000 -> 0.7107 | H10: =BG10/1000 -> 0.7503 | I10: =BH10/1000 -> 0.7179 | J10: =BI10/1000 -> 0.7179 | M10: 5.937 | N10: 5.845 | O10: 5.575 | P10: 5.276 | Q10: 5.363 | R10: 6.645 | S10: 5.654 | V10: Fossil fuels | W10: =D10/M10 -> 0.12844871 | X10: =E10/N10 -> 0.12446536 | Y10: =F10/O10 -> 0.1287713 | Z10: =G10/P10 -> 0.13470432 | AA10: =H10/Q10 -> 0.13990304 | AB10: =I10/R10 -> 0.10803612 | AC10: =J10/S10 -> 0.12697206 | AF10: =W10 -> 0.12844871 | AG10: =X10 -> 0.12446536 | AH10: =Y10 -> 0.1287713 | AI10: =Z10 -> 0.13470432 | AJ10: =AA10 -> 0.13990304 | AK10: =AB10*1.15 -> 0.12424153 | AL10: =AC10*1.15 -> 0.14601786 | AO10: =W10 -> 0.12844871 | AP10: =X10 -> 0.12446536 | AQ10: =Y10 -> 0.1287713 | AR10: =Z10 -> 0.13470432 | AS10: =AA10 -> 0.13990304 | AT10: =AB10*0.85 -> 0.0918307 | AU10: =AC10*0.85 -> 0.10792625 | BA10: Fossil fuels | BB10: 788.8 | BC10: 762.6 | BD10: 727.5 | BE10: 717.9 | BF10: 710.7 | BG10: 750.3 | BH10: 717.9 | BI10: 717.9
B11: Coal | C11: =BB11/1000 -> 0.2381 | D11: =BC11/1000 -> 0.2075 | E11: =BD11/1000 -> 0.1951 | F11: =BE11/1000 -> 0.1916 | G11: =BF11/1000 -> 0.186 | H11: =BG11/1000 -> 0.1938 | I11: =BH11/1000 -> 0.1916 | J11: =BI11/1000 -> 0.1916 | M11: 5.937 | N11: 5.845 | O11: 5.575 | P11: 5.276 | Q11: 5.363 | R11: 6.645 | S11: 5.654 | V11: Coal | W11: =D11/M11 -> 0.034950312 | X11: =E11/N11 -> 0.033378956 | Y11: =F11/O11 -> 0.034367713 | Z11: =G11/P11 -> 0.03525398 | AA11: =H11/Q11 -> 0.036136491 | AB11: =I11/R11 -> 0.02883371 | AC11: =J11/S11 -> 0.033887513 | AF11: =W11 -> 0.034950312 | AG11: =X11 -> 0.033378956 | AH11: =Y11 -> 0.034367713 | AI11: =Z11 -> 0.03525398 | AJ11: =AA11 -> 0.036136491 | AK11: =AB11*1.15 -> 0.033158766 | AL11: =AC11*1.15 -> 0.03897064 | AO11: =W11 -> 0.034950312 | AP11: =X11 -> 0.033378956 | AQ11: =Y11 -> 0.034367713 | AR11: =Z11 -> 0.03525398 | AS11: =AA11 -> 0.036136491 | AT11: =AB11*0.85 -> 0.024508653 | AU11: =AC11*0.85 -> 0.028804386 | BA11: Coal | BB11: 238.1 | BC11: 207.5 | BD11: 195.1 | BE11: 191.6 | BF11: 186 | BG11: 193.8 | BH11: 191.6 | BI11: 191.6
B12: Natural gas | C12: =BB12/1000 -> 0.4629 | D12: =BC12/1000 -> 0.4749 | E12: =BD12/1000 -> 0.4551 | F12: =BE12/1000 -> 0.45 | G12: =BF12/1000 -> 0.4459 | H12: =BG12/1000 -> 0.4747 | I12: =BH12/1000 -> 0.45 | J12: =BI12/1000 -> 0.45 | M12: 5.937 | N12: 5.845 | O12: 5.575 | P12: 5.276 | Q12: 5.363 | R12: 6.645 | S12: 5.654 | V12: Natural gas | W12: =D12/M12 -> 0.079989894 | X12: =E12/N12 -> 0.07786142 | Y12: =F12/O12 -> 0.080717489 | Z12: =G12/P12 -> 0.084514784 | AA12: =H12/Q12 -> 0.088513891 | AB12: =I12/R12 -> 0.06772009 | AC12: =J12/S12 -> 0.079589671 | AF12: =W12 -> 0.079989894 | AG12: =X12 -> 0.07786142 | AH12: =Y12 -> 0.080717489 | AI12: =Z12 -> 0.084514784 | AJ12: =AA12 -> 0.088513891 | AK12: =AB12*1.15 -> 0.077878104 | AL12: =AC12*1.15 -> 0.091528122 | AO12: =W12 -> 0.079989894 | AP12: =X12 -> 0.07786142 | AQ12: =Y12 -> 0.080717489 | AR12: =Z12 -> 0.084514784 | AS12: =AA12 -> 0.088513891 | AT12: =AB12*0.85 -> 0.057562077 | AU12: =AC12*0.85 -> 0.06765122 | BA12: Natural gas | BB12: 462.9 | BC12: 474.9 | BD12: 455.1 | BE12: 450 | BF12: 445.9 | BG12: 474.7 | BH12: 450 | BI12: 450
B13: Petroleum | C13: =BB13/1000 -> 0.0877 | D13: =BC13/1000 -> 0.0802 | E13: =BD13/1000 -> 0.0772 | F13: =BE13/1000 -> 0.0763 | G13: =BF13/1000 -> 0.0789 | H13: =BG13/1000 -> 0.0817 | I13: =BH13/1000 -> 0.0763 | J13: =BI13/1000 -> 0.0763 | M13: 5.937 | N13: 5.845 | O13: 5.575 | P13: 5.276 | Q13: 5.363 | R13: 6.645 | S13: 5.654 | V13: Petroleum | W13: =D13/M13 -> 0.013508506 | X13: =E13/N13 -> 0.01320787 | Y13: =F13/O13 -> 0.013686099 | Z13: =G13/P13 -> 0.014954511 | AA13: =H13/Q13 -> 0.015234011 | AB13: =I13/R13 -> 0.011482318 | AC13: =J13/S13 -> 0.013494871 | AF13: =W13 -> 0.013508506 | AG13: =X13 -> 0.01320787 | AH13: =Y13 -> 0.013686099 | AI13: =Z13 -> 0.014954511 | AJ13: =AA13 -> 0.015234011 | AK13: =AB13*1.15 -> 0.013204665 | AL13: =AC13*1.15 -> 0.015519102 | AO13: =W13 -> 0.013508506 | AP13: =X13 -> 0.01320787 | AQ13: =Y13 -> 0.013686099 | AR13: =Z13 -> 0.014954511 | AS13: =AA13 -> 0.015234011 | AT13: =AB13*0.85 -> 0.0097599699 | AU13: =AC13*0.85 -> 0.01147064 | BA13: Petroleum | BB13: 87.7 | BC13: 80.2 | BD13: 77.2 | BE13: 76.3 | BF13: 78.9 | BG13: 81.7 | BH13: 76.3 | BI13: 76.3
A14: China | B14: Total Energy | C14: =BB14/1000 -> 0.8705 | D14: =BC14/1000 -> 0.8381 | E14: =BD14/1000 -> 0.799 | F14: =BE14/1000 -> 0.7882 | G14: =BF14/1000 -> 0.7835 | H14: =BG14/1000 -> 0.8253 | I14: =BH14/1000 -> 0.7882 | J14: =BI14/1000 -> 0.7882 | M14: 5.937 | N14: 5.845 | O14: 5.575 | P14: 5.276 | Q14: 5.363 | R14: 6.645 | S14: 5.654 | U14: China | V14: Total Energy | W14: =D14/M14 -> 0.14116557 | X14: =E14/N14 -> 0.13669803 | Y14: =F14/O14 -> 0.14138117 | Z14: =G14/P14 -> 0.14850265 | AA14: =H14/Q14 -> 0.15388775 | AB14: =I14/R14 -> 0.1186155 | AC14: =J14/S14 -> 0.13940573 | AF14: =W14 -> 0.14116557 | AG14: =X14 -> 0.13669803 | AH14: =Y14 -> 0.14138117 | AI14: =Z14 -> 0.14850265 | AJ14: =AA14 -> 0.15388775 | AK14: =AB14*1.15 -> 0.13640783 | AL14: =AC14*1.15 -> 0.16031659 | AO14: =W14 -> 0.14116557 | AP14: =X14 -> 0.13669803 | AQ14: =Y14 -> 0.14138117 | AR14: =Z14 -> 0.14850265 | AS14: =AA14 -> 0.15388775 | AT14: =AB14*0.85 -> 0.10082318 | AU14: =AC14*0.85 -> 0.11849487 | AZ14: China | BA14: Total Energy | BB14: 870.5 | BC14: 838.1 | BD14: 799 | BE14: 788.2 | BF14: 783.5 | BG14: 825.3 | BH14: 788.2 | BI14: 788.2
B15: Fossil fuels | C15: =BB15/1000 -> 0.8012 | D15: =BC15/1000 -> 0.7738 | E15: =BD15/1000 -> 0.7382 | F15: =BE15/1000 -> 0.7285 | G15: =BF15/1000 -> 0.7214 | H15: =BG15/1000 -> 0.7613 | I15: =BH15/1000 -> 0.7285 | J15: =BI15/1000 -> 0.7285 | M15: 5.937 | N15: 5.845 | O15: 5.575 | P15: 5.276 | Q15: 5.363 | R15: 6.645 | S15: 5.654 | V15: Fossil fuels | W15: =D15/M15 -> 0.13033519 | X15: =E15/N15 -> 0.12629598 | Y15: =F15/O15 -> 0.13067265 | Z15: =G15/P15 -> 0.13673237 | AA15: =H15/Q15 -> 0.14195413 | AB15: =I15/R15 -> 0.1096313 | AC15: =J15/S15 -> 0.12884683 | AF15: =W15 -> 0.13033519 | AG15: =X15 -> 0.12629598 | AH15: =Y15 -> 0.13067265 | AI15: =Z15 -> 0.13673237 | AJ15: =AA15 -> 0.14195413 | AK15: =AB15*1.15 -> 0.126076 | AL15: =AC15*1.15 -> 0.14817386 | AO15: =W15 -> 0.13033519 | AP15: =X15 -> 0.12629598 | AQ15: =Y15 -> 0.13067265 | AR15: =Z15 -> 0.13673237 | AS15: =AA15 -> 0.14195413 | AT15: =AB15*0.85 -> 0.093186606 | AU15: =AC15*0.85 -> 0.10951981 | BA15: Fossil fuels | BB15: 801.2 | BC15: 773.8 | BD15: 738.2 | BE15: 728.5 | BF15: 721.4 | BG15: 761.3 | BH15: 728.5 | BI15: 728.5
B16: Coal | C16: =BB16/1000 -> 0.3021 | D16: =BC16/1000 -> 0.2654 | E16: =BD16/1000 -> 0.2502 | F16: =BE16/1000 -> 0.246 | G16: =BF16/1000 -> 0.2408 | H16: =BG16/1000 -> 0.2506 | I16: =BH16/1000 -> 0.246 | J16: =BI16/1000 -> 0.246 | M16: 5.937 | N16: 5.845 | O16: 5.575 | P16: 5.276 | Q16: 5.363 | R16: 6.645 | S16: 5.654 | V16: Coal | W16: =D16/M16 -> 0.044702712 | X16: =E16/N16 -> 0.042805817 | Y16: =F16/O16 -> 0.044125561 | Z16: =G16/P16 -> 0.045640637 | AA16: =H16/Q16 -> 0.046727578 | AB16: =I16/R16 -> 0.037020316 | AC16: =J16/S16 -> 0.04350902 | AF16: =W16 -> 0.044702712 | AG16: =X16 -> 0.042805817 | AH16: =Y16 -> 0.044125561 | AI16: =Z16 -> 0.045640637 | AJ16: =AA16 -> 0.046727578 | AK16: =AB16*1.15 -> 0.042573363 | AL16: =AC16*1.15 -> 0.050035373 | AO16: =W16 -> 0.044702712 | AP16: =X16 -> 0.042805817 | AQ16: =Y16 -> 0.044125561 | AR16: =Z16 -> 0.045640637 | AS16: =AA16 -> 0.046727578 | AT16: =AB16*0.85 -> 0.031467269 | AU16: =AC16*0.85 -> 0.036982667 | BA16: Coal | BB16: 302.1 | BC16: 265.4 | BD16: 250.2 | BE16: 246 | BF16: 240.8 | BG16: 250.6 | BH16: 246 | BI16: 246
B17: Natural gas | C17: =BB17/1000 -> 0.4137 | D17: =BC17/1000 -> 0.4304 | E17: =BD17/1000 -> 0.4127 | F17: =BE17/1000 -> 0.4081 | G17: =BF17/1000 -> 0.4037 | H17: =BG17/1000 -> 0.4311 | I17: =BH17/1000 -> 0.4081 | J17: =BI17/1000 -> 0.4081 | M17: 5.937 | N17: 5.845 | O17: 5.575 | P17: 5.276 | Q17: 5.363 | R17: 6.645 | S17: 5.654 | V17: Natural gas | W17: =D17/M17 -> 0.072494526 | X17: =E17/N17 -> 0.070607357 | Y17: =F17/O17 -> 0.073201794 | Z17: =G17/P17 -> 0.0765163 | AA17: =H17/Q17 -> 0.080384113 | AB17: =I17/R17 -> 0.061414597 | AC17: =J17/S17 -> 0.072178988 | AF17: =W17 -> 0.072494526 | AG17: =X17 -> 0.070607357 | AH17: =Y17 -> 0.073201794 | AI17: =Z17 -> 0.0765163 | AJ17: =AA17 -> 0.080384113 | AK17: =AB17*1.15 -> 0.070626787 | AL17: =AC17*1.15 -> 0.083005837 | AO17: =W17 -> 0.072494526 | AP17: =X17 -> 0.070607357 | AQ17: =Y17 -> 0.073201794 | AR17: =Z17 -> 0.0765163 | AS17: =AA17 -> 0.080384113 | AT17: =AB17*0.85 -> 0.052202408 | AU17: =AC17*0.85 -> 0.06135214 | BA17: Natural gas | BB17: 413.7 | BC17: 430.4 | BD17: 412.7 | BE17: 408.1 | BF17: 403.7 | BG17: 431.1 | BH17: 408.1 | BI17: 408.1
B18: Petroleum | C18: =BB18/1000 -> 0.0853 | D18: =BC18/1000 -> 0.0781 | E18: =BD18/1000 -> 0.0752 | F18: =BE18/1000 -> 0.0743 | G18: =BF18/1000 -> 0.0768 | H18: =BG18/1000 -> 0.0797 | I18: =BH18/1000 -> 0.0743 | J18: =BI18/1000 -> 0.0743 | M18: 5.937 | N18: 5.845 | O18: 5.575 | P18: 5.276 | Q18: 5.363 | R18: 6.645 | S18: 5.654 | V18: Petroleum | W18: =D18/M18 -> 0.013154792 | X18: =E18/N18 -> 0.012865697 | Y18: =F18/O18 -> 0.013327354 | Z18: =G18/P18 -> 0.014556482 | AA18: =H18/Q18 -> 0.014861085 | AB18: =I18/R18 -> 0.011181339 | AC18: =J18/S18 -> 0.013141139 | AF18: =W18 -> 0.013154792 | AG18: =X18 -> 0.012865697 | AH18: =Y18 -> 0.013327354 | AI18: =Z18 -> 0.014556482 | AJ18: =AA18 -> 0.014861085 | AK18: =AB18*1.15 -> 0.01285854 | AL18: =AC18*1.15 -> 0.01511231 | AO18: =W18 -> 0.013154792 | AP18: =X18 -> 0.012865697 | AQ18: =Y18 -> 0.013327354 | AR18: =Z18 -> 0.014556482 | AS18: =AA18 -> 0.014861085 | AT18: =AB18*0.85 -> 0.0095041384 | AU18: =AC18*0.85 -> 0.011169968 | BA18: Petroleum | BB18: 85.3 | BC18: 78.1 | BD18: 75.2 | BE18: 74.3 | BF18: 76.8 | BG18: 79.7 | BH18: 74.3 | BI18: 74.3
A21: Hydrometallurgical | AZ21: Hydrometallurgical
A22: Location | B22: Energy use (MJ/kWh battery produced) | C22: Chemistry | AZ22: Location | BA22: Energy use (MJ/kWh battery produced) | BB22: Chemistry
C23: LCO | D23: NMC111 | E23: NMC532 | F23: NMC622 | G23: NMC811 | H23: NCA | I23: LMO | J23: LFP | M23: NMC111 | N23: NMC532 | O23: NMC622 | P23: NMC811 | Q23: NCA | R23: LMO | S23: LFP | V23: PJ/ktonne | W23: NMC111 | X23: NMC532 | Y23: NMC622 | Z23: NMC811 | AA23: NCA | AB23: LMO | AC23: LFP | AF23: NMC111 | AG23: NMC532 | AH23: NMC622 | AI23: NMC811 | AJ23: NCA | AK23: LMO | AL23: LFP | AO23: NMC111 | AP23: NMC532 | AQ23: NMC622 | AR23: NMC811 | AS23: NCA | AT23: LMO | AU23: LFP | BB23: LCO | BC23: NMC111 | BD23: NMC532 | BE23: NMC622 | BF23: NMC811 | BG23: NCA | BH23: LMO | BI23: LFP
A24: US | B24: Total Energy | C24: =BB24/1000 -> 0.8898 | D24: =BC24/1000 -> 0.8432 | E24: =BD24/1000 -> 0.8038 | F24: =BE24/1000 -> 0.7946 | G24: =BF24/1000 -> 0.7665 | H24: =BG24/1000 -> 0.8066 | I24: =BH24/1000 -> 0.7946 | J24: =BI24/1000 -> 0.7946 | M24: 5.937 | N24: 5.845 | O24: 5.575 | P24: 5.276 | Q24: 5.363 | R24: 6.645 | S24: 5.654 | U24: US | V24: Total Energy | W24: =D24/M24 -> 0.14202459 | X24: =E24/N24 -> 0.13751925 | Y24: =F24/O24 -> 0.14252915 | Z24: =G24/P24 -> 0.14528052 | AA24: =H24/Q24 -> 0.1504009 | AB24: =I24/R24 -> 0.11957863 | AC24: =J24/S24 -> 0.14053767 | AF24: =W24 -> 0.14202459 | AG24: =X24 -> 0.13751925 | AH24: =Y24 -> 0.14252915 | AI24: =Z24 -> 0.14528052 | AJ24: =AA24 -> 0.1504009 | AK24: =AB24*1.15 -> 0.13751543 | AL24: =AC24*1.15 -> 0.16161832 | AO24: =W24 -> 0.14202459 | AP24: =X24 -> 0.13751925 | AQ24: =Y24 -> 0.14252915 | AR24: =Z24 -> 0.14528052 | AS24: =AA24 -> 0.1504009 | AT24: =AB24*0.85 -> 0.10164184 | AU24: =AC24*0.85 -> 0.11945702 | AZ24: US | BA24: Total Energy | BB24: 889.8 | BC24: 843.2 | BD24: 803.8 | BE24: 794.6 | BF24: 766.5 | BG24: 806.6 | BH24: 794.6 | BI24: 794.6
B25: Fossil fuels | C25: =BB25/1000 -> 0.8124 | D25: =BC25/1000 -> 0.7746 | E25: =BD25/1000 -> 0.739 | F25: =BE25/1000 -> 0.7307 | G25: =BF25/1000 -> 0.7045 | H25: =BG25/1000 -> 0.7424 | I25: =BH25/1000 -> 0.7307 | J25: =BI25/1000 -> 0.7307 | M25: 5.937 | N25: 5.845 | O25: 5.575 | P25: 5.276 | Q25: 5.363 | R25: 6.645 | S25: 5.654 | V25: Fossil fuels | W25: =D25/M25 -> 0.13046993 | X25: =E25/N25 -> 0.12643285 | Y25: =F25/O25 -> 0.13106726 | Z25: =G25/P25 -> 0.13352919 | AA25: =H25/Q25 -> 0.13842998 | AB25: =I25/R25 -> 0.10996238 | AC25: =J25/S25 -> 0.12923594 | AF25: =W25 -> 0.13046993 | AG25: =X25 -> 0.12643285 | AH25: =Y25 -> 0.13106726 | AI25: =Z25 -> 0.13352919 | AJ25: =AA25 -> 0.13842998 | AK25: =AB25*1.15 -> 0.12645673 | AL25: =AC25*1.15 -> 0.14862133 | AO25: =W25 -> 0.13046993 | AP25: =X25 -> 0.12643285 | AQ25: =Y25 -> 0.13106726 | AR25: =Z25 -> 0.13352919 | AS25: =AA25 -> 0.13842998 | AT25: =AB25*0.85 -> 0.093468021 | AU25: =AC25*0.85 -> 0.10985055 | BA25: Fossil fuels | BB25: 812.4 | BC25: 774.6 | BD25: 739 | BE25: 730.7 | BF25: 704.5 | BG25: 742.4 | BH25: 730.7 | BI25: 730.7
B26: Coal | C26: =BB26/1000 -> 0.1699 | D26: =BC26/1000 -> 0.1497 | E26: =BD26/1000 -> 0.1418 | F26: =BE26/1000 -> 0.1399 | G26: =BF26/1000 -> 0.1359 | H26: =BG26/1000 -> 0.1408 | I26: =BH26/1000 -> 0.1399 | J26: =BI26/1000 -> 0.1399 | M26: 5.937 | N26: 5.845 | O26: 5.575 | P26: 5.276 | Q26: 5.363 | R26: 6.645 | S26: 5.654 | V26: Coal | W26: =D26/M26 -> 0.025214755 | X26: =E26/N26 -> 0.024260051 | Y26: =F26/O26 -> 0.02509417 | Z26: =G26/P26 -> 0.02575815 | AA26: =H26/Q26 -> 0.026253962 | AB26: =I26/R26 -> 0.021053424 | AC26: =J26/S26 -> 0.024743544 | AF26: =W26 -> 0.025214755 | AG26: =X26 -> 0.024260051 | AH26: =Y26 -> 0.02509417 | AI26: =Z26 -> 0.02575815 | AJ26: =AA26 -> 0.026253962 | AK26: =AB26*1.15 -> 0.024211437 | AL26: =AC26*1.15 -> 0.028455076 | AO26: =W26 -> 0.025214755 | AP26: =X26 -> 0.024260051 | AQ26: =Y26 -> 0.02509417 | AR26: =Z26 -> 0.02575815 | AS26: =AA26 -> 0.026253962 | AT26: =AB26*0.85 -> 0.01789541 | AU26: =AC26*0.85 -> 0.021032013 | BA26: Coal | BB26: 169.9 | BC26: 149.7 | BD26: 141.8 | BE26: 139.9 | BF26: 135.9 | BG26: 140.8 | BH26: 139.9 | BI26: 139.9
B27: Natural gas | C27: =BB27/1000 -> 0.5978 | D27: =BC27/1000 -> 0.5807 | E27: =BD27/1000 -> 0.554 | F27: =BE27/1000 -> 0.5478 | G27: =BF27/1000 -> 0.526 | H27: =BG27/1000 -> 0.5575 | I27: =BH27/1000 -> 0.5478 | J27: =BI27/1000 -> 0.5478 | M27: 5.937 | N27: 5.845 | O27: 5.575 | P27: 5.276 | Q27: 5.363 | R27: 6.645 | S27: 5.654 | V27: Natural gas | W27: =D27/M27 -> 0.097810342 | X27: =E27/N27 -> 0.094781865 | Y27: =F27/O27 -> 0.09826009 | Z27: =G27/P27 -> 0.09969674 | AA27: =H27/Q27 -> 0.10395301 | AB27: =I27/R27 -> 0.082437923 | AC27: =J27/S27 -> 0.09688716 | AF27: =W27 -> 0.097810342 | AG27: =X27 -> 0.094781865 | AH27: =Y27 -> 0.09826009 | AI27: =Z27 -> 0.09969674 | AJ27: =AA27 -> 0.10395301 | AK27: =AB27*1.15 -> 0.094803612 | AL27: =AC27*1.15 -> 0.11142023 | AO27: =W27 -> 0.097810342 | AP27: =X27 -> 0.094781865 | AQ27: =Y27 -> 0.09826009 | AR27: =Z27 -> 0.09969674 | AS27: =AA27 -> 0.10395301 | AT27: =AB27*0.85 -> 0.070072235 | AU27: =AC27*0.85 -> 0.082354086 | BA27: Natural gas | BB27: 597.8 | BC27: 580.7 | BD27: 554 | BE27: 547.8 | BF27: 526 | BG27: 557.5 | BH27: 547.8 | BI27: 547.8
B28: Petroleum | C28: =BB28/1000 -> 0.085 | D28: =BC28/1000 -> 0.0786 | E28: =BD28/1000 -> 0.0763 | F28: =BE28/1000 -> 0.0759 | G28: =BF28/1000 -> 0.0737 | H28: =BG28/1000 -> 0.076 | I28: =BH28/1000 -> 0.0759 | J28: =BI28/1000 -> 0.0759 | M28: 5.937 | N28: 5.845 | O28: 5.575 | P28: 5.276 | Q28: 5.363 | R28: 6.645 | S28: 5.654 | V28: Petroleum | W28: =D28/M28 -> 0.01323901 | X28: =E28/N28 -> 0.013053892 | Y28: =F28/O28 -> 0.01361435 | Z28: =G28/P28 -> 0.013968916 | AA28: =H28/Q28 -> 0.014171173 | AB28: =I28/R28 -> 0.011422122 | AC28: =J28/S28 -> 0.013424125 | AF28: =W28 -> 0.01323901 | AG28: =X28 -> 0.013053892 | AH28: =Y28 -> 0.01361435 | AI28: =Z28 -> 0.013968916 | AJ28: =AA28 -> 0.014171173 | AK28: =AB28*1.15 -> 0.01313544 | AL28: =AC28*1.15 -> 0.015437743 | AO28: =W28 -> 0.01323901 | AP28: =X28 -> 0.013053892 | AQ28: =Y28 -> 0.01361435 | AR28: =Z28 -> 0.013968916 | AS28: =AA28 -> 0.014171173 | AT28: =AB28*0.85 -> 0.0097088036 | AU28: =AC28*0.85 -> 0.011410506 | BA28: Petroleum | BB28: 85 | BC28: 78.6 | BD28: 76.3 | BE28: 75.9 | BF28: 73.7 | BG28: 76 | BH28: 75.9 | BI28: 75.9
A29: Korea | B29: Total Energy | C29: =BB29/1000 -> 0.9068 | D29: =BC29/1000 -> 0.8586 | E29: =BD29/1000 -> 0.8184 | F29: =BE29/1000 -> 0.8091 | G29: =BF29/1000 -> 0.7811 | H29: =BG29/1000 -> 0.8217 | I29: =BH29/1000 -> 0.8091 | J29: =BI29/1000 -> 0.8091 | M29: 5.937 | N29: 5.845 | O29: 5.575 | P29: 5.276 | Q29: 5.363 | R29: 6.645 | S29: 5.654 | U29: Korea | V29: Total Energy | W29: =D29/M29 -> 0.14461849 | X29: =E29/N29 -> 0.14001711 | Y29: =F29/O29 -> 0.14513004 | Z29: =G29/P29 -> 0.14804776 | AA29: =H29/Q29 -> 0.15321648 | AB29: =I29/R29 -> 0.12176072 | AC29: =J29/S29 -> 0.14310223 | AF29: =W29 -> 0.14461849 | AG29: =X29 -> 0.14001711 | AH29: =Y29 -> 0.14513004 | AI29: =Z29 -> 0.14804776 | AJ29: =AA29 -> 0.15321648 | AK29: =AB29*1.15 -> 0.14002483 | AL29: =AC29*1.15 -> 0.16456756 | AO29: =W29 -> 0.14461849 | AP29: =X29 -> 0.14001711 | AQ29: =Y29 -> 0.14513004 | AR29: =Z29 -> 0.14804776 | AS29: =AA29 -> 0.15321648 | AT29: =AB29*0.85 -> 0.10349661 | AU29: =AC29*0.85 -> 0.12163689 | AZ29: Korea | BA29: Total Energy | BB29: 906.8 | BC29: 858.6 | BD29: 818.4 | BE29: 809.1 | BF29: 781.1 | BG29: 821.7 | BH29: 809.1 | BI29: 809.1
B30: Fossil fuels | C30: =BB30/1000 -> 0.8303 | D30: =BC30/1000 -> 0.7909 | E30: =BD30/1000 -> 0.7545 | F30: =BE30/1000 -> 0.746 | G30: =BF30/1000 -> 0.7199 | H30: =BG30/1000 -> 0.7584 | I30: =BH30/1000 -> 0.746 | J30: =BI30/1000 -> 0.746 | M30: 5.937 | N30: 5.845 | O30: 5.575 | P30: 5.276 | Q30: 5.363 | R30: 6.645 | S30: 5.654 | V30: Fossil fuels | W30: =D30/M30 -> 0.13321543 | X30: =E30/N30 -> 0.12908469 | Y30: =F30/O30 -> 0.13381166 | Z30: =G30/P30 -> 0.13644807 | AA30: =H30/Q30 -> 0.14141339 | AB30: =I30/R30 -> 0.11226486 | AC30: =J30/S30 -> 0.13194199 | AF30: =W30 -> 0.13321543 | AG30: =X30 -> 0.12908469 | AH30: =Y30 -> 0.13381166 | AI30: =Z30 -> 0.13644807 | AJ30: =AA30 -> 0.14141339 | AK30: =AB30*1.15 -> 0.12910459 | AL30: =AC30*1.15 -> 0.15173329 | AO30: =W30 -> 0.13321543 | AP30: =X30 -> 0.12908469 | AQ30: =Y30 -> 0.13381166 | AR30: =Z30 -> 0.13644807 | AS30: =AA30 -> 0.14141339 | AT30: =AB30*0.85 -> 0.095425132 | AU30: =AC30*0.85 -> 0.11215069 | BA30: Fossil fuels | BB30: 830.3 | BC30: 790.9 | BD30: 754.5 | BE30: 746 | BF30: 719.9 | BG30: 758.4 | BH30: 746 | BI30: 746
B31: Coal | C31: =BB31/1000 -> 0.2079 | D31: =BC31/1000 -> 0.1842 | E31: =BD31/1000 -> 0.1746 | F31: =BE31/1000 -> 0.1724 | G31: =BF31/1000 -> 0.1687 | H31: =BG31/1000 -> 0.1747 | I31: =BH31/1000 -> 0.1724 | J31: =BI31/1000 -> 0.1724 | M31: 5.937 | N31: 5.845 | O31: 5.575 | P31: 5.276 | Q31: 5.363 | R31: 6.645 | S31: 5.654 | V31: Coal | W31: =D31/M31 -> 0.031025771 | X31: =E31/N31 -> 0.029871685 | Y31: =F31/O31 -> 0.030923767 | Z31: =G31/P31 -> 0.031974981 | AA31: =H31/Q31 -> 0.032575051 | AB31: =I31/R31 -> 0.025944319 | AC31: =J31/S31 -> 0.030491687 | AF31: =W31 -> 0.031025771 | AG31: =X31 -> 0.029871685 | AH31: =Y31 -> 0.030923767 | AI31: =Z31 -> 0.031974981 | AJ31: =AA31 -> 0.032575051 | AK31: =AB31*1.15 -> 0.029835967 | AL31: =AC31*1.15 -> 0.03506544 | AO31: =W31 -> 0.031025771 | AP31: =X31 -> 0.029871685 | AQ31: =Y31 -> 0.030923767 | AR31: =Z31 -> 0.031974981 | AS31: =AA31 -> 0.032575051 | AT31: =AB31*0.85 -> 0.022052671 | AU31: =AC31*0.85 -> 0.025917934 | BA31: Coal | BB31: 207.9 | BC31: 184.2 | BD31: 174.6 | BE31: 172.4 | BF31: 168.7 | BG31: 174.7 | BH31: 172.4 | BI31: 172.4
B32: Natural gas | C32: =BB32/1000 -> 0.5747 | D32: =BC32/1000 -> 0.5597 | E32: =BD32/1000 -> 0.534 | F32: =BE32/1000 -> 0.528 | G32: =BF32/1000 -> 0.5061 | H32: =BG32/1000 -> 0.5369 | I32: =BH32/1000 -> 0.528 | J32: =BI32/1000 -> 0.528 | M32: 5.937 | N32: 5.845 | O32: 5.575 | P32: 5.276 | Q32: 5.363 | R32: 6.645 | S32: 5.654 | V32: Natural gas | W32: =D32/M32 -> 0.094273202 | X32: =E32/N32 -> 0.091360137 | Y32: =F32/O32 -> 0.09470852 | Z32: =G32/P32 -> 0.095924943 | AA32: =H32/Q32 -> 0.10011188 | AB32: =I32/R32 -> 0.079458239 | AC32: =J32/S32 -> 0.093385214 | AF32: =W32 -> 0.094273202 | AG32: =X32 -> 0.091360137 | AH32: =Y32 -> 0.09470852 | AI32: =Z32 -> 0.095924943 | AJ32: =AA32 -> 0.10011188 | AK32: =AB32*1.15 -> 0.091376975 | AL32: =AC32*1.15 -> 0.107393 | AO32: =W32 -> 0.094273202 | AP32: =X32 -> 0.091360137 | AQ32: =Y32 -> 0.09470852 | AR32: =Z32 -> 0.095924943 | AS32: =AA32 -> 0.10011188 | AT32: =AB32*0.85 -> 0.067539503 | AU32: =AC32*0.85 -> 0.079377432 | BA32: Natural gas | BB32: 574.7 | BC32: 559.7 | BD32: 534 | BE32: 528 | BF32: 506.1 | BG32: 536.9 | BH32: 528 | BI32: 528
B33: Petroleum | C33: =BB33/1000 -> 0.088 | D33: =BC33/1000 -> 0.0814 | E33: =BD33/1000 -> 0.079 | F33: =BE33/1000 -> 0.0785 | G33: =BF33/1000 -> 0.0764 | H33: =BG33/1000 -> 0.0787 | I33: =BH33/1000 -> 0.0785 | J33: =BI33/1000 -> 0.0785 | M33: 5.937 | N33: 5.845 | O33: 5.575 | P33: 5.276 | Q33: 5.363 | R33: 6.645 | S33: 5.654 | V33: Petroleum | W33: =D33/M33 -> 0.013710628 | X33: =E33/N33 -> 0.013515825 | Y33: =F33/O33 -> 0.014080717 | Z33: =G33/P33 -> 0.014480667 | AA33: =H33/Q33 -> 0.014674622 | AB33: =I33/R33 -> 0.011813394 | AC33: =J33/S33 -> 0.013883976 | AF33: =W33 -> 0.013710628 | AG33: =X33 -> 0.013515825 | AH33: =Y33 -> 0.014080717 | AI33: =Z33 -> 0.014480667 | AJ33: =AA33 -> 0.014674622 | AK33: =AB33*1.15 -> 0.013585403 | AL33: =AC33*1.15 -> 0.015966572 | AO33: =W33 -> 0.013710628 | AP33: =X33 -> 0.013515825 | AQ33: =Y33 -> 0.014080717 | AR33: =Z33 -> 0.014480667 | AS33: =AA33 -> 0.014674622 | AT33: =AB33*0.85 -> 0.010041384 | AU33: =AC33*0.85 -> 0.01180138 | BA33: Petroleum | BB33: 88 | BC33: 81.4 | BD33: 79 | BE33: 78.5 | BF33: 76.4 | BG33: 78.7 | BH33: 78.5 | BI33: 78.5
A34: China | B34: Total Energy | C34: =BB34/1000 -> 0.9217 | D34: =BC34/1000 -> 0.8721 | E34: =BD34/1000 -> 0.8313 | F34: =BE34/1000 -> 0.8218 | G34: =BF34/1000 -> 0.794 | H34: =BG34/1000 -> 0.835 | I34: =BH34/1000 -> 0.8218 | J34: =BI34/1000 -> 0.8218 | M34: 5.937 | N34: 5.845 | O34: 5.575 | P34: 5.276 | Q34: 5.363 | R34: 6.645 | S34: 5.654 | U34: China | V34: Total Energy | W34: =D34/M34 -> 0.14689237 | X34: =E34/N34 -> 0.14222412 | Y34: =F34/O34 -> 0.14740807 | Z34: =G34/P34 -> 0.1504928 | AA34: =H34/Q34 -> 0.15569644 | AB34: =I34/R34 -> 0.12367193 | AC34: =J34/S34 -> 0.14534843 | AF34: =W34 -> 0.14689237 | AG34: =X34 -> 0.14222412 | AH34: =Y34 -> 0.14740807 | AI34: =Z34 -> 0.1504928 | AJ34: =AA34 -> 0.15569644 | AK34: =AB34*1.15 -> 0.14222272 | AL34: =AC34*1.15 -> 0.16715069 | AO34: =W34 -> 0.14689237 | AP34: =X34 -> 0.14222412 | AQ34: =Y34 -> 0.14740807 | AR34: =Z34 -> 0.1504928 | AS34: =AA34 -> 0.15569644 | AT34: =AB34*0.85 -> 0.10512114 | AU34: =AC34*0.85 -> 0.12354616 | AZ34: China | BA34: Total Energy | BB34: 921.7 | BC34: 872.1 | BD34: 831.3 | BE34: 821.8 | BF34: 794 | BG34: 835 | BH34: 821.8 | BI34: 821.8
