Workbook

Sheet Hydro Methodology
A1: HYDROPOWER SUPPLY CURVES FOR TIMES MODELING
A3: DATA SOURCES
A4: Primary - Gross Potential | B4: Hoes et al. (2017) PLOS ONE - DOI: 10.1371/journal.pone.0171844
A5: Economic Ratios | B5: Gernaat et al. (2017) Nature Energy - DOI: 10.1038/s41560-017-0006-y
A6: Capital Costs | B6: AR6 Scenario Database - Regional median costs for hydro (2020 USD/kW)
A7: Current Capacity | B7: IHA World Hydropower Outlook 2024, IRENA Statistics
A9: METHODOLOGY
A10: Gross Potential | B10: From Hoes et al. 11.8 million site assessment using 7.5 arcsec DEM
A11: Economic Potential | B11: ~18% of gross (Gernaat ratio for sites <$0.50/kWh)
A12: GW Conversion | B12: Assumes 4000 full load hours (46% capacity factor)
A13: Additional_Low | B13: Economic potential minus current installed capacity
A14: Additional_High | B14: 25% of gross potential minus current installed capacity
A16: COST METHODOLOGY (AR6-BASED)
A17: Base Cost Source | B17: AR6 scenario database median capital costs by R10 region
A18: T1 (Best Sites) | B18: 25%/20% of potential | 0.90x base cost | Best available sites
A19: T2 (Good Sites) | B19: 40%/35% of potential | 1.00x base cost | Median cost sites
A20: T3 (Average Sites) | B20: 25%/30% of potential | 1.15x base cost | Above-average cost
A21: T4 (Marginal Sites) | B21: 10%/15% of potential | 1.35x base cost | Highest cost sites
A23: AR6 REGIONAL BASE COSTS (2020 USD/kW)
A24: AFR (Africa) | B24: $2,689/kW
A25: CSA (Latin America) | B25: $3,074/kW
A26: CPA (China+) | B26: $2,273/kW
A27: SAS (India+) | B27: $2,585/kW
A28: PAS (Rest of Asia) | B28: $2,864/kW
A29: FSU (Former Soviet Union) | B29: $2,860/kW
A30: MEA (Middle East) | B30: $2,790/kW
A31: EUR (Europe) | B31: $2,752/kW
A32: NAM (North America) | B32: $2,852/kW
A33: PAO (Pacific OECD) | B33: $2,808/kW
A35: INCREMENTAL COST INTERPRETATION
A36: T1 Cost = 0 | B36: First tranche baseline; absolute cost embedded in base technology
A37: T2-T4 Costs | B37: ADDITIONAL cost above T1 to access that tranche of potential
A38: TIMES Usage | B38: Model as stepped supply curve using NCAP_BND(UP) for each tranche
A40: TECHNOLOGY NAMING
A41: Convention | B41: EN_Hydro_<ISO3>_<Tranche>
A42: Example | B42: EN_Hydro_BRA_T1, EN_Hydro_BRA_T2, EN_Hydro_BRA_T3, EN_Hydro_BRA_T4
A44: NOTES
A45: Excludes | B45: Pumped storage hydro (PSH) - separate technology
A46: Constraints | B46: Environmental/social factors may further limit development
A47: Climate | B47: Potential may shift with changing precipitation patterns
...

Sheet Hydro
B3: ~fi_t | H3: ~fi_process
B4: process | C4: comm-in | D4: comm-out | E4: cap_bnd | F4: invcost~USD21_alt | H4: set | I4: process | J4: description | K4: capacity_unit | L4: activity_unit | M4: timeslicelevel | N4: vintage
B5: =SupplyCurves_High!A2 -> EN_Hydro_BRA_T1 | C5: ELCHYD | D5: ELC | E5: =SupplyCurves_High!F2 -> 13.2 | F5: =SupplyCurves_High!H2 -> 0 | H5: ELE | I5: =B5 -> EN_Hydro_BRA_T1 | J5: =SupplyCurves_High!C2&" -- "&SupplyCurves_High!E2&" -- "&SupplyCurves_High!K2 -> Brazil -- T1 -- $0.04-0.06/kWh | K5: GW | L5: PJ | M5: daynite | N5: no
B6: =SupplyCurves_High!A3 -> EN_Hydro_BRA_T2 | C6: ELCHYD | D6: ELC | E6: =SupplyCurves_High!F3 -> 23.1 | F6: =SupplyCurves_High!H3 -> 307 | H6: ELE | I6: =B6 -> EN_Hydro_BRA_T2 | J6: =SupplyCurves_High!C3&" -- "&SupplyCurves_High!E3&" -- "&SupplyCurves_High!K3 -> Brazil -- T2 -- $0.06-0.08/kWh | K6: GW | L6: PJ | M6: daynite | N6: no
B7: =SupplyCurves_High!A4 -> EN_Hydro_BRA_T3 | C7: ELCHYD | D7: ELC | E7: =SupplyCurves_High!F4 -> 19.8 | F7: =SupplyCurves_High!H4 -> 768 | H7: ELE | I7: =B7 -> EN_Hydro_BRA_T3 | J7: =SupplyCurves_High!C4&" -- "&SupplyCurves_High!E4&" -- "&SupplyCurves_High!K4 -> Brazil -- T3 -- $0.08-0.10/kWh | K7: GW | L7: PJ | M7: daynite | N7: no
B8: =SupplyCurves_High!A5 -> EN_Hydro_BRA_T4 | C8: ELCHYD | D8: ELC | E8: =SupplyCurves_High!F5 -> 9.9 | F8: =SupplyCurves_High!H5 -> 1383 | H8: ELE | I8: =B8 -> EN_Hydro_BRA_T4 | J8: =SupplyCurves_High!C5&" -- "&SupplyCurves_High!E5&" -- "&SupplyCurves_High!K5 -> Brazil -- T4 -- $0.10-0.14/kWh | K8: GW | L8: PJ | M8: daynite | N8: no
B9: =SupplyCurves_High!A6 -> EN_Hydro_RUS_T1 | C9: ELCHYD | D9: ELC | E9: =SupplyCurves_High!F6 -> 17.1 | F9: =SupplyCurves_High!H6 -> 0 | H9: ELE | I9: =B9 -> EN_Hydro_RUS_T1 | J9: =SupplyCurves_High!C6&" -- "&SupplyCurves_High!E6&" -- "&SupplyCurves_High!K6 -> Russia -- T1 -- $0.04-0.06/kWh | K9: GW | L9: PJ | M9: daynite | N9: no
B10: =SupplyCurves_High!A7 -> EN_Hydro_RUS_T2 | C10: ELCHYD | D10: ELC | E10: =SupplyCurves_High!F7 -> 29.925 | F10: =SupplyCurves_High!H7 -> 286 | H10: ELE | I10: =B10 -> EN_Hydro_RUS_T2 | J10: =SupplyCurves_High!C7&" -- "&SupplyCurves_High!E7&" -- "&SupplyCurves_High!K7 -> Russia -- T2 -- $0.06-0.08/kWh | K10: GW | L10: PJ | M10: daynite | N10: no
B11: =SupplyCurves_High!A8 -> EN_Hydro_RUS_T3 | C11: ELCHYD | D11: ELC | E11: =SupplyCurves_High!F8 -> 25.65 | F11: =SupplyCurves_High!H8 -> 715 | H11: ELE | I11: =B11 -> EN_Hydro_RUS_T3 | J11: =SupplyCurves_High!C8&" -- "&SupplyCurves_High!E8&" -- "&SupplyCurves_High!K8 -> Russia -- T3 -- $0.08-0.10/kWh | K11: GW | L11: PJ | M11: daynite | N11: no
B12: =SupplyCurves_High!A9 -> EN_Hydro_RUS_T4 | C12: ELCHYD | D12: ELC | E12: =SupplyCurves_High!F9 -> 12.825 | F12: =SupplyCurves_High!H9 -> 1287 | H12: ELE | I12: =B12 -> EN_Hydro_RUS_T4 | J12: =SupplyCurves_High!C9&" -- "&SupplyCurves_High!E9&" -- "&SupplyCurves_High!K9 -> Russia -- T4 -- $0.10-0.14/kWh | K12: GW | L12: PJ | M12: daynite | N12: no
B13: =SupplyCurves_High!A10 -> EN_Hydro_CAN_T1 | C13: ELCHYD | D13: ELC | E13: =SupplyCurves_High!F10 -> 6.1 | F13: =SupplyCurves_High!H10 -> 0 | H13: ELE | I13: =B13 -> EN_Hydro_CAN_T1 | J13: =SupplyCurves_High!C10&" -- "&SupplyCurves_High!E10&" -- "&SupplyCurves_High!K10 -> Canada -- T1 -- $0.04-0.06/kWh | K13: GW | L13: PJ | M13: daynite | N13: no
B14: =SupplyCurves_High!A11 -> EN_Hydro_CAN_T2 | C14: ELCHYD | D14: ELC | E14: =SupplyCurves_High!F11 -> 10.675 | F14: =SupplyCurves_High!H11 -> 285 | H14: ELE | I14: =B14 -> EN_Hydro_CAN_T2 | J14: =SupplyCurves_High!C11&" -- "&SupplyCurves_High!E11&" -- "&SupplyCurves_High!K11 -> Canada -- T2 -- $0.06-0.08/kWh | K14: GW | L14: PJ | M14: daynite | N14: no
B15: =SupplyCurves_High!A12 -> EN_Hydro_CAN_T3 | C15: ELCHYD | D15: ELC | E15: =SupplyCurves_High!F12 -> 9.15 | F15: =SupplyCurves_High!H12 -> 713 | H15: ELE | I15: =B15 -> EN_Hydro_CAN_T3 | J15: =SupplyCurves_High!C12&" -- "&SupplyCurves_High!E12&" -- "&SupplyCurves_High!K12 -> Canada -- T3 -- $0.08-0.10/kWh | K15: GW | L15: PJ | M15: daynite | N15: no
B16: =SupplyCurves_High!A13 -> EN_Hydro_CAN_T4 | C16: ELCHYD | D16: ELC | E16: =SupplyCurves_High!F13 -> 4.575 | F16: =SupplyCurves_High!H13 -> 1284 | H16: ELE | I16: =B16 -> EN_Hydro_CAN_T4 | J16: =SupplyCurves_High!C13&" -- "&SupplyCurves_High!E13&" -- "&SupplyCurves_High!K13 -> Canada -- T4 -- $0.10-0.14/kWh | K16: GW | L16: PJ | M16: daynite | N16: no
... B208: =SupplyCurves_High!A205 -> EN_Hydro_MLI_T4 | C208: ELCHYD | D208: ELC | E208: =SupplyCurves_High!F205 -> 0.09 | F208: =SupplyCurves_High!H205 -> 1210 | H208: ELE | I208: =B208 -> EN_Hydro_MLI_T4 | J208: =SupplyCurves_High!C205&" -- "&SupplyCurves_High!E205&" -- "&SupplyCurves_High!K205 -> Mali -- T4 -- $0.10-0.14/kWh | K208: GW | L208: PJ | M208: daynite | N208: no

Sheet SupplyCurves_Low
A1: TechName | B1: ISO3 | C1: Country | D1: Region | E1: Tranche | F1: Potential_GW | G1: Potential_MW | H1: INVCOST_Incremental_USD_kW | I1: INVCOST_Absolute_USD_kW | J1: AR6_Base_Cost_USD_kW | K1: LCOE_Range
A2: EN_Hydro_BRA_T1 | B2: BRA | C2: Brazil | D2: CSA | E2: T1 | F2: 4.25 | G2: 4250 | H2: 0 | I2: 2767 | J2: 3074 | K2: $0.04-0.06/kWh
A3: EN_Hydro_BRA_T2 | B3: BRA | C3: Brazil | D3: CSA | E3: T2 | F3: 6.8 | G3: 6800 | H3: 307 | I3: 3074 | J3: 3074 | K3: $0.06-0.08/kWh
A4: EN_Hydro_BRA_T3 | B4: BRA | C4: Brazil | D4: CSA | E4: T3 | F4: 4.25 | G4: 4250 | H4: 768 | I4: 3535 | J4: 3074 | K4: $0.08-0.10/kWh
A5: EN_Hydro_BRA_T4 | B5: BRA | C5: Brazil | D5: CSA | E5: T4 | F5: 1.7 | G5: 1700 | H5: 1383 | I5: 4150 | J5: 3074 | K5: $0.10-0.14/kWh
A6: EN_Hydro_RUS_T1 | B6: RUS | C6: Russia | D6: FSU | E6: T1 | F6: 11.75 | G6: 11750 | H6: 0 | I6: 2574 | J6: 2860 | K6: $0.04-0.06/kWh
A7: EN_Hydro_RUS_T2 | B7: RUS | C7: Russia | D7: FSU | E7: T2 | F7: 18.8 | G7: 18800 | H7: 286 | I7: 2860 | J7: 2860 | K7: $0.06-0.08/kWh
A8: EN_Hydro_RUS_T3 | B8: RUS | C8: Russia | D8: FSU | E8: T3 | F8: 11.75 | G8: 11750 | H8: 715 | I8: 3289 | J8: 2860 | K8: $0.08-0.10/kWh
A9: EN_Hydro_RUS_T4 | B9: RUS | C9: Russia | D9: FSU | E9: T4 | F9: 4.7 | G9: 4700 | H9: 1287 | I9: 3861 | J9: 2860 | K9: $0.10-0.14/kWh
A10: EN_Hydro_IND_T1 | B10: IND | C10: India | D10: SAS | E10: T1 | F10: 0.5 | G10: 500 | H10: 0 | I10: 2327 | J10: 2585 | K10: $0.04-0.06/kWh
A11: EN_Hydro_IND_T2 | B11: IND | C11: India | D11: SAS | E11: T2 | F11: 0.8 | G11: 800 | H11: 259 | I11: 2585 | J11: 2585 | K11: $0.06-0.08/kWh
A12: EN_Hydro_IND_T3 | B12: IND | C12: India | D12: SAS | E12: T3 | F12: 0.5 | G12: 500 | H12: 646 | I12: 2973 | J12: 2585 | K12: $0.08-0.10/kWh
A13: EN_Hydro_IND_T4 | B13: IND | C13: India | D13: SAS | E13: T4 | F13: 0.2 | G13: 200 | H13: 1163 | I13: 3490 | J13: 2585 | K13: $0.10-0.14/kWh
... A205: EN_Hydro_BLR_T4 | B205: BLR | C205: Belarus | D205: FSU | E205: T4 | F205: 0.01 | G205: 10 | H205: 1287 | I205: 3861 | J205: 2860 | K205: $0.10-0.14/kWh

Sheet SupplyCurves_High
A1: TechName | B1: ISO3 | C1: Country | D1: Region | E1: Tranche | F1: Potential_GW | G1: Potential_MW | H1: INVCOST_Incremental_USD_kW | I1: INVCOST_Absolute_USD_kW | J1: AR6_Base_Cost_USD_kW | K1: LCOE_Range
A2: EN_Hydro_BRA_T1 | B2: BRA | C2: Brazil | D2: CSA | E2: T1 | F2: 13.2 | G2: 13200 | H2: 0 | I2: 2767 | J2: 3074 | K2: $0.04-0.06/kWh
A3: EN_Hydro_BRA_T2 | B3: BRA | C3: Brazil | D3: CSA | E3: T2 | F3: 23.1 | G3: 23100 | H3: 307 | I3: 3074 | J3: 3074 | K3: $0.06-0.08/kWh
A4: EN_Hydro_BRA_T3 | B4: BRA | C4: Brazil | D4: CSA | E4: T3 | F4: 19.8 | G4: 19800 | H4: 768 | I4: 3535 | J4: 3074 | K4: $0.08-0.10/kWh
A5: EN_Hydro_BRA_T4 | B5: BRA | C5: Brazil | D5: CSA | E5: T4 | F5: 9.9 | G5: 9900 | H5: 1383 | I5: 4150 | J5: 3074 | K5: $0.10-0.14/kWh
A6: EN_Hydro_RUS_T1 | B6: RUS | C6: Russia | D6: FSU | E6: T1 | F6: 17.1 | G6: 17100 | H6: 0 | I6: 2574 | J6: 2860 | K6: $0.04-0.06/kWh
A7: EN_Hydro_RUS_T2 | B7: RUS | C7: Russia | D7: FSU | E7: T2 | F7: 29.925 | G7: 29925 | H7: 286 | I7: 2860 | J7: 2860 | K7: $0.06-0.08/kWh
A8: EN_Hydro_RUS_T3 | B8: RUS | C8: Russia | D8: FSU | E8: T3 | F8: 25.65 | G8: 25650 | H8: 715 | I8: 3289 | J8: 2860 | K8: $0.08-0.10/kWh
A9: EN_Hydro_RUS_T4 | B9: RUS | C9: Russia | D9: FSU | E9: T4 | F9: 12.825 | G9: 12825 | H9: 1287 | I9: 3861 | J9: 2860 | K9: $0.10-0.14/kWh
A10: EN_Hydro_CAN_T1 | B10: CAN | C10: Canada | D10: NAM | E10: T1 | F10: 6.1 | G10: 6100 | H10: 0 | I10: 2567 | J10: 2852 | K10: $0.04-0.06/kWh
A11: EN_Hydro_CAN_T2 | B11: CAN | C11: Canada | D11: NAM | E11: T2 | F11: 10.675 | G11: 10675 | H11: 285 | I11: 2852 | J11: 2852 | K11: $0.06-0.08/kWh
A12: EN_Hydro_CAN_T3 | B12: CAN | C12: Canada | D12: NAM | E12: T3 | F12: 9.15 | G12: 9150 | H12: 713 | I12: 3280 | J12: 2852 | K12: $0.08-0.10/kWh
A13: EN_Hydro_CAN_T4 | B13: CAN | C13: Canada | D13: NAM | E13: T4 | F13: 4.575 | G13: 4575 | H13: 1284 | I13: 3851 | J13: 2852 | K13: $0.10-0.14/kWh
... A245: EN_Hydro_JOR_T4 | B245: JOR | C245: Jordan | D245: MEA | E245: T4 | F245: 0.015 | G245: 15 | H245: 1256 | I245: 3767 | J245: 2790 | K245: $0.10-0.14/kWh

Sheet LNG Terminals
A1: This is independent of model regional aggregation
A2: source: TF - step 10 - LNG terminals SubRES - model independent.sql
D4: ~FI_T | L4: ~FI_Process
B5: TechName | C5: Comm-IN | D5: Comm-OUT | E5: EFF | F5: LIFE | G5: NCAP_BND~0 | H5: PASTI | I5: Cap2ACT | J5: Year | L5: Sets | M5: TechName | N5: TechDesc | O5: TCap | P5: TAct | Q5: pcg
B6: LNG_exp_FLNG_AUS | C6: GASNGA | D6: GASLNG | E6: 0.9 | F6: 200 | G6: 2 | H6: 3.6 | I6: 54 | J6: 2019 | L6: PRE | M6: LNG_exp_FLNG_AUS | N6: LNG export terminals - FLNG - Australia | O6: mtpa | P6: PJ
B7: LNG_exp_FLNG_CMR | C7: GASNGA | D7: GASLNG | E7: 0.9 | F7: 200 | G7: 2 | H7: 2.4 | I7: 54 | J7: 2018 | L7: PRE | M7: LNG_exp_FLNG_CMR | N7: LNG export terminals - FLNG - Cameroon | O7: mtpa | P7: PJ
B8: LNG_exp_FLNG_COD | C8: GASNGA | D8: GASLNG | E8: 0.9 | F8: 200 | G8: 2 | H8: 3 | I8: 54 | J8: 2023 | L8: PRE | M8: LNG_exp_FLNG_COD | N8: LNG export terminals - FLNG - Democratic Republic of the Congo | O8: mtpa | P8: PJ
B9: LNG_exp_FLNG_GAB | C9: GASNGA | D9: GASLNG | E9: 0.9 | F9: 200 | G9: 2 | H9: 0.7 | I9: 54 | J9: 2026 | L9: PRE | M9: LNG_exp_FLNG_GAB | N9: LNG export terminals - FLNG - Gabon | O9: mtpa | P9: PJ
B10: LNG_exp_FLNG_MOZ | C10: GASNGA | D10: GASLNG | E10: 0.9 | F10: 200 | G10: 2 | H10: 3.4 | I10: 54 | J10: 2022 | L10: PRE | M10: LNG_exp_FLNG_MOZ | N10: LNG export terminals - FLNG - Mozambique | O10: mtpa | P10: PJ
B11: LNG_exp_FLNG_MYS | C11: GASNGA | D11: GASLNG | E11: 0.9 | F11: 200 | G11: 2 | H11: 1.2 | I11: 54 | J11: 2017 | L11: PRE | M11: LNG_exp_FLNG_MYS | N11: LNG export terminals - FLNG - Malaysia | O11: mtpa | P11: PJ
B12: LNG_exp_FLNG_MYS | C12: GASNGA | D12: GASLNG | E12: 0.9 | F12: 200 | G12: 2 | H12: 1.5 | I12: 54 | J12: 2020 | L12: PRE | M12: LNG_exp_FLNG_MYS | N12: LNG export terminals - FLNG - Malaysia | O12: mtpa | P12: PJ
B13: LNG_exp_FLNG_MYS | C13: GASNGA | D13: GASLNG | E13: 0.9 | F13: 200 | G13: 2 | H13: 2 | I13: 54 | J13: 2027 | L13: PRE | M13: LNG_exp_FLNG_MYS | N13: LNG export terminals - FLNG - Malaysia | O13: mtpa | P13: PJ
B14: LNG_exp_FLNG_SEN | C14: GASNGA | D14: GASLNG | E14: 0.9 | F14: 200 | G14: 2 | H14: 2.5 | I14: 54 | J14: 2023 | L14: PRE | M14: LNG_exp_FLNG_SEN | N14: LNG export terminals - FLNG - Mauritania/Senegal | O14: mtpa | P14: PJ
B15: LNG_exp_Onshore_AGO | C15: GASNGA | D15: GASLNG | E15: 0.9 | F15: 200 | G15: 2 | H15: 5.2 | I15: 54 | J15: 2013 | L15: PRE | M15: LNG_exp_Onshore_AGO | N15: LNG export terminals - Onshore - Angola | O15: mtpa | P15: PJ
B16: LNG_exp_Onshore_ARE | C16: GASNGA | D16: GASLNG | E16: 0.9 | F16: 200 | G16: 2 | H16: 2.6 | I16: 54 | J16: 1977 | L16: PRE | M16: LNG_exp_Onshore_ARE | N16: LNG export terminals - Onshore - UAE | O16: mtpa | P16: PJ
B17: LNG_exp_Onshore_ARE | C17: GASNGA | D17: GASLNG | E17: 0.9 | F17: 200 | G17: 2 | H17: 3.2 | I17: 54 | J17: 1994 | L17: PRE | M17: LNG_exp_Onshore_ARE | N17: LNG export terminals - Onshore - UAE | O17: mtpa | P17: PJ
... B89: LNG_exp_Onshore_USA | C89: GASNGA | D89: GASLNG | E89: 0.9 | F89: 200 | G89: 2 | H89: 32 | I89: 54 | J89: 2025 | L89: PRE | M89: LNG_exp_Onshore_USA | N89: LNG export terminals - Onshore - USA | O89: mtpa | P89: PJ
B90: LNG_imp_FSRU _BRA | C90: GASLNG | D90: GASNGA | E90: 0.9755 | F90: 200 | G90: 2 | H90: 9.8294118 | I90: 54 | J90: 2009 | L90: PRE | M90: LNG_imp_FSRU _BRA | N90: LNG import terminals - FSRU - Brazil | O90: mtpa | P90: PJ | Q90: GASLNG
B91: LNG_imp_FSRU_ARE | C91: GASLNG | D91: GASNGA | E91: 0.9755 | F91: 200 | G91: 2 | H91: 3.8 | I91: 54 | J91: 2016 | L91: PRE | M91: LNG_imp_FSRU_ARE | N91: LNG import terminals - FSRU - UAE | O91: mtpa | P91: PJ | Q91: GASLNG
B92: LNG_imp_FSRU_ARE | C92: GASLNG | D92: GASNGA | E92: 0.9755 | F92: 200 | G92: 2 | H92: 6.0294118 | I92: 54 | J92: 2010 | L92: PRE | M92: LNG_imp_FSRU_ARE | N92: LNG import terminals - FSRU - UAE | O92: mtpa | P92: PJ | Q92: GASLNG
B93: LNG_imp_FSRU_ARG | C93: GASLNG | D93: GASNGA | E93: 0.9755 | F93: 200 | G93: 2 | H93: 6.1 | I93: 54 | J93: 2011 | L93: PRE | M93: LNG_imp_FSRU_ARG | N93: LNG import terminals - FSRU - Argentina | O93: mtpa | P93: PJ | Q93: GASLNG
B94: LNG_imp_FSRU_AUS | C94: GASLNG | D94: GASNGA | E94: 0.9755 | F94: 200 | G94: 2 | H94: 2 | I94: 54 | J94: 2023 | L94: PRE | M94: LNG_imp_FSRU_AUS | N94: LNG import terminals - FSRU - Australia | O94: mtpa | P94: PJ | Q94: GASLNG
B95: LNG_imp_FSRU_BGD | C95: GASLNG | D95: GASNGA | E95: 0.9755 | F95: 200 | G95: 2 | H95: 3.8 | I95: 54 | J95: 2018 | L95: PRE | M95: LNG_imp_FSRU_BGD | N95: LNG import terminals - FSRU - Bangladesh | O95: mtpa | P95: PJ | Q95: GASLNG
B96: LNG_imp_FSRU_BGD | C96: GASLNG | D96: GASNGA | E96: 0.9755 | F96: 200 | G96: 2 | H96: 3.8 | I96: 54 | J96: 2019 | L96: PRE | M96: LNG_imp_FSRU_BGD | N96: LNG import terminals - FSRU - Bangladesh | O96: mtpa | P96: PJ | Q96: GASLNG
B97: LNG_imp_FSRU_BRA | C97: GASLNG | D97: GASNGA | E97: 0.9755 | F97: 200 | G97: 2 | H97: 5.6 | I97: 54 | J97: 2013 | L97: PRE | M97: LNG_imp_FSRU_BRA | N97: LNG import terminals - FSRU - Brazil | O97: mtpa | P97: PJ | Q97: GASLNG
B98: LNG_imp_FSRU_BRA | C98: GASLNG | D98: GASNGA | E98: 0.9755 | F98: 200 | G98: 2 | H98: 11.2 | I98: 54 | J98: 2020 | L98: PRE | M98: LNG_imp_FSRU_BRA | N98: LNG import terminals - FSRU - Brazil | O98: mtpa | P98: PJ | Q98: GASLNG
B99: LNG_imp_FSRU_BRA | C99: GASLNG | D99: GASNGA | E99: 0.9755 | F99: 200 | G99: 2 | H99: 11.3 | I99: 54 | J99: 2023 | L99: PRE | M99: LNG_imp_FSRU_BRA | N99: LNG import terminals - FSRU - Brazil | O99: mtpa | P99: PJ | Q99: GASLNG
B100: LNG_imp_FSRU_CHN | C100: GASLNG | D100: GASNGA | E100: 0.9755 | F100: 200 | G100: 2 | H100: 6 | I100: 54 | J100: 2013 | L100: PRE | M100: LNG_imp_FSRU_CHN | N100: LNG import terminals - FSRU - China | O100: mtpa | P100: PJ | Q100: GASLNG
B101: LNG_imp_FSRU_COL | C101: GASLNG | D101: GASNGA | E101: 0.9755 | F101: 200 | G101: 2 | H101: 4 | I101: 54 | J101: 2016 | L101: PRE | M101: LNG_imp_FSRU_COL | N101: LNG import terminals - FSRU - Colombia | O101: mtpa | P101: PJ | Q101: GASLNG
... B263: LNG_imp_Onshore_VNM | C263: GASLNG | D263: GASNGA | E263: 0.9755 | F263: 200 | G263: 2 | H263: 5 | I263: 54 | J263: 2022 | L263: PRE | M263: LNG_imp_Onshore_VNM | N263: LNG import terminals - Onshore - Vietnam | O263: mtpa | P263: PJ | Q263: GASLNG

Sheet storage doc
A1: CO₂ geological storage supply curves — country steps
A2: Generated: 2026-08-06
A3: Package: 7co2_transport_storage | methodology: CCS_SUPPLY_CURVES_METHODOLOGY.md
A5: What this workbook is
A6: One process per country × storage supply-curve step (saline / petroleum,
A7: distance band, quality tier, onshore pipe / offshore pipe / ship).
A8: Kept at ISO level so each model region only sees the countries it owns
A9: (via AVA on the _ISO3 suffix in the process name) — no pre-aggregation
A10: that would let one country borrow a neighbour's storage headroom.
A11: Meant to sit in the REZoning SubRES; this file is for review before fold-in.
A13: What a step represents
A14: Capacity (P10 / P50 / P90), a transport+storage unit cost, and a share of
... A70: Input files: storage_potential_by_country.csv ; supply_curve_steps_global_PESSCOST.csv

Sheet storage_ISO_steps
C2: ~FI_T: ACT_BND~USD20~UP | V2: ~FI_Process
A3: TechName | B3: Comm-IN | C3: ACT_CUM | D3: ACT_CUM_P10 | E3: ACT_CUM_P50 | F3: ACT_CUM_P90 | G3: ACT_COST | H3: ACT_COST_PessCost | I3: ACT_COST_PessFOAK | J3: 2025 | K3: 2030 | L3: 2035 | M3: 2040 | N3: 2045 | O3: 2050 | P3: 2060 | Q3: 2070 | R3: 2080 | S3: 2090 | T3: 2100 | V3: Sets | W3: TechName | X3: TechDesc | Y3: TCap | Z3: TAct | AB3: country | AC3: iso3 | AD3: category | AE3: subtype | AF3: onshore_offshore | AG3: cost_step | AH3: dist_band | AI3: quality_tier | AJ3: sink_mode | AK3: n_sites | AL3: capacity_Mt_P10 | AM3: capacity_Mt_P50 | AN3: capacity_Mt_P90 | AO3: share_emissions_weighted | AP3: mtco2_pa_demand_proximity | AQ3: transport_usd_per_t | AR3: storage_usd_per_t | AS3: ts_total_usd_per_t | AT3: transport_usd_per_t_pess | AU3: storage_usd_per_t_pess | AV3: ts_total_usd_per_t_pess | AW3: inj_rate_step_Mtpa | AX3: inj_rate_step_Mtpa_2100 | AY3: inj_rate_method | AZ3: range_reported | BA3: source | BB3: quality_flag | BC3: pess_matched
A4: STO_Saline_onshore_D1Q3P_AFG | B4: CO2ForStorage | C4: 5913000 | D4: 3215300 | E4: 5913000 | F4: 11985200 | G4: 0.01540609 | H4: 0.050623746 | I4: 0.075935619 | J4: 236520 | K4: 234296.09 | L4: 232072.19 | M4: 229848.28 | N4: 227624.38 | O4: 225400.47 | P4: 220952.66 | Q4: 216504.85 | R4: 212057.04 | S4: 207609.23 | T4: 203161.42 | V4: PRE | W4: STO_Saline_onshore_D1Q3P_AFG | X4: CO2 storage step -- Saline (2 sites) - onshore_pipe - 0-50km - Afghanistan | Y4: ktpa | Z4: kt | AB4: Afghanistan | AC4: AFG | AD4: Saline | AF4: onshore | AG4: D1Q3P | AH4: 0-50km | AI4: Q3 | AJ4: onshore_pipe | AK4: 2 | AL4: 3215.3 | AM4: 5913 | AN4: 11985.2 | AO4: 0.58523867 | AP4: 0.4377 | AQ4: 0.68070854 | AR4: 14.725382 | AS4: 15.40609 | AT4: 1.9123716 | AU4: 48.711374 | AV4: 50.623746 | AW4: 236.52 | AX4: 203.16142 | AY4: pressure_limited_rerun | AZ4: P10/P50/P90 (category-ratio envelope) | BA4: phase2_distance_engine | BB4: emissions_weighted+life_capped | BC4: TRUE
A5: STO_Saline_onshore_D2Q3P_AFG | B5: CO2ForStorage | C5: 4190500 | D5: 2278700 | E5: 4190500 | F5: 8494000 | G5: 0.02284983 | H5: 0.060085602 | I5: 0.090128404 | J5: 167620 | K5: 166043.93 | L5: 164467.87 | M5: 162891.8 | N5: 161315.74 | O5: 159739.67 | P5: 156587.54 | Q5: 153435.41 | R5: 150283.28 | S5: 147131.15 | T5: 143979.02 | V5: PRE | W5: STO_Saline_onshore_D2Q3P_AFG | X5: CO2 storage step -- Saline (1 site) - onshore_pipe - 50-200km - Afghanistan | Y5: ktpa | Z5: kt | AB5: Afghanistan | AC5: AFG | AD5: Saline | AF5: onshore | AG5: D2Q3P | AH5: 50-200km | AI5: Q3 | AJ5: onshore_pipe | AK5: 1 | AL5: 2278.7 | AM5: 4190.5 | AN5: 8494 | AO5: 0.41476133 | AP5: 0.3102 | AQ5: 8.1244487 | AR5: 14.725382 | AS5: 22.84983 | AT5: 11.374228 | AU5: 48.711374 | AV5: 60.085602 | AW5: 167.62 | AX5: 143.97902 | AY5: pressure_limited_rerun | AZ5: P10/P50/P90 (category-ratio envelope) | BA5: phase2_distance_engine | BB5: emissions_weighted+life_capped | BC5: TRUE
A6: STO_Saline_onshore_D1Q2P_AGO | B6: CO2ForStorage | C6: 8147300 | D6: 4430300 | E6: 8147300 | F6: 16514200 | G6: 0.0079356481 | H6: 0.023923013 | I6: 0.035884519 | J6: 325892 | K6: 325892 | L6: 325892 | M6: 325892 | N6: 325892 | O6: 325892 | P6: 325892 | Q6: 325892 | R6: 325892 | S6: 325892 | T6: 325892 | V6: PRE | W6: STO_Saline_onshore_D1Q2P_AGO | X6: CO2 storage step -- Saline (6 sites) - onshore_pipe - 0-50km - Angola | Y6: ktpa | Z6: kt | AB6: Angola | AC6: AGO | AD6: Saline | AF6: onshore | AG6: D1Q2P | AH6: 0-50km | AI6: Q2 | AJ6: onshore_pipe | AK6: 6 | AL6: 4430.3 | AM6: 8147.3 | AN6: 16514.2 | AO6: 1 | AP6: 7.4369 | AQ6: 0.18564814 | AR6: 7.75 | AS6: 7.9356481 | AT6: 0.32301285 | AU6: 23.6 | AV6: 23.923013 | AW6: 325.892 | AX6: 325.892 | AY6: pressure_limited_rerun | AZ6: P10/P50/P90 (category-ratio envelope) | BA6: phase2_distance_engine | BB6: emissions_weighted+life_capped | BC6: TRUE
A7: STO_Saline_onshore_D1Q3P_ALB | B7: CO2ForStorage | C7: 1721700 | D7: 936200 | E7: 1721700 | F7: 3489700 | G7: 0.014704492 | J7: 68868 | K7: 68868 | L7: 68868 | M7: 68868 | N7: 68868 | O7: 68868 | P7: 68868 | Q7: 68868 | R7: 68868 | S7: 68868 | T7: 68868 | V7: PRE | W7: STO_Saline_onshore_D1Q3P_ALB | X7: CO2 storage step -- Saline (1 site) - onshore_pipe - 0-50km - Albania | Y7: ktpa | Z7: kt | AB7: Albania | AC7: ALB | AD7: Saline | AF7: onshore | AG7: D1Q3P | AH7: 0-50km | AI7: Q3 | AJ7: onshore_pipe | AK7: 1 | AL7: 936.2 | AM7: 1721.7 | AN7: 3489.7 | AO7: 0.45112782 | AP7: 1.02 | AQ7: 0.38047643 | AR7: 14.324015 | AS7: 14.704492 | AW7: 68.868 | AX7: 68.868 | AY7: pressure_limited_rerun | AZ7: P10/P50/P90 (category-ratio envelope) | BA7: phase2_distance_engine | BB7: emissions_weighted+life_capped | BC7: FALSE
A8: STO_Saline_onshore_D2Q2P_ALB | B8: CO2ForStorage | C8: 100 | D8: 0 | E8: 100 | F8: 200 | G8: 0.014478038 | H8: 0.033019253 | I8: 0.049528879 | J8: 4 | K8: 4 | L8: 4 | M8: 4 | N8: 4 | O8: 4 | P8: 4 | Q8: 4 | R8: 4 | S8: 4 | T8: 4 | V8: PRE | W8: STO_Saline_onshore_D2Q2P_ALB | X8: CO2 storage step -- Saline (1 site) - onshore_pipe - 50-200km - Albania | Y8: ktpa | Z8: kt | AB8: Albania | AC8: ALB | AD8: Saline | AF8: onshore | AG8: D2Q2P | AH8: 50-200km | AI8: Q2 | AJ8: onshore_pipe | AK8: 1 | AL8: 0 | AM8: 0.1 | AN8: 0.2 | AO8: 0.54887218 | AP8: 1.241 | AQ8: 6.7280376 | AR8: 7.75 | AS8: 14.478038 | AT8: 9.4192526 | AU8: 23.6 | AV8: 33.019253 | AW8: 0.004 | AX8: 0.004 | AY8: pressure_limited_rerun | AZ8: P10/P50/P90 (category-ratio envelope) | BA8: phase2_distance_engine | BB8: emissions_weighted+life_capped | BC8: TRUE
A9: STO_Petroleum_onshore_D1Q3P_ARE | B9: CO2ForStorage | C9: 16260700 | D9: 12480600 | E9: 16260700 | F9: 27378400 | G9: 0.008399943 | H9: 0.023700754 | I9: 0.03555113 | J9: 147144 | K9: 147144 | L9: 147144 | M9: 147144 | N9: 147144 | O9: 147144 | P9: 147144 | Q9: 147144 | R9: 147144 | S9: 147144 | T9: 147144 | V9: PRE | W9: STO_Petroleum_onshore_D1Q3P_ARE | X9: CO2 storage step -- Petroleum (2 sites) - onshore_pipe - 0-50km - United Arab Emirates | Y9: ktpa | Z9: kt | AB9: United Arab Emirates | AC9: ARE | AD9: Petroleum | AF9: onshore | AG9: D1Q3P | AH9: 0-50km | AI9: Q3 | AJ9: onshore_pipe | AK9: 2 | AL9: 12480.6 | AM9: 16260.7 | AN9: 27378.4 | AO9: 0.048457143 | AP9: 4.4531 | AQ9: 0.22363654 | AR9: 8.1763065 | AS9: 8.399943 | AT9: 0.50868078 | AU9: 23.192073 | AV9: 23.700754 | AW9: 147.144 | AX9: 147.144 | AY9: voidage | AZ9: P10/P50/P90 (category-ratio envelope) | BA9: phase2_distance_engine | BB9: emissions_weighted | BC9: TRUE
A10: STO_Saline_onshore_D1Q2P_ARE | B10: CO2ForStorage | C10: 2531600 | D10: 1376600 | E10: 2531600 | F10: 5131400 | G10: 0.0077884548 | H10: 0.023802097 | I10: 0.035703146 | J10: 0 | K10: 0 | L10: 0 | M10: 0 | N10: 0 | O10: 0 | P10: 0 | Q10: 0 | R10: 0 | S10: 0 | T10: 0 | V10: PRE | W10: STO_Saline_onshore_D1Q2P_ARE | X10: CO2 storage step -- Saline (37 sites) - onshore_pipe - 0-50km - United Arab Emirates | Y10: ktpa | Z10: kt | AB10: United Arab Emirates | AC10: ARE | AD10: Saline | AF10: onshore | AG10: D1Q2P | AH10: 0-50km | AI10: Q2 | AJ10: onshore_pipe | AK10: 37 | AL10: 1376.6 | AM10: 2531.6 | AN10: 5131.4 | AO10: 0.95154286 | AP10: 87.4446 | AQ10: 0.038454762 | AR10: 7.75 | AS10: 7.7884548 | AT10: 0.20209729 | AU10: 23.6 | AV10: 23.802097 | AW10: 0 | AX10: 0 | AY10: no_tier1_rate | AZ10: P10/P50/P90 (category-ratio envelope) | BA10: phase2_distance_engine | BB10: emissions_weighted | BC10: TRUE
A11: STO_Petroleum_onshore_D2Q1P_ARG | B11: CO2ForStorage | C11: 9789000 | D11: 7513400 | E11: 9789000 | F11: 16481900 | G11: 0.0068192762 | H11: 0.016311822 | I11: 0.024467733 | J11: 97890 | K11: 97890 | L11: 97890 | M11: 97890 | N11: 97890 | O11: 97890 | P11: 97890 | Q11: 97890 | R11: 97890 | S11: 97890 | T11: 97890 | V11: PRE | W11: STO_Petroleum_onshore_D2Q1P_ARG | X11: CO2 storage step -- Petroleum (3 sites) - onshore_pipe - 50-200km - Argentina | Y11: ktpa | Z11: kt | AB11: Argentina | AC11: ARG | AD11: Petroleum | AF11: onshore | AG11: D2Q1P | AH11: 50-200km | AI11: Q1 | AJ11: onshore_pipe | AK11: 3 | AL11: 7513.4 | AM11: 9789 | AN11: 16481.9 | AO11: 0.03524169 | AP11: 1.705 | AQ11: 3.0992762 | AR11: 3.72 | AS11: 6.8192762 | AT11: 7.6318221 | AU11: 8.68 | AV11: 16.311822 | AW11: 97.89 | AX11: 97.89 | AY11: voidage | AZ11: P10/P50/P90 (category-ratio envelope) | BA11: phase2_distance_engine | BB11: emissions_weighted | BC11: TRUE
A12: STO_Saline_onshore_D1Q2P_ARG | B12: CO2ForStorage | C12: 18371400 | D12: 9990000 | E12: 18371400 | F12: 37237700 | G12: 0.0081207679 | H12: 0.024595954 | I12: 0.036893931 | J12: 591739.19 | K12: 576339.68 | L12: 560940.17 | M12: 545540.66 | N12: 530141.15 | O12: 514741.64 | P12: 483942.62 | Q12: 453143.59 | R12: 422344.57 | S12: 391545.55 | T12: 360746.53 | V12: PRE | W12: STO_Saline_onshore_D1Q2P_ARG | X12: CO2 storage step -- Saline (31 sites) - onshore_pipe - 0-50km - Argentina | Y12: ktpa | Z12: kt | AB12: Argentina | AC12: ARG | AD12: Saline | AF12: onshore | AG12: D1Q2P | AH12: 0-50km | AI12: Q2 | AJ12: onshore_pipe | AK12: 31 | AL12: 9990 | AM12: 18371.4 | AN12: 37237.7 | AO12: 0.75358928 | AP12: 36.4588 | AQ12: 0.37076791 | AR12: 7.75 | AS12: 8.1207679 | AT12: 0.9959538 | AU12: 23.6 | AV12: 24.595954 | AW12: 591.73919 | AX12: 360.74653 | AY12: pressure_limited_rerun | AZ12: P10/P50/P90 (category-ratio envelope) | BA12: phase2_distance_engine | BB12: emissions_weighted | BC12: TRUE
A13: STO_Saline_onshore_D1Q3P_ARG | B13: CO2ForStorage | C13: 90302800 | D13: 49104700 | E13: 90302800 | F13: 183038200 | G13: 0.014052294 | J13: 2908635.5 | K13: 2832940.7 | L13: 2757245.9 | M13: 2681551.2 | N13: 2605856.4 | O13: 2530161.6 | P13: 2378772.1 | Q13: 2227382.5 | R13: 2075993 | S13: 1924603.4 | T13: 1773213.9 | V13: PRE | W13: STO_Saline_onshore_D1Q3P_ARG | X13: CO2 storage step -- Saline (4 sites) - onshore_pipe - 0-50km - Argentina | Y13: ktpa | Z13: kt | AB13: Argentina | AC13: ARG | AD13: Saline | AF13: onshore | AG13: D1Q3P | AH13: 0-50km | AI13: Q3 | AJ13: onshore_pipe | AK13: 4 | AL13: 49104.7 | AM13: 90302.8 | AN13: 183038.2 | AO13: 0.050944395 | AP13: 2.4647 | AQ13: 0.41267716 | AR13: 13.639616 | AS13: 14.052294 | AW13: 2908.6355 | AX13: 1773.2139 | AY13: pressure_limited_rerun | AZ13: P10/P50/P90 (category-ratio envelope) | BA13: phase2_distance_engine | BB13: emissions_weighted | BC13: FALSE
A14: STO_Saline_onshore_D2Q2P_ARG | B14: CO2ForStorage | C14: 3906000 | D14: 2124000 | E14: 3906000 | F14: 7917300 | G14: 0.011081341 | H14: 0.030485606 | I14: 0.045728408 | J14: 125811.49 | K14: 122537.36 | L14: 119263.22 | M14: 115989.08 | N14: 112714.94 | O14: 109440.81 | P14: 102892.53 | Q14: 96344.257 | R14: 89795.982 | S14: 83247.707 | T14: 76699.432 | V14: PRE | W14: STO_Saline_onshore_D2Q2P_ARG | X14: CO2 storage step -- Saline (8 sites) - onshore_pipe - 50-200km - Argentina | Y14: ktpa | Z14: kt | AB14: Argentina | AC14: ARG | AD14: Saline | AF14: onshore | AG14: D2Q2P | AH14: 50-200km | AI14: Q2 | AJ14: onshore_pipe | AK14: 8 | AL14: 2124 | AM14: 3906 | AN14: 7917.3 | AO14: 0.16022464 | AP14: 7.7517 | AQ14: 3.3313409 | AR14: 7.75 | AS14: 11.081341 | AT14: 6.8856056 | AU14: 23.6 | AV14: 30.485606 | AW14: 125.81149 | AX14: 76.699432 | AY14: pressure_limited_rerun | AZ14: P10/P50/P90 (category-ratio envelope) | BA14: phase2_distance_engine | BB14: emissions_weighted | BC14: TRUE
A15: STO_Saline_offshore_D3Q3S_ARM | B15: CO2ForStorage | C15: 0 | D15: 0 | E15: 0 | F15: 0 | G15: 0.077606254 | H15: 0.13237551 | I15: 0.19856326 | J15: 0 | K15: 0 | L15: 0 | M15: 0 | N15: 0 | O15: 0 | P15: 0 | Q15: 0 | R15: 0 | S15: 0 | T15: 0 | V15: PRE | W15: STO_Saline_offshore_D3Q3S_ARM | X15: CO2 storage step -- Saline (1 site) - offshore_ship - 200-500km - ARM | Y15: ktpa | Z15: kt | AB15: ARM | AC15: ARM | AD15: Saline | AF15: offshore | AG15: D3Q3S | AH15: 200-500km | AI15: Q3 | AJ15: offshore_ship | AK15: 1 | AL15: 0 | AM15: 0 | AN15: 0 | AO15: 0.55988097 | AP15: 0.9219 | AQ15: 36.090438 | AR15: 41.515816 | AS15: 77.606254 | AT15: 53.913043 | AU15: 78.462462 | AV15: 132.37551 | AW15: 0 | AX15: 0 | AY15: pressure_limited_rerun | AZ15: P10/P50/P90 (category-ratio envelope) | BA15: phase2_distance_engine | BB15: emissions_weighted | BC15: TRUE
A16: STO_Saline_onshore_D1Q3P_ARM | B16: CO2ForStorage | C16: 20100 | D16: 10900 | E16: 20100 | F16: 40700 | G16: 0.015221687 | J16: 804 | K16: 804 | L16: 804 | M16: 804 | N16: 804 | O16: 804 | P16: 804 | Q16: 804 | R16: 804 | S16: 804 | T16: 804 | V16: PRE | W16: STO_Saline_onshore_D1Q3P_ARM | X16: CO2 storage step -- Saline (2 sites) - onshore_pipe - 0-50km - ARM | Y16: ktpa | Z16: kt | AB16: ARM | AC16: ARM | AD16: Saline | AF16: onshore | AG16: D1Q3P | AH16: 0-50km | AI16: Q3 | AJ16: onshore_pipe | AK16: 2 | AL16: 10.9 | AM16: 20.1 | AN16: 40.7 | AO16: 0.44011903 | AP16: 0.7247 | AQ16: 0.39461032 | AR16: 14.827077 | AS16: 15.221687 | AW16: 0.804 | AX16: 0.804 | AY16: pressure_limited_rerun | AZ16: P10/P50/P90 (category-ratio envelope) | BA16: phase2_distance_engine | BB16: emissions_weighted+life_capped | BC16: FALSE
A17: STO_Petroleum_onshore_D2Q1P_AUS | B17: CO2ForStorage | C17: 182500 | D17: 140100 | E17: 182500 | F17: 307400 | G17: 0.0064609799 | H17: 0.012517372 | I17: 0.018776058 | J17: 7300 | K17: 7300 | L17: 7300 | M17: 7300 | N17: 7300 | O17: 7300 | P17: 7300 | Q17: 7300 | R17: 7300 | S17: 7300 | T17: 7300 | V17: PRE | W17: STO_Petroleum_onshore_D2Q1P_AUS | X17: CO2 storage step -- Petroleum (1 site) - onshore_pipe - 50-200km - Australia | Y17: ktpa | Z17: kt | AB17: Australia | AC17: AUS | AD17: Petroleum | AF17: onshore | AG17: D2Q1P | AH17: 50-200km | AI17: Q1 | AJ17: onshore_pipe | AK17: 1 | AL17: 140.1 | AM17: 182.5 | AN17: 307.4 | AO17: 0.043052703 | AP17: 6.14 | AQ17: 2.7409799 | AR17: 3.72 | AS17: 6.4609799 | AT17: 3.8373719 | AU17: 8.68 | AV17: 12.517372 | AW17: 7.3 | AX17: 7.3 | AY17: voidage | AZ17: P10/P50/P90 (category-ratio envelope) | BA17: phase2_distance_engine | BB17: emissions_weighted+life_capped | BC17: TRUE
A18: STO_Petroleum_onshore_D3Q1P_AUS | B18: CO2ForStorage | C18: 1315200 | D18: 1009500 | E18: 1315200 | F18: 2214400 | G18: 0.0054694275 | H18: 0.012986482 | I18: 0.019479723 | J18: 52608 | K18: 52608 | L18: 52608 | M18: 52608 | N18: 52608 | O18: 52608 | P18: 52608 | Q18: 52608 | R18: 52608 | S18: 52608 | T18: 52608 | V18: PRE | W18: STO_Petroleum_onshore_D3Q1P_AUS | X18: CO2 storage step -- Petroleum (5 sites) - onshore_pipe - 200-500km - Australia | Y18: ktpa | Z18: kt | AB18: Australia | AC18: AUS | AD18: Petroleum | AF18: onshore | AG18: D3Q1P | AH18: 200-500km | AI18: Q1 | AJ18: onshore_pipe | AK18: 5 | AL18: 1009.5 | AM18: 1315.2 | AN18: 2214.4 | AO18: 0.31018982 | AP18: 44.238 | AQ18: 1.7494275 | AR18: 3.72 | AS18: 5.4694275 | AT18: 4.3064823 | AU18: 8.68 | AV18: 12.986482 | AW18: 52.608 | AX18: 52.608 | AY18: voidage | AZ18: P10/P50/P90 (category-ratio envelope) | BA18: phase2_distance_engine | BB18: emissions_weighted+life_capped | BC18: TRUE
A19: STO_Saline_onshore_D1Q1P_AUS | B19: CO2ForStorage | C19: 160700 | D19: 87400 | E19: 160700 | F19: 325600 | G19: 0.0068213622 | H19: 0.016491431 | I19: 0.024737147 | J19: 3537.6732 | K19: 3440.3577 | L19: 3343.0422 | M19: 3245.7267 | N19: 3148.4112 | O19: 3051.0957 | P19: 2856.4647 | Q19: 2661.8338 | R19: 2467.2028 | S19: 2272.5718 | T19: 2077.9408 | V19: PRE | W19: STO_Saline_onshore_D1Q1P_AUS | X19: CO2 storage step -- Saline (6 sites) - onshore_pipe - 0-50km - Australia | Y19: ktpa | Z19: kt | AB19: Australia | AC19: AUS | AD19: Saline | AF19: onshore | AG19: D1Q1P | AH19: 0-50km | AI19: Q1 | AJ19: onshore_pipe | AK19: 6 | AL19: 87.4 | AM19: 160.7 | AN19: 325.6 | AO19: 0.037890586 | AP19: 5.4038 | AQ19: 0.62136219 | AR19: 6.2 | AS19: 6.8213622 | AT19: 1.6114313 | AU19: 14.88 | AV19: 16.491431 | AW19: 3.5376732 | AX19: 2.0779408 | AY19: pressure_limited_rerun | AZ19: P10/P50/P90 (category-ratio envelope) | BA19: phase2_distance_engine | BB19: emissions_weighted | BC19: TRUE
A20: STO_Saline_onshore_D1Q2P_AUS | B20: CO2ForStorage | C20: 43037200 | D20: 23402700 | E20: 43037200 | F20: 87233700 | G20: 0.0081093171 | H20: 0.024357233 | I20: 0.036535849 | J20: 947427.19 | K20: 921365.04 | L20: 895302.9 | M20: 869240.76 | N20: 843178.62 | O20: 817116.47 | P20: 764992.19 | Q20: 712867.9 | R20: 660743.62 | S20: 608619.33 | T20: 556495.04 | V20: PRE | W20: STO_Saline_onshore_D1Q2P_AUS | X20: CO2 storage step -- Saline (30 sites) - onshore_pipe - 0-50km - Australia | Y20: ktpa | Z20: kt | AB20: Australia | AC20: AUS | AD20: Saline | AF20: onshore | AG20: D1Q2P | AH20: 0-50km | AI20: Q2 | AJ20: onshore_pipe | AK20: 30 | AL20: 23402.7 | AM20: 43037.2 | AN20: 87233.7 | AO20: 0.35615314 | AP20: 50.7931 | AQ20: 0.3593171 | AR20: 7.75 | AS20: 8.1093171 | AT20: 0.75723287 | AU20: 23.6 | AV20: 24.357233 | AW20: 947.42719 | AX20: 556.49504 | AY20: pressure_limited_rerun | AZ20: P10/P50/P90 (category-ratio envelope) | BA20: phase2_distance_engine | BB20: emissions_weighted | BC20: TRUE
A21: STO_Saline_onshore_D1Q3P_AUS | B21: CO2ForStorage | C21: 172404600 | D21: 93749800 | E21: 172404600 | F21: 349453400 | G21: 0.015570465 | H21: 0.04745665 | I21: 0.071184975 | J21: 3795340 | K21: 3690936.5 | L21: 3586533 | M21: 3482129.5 | N21: 3377726.1 | O21: 3273322.6 | P21: 3064515.6 | Q21: 2855708.7 | R21: 2646901.7 | S21: 2438094.8 | T21: 2229287.8 | V21: PRE | W21: STO_Saline_onshore_D1Q3P_AUS | X21: CO2 storage step -- Saline (5 sites) - onshore_pipe - 0-50km - Australia | Y21: ktpa | Z21: kt | AB21: Australia | AC21: AUS | AD21: Saline | AF21: onshore | AG21: D1Q3P | AH21: 0-50km | AI21: Q3 | AJ21: onshore_pipe | AK21: 5 | AL21: 93749.8 | AM21: 172404.6 | AN21: 349453.4 | AO21: 0.01070638 | AP21: 1.5269 | AQ21: 1.8333761 | AR21: 13.737088 | AS21: 15.570465 | AT21: 2.3031312 | AU21: 45.153519 | AV21: 47.45665 | AW21: 3795.34 | AX21: 2229.2878 | AY21: pressure_limited_rerun | AZ21: P10/P50/P90 (category-ratio envelope) | BA21: phase2_distance_engine | BB21: emissions_weighted | BC21: TRUE
A22: STO_Saline_onshore_D2Q1P_AUS | B22: CO2ForStorage | C22: 44900 | D22: 24400 | E22: 44900 | F22: 91000 | G22: 0.0071327789 | H22: 0.016934205 | I22: 0.025401307 | J22: 988.43514 | K22: 961.24493 | L22: 934.05473 | M22: 906.86453 | N22: 879.67432 | O22: 852.48412 | P22: 798.10371 | Q22: 743.72331 | R22: 689.3429 | S22: 634.9625 | T22: 580.58209 | V22: PRE | W22: STO_Saline_onshore_D2Q1P_AUS | X22: CO2 storage step -- Saline (1 site) - onshore_pipe - 50-200km - Australia | Y22: ktpa | Z22: kt | AB22: Australia | AC22: AUS | AD22: Saline | AF22: onshore | AG22: D2Q1P | AH22: 50-200km | AI22: Q1 | AJ22: onshore_pipe | AK22: 1 | AL22: 24.4 | AM22: 44.9 | AN22: 91 | AO22: 0.010586477 | AP22: 1.5098 | AQ22: 0.93277886 | AR22: 6.2 | AS22: 7.1327789 | AT22: 2.0542047 | AU22: 14.88 | AV22: 16.934205 | AW22: 0.98843514 | AX22: 0.58058209 | AY22: pressure_limited_rerun | AZ22: P10/P50/P90 (category-ratio envelope) | BA22: phase2_distance_engine | BB22: emissions_weighted | BC22: TRUE
A23: STO_Saline_onshore_D2Q2P_AUS | B23: CO2ForStorage | C23: 27476900 | D23: 14941300 | E23: 27476900 | F23: 55693900 | G23: 0.0094287921 | H23: 0.02753597 | I23: 0.041303955 | J23: 604880.48 | K23: 588241.22 | L23: 571601.97 | M23: 554962.72 | N23: 538323.46 | O23: 521684.21 | P23: 488405.7 | Q23: 455127.19 | R23: 421848.69 | S23: 388570.18 | T23: 355291.67 | V23: PRE | W23: STO_Saline_onshore_D2Q2P_AUS | X23: CO2 storage step -- Saline (16 sites) - onshore_pipe - 50-200km - Australia | Y23: ktpa | Z23: kt | AB23: Australia | AC23: AUS | AD23: Saline | AF23: onshore | AG23: D2Q2P | AH23: 50-200km | AI23: Q2 | AJ23: onshore_pipe | AK23: 16 | AL23: 14941.3 | AM23: 27476.9 | AN23: 55693.9 | AO23: 0.22738418 | AP23: 32.4286 | AQ23: 1.6787921 | AR23: 7.75 | AS23: 9.4287921 | AT23: 3.9359698 | AU23: 23.6 | AV23: 27.53597 | AW23: 604.88048 | AX23: 355.29167 | AY23: pressure_limited_rerun | AZ23: P10/P50/P90 (category-ratio envelope) | BA23: phase2_distance_engine | BB23: emissions_weighted | BC23: TRUE
A24: STO_Saline_onshore_D2Q3P_AUS | B24: CO2ForStorage | C24: 65003100 | D24: 35347300 | E24: 65003100 | F24: 131757400 | G24: 0.027396901 | H24: 0.064277256 | I24: 0.096415883 | J24: 1430987.7 | K24: 1391623.6 | L24: 1352259.5 | M24: 1312895.4 | N24: 1273531.4 | O24: 1234167.3 | P24: 1155439.1 | Q24: 1076710.9 | R24: 997982.75 | S24: 919254.58 | T24: 840526.41 | V24: PRE | W24: STO_Saline_onshore_D2Q3P_AUS | X24: CO2 storage step -- Saline (2 sites) - onshore_pipe - 50-200km - Australia | Y24: ktpa | Z24: kt | AB24: Australia | AC24: AUS | AD24: Saline | AF24: onshore | AG24: D2Q3P | AH24: 50-200km | AI24: Q3 | AJ24: onshore_pipe | AK24: 2 | AL24: 35347.3 | AM24: 65003.1 | AN24: 131757.4 | AO24: 0.0040367168 | AP24: 0.5757 | AQ24: 13.659812 | AR24: 13.737088 | AS24: 27.396901 | AT24: 19.123737 | AU24: 45.153519 | AV24: 64.277256 | AW24: 1430.9877 | AX24: 840.52641 | AY24: pressure_limited_rerun | AZ24: P10/P50/P90 (category-ratio envelope) | BA24: phase2_distance_engine | BB24: emissions_weighted | BC24: TRUE
A25: STO_Petroleum_onshore_D1Q1P_AUT | B25: CO2ForStorage | C25: 146000 | D25: 112100 | E25: 146000 | F25: 245800 | G25: 0.0041284479 | H25: 0.0093728152 | I25: 0.014059223 | J25: 2210 | K25: 2210 | L25: 2210 | M25: 2210 | N25: 2210 | O25: 2210 | P25: 2210 | Q25: 2210 | R25: 2210 | S25: 2210 | T25: 2210 | V25: PRE | W25: STO_Petroleum_onshore_D1Q1P_AUT | X25: CO2 storage step -- Petroleum (6 sites) - onshore_pipe - 0-50km - Austria | Y25: ktpa | Z25: kt | AB25: Austria | AC25: AUT | AD25: Petroleum | AF25: onshore | AG25: D1Q1P | AH25: 0-50km | AI25: Q1 | AJ25: onshore_pipe | AK25: 6 | AL25: 112.1 | AM25: 146 | AN25: 245.8 | AO25: 0.61563621 | AP25: 13.7969 | AQ25: 0.40844794 | AR25: 3.72 | AS25: 4.1284479 | AT25: 0.69281525 | AU25: 8.68 | AV25: 9.3728152 | AW25: 2.21 | AX25: 2.21 | AY25: voidage | AZ25: P10/P50/P90 (category-ratio envelope) | BA25: phase2_distance_engine | BB25: emissions_weighted | BC25: TRUE
A26: STO_Saline_onshore_D1Q3P_AUT | B26: CO2ForStorage | C26: 492000 | D26: 267500 | E26: 492000 | F26: 997300 | G26: 0.03009346 | H26: 0.099130473 | I26: 0.14869571 | J26: 19680 | K26: 19680 | L26: 19680 | M26: 19680 | N26: 19680 | O26: 19680 | P26: 19680 | Q26: 19680 | R26: 19680 | S26: 19680 | T26: 19680 | V26: PRE | W26: STO_Saline_onshore_D1Q3P_AUT | X26: CO2 storage step -- Saline (8 sites) - onshore_pipe - 0-50km - Austria | Y26: ktpa | Z26: kt | AB26: Austria | AC26: AUT | AD26: Saline | AF26: onshore | AG26: D1Q3P | AH26: 0-50km | AI26: Q3 | AJ26: onshore_pipe | AK26: 8 | AL26: 267.5 | AM26: 492 | AN26: 997.3 | AO26: 0.36498028 | AP26: 8.1795 | AQ26: 0.43961488 | AR26: 29.653845 | AS26: 30.09346 | AT26: 0.97662926 | AU26: 98.153844 | AV26: 99.130473 | AW26: 19.68 | AX26: 19.68 | AY26: pressure_limited_rerun | AZ26: P10/P50/P90 (category-ratio envelope) | BA26: phase2_distance_engine | BB26: emissions_weighted+life_capped | BC26: TRUE
A27: STO_Saline_onshore_D2Q3P_AUT | B27: CO2ForStorage | C27: 26100 | D27: 14200 | E27: 26100 | F27: 53000 | G27: 0.035518028 | H27: 0.1063637 | I27: 0.15954555 | J27: 1044 | K27: 1044 | L27: 1044 | M27: 1044 | N27: 1044 | O27: 1044 | P27: 1044 | Q27: 1044 | R27: 1044 | S27: 1044 | T27: 1044 | V27: PRE | W27: STO_Saline_onshore_D2Q3P_AUT | X27: CO2 storage step -- Saline (1 site) - onshore_pipe - 50-200km - Austria | Y27: ktpa | Z27: kt | AB27: Austria | AC27: AUT | AD27: Saline | AF27: onshore | AG27: D2Q3P | AH27: 50-200km | AI27: Q3 | AJ27: onshore_pipe | AK27: 1 | AL27: 14.2 | AM27: 26.1 | AN27: 53 | AO27: 0.019383512 | AP27: 0.4344 | AQ27: 5.8641827 | AR27: 29.653845 | AS27: 35.518028 | AT27: 8.2098558 | AU27: 98.153844 | AV27: 106.3637 | AW27: 1.044 | AX27: 1.044 | AY27: pressure_limited_rerun | AZ27: P10/P50/P90 (category-ratio envelope) | BA27: phase2_distance_engine | BB27: emissions_weighted+life_capped | BC27: TRUE
A28: STO_Petroleum_onshore_D1Q3P_AZE | B28: CO2ForStorage | C28: 12180600 | D28: 9349000 | E28: 12180600 | F28: 20508700 | G28: 0.0091616236 | H28: 0.026390432 | I28: 0.039585647 | J28: 38761.018 | K28: 38761.018 | L28: 38761.018 | M28: 38761.018 | N28: 38761.018 | O28: 38761.018 | P28: 38761.018 | Q28: 38761.018 | R28: 38761.018 | S28: 38761.018 | T28: 38761.018 | V28: PRE | W28: STO_Petroleum_onshore_D1Q3P_AZE | X28: CO2 storage step -- Petroleum (7 sites) - onshore_pipe - 0-50km - Azerbaijan | Y28: ktpa | Z28: kt | AB28: Azerbaijan | AC28: AZE | AD28: Petroleum | AF28: onshore | AG28: D1Q3P | AH28: 0-50km | AI28: Q3 | AJ28: onshore_pipe | AK28: 7 | AL28: 9349 | AM28: 12180.6 | AN28: 20508.7 | AO28: 0.77132244 | AP28: 9.3438 | AQ28: 0.26538101 | AR28: 8.8962426 | AS28: 9.1616236 | AT28: 0.67858253 | AU28: 25.711849 | AV28: 26.390432 | AW28: 38.761018 | AX28: 38.761018 | AY28: voidage | AZ28: P10/P50/P90 (category-ratio envelope) | BA28: phase2_distance_engine | BB28: emissions_weighted | BC28: TRUE
... A36: STO_Petroleum_onshore_D2Q1P_BGD | B36: CO2ForStorage | C36: 802200 | D36: 615700 | E36: 802200 | F36: 1350700 | G36: 0.0053729618 | H36: 0.012588247 | I36: 0.018882371 | J36: 2499.4297 | K36: 2499.4297 | L36: 2499.4297 | M36: 2499.4297 | N36: 2499.4297 | O36: 2499.4297 | P36: 2499.4297 | Q36: 2499.4297 | R36: 2499.4297 | S36: 2499.4297 | T36: 2499.4297 | V36: PRE | W36: STO_Petroleum_onshore_D2Q1P_BGD | X36: CO2 storage step -- Petroleum (16 sites) - onshore_pipe - 50-200km - Bangladesh | Y36: ktpa | Z36: kt | AB36: Bangladesh | AC36: BGD | AD36: Petroleum | AF36: onshore | AG36: D2Q1P | AH36: 50-200km | AI36: Q1 | AJ36: onshore_pipe | AK36: 16 | AL36: 615.7 | AM36: 802.2 | AN36: 1350.7 | AO36: 0.57632 | AP36: 26.8568 | AQ36: 1.6529618 | AR36: 3.72 | AS36: 5.3729618 | AT36: 3.9082472 | AU36: 8.68 | AV36: 12.588247 | AW36: 2.4994297 | AX36: 2.4994297 | AY36: voidage | AZ36: P10/P50/P90 (category-ratio envelope) | BA36: phase2_distance_engine | BB36: emissions_weighted | BC36: TRUE
A37: STO_Petroleum_onshore_D3Q3P_BGD | B37: CO2ForStorage | C37: 2503400 | D37: 1921400 | E37: 2503400 | F37: 4215000 | G37: 0.014789461 | J37: 7799.8906 | K37: 7799.8906 | L37: 7799.8906 | M37: 7799.8906 | N37: 7799.8906 | O37: 7799.8906 | P37: 7799.8906 | Q37: 7799.8906 | R37: 7799.8906 | S37: 7799.8906 | T37: 7799.8906 | V37: PRE | W37: STO_Petroleum_onshore_D3Q3P_BGD | X37: CO2 storage step -- Petroleum (1 site) - onshore_pipe - 200-500km - Bangladesh | Y37: ktpa | Z37: kt | AB37: Bangladesh | AC37: BGD | AD37: Petroleum | AF37: onshore | AG37: D3Q3P | AH37: 200-500km | AI37: Q3 | AJ37: onshore_pipe | AK37: 1 | AL37: 1921.4 | AM37: 2503.4 | AN37: 4215 | AO37: 0.013167241 | AP37: 0.6136 | AQ37: 6.030553 | AR37: 8.7589077 | AS37: 14.789461 | AW37: 7.7998906 | AX37: 7.7998906 | AY37: voidage | AZ37: P10/P50/P90 (category-ratio envelope) | BA37: phase2_distance_engine | BB37: emissions_weighted | BC37: FALSE
A38: STO_Saline_onshore_D1Q3P_BGD | B38: CO2ForStorage | C38: 29776600 | D38: 16191800 | E38: 29776600 | F38: 60355300 | G38: 0.014901776 | H38: 0.049039354 | I38: 0.073559031 | J38: 474738.9 | K38: 463680.25 | L38: 452621.61 | M38: 441562.96 | N38: 430504.32 | O38: 419445.68 | P38: 397328.39 | Q38: 375211.1 | R38: 353093.81 | S38: 330976.52 | T38: 308859.23 | V38: PRE | W38: STO_Saline_onshore_D1Q3P_BGD | X38: CO2 storage step -- Saline (9 sites) - onshore_pipe - 0-50km - Bangladesh | Y38: ktpa | Z38: kt | AB38: Bangladesh | AC38: BGD | AD38: Saline | AF38: onshore | AG38: D1Q3P | AH38: 0-50km | AI38: Q3 | AJ38: onshore_pipe | AK38: 9 | AL38: 16191.8 | AM38: 29776.6 | AN38: 60355.3 | AO38: 0.15661849 | AP38: 7.2985 | AQ38: 0.30359646 | AR38: 14.59818 | AS38: 14.901776 | AT38: 0.78590766 | AU38: 48.253446 | AV38: 49.039354 | AW38: 474.7389 | AX38: 308.85923 | AY38: pressure_limited_rerun | AZ38: P10/P50/P90 (category-ratio envelope) | BA38: phase2_distance_engine | BB38: emissions_weighted | BC38: TRUE
A39: STO_Saline_onshore_D3Q2P_BGD | B39: CO2ForStorage | C39: 7900 | D39: 4300 | E39: 7900 | F39: 16000 | G39: 0.014184015 | H39: 0.046288876 | I39: 0.069433315 | J39: 125.9525 | K39: 123.01854 | L39: 120.08459 | M39: 117.15063 | N39: 114.21667 | O39: 111.28271 | P39: 105.4148 | Q39: 99.546882 | R39: 93.678966 | S39: 87.81105 | T39: 81.943134 | V39: PRE | W39: STO_Saline_onshore_D3Q2P_BGD | X39: CO2 storage step -- Saline (2 sites) - onshore_pipe - 200-500km - Bangladesh | Y39: ktpa | Z39: kt | AB39: Bangladesh | AC39: BGD | AD39: Saline | AF39: onshore | AG39: D3Q2P | AH39: 200-500km | AI39: Q2 | AJ39: onshore_pipe | AK39: 2 | AL39: 4.3 | AM39: 7.9 | AN39: 16 | AO39: 0.01626592 | AP39: 0.758 | AQ39: 6.4340155 | AR39: 7.75 | AS39: 14.184015 | AT39: 22.688876 | AU39: 23.6 | AV39: 46.288876 | AW39: 0.1259525 | AX39: 0.081943134 | AY39: pressure_limited_rerun | AZ39: P10/P50/P90 (category-ratio envelope) | BA39: phase2_distance_engine | BB39: emissions_weighted | BC39: TRUE
A40: STO_Saline_onshore_D1Q2P_BGR | B40: CO2ForStorage | C40: 85700 | D40: 46600 | E40: 85700 | F40: 173600 | G40: 0.008484063 | J40: 3428 | K40: 3428 | L40: 3428 | M40: 3428 | N40: 3428 | O40: 3428 | P40: 3428 | Q40: 3428 | R40: 3428 | S40: 3428 | T40: 3428 | V40: PRE | W40: STO_Saline_onshore_D1Q2P_BGR | X40: CO2 storage step -- Saline (5 sites) - onshore_pipe - 0-50km - Bulgaria | Y40: ktpa | Z40: kt | AB40: Bulgaria | AC40: BGR | AD40: Saline | AF40: onshore | AG40: D1Q2P | AH40: 0-50km | AI40: Q2 | AJ40: onshore_pipe | AK40: 5 | AL40: 46.6 | AM40: 85.7 | AN40: 173.6 | AO40: 0.15341295 | AP40: 3.634 | AQ40: 0.73406304 | AR40: 7.75 | AS40: 8.484063 | AW40: 3.428 | AX40: 3.428 | AY40: pressure_limited_rerun | AZ40: P10/P50/P90 (category-ratio envelope) | BA40: phase2_distance_engine | BB40: emissions_weighted+life_capped | BC40: FALSE
A41: STO_Saline_onshore_D1Q3P_BGR | B41: CO2ForStorage | C41: 3693600 | D41: 2008500 | E41: 3693600 | F41: 7486600 | G41: 0.015181925 | H41: 0.050943311 | I41: 0.076414967 | J41: 147744 | K41: 147744 | L41: 147744 | M41: 147744 | N41: 147744 | O41: 147744 | P41: 147744 | Q41: 147744 | R41: 147744 | S41: 147744 | T41: 147744 | V41: PRE | W41: STO_Saline_onshore_D1Q3P_BGR | X41: CO2 storage step -- Saline (5 sites) - onshore_pipe - 0-50km - Bulgaria | Y41: ktpa | Z41: kt | AB41: Bulgaria | AC41: BGR | AD41: Saline | AF41: onshore | AG41: D1Q3P | AH41: 0-50km | AI41: Q3 | AJ41: onshore_pipe | AK41: 5 | AL41: 2008.5 | AM41: 3693.6 | AN41: 7486.6 | AO41: 0.50600945 | AP41: 11.9862 | AQ41: 0.62714453 | AR41: 14.554781 | AS41: 15.181925 | AT41: 2.8461003 | AU41: 48.097211 | AV41: 50.943311 | AW41: 147.744 | AX41: 147.744 | AY41: pressure_limited_rerun | AZ41: P10/P50/P90 (category-ratio envelope) | BA41: phase2_distance_engine | BB41: emissions_weighted+life_capped | BC41: TRUE
A42: STO_Saline_onshore_D2Q2P_BGR | B42: CO2ForStorage | C42: 92300 | D42: 50200 | E42: 92300 | F42: 187100 | G42: 0.0088442304 | H42: 0.025252728 | I42: 0.037879092 | J42: 3692 | K42: 3692 | L42: 3692 | M42: 3692 | N42: 3692 | O42: 3692 | P42: 3692 | Q42: 3692 | R42: 3692 | S42: 3692 | T42: 3692 | V42: PRE | W42: STO_Saline_onshore_D2Q2P_BGR | X42: CO2 storage step -- Saline (1 site) - onshore_pipe - 50-200km - Bulgaria | Y42: ktpa | Z42: kt | AB42: Bulgaria | AC42: BGR | AD42: Saline | AF42: onshore | AG42: D2Q2P | AH42: 50-200km | AI42: Q2 | AJ42: onshore_pipe | AK42: 1 | AL42: 50.2 | AM42: 92.3 | AN42: 187.1 | AO42: 0.16535586 | AP42: 3.9169 | AQ42: 1.0942304 | AR42: 7.75 | AS42: 8.8442304 | AT42: 1.6527278 | AU42: 23.6 | AV42: 25.252728 | AW42: 3.692 | AX42: 3.692 | AY42: pressure_limited_rerun | AZ42: P10/P50/P90 (category-ratio envelope) | BA42: phase2_distance_engine | BB42: emissions_weighted+life_capped | BC42: TRUE
A43: STO_Saline_onshore_D2Q3P_BGR | B43: CO2ForStorage | C43: 1279000 | D43: 695500 | E43: 1279000 | F43: 2592500 | G43: 0.016419955 | H43: 0.054303281 | I43: 0.081454921 | J43: 51160 | K43: 51160 | L43: 51160 | M43: 51160 | N43: 51160 | O43: 51160 | P43: 51160 | Q43: 51160 | R43: 51160 | S43: 51160 | T43: 51160 | V43: PRE | W43: STO_Saline_onshore_D2Q3P_BGR | X43: CO2 storage step -- Saline (3 sites) - onshore_pipe - 50-200km - Bulgaria | Y43: ktpa | Z43: kt | AB43: Bulgaria | AC43: BGR | AD43: Saline | AF43: onshore | AG43: D2Q3P | AH43: 50-200km | AI43: Q3 | AJ43: onshore_pipe | AK43: 3 | AL43: 695.5 | AM43: 1279 | AN43: 2592.5 | AO43: 0.17522174 | AP43: 4.1506 | AQ43: 1.8651739 | AR43: 14.554781 | AS43: 16.419955 | AT43: 6.2060701 | AU43: 48.097211 | AV43: 54.303281 | AW43: 51.16 | AX43: 51.16 | AY43: pressure_limited_rerun | AZ43: P10/P50/P90 (category-ratio envelope) | BA43: phase2_distance_engine | BB43: emissions_weighted+life_capped | BC43: TRUE
A44: STO_Petroleum_onshore_D2Q3P_BHR | B44: CO2ForStorage | C44: 122700 | D44: 94100 | E44: 122700 | F44: 206500 | G44: 0.0091389587 | H44: 0.025948312 | I44: 0.038922468 | J44: 0 | K44: 0 | L44: 0 | M44: 0 | N44: 0 | O44: 0 | P44: 0 | Q44: 0 | R44: 0 | S44: 0 | T44: 0 | V44: PRE | W44: STO_Petroleum_onshore_D2Q3P_BHR | X44: CO2 storage step -- Petroleum (1 site) - onshore_pipe - 50-200km - BHR | Y44: ktpa | Z44: kt | AB44: BHR | AC44: BHR | AD44: Petroleum | AF44: onshore | AG44: D2Q3P | AH44: 50-200km | AI44: Q3 | AJ44: onshore_pipe | AK44: 1 | AL44: 94.1 | AM44: 122.7 | AN44: 206.5 | AO44: 0.38814432 | AP44: 5.7372 | AQ44: 0.63130578 | AR44: 8.5076529 | AS44: 9.1389587 | AT44: 1.5965268 | AU44: 24.351785 | AV44: 25.948312 | AW44: 0 | AX44: 0 | AY44: voidage | AZ44: P10/P50/P90 (category-ratio envelope) | BA44: phase2_distance_engine | BB44: emissions_weighted | BC44: TRUE
A45: STO_Saline_offshore_D1Q2P_BHR | B45: CO2ForStorage | C45: 131100 | D45: 71300 | E45: 131100 | F45: 265800 | G45: 0.022094924 | H45: 0.036611987 | I45: 0.054917981 | J45: 0 | K45: 0 | L45: 0 | M45: 0 | N45: 0 | O45: 0 | P45: 0 | Q45: 0 | R45: 0 | S45: 0 | T45: 0 | V45: PRE | W45: STO_Saline_offshore_D1Q2P_BHR | X45: CO2 storage step -- Saline (5 sites) - offshore_pipe - 0-50km - BHR | Y45: ktpa | Z45: kt | AB45: BHR | AC45: BHR | AD45: Saline | AF45: offshore | AG45: D1Q2P | AH45: 0-50km | AI45: Q2 | AJ45: offshore_pipe | AK45: 5 | AL45: 71.3 | AM45: 131.1 | AN45: 265.8 | AO45: 0.34241024 | AP45: 5.0612 | AQ45: 0.3949238 | AR45: 21.7 | AS45: 22.094924 | AT45: 0.61198728 | AU45: 36 | AV45: 36.611987 | AW45: 0 | AX45: 0 | AY45: no_tier1_rate | AZ45: P10/P50/P90 (category-ratio envelope) | BA45: phase2_distance_engine | BB45: emissions_weighted | BC45: TRUE
A46: STO_Saline_onshore_D1Q2P_BHR | B46: CO2ForStorage | C46: 1600 | D46: 900 | E46: 1600 | F46: 3300 | G46: 0.0078372899 | H46: 0.023715549 | I46: 0.035573324 | J46: 0 | K46: 0 | L46: 0 | M46: 0 | N46: 0 | O46: 0 | P46: 0 | Q46: 0 | R46: 0 | S46: 0 | T46: 0 | V46: PRE | W46: STO_Saline_onshore_D1Q2P_BHR | X46: CO2 storage step -- Saline (1 site) - onshore_pipe - 0-50km - BHR | Y46: ktpa | Z46: kt | AB46: BHR | AC46: BHR | AD46: Saline | AF46: onshore | AG46: D1Q2P | AH46: 0-50km | AI46: Q2 | AJ46: onshore_pipe | AK46: 1 | AL46: 0.9 | AM46: 1.6 | AN46: 3.3 | AO46: 0.26944544 | AP46: 3.9827 | AQ46: 0.087289869 | AR46: 7.75 | AS46: 7.8372899 | AT46: 0.11554938 | AU46: 23.6 | AV46: 23.715549 | AW46: 0 | AX46: 0 | AY46: no_tier1_rate | AZ46: P10/P50/P90 (category-ratio envelope) | BA46: phase2_distance_engine | BB46: emissions_weighted | BC46: TRUE
A47: STO_Saline_offshore_D2Q3S_BIH | B47: CO2ForStorage | C47: 2400 | D47: 1300 | E47: 2400 | F47: 4800 | G47: 0.069048525 | H47: 0.12127097 | I47: 0.18190646 | J47: 96 | K47: 96 | L47: 96 | M47: 96 | N47: 96 | O47: 96 | P47: 96 | Q47: 96 | R47: 96 | S47: 96 | T47: 96 | V47: PRE | W47: STO_Saline_offshore_D2Q3S_BIH | X47: CO2 storage step -- Saline (3 sites) - offshore_ship - 50-200km - Bosnia and Herzegovina | Y47: ktpa | Z47: kt | AB47: Bosnia and Herzegovina | AC47: BIH | AD47: Saline | AF47: offshore | AG47: D2Q3S | AH47: 50-200km | AI47: Q3 | AJ47: offshore_ship | AK47: 3 | AL47: 1.3 | AM47: 2.4 | AN47: 4.8 | AO47: 0.28896628 | AP47: 3.6178 | AQ47: 27.532709 | AR47: 41.515816 | AS47: 69.048525 | AT47: 42.808511 | AU47: 78.462462 | AV47: 121.27097 | AW47: 0.096 | AX47: 0.096 | AY47: pressure_limited_rerun | AZ47: P10/P50/P90 (category-ratio envelope) | BA47: phase2_distance_engine | BB47: emissions_weighted+life_capped | BC47: TRUE
A48: STO_Saline_onshore_D1Q3P_BIH | B48: CO2ForStorage | C48: 212400 | D48: 115500 | E48: 212400 | F48: 430600 | G48: 0.015337046 | H48: 0.050318619 | I48: 0.075477928 | J48: 8496 | K48: 8496 | L48: 8496 | M48: 8496 | N48: 8496 | O48: 8496 | P48: 8496 | Q48: 8496 | R48: 8496 | S48: 8496 | T48: 8496 | V48: PRE | W48: STO_Saline_onshore_D1Q3P_BIH | X48: CO2 storage step -- Saline (5 sites) - onshore_pipe - 0-50km - Bosnia and Herzegovina | Y48: ktpa | Z48: kt | AB48: Bosnia and Herzegovina | AC48: BIH | AD48: Saline | AF48: onshore | AG48: D1Q3P | AH48: 0-50km | AI48: Q3 | AJ48: onshore_pipe | AK48: 5 | AL48: 115.5 | AM48: 212.4 | AN48: 430.6 | AO48: 0.71103372 | AP48: 8.902 | AQ48: 0.50996884 | AR48: 14.827077 | AS48: 15.337046 | AT48: 1.2411414 | AU48: 49.077477 | AV48: 50.318619 | AW48: 8.496 | AX48: 8.496 | AY48: pressure_limited_rerun | AZ48: P10/P50/P90 (category-ratio envelope) | BA48: phase2_distance_engine | BB48: emissions_weighted+life_capped | BC48: TRUE
...

Sheet spv
A1: ~fi_process | I1: ~fi_t | P1: ~fi_process | X1: ~fi_t
A2: set | B2: process | C2: description | D2: capacity_unit | E2: activity_unit | F2: timeslicelevel | G2: vintage | I2: process | J2: comm-out | K2: cap_bnd | L2: af~fx | M2: avg_grid_dist_km | N2: invcost~USD21_alt | P2: set | Q2: process | R2: description | S2: capacity_unit | T2: activity_unit | U2: timeslicelevel | V2: vintage | X2: process | Y2: comm-out | Z2: EFF
A3: ele | B3: en_spv_AFG_001 | C3: solar resource in Kunduz region (near Kunduz) -- Afghanistan | D3: GW | E3: PJ | F3: annual | G3: no | I3: en_spv_AFG_001 | J3: elc_spv_AFG_001 | K3: 40.429624 | L3: 0.24209172 | M3: 65.282529 | N3: 71.810782 | P3: ele | Q3: elcagg_spv_AFG | R3: solar aggregator to grid -- Afghanistan | S3: GW | T3: PJ | U3: daynite | V3: no | X3: elcagg_spv_AFG | Y3: ELC | Z3: 1
A4: ele | B4: en_spv_AFG_002 | C4: solar resource in Faryab region (near Aqchah) -- Afghanistan | D4: GW | E4: PJ | F4: annual | G4: no | I4: en_spv_AFG_002 | J4: elc_spv_AFG_002 | K4: 35.885729 | L4: 0.24322688 | M4: 131.68484 | N4: 144.85332 | P4: ele | Q4: elcagg_spv_AGO | R4: solar aggregator to grid -- Angola | S4: GW | T4: PJ | U4: daynite | V4: no | X4: elcagg_spv_AGO | Y4: ELC | Z4: 1
A5: ele | B5: en_spv_AFG_003 | C5: solar resource in Herat region (near Herat) -- Afghanistan | D5: GW | E5: PJ | F5: annual | G5: no | I5: en_spv_AFG_003 | J5: elc_spv_AFG_003 | K5: 1.7962177 | L5: 0.28135755 | M5: 196.73382 | N5: 216.4072 | P5: ele | Q5: elcagg_spv_ALB | R5: solar aggregator to grid -- Albania | S5: GW | T5: PJ | U5: daynite | V5: no | X5: elcagg_spv_ALB | Y5: ELC | Z5: 1
A6: ele | B6: en_spv_AFG_004 | C6: solar resource in Herat region (near Herat) -- Afghanistan | D6: GW | E6: PJ | F6: annual | G6: no | I6: en_spv_AFG_004 | J6: elc_spv_AFG_004 | K6: 26.77047 | L6: 0.25611273 | M6: 133.8085 | N6: 147.18935 | P6: ele | Q6: elcagg_spv_ARE | R6: solar aggregator to grid -- United Arab Emirates | S6: GW | T6: PJ | U6: daynite | V6: no | X6: elcagg_spv_ARE | Y6: ELC | Z6: 1
A7: ele | B7: en_spv_AFG_005 | C7: solar resource in Zabul region (near Kandahar) -- Afghanistan | D7: GW | E7: PJ | F7: annual | G7: no | I7: en_spv_AFG_005 | J7: elc_spv_AFG_005 | K7: 37.987338 | L7: 0.28061222 | M7: 176.56115 | N7: 194.21727 | P7: ele | Q7: elcagg_spv_ARG | R7: solar aggregator to grid -- Argentina | S7: GW | T7: PJ | U7: daynite | V7: no | X7: elcagg_spv_ARG | Y7: ELC | Z7: 1
A8: ele | B8: en_spv_AFG_006 | C8: solar resource in Paktika region (near Kabul) -- Afghanistan | D8: GW | E8: PJ | F8: annual | G8: no | I8: en_spv_AFG_006 | J8: elc_spv_AFG_006 | K8: 17.571408 | L8: 0.26265162 | M8: 164.63721 | N8: 181.10093 | P8: ele | Q8: elcagg_spv_ARM | R8: solar aggregator to grid -- Armenia | S8: GW | T8: PJ | U8: daynite | V8: no | X8: elcagg_spv_ARM | Y8: ELC | Z8: 1
A9: ele | B9: en_spv_AFG_007 | C9: solar resource in Federally Administered Tribal Areas region (near Jalalabad) -- Afghanistan | D9: GW | E9: PJ | F9: annual | G9: no | I9: en_spv_AFG_007 | J9: elc_spv_AFG_007 | K9: 0.64643546 | L9: 0.23136532 | M9: 104.57988 | N9: 115.03787 | P9: ele | Q9: elcagg_spv_AUS | R9: solar aggregator to grid -- Australia | S9: GW | T9: PJ | U9: daynite | V9: no | X9: elcagg_spv_AUS | Y9: ELC | Z9: 1
A10: ele | B10: en_spv_AFG_008 | C10: solar resource in Kandahar region (near Kandahar) -- Afghanistan | D10: GW | E10: PJ | F10: annual | G10: no | I10: en_spv_AFG_008 | J10: elc_spv_AFG_008 | K10: 94.698737 | L10: 0.27584854 | M10: 116.95457 | N10: 128.65002 | P10: ele | Q10: elcagg_spv_AUT | R10: solar aggregator to grid -- Austria | S10: GW | T10: PJ | U10: daynite | V10: no | X10: elcagg_spv_AUT | Y10: ELC | Z10: 1
A11: ele | B11: en_spv_AFG_009 | C11: solar resource in Nimruz region (near Farah) -- Afghanistan | D11: GW | E11: PJ | F11: annual | G11: no | I11: en_spv_AFG_009 | J11: elc_spv_AFG_009 | K11: 105.31756 | L11: 0.27260803 | M11: 156.78052 | N11: 172.45857 | P11: ele | Q11: elcagg_spv_AZE | R11: solar aggregator to grid -- Azerbaijan | S11: GW | T11: PJ | U11: daynite | V11: no | X11: elcagg_spv_AZE | Y11: ELC | Z11: 1
