Workbook
Name Cars_12: '[1]TechRep-Doc'!#REF!
Name ddddd: [2]AGR_Fuels!$A$2
Name DISCRATE: '[1]TechRep-Doc'!#REF!
Name FID_1: [3]AGR_Fuels!$A$2
Name GROWTH: '[1]TechRep-Doc'!#REF!
Name GROWTH_TID: '[1]TechRep-Doc'!#REF!
Name INVCOST: '[1]TechRep-Doc'!#REF!
Name LIFE: '[1]TechRep-Doc'!#REF!
Name NAs_CCAR: '[1]TechRep-Doc'!#REF!
Name SETS: '[1]TechRep-Doc'!#REF!
Name TRTGAB005: '[1]TechRep-Doc'!#REF!
Name TRTGAC005: '[1]TechRep-Doc'!#REF!
Name Trucks_15: '[1]TechRep-Doc'!#REF!
Name TSUB_COST: '[1]TechRep-Doc'!#REF!
Name x: [1]AGR_Fuels!$A$2

Sheet Discuss_log
B2: Discuss log: 02/17 | C2: to input EFF for recycling processes; validate the cost (learning rate); lower and upper values [throughout should increase with time]
C3: Manufacture costs for different batteries
C4: Make sure one approach is correct, then incorporate other two
C5: Website for categorizing countries;
C6: We will keep detagling cost because amit is also not sure about decommining
C8: Migrate to Trans | D8: Flo_bound for different mining; you don't need to seperate them to different processes

Sheet Cover
B7: Techno-economic assumptions of the PRIMES-TREMOVE transport model
B10: © E3-Modelling

Sheet Small_cars
B1: Modelled economic possibilities for reducing specific energy consumption by transport mode/equipment and fuel/technology over time
B2: © E3-Modelling
B5: Reference values for Small size ICE gasoline
B6: 2015
B7: Energy consumption | C7: lt/100 km | D7: 5.4692719
B8: Capital cost | C8: Euro15 /veh | D8: 14228.271
B10: Reduction of specific energy consumption relative to 2015 gasoline vehicle (%) | C10: ICE Small size gasoline car
C13: 2020 | D13: 2030 | E13: 2040 | F13: 2050
B14: 0.14660195 | C14: 14411.641 | D14: 14288.29 | E14: 14288.29 | F14: 14288.29
B15: 0.24660195 | C15: 15078.096 | D15: 14591.542 | E15: 14591.542 | F15: 14591.542
B16: 0.34660195 | C16: 16731.894 | D16: 15344.176 | E16: 15344.176 | F16: 15344.176
B17: 0.39660195 | C17: 18944.887 | D17: 16114.335 | E17: 16114.335 | F17: 16114.335
B18: 0.44660195 | C18: 38658.679 | D18: 18014.252 | E18: 18014.252 | F18: 18014.252
B19: 0.49660195 | C19: 114048 | D19: 37206.372 | E19: 37206.372 | F19: 37206.372
B24: Reduction of specific energy consumption relative to 2015 gasoline vehicle (%) | C24: ICE Small size hybrid gasoline car
C27: 2020 | D27: 2030 | E27: 2040 | F27: 2050
B28: 0.19160195 | C28: 16485.6 | D28: 15586.91 | E28: 15586.91 | F28: 15586.91
B29: 0.29160195 | C29: 16616.3 | D29: 15731.46 | E29: 15731.46 | F29: 15731.46
B30: 0.34160195 | C30: 16732.15 | D30: 15858.84 | E30: 15858.84 | F30: 15858.84
B31: 0.39160195 | C31: 17029.8 | D31: 16087.56 | E31: 16087.56 | F31: 16087.56
B32: 0.44160195 | C32: 17472.24 | D32: 16395.8 | E32: 16395.8 | F32: 16395.8
B33: 0.49160195 | C33: 26028.09 | D33: 16921.19 | E33: 16921.19 | F33: 16921.19
B34: 0.54160195 | C34: 103040.24 | D34: 31789.08 | E34: 31789.08 | F34: 31789.08
B39: Reduction of specific energy consumption relative to 2015 gasoline vehicle (%) | C39: ICE Small size plug-in hybrid gasoline car
C42: 2020 | D42: 2030 | E42: 2040 | F42: 2050
B43: 0.72160195 | C43: 20812.713 | D43: 17365.357 | E43: 16391.882 | F43: 16107.962
B44: 0.73160195 | C44: 20851.39 | D44: 17382.308 | E44: 16398.045 | F44: 16110.409
B45: 0.74410195 | C45: 20931.943 | D45: 17404.545 | E45: 16408.443 | F45: 16116.834
B46: 0.75410195 | C46: 21037.784 | D46: 17418.007 | E46: 16417.16 | F46: 16124.089
B47: 0.76410195 | C47: 21236.317 | D47: 17424.3 | E47: 16427.426 | F47: 16136.084
B48: 0.81160195 | C48: 59492.373 | D48: 18038.155 | E48: 16838.025 | F48: 16485.136
B49: 0.81910195 | C49: 103206.42 | D49: 18410.743 | E49: 17196.049 | F49: 16848.2
B50: 0.82660195 | D50: 35985.742 | E50: 34084.03 | F50: 33973.934
B55: Reference values for small size ICE diesel
B56: 2015
B57: Energy consumption | C57: lt/100 km | D57: 4.0003418
B58: Capital cost | C58: Euro15 /veh | D58: 16512.16
B60: Reduction of specific energy consumption relative to 2015 diesel vehicle (%) | C60: ICE Small size diesel car
C63: 2020 | D63: 2030 | E63: 2040 | F63: 2050
B64: 0.23896485 | C64: 17256.927 | D64: 16675.841 | E64: 16675.841 | F64: 16675.841
...

Sheet Large_cars
B1: Modelled economic possibilities for reducing specific energy consumption by transport mode/equipment and fuel/technology over time
B2: © E3-Modelling
B5: Reference values for Large size ICE gasoline
B6: 2015
B7: Energy consumption | C7: lt/100 km | D7: 7.8951872
B8: Capital cost | C8: Euro15 /veh | D8: 37057.81
B10: Reduction of specific energy consumption relative to 2015 gasoline vehicle (%) | C10: ICE Large size gasoline car
C13: 2020 | D13: 2030 | E13: 2040 | F13: 2050
B14: 0.098944858 | C14: 37317.461 | D14: 37171.82 | E14: 37171.82 | F14: 37171.82
B15: 0.19894486 | C15: 38176.103 | D15: 37390.028 | E15: 37390.028 | F15: 37390.028
B16: 0.29894486 | C16: 40102.528 | D16: 37818.503 | E16: 37818.503 | F16: 37818.503
B17: 0.34894486 | C17: 42408.539 | D17: 38408.139 | E17: 38408.139 | F17: 38408.139
B18: 0.39894486 | C18: 48739.818 | D18: 39463.251 | E18: 39463.251 | F18: 39463.251
B19: 0.44894486 | C19: 103044.93 | D19: 42665.919 | E19: 42665.919 | F19: 42665.919
B24: Reduction of specific energy consumption relative to 2015 gasoline vehicle (%) | C24: ICE Large size hybrid gasoline car
C27: 2020 | D27: 2030 | E27: 2040 | F27: 2050
B28: 0.24644486 | C28: 40649.729 | D28: 39285.929 | E28: 39285.929 | F28: 39285.929
B29: 0.34644486 | C29: 40906.889 | D29: 39430.919 | E29: 39430.919 | F29: 39430.919
B30: 0.39644486 | C30: 41410.249 | D30: 39592.029 | E30: 39592.029 | F30: 39592.029
B31: 0.44644486 | C31: 42124.729 | D31: 39729.289 | E31: 39729.289 | F31: 39729.289
B32: 0.49644486 | C32: 44259.829 | D32: 39901.229 | E32: 39901.229 | F32: 39901.229
B33: 0.54644486 | C33: 81512.519 | D33: 40354.459 | E33: 40354.459 | F33: 40354.459
B34: 0.59644486 | C34: 136921.63 | D34: 48595.519 | E34: 48595.519 | F34: 48595.519
B39: Reduction of specific energy consumption relative to 2015 gasoline vehicle (%) | C39: ICE Large size plug-in hybrid gasoline car
C42: 2020 | D42: 2030 | E42: 2040 | F42: 2050
B43: 0.67394486 | C43: 46420.589 | D43: 41366.35 | E43: 40062.051 | F43: 39681.645
B44: 0.68394486 | C44: 46586.715 | D44: 41403.064 | E44: 40074.719 | F44: 39685.998
B45: 0.69644486 | C45: 46895.555 | D45: 41450.09 | E45: 40091.643 | F45: 39692.546
B46: 0.70644486 | C46: 47296.934 | D46: 41477.605 | E46: 40099.993 | F46: 39694.219
B47: 0.71644486 | C47: 48114.027 | D47: 41493.429 | E47: 40105.023 | F47: 39695.499
B48: 0.76394486 | C48: 108321.21 | D48: 42684.171 | E48: 40858.055 | F48: 40312.216
B49: 0.77144486 | D49: 42729.638 | E49: 40901.744 | F49: 40356.521
B55: Reference values for Large size ICE diesel
B56: 2015
B57: Energy consumption | C57: lt/100 km | D57: 6.7325109
B58: Capital cost | C58: Euro15 /veh | D58: 42530.904
B60: Reduction of specific energy consumption relative to 2015 diesel vehicle (%) | C60: ICE Large size diesel car
C63: 2020 | D63: 2030 | E63: 2040 | F63: 2050
B64: 0.18117419 | C64: 43323.557 | D64: 42722.785 | E64: 42722.785 | F64: 42722.785
B65: 0.28117419 | C65: 45065.867 | D65: 43554.306 | E65: 43554.306 | F65: 43554.306
...

Sheet Medium_cars
B1: Modelled economic possibilities for reducing specific energy consumption by transport mode/equipment and fuel/technology over time | Q1: gsl | R1: ICE medium size gasoline car | S1: ="Trd_car_"&Q1 -> Trd_car_gsl
B2: © E3-Modelling | I2: 0.052009938 | J2: GJ/kg LNG | Q2: gsl-hyb | R2: ICE medium size hybrid gasoline car | S2: ="Trd_car_"&Q2 -> Trd_car_gsl-hyb
I3: =31536000/10^9 -> 0.031536 | J3: GJ/lt Gasoline | Q3: gsl-pih | R3: ICE medium size plug-in hybrid gasoline car | S3: ="Trd_car_"&Q3 -> Trd_car_gsl-pih
I4: 0.038 | J4: GJ/lt Diesel | Q4: dsl | R4: ICE medium size diesel car | S4: ="Trd_car_"&Q4 -> Trd_car_dsl
I5: =1.406/26.137 -> 0.053793473 | J5: GJ/kg CNG | Q5: dsl-hyb | R5: ICE medium size hybrid diesel car | S5: ="Trd_car_"&Q5 -> Trd_car_dsl-hyb
I6: 0.02559 | J6: GJ/lt LPG | Q6: dsl-pih | R6: ICE medium size plug-in hybrid diesel car | S6: ="Trd_car_"&Q6 -> Trd_car_dsl-pih
Q7: cng | R7: ICE medium size CNG car | S7: ="Trd_car_"&Q7 -> Trd_car_cng
Q8: lpg | R8: ICE medium size LPG car | S8: ="\I:Trd_car_"&Q8 -> \I:Trd_car_lpg
Q9: E85 | R9: ICE medium size E85 flex-fuel car | S9: ="\I:Trd_car_"&Q9 -> \I:Trd_car_E85
B10: Reference values for medium size ICE gasoline | Q10: elc | R10: Medium size battery electric car | S10: ="Trd_car_"&Q10 -> Trd_car_elc
B11: 2015 | Q11: hh2 | R11: Medium size hydrogen fuel cell | S11: ="Trd_car_"&Q11 -> Trd_car_hh2
B12: Energy consumption | C12: lt/100 km | D12: 6.8039045 | G12: =D12*$I$3/100*10^9/10^6 -> 2.1456793 | I12: =1/G12 -> 0.46605287
B13: Capital cost | C13: Euro15 /veh | D13: 19114.108 | I13: bvkm/PJ | S13: 0.9015
K15: ~FI_T: UP~EUR15~INVCOST | S15: ~FI_Process
I16: EFF | J16: *process | K16: Process | L16: Comm-OUT | M16: =C20 -> 2020 | N16: =D20 -> 2030 | O16: =E20 -> 2040 | P16: =F20 -> 2050 | Q16: FLO_MARK | S16: Sets | T16: TechName | U16: TechDesc | V16: Tact | W16: Tcap
B17: Reduction of specific energy consumption relative to 2015 gasoline vehicle (%) | C17: ICE medium size gasoline car | J17: =IFERROR(VLOOKUP(C17,$R$1:$S$11,2,FALSE),J16) -> Trd_car_gsl | K17: =IFERROR(IF(VALUE(C17)>2020,J17&"_"&TEXT(B17*100,"00"),"\I:"),"\I:") -> \I: | L17: =LEFT(K17,7) -> \I: | M17: =IF($K17="\I:","",C17) | N17: =IF($K17="\I:","",D17) | O17: =IF($K17="\I:","",E17) | P17: =IF($K17="\I:","",F17) | S17: DMD | T17: =K17 -> \I: | U17: =OFFSET($S$1,MATCH(J17,$S$1:$S$11,0)-1,-1)&" -- "&TEXT(B17,"00%") -> ICE medium size gasoline car -- Reduction of specific energy consumption relative to 2015 gasoline vehicle (%) | V17: Bvkm | W17: million vehicles
J18: =IFERROR(VLOOKUP(C18,$R$1:$S$11,2,FALSE),J17) -> Trd_car_gsl | K18: =IFERROR(IF(VALUE(C18)>2020,J18&"_"&TEXT(B18*100,"00"),"\I:"),"\I:") -> \I: | L18: =LEFT(K18,7) -> \I: | M18: =IF($K18="\I:","",C18) | N18: =IF($K18="\I:","",D18) | O18: =IF($K18="\I:","",E18) | P18: =IF($K18="\I:","",F18) | S18: DMD | T18: =K18 -> \I: | U18: =OFFSET($S$1,MATCH(J18,$S$1:$S$11,0)-1,-1)&" -- "&TEXT(B18,"00%") -> ICE medium size gasoline car -- 00% | V18: Bvkm | W18: million vehicles
J19: =IFERROR(VLOOKUP(C19,$R$1:$S$11,2,FALSE),J18) -> Trd_car_gsl | K19: =IFERROR(IF(VALUE(C19)>2020,J19&"_"&TEXT(B19*100,"00"),"\I:"),"\I:") -> \I: | L19: =LEFT(K19,7) -> \I: | M19: =IF($K19="\I:","",C19) | N19: =IF($K19="\I:","",D19) | O19: =IF($K19="\I:","",E19) | P19: =IF($K19="\I:","",F19) | S19: DMD | T19: =K19 -> \I: | U19: =OFFSET($S$1,MATCH(J19,$S$1:$S$11,0)-1,-1)&" -- "&TEXT(B19,"00%") -> ICE medium size gasoline car -- 00% | V19: Bvkm | W19: million vehicles
B20: 0 | C20: 2020 | D20: 2030 | E20: 2040 | F20: 2050 | I20: 1 | J20: =IFERROR(VLOOKUP(C20,$R$1:$S$11,2,FALSE),J19) -> Trd_car_gsl | K20: =IFERROR(IF(VALUE(C20)>200,J20&"_"&TEXT(B20*100,"00"),"\I:"),"\I:") -> Trd_car_gsl_00 | L20: =LEFT(K20,7) -> Trd_car | M20: =D13 -> 19114.108 | S20: DMD | T20: =K20 -> Trd_car_gsl_00 | U20: =OFFSET($S$1,MATCH(J20,$S$1:$S$11,0)-1,-1)&" -- "&TEXT(B20,"00%") -> ICE medium size gasoline car -- 00% | V20: Bvkm | W20: million vehicles
B21: 0.13362396 | C21: 19378.329 | D21: 19184.954 | E21: 19184.954 | F21: 19184.954 | I21: =(1+B21) -> 1.133624 | J21: =IFERROR(VLOOKUP(C21,$R$1:$S$11,2,FALSE),J20) -> Trd_car_gsl | K21: =IFERROR(IF(VALUE(C21)>2020,J21&"_"&TEXT(B21*100,"00"),"\I:"),"\I:") -> Trd_car_gsl_13 | L21: =LEFT(K21,7) -> Trd_car | M21: =IF($K21="\I:","",C21) -> 19378.329 | N21: =IF($K21="\I:","",D21) -> 19184.954 | O21: =IF($K21="\I:","",E21) -> 19184.954 | P21: =IF($K21="\I:","",F21) -> 19184.954 | S21: DMD | T21: =K21 -> Trd_car_gsl_13 | U21: =OFFSET($S$1,MATCH(J21,$S$1:$S$11,0)-1,-1)&" -- "&TEXT(B21,"00%") -> ICE medium size gasoline car -- 13% | V21: Bvkm | W21: million vehicles
B22: 0.23362396 | C22: 20194.176 | D22: 19445.906 | E22: 19445.906 | F22: 19445.906 | I22: =(1+B22) -> 1.233624 | J22: =IFERROR(VLOOKUP(C22,$R$1:$S$11,2,FALSE),J21) -> Trd_car_gsl | K22: =IFERROR(IF(VALUE(C22)>2020,J22&"_"&TEXT(B22*100,"00"),"\I:"),"\I:") -> Trd_car_gsl_23 | L22: =LEFT(K22,7) -> Trd_car | M22: =IF($K22="\I:","",C22) -> 20194.176 | N22: =IF($K22="\I:","",D22) -> 19445.906 | O22: =IF($K22="\I:","",E22) -> 19445.906 | P22: =IF($K22="\I:","",F22) -> 19445.906 | S22: DMD | T22: =K22 -> Trd_car_gsl_23 | U22: =OFFSET($S$1,MATCH(J22,$S$1:$S$11,0)-1,-1)&" -- "&TEXT(B22,"00%") -> ICE medium size gasoline car -- 23% | V22: Bvkm | W22: million vehicles
B23: 0.33362396 | C23: 21957.324 | D23: 20077.205 | E23: 20077.205 | F23: 20077.205 | I23: =(1+B23) -> 1.333624 | J23: =IFERROR(VLOOKUP(C23,$R$1:$S$11,2,FALSE),J22) -> Trd_car_gsl | K23: =IFERROR(IF(VALUE(C23)>2020,J23&"_"&TEXT(B23*100,"00"),"\I:"),"\I:") -> Trd_car_gsl_33 | L23: =LEFT(K23,7) -> Trd_car | M23: =IF($K23="\I:","",C23) -> 21957.324 | N23: =IF($K23="\I:","",D23) -> 20077.205 | O23: =IF($K23="\I:","",E23) -> 20077.205 | P23: =IF($K23="\I:","",F23) -> 20077.205 | S23: DMD | T23: =K23 -> Trd_car_gsl_33 | U23: =OFFSET($S$1,MATCH(J23,$S$1:$S$11,0)-1,-1)&" -- "&TEXT(B23,"00%") -> ICE medium size gasoline car -- 33% | V23: Bvkm | W23: million vehicles
B24: 0.38362396 | C24: 24470.648 | D24: 20810.347 | E24: 20810.347 | F24: 20810.347 | I24: =(1+B24) -> 1.383624 | J24: =IFERROR(VLOOKUP(C24,$R$1:$S$11,2,FALSE),J23) -> Trd_car_gsl | K24: =IFERROR(IF(VALUE(C24)>2020,J24&"_"&TEXT(B24*100,"00"),"\I:"),"\I:") -> Trd_car_gsl_38 | L24: =LEFT(K24,7) -> Trd_car | M24: =IF($K24="\I:","",C24) -> 24470.648 | N24: =IF($K24="\I:","",D24) -> 20810.347 | O24: =IF($K24="\I:","",E24) -> 20810.347 | P24: =IF($K24="\I:","",F24) -> 20810.347 | S24: DMD | T24: =K24 -> Trd_car_gsl_38 | U24: =OFFSET($S$1,MATCH(J24,$S$1:$S$11,0)-1,-1)&" -- "&TEXT(B24,"00%") -> ICE medium size gasoline car -- 38% | V24: Bvkm | W24: million vehicles
B25: 0.43362396 | C25: 53739.803 | D25: 22623.261 | E25: 22623.261 | F25: 22623.261 | I25: =(1+B25) -> 1.433624 | J25: =IFERROR(VLOOKUP(C25,$R$1:$S$11,2,FALSE),J24) -> Trd_car_gsl | K25: =IFERROR(IF(VALUE(C25)>2020,J25&"_"&TEXT(B25*100,"00"),"\I:"),"\I:") -> Trd_car_gsl_43 | L25: =LEFT(K25,7) -> Trd_car | M25: =IF($K25="\I:","",C25) -> 53739.803 | N25: =IF($K25="\I:","",D25) -> 22623.261 | O25: =IF($K25="\I:","",E25) -> 22623.261 | P25: =IF($K25="\I:","",F25) -> 22623.261 | S25: DMD | T25: =K25 -> Trd_car_gsl_43 | U25: =OFFSET($S$1,MATCH(J25,$S$1:$S$11,0)-1,-1)&" -- "&TEXT(B25,"00%") -> ICE medium size gasoline car -- 43% | V25: Bvkm | W25: million vehicles
B26: 0.48362396 | C26: 118918.12 | D26: 41097.305 | E26: 41097.305 | F26: 41097.305 | I26: =(1+B26) -> 1.483624 | J26: =IFERROR(VLOOKUP(C26,$R$1:$S$11,2,FALSE),J25) -> Trd_car_gsl | K26: =IFERROR(IF(VALUE(C26)>2020,J26&"_"&TEXT(B26*100,"00"),"\I:"),"\I:") -> Trd_car_gsl_48 | L26: =LEFT(K26,7) -> Trd_car | M26: =IF($K26="\I:","",C26) -> 118918.12 | N26: =IF($K26="\I:","",D26) -> 41097.305 | O26: =IF($K26="\I:","",E26) -> 41097.305 | P26: =IF($K26="\I:","",F26) -> 41097.305 | S26: DMD | T26: =K26 -> Trd_car_gsl_48 | U26: =OFFSET($S$1,MATCH(J26,$S$1:$S$11,0)-1,-1)&" -- "&TEXT(B26,"00%") -> ICE medium size gasoline car -- 48% | V26: Bvkm | W26: million vehicles
J27: =IFERROR(VLOOKUP(C27,$R$1:$S$11,2,FALSE),J26) -> Trd_car_gsl | K27: =IFERROR(IF(VALUE(C27)>2020,J27&"_"&TEXT(B27*100,"00"),"\I:"),"\I:") -> \I: | L27: =LEFT(K27,7) -> \I: | M27: =IF($K27="\I:","",C27) | N27: =IF($K27="\I:","",D27) | O27: =IF($K27="\I:","",E27) | P27: =IF($K27="\I:","",F27) | T27: =K27 -> \I: | U27: =OFFSET($S$1,MATCH(J27,$S$1:$S$11,0)-1,-1)&" -- "&TEXT(B27,"00%") -> ICE medium size gasoline car -- 00% | V27: Bvkm | W27: million vehicles
J28: =IFERROR(VLOOKUP(C28,$R$1:$S$11,2,FALSE),J27) -> Trd_car_gsl | K28: =IFERROR(IF(VALUE(C28)>2020,J28&"_"&TEXT(B28*100,"00"),"\I:"),"\I:") -> \I: | L28: =LEFT(K28,7) -> \I: | M28: =IF($K28="\I:","",C28) | N28: =IF($K28="\I:","",D28) | O28: =IF($K28="\I:","",E28) | P28: =IF($K28="\I:","",F28) | T28: =K28 -> \I: | U28: =OFFSET($S$1,MATCH(J28,$S$1:$S$11,0)-1,-1)&" -- "&TEXT(B28,"00%") -> ICE medium size gasoline car -- 00% | V28: Bvkm | W28: million vehicles
J29: =IFERROR(VLOOKUP(C29,$R$1:$S$11,2,FALSE),J28) -> Trd_car_gsl | K29: =IFERROR(IF(VALUE(C29)>2020,J29&"_"&TEXT(B29*100,"00"),"\I:"),"\I:") -> \I: | L29: =LEFT(K29,7) -> \I: | M29: =IF($K29="\I:","",C29) | N29: =IF($K29="\I:","",D29) | O29: =IF($K29="\I:","",E29) | P29: =IF($K29="\I:","",F29) | T29: =K29 -> \I: | U29: =OFFSET($S$1,MATCH(J29,$S$1:$S$11,0)-1,-1)&" -- "&TEXT(B29,"00%") -> ICE medium size gasoline car -- 00% | V29: Bvkm | W29: million vehicles
J30: =IFERROR(VLOOKUP(C30,$R$1:$S$11,2,FALSE),J29) -> Trd_car_gsl | K30: =IFERROR(IF(VALUE(C30)>2020,J30&"_"&TEXT(B30*100,"00"),"\I:"),"\I:") -> \I: | L30: =LEFT(K30,7) -> \I: | M30: =IF($K30="\I:","",C30) | N30: =IF($K30="\I:","",D30) | O30: =IF($K30="\I:","",E30) | P30: =IF($K30="\I:","",F30) | T30: =K30 -> \I: | U30: =OFFSET($S$1,MATCH(J30,$S$1:$S$11,0)-1,-1)&" -- "&TEXT(B30,"00%") -> ICE medium size gasoline car -- 00% | V30: Bvkm | W30: million vehicles
B31: Reduction of specific energy consumption relative to 2015 gasoline vehicle (%) | C31: ICE medium size hybrid gasoline car | J31: =IFERROR(VLOOKUP(C31,$R$1:$S$11,2,FALSE),J30) -> Trd_car_gsl-hyb | K31: =IFERROR(IF(VALUE(C31)>2020,J31&"_"&TEXT(B31*100,"00"),"\I:"),"\I:") -> \I: | L31: =LEFT(K31,7) -> \I: | M31: =IF($K31="\I:","",C31) | N31: =IF($K31="\I:","",D31) | O31: =IF($K31="\I:","",E31) | P31: =IF($K31="\I:","",F31) | T31: =K31 -> \I: | U31: =OFFSET($S$1,MATCH(J31,$S$1:$S$11,0)-1,-1)&" -- "&TEXT(B31,"00%") -> ICE medium size hybrid gasoline car -- Reduction of specific energy consumption relative to 2015 gasoline vehicle (%) | V31: Bvkm | W31: million vehicles
J32: =IFERROR(VLOOKUP(C32,$R$1:$S$11,2,FALSE),J31) -> Trd_car_gsl-hyb | K32: =IFERROR(IF(VALUE(C32)>2020,J32&"_"&TEXT(B32*100,"00"),"\I:"),"\I:") -> \I: | L32: =LEFT(K32,7) -> \I: | M32: =IF($K32="\I:","",C32) | N32: =IF($K32="\I:","",D32) | O32: =IF($K32="\I:","",E32) | P32: =IF($K32="\I:","",F32) | T32: =K32 -> \I: | U32: =OFFSET($S$1,MATCH(J32,$S$1:$S$11,0)-1,-1)&" -- "&TEXT(B32,"00%") -> ICE medium size hybrid gasoline car -- 00% | V32: Bvkm | W32: million vehicles
J33: =IFERROR(VLOOKUP(C33,$R$1:$S$11,2,FALSE),J32) -> Trd_car_gsl-hyb | K33: =IFERROR(IF(VALUE(C33)>2020,J33&"_"&TEXT(B33*100,"00"),"\I:"),"\I:") -> \I: | L33: =LEFT(K33,7) -> \I: | M33: =IF($K33="\I:","",C33) | N33: =IF($K33="\I:","",D33) | O33: =IF($K33="\I:","",E33) | P33: =IF($K33="\I:","",F33) | T33: =K33 -> \I: | U33: =OFFSET($S$1,MATCH(J33,$S$1:$S$11,0)-1,-1)&" -- "&TEXT(B33,"00%") -> ICE medium size hybrid gasoline car -- 00% | V33: Bvkm | W33: million vehicles
C34: 2020 | D34: 2030 | E34: 2040 | F34: 2050 | J34: =IFERROR(VLOOKUP(C34,$R$1:$S$11,2,FALSE),J33) -> Trd_car_gsl-hyb | K34: =IFERROR(IF(VALUE(C34)>2020,J34&"_"&TEXT(B34*100,"00"),"\I:"),"\I:") -> \I: | L34: =LEFT(K34,7) -> \I: | M34: =IF($K34="\I:","",C34) | N34: =IF($K34="\I:","",D34) | O34: =IF($K34="\I:","",E34) | P34: =IF($K34="\I:","",F34) | T34: =K34 -> \I: | U34: =OFFSET($S$1,MATCH(J34,$S$1:$S$11,0)-1,-1)&" -- "&TEXT(B34,"00%") -> ICE medium size hybrid gasoline car -- 00% | V34: Bvkm | W34: million vehicles
B35: 0.23611494 | C35: 21857.344 | D35: 20782.131 | E35: 20782.131 | F35: 20782.131 | I35: =(1+B35) -> 1.2361149 | J35: =IFERROR(VLOOKUP(C35,$R$1:$S$11,2,FALSE),J34) -> Trd_car_gsl-hyb | K35: =IFERROR(IF(VALUE(C35)>2020,J35&"_"&TEXT(B35*100,"00"),"\I:"),"\I:") -> Trd_car_gsl-hyb_24 | L35: =LEFT(K35,7) -> Trd_car | M35: =IF($K35="\I:","",C35) -> 21857.344 | N35: =IF($K35="\I:","",D35) -> 20782.131 | O35: =IF($K35="\I:","",E35) -> 20782.131 | P35: =IF($K35="\I:","",F35) -> 20782.131 | T35: =K35 -> Trd_car_gsl-hyb_24 | U35: =OFFSET($S$1,MATCH(J35,$S$1:$S$11,0)-1,-1)&" -- "&TEXT(B35,"00%") -> ICE medium size hybrid gasoline car -- 24% | V35: Bvkm | W35: million vehicles
B36: 0.33611494 | C36: 22033.117 | D36: 20950.891 | E36: 20950.891 | F36: 20950.891 | I36: =(1+B36) -> 1.3361149 | J36: =IFERROR(VLOOKUP(C36,$R$1:$S$11,2,FALSE),J35) -> Trd_car_gsl-hyb | K36: =IFERROR(IF(VALUE(C36)>2020,J36&"_"&TEXT(B36*100,"00"),"\I:"),"\I:") -> Trd_car_gsl-hyb_34 | L36: =LEFT(K36,7) -> Trd_car | M36: =IF($K36="\I:","",C36) -> 22033.117 | N36: =IF($K36="\I:","",D36) -> 20950.891 | O36: =IF($K36="\I:","",E36) -> 20950.891 | P36: =IF($K36="\I:","",F36) -> 20950.891 | T36: =K36 -> Trd_car_gsl-hyb_34 | U36: =OFFSET($S$1,MATCH(J36,$S$1:$S$11,0)-1,-1)&" -- "&TEXT(B36,"00%") -> ICE medium size hybrid gasoline car -- 34% | V36: Bvkm | W36: million vehicles
B37: 0.38611494 | C37: 22246.228 | D37: 21100.82 | E37: 21100.82 | F37: 21100.82 | I37: =(1+B37) -> 1.3861149 | J37: =IFERROR(VLOOKUP(C37,$R$1:$S$11,2,FALSE),J36) -> Trd_car_gsl-hyb | K37: =IFERROR(IF(VALUE(C37)>2020,J37&"_"&TEXT(B37*100,"00"),"\I:"),"\I:") -> Trd_car_gsl-hyb_39 | L37: =LEFT(K37,7) -> Trd_car | M37: =IF($K37="\I:","",C37) -> 22246.228 | N37: =IF($K37="\I:","",D37) -> 21100.82 | O37: =IF($K37="\I:","",E37) -> 21100.82 | P37: =IF($K37="\I:","",F37) -> 21100.82 | T37: =K37 -> Trd_car_gsl-hyb_39 | U37: =OFFSET($S$1,MATCH(J37,$S$1:$S$11,0)-1,-1)&" -- "&TEXT(B37,"00%") -> ICE medium size hybrid gasoline car -- 39% | V37: Bvkm | W37: million vehicles
B38: 0.43611494 | C38: 22681.265 | D38: 21227.425 | E38: 21227.425 | F38: 21227.425 | I38: =(1+B38) -> 1.4361149 | J38: =IFERROR(VLOOKUP(C38,$R$1:$S$11,2,FALSE),J37) -> Trd_car_gsl-hyb | K38: =IFERROR(IF(VALUE(C38)>2020,J38&"_"&TEXT(B38*100,"00"),"\I:"),"\I:") -> Trd_car_gsl-hyb_44 | L38: =LEFT(K38,7) -> Trd_car | M38: =IF($K38="\I:","",C38) -> 22681.265 | N38: =IF($K38="\I:","",D38) -> 21227.425 | O38: =IF($K38="\I:","",E38) -> 21227.425 | P38: =IF($K38="\I:","",F38) -> 21227.425 | T38: =K38 -> Trd_car_gsl-hyb_44 | U38: =OFFSET($S$1,MATCH(J38,$S$1:$S$11,0)-1,-1)&" -- "&TEXT(B38,"00%") -> ICE medium size hybrid gasoline car -- 44% | V38: Bvkm | W38: million vehicles
B39: 0.48611494 | C39: 23657.608 | D39: 21496.841 | E39: 21496.841 | F39: 21496.841 | I39: =(1+B39) -> 1.4861149 | J39: =IFERROR(VLOOKUP(C39,$R$1:$S$11,2,FALSE),J38) -> Trd_car_gsl-hyb | K39: =IFERROR(IF(VALUE(C39)>2020,J39&"_"&TEXT(B39*100,"00"),"\I:"),"\I:") -> Trd_car_gsl-hyb_49 | L39: =LEFT(K39,7) -> Trd_car | M39: =IF($K39="\I:","",C39) -> 23657.608 | N39: =IF($K39="\I:","",D39) -> 21496.841 | O39: =IF($K39="\I:","",E39) -> 21496.841 | P39: =IF($K39="\I:","",F39) -> 21496.841 | T39: =K39 -> Trd_car_gsl-hyb_49 | U39: =OFFSET($S$1,MATCH(J39,$S$1:$S$11,0)-1,-1)&" -- "&TEXT(B39,"00%") -> ICE medium size hybrid gasoline car -- 49% | V39: Bvkm | W39: million vehicles
B40: 0.53611494 | C40: 45787.585 | D40: 22147.35 | E40: 22147.35 | F40: 22147.35 | I40: =(1+B40) -> 1.5361149 | J40: =IFERROR(VLOOKUP(C40,$R$1:$S$11,2,FALSE),J39) -> Trd_car_gsl-hyb | K40: =IFERROR(IF(VALUE(C40)>2020,J40&"_"&TEXT(B40*100,"00"),"\I:"),"\I:") -> Trd_car_gsl-hyb_54 | L40: =LEFT(K40,7) -> Trd_car | M40: =IF($K40="\I:","",C40) -> 45787.585 | N40: =IF($K40="\I:","",D40) -> 22147.35 | O40: =IF($K40="\I:","",E40) -> 22147.35 | P40: =IF($K40="\I:","",F40) -> 22147.35 | T40: =K40 -> Trd_car_gsl-hyb_54 | U40: =OFFSET($S$1,MATCH(J40,$S$1:$S$11,0)-1,-1)&" -- "&TEXT(B40,"00%") -> ICE medium size hybrid gasoline car -- 54% | V40: Bvkm | W40: million vehicles
B41: 0.58611494 | C41: 118918.12 | D41: 34938.661 | E41: 34938.661 | F41: 34938.661 | I41: =(1+B41) -> 1.5861149 | J41: =IFERROR(VLOOKUP(C41,$R$1:$S$11,2,FALSE),J40) -> Trd_car_gsl-hyb | K41: =IFERROR(IF(VALUE(C41)>2020,J41&"_"&TEXT(B41*100,"00"),"\I:"),"\I:") -> Trd_car_gsl-hyb_59 | L41: =LEFT(K41,7) -> Trd_car | M41: =IF($K41="\I:","",C41) -> 118918.12 | N41: =IF($K41="\I:","",D41) -> 34938.661 | O41: =IF($K41="\I:","",E41) -> 34938.661 | P41: =IF($K41="\I:","",F41) -> 34938.661 | T41: =K41 -> Trd_car_gsl-hyb_59 | U41: =OFFSET($S$1,MATCH(J41,$S$1:$S$11,0)-1,-1)&" -- "&TEXT(B41,"00%") -> ICE medium size hybrid gasoline car -- 59% | V41: Bvkm | W41: million vehicles
...

Sheet LCVs
B1: Modelled economic possibilities for reducing specific energy consumption by transport mode/equipment and fuel/technology over time | Q1: gsl | R1: ICE gasoline LCV | S1: ="Trd_lcv_"&Q1 -> Trd_lcv_gsl
B2: © E3-Modelling | Q2: gsl-hyb | R2: ICE gasoline hybrid LCV | S2: ="Trd_lcv_"&Q2 -> Trd_lcv_gsl-hyb
Q3: gsl-pih | R3: ICE gasoline plug-in hybrid LCV | S3: ="Trd_lcv_"&Q3 -> Trd_lcv_gsl-pih
Q4: dsl | R4: ICE diesel LCV | S4: ="Trd_lcv_"&Q4 -> Trd_lcv_dsl
Q5: dsl-hyb | R5: ICE hybrid diesel LCV | S5: ="Trd_lcv_"&Q5 -> Trd_lcv_dsl-hyb
Q6: dsl-pih | R6: ICE plug-in hybrid diesel LCV | S6: ="Trd_lcv_"&Q6 -> Trd_lcv_dsl-pih
F7: =31536000/10^9 -> 0.031536 | G7: GJ/lt Gasoline | Q7: cng | R7: ICE CNG LCV | S7: ="Trd_lcv_"&Q7 -> Trd_lcv_cng
F8: 0.038 | G8: GJ/lt Diesel | Q8: lpg | R8: ICE LPG LCV | S8: ="\I:Trd_lcv_"&Q8 -> \I:Trd_lcv_lpg
B9: Reference values for gasoline LCV | F9: =1.406/26.137 -> 0.053793473 | G9: GJ/kg CNG | Q9: elc | R9: Battery electric LCV | S9: ="Trd_lcv_"&Q9 -> Trd_lcv_elc
B10: 2015 | F10: 0.02559 | G10: GJ/lt LPG | Q10: hh2 | R10: Hydrogen fuel cell LCV | S10: ="Trd_lcv_"&Q10 -> Trd_lcv_hh2
B11: Energy consumption | C11: lt/100 km | D11: 8.5078255 | G11: =D11*$F$7/100*10^9/10^6 -> 2.6830279 | I11: =1/G11 -> 0.37271324
B12: Capital cost | C12: Euro15 /veh | D12: 17407.979 | I12: bvkm/PJ
K14: ~FI_T: UP~EUR15~INVCOST | S14: ~FI_Process
I15: EFF | J15: *process | K15: Process | L15: Comm-OUT | M15: =C19 -> 2020 | N15: =D19 -> 2030 | O15: =E19 -> 2040 | P15: =F19 -> 2050 | Q15: FLO_MARK | S15: Sets | T15: TechName | U15: TechDesc | V15: Tact | W15: Tcap
B16: Reduction of specific energy consumption relative to 2015 gasoline vehicle (%) | C16: ICE gasoline LCV | J16: =IFERROR(VLOOKUP(C16,$R$1:$S$10,2,FALSE),J14) -> Trd_lcv_gsl | K16: =IFERROR(IF(VALUE(C16)>2020,J16&"_"&TEXT(B16*100,"00"),"\I:"),"\I:") -> \I: | L16: =LEFT(K16,7) -> \I: | M16: =IF($K16="\I:","",C16) | N16: =IF($K16="\I:","",D16) | O16: =IF($K16="\I:","",E16) | P16: =IF($K16="\I:","",F16) | S16: DMD | T16: =K16 -> \I: | U16: =OFFSET($S$1,MATCH(J16,$S$1:$S$10,0)-1,-1)&" -- "&TEXT(B16,"00%") -> ICE gasoline LCV -- Reduction of specific energy consumption relative to 2015 gasoline vehicle (%) | V16: Bvkm | W16: million vehicles
J17: =IFERROR(VLOOKUP(C17,$R$1:$S$10,2,FALSE),J16) -> Trd_lcv_gsl | K17: =IFERROR(IF(VALUE(C17)>2020,J17&"_"&TEXT(B17*100,"00"),"\I:"),"\I:") -> \I: | L17: =LEFT(K17,7) -> \I: | M17: =IF($K17="\I:","",C17) | N17: =IF($K17="\I:","",D17) | O17: =IF($K17="\I:","",E17) | P17: =IF($K17="\I:","",F17) | S17: DMD | T17: =K17 -> \I: | U17: =OFFSET($S$1,MATCH(J17,$S$1:$S$10,0)-1,-1)&" -- "&TEXT(B17,"00%") -> ICE gasoline LCV -- 00% | V17: Bvkm | W17: million vehicles
J18: =IFERROR(VLOOKUP(C18,$R$1:$S$10,2,FALSE),J17) -> Trd_lcv_gsl | K18: =IFERROR(IF(VALUE(C18)>2020,J18&"_"&TEXT(B18*100,"00"),"\I:"),"\I:") -> \I: | L18: =LEFT(K18,7) -> \I: | M18: =IF($K18="\I:","",C18) | N18: =IF($K18="\I:","",D18) | O18: =IF($K18="\I:","",E18) | P18: =IF($K18="\I:","",F18) | S18: DMD | T18: =K18 -> \I: | U18: =OFFSET($S$1,MATCH(J18,$S$1:$S$10,0)-1,-1)&" -- "&TEXT(B18,"00%") -> ICE gasoline LCV -- 00% | V18: Bvkm | W18: million vehicles
C19: 2020 | D19: 2030 | E19: 2040 | F19: 2050 | I19: 1 | J19: =IFERROR(VLOOKUP(C19,$R$1:$S$11,2,FALSE),J18) -> Trd_lcv_gsl | K19: =IFERROR(IF(VALUE(C19)>200,J19&"_"&TEXT(B19*100,"00"),"\I:"),"\I:") -> Trd_lcv_gsl_00 | L19: =LEFT(K19,7) -> Trd_lcv | M19: =D12 -> 17407.979 | S19: DMD | T19: =K19 -> Trd_lcv_gsl_00 | U19: =OFFSET($S$1,MATCH(J19,$S$1:$S$10,0)-1,-1)&" -- "&TEXT(B19,"00%") -> ICE gasoline LCV -- 00% | V19: Bvkm | W19: million vehicles
B20: 0.14556058 | C20: 17878.598 | D20: 17417.427 | E20: 17417.427 | F20: 17417.427 | I20: =(1+B20) -> 1.1455606 | J20: =IFERROR(VLOOKUP(C20,$R$1:$S$10,2,FALSE),J19) -> Trd_lcv_gsl | K20: =IFERROR(IF(VALUE(C20)>2020,J20&"_"&TEXT(B20*100,"00"),"\I:"),"\I:") -> Trd_lcv_gsl_15 | L20: =LEFT(K20,7) -> Trd_lcv | M20: =IF($K20="\I:","",C20) -> 17878.598 | N20: =IF($K20="\I:","",D20) -> 17417.427 | O20: =IF($K20="\I:","",E20) -> 17417.427 | P20: =IF($K20="\I:","",F20) -> 17417.427 | S20: DMD | T20: =K20 -> Trd_lcv_gsl_15 | U20: =OFFSET($S$1,MATCH(J20,$S$1:$S$10,0)-1,-1)&" -- "&TEXT(B20,"00%") -> ICE gasoline LCV -- 15% | V20: Bvkm | W20: million vehicles
B21: 0.24556058 | C21: 19243.432 | D21: 17966.601 | E21: 17966.601 | F21: 17966.601 | I21: =(1+B21) -> 1.2455606 | J21: =IFERROR(VLOOKUP(C21,$R$1:$S$10,2,FALSE),J20) -> Trd_lcv_gsl | K21: =IFERROR(IF(VALUE(C21)>2020,J21&"_"&TEXT(B21*100,"00"),"\I:"),"\I:") -> Trd_lcv_gsl_25 | L21: =LEFT(K21,7) -> Trd_lcv | M21: =IF($K21="\I:","",C21) -> 19243.432 | N21: =IF($K21="\I:","",D21) -> 17966.601 | O21: =IF($K21="\I:","",E21) -> 17966.601 | P21: =IF($K21="\I:","",F21) -> 17966.601 | S21: DMD | T21: =K21 -> Trd_lcv_gsl_25 | U21: =OFFSET($S$1,MATCH(J21,$S$1:$S$10,0)-1,-1)&" -- "&TEXT(B21,"00%") -> ICE gasoline LCV -- 25% | V21: Bvkm | W21: million vehicles
B22: 0.34556058 | C22: 24327.604 | D22: 19194.381 | E22: 19194.381 | F22: 19194.381 | I22: =(1+B22) -> 1.3455606 | J22: =IFERROR(VLOOKUP(C22,$R$1:$S$10,2,FALSE),J21) -> Trd_lcv_gsl | K22: =IFERROR(IF(VALUE(C22)>2020,J22&"_"&TEXT(B22*100,"00"),"\I:"),"\I:") -> Trd_lcv_gsl_35 | L22: =LEFT(K22,7) -> Trd_lcv | M22: =IF($K22="\I:","",C22) -> 24327.604 | N22: =IF($K22="\I:","",D22) -> 19194.381 | O22: =IF($K22="\I:","",E22) -> 19194.381 | P22: =IF($K22="\I:","",F22) -> 19194.381 | S22: DMD | T22: =K22 -> Trd_lcv_gsl_35 | U22: =OFFSET($S$1,MATCH(J22,$S$1:$S$10,0)-1,-1)&" -- "&TEXT(B22,"00%") -> ICE gasoline LCV -- 35% | V22: Bvkm | W22: million vehicles
B23: 0.39556058 | C23: 32775.022 | D23: 21558.477 | E23: 21558.477 | F23: 21558.477 | I23: =(1+B23) -> 1.3955606 | J23: =IFERROR(VLOOKUP(C23,$R$1:$S$10,2,FALSE),J22) -> Trd_lcv_gsl | K23: =IFERROR(IF(VALUE(C23)>2020,J23&"_"&TEXT(B23*100,"00"),"\I:"),"\I:") -> Trd_lcv_gsl_40 | L23: =LEFT(K23,7) -> Trd_lcv | M23: =IF($K23="\I:","",C23) -> 32775.022 | N23: =IF($K23="\I:","",D23) -> 21558.477 | O23: =IF($K23="\I:","",E23) -> 21558.477 | P23: =IF($K23="\I:","",F23) -> 21558.477 | S23: DMD | T23: =K23 -> Trd_lcv_gsl_40 | U23: =OFFSET($S$1,MATCH(J23,$S$1:$S$10,0)-1,-1)&" -- "&TEXT(B23,"00%") -> ICE gasoline LCV -- 40% | V23: Bvkm | W23: million vehicles
B24: 0.44556058 | C24: 99589.703 | D24: 26988.331 | E24: 26988.331 | F24: 26988.331 | I24: =(1+B24) -> 1.4455606 | J24: =IFERROR(VLOOKUP(C24,$R$1:$S$10,2,FALSE),J23) -> Trd_lcv_gsl | K24: =IFERROR(IF(VALUE(C24)>2020,J24&"_"&TEXT(B24*100,"00"),"\I:"),"\I:") -> Trd_lcv_gsl_45 | L24: =LEFT(K24,7) -> Trd_lcv | M24: =IF($K24="\I:","",C24) -> 99589.703 | N24: =IF($K24="\I:","",D24) -> 26988.331 | O24: =IF($K24="\I:","",E24) -> 26988.331 | P24: =IF($K24="\I:","",F24) -> 26988.331 | S24: DMD | T24: =K24 -> Trd_lcv_gsl_45 | U24: =OFFSET($S$1,MATCH(J24,$S$1:$S$10,0)-1,-1)&" -- "&TEXT(B24,"00%") -> ICE gasoline LCV -- 45% | V24: Bvkm | W24: million vehicles
B25: 0.49556058 | C25: 116875.34 | D25: 78477.079 | E25: 78477.079 | F25: 78477.079 | I25: =(1+B25) -> 1.4955606 | J25: =IFERROR(VLOOKUP(C25,$R$1:$S$10,2,FALSE),J24) -> Trd_lcv_gsl | K25: =IFERROR(IF(VALUE(C25)>2020,J25&"_"&TEXT(B25*100,"00"),"\I:"),"\I:") -> Trd_lcv_gsl_50 | L25: =LEFT(K25,7) -> Trd_lcv | M25: =IF($K25="\I:","",C25) -> 116875.34 | N25: =IF($K25="\I:","",D25) -> 78477.079 | O25: =IF($K25="\I:","",E25) -> 78477.079 | P25: =IF($K25="\I:","",F25) -> 78477.079 | S25: DMD | T25: =K25 -> Trd_lcv_gsl_50 | U25: =OFFSET($S$1,MATCH(J25,$S$1:$S$10,0)-1,-1)&" -- "&TEXT(B25,"00%") -> ICE gasoline LCV -- 50% | V25: Bvkm | W25: million vehicles
J26: =IFERROR(VLOOKUP(C26,$R$1:$S$10,2,FALSE),J25) -> Trd_lcv_gsl | K26: =IFERROR(IF(VALUE(C26)>2020,J26&"_"&TEXT(B26*100,"00"),"\I:"),"\I:") -> \I: | L26: =LEFT(K26,7) -> \I: | M26: =IF($K26="\I:","",C26) | N26: =IF($K26="\I:","",D26) | O26: =IF($K26="\I:","",E26) | P26: =IF($K26="\I:","",F26) | T26: =K26 -> \I: | U26: =OFFSET($S$1,MATCH(J26,$S$1:$S$10,0)-1,-1)&" -- "&TEXT(B26,"00%") -> ICE gasoline LCV -- 00% | V26: Bvkm | W26: million vehicles
J27: =IFERROR(VLOOKUP(C27,$R$1:$S$10,2,FALSE),J26) -> Trd_lcv_gsl | K27: =IFERROR(IF(VALUE(C27)>2020,J27&"_"&TEXT(B27*100,"00"),"\I:"),"\I:") -> \I: | L27: =LEFT(K27,7) -> \I: | M27: =IF($K27="\I:","",C27) | N27: =IF($K27="\I:","",D27) | O27: =IF($K27="\I:","",E27) | P27: =IF($K27="\I:","",F27) | T27: =K27 -> \I: | U27: =OFFSET($S$1,MATCH(J27,$S$1:$S$10,0)-1,-1)&" -- "&TEXT(B27,"00%") -> ICE gasoline LCV -- 00% | V27: Bvkm | W27: million vehicles
J28: =IFERROR(VLOOKUP(C28,$R$1:$S$10,2,FALSE),J27) -> Trd_lcv_gsl | K28: =IFERROR(IF(VALUE(C28)>2020,J28&"_"&TEXT(B28*100,"00"),"\I:"),"\I:") -> \I: | L28: =LEFT(K28,7) -> \I: | M28: =IF($K28="\I:","",C28) | N28: =IF($K28="\I:","",D28) | O28: =IF($K28="\I:","",E28) | P28: =IF($K28="\I:","",F28) | T28: =K28 -> \I: | U28: =OFFSET($S$1,MATCH(J28,$S$1:$S$10,0)-1,-1)&" -- "&TEXT(B28,"00%") -> ICE gasoline LCV -- 00% | V28: Bvkm | W28: million vehicles
J29: =IFERROR(VLOOKUP(C29,$R$1:$S$10,2,FALSE),J28) -> Trd_lcv_gsl | K29: =IFERROR(IF(VALUE(C29)>2020,J29&"_"&TEXT(B29*100,"00"),"\I:"),"\I:") -> \I: | L29: =LEFT(K29,7) -> \I: | M29: =IF($K29="\I:","",C29) | N29: =IF($K29="\I:","",D29) | O29: =IF($K29="\I:","",E29) | P29: =IF($K29="\I:","",F29) | T29: =K29 -> \I: | U29: =OFFSET($S$1,MATCH(J29,$S$1:$S$10,0)-1,-1)&" -- "&TEXT(B29,"00%") -> ICE gasoline LCV -- 00% | V29: Bvkm | W29: million vehicles
B30: Reduction of specific energy consumption relative to 2015 gasoline vehicle (%) | C30: ICE gasoline hybrid LCV | J30: =IFERROR(VLOOKUP(C30,$R$1:$S$10,2,FALSE),J29) -> Trd_lcv_gsl-hyb | K30: =IFERROR(IF(VALUE(C30)>2020,J30&"_"&TEXT(B30*100,"00"),"\I:"),"\I:") -> \I: | L30: =LEFT(K30,7) -> \I: | M30: =IF($K30="\I:","",C30) | N30: =IF($K30="\I:","",D30) | O30: =IF($K30="\I:","",E30) | P30: =IF($K30="\I:","",F30) | T30: =K30 -> \I: | U30: =OFFSET($S$1,MATCH(J30,$S$1:$S$10,0)-1,-1)&" -- "&TEXT(B30,"00%") -> ICE gasoline hybrid LCV -- Reduction of specific energy consumption relative to 2015 gasoline vehicle (%) | V30: Bvkm | W30: million vehicles
J31: =IFERROR(VLOOKUP(C31,$R$1:$S$10,2,FALSE),J30) -> Trd_lcv_gsl-hyb | K31: =IFERROR(IF(VALUE(C31)>2020,J31&"_"&TEXT(B31*100,"00"),"\I:"),"\I:") -> \I: | L31: =LEFT(K31,7) -> \I: | M31: =IF($K31="\I:","",C31) | N31: =IF($K31="\I:","",D31) | O31: =IF($K31="\I:","",E31) | P31: =IF($K31="\I:","",F31) | T31: =K31 -> \I: | U31: =OFFSET($S$1,MATCH(J31,$S$1:$S$10,0)-1,-1)&" -- "&TEXT(B31,"00%") -> ICE gasoline hybrid LCV -- 00% | V31: Bvkm | W31: million vehicles
J32: =IFERROR(VLOOKUP(C32,$R$1:$S$10,2,FALSE),J31) -> Trd_lcv_gsl-hyb | K32: =IFERROR(IF(VALUE(C32)>2020,J32&"_"&TEXT(B32*100,"00"),"\I:"),"\I:") -> \I: | L32: =LEFT(K32,7) -> \I: | M32: =IF($K32="\I:","",C32) | N32: =IF($K32="\I:","",D32) | O32: =IF($K32="\I:","",E32) | P32: =IF($K32="\I:","",F32) | T32: =K32 -> \I: | U32: =OFFSET($S$1,MATCH(J32,$S$1:$S$10,0)-1,-1)&" -- "&TEXT(B32,"00%") -> ICE gasoline hybrid LCV -- 00% | V32: Bvkm | W32: million vehicles
C33: 2020 | D33: 2030 | E33: 2040 | F33: 2050 | J33: =IFERROR(VLOOKUP(C33,$R$1:$S$10,2,FALSE),J32) -> Trd_lcv_gsl-hyb | K33: =IFERROR(IF(VALUE(C33)>2020,J33&"_"&TEXT(B33*100,"00"),"\I:"),"\I:") -> \I: | L33: =LEFT(K33,7) -> \I: | M33: =IF($K33="\I:","",C33) | N33: =IF($K33="\I:","",D33) | O33: =IF($K33="\I:","",E33) | P33: =IF($K33="\I:","",F33) | T33: =K33 -> \I: | U33: =OFFSET($S$1,MATCH(J33,$S$1:$S$10,0)-1,-1)&" -- "&TEXT(B33,"00%") -> ICE gasoline hybrid LCV -- 00% | V33: Bvkm | W33: million vehicles
B34: 0.14185866 | C34: 20504.456 | D34: 19138.749 | E34: 19138.749 | F34: 19138.749 | I34: =(1+B34) -> 1.1418587 | J34: =IFERROR(VLOOKUP(C34,$R$1:$S$10,2,FALSE),J33) -> Trd_lcv_gsl-hyb | K34: =IFERROR(IF(VALUE(C34)>2020,J34&"_"&TEXT(B34*100,"00"),"\I:"),"\I:") -> Trd_lcv_gsl-hyb_14 | L34: =LEFT(K34,7) -> Trd_lcv | M34: =IF($K34="\I:","",C34) -> 20504.456 | N34: =IF($K34="\I:","",D34) -> 19138.749 | O34: =IF($K34="\I:","",E34) -> 19138.749 | P34: =IF($K34="\I:","",F34) -> 19138.749 | T34: =K34 -> Trd_lcv_gsl-hyb_14 | U34: =OFFSET($S$1,MATCH(J34,$S$1:$S$10,0)-1,-1)&" -- "&TEXT(B34,"00%") -> ICE gasoline hybrid LCV -- 14% | V34: Bvkm | W34: million vehicles
B35: 0.24185866 | C35: 20722.243 | D35: 19390.083 | E35: 19390.083 | F35: 19390.083 | I35: =(1+B35) -> 1.2418587 | J35: =IFERROR(VLOOKUP(C35,$R$1:$S$10,2,FALSE),J34) -> Trd_lcv_gsl-hyb | K35: =IFERROR(IF(VALUE(C35)>2020,J35&"_"&TEXT(B35*100,"00"),"\I:"),"\I:") -> Trd_lcv_gsl-hyb_24 | L35: =LEFT(K35,7) -> Trd_lcv | M35: =IF($K35="\I:","",C35) -> 20722.243 | N35: =IF($K35="\I:","",D35) -> 19390.083 | O35: =IF($K35="\I:","",E35) -> 19390.083 | P35: =IF($K35="\I:","",F35) -> 19390.083 | T35: =K35 -> Trd_lcv_gsl-hyb_24 | U35: =OFFSET($S$1,MATCH(J35,$S$1:$S$10,0)-1,-1)&" -- "&TEXT(B35,"00%") -> ICE gasoline hybrid LCV -- 24% | V35: Bvkm | W35: million vehicles
B36: 0.29185866 | C36: 20967.658 | D36: 19601.209 | E36: 19601.209 | F36: 19601.209 | I36: =(1+B36) -> 1.2918587 | J36: =IFERROR(VLOOKUP(C36,$R$1:$S$10,2,FALSE),J35) -> Trd_lcv_gsl-hyb | K36: =IFERROR(IF(VALUE(C36)>2020,J36&"_"&TEXT(B36*100,"00"),"\I:"),"\I:") -> Trd_lcv_gsl-hyb_29 | L36: =LEFT(K36,7) -> Trd_lcv | M36: =IF($K36="\I:","",C36) -> 20967.658 | N36: =IF($K36="\I:","",D36) -> 19601.209 | O36: =IF($K36="\I:","",E36) -> 19601.209 | P36: =IF($K36="\I:","",F36) -> 19601.209 | T36: =K36 -> Trd_lcv_gsl-hyb_29 | U36: =OFFSET($S$1,MATCH(J36,$S$1:$S$10,0)-1,-1)&" -- "&TEXT(B36,"00%") -> ICE gasoline hybrid LCV -- 29% | V36: Bvkm | W36: million vehicles
B37: 0.34185866 | C37: 21437.622 | D37: 19855.904 | E37: 19855.904 | F37: 19855.904 | I37: =(1+B37) -> 1.3418587 | J37: =IFERROR(VLOOKUP(C37,$R$1:$S$10,2,FALSE),J36) -> Trd_lcv_gsl-hyb | K37: =IFERROR(IF(VALUE(C37)>2020,J37&"_"&TEXT(B37*100,"00"),"\I:"),"\I:") -> Trd_lcv_gsl-hyb_34 | L37: =LEFT(K37,7) -> Trd_lcv | M37: =IF($K37="\I:","",C37) -> 21437.622 | N37: =IF($K37="\I:","",D37) -> 19855.904 | O37: =IF($K37="\I:","",E37) -> 19855.904 | P37: =IF($K37="\I:","",F37) -> 19855.904 | T37: =K37 -> Trd_lcv_gsl-hyb_34 | U37: =OFFSET($S$1,MATCH(J37,$S$1:$S$10,0)-1,-1)&" -- "&TEXT(B37,"00%") -> ICE gasoline hybrid LCV -- 34% | V37: Bvkm | W37: million vehicles
B38: 0.39185866 | C38: 22211.009 | D38: 20325.563 | E38: 20325.563 | F38: 20325.563 | I38: =(1+B38) -> 1.3918587 | J38: =IFERROR(VLOOKUP(C38,$R$1:$S$10,2,FALSE),J37) -> Trd_lcv_gsl-hyb | K38: =IFERROR(IF(VALUE(C38)>2020,J38&"_"&TEXT(B38*100,"00"),"\I:"),"\I:") -> Trd_lcv_gsl-hyb_39 | L38: =LEFT(K38,7) -> Trd_lcv | M38: =IF($K38="\I:","",C38) -> 22211.009 | N38: =IF($K38="\I:","",D38) -> 20325.563 | O38: =IF($K38="\I:","",E38) -> 20325.563 | P38: =IF($K38="\I:","",F38) -> 20325.563 | T38: =K38 -> Trd_lcv_gsl-hyb_39 | U38: =OFFSET($S$1,MATCH(J38,$S$1:$S$10,0)-1,-1)&" -- "&TEXT(B38,"00%") -> ICE gasoline hybrid LCV -- 39% | V38: Bvkm | W38: million vehicles
B39: 0.44185866 | C39: 46471.149 | D39: 26131.898 | E39: 26131.898 | F39: 26131.898 | I39: =(1+B39) -> 1.4418587 | J39: =IFERROR(VLOOKUP(C39,$R$1:$S$10,2,FALSE),J38) -> Trd_lcv_gsl-hyb | K39: =IFERROR(IF(VALUE(C39)>2020,J39&"_"&TEXT(B39*100,"00"),"\I:"),"\I:") -> Trd_lcv_gsl-hyb_44 | L39: =LEFT(K39,7) -> Trd_lcv | M39: =IF($K39="\I:","",C39) -> 46471.149 | N39: =IF($K39="\I:","",D39) -> 26131.898 | O39: =IF($K39="\I:","",E39) -> 26131.898 | P39: =IF($K39="\I:","",F39) -> 26131.898 | T39: =K39 -> Trd_lcv_gsl-hyb_44 | U39: =OFFSET($S$1,MATCH(J39,$S$1:$S$10,0)-1,-1)&" -- "&TEXT(B39,"00%") -> ICE gasoline hybrid LCV -- 44% | V39: Bvkm | W39: million vehicles
B40: 0.49185866 | C40: 108265.76 | D40: 77485.562 | E40: 77485.562 | F40: 77485.562 | I40: =(1+B40) -> 1.4918587 | J40: =IFERROR(VLOOKUP(C40,$R$1:$S$10,2,FALSE),J39) -> Trd_lcv_gsl-hyb | K40: =IFERROR(IF(VALUE(C40)>2020,J40&"_"&TEXT(B40*100,"00"),"\I:"),"\I:") -> Trd_lcv_gsl-hyb_49 | L40: =LEFT(K40,7) -> Trd_lcv | M40: =IF($K40="\I:","",C40) -> 108265.76 | N40: =IF($K40="\I:","",D40) -> 77485.562 | O40: =IF($K40="\I:","",E40) -> 77485.562 | P40: =IF($K40="\I:","",F40) -> 77485.562 | T40: =K40 -> Trd_lcv_gsl-hyb_49 | U40: =OFFSET($S$1,MATCH(J40,$S$1:$S$10,0)-1,-1)&" -- "&TEXT(B40,"00%") -> ICE gasoline hybrid LCV -- 49% | V40: Bvkm | W40: million vehicles
J41: =IFERROR(VLOOKUP(C41,$R$1:$S$10,2,FALSE),J40) -> Trd_lcv_gsl-hyb | K41: =IFERROR(IF(VALUE(C41)>2020,J41&"_"&TEXT(B41*100,"00"),"\I:"),"\I:") -> \I: | L41: =LEFT(K41,7) -> \I: | M41: =IF($K41="\I:","",C41) | N41: =IF($K41="\I:","",D41) | O41: =IF($K41="\I:","",E41) | P41: =IF($K41="\I:","",F41) | T41: =K41 -> \I: | U41: =OFFSET($S$1,MATCH(J41,$S$1:$S$10,0)-1,-1)&" -- "&TEXT(B41,"00%") -> ICE gasoline hybrid LCV -- 00% | V41: Bvkm | W41: million vehicles
...

Sheet Hdt
B1: Modelled economic possibilities for reducing specific energy consumption by transport mode/equipment and fuel/technology over time | Q1: dsl | R1: 7.5-16t diesel truck | S1: ="Trd_hdt_"&Q1 -> Trd_hdt_dsl
B2: © E3-Modelling | I2: 0.052009938 | J2: GJ/kg LNG | Q2: dsl-hyb | R2: 7.5-16t diesel hybrid truck | S2: ="Trd_hdt_"&Q2 -> Trd_hdt_dsl-hyb
B3: TRUCKS between 7.5-16 tons Gross Vehicle Weight | I3: =31536000/10^9 -> 0.031536 | J3: GJ/lt Gasoline | Q3: lng | R3: 7.5-16t LNG truck | S3: ="Trd_hdt_"&Q3 -> Trd_hdt_lng
I4: 0.038 | J4: GJ/lt Diesel | Q4: lpg | R4: 7.5-16t LPG truck | S4: ="\I:Trd_hdt_"&Q4 -> \I:Trd_hdt_lpg
B5: Reference values for diesel truck 7.5-16t | I5: =1.406/26.137 -> 0.053793473 | J5: GJ/kg CNG | Q5: elc | R5: 7.5-16t battery electric truck | S5: ="Trd_hdt_"&Q5 -> Trd_hdt_elc
B6: 2015 | I6: 0.02559 | J6: GJ/lt LPG | Q6: hh2 | R6: 7.5-16t Hydrogen fuel cell truck | S6: ="Trd_hdt_"&Q6 -> Trd_hdt_hh2
B7: Energy consumption | C7: lt/100 km | D7: 18.882516 | G7: =D7*$I$4/100*10^9/10^6 -> 7.1753562 | I7: =1/G7 -> 0.1393659
B8: Capital cost | C8: Euro15 /veh | D8: 79045.068 | I8: bvkm/PJ
K10: ~FI_T: UP~EUR15~INVCOST | S10: ~FI_Process
I11: EFF | J11: *process | K11: Process | L11: Comm-OUT | M11: =C15 -> 2020 | N11: =D15 -> 2030 | O11: =E15 -> 2040 | P11: =F15 -> 2050 | Q11: FLO_MARK | S11: Sets | T11: TechName | U11: TechDesc | V11: Tact | W11: Tcap
B12: Reduction of specific energy consumption relative to 2015 diesel vehicle(%) | C12: 7.5-16t diesel truck | J12: =IFERROR(VLOOKUP(C12,$R$1:$S$7,2,FALSE),J10) -> Trd_hdt_dsl | K12: =IFERROR(IF(VALUE(C12)>2020,J12&"_"&TEXT(B12*100,"00"),"\I:"),"\I:") -> \I: | L12: =LEFT(K12,7) -> \I: | M12: =IF($K12="\I:","",C12) | N12: =IF($K12="\I:","",D12) | O12: =IF($K12="\I:","",E12) | P12: =IF($K12="\I:","",F12) | S12: DMD | T12: =K12 -> \I: | U12: =OFFSET($S$1,MATCH(J12,$S$1:$S$11,0)-1,-1)&" -- "&TEXT(B12,"00%") -> 7.5-16t diesel truck -- Reduction of specific energy consumption relative to 2015 diesel vehicle(%) | V12: Bvkm | W12: million vehicles
J13: =IFERROR(VLOOKUP(C13,$R$1:$S$7,2,FALSE),J12) -> Trd_hdt_dsl | K13: =IFERROR(IF(VALUE(C13)>2020,J13&"_"&TEXT(B13*100,"00"),"\I:"),"\I:") -> \I: | L13: =LEFT(K13,7) -> \I: | M13: =IF($K13="\I:","",C13) | N13: =IF($K13="\I:","",D13) | O13: =IF($K13="\I:","",E13) | P13: =IF($K13="\I:","",F13) | S13: DMD | T13: =K13 -> \I: | U13: =OFFSET($S$1,MATCH(J13,$S$1:$S$11,0)-1,-1)&" -- "&TEXT(B13,"00%") -> 7.5-16t diesel truck -- 00% | V13: Bvkm | W13: million vehicles
J14: =IFERROR(VLOOKUP(C14,$R$1:$S$7,2,FALSE),J13) -> Trd_hdt_dsl | K14: =IFERROR(IF(VALUE(C14)>2020,J14&"_"&TEXT(B14*100,"00"),"\I:"),"\I:") -> \I: | L14: =LEFT(K14,7) -> \I: | M14: =IF($K14="\I:","",C14) | N14: =IF($K14="\I:","",D14) | O14: =IF($K14="\I:","",E14) | P14: =IF($K14="\I:","",F14) | S14: DMD | T14: =K14 -> \I: | U14: =OFFSET($S$1,MATCH(J14,$S$1:$S$11,0)-1,-1)&" -- "&TEXT(B14,"00%") -> 7.5-16t diesel truck -- 00% | V14: Bvkm | W14: million vehicles
C15: 2020 | D15: 2030 | E15: 2040 | F15: 2050 | J15: =IFERROR(VLOOKUP(C15,$R$1:$S$7,2,FALSE),J14) -> Trd_hdt_dsl | K15: =IFERROR(IF(VALUE(C15)>2020,J15&"_"&TEXT(B15*100,"00"),"\I:"),"\I:") -> \I: | L15: =LEFT(K15,7) -> \I: | M15: =IF($K15="\I:","",C15) | N15: =IF($K15="\I:","",D15) | O15: =IF($K15="\I:","",E15) | P15: =IF($K15="\I:","",F15) | S15: DMD | T15: =K15 -> \I: | U15: =OFFSET($S$1,MATCH(J15,$S$1:$S$11,0)-1,-1)&" -- "&TEXT(B15,"00%") -> 7.5-16t diesel truck -- 00% | V15: Bvkm | W15: million vehicles
B16: 0.044125814 | C16: 79927.754 | D16: 79927.754 | E16: 79927.754 | F16: 79927.754 | I16: =(1+B16) -> 1.0441258 | J16: =IFERROR(VLOOKUP(C16,$R$1:$S$7,2,FALSE),J15) -> Trd_hdt_dsl | K16: =IFERROR(IF(VALUE(C16)>2020,J16&"_"&TEXT(B16*100,"00"),"\I:"),"\I:") -> Trd_hdt_dsl_04 | L16: =LEFT(K16,7) -> Trd_hdt | M16: =IF($K16="\I:","",C16) -> 79927.754 | N16: =IF($K16="\I:","",D16) -> 79927.754 | O16: =IF($K16="\I:","",E16) -> 79927.754 | P16: =IF($K16="\I:","",F16) -> 79927.754 | S16: DMD | T16: =K16 -> Trd_hdt_dsl_04 | U16: =OFFSET($S$1,MATCH(J16,$S$1:$S$11,0)-1,-1)&" -- "&TEXT(B16,"00%") -> 7.5-16t diesel truck -- 04% | V16: Bvkm | W16: million vehicles
B17: 0.094125814 | C17: 81360.186 | D17: 80873.238 | E17: 80873.238 | F17: 80873.238 | I17: =(1+B17) -> 1.0941258 | J17: =IFERROR(VLOOKUP(C17,$R$1:$S$7,2,FALSE),J16) -> Trd_hdt_dsl | K17: =IFERROR(IF(VALUE(C17)>2020,J17&"_"&TEXT(B17*100,"00"),"\I:"),"\I:") -> Trd_hdt_dsl_09 | L17: =LEFT(K17,7) -> Trd_hdt | M17: =IF($K17="\I:","",C17) -> 81360.186 | N17: =IF($K17="\I:","",D17) -> 80873.238 | O17: =IF($K17="\I:","",E17) -> 80873.238 | P17: =IF($K17="\I:","",F17) -> 80873.238 | S17: DMD | T17: =K17 -> Trd_hdt_dsl_09 | U17: =OFFSET($S$1,MATCH(J17,$S$1:$S$11,0)-1,-1)&" -- "&TEXT(B17,"00%") -> 7.5-16t diesel truck -- 09% | V17: Bvkm | W17: million vehicles
B18: 0.14412581 | C18: 82659.163 | D18: 82265.607 | E18: 82265.607 | F18: 82265.607 | I18: =(1+B18) -> 1.1441258 | J18: =IFERROR(VLOOKUP(C18,$R$1:$S$7,2,FALSE),J17) -> Trd_hdt_dsl | K18: =IFERROR(IF(VALUE(C18)>2020,J18&"_"&TEXT(B18*100,"00"),"\I:"),"\I:") -> Trd_hdt_dsl_14 | L18: =LEFT(K18,7) -> Trd_hdt | M18: =IF($K18="\I:","",C18) -> 82659.163 | N18: =IF($K18="\I:","",D18) -> 82265.607 | O18: =IF($K18="\I:","",E18) -> 82265.607 | P18: =IF($K18="\I:","",F18) -> 82265.607 | S18: DMD | T18: =K18 -> Trd_hdt_dsl_14 | U18: =OFFSET($S$1,MATCH(J18,$S$1:$S$11,0)-1,-1)&" -- "&TEXT(B18,"00%") -> 7.5-16t diesel truck -- 14% | V18: Bvkm | W18: million vehicles
B19: 0.19412581 | C19: 88191.03 | D19: 84316.081 | E19: 84316.081 | F19: 84316.081 | I19: =(1+B19) -> 1.1941258 | J19: =IFERROR(VLOOKUP(C19,$R$1:$S$7,2,FALSE),J18) -> Trd_hdt_dsl | K19: =IFERROR(IF(VALUE(C19)>2020,J19&"_"&TEXT(B19*100,"00"),"\I:"),"\I:") -> Trd_hdt_dsl_19 | L19: =LEFT(K19,7) -> Trd_hdt | M19: =IF($K19="\I:","",C19) -> 88191.03 | N19: =IF($K19="\I:","",D19) -> 84316.081 | O19: =IF($K19="\I:","",E19) -> 84316.081 | P19: =IF($K19="\I:","",F19) -> 84316.081 | S19: DMD | T19: =K19 -> Trd_hdt_dsl_19 | U19: =OFFSET($S$1,MATCH(J19,$S$1:$S$11,0)-1,-1)&" -- "&TEXT(B19,"00%") -> 7.5-16t diesel truck -- 19% | V19: Bvkm | W19: million vehicles
B20: 0.24412581 | C20: 92499.125 | D20: 87335.716 | E20: 87335.716 | F20: 87335.716 | I20: =(1+B20) -> 1.2441258 | J20: =IFERROR(VLOOKUP(C20,$R$1:$S$7,2,FALSE),J19) -> Trd_hdt_dsl | K20: =IFERROR(IF(VALUE(C20)>2020,J20&"_"&TEXT(B20*100,"00"),"\I:"),"\I:") -> Trd_hdt_dsl_24 | L20: =LEFT(K20,7) -> Trd_hdt | M20: =IF($K20="\I:","",C20) -> 92499.125 | N20: =IF($K20="\I:","",D20) -> 87335.716 | O20: =IF($K20="\I:","",E20) -> 87335.716 | P20: =IF($K20="\I:","",F20) -> 87335.716 | S20: DMD | T20: =K20 -> Trd_hdt_dsl_24 | U20: =OFFSET($S$1,MATCH(J20,$S$1:$S$11,0)-1,-1)&" -- "&TEXT(B20,"00%") -> 7.5-16t diesel truck -- 24% | V20: Bvkm | W20: million vehicles
B21: 0.26412581 | C21: 115400.25 | D21: 91896.61 | E21: 91782.585 | F21: 91782.585 | I21: =(1+B21) -> 1.2641258 | J21: =IFERROR(VLOOKUP(C21,$R$1:$S$7,2,FALSE),J20) -> Trd_hdt_dsl | K21: =IFERROR(IF(VALUE(C21)>2020,J21&"_"&TEXT(B21*100,"00"),"\I:"),"\I:") -> Trd_hdt_dsl_26 | L21: =LEFT(K21,7) -> Trd_hdt | M21: =IF($K21="\I:","",C21) -> 115400.25 | N21: =IF($K21="\I:","",D21) -> 91896.61 | O21: =IF($K21="\I:","",E21) -> 91782.585 | P21: =IF($K21="\I:","",F21) -> 91782.585 | S21: DMD | T21: =K21 -> Trd_hdt_dsl_26 | U21: =OFFSET($S$1,MATCH(J21,$S$1:$S$11,0)-1,-1)&" -- "&TEXT(B21,"00%") -> 7.5-16t diesel truck -- 26% | V21: Bvkm | W21: million vehicles
B22: 0.29412581 | C22: 189775.23 | D22: 105837.45 | E22: 98331.275 | F22: 98331.275 | I22: =(1+B22) -> 1.2941258 | J22: =IFERROR(VLOOKUP(C22,$R$1:$S$7,2,FALSE),J21) -> Trd_hdt_dsl | K22: =IFERROR(IF(VALUE(C22)>2020,J22&"_"&TEXT(B22*100,"00"),"\I:"),"\I:") -> Trd_hdt_dsl_29 | L22: =LEFT(K22,7) -> Trd_hdt | M22: =IF($K22="\I:","",C22) -> 189775.23 | N22: =IF($K22="\I:","",D22) -> 105837.45 | O22: =IF($K22="\I:","",E22) -> 98331.275 | P22: =IF($K22="\I:","",F22) -> 98331.275 | S22: DMD | T22: =K22 -> Trd_hdt_dsl_29 | U22: =OFFSET($S$1,MATCH(J22,$S$1:$S$11,0)-1,-1)&" -- "&TEXT(B22,"00%") -> 7.5-16t diesel truck -- 29% | V22: Bvkm | W22: million vehicles
J23: =IFERROR(VLOOKUP(C23,$R$1:$S$7,2,FALSE),J22) -> Trd_hdt_dsl | K23: =IFERROR(IF(VALUE(C23)>2020,J23&"_"&TEXT(B23*100,"00"),"\I:"),"\I:") -> \I: | L23: =LEFT(K23,7) -> \I: | M23: =IF($K23="\I:","",C23) | N23: =IF($K23="\I:","",D23) | O23: =IF($K23="\I:","",E23) | P23: =IF($K23="\I:","",F23) | T23: =K23 -> \I: | U23: =OFFSET($S$1,MATCH(J23,$S$1:$S$11,0)-1,-1)&" -- "&TEXT(B23,"00%") -> 7.5-16t diesel truck -- 00% | V23: Bvkm | W23: million vehicles
J24: =IFERROR(VLOOKUP(C24,$R$1:$S$7,2,FALSE),J23) -> Trd_hdt_dsl | K24: =IFERROR(IF(VALUE(C24)>2020,J24&"_"&TEXT(B24*100,"00"),"\I:"),"\I:") -> \I: | L24: =LEFT(K24,7) -> \I: | M24: =IF($K24="\I:","",C24) | N24: =IF($K24="\I:","",D24) | O24: =IF($K24="\I:","",E24) | P24: =IF($K24="\I:","",F24) | T24: =K24 -> \I: | U24: =OFFSET($S$1,MATCH(J24,$S$1:$S$11,0)-1,-1)&" -- "&TEXT(B24,"00%") -> 7.5-16t diesel truck -- 00% | V24: Bvkm | W24: million vehicles
J25: =IFERROR(VLOOKUP(C25,$R$1:$S$7,2,FALSE),J24) -> Trd_hdt_dsl | K25: =IFERROR(IF(VALUE(C25)>2020,J25&"_"&TEXT(B25*100,"00"),"\I:"),"\I:") -> \I: | L25: =LEFT(K25,7) -> \I: | M25: =IF($K25="\I:","",C25) | N25: =IF($K25="\I:","",D25) | O25: =IF($K25="\I:","",E25) | P25: =IF($K25="\I:","",F25) | T25: =K25 -> \I: | U25: =OFFSET($S$1,MATCH(J25,$S$1:$S$11,0)-1,-1)&" -- "&TEXT(B25,"00%") -> 7.5-16t diesel truck -- 00% | V25: Bvkm | W25: million vehicles
B26: Reduction of specific energy consumption relative to 2015 diesel vehicle(%) | C26: 7.5-16t diesel hybrid truck | J26: =IFERROR(VLOOKUP(C26,$R$1:$S$7,2,FALSE),J25) -> Trd_hdt_dsl-hyb | K26: =IFERROR(IF(VALUE(C26)>2020,J26&"_"&TEXT(B26*100,"00"),"\I:"),"\I:") -> \I: | L26: =LEFT(K26,7) -> \I: | M26: =IF($K26="\I:","",C26) | N26: =IF($K26="\I:","",D26) | O26: =IF($K26="\I:","",E26) | P26: =IF($K26="\I:","",F26) | T26: =K26 -> \I: | U26: =OFFSET($S$1,MATCH(J26,$S$1:$S$11,0)-1,-1)&" -- "&TEXT(B26,"00%") -> 7.5-16t diesel hybrid truck -- Reduction of specific energy consumption relative to 2015 diesel vehicle(%) | V26: Bvkm | W26: million vehicles
J27: =IFERROR(VLOOKUP(C27,$R$1:$S$7,2,FALSE),J26) -> Trd_hdt_dsl-hyb | K27: =IFERROR(IF(VALUE(C27)>2020,J27&"_"&TEXT(B27*100,"00"),"\I:"),"\I:") -> \I: | L27: =LEFT(K27,7) -> \I: | M27: =IF($K27="\I:","",C27) | N27: =IF($K27="\I:","",D27) | O27: =IF($K27="\I:","",E27) | P27: =IF($K27="\I:","",F27) | T27: =K27 -> \I: | U27: =OFFSET($S$1,MATCH(J27,$S$1:$S$11,0)-1,-1)&" -- "&TEXT(B27,"00%") -> 7.5-16t diesel hybrid truck -- 00% | V27: Bvkm | W27: million vehicles
J28: =IFERROR(VLOOKUP(C28,$R$1:$S$7,2,FALSE),J27) -> Trd_hdt_dsl-hyb | K28: =IFERROR(IF(VALUE(C28)>2020,J28&"_"&TEXT(B28*100,"00"),"\I:"),"\I:") -> \I: | L28: =LEFT(K28,7) -> \I: | M28: =IF($K28="\I:","",C28) | N28: =IF($K28="\I:","",D28) | O28: =IF($K28="\I:","",E28) | P28: =IF($K28="\I:","",F28) | T28: =K28 -> \I: | U28: =OFFSET($S$1,MATCH(J28,$S$1:$S$11,0)-1,-1)&" -- "&TEXT(B28,"00%") -> 7.5-16t diesel hybrid truck -- 00% | V28: Bvkm | W28: million vehicles
C29: 2020 | D29: 2030 | E29: 2040 | F29: 2050 | J29: =IFERROR(VLOOKUP(C29,$R$1:$S$7,2,FALSE),J28) -> Trd_hdt_dsl-hyb | K29: =IFERROR(IF(VALUE(C29)>2020,J29&"_"&TEXT(B29*100,"00"),"\I:"),"\I:") -> \I: | L29: =LEFT(K29,7) -> \I: | M29: =IF($K29="\I:","",C29) | N29: =IF($K29="\I:","",D29) | O29: =IF($K29="\I:","",E29) | P29: =IF($K29="\I:","",F29) | T29: =K29 -> \I: | U29: =OFFSET($S$1,MATCH(J29,$S$1:$S$11,0)-1,-1)&" -- "&TEXT(B29,"00%") -> 7.5-16t diesel hybrid truck -- 00% | V29: Bvkm | W29: million vehicles
B30: 0.1 | C30: 88920.665 | D30: 85723.707 | E30: 84520.589 | F30: 83595.636 | I30: =(1+B30) -> 1.1 | J30: =IFERROR(VLOOKUP(C30,$R$1:$S$7,2,FALSE),J29) -> Trd_hdt_dsl-hyb | K30: =IFERROR(IF(VALUE(C30)>2020,J30&"_"&TEXT(B30*100,"00"),"\I:"),"\I:") -> Trd_hdt_dsl-hyb_10 | L30: =LEFT(K30,7) -> Trd_hdt | M30: =IF($K30="\I:","",C30) -> 88920.665 | N30: =IF($K30="\I:","",D30) -> 85723.707 | O30: =IF($K30="\I:","",E30) -> 84520.589 | P30: =IF($K30="\I:","",F30) -> 83595.636 | T30: =K30 -> Trd_hdt_dsl-hyb_10 | U30: =OFFSET($S$1,MATCH(J30,$S$1:$S$11,0)-1,-1)&" -- "&TEXT(B30,"00%") -> 7.5-16t diesel hybrid truck -- 10% | V30: Bvkm | W30: million vehicles
B31: 0.15 | C31: 90395.02 | D31: 85866.889 | E31: 84742.075 | F31: 83858.379 | I31: =(1+B31) -> 1.15 | J31: =IFERROR(VLOOKUP(C31,$R$1:$S$7,2,FALSE),J30) -> Trd_hdt_dsl-hyb | K31: =IFERROR(IF(VALUE(C31)>2020,J31&"_"&TEXT(B31*100,"00"),"\I:"),"\I:") -> Trd_hdt_dsl-hyb_15 | L31: =LEFT(K31,7) -> Trd_hdt | M31: =IF($K31="\I:","",C31) -> 90395.02 | N31: =IF($K31="\I:","",D31) -> 85866.889 | O31: =IF($K31="\I:","",E31) -> 84742.075 | P31: =IF($K31="\I:","",F31) -> 83858.379 | T31: =K31 -> Trd_hdt_dsl-hyb_15 | U31: =OFFSET($S$1,MATCH(J31,$S$1:$S$11,0)-1,-1)&" -- "&TEXT(B31,"00%") -> 7.5-16t diesel hybrid truck -- 15% | V31: Bvkm | W31: million vehicles
B32: 0.2 | C32: 91869.376 | D32: 86041.571 | E32: 84996.503 | F32: 84156.751 | I32: =(1+B32) -> 1.2 | J32: =IFERROR(VLOOKUP(C32,$R$1:$S$7,2,FALSE),J31) -> Trd_hdt_dsl-hyb | K32: =IFERROR(IF(VALUE(C32)>2020,J32&"_"&TEXT(B32*100,"00"),"\I:"),"\I:") -> Trd_hdt_dsl-hyb_20 | L32: =LEFT(K32,7) -> Trd_hdt | M32: =IF($K32="\I:","",C32) -> 91869.376 | N32: =IF($K32="\I:","",D32) -> 86041.571 | O32: =IF($K32="\I:","",E32) -> 84996.503 | P32: =IF($K32="\I:","",F32) -> 84156.751 | T32: =K32 -> Trd_hdt_dsl-hyb_20 | U32: =OFFSET($S$1,MATCH(J32,$S$1:$S$11,0)-1,-1)&" -- "&TEXT(B32,"00%") -> 7.5-16t diesel hybrid truck -- 20% | V32: Bvkm | W32: million vehicles
B33: 0.25 | C33: 93343.731 | D33: 86487.444 | E33: 85493.169 | F33: 84675.056 | I33: =(1+B33) -> 1.25 | J33: =IFERROR(VLOOKUP(C33,$R$1:$S$7,2,FALSE),J32) -> Trd_hdt_dsl-hyb | K33: =IFERROR(IF(VALUE(C33)>2020,J33&"_"&TEXT(B33*100,"00"),"\I:"),"\I:") -> Trd_hdt_dsl-hyb_25 | L33: =LEFT(K33,7) -> Trd_hdt | M33: =IF($K33="\I:","",C33) -> 93343.731 | N33: =IF($K33="\I:","",D33) -> 86487.444 | O33: =IF($K33="\I:","",E33) -> 85493.169 | P33: =IF($K33="\I:","",F33) -> 84675.056 | T33: =K33 -> Trd_hdt_dsl-hyb_25 | U33: =OFFSET($S$1,MATCH(J33,$S$1:$S$11,0)-1,-1)&" -- "&TEXT(B33,"00%") -> 7.5-16t diesel hybrid truck -- 25% | V33: Bvkm | W33: million vehicles
B34: 0.3 | C34: 94818.087 | D34: 87242.497 | E34: 86278.806 | F34: 85465.438 | I34: =(1+B34) -> 1.3 | J34: =IFERROR(VLOOKUP(C34,$R$1:$S$7,2,FALSE),J33) -> Trd_hdt_dsl-hyb | K34: =IFERROR(IF(VALUE(C34)>2020,J34&"_"&TEXT(B34*100,"00"),"\I:"),"\I:") -> Trd_hdt_dsl-hyb_30 | L34: =LEFT(K34,7) -> Trd_hdt | M34: =IF($K34="\I:","",C34) -> 94818.087 | N34: =IF($K34="\I:","",D34) -> 87242.497 | O34: =IF($K34="\I:","",E34) -> 86278.806 | P34: =IF($K34="\I:","",F34) -> 85465.438 | T34: =K34 -> Trd_hdt_dsl-hyb_30 | U34: =OFFSET($S$1,MATCH(J34,$S$1:$S$11,0)-1,-1)&" -- "&TEXT(B34,"00%") -> 7.5-16t diesel hybrid truck -- 30% | V34: Bvkm | W34: million vehicles
B35: 0.35 | C35: 96915.145 | D35: 88296.021 | E35: 87359.295 | F35: 86546.242 | I35: =(1+B35) -> 1.35 | J35: =IFERROR(VLOOKUP(C35,$R$1:$S$7,2,FALSE),J34) -> Trd_hdt_dsl-hyb | K35: =IFERROR(IF(VALUE(C35)>2020,J35&"_"&TEXT(B35*100,"00"),"\I:"),"\I:") -> Trd_hdt_dsl-hyb_35 | L35: =LEFT(K35,7) -> Trd_hdt | M35: =IF($K35="\I:","",C35) -> 96915.145 | N35: =IF($K35="\I:","",D35) -> 88296.021 | O35: =IF($K35="\I:","",E35) -> 87359.295 | P35: =IF($K35="\I:","",F35) -> 86546.242 | T35: =K35 -> Trd_hdt_dsl-hyb_35 | U35: =OFFSET($S$1,MATCH(J35,$S$1:$S$11,0)-1,-1)&" -- "&TEXT(B35,"00%") -> 7.5-16t diesel hybrid truck -- 35% | V35: Bvkm | W35: million vehicles
B36: 0.4 | C36: 98758.177 | D36: 91896.257 | E36: 90807.971 | F36: 89832.554 | I36: =(1+B36) -> 1.4 | J36: =IFERROR(VLOOKUP(C36,$R$1:$S$7,2,FALSE),J35) -> Trd_hdt_dsl-hyb | K36: =IFERROR(IF(VALUE(C36)>2020,J36&"_"&TEXT(B36*100,"00"),"\I:"),"\I:") -> Trd_hdt_dsl-hyb_40 | L36: =LEFT(K36,7) -> Trd_hdt | M36: =IF($K36="\I:","",C36) -> 98758.177 | N36: =IF($K36="\I:","",D36) -> 91896.257 | O36: =IF($K36="\I:","",E36) -> 90807.971 | P36: =IF($K36="\I:","",F36) -> 89832.554 | T36: =K36 -> Trd_hdt_dsl-hyb_40 | U36: =OFFSET($S$1,MATCH(J36,$S$1:$S$11,0)-1,-1)&" -- "&TEXT(B36,"00%") -> 7.5-16t diesel hybrid truck -- 40% | V36: Bvkm | W36: million vehicles
B37: 0.45 | C37: 104720.41 | D37: 97691.662 | E37: 96426.758 | F37: 95247.659 | I37: =(1+B37) -> 1.45 | J37: =IFERROR(VLOOKUP(C37,$R$1:$S$7,2,FALSE),J36) -> Trd_hdt_dsl-hyb | K37: =IFERROR(IF(VALUE(C37)>2020,J37&"_"&TEXT(B37*100,"00"),"\I:"),"\I:") -> Trd_hdt_dsl-hyb_45 | L37: =LEFT(K37,7) -> Trd_hdt | M37: =IF($K37="\I:","",C37) -> 104720.41 | N37: =IF($K37="\I:","",D37) -> 97691.662 | O37: =IF($K37="\I:","",E37) -> 96426.758 | P37: =IF($K37="\I:","",F37) -> 95247.659 | T37: =K37 -> Trd_hdt_dsl-hyb_45 | U37: =OFFSET($S$1,MATCH(J37,$S$1:$S$11,0)-1,-1)&" -- "&TEXT(B37,"00%") -> 7.5-16t diesel hybrid truck -- 45% | V37: Bvkm | W37: million vehicles
J38: =IFERROR(VLOOKUP(C38,$R$1:$S$7,2,FALSE),J37) -> Trd_hdt_dsl-hyb | K38: =IFERROR(IF(VALUE(C38)>2020,J38&"_"&TEXT(B38*100,"00"),"\I:"),"\I:") -> \I: | L38: =LEFT(K38,7) -> \I: | M38: =IF($K38="\I:","",C38) | N38: =IF($K38="\I:","",D38) | O38: =IF($K38="\I:","",E38) | P38: =IF($K38="\I:","",F38) | T38: =K38 -> \I: | U38: =OFFSET($S$1,MATCH(J38,$S$1:$S$11,0)-1,-1)&" -- "&TEXT(B38,"00%") -> 7.5-16t diesel hybrid truck -- 00% | V38: Bvkm | W38: million vehicles
J39: =IFERROR(VLOOKUP(C39,$R$1:$S$7,2,FALSE),J38) -> Trd_hdt_dsl-hyb | K39: =IFERROR(IF(VALUE(C39)>2020,J39&"_"&TEXT(B39*100,"00"),"\I:"),"\I:") -> \I: | L39: =LEFT(K39,7) -> \I: | M39: =IF($K39="\I:","",C39) | N39: =IF($K39="\I:","",D39) | O39: =IF($K39="\I:","",E39) | P39: =IF($K39="\I:","",F39) | T39: =K39 -> \I: | U39: =OFFSET($S$1,MATCH(J39,$S$1:$S$11,0)-1,-1)&" -- "&TEXT(B39,"00%") -> 7.5-16t diesel hybrid truck -- 00% | V39: Bvkm | W39: million vehicles
J40: =IFERROR(VLOOKUP(C40,$R$1:$S$7,2,FALSE),J39) -> Trd_hdt_dsl-hyb | K40: =IFERROR(IF(VALUE(C40)>2020,J40&"_"&TEXT(B40*100,"00"),"\I:"),"\I:") -> \I: | L40: =LEFT(K40,7) -> \I: | M40: =IF($K40="\I:","",C40) | N40: =IF($K40="\I:","",D40) | O40: =IF($K40="\I:","",E40) | P40: =IF($K40="\I:","",F40) | T40: =K40 -> \I: | U40: =OFFSET($S$1,MATCH(J40,$S$1:$S$11,0)-1,-1)&" -- "&TEXT(B40,"00%") -> 7.5-16t diesel hybrid truck -- 00% | V40: Bvkm | W40: million vehicles
J41: =IFERROR(VLOOKUP(C41,$R$1:$S$7,2,FALSE),J40) -> Trd_hdt_dsl-hyb | K41: =IFERROR(IF(VALUE(C41)>2020,J41&"_"&TEXT(B41*100,"00"),"\I:"),"\I:") -> \I: | L41: =LEFT(K41,7) -> \I: | M41: =IF($K41="\I:","",C41) | N41: =IF($K41="\I:","",D41) | O41: =IF($K41="\I:","",E41) | P41: =IF($K41="\I:","",F41) | T41: =K41 -> \I: | U41: =OFFSET($S$1,MATCH(J41,$S$1:$S$11,0)-1,-1)&" -- "&TEXT(B41,"00%") -> 7.5-16t diesel hybrid truck -- 00% | V41: Bvkm | W41: million vehicles
...

Sheet 2-3wheelers
B1: Modelled economic possibilities for reducing specific energy consumption by transport mode/equipment and fuel/technology over time | Q1: gsl150 | R1: 4-stroke MC 50-250 cc motorcycle | S1: ="Trd_2w_"&Q1 -> Trd_2w_gsl150
B2: © E3-Modelling | Q2: gsl500 | R2: 4-stroke MC 250-750 cc motorcycle | S2: ="Trd_2w_"&Q2 -> Trd_2w_gsl500
Q3: gsl | R3: 4-stroke MC >750 cc motorcycle | S3: ="Trd_3w_"&Q3 -> Trd_3w_gsl
I4: =31536000/10^9 -> 0.031536 | J4: GJ/lt Gasoline | Q4: gsl50 | R4: Moped | S4: ="Trd_2w_"&Q4 -> Trd_2w_gsl50
B5: Reference values for 4-stroke MC 50-250 cc motorcycle | Q5: elc150 | R5: Battery electric motorcycle (equivalent to 50-250 cc motorcycle) | S5: ="Trd_2w_"&Q5 -> Trd_2w_elc150
B6: 2015 | Q6: elc500 | R6: Battery electric motorcycle (equivalent to 250-750 cc motorcycle) | S6: ="Trd_2w_"&Q6 -> Trd_2w_elc500
