Workbook
Name FID_1: [1]AGR_Fuels!$A$2
Name GROWTH: '[2]TechRep-Doc'!#REF!
Name DISCRATE: '[2]TechRep-Doc'!#REF!
Name FuelList: #REF!

Sheet TechSelection
A3: ~TFM_AVA
A4: Region | B4: Process
A5: Africa_North | B5: *
A6: Africa_Other | B6: *
A7: Australia | B7: *
A8: Austria | B8: *
A9: Baltics | B9: *
A10: BeNeLux | B10: *
A11: Brazil | B11: *
A12: China | B12: *
A13: CroSloven | B13: *
A14: CzechSlovak | B14: *
A15: France | B15: *
... A39: WestBalkans | B39: *

Sheet InvCost_for_packManufacturing
B1: *The original pack CAPEX price is 10million USD/GWh is too rough, and we also wanna project cost trends over time, so we sourced from NREL's ATB report | R1: *Downloaded from ATB 2024: output file, only representative vehicle battery type is presented below | S1: year | T1: scenario | U1: vehicle_weight_category | V1: vehicle_class | W1: vehicle_powertrain | X1: vehicle_detail | Y1: fuel_category | Z1: fuel2_category | AA1: metric | AB1: value | AC1: reference | AH1: 2023 | AI1: 2025 | AJ1: 2030 | AK1: 2035 | AL1: 2040 | AM1: 2045 | AN1: 2050 | AW1: ~TFM_INS: attribute=INVCOST | BD1: ~TFM_INS: attribute=ACT_COST | BO1: ~TFM_INS: attribute=INVCOST
B2: Battery Electric Vehicle Assumptions | Transportation | 2024 | ATB | NLR | S2: 2023 | T2: Mid | U2: Light Duty | V2: Compact | W2: Battery Electric | X2: Battery Electric Vehicle (300-mile range) | Y2: Electricity | AA2: Battery Cost (2022$/kWh) (pack-level, rated capacity) | AB2: 132.92732 | AC2: ANL, Autonomie (2023) | AG2: Whole pack CAPEX in NREL | AH2: 132.92732 | AI2: 120.58407 | AJ2: 104.4429 | AK2: 94.948087 | AL2: 92.108475 | AM2: 88.961165 | AN2: 85.453278
F3: Sourced from before calculations | S3: 2025 | T3: Mid | U3: Light Duty | V3: Compact | W3: Battery Electric | X3: Battery Electric Vehicle (300-mile range) | Y3: Electricity | AA3: Battery Cost (2022$/kWh) (pack-level, rated capacity) | AB3: 120.58407 | AC3: ANL, Autonomie (2023) | AH3: =AH2 -> 132.92732 | AI3: =AI2 -> 120.58407 | AJ3: =AJ2 -> 104.4429 | AK3: =AK2 -> 94.948087 | AL3: =AL2 -> 92.108475 | AM3: =AM2 -> 88.961165 | AN3: =AN2 -> 85.453278 | AS3: AllRegions | AT3: China | AU3: NorthAm | AW3: process | AX3: year | AY3: AllRegions | AZ3: China | BA3: NorthAm | BD3: process | BE3: year | BF3: AllRegions | BG3: China | BH3: NorthAm | BO3: process | BP3: year | BQ3: AllRegions | BR3: China | BS3: NorthAm
F4: process | G4: AllRegions | H4: China | I4: NorthAm | S4: 2030 | T4: Mid | U4: Light Duty | V4: Compact | W4: Battery Electric | X4: Battery Electric Vehicle (300-mile range) | Y4: Electricity | AA4: Battery Cost (2022$/kWh) (pack-level, rated capacity) | AB4: 104.4429 | AC4: ANL, Autonomie (2023) | AH4: =AH3 -> 132.92732 | AI4: =AI3 -> 120.58407 | AJ4: =AJ3 -> 104.4429 | AK4: =AK3 -> 94.948087 | AL4: =AL3 -> 92.108475 | AM4: =AM3 -> 88.961165 | AN4: =AN3 -> 85.453278 | AS4: 80.383177 | AT4: 55.48673 | AU4: 106.82505 | AW4: Tra_EV_Batt-LFP_fromrecy | AX4: 2023 | AY4: =G5 -> 80.383177 | AZ4: =H5 -> 55.48673 | BA4: =I5 -> 106.82505 | BD4: Tra_EV_Batt-LFP_virgin | BE4: 2023 | BF4: =AS4*70% -> 56.268224 | BG4: =AT4*70% -> 38.840711 | BH4: =AU4*70% -> 74.777535 | BO4: Tra_EV_Batt-LFP_virgin_pack | BP4: 2023 | BQ4: =AS4*30% -> 24.114953 | BR4: =AT4*30% -> 16.646019 | BS4: =AU4*30% -> 32.047515
B5: *However, (1) as suggested by Sally Benson's Nature energy in 2025, the learning-by-doing reduction only applied to other cost components (conversion cost) = whole pack CAPEX-material costs (2) Argonne lab / EverBatt model/ Anna's provided data has its own CAPEX , we have already made the deduction in the SubRES_Transport table (avoiding Double-counting learning) (3) energy economic cost only accounts for negligible proportion of CAPEX, so to make the paper cleaner we do not need to deduct this part (4) but Argonne database do not have future cost projections | F5: Tra_EV_Batt-LFP | G5: =[3]R_strategies_n_GridBattery!$D$131 -> 80.383177 | H5: =[3]R_strategies_n_GridBattery!$E$131 -> 55.48673 | I5: =[3]R_strategies_n_GridBattery!$F$131 -> 106.82505 | S5: 2035 | T5: Mid | U5: Light Duty | V5: Compact | W5: Battery Electric | X5: Battery Electric Vehicle (300-mile range) | Y5: Electricity | AA5: Battery Cost (2022$/kWh) (pack-level, rated capacity) | AB5: 94.948087 | AC5: ANL, Autonomie (2023) | AH5: =AH4 -> 132.92732 | AI5: =AI4 -> 120.58407 | AJ5: =AJ4 -> 104.4429 | AK5: =AK4 -> 94.948087 | AL5: =AL4 -> 92.108475 | AM5: =AM4 -> 88.961165 | AN5: =AN4 -> 85.453278 | AS5: 95.4086 | AT5: 66.32565 | AU5: 126.26355 | AW5: Tra_EV_Batt-LMO_fromrecy | AX5: =AX4 -> 2023 | AY5: =G6 -> 95.4086 | AZ5: =H6 -> 66.32565 | BA5: =I6 -> 126.26355 | BD5: Tra_EV_Batt-LMO_virgin | BE5: 2023 | BF5: =AS5*70% -> 66.78602 | BG5: =AT5*70% -> 46.427955 | BH5: =AU5*70% -> 88.384485 | BO5: Tra_EV_Batt-LMO_virgin_pack | BP5: 2023 | BQ5: =AS5*30% -> 28.62258 | BR5: =AT5*30% -> 19.897695 | BS5: =AU5*30% -> 37.879065
F6: Tra_EV_Batt-LMO | G6: =[3]R_strategies_n_GridBattery!$D$132 -> 95.4086 | H6: =[3]R_strategies_n_GridBattery!$E$132 -> 66.32565 | I6: =[3]R_strategies_n_GridBattery!$F$132 -> 126.26355 | S6: 2040 | T6: Mid | U6: Light Duty | V6: Compact | W6: Battery Electric | X6: Battery Electric Vehicle (300-mile range) | Y6: Electricity | AA6: Battery Cost (2022$/kWh) (pack-level, rated capacity) | AB6: 92.108475 | AC6: ANL, Autonomie (2023) | AH6: =AH5 -> 132.92732 | AI6: =AI5 -> 120.58407 | AJ6: =AJ5 -> 104.4429 | AK6: =AK5 -> 94.948087 | AL6: =AL5 -> 92.108475 | AM6: =AM5 -> 88.961165 | AN6: =AN5 -> 85.453278 | AS6: 85.347697 | AT6: 56.10147 | AU6: 116.32796 | AW6: Tra_EV_Batt-NCA_fromrecy | AX6: =AX5 -> 2023 | AY6: =G7 -> 85.347697 | AZ6: =H7 -> 56.10147 | BA6: =I7 -> 116.32796 | BD6: Tra_EV_Batt-NCA_virgin | BE6: 2023 | BF6: =AS6*70% -> 59.743388 | BG6: =AT6*70% -> 39.271029 | BH6: =AU6*70% -> 81.429572 | BO6: Tra_EV_Batt-NCA_virgin_pack | BP6: 2023 | BQ6: =AS6*30% -> 25.604309 | BR6: =AT6*30% -> 16.830441 | BS6: =AU6*30% -> 34.898388
F7: Tra_EV_Batt-NCA | G7: =[3]R_strategies_n_GridBattery!$D$133 -> 85.347697 | H7: =[3]R_strategies_n_GridBattery!$E$133 -> 56.10147 | I7: =[3]R_strategies_n_GridBattery!$F$133 -> 116.32796 | S7: 2045 | T7: Mid | U7: Light Duty | V7: Compact | W7: Battery Electric | X7: Battery Electric Vehicle (300-mile range) | Y7: Electricity | AA7: Battery Cost (2022$/kWh) (pack-level, rated capacity) | AB7: 88.961165 | AC7: ANL, Autonomie (2023) | AH7: =AH6 -> 132.92732 | AI7: =AI6 -> 120.58407 | AJ7: =AJ6 -> 104.4429 | AK7: =AK6 -> 94.948087 | AL7: =AL6 -> 92.108475 | AM7: =AM6 -> 88.961165 | AN7: =AN6 -> 85.453278 | AS7: 85.52157 | AT7: 55.55951 | AU7: 117.30431 | AW7: Tra_EV_Batt-NMC111_fromrecy | AX7: =AX6 -> 2023 | AY7: =G8 -> 85.52157 | AZ7: =H8 -> 55.55951 | BA7: =I8 -> 117.30431 | BD7: Tra_EV_Batt-NMC111_virgin | BE7: 2023 | BF7: =AS7*70% -> 59.865099 | BG7: =AT7*70% -> 38.891657 | BH7: =AU7*70% -> 82.113017 | BO7: Tra_EV_Batt-NMC111_virgin_pack | BP7: 2023 | BQ7: =AS7*30% -> 25.656471 | BR7: =AT7*30% -> 16.667853 | BS7: =AU7*30% -> 35.191293
B8: So we use Argonne baseline cost → deduct material cost → get conversion CAPEX → apply NREL learning rate to conversion component.----no it seems that NorthAmerica too high so we included the regional learning rate differences in | F8: Tra_EV_Batt-NMC111 | G8: =[3]R_strategies_n_GridBattery!$D$134 -> 85.52157 | H8: =[3]R_strategies_n_GridBattery!$E$134 -> 55.55951 | I8: =[3]R_strategies_n_GridBattery!$F$134 -> 117.30431 | S8: 2050 | T8: Mid | U8: Light Duty | V8: Compact | W8: Battery Electric | X8: Battery Electric Vehicle (300-mile range) | Y8: Electricity | AA8: Battery Cost (2022$/kWh) (pack-level, rated capacity) | AB8: 85.453278 | AC8: ANL, Autonomie (2023) | AH8: =AH7 -> 132.92732 | AI8: =AI7 -> 120.58407 | AJ8: =AJ7 -> 104.4429 | AK8: =AK7 -> 94.948087 | AL8: =AL7 -> 92.108475 | AM8: =AM7 -> 88.961165 | AN8: =AN7 -> 85.453278 | AS8: 90.092917 | AT8: 59.3677 | AU8: 122.66905 | AW8: Tra_EV_Batt-NMC532_fromrecy | AX8: =AX7 -> 2023 | AY8: =G9 -> 90.092917 | AZ8: =H9 -> 59.3677 | BA8: =I9 -> 122.66905 | BD8: Tra_EV_Batt-NMC532_virgin | BE8: 2023 | BF8: =AS8*70% -> 63.065042 | BG8: =AT8*70% -> 41.55739 | BH8: =AU8*70% -> 85.868335 | BO8: Tra_EV_Batt-NMC532_virgin_pack | BP8: 2023 | BQ8: =AS8*30% -> 27.027875 | BR8: =AT8*30% -> 17.81031 | BS8: =AU8*30% -> 36.800715
F9: Tra_EV_Batt-NMC532 | G9: =[3]R_strategies_n_GridBattery!$D$135 -> 90.092917 | H9: =[3]R_strategies_n_GridBattery!$E$135 -> 59.3677 | I9: =[3]R_strategies_n_GridBattery!$F$135 -> 122.66905 | AH9: =AH8 -> 132.92732 | AI9: =AI8 -> 120.58407 | AJ9: =AJ8 -> 104.4429 | AK9: =AK8 -> 94.948087 | AL9: =AL8 -> 92.108475 | AM9: =AM8 -> 88.961165 | AN9: =AN8 -> 85.453278 | AS9: 86.922217 | AT9: 57.33755 | AU9: 118.2723 | AW9: Tra_EV_Batt-NMC622_fromrecy | AX9: =AX8 -> 2023 | AY9: =G10 -> 86.922217 | AZ9: =H10 -> 57.33755 | BA9: =I10 -> 118.2723 | BD9: Tra_EV_Batt-NMC622_virgin | BE9: 2023 | BF9: =AS9*70% -> 60.845552 | BG9: =AT9*70% -> 40.136285 | BH9: =AU9*70% -> 82.79061 | BO9: Tra_EV_Batt-NMC622_virgin_pack | BP9: 2023 | BQ9: =AS9*30% -> 26.076665 | BR9: =AT9*30% -> 17.201265 | BS9: =AU9*30% -> 35.48169
F10: Tra_EV_Batt-NMC622 | G10: =[3]R_strategies_n_GridBattery!$D$136 -> 86.922217 | H10: =[3]R_strategies_n_GridBattery!$E$136 -> 57.33755 | I10: =[3]R_strategies_n_GridBattery!$F$136 -> 118.2723 | AH10: =AH9 -> 132.92732 | AI10: =AI9 -> 120.58407 | AJ10: =AJ9 -> 104.4429 | AK10: =AK9 -> 94.948087 | AL10: =AL9 -> 92.108475 | AM10: =AM9 -> 88.961165 | AN10: =AN9 -> 85.453278 | AS10: 89.552667 | AT10: 59.98948 | AU10: 120.87452 | AW10: Tra_EV_Batt-NMC811_fromrecy | AX10: =AX9 -> 2023 | AY10: =G11 -> 89.552667 | AZ10: =H11 -> 59.98948 | BA10: =I11 -> 120.87452 | BD10: Tra_EV_Batt-NMC811_virgin | BE10: 2023 | BF10: =AS10*70% -> 62.686867 | BG10: =AT10*70% -> 41.992636 | BH10: =AU10*70% -> 84.612164 | BO10: Tra_EV_Batt-NMC811_virgin_pack | BP10: 2023 | BQ10: =AS10*30% -> 26.8658 | BR10: =AT10*30% -> 17.996844 | BS10: =AU10*30% -> 36.262356
F11: Tra_EV_Batt-NMC811 | G11: =[3]R_strategies_n_GridBattery!$D$137 -> 89.552667 | H11: =[3]R_strategies_n_GridBattery!$E$137 -> 59.98948 | I11: =[3]R_strategies_n_GridBattery!$F$137 -> 120.87452 | AH11: =AH10 -> 132.92732 | AI11: =AI10 -> 120.58407 | AJ11: =AJ10 -> 104.4429 | AK11: =AK10 -> 94.948087 | AL11: =AL10 -> 92.108475 | AM11: =AM10 -> 88.961165 | AN11: =AN10 -> 85.453278 | AS11: 162.09333 | AT11: 162.09333 | AU11: 162.09333 | BD11: Tra_EV_Batt-Sodium_virgin | BE11: 2023 | BF11: =AS11*70% -> 113.46533 | BG11: =AT11*70% -> 113.46533 | BH11: =AU11*70% -> 113.46533 | BO11: Tra_EV_Batt-Sodium_virgin_pack | BP11: 2023 | BQ11: =AS11*30% -> 48.628 | BR11: =AT11*30% -> 48.628 | BS11: =AU11*30% -> 48.628
AH12: =AH11 -> 132.92732 | AI12: =AI11 -> 120.58407 | AJ12: =AJ11 -> 104.4429 | AK12: =AK11 -> 94.948087 | AL12: =AL11 -> 92.108475 | AM12: =AM11 -> 88.961165 | AN12: =AN11 -> 85.453278
AL14: =AL2/AK2 -> 0.970093 | AM14: =AM2/AL2 -> 0.96583039 | AN14: =AN2/AM2 -> 0.96056834
AS16: AllRegions | AT16: China | AU16: NorthAm | AW16: process | AX16: year | AY16: AllRegions | AZ16: China | BA16: NorthAm | BD16: process | BE16: year | BF16: AllRegions | BG16: China | BH16: NorthAm | BO16: process | BP16: year | BQ16: AllRegions | BR16: China | BS16: NorthAm
AS17: 72.919025 | AT17: 50.334391 | AU17: 96.905581 | AW17: Tra_EV_Batt-LFP_fromrecy | AX17: 2025 | AY17: =AY4*AI2/AH2 -> 72.919025 | AZ17: =AZ4*AI2/AH2 -> 50.334391 | BA17: =BA4*AI2/AH2 -> 96.905581 | BD17: Tra_EV_Batt-LFP_virgin | BE17: 2025 | BF17: =AS17*70% -> 51.043317 | BG17: =AT17*70% -> 35.234074 | BH17: =AU17*70% -> 67.833907 | BO17: Tra_EV_Batt-LFP_virgin_pack | BP17: 2025 | BQ17: =AS17*30% -> 21.875707 | BR17: =AT17*30% -> 15.100317 | BS17: =AU17*30% -> 29.071674
AS18: 86.54923 | AT18: 60.16684 | AU18: 114.53908 | AW18: Tra_EV_Batt-LMO_fromrecy | AX18: =AX17 -> 2025 | AY18: =AY5*AI3/AH3 -> 86.54923 | AZ18: =AZ5*AI3/AH3 -> 60.16684 | BA18: =BA5*AI3/AH3 -> 114.53908 | BD18: Tra_EV_Batt-LMO_virgin | BE18: 2025 | BF18: =AS18*70% -> 60.584461 | BG18: =AT18*70% -> 42.116788 | BH18: =AU18*70% -> 80.177354 | BO18: Tra_EV_Batt-LMO_virgin_pack | BP18: 2025 | BQ18: =AS18*30% -> 25.964769 | BR18: =AT18*30% -> 18.050052 | BS18: =AU18*30% -> 34.361723
AS19: 77.422553 | AT19: 50.892048 | AU19: 105.52608 | AW19: Tra_EV_Batt-NCA_fromrecy | AX19: =AX18 -> 2025 | AY19: =AY6*AI4/AH4 -> 77.422553 | AZ19: =AZ6*AI4/AH4 -> 50.892048 | BA19: =BA6*AI4/AH4 -> 105.52608 | BD19: Tra_EV_Batt-NCA_virgin | BE19: 2025 | BF19: =AS19*70% -> 54.195787 | BG19: =AT19*70% -> 35.624433 | BH19: =AU19*70% -> 73.868255 | BO19: Tra_EV_Batt-NCA_virgin_pack | BP19: 2025 | BQ19: =AS19*30% -> 23.226766 | BR19: =AT19*30% -> 15.267614 | BS19: =AU19*30% -> 31.657823
AS20: 77.580281 | AT20: 50.400413 | AU20: 106.41177 | AW20: Tra_EV_Batt-NMC111_fromrecy | AX20: =AX19 -> 2025 | AY20: =AY7*AI5/AH5 -> 77.580281 | AZ20: =AZ7*AI5/AH5 -> 50.400413 | BA20: =BA7*AI5/AH5 -> 106.41177 | BD20: Tra_EV_Batt-NMC111_virgin | BE20: 2025 | BF20: =AS20*70% -> 54.306197 | BG20: =AT20*70% -> 35.280289 | BH20: =AU20*70% -> 74.488237 | BO20: Tra_EV_Batt-NMC111_virgin_pack | BP20: 2025 | BQ20: =AS20*30% -> 23.274084 | BR20: =AT20*30% -> 15.120124 | BS20: =AU20*30% -> 31.92353
AS21: 81.727146 | AT21: 53.854985 | AU21: 111.27835 | AW21: Tra_EV_Batt-NMC532_fromrecy | AX21: =AX20 -> 2025 | AY21: =AY8*AI6/AH6 -> 81.727146 | AZ21: =AZ8*AI6/AH6 -> 53.854985 | BA21: =BA8*AI6/AH6 -> 111.27835 | BD21: Tra_EV_Batt-NMC532_virgin | BE21: 2025 | BF21: =AS21*70% -> 57.209002 | BG21: =AT21*70% -> 37.698489 | BH21: =AU21*70% -> 77.894847 | BO21: Tra_EV_Batt-NMC532_virgin_pack | BP21: 2025 | BQ21: =AS21*30% -> 24.518144 | BR21: =AT21*30% -> 16.156495 | BS21: =AU21*30% -> 33.383506
AS22: 78.850868 | AT22: 52.013349 | AU22: 107.28987 | AW22: Tra_EV_Batt-NMC622_fromrecy | AX22: =AX21 -> 2025 | AY22: =AY9*AI7/AH7 -> 78.850868 | AZ22: =AZ9*AI7/AH7 -> 52.013349 | BA22: =BA9*AI7/AH7 -> 107.28987 | BD22: Tra_EV_Batt-NMC622_virgin | BE22: 2025 | BF22: =AS22*70% -> 55.195608 | BG22: =AT22*70% -> 36.409344 | BH22: =AU22*70% -> 75.10291 | BO22: Tra_EV_Batt-NMC622_virgin_pack | BP22: 2025 | BQ22: =AS22*30% -> 23.65526 | BR22: =AT22*30% -> 15.604005 | BS22: =AU22*30% -> 32.186962
AS23: 81.237062 | AT23: 54.419028 | AU23: 109.65046 | AW23: Tra_EV_Batt-NMC811_fromrecy | AX23: =AX22 -> 2025 | AY23: =AY10*AI8/AH8 -> 81.237062 | AZ23: =AZ10*AI8/AH8 -> 54.419028 | BA23: =BA10*AI8/AH8 -> 109.65046 | BD23: Tra_EV_Batt-NMC811_virgin | BE23: 2025 | BF23: =AS23*70% -> 56.865943 | BG23: =AT23*70% -> 38.09332 | BH23: =AU23*70% -> 76.75532 | BO23: Tra_EV_Batt-NMC811_virgin_pack | BP23: 2025 | BQ23: =AS23*30% -> 24.371119 | BR23: =AT23*30% -> 16.325708 | BS23: =AU23*30% -> 32.895137
AS24: 147.04181 | AT24: 147.04181 | AU24: 147.04181 | BD24: Tra_EV_Batt-Sodium_virgin | BE24: 2025 | BF24: =AS24*70% -> 102.92927 | BG24: =AT24*70% -> 102.92927 | BH24: =AU24*70% -> 102.92927 | BO24: Tra_EV_Batt-Sodium_virgin_pack | BP24: 2025 | BQ24: =AS24*30% -> 44.112543 | BR24: =AT24*30% -> 44.112543 | BS24: =AU24*30% -> 44.112543
F27: Total CAPEX for batteries before deducting material flow costs (USD/kWh)
G28: AllRegions | H28: China | I28: NorthAm
F29: Tra_EV_Batt-LFP | G29: 99.076927 | H29: 74.18048 | I29: 125.5188
F30: Tra_EV_Batt-LMO | G30: 115.8002 | H30: 86.71725 | I30: 146.65515
F31: Tra_EV_Batt-NCA | G31: 116.6095 | H31: 87.36327 | I31: 147.58976 | AS31: AllRegions | AT31: China | AU31: NorthAm | AW31: process | AX31: year | AY31: AllRegions | AZ31: China | BA31: NorthAm | BD31: process | BE31: year | BF31: AllRegions | BG31: China | BH31: NorthAm | BO31: process | BP31: year | BQ31: AllRegions | BR31: China | BS31: NorthAm
B32: Cell cost for Na-ion (USD24/kWh) | C32: Pack cost for Na-ion | F32: Tra_EV_Batt-NMC111 | G32: 119.49202 | H32: 89.52996 | I32: 151.27476 | AS32: 63.15821 | AT32: 43.596716 | AU32: 83.933968 | AW32: Tra_EV_Batt-LFP_fromrecy | AX32: 2030 | AY32: =AY17*AJ2/AI2 -> 63.15821 | AZ32: =AZ17*AJ2/AI2 -> 43.596716 | BA32: =BA17*AJ2/AI2 -> 83.933968 | BD32: Tra_EV_Batt-LFP_virgin | BE32: 2030 | BF32: =AS32*70% -> 44.210747 | BG32: =AT32*70% -> 30.517702 | BH32: =AU32*70% -> 58.753777 | BO32: Tra_EV_Batt-LFP_virgin_pack | BP32: 2030 | BQ32: =AS32*30% -> 18.947463 | BR32: =AT32*30% -> 13.079015 | BS32: =AU32*30% -> 25.18019
B33: 121.57 | C33: =B33/0.75 -> 162.09333 | F33: Tra_EV_Batt-NMC532 | G33: 122.49172 | H33: 91.7665 | I33: 155.06785 | AS33: 74.9639 | AT33: 52.113011 | AU33: 99.207075 | AW33: Tra_EV_Batt-LMO_fromrecy | AX33: =AX32 -> 2030 | AY33: =AY18*AJ3/AI3 -> 74.9639 | AZ33: =AZ18*AJ3/AI3 -> 52.113011 | BA33: =BA18*AJ3/AI3 -> 99.207075 | BD33: Tra_EV_Batt-LMO_virgin | BE33: 2030 | BF33: =AS33*70% -> 52.47473 | BG33: =AT33*70% -> 36.479107 | BH33: =AU33*70% -> 69.444952 | BO33: Tra_EV_Batt-LMO_virgin_pack | BP33: 2030 | BQ33: =AS33*30% -> 22.48917 | BR33: =AT33*30% -> 15.633903 | BS33: =AU33*30% -> 29.762123
F34: Tra_EV_Batt-NMC622 | G34: 117.94842 | H34: 88.36375 | I34: 149.2985 | AS34: 67.058905 | AT34: 44.079726 | AU34: 91.40054 | AW34: Tra_EV_Batt-NCA_fromrecy | AX34: =AX33 -> 2030 | AY34: =AY19*AJ4/AI4 -> 67.058905 | AZ34: =AZ19*AJ4/AI4 -> 44.079726 | BA34: =BA19*AJ4/AI4 -> 91.40054 | BD34: Tra_EV_Batt-NCA_virgin | BE34: 2030 | BF34: =AS34*70% -> 46.941233 | BG34: =AT34*70% -> 30.855808 | BH34: =AU34*70% -> 63.980378 | BO34: Tra_EV_Batt-NCA_virgin_pack | BP34: 2030 | BQ34: =AS34*30% -> 20.117671 | BR34: =AT34*30% -> 13.223918 | BS34: =AU34*30% -> 27.420162
F35: Tra_EV_Batt-NMC811 | G35: 117.83067 | H35: 88.26748 | I35: 149.15252 | AS35: 67.195519 | AT35: 43.653901 | AU35: 92.167672 | AW35: Tra_EV_Batt-NMC111_fromrecy | AX35: =AX34 -> 2030 | AY35: =AY20*AJ5/AI5 -> 67.195519 | AZ35: =AZ20*AJ5/AI5 -> 43.653901 | BA35: =BA20*AJ5/AI5 -> 92.167672 | BD35: Tra_EV_Batt-NMC111_virgin | BE35: 2030 | BF35: =AS35*70% -> 47.036863 | BG35: =AT35*70% -> 30.557731 | BH35: =AU35*70% -> 64.51737 | BO35: Tra_EV_Batt-NMC111_virgin_pack | BP35: 2030 | BQ35: =AS35*30% -> 20.158656 | BR35: =AT35*30% -> 13.09617 | BS35: =AU35*30% -> 27.650302
AS36: 70.787292 | AT36: 46.64605 | AU36: 96.382825 | AW36: Tra_EV_Batt-NMC532_fromrecy | AX36: =AX35 -> 2030 | AY36: =AY21*AJ6/AI6 -> 70.787292 | AZ36: =AZ21*AJ6/AI6 -> 46.64605 | BA36: =BA21*AJ6/AI6 -> 96.382825 | BD36: Tra_EV_Batt-NMC532_virgin | BE36: 2030 | BF36: =AS36*70% -> 49.551104 | BG36: =AT36*70% -> 32.652235 | BH36: =AU36*70% -> 67.467977 | BO36: Tra_EV_Batt-NMC532_virgin_pack | BP36: 2030 | BQ36: =AS36*30% -> 21.236187 | BR36: =AT36*30% -> 13.993815 | BS36: =AU36*30% -> 28.914848
AS37: 68.296027 | AT37: 45.050932 | AU37: 92.928236 | AW37: Tra_EV_Batt-NMC622_fromrecy | AX37: =AX36 -> 2030 | AY37: =AY22*AJ7/AI7 -> 68.296027 | AZ37: =AZ22*AJ7/AI7 -> 45.050932 | BA37: =BA22*AJ7/AI7 -> 92.928236 | BD37: Tra_EV_Batt-NMC622_virgin | BE37: 2030 | BF37: =AS37*70% -> 47.807219 | BG37: =AT37*70% -> 31.535653 | BH37: =AU37*70% -> 65.049765 | BO37: Tra_EV_Batt-NMC622_virgin_pack | BP37: 2030 | BQ37: =AS37*30% -> 20.488808 | BR37: =AT37*30% -> 13.51528 | BS37: =AU37*30% -> 27.878471
AS38: 70.36281 | AT38: 47.134591 | AU38: 94.972837 | AW38: Tra_EV_Batt-NMC811_fromrecy | AX38: =AX37 -> 2030 | AY38: =AY23*AJ8/AI8 -> 70.36281 | AZ38: =AZ23*AJ8/AI8 -> 47.134591 | BA38: =BA23*AJ8/AI8 -> 94.972837 | BD38: Tra_EV_Batt-NMC811_virgin | BE38: 2030 | BF38: =AS38*70% -> 49.253967 | BG38: =AT38*70% -> 32.994214 | BH38: =AU38*70% -> 66.480986 | BO38: Tra_EV_Batt-NMC811_virgin_pack | BP38: 2030 | BQ38: =AS38*30% -> 21.108843 | BR38: =AT38*30% -> 14.140377 | BS38: =AU38*30% -> 28.491851
AS39: 127.35905 | AT39: 127.35905 | AU39: 127.35905 | BD39: Tra_EV_Batt-Sodium_virgin | BE39: 2030 | BF39: =AS39*70% -> 89.151333 | BG39: =AT39*70% -> 89.151333 | BH39: =AU39*70% -> 89.151333 | BO39: Tra_EV_Batt-Sodium_virgin_pack | BP39: 2030 | BQ39: =AS39*30% -> 38.207714 | BR39: =AT39*30% -> 38.207714 | BS39: =AU39*30% -> 38.207714
AG41: ~TFM_INS: attribute=INVCOST
AG45: process | AH45: year | AI45: AllRegions | AJ45: China | AK45: NorthAm | AS45: AllRegions | AT45: China | AU45: NorthAm | AW45: process | AX45: year | AY45: AllRegions | AZ45: China | BA45: NorthAm | BD45: process | BE45: year | BF45: AllRegions | BG45: China | BH45: NorthAm | BO45: process | BP45: year | BQ45: AllRegions | BR45: China | BS45: NorthAm
AG46: Tra_EV_Batt-LFP_virgin | AH46: 2023 | AI46: 0.1 | AJ46: =AI46 -> 0.1 | AK46: =AJ46 -> 0.1 | AS46: 57.416555 | AT46: 39.633379 | AU46: 76.303607 | AW46: Tra_EV_Batt-LFP_fromrecy | AX46: 2035 | AY46: =AY32*AK2/AJ2 -> 57.416555 | AZ46: =AZ32*AK2/AJ2 -> 39.633379 | BA46: =BA32*AK2/AJ2 -> 76.303607 | BD46: Tra_EV_Batt-LFP_virgin | BE46: 2035 | BF46: =AS46*70% -> 40.191588 | BG46: =AT46*70% -> 27.743365 | BH46: =AU46*70% -> 53.412525 | BO46: Tra_EV_Batt-LFP_virgin_pack | BP46: 2035 | BQ46: =AS46*30% -> 17.224966 | BR46: =AT46*30% -> 11.890014 | BS46: =AU46*30% -> 22.891082
AG47: Tra_EV_Batt-LMO_virgin | AH47: 2023 | AI47: 0.1 | AJ47: =AJ46 -> 0.1 | AK47: =AK46 -> 0.1 | AS47: 68.149 | AT47: 47.375464 | AU47: 90.18825 | AW47: Tra_EV_Batt-LMO_fromrecy | AX47: =AX46 -> 2035 | AY47: =AY33*AK3/AJ3 -> 68.149 | AZ47: =AZ33*AK3/AJ3 -> 47.375464 | BA47: =BA33*AK3/AJ3 -> 90.18825 | BD47: Tra_EV_Batt-LMO_virgin | BE47: 2035 | BF47: =AS47*70% -> 47.7043 | BG47: =AT47*70% -> 33.162825 | BH47: =AU47*70% -> 63.131775 | BO47: Tra_EV_Batt-LMO_virgin_pack | BP47: 2035 | BQ47: =AS47*30% -> 20.4447 | BR47: =AT47*30% -> 14.212639 | BS47: =AU47*30% -> 27.056475
AG48: Tra_EV_Batt-NCA_virgin | AH48: 2023 | AI48: =AI47 -> 0.1 | AJ48: =AJ47 -> 0.1 | AK48: =AK47 -> 0.1 | AS48: 60.96264 | AT48: 40.072479 | AU48: 83.0914 | AW48: Tra_EV_Batt-NCA_fromrecy | AX48: =AX47 -> 2035 | AY48: =AY34*AK4/AJ4 -> 60.96264 | AZ48: =AZ34*AK4/AJ4 -> 40.072479 | BA48: =BA34*AK4/AJ4 -> 83.0914 | BD48: Tra_EV_Batt-NCA_virgin | BE48: 2035 | BF48: =AS48*70% -> 42.673848 | BG48: =AT48*70% -> 28.050735 | BH48: =AU48*70% -> 58.16398 | BO48: Tra_EV_Batt-NCA_virgin_pack | BP48: 2035 | BQ48: =AS48*30% -> 18.288792 | BR48: =AT48*30% -> 12.021744 | BS48: =AU48*30% -> 24.92742
...

Sheet Revised__InvCost
A1: EV battery INVCOST (million $ per GWh) - virgin and recycled routes, 35 regions
A2: Blue = editable input. Black = formula. Yellow = key assumption to test. INVCOST = BaseCost(chem) x FrontierIndex(route,year) x RegionMultiplier(tier,year).
A4: 1. BASE COST BY CHEMISTRY (2023, China frontier)
A5: Process - recycled | B5: Process - virgin | C5: Base 2023 recy | D5: Virgin/recy ratio | E5: Base 2023 virgin
A6: Tra_EV_Batt-LFP_fromrecy | B6: Tra_EV_Batt-LFP | C6: 55.48673 | D6: 1 | E6: =C6*D6 -> 55.48673
A7: Tra_EV_Batt-LMO_fromrecy | B7: Tra_EV_Batt-LMO | C7: 66.32565 | D7: 1 | E7: =C7*D7 -> 66.32565
A8: Tra_EV_Batt-NCA_fromrecy | B8: Tra_EV_Batt-NCA | C8: 56.10147 | D8: 1 | E8: =C8*D8 -> 56.10147
A9: Tra_EV_Batt-NMC111_fromrecy | B9: Tra_EV_Batt-NMC111 | C9: 55.55951 | D9: 1 | E9: =C9*D9 -> 55.55951
A10: Tra_EV_Batt-NMC532_fromrecy | B10: Tra_EV_Batt-NMC532 | C10: 59.3677 | D10: 1 | E10: =C10*D10 -> 59.3677
A11: Tra_EV_Batt-NMC622_fromrecy | B11: Tra_EV_Batt-NMC622 | C11: 57.33755 | D11: 1 | E11: =C11*D11 -> 57.33755
A12: Tra_EV_Batt-NMC811_fromrecy | B12: Tra_EV_Batt-NMC811 | C12: 59.98948 | D12: 1 | E12: =C12*D12 -> 59.98948
A13: Base costs are your own 2023 China values. Virgin ratio defaults to 1.000 - REPLACE with real virgin capex data. Virgin process names are placeholders; overwrite column B.
A15: 2. FRONTIER DECAY - Index(t) = Floor + (1-Floor) x EXP(-lambda x (t-2023))
A16: Route | B16: Floor | C16: Lambda
A17: recy | B17: 0.38 | C17: 0.0479
A18: virgin | B18: 0.46 | C18: 0.0451
A20: Frontier index (2023 = 1.000)
A21: Route | B21: 2023 | C21: 2050 | D21: 2100
A22: recy | B22: =$B$17+(1-$B$17)*EXP(-$C$17*(2023-2023)) -> 1 | C22: =$B$17+(1-$B$17)*EXP(-$C$17*(2050-2023)) -> 0.55010561 | D22: =$B$17+(1-$B$17)*EXP(-$C$17*(2100-2023)) -> 0.39550898
A23: virgin | B23: =$B$18+(1-$B$18)*EXP(-$C$18*(2023-2023)) -> 1 | C23: =$B$18+(1-$B$18)*EXP(-$C$18*(2050-2023)) -> 0.61979139 | D23: =$B$18+(1-$B$18)*EXP(-$C$18*(2100-2023)) -> 0.47675789
A24: Recycling declines faster than virgin: less mature technology, more learning headroom. Anchor lambda to a published Li-ion learning rate (~15-20% per doubling) and cite it.
A26: 3. REGION TIERS - Mult(t) = Mfloor + (M2023 - Mfloor) x EXP(-k x (t-2023))
A27: Tier | B27: M 2023 | C27: M floor | D27: k | E27: Rationale
A28: Frontier | B28: 1 | C28: 1 | D28: 0 | E28: China. Global cost frontier, already near its floor.
A29: Developed | B29: 1.75 | C29: 1.18 | D29: 0.04484 | E29: High labour, energy, permitting costs; strong catch-up potential.
A30: Emerging | B30: 1.45 | C30: 1.08 | D30: 0.04846 | E30: Higher capital cost, no scale today; fastest convergence.
A31: Floors stay above 1.00: industrial electricity price, permitting and labour differences do not vanish, so full convergence to parity would not be credible. Tier column below is editable.
A33: 4. MULTIPLIER BY REGION
A34: Region | B34: Tier | C34: 2023 | D34: 2050 | E34: 2100
A35: Africa_North | B35: Emerging | C35: =INDEX($C$28:$C$30,MATCH($B35,$A$28:$A$30,0))+(INDEX($B$28:$B$30,MATCH($B35,$A$28:$A$30,0))-INDEX($C$28:$C$30,MATCH($B35,$A$28:$A$30,0)))*EXP(-INDEX($D$28:$D$30,MATCH($B35,$A$28:$A$30,0))*(2023-2023)) -> 1.45 | D35: =INDEX($C$28:$C$30,MATCH($B35,$A$28:$A$30,0))+(INDEX($B$28:$B$30,MATCH($B35,$A$28:$A$30,0))-INDEX($C$28:$C$30,MATCH($B35,$A$28:$A$30,0)))*EXP(-INDEX($D$28:$D$30,MATCH($B35,$A$28:$A$30,0))*(2050-2023)) -> 1.1799913 | E35: =INDEX($C$28:$C$30,MATCH($B35,$A$28:$A$30,0))+(INDEX($B$28:$B$30,MATCH($B35,$A$28:$A$30,0))-INDEX($C$28:$C$30,MATCH($B35,$A$28:$A$30,0)))*EXP(-INDEX($D$28:$D$30,MATCH($B35,$A$28:$A$30,0))*(2100-2023)) -> 1.0888648
A36: Africa_Other | B36: Emerging | C36: =INDEX($C$28:$C$30,MATCH($B36,$A$28:$A$30,0))+(INDEX($B$28:$B$30,MATCH($B36,$A$28:$A$30,0))-INDEX($C$28:$C$30,MATCH($B36,$A$28:$A$30,0)))*EXP(-INDEX($D$28:$D$30,MATCH($B36,$A$28:$A$30,0))*(2023-2023)) -> 1.45 | D36: =INDEX($C$28:$C$30,MATCH($B36,$A$28:$A$30,0))+(INDEX($B$28:$B$30,MATCH($B36,$A$28:$A$30,0))-INDEX($C$28:$C$30,MATCH($B36,$A$28:$A$30,0)))*EXP(-INDEX($D$28:$D$30,MATCH($B36,$A$28:$A$30,0))*(2050-2023)) -> 1.1799913 | E36: =INDEX($C$28:$C$30,MATCH($B36,$A$28:$A$30,0))+(INDEX($B$28:$B$30,MATCH($B36,$A$28:$A$30,0))-INDEX($C$28:$C$30,MATCH($B36,$A$28:$A$30,0)))*EXP(-INDEX($D$28:$D$30,MATCH($B36,$A$28:$A$30,0))*(2100-2023)) -> 1.0888648
A37: Australia | B37: Developed | C37: =INDEX($C$28:$C$30,MATCH($B37,$A$28:$A$30,0))+(INDEX($B$28:$B$30,MATCH($B37,$A$28:$A$30,0))-INDEX($C$28:$C$30,MATCH($B37,$A$28:$A$30,0)))*EXP(-INDEX($D$28:$D$30,MATCH($B37,$A$28:$A$30,0))*(2023-2023)) -> 1.75 | D37: =INDEX($C$28:$C$30,MATCH($B37,$A$28:$A$30,0))+(INDEX($B$28:$B$30,MATCH($B37,$A$28:$A$30,0))-INDEX($C$28:$C$30,MATCH($B37,$A$28:$A$30,0)))*EXP(-INDEX($D$28:$D$30,MATCH($B37,$A$28:$A$30,0))*(2050-2023)) -> 1.3498569 | E37: =INDEX($C$28:$C$30,MATCH($B37,$A$28:$A$30,0))+(INDEX($B$28:$B$30,MATCH($B37,$A$28:$A$30,0))-INDEX($C$28:$C$30,MATCH($B37,$A$28:$A$30,0)))*EXP(-INDEX($D$28:$D$30,MATCH($B37,$A$28:$A$30,0))*(2100-2023)) -> 1.1980466
A38: Austria | B38: Developed | C38: =INDEX($C$28:$C$30,MATCH($B38,$A$28:$A$30,0))+(INDEX($B$28:$B$30,MATCH($B38,$A$28:$A$30,0))-INDEX($C$28:$C$30,MATCH($B38,$A$28:$A$30,0)))*EXP(-INDEX($D$28:$D$30,MATCH($B38,$A$28:$A$30,0))*(2023-2023)) -> 1.75 | D38: =INDEX($C$28:$C$30,MATCH($B38,$A$28:$A$30,0))+(INDEX($B$28:$B$30,MATCH($B38,$A$28:$A$30,0))-INDEX($C$28:$C$30,MATCH($B38,$A$28:$A$30,0)))*EXP(-INDEX($D$28:$D$30,MATCH($B38,$A$28:$A$30,0))*(2050-2023)) -> 1.3498569 | E38: =INDEX($C$28:$C$30,MATCH($B38,$A$28:$A$30,0))+(INDEX($B$28:$B$30,MATCH($B38,$A$28:$A$30,0))-INDEX($C$28:$C$30,MATCH($B38,$A$28:$A$30,0)))*EXP(-INDEX($D$28:$D$30,MATCH($B38,$A$28:$A$30,0))*(2100-2023)) -> 1.1980466
A39: Baltics | B39: Emerging | C39: =INDEX($C$28:$C$30,MATCH($B39,$A$28:$A$30,0))+(INDEX($B$28:$B$30,MATCH($B39,$A$28:$A$30,0))-INDEX($C$28:$C$30,MATCH($B39,$A$28:$A$30,0)))*EXP(-INDEX($D$28:$D$30,MATCH($B39,$A$28:$A$30,0))*(2023-2023)) -> 1.45 | D39: =INDEX($C$28:$C$30,MATCH($B39,$A$28:$A$30,0))+(INDEX($B$28:$B$30,MATCH($B39,$A$28:$A$30,0))-INDEX($C$28:$C$30,MATCH($B39,$A$28:$A$30,0)))*EXP(-INDEX($D$28:$D$30,MATCH($B39,$A$28:$A$30,0))*(2050-2023)) -> 1.1799913 | E39: =INDEX($C$28:$C$30,MATCH($B39,$A$28:$A$30,0))+(INDEX($B$28:$B$30,MATCH($B39,$A$28:$A$30,0))-INDEX($C$28:$C$30,MATCH($B39,$A$28:$A$30,0)))*EXP(-INDEX($D$28:$D$30,MATCH($B39,$A$28:$A$30,0))*(2100-2023)) -> 1.0888648
A40: BeNeLux | B40: Developed | C40: =INDEX($C$28:$C$30,MATCH($B40,$A$28:$A$30,0))+(INDEX($B$28:$B$30,MATCH($B40,$A$28:$A$30,0))-INDEX($C$28:$C$30,MATCH($B40,$A$28:$A$30,0)))*EXP(-INDEX($D$28:$D$30,MATCH($B40,$A$28:$A$30,0))*(2023-2023)) -> 1.75 | D40: =INDEX($C$28:$C$30,MATCH($B40,$A$28:$A$30,0))+(INDEX($B$28:$B$30,MATCH($B40,$A$28:$A$30,0))-INDEX($C$28:$C$30,MATCH($B40,$A$28:$A$30,0)))*EXP(-INDEX($D$28:$D$30,MATCH($B40,$A$28:$A$30,0))*(2050-2023)) -> 1.3498569 | E40: =INDEX($C$28:$C$30,MATCH($B40,$A$28:$A$30,0))+(INDEX($B$28:$B$30,MATCH($B40,$A$28:$A$30,0))-INDEX($C$28:$C$30,MATCH($B40,$A$28:$A$30,0)))*EXP(-INDEX($D$28:$D$30,MATCH($B40,$A$28:$A$30,0))*(2100-2023)) -> 1.1980466
A41: Brazil | B41: Emerging | C41: =INDEX($C$28:$C$30,MATCH($B41,$A$28:$A$30,0))+(INDEX($B$28:$B$30,MATCH($B41,$A$28:$A$30,0))-INDEX($C$28:$C$30,MATCH($B41,$A$28:$A$30,0)))*EXP(-INDEX($D$28:$D$30,MATCH($B41,$A$28:$A$30,0))*(2023-2023)) -> 1.45 | D41: =INDEX($C$28:$C$30,MATCH($B41,$A$28:$A$30,0))+(INDEX($B$28:$B$30,MATCH($B41,$A$28:$A$30,0))-INDEX($C$28:$C$30,MATCH($B41,$A$28:$A$30,0)))*EXP(-INDEX($D$28:$D$30,MATCH($B41,$A$28:$A$30,0))*(2050-2023)) -> 1.1799913 | E41: =INDEX($C$28:$C$30,MATCH($B41,$A$28:$A$30,0))+(INDEX($B$28:$B$30,MATCH($B41,$A$28:$A$30,0))-INDEX($C$28:$C$30,MATCH($B41,$A$28:$A$30,0)))*EXP(-INDEX($D$28:$D$30,MATCH($B41,$A$28:$A$30,0))*(2100-2023)) -> 1.0888648
A42: China | B42: Frontier | C42: =INDEX($C$28:$C$30,MATCH($B42,$A$28:$A$30,0))+(INDEX($B$28:$B$30,MATCH($B42,$A$28:$A$30,0))-INDEX($C$28:$C$30,MATCH($B42,$A$28:$A$30,0)))*EXP(-INDEX($D$28:$D$30,MATCH($B42,$A$28:$A$30,0))*(2023-2023)) -> 1 | D42: =INDEX($C$28:$C$30,MATCH($B42,$A$28:$A$30,0))+(INDEX($B$28:$B$30,MATCH($B42,$A$28:$A$30,0))-INDEX($C$28:$C$30,MATCH($B42,$A$28:$A$30,0)))*EXP(-INDEX($D$28:$D$30,MATCH($B42,$A$28:$A$30,0))*(2050-2023)) -> 1 | E42: =INDEX($C$28:$C$30,MATCH($B42,$A$28:$A$30,0))+(INDEX($B$28:$B$30,MATCH($B42,$A$28:$A$30,0))-INDEX($C$28:$C$30,MATCH($B42,$A$28:$A$30,0)))*EXP(-INDEX($D$28:$D$30,MATCH($B42,$A$28:$A$30,0))*(2100-2023)) -> 1
A43: CroSloven | B43: Emerging | C43: =INDEX($C$28:$C$30,MATCH($B43,$A$28:$A$30,0))+(INDEX($B$28:$B$30,MATCH($B43,$A$28:$A$30,0))-INDEX($C$28:$C$30,MATCH($B43,$A$28:$A$30,0)))*EXP(-INDEX($D$28:$D$30,MATCH($B43,$A$28:$A$30,0))*(2023-2023)) -> 1.45 | D43: =INDEX($C$28:$C$30,MATCH($B43,$A$28:$A$30,0))+(INDEX($B$28:$B$30,MATCH($B43,$A$28:$A$30,0))-INDEX($C$28:$C$30,MATCH($B43,$A$28:$A$30,0)))*EXP(-INDEX($D$28:$D$30,MATCH($B43,$A$28:$A$30,0))*(2050-2023)) -> 1.1799913 | E43: =INDEX($C$28:$C$30,MATCH($B43,$A$28:$A$30,0))+(INDEX($B$28:$B$30,MATCH($B43,$A$28:$A$30,0))-INDEX($C$28:$C$30,MATCH($B43,$A$28:$A$30,0)))*EXP(-INDEX($D$28:$D$30,MATCH($B43,$A$28:$A$30,0))*(2100-2023)) -> 1.0888648
A44: CzechSlovak | B44: Emerging | C44: =INDEX($C$28:$C$30,MATCH($B44,$A$28:$A$30,0))+(INDEX($B$28:$B$30,MATCH($B44,$A$28:$A$30,0))-INDEX($C$28:$C$30,MATCH($B44,$A$28:$A$30,0)))*EXP(-INDEX($D$28:$D$30,MATCH($B44,$A$28:$A$30,0))*(2023-2023)) -> 1.45 | D44: =INDEX($C$28:$C$30,MATCH($B44,$A$28:$A$30,0))+(INDEX($B$28:$B$30,MATCH($B44,$A$28:$A$30,0))-INDEX($C$28:$C$30,MATCH($B44,$A$28:$A$30,0)))*EXP(-INDEX($D$28:$D$30,MATCH($B44,$A$28:$A$30,0))*(2050-2023)) -> 1.1799913 | E44: =INDEX($C$28:$C$30,MATCH($B44,$A$28:$A$30,0))+(INDEX($B$28:$B$30,MATCH($B44,$A$28:$A$30,0))-INDEX($C$28:$C$30,MATCH($B44,$A$28:$A$30,0)))*EXP(-INDEX($D$28:$D$30,MATCH($B44,$A$28:$A$30,0))*(2100-2023)) -> 1.0888648
A45: France | B45: Developed | C45: =INDEX($C$28:$C$30,MATCH($B45,$A$28:$A$30,0))+(INDEX($B$28:$B$30,MATCH($B45,$A$28:$A$30,0))-INDEX($C$28:$C$30,MATCH($B45,$A$28:$A$30,0)))*EXP(-INDEX($D$28:$D$30,MATCH($B45,$A$28:$A$30,0))*(2023-2023)) -> 1.75 | D45: =INDEX($C$28:$C$30,MATCH($B45,$A$28:$A$30,0))+(INDEX($B$28:$B$30,MATCH($B45,$A$28:$A$30,0))-INDEX($C$28:$C$30,MATCH($B45,$A$28:$A$30,0)))*EXP(-INDEX($D$28:$D$30,MATCH($B45,$A$28:$A$30,0))*(2050-2023)) -> 1.3498569 | E45: =INDEX($C$28:$C$30,MATCH($B45,$A$28:$A$30,0))+(INDEX($B$28:$B$30,MATCH($B45,$A$28:$A$30,0))-INDEX($C$28:$C$30,MATCH($B45,$A$28:$A$30,0)))*EXP(-INDEX($D$28:$D$30,MATCH($B45,$A$28:$A$30,0))*(2100-2023)) -> 1.1980466
...

Sheet Road transport
B2: ~TFM_FILL-R:w=RoadTra_BY; hcol=region | K2: ~TFM_TOPINS | P2: TFM_TOPINS
B3: Scenario | C3: Attribute | D3: PSET_CO | E3: AllRegions | K3: process | L3: IO | M3: commodity | P3: pset_ci | Q3: pset_co | R3: cset_cn | S3: IO
B4: BASE | C4: AF | D4: Trd[_]* | E4: *1 | K4: Trd[_]*gsl* | L4: IN | M4: TRAGSL,TRABGS | P4: TRAELC | Q4: TRDELC | R4: ELC | S4: Out
B5: BASE | C5: EFF | D5: Trd[_]* | E5: *1 | K5: Trd[_]*dsl* | L5: IN | M5: TRADST,TRABDS
K6: Trd[_]*hh2* | L6: IN | M6: TRAGH2
K7: Trd[_]*cng* | L7: IN | M7: TRANGA
B8: ~TFM_INS | K8: Trd[_]*elc* | L8: IN | M8: TRDELC
B9: attribute | C9: PSET_PN | D9: PSET_CI | E9: CSET_CN | F9: value | G9: limtype | H9: year | K9: Trd[_]*lng* | L9: IN | M9: TRANGA
B10: Share | C10: Trd[_]*-pih* | E10: TRDELC | F10: 0.25 | G10: FX | K10: Trd[_]*-pih* | L10: IN | M10: TRDELC
B11: Share | C11: Trd[_]*-pih* | E11: TRDELC | F11: 3 | G11: FX | H11: 0
B12: LIFE | C12: Trd[_]* | F12: 15 | K12: ~TFM_MIG
B13: *START | C13: Trd[_]* | E13: -TRDELC | F13: 2019 | K13: attribute | L13: value | M13: attribute2 | N13: pset_pn
K14: INVCOST | L14: *.03 | M14: FIXOM | N14: Trd[_]*
B15: CEFF | D15: TRAGSL | E15: TRABGS | F15: 0.93 | K15: INVCOST | L15: *.02 | M15: FIXOM | N15: Trd[_]*elc*
B16: ~TFM_INS-TS: attribute=FLO_MARK
B18: pset_ci | C18: 2019 | D18: 0 | E18: attrib_cond | F18: commodity | G18: top_check
B19: -TRDELC | C19: 0.2 | D19: 3 | E19: -FLO_MARK | F19: Trd[_]* | G19: OUT
C21: ~TFM_INS
C22: attribute | D22: =IF(RoadTra_BY!L$1="","\I:",RoadTra_BY!L$1) -> Africa_North | E22: =IF(RoadTra_BY!M$1="","\I:",RoadTra_BY!M$1) -> Africa_Other | F22: =IF(RoadTra_BY!N$1="","\I:",RoadTra_BY!N$1) -> Australia | G22: =IF(RoadTra_BY!O$1="","\I:",RoadTra_BY!O$1) -> Austria | H22: =IF(RoadTra_BY!P$1="","\I:",RoadTra_BY!P$1) -> Baltics | I22: =IF(RoadTra_BY!Q$1="","\I:",RoadTra_BY!Q$1) -> BeNeLux | J22: =IF(RoadTra_BY!R$1="","\I:",RoadTra_BY!R$1) -> Brazil | K22: =IF(RoadTra_BY!S$1="","\I:",RoadTra_BY!S$1) -> China | ... AW22: =IF(RoadTra_BY!BE$1="","\I:",RoadTra_BY!BE$1) -> \I: | AX22: process
C23: AF | D23: =AVERAGEIFS(RoadTra_BY!L$2:L$999,RoadTra_BY!$B$2:$B$999,'Road transport'!$C23,RoadTra_BY!$C$2:$C$999,'Road transport'!$AX23) -> 7 | E23: =AVERAGEIFS(RoadTra_BY!M$2:M$999,RoadTra_BY!$B$2:$B$999,'Road transport'!$C23,RoadTra_BY!$C$2:$C$999,'Road transport'!$AX23) -> 7 | F23: =AVERAGEIFS(RoadTra_BY!N$2:N$999,RoadTra_BY!$B$2:$B$999,'Road transport'!$C23,RoadTra_BY!$C$2:$C$999,'Road transport'!$AX23) -> 7 | G23: =AVERAGEIFS(RoadTra_BY!O$2:O$999,RoadTra_BY!$B$2:$B$999,'Road transport'!$C23,RoadTra_BY!$C$2:$C$999,'Road transport'!$AX23) -> 7 | H23: =AVERAGEIFS(RoadTra_BY!P$2:P$999,RoadTra_BY!$B$2:$B$999,'Road transport'!$C23,RoadTra_BY!$C$2:$C$999,'Road transport'!$AX23) -> 7 | I23: =AVERAGEIFS(RoadTra_BY!Q$2:Q$999,RoadTra_BY!$B$2:$B$999,'Road transport'!$C23,RoadTra_BY!$C$2:$C$999,'Road transport'!$AX23) -> 7 | J23: =AVERAGEIFS(RoadTra_BY!R$2:R$999,RoadTra_BY!$B$2:$B$999,'Road transport'!$C23,RoadTra_BY!$C$2:$C$999,'Road transport'!$AX23) -> 7 | K23: =AVERAGEIFS(RoadTra_BY!S$2:S$999,RoadTra_BY!$B$2:$B$999,'Road transport'!$C23,RoadTra_BY!$C$2:$C$999,'Road transport'!$AX23) -> 7 | ... AW23: =AVERAGEIFS(RoadTra_BY!BE$2:BE$999,RoadTra_BY!$B$2:$B$999,'Road transport'!$C23,RoadTra_BY!$C$2:$C$999,'Road transport'!$AX23) -> #DIV/0! | AX23: Trd_2w_*
C24: AF | D24: =AVERAGEIFS(RoadTra_BY!L$2:L$999,RoadTra_BY!$B$2:$B$999,'Road transport'!$C24,RoadTra_BY!$C$2:$C$999,'Road transport'!$AX24) -> 15 | E24: =AVERAGEIFS(RoadTra_BY!M$2:M$999,RoadTra_BY!$B$2:$B$999,'Road transport'!$C24,RoadTra_BY!$C$2:$C$999,'Road transport'!$AX24) -> 15 | F24: =AVERAGEIFS(RoadTra_BY!N$2:N$999,RoadTra_BY!$B$2:$B$999,'Road transport'!$C24,RoadTra_BY!$C$2:$C$999,'Road transport'!$AX24) -> 15 | G24: =AVERAGEIFS(RoadTra_BY!O$2:O$999,RoadTra_BY!$B$2:$B$999,'Road transport'!$C24,RoadTra_BY!$C$2:$C$999,'Road transport'!$AX24) -> 15 | H24: =AVERAGEIFS(RoadTra_BY!P$2:P$999,RoadTra_BY!$B$2:$B$999,'Road transport'!$C24,RoadTra_BY!$C$2:$C$999,'Road transport'!$AX24) -> 15 | I24: =AVERAGEIFS(RoadTra_BY!Q$2:Q$999,RoadTra_BY!$B$2:$B$999,'Road transport'!$C24,RoadTra_BY!$C$2:$C$999,'Road transport'!$AX24) -> 15 | J24: =AVERAGEIFS(RoadTra_BY!R$2:R$999,RoadTra_BY!$B$2:$B$999,'Road transport'!$C24,RoadTra_BY!$C$2:$C$999,'Road transport'!$AX24) -> 15 | K24: =AVERAGEIFS(RoadTra_BY!S$2:S$999,RoadTra_BY!$B$2:$B$999,'Road transport'!$C24,RoadTra_BY!$C$2:$C$999,'Road transport'!$AX24) -> 15 | ... AW24: =AVERAGEIFS(RoadTra_BY!BE$2:BE$999,RoadTra_BY!$B$2:$B$999,'Road transport'!$C24,RoadTra_BY!$C$2:$C$999,'Road transport'!$AX24) -> #DIV/0! | AX24: Trd_3w_*
C25: AF | D25: =AVERAGEIFS(RoadTra_BY!L$2:L$999,RoadTra_BY!$B$2:$B$999,'Road transport'!$C25,RoadTra_BY!$C$2:$C$999,'Road transport'!$AX25) -> 35 | E25: =AVERAGEIFS(RoadTra_BY!M$2:M$999,RoadTra_BY!$B$2:$B$999,'Road transport'!$C25,RoadTra_BY!$C$2:$C$999,'Road transport'!$AX25) -> 35 | F25: =AVERAGEIFS(RoadTra_BY!N$2:N$999,RoadTra_BY!$B$2:$B$999,'Road transport'!$C25,RoadTra_BY!$C$2:$C$999,'Road transport'!$AX25) -> 35 | G25: =AVERAGEIFS(RoadTra_BY!O$2:O$999,RoadTra_BY!$B$2:$B$999,'Road transport'!$C25,RoadTra_BY!$C$2:$C$999,'Road transport'!$AX25) -> 35 | H25: =AVERAGEIFS(RoadTra_BY!P$2:P$999,RoadTra_BY!$B$2:$B$999,'Road transport'!$C25,RoadTra_BY!$C$2:$C$999,'Road transport'!$AX25) -> 35 | I25: =AVERAGEIFS(RoadTra_BY!Q$2:Q$999,RoadTra_BY!$B$2:$B$999,'Road transport'!$C25,RoadTra_BY!$C$2:$C$999,'Road transport'!$AX25) -> 35 | J25: =AVERAGEIFS(RoadTra_BY!R$2:R$999,RoadTra_BY!$B$2:$B$999,'Road transport'!$C25,RoadTra_BY!$C$2:$C$999,'Road transport'!$AX25) -> 35 | K25: =AVERAGEIFS(RoadTra_BY!S$2:S$999,RoadTra_BY!$B$2:$B$999,'Road transport'!$C25,RoadTra_BY!$C$2:$C$999,'Road transport'!$AX25) -> 35 | ... AW25: =AVERAGEIFS(RoadTra_BY!BE$2:BE$999,RoadTra_BY!$B$2:$B$999,'Road transport'!$C25,RoadTra_BY!$C$2:$C$999,'Road transport'!$AX25) -> #DIV/0! | AX25: Trd_bus*
C26: AF | D26: =AVERAGEIFS(RoadTra_BY!L$2:L$999,RoadTra_BY!$B$2:$B$999,'Road transport'!$C26,RoadTra_BY!$C$2:$C$999,'Road transport'!$AX26) -> 12 | E26: =AVERAGEIFS(RoadTra_BY!M$2:M$999,RoadTra_BY!$B$2:$B$999,'Road transport'!$C26,RoadTra_BY!$C$2:$C$999,'Road transport'!$AX26) -> 12 | F26: =AVERAGEIFS(RoadTra_BY!N$2:N$999,RoadTra_BY!$B$2:$B$999,'Road transport'!$C26,RoadTra_BY!$C$2:$C$999,'Road transport'!$AX26) -> 12 | G26: =AVERAGEIFS(RoadTra_BY!O$2:O$999,RoadTra_BY!$B$2:$B$999,'Road transport'!$C26,RoadTra_BY!$C$2:$C$999,'Road transport'!$AX26) -> 12 | H26: =AVERAGEIFS(RoadTra_BY!P$2:P$999,RoadTra_BY!$B$2:$B$999,'Road transport'!$C26,RoadTra_BY!$C$2:$C$999,'Road transport'!$AX26) -> 12 | I26: =AVERAGEIFS(RoadTra_BY!Q$2:Q$999,RoadTra_BY!$B$2:$B$999,'Road transport'!$C26,RoadTra_BY!$C$2:$C$999,'Road transport'!$AX26) -> 12 | J26: =AVERAGEIFS(RoadTra_BY!R$2:R$999,RoadTra_BY!$B$2:$B$999,'Road transport'!$C26,RoadTra_BY!$C$2:$C$999,'Road transport'!$AX26) -> 12 | K26: =AVERAGEIFS(RoadTra_BY!S$2:S$999,RoadTra_BY!$B$2:$B$999,'Road transport'!$C26,RoadTra_BY!$C$2:$C$999,'Road transport'!$AX26) -> 8 | ... AW26: =AVERAGEIFS(RoadTra_BY!BE$2:BE$999,RoadTra_BY!$B$2:$B$999,'Road transport'!$C26,RoadTra_BY!$C$2:$C$999,'Road transport'!$AX26) -> #DIV/0! | AX26: Trd_car*
C27: AF | D27: =AVERAGEIFS(RoadTra_BY!L$2:L$999,RoadTra_BY!$B$2:$B$999,'Road transport'!$C27,RoadTra_BY!$C$2:$C$999,'Road transport'!$AX27) -> 100 | E27: =AVERAGEIFS(RoadTra_BY!M$2:M$999,RoadTra_BY!$B$2:$B$999,'Road transport'!$C27,RoadTra_BY!$C$2:$C$999,'Road transport'!$AX27) -> 100 | F27: =AVERAGEIFS(RoadTra_BY!N$2:N$999,RoadTra_BY!$B$2:$B$999,'Road transport'!$C27,RoadTra_BY!$C$2:$C$999,'Road transport'!$AX27) -> 100 | G27: =AVERAGEIFS(RoadTra_BY!O$2:O$999,RoadTra_BY!$B$2:$B$999,'Road transport'!$C27,RoadTra_BY!$C$2:$C$999,'Road transport'!$AX27) -> 100 | H27: =AVERAGEIFS(RoadTra_BY!P$2:P$999,RoadTra_BY!$B$2:$B$999,'Road transport'!$C27,RoadTra_BY!$C$2:$C$999,'Road transport'!$AX27) -> 100 | I27: =AVERAGEIFS(RoadTra_BY!Q$2:Q$999,RoadTra_BY!$B$2:$B$999,'Road transport'!$C27,RoadTra_BY!$C$2:$C$999,'Road transport'!$AX27) -> 100 | J27: =AVERAGEIFS(RoadTra_BY!R$2:R$999,RoadTra_BY!$B$2:$B$999,'Road transport'!$C27,RoadTra_BY!$C$2:$C$999,'Road transport'!$AX27) -> 100 | K27: =AVERAGEIFS(RoadTra_BY!S$2:S$999,RoadTra_BY!$B$2:$B$999,'Road transport'!$C27,RoadTra_BY!$C$2:$C$999,'Road transport'!$AX27) -> 100 | ... AW27: =AVERAGEIFS(RoadTra_BY!BE$2:BE$999,RoadTra_BY!$B$2:$B$999,'Road transport'!$C27,RoadTra_BY!$C$2:$C$999,'Road transport'!$AX27) -> #DIV/0! | AX27: Trd_hdt*
C28: AF | D28: =AVERAGEIFS(RoadTra_BY!L$2:L$999,RoadTra_BY!$B$2:$B$999,'Road transport'!$C28,RoadTra_BY!$C$2:$C$999,'Road transport'!$AX28) -> 40 | E28: =AVERAGEIFS(RoadTra_BY!M$2:M$999,RoadTra_BY!$B$2:$B$999,'Road transport'!$C28,RoadTra_BY!$C$2:$C$999,'Road transport'!$AX28) -> 40 | F28: =AVERAGEIFS(RoadTra_BY!N$2:N$999,RoadTra_BY!$B$2:$B$999,'Road transport'!$C28,RoadTra_BY!$C$2:$C$999,'Road transport'!$AX28) -> 40 | G28: =AVERAGEIFS(RoadTra_BY!O$2:O$999,RoadTra_BY!$B$2:$B$999,'Road transport'!$C28,RoadTra_BY!$C$2:$C$999,'Road transport'!$AX28) -> 40 | H28: =AVERAGEIFS(RoadTra_BY!P$2:P$999,RoadTra_BY!$B$2:$B$999,'Road transport'!$C28,RoadTra_BY!$C$2:$C$999,'Road transport'!$AX28) -> 40 | I28: =AVERAGEIFS(RoadTra_BY!Q$2:Q$999,RoadTra_BY!$B$2:$B$999,'Road transport'!$C28,RoadTra_BY!$C$2:$C$999,'Road transport'!$AX28) -> 40 | J28: =AVERAGEIFS(RoadTra_BY!R$2:R$999,RoadTra_BY!$B$2:$B$999,'Road transport'!$C28,RoadTra_BY!$C$2:$C$999,'Road transport'!$AX28) -> 40 | K28: =AVERAGEIFS(RoadTra_BY!S$2:S$999,RoadTra_BY!$B$2:$B$999,'Road transport'!$C28,RoadTra_BY!$C$2:$C$999,'Road transport'!$AX28) -> 40 | ... AW28: =AVERAGEIFS(RoadTra_BY!BE$2:BE$999,RoadTra_BY!$B$2:$B$999,'Road transport'!$C28,RoadTra_BY!$C$2:$C$999,'Road transport'!$AX28) -> #DIV/0! | AX28: Trd_lcv*
C31: ~TFM_UPD
C32: attribute | D32: =IF(RoadTra_BY!L$1="","\I:",RoadTra_BY!L$1) -> Africa_North | E32: =IF(RoadTra_BY!M$1="","\I:",RoadTra_BY!M$1) -> Africa_Other | F32: =IF(RoadTra_BY!N$1="","\I:",RoadTra_BY!N$1) -> Australia | G32: =IF(RoadTra_BY!O$1="","\I:",RoadTra_BY!O$1) -> Austria | H32: =IF(RoadTra_BY!P$1="","\I:",RoadTra_BY!P$1) -> Baltics | I32: =IF(RoadTra_BY!Q$1="","\I:",RoadTra_BY!Q$1) -> BeNeLux | J32: =IF(RoadTra_BY!R$1="","\I:",RoadTra_BY!R$1) -> Brazil | K32: =IF(RoadTra_BY!S$1="","\I:",RoadTra_BY!S$1) -> China | ... AW32: =IF(RoadTra_BY!BE$1="","\I:",RoadTra_BY!BE$1) -> \I: | AX32: process
C33: EFF | D33: ="*"&ROUND(SUMIFS(RoadTra_BY!L$2:L$79,RoadTra_BY!$B$2:$B$79,'Road transport'!$C33,RoadTra_BY!$C$2:$C$79,'Road transport'!$BA33),3) -> *0.99 | E33: ="*"&ROUND(SUMIFS(RoadTra_BY!M$2:M$79,RoadTra_BY!$B$2:$B$79,'Road transport'!$C33,RoadTra_BY!$C$2:$C$79,'Road transport'!$BA33),3) -> *0.99 | F33: ="*"&ROUND(SUMIFS(RoadTra_BY!N$2:N$79,RoadTra_BY!$B$2:$B$79,'Road transport'!$C33,RoadTra_BY!$C$2:$C$79,'Road transport'!$BA33),3) -> *0.99 | G33: ="*"&ROUND(SUMIFS(RoadTra_BY!O$2:O$79,RoadTra_BY!$B$2:$B$79,'Road transport'!$C33,RoadTra_BY!$C$2:$C$79,'Road transport'!$BA33),3) -> *0.99 | H33: ="*"&ROUND(SUMIFS(RoadTra_BY!P$2:P$79,RoadTra_BY!$B$2:$B$79,'Road transport'!$C33,RoadTra_BY!$C$2:$C$79,'Road transport'!$BA33),3) -> *0.99 | I33: ="*"&ROUND(SUMIFS(RoadTra_BY!Q$2:Q$79,RoadTra_BY!$B$2:$B$79,'Road transport'!$C33,RoadTra_BY!$C$2:$C$79,'Road transport'!$BA33),3) -> *0.99 | J33: ="*"&ROUND(SUMIFS(RoadTra_BY!R$2:R$79,RoadTra_BY!$B$2:$B$79,'Road transport'!$C33,RoadTra_BY!$C$2:$C$79,'Road transport'!$BA33),3) -> *0.99 | K33: ="*"&ROUND(SUMIFS(RoadTra_BY!S$2:S$79,RoadTra_BY!$B$2:$B$79,'Road transport'!$C33,RoadTra_BY!$C$2:$C$79,'Road transport'!$BA33),3) -> *0.99 | ... AW33: ="*"&ROUND(SUMIFS(RoadTra_BY!BE$2:BE$79,RoadTra_BY!$B$2:$B$79,'Road transport'!$C33,RoadTra_BY!$C$2:$C$79,'Road transport'!$BA33),3) -> *0 | AX33: =SUBSTITUTE(SUBSTITUTE(BA33,"gsl",""),"dsl","")&"*" -> Trd_2w_* | AZ33: =IFERROR(IF(FIND("gsl",BA33)>0,1,0),2) -> 1 | BA33: Trd_2w_gsl
C34: EFF | D34: ="*"&ROUND(SUMIFS(RoadTra_BY!L$2:L$79,RoadTra_BY!$B$2:$B$79,'Road transport'!$C34,RoadTra_BY!$C$2:$C$79,'Road transport'!$BA34),3) -> *0.587 | E34: ="*"&ROUND(SUMIFS(RoadTra_BY!M$2:M$79,RoadTra_BY!$B$2:$B$79,'Road transport'!$C34,RoadTra_BY!$C$2:$C$79,'Road transport'!$BA34),3) -> *0.587 | F34: ="*"&ROUND(SUMIFS(RoadTra_BY!N$2:N$79,RoadTra_BY!$B$2:$B$79,'Road transport'!$C34,RoadTra_BY!$C$2:$C$79,'Road transport'!$BA34),3) -> *0.587 | G34: ="*"&ROUND(SUMIFS(RoadTra_BY!O$2:O$79,RoadTra_BY!$B$2:$B$79,'Road transport'!$C34,RoadTra_BY!$C$2:$C$79,'Road transport'!$BA34),3) -> *0.587 | H34: ="*"&ROUND(SUMIFS(RoadTra_BY!P$2:P$79,RoadTra_BY!$B$2:$B$79,'Road transport'!$C34,RoadTra_BY!$C$2:$C$79,'Road transport'!$BA34),3) -> *0.587 | I34: ="*"&ROUND(SUMIFS(RoadTra_BY!Q$2:Q$79,RoadTra_BY!$B$2:$B$79,'Road transport'!$C34,RoadTra_BY!$C$2:$C$79,'Road transport'!$BA34),3) -> *0.587 | J34: ="*"&ROUND(SUMIFS(RoadTra_BY!R$2:R$79,RoadTra_BY!$B$2:$B$79,'Road transport'!$C34,RoadTra_BY!$C$2:$C$79,'Road transport'!$BA34),3) -> *0.587 | K34: ="*"&ROUND(SUMIFS(RoadTra_BY!S$2:S$79,RoadTra_BY!$B$2:$B$79,'Road transport'!$C34,RoadTra_BY!$C$2:$C$79,'Road transport'!$BA34),3) -> *0.587 | ... AW34: ="*"&ROUND(SUMIFS(RoadTra_BY!BE$2:BE$79,RoadTra_BY!$B$2:$B$79,'Road transport'!$C34,RoadTra_BY!$C$2:$C$79,'Road transport'!$BA34),3) -> *0 | AX34: =SUBSTITUTE(SUBSTITUTE(BA34,"gsl",""),"dsl","")&"*" -> Trd_3w_* | AZ34: =IFERROR(IF(FIND("gsl",BA34)>0,1,0),2) -> 1 | BA34: Trd_3w_gsl
C35: EFF | D35: ="*"&ROUND(SUMIFS(RoadTra_BY!L$2:L$79,RoadTra_BY!$B$2:$B$79,'Road transport'!$C35,RoadTra_BY!$C$2:$C$79,'Road transport'!$BA35),3) -> *0.072 | E35: ="*"&ROUND(SUMIFS(RoadTra_BY!M$2:M$79,RoadTra_BY!$B$2:$B$79,'Road transport'!$C35,RoadTra_BY!$C$2:$C$79,'Road transport'!$BA35),3) -> *0.072 | F35: ="*"&ROUND(SUMIFS(RoadTra_BY!N$2:N$79,RoadTra_BY!$B$2:$B$79,'Road transport'!$C35,RoadTra_BY!$C$2:$C$79,'Road transport'!$BA35),3) -> *0.072 | G35: ="*"&ROUND(SUMIFS(RoadTra_BY!O$2:O$79,RoadTra_BY!$B$2:$B$79,'Road transport'!$C35,RoadTra_BY!$C$2:$C$79,'Road transport'!$BA35),3) -> *0.072 | H35: ="*"&ROUND(SUMIFS(RoadTra_BY!P$2:P$79,RoadTra_BY!$B$2:$B$79,'Road transport'!$C35,RoadTra_BY!$C$2:$C$79,'Road transport'!$BA35),3) -> *0.072 | I35: ="*"&ROUND(SUMIFS(RoadTra_BY!Q$2:Q$79,RoadTra_BY!$B$2:$B$79,'Road transport'!$C35,RoadTra_BY!$C$2:$C$79,'Road transport'!$BA35),3) -> *0.072 | J35: ="*"&ROUND(SUMIFS(RoadTra_BY!R$2:R$79,RoadTra_BY!$B$2:$B$79,'Road transport'!$C35,RoadTra_BY!$C$2:$C$79,'Road transport'!$BA35),3) -> *0.072 | K35: ="*"&ROUND(SUMIFS(RoadTra_BY!S$2:S$79,RoadTra_BY!$B$2:$B$79,'Road transport'!$C35,RoadTra_BY!$C$2:$C$79,'Road transport'!$BA35),3) -> *0.072 | ... AW35: ="*"&ROUND(SUMIFS(RoadTra_BY!BE$2:BE$79,RoadTra_BY!$B$2:$B$79,'Road transport'!$C35,RoadTra_BY!$C$2:$C$79,'Road transport'!$BA35),3) -> *0 | AX35: =SUBSTITUTE(SUBSTITUTE(BA35,"gsl",""),"dsl","")&"*" -> Trd_bus_* | AZ35: =IFERROR(IF(FIND("gsl",BA35)>0,1,0),2) -> 2 | BA35: Trd_bus_dsl
C36: EFF | D36: ="*"&ROUND(SUMIFS(RoadTra_BY!L$2:L$79,RoadTra_BY!$B$2:$B$79,'Road transport'!$C36,RoadTra_BY!$C$2:$C$79,'Road transport'!$BA36),3) -> *0.466 | E36: ="*"&ROUND(SUMIFS(RoadTra_BY!M$2:M$79,RoadTra_BY!$B$2:$B$79,'Road transport'!$C36,RoadTra_BY!$C$2:$C$79,'Road transport'!$BA36),3) -> *0.466 | F36: ="*"&ROUND(SUMIFS(RoadTra_BY!N$2:N$79,RoadTra_BY!$B$2:$B$79,'Road transport'!$C36,RoadTra_BY!$C$2:$C$79,'Road transport'!$BA36),3) -> *0.466 | G36: ="*"&ROUND(SUMIFS(RoadTra_BY!O$2:O$79,RoadTra_BY!$B$2:$B$79,'Road transport'!$C36,RoadTra_BY!$C$2:$C$79,'Road transport'!$BA36),3) -> *0.466 | H36: ="*"&ROUND(SUMIFS(RoadTra_BY!P$2:P$79,RoadTra_BY!$B$2:$B$79,'Road transport'!$C36,RoadTra_BY!$C$2:$C$79,'Road transport'!$BA36),3) -> *0.466 | I36: ="*"&ROUND(SUMIFS(RoadTra_BY!Q$2:Q$79,RoadTra_BY!$B$2:$B$79,'Road transport'!$C36,RoadTra_BY!$C$2:$C$79,'Road transport'!$BA36),3) -> *0.466 | J36: ="*"&ROUND(SUMIFS(RoadTra_BY!R$2:R$79,RoadTra_BY!$B$2:$B$79,'Road transport'!$C36,RoadTra_BY!$C$2:$C$79,'Road transport'!$BA36),3) -> *0.466 | K36: ="*"&ROUND(SUMIFS(RoadTra_BY!S$2:S$79,RoadTra_BY!$B$2:$B$79,'Road transport'!$C36,RoadTra_BY!$C$2:$C$79,'Road transport'!$BA36),3) -> *0.466 | ... AW36: ="*"&ROUND(SUMIFS(RoadTra_BY!BE$2:BE$79,RoadTra_BY!$B$2:$B$79,'Road transport'!$C36,RoadTra_BY!$C$2:$C$79,'Road transport'!$BA36),3) -> *0 | AX36: =SUBSTITUTE(SUBSTITUTE(BA36,"gsl",""),"dsl","")&"*" -> Trd_car_* | AZ36: =IFERROR(IF(FIND("gsl",BA36)>0,1,0),2) -> 1 | BA36: Trd_car_gsl
C37: EFF | D37: ="*"&ROUND(SUMIFS(RoadTra_BY!L$2:L$79,RoadTra_BY!$B$2:$B$79,'Road transport'!$C37,RoadTra_BY!$C$2:$C$79,'Road transport'!$BA37),3) -> *0.139 | E37: ="*"&ROUND(SUMIFS(RoadTra_BY!M$2:M$79,RoadTra_BY!$B$2:$B$79,'Road transport'!$C37,RoadTra_BY!$C$2:$C$79,'Road transport'!$BA37),3) -> *0.139 | F37: ="*"&ROUND(SUMIFS(RoadTra_BY!N$2:N$79,RoadTra_BY!$B$2:$B$79,'Road transport'!$C37,RoadTra_BY!$C$2:$C$79,'Road transport'!$BA37),3) -> *0.139 | G37: ="*"&ROUND(SUMIFS(RoadTra_BY!O$2:O$79,RoadTra_BY!$B$2:$B$79,'Road transport'!$C37,RoadTra_BY!$C$2:$C$79,'Road transport'!$BA37),3) -> *0.139 | H37: ="*"&ROUND(SUMIFS(RoadTra_BY!P$2:P$79,RoadTra_BY!$B$2:$B$79,'Road transport'!$C37,RoadTra_BY!$C$2:$C$79,'Road transport'!$BA37),3) -> *0.139 | I37: ="*"&ROUND(SUMIFS(RoadTra_BY!Q$2:Q$79,RoadTra_BY!$B$2:$B$79,'Road transport'!$C37,RoadTra_BY!$C$2:$C$79,'Road transport'!$BA37),3) -> *0.139 | J37: ="*"&ROUND(SUMIFS(RoadTra_BY!R$2:R$79,RoadTra_BY!$B$2:$B$79,'Road transport'!$C37,RoadTra_BY!$C$2:$C$79,'Road transport'!$BA37),3) -> *0.139 | K37: ="*"&ROUND(SUMIFS(RoadTra_BY!S$2:S$79,RoadTra_BY!$B$2:$B$79,'Road transport'!$C37,RoadTra_BY!$C$2:$C$79,'Road transport'!$BA37),3) -> *0.139 | ... AW37: ="*"&ROUND(SUMIFS(RoadTra_BY!BE$2:BE$79,RoadTra_BY!$B$2:$B$79,'Road transport'!$C37,RoadTra_BY!$C$2:$C$79,'Road transport'!$BA37),3) -> *0 | AX37: =SUBSTITUTE(SUBSTITUTE(BA37,"gsl",""),"dsl","")&"*" -> Trd_hdt_* | AZ37: =IFERROR(IF(FIND("gsl",BA37)>0,1,0),2) -> 2 | BA37: Trd_hdt_dsl
C38: EFF | D38: ="*"&ROUND(SUMIFS(RoadTra_BY!L$2:L$79,RoadTra_BY!$B$2:$B$79,'Road transport'!$C38,RoadTra_BY!$C$2:$C$79,'Road transport'!$BA38),3) -> *0.38 | E38: ="*"&ROUND(SUMIFS(RoadTra_BY!M$2:M$79,RoadTra_BY!$B$2:$B$79,'Road transport'!$C38,RoadTra_BY!$C$2:$C$79,'Road transport'!$BA38),3) -> *0.38 | F38: ="*"&ROUND(SUMIFS(RoadTra_BY!N$2:N$79,RoadTra_BY!$B$2:$B$79,'Road transport'!$C38,RoadTra_BY!$C$2:$C$79,'Road transport'!$BA38),3) -> *0.38 | G38: ="*"&ROUND(SUMIFS(RoadTra_BY!O$2:O$79,RoadTra_BY!$B$2:$B$79,'Road transport'!$C38,RoadTra_BY!$C$2:$C$79,'Road transport'!$BA38),3) -> *0.38 | H38: ="*"&ROUND(SUMIFS(RoadTra_BY!P$2:P$79,RoadTra_BY!$B$2:$B$79,'Road transport'!$C38,RoadTra_BY!$C$2:$C$79,'Road transport'!$BA38),3) -> *0.38 | I38: ="*"&ROUND(SUMIFS(RoadTra_BY!Q$2:Q$79,RoadTra_BY!$B$2:$B$79,'Road transport'!$C38,RoadTra_BY!$C$2:$C$79,'Road transport'!$BA38),3) -> *0.38 | J38: ="*"&ROUND(SUMIFS(RoadTra_BY!R$2:R$79,RoadTra_BY!$B$2:$B$79,'Road transport'!$C38,RoadTra_BY!$C$2:$C$79,'Road transport'!$BA38),3) -> *0.38 | K38: ="*"&ROUND(SUMIFS(RoadTra_BY!S$2:S$79,RoadTra_BY!$B$2:$B$79,'Road transport'!$C38,RoadTra_BY!$C$2:$C$79,'Road transport'!$BA38),3) -> *0.38 | ... AW38: ="*"&ROUND(SUMIFS(RoadTra_BY!BE$2:BE$79,RoadTra_BY!$B$2:$B$79,'Road transport'!$C38,RoadTra_BY!$C$2:$C$79,'Road transport'!$BA38),3) -> *0 | AX38: =SUBSTITUTE(SUBSTITUTE(BA38,"gsl",""),"dsl","")&"*" -> Trd_lcv_* | AZ38: =IFERROR(IF(FIND("gsl",BA38)>0,1,0),2) -> 2 | BA38: Trd_lcv_dsl
B48: ~TFM_UPD
B49: attribute | C49: value | D49: pset_ci | E49: pset_co | I49: tempering the Eff improvement in smaller Evs
B50: EFF | C50: *.5 | D50: TRDELC | E50: Trd_2w,Trd_3w
B53: ~TFM_INS
B54: attribute | C54: value | D54: pset_set | E54: attrib_cond | F54: cset_cn | G54: other_indexes | H54: pset_co | I54: pset_pn
B55: INVCOST | C55: 10 | D55: ELE | E55: -INVCOST | I55: -Util_Rep_Batt*
B56: FLO_FUNC | C56: 1 | F56: AuxStoIN | G56: TRAELC | H56: =F56 -> AuxStoIN | I56: Tra*
...

Sheet RoadTra_BY
A1: scenario | B1: attribute | C1: process | D1: commodity | E1: lim_type | F1: time_slice | G1: year | H1: commodity_group | I1: currency | J1: stage | K1: sow | L1: Africa_North | M1: Africa_Other | N1: Australia | O1: Austria | P1: Baltics | Q1: BeNeLux | R1: Brazil | S1: China | T1: CroSloven | U1: CzechSlovak | V1: France | W1: Germany | X1: GreeceCyp | Y1: HunRomBul | Z1: Iceland | AA1: India | AB1: Ireland | AC1: ItalyMal | AD1: Japan | AE1: LatAm | AF1: MidEast | AG1: NorthAm | AH1: Norway | AI1: Poland | AJ1: ROW | AK1: Russia | AL1: SaudiArabia | AM1: SouthAfrica | AN1: SpainPor | AO1: SweFinDen | AP1: Switzerland | AQ1: Turkey | AR1: UK | AS1: Ukraine | AT1: WestBalkans | AU1: year2
A2: BASE | B2: AF | C2: Trd_2w_elc | D2: - | E2: UP | F2: ANNUAL | G2: 2019 | H2: - | I2: - | J2: - | K2: - | L2: 7 | M2: 7 | N2: 7 | O2: 7 | P2: 7 | Q2: 7 | R2: 7 | S2: 7 | T2: 7 | U2: 7 | V2: 7 | W2: 7 | X2: 7 | Y2: 7 | Z2: 7 | AA2: 7 | AB2: 7 | AC2: 7 | AD2: 4 | AE2: 7 | AF2: 5 | AG2: 7 | AH2: 4 | AI2: 7 | AJ2: 7 | AK2: 3 | AL2: 7 | AM2: 7 | AN2: 6.5 | AO2: 7 | AP2: 7 | AQ2: 7 | AR2: 4 | AS2: 4 | AT2: 4 | AU2: -
A3: BASE | B3: AF | C3: Trd_2w_gsl | D3: - | E3: UP | F3: ANNUAL | G3: 2019 | H3: - | I3: - | J3: - | K3: - | L3: 7 | M3: 7 | N3: 7 | O3: 7 | P3: 7 | Q3: 7 | R3: 7 | S3: 7 | T3: 7 | U3: 7 | V3: 7 | W3: 7 | X3: 7 | Y3: 7 | Z3: 7 | AA3: 7 | AB3: 7 | AC3: 7 | AD3: 4 | AE3: 7 | AF3: 5 | AG3: 7 | AH3: 4 | AI3: 7 | AJ3: 7 | AK3: 3 | AL3: 7 | AM3: 7 | AN3: 6.5 | AO3: 7 | AP3: 7 | AQ3: 7 | AR3: 4 | AS3: 4 | AT3: 4 | AU3: -
A4: BASE | B4: AF | C4: Trd_3w_bdl | D4: - | E4: UP | F4: ANNUAL | G4: 2019 | H4: - | I4: - | J4: - | K4: - | L4: 15 | M4: 15 | N4: 15 | O4: 15 | P4: 15 | Q4: 15 | R4: 15 | S4: 15 | T4: 15 | U4: 15 | V4: 15 | W4: 15 | X4: 15 | Y4: 15 | Z4: 15 | AA4: 15 | AB4: 15 | AC4: 15 | AD4: 15 | AE4: 15 | AF4: 15 | AG4: 15 | AH4: 15 | AI4: 15 | AJ4: 15 | AK4: 15 | AL4: 15 | AM4: 15 | AN4: 20 | AO4: 15 | AP4: 15 | AQ4: 15 | AR4: 15 | AS4: 15 | AT4: 15 | AU4: -
A5: BASE | B5: AF | C5: Trd_3w_dsl | D5: - | E5: UP | F5: ANNUAL | G5: 2019 | H5: - | I5: - | J5: - | K5: - | L5: 15 | M5: 15 | N5: 15 | O5: 15 | P5: 15 | Q5: 15 | R5: 15 | S5: 15 | T5: 15 | U5: 15 | V5: 15 | W5: 15 | X5: 15 | Y5: 15 | Z5: 15 | AA5: 15 | AB5: 15 | AC5: 15 | AD5: 15 | AE5: 15 | AF5: 15 | AG5: 15 | AH5: 15 | AI5: 15 | AJ5: 15 | AK5: 15 | AL5: 15 | AM5: 15 | AN5: 20 | AO5: 15 | AP5: 15 | AQ5: 15 | AR5: 15 | AS5: 15 | AT5: 15 | AU5: -
A6: BASE | B6: AF | C6: Trd_3w_gsl | D6: - | E6: UP | F6: ANNUAL | G6: 2019 | H6: - | I6: - | J6: - | K6: - | L6: 15 | M6: 15 | N6: 15 | O6: 15 | P6: 15 | Q6: 15 | R6: 15 | S6: 15 | T6: 15 | U6: 15 | V6: 15 | W6: 15 | X6: 15 | Y6: 15 | Z6: 15 | AA6: 15 | AB6: 15 | AC6: 15 | AD6: 15 | AE6: 15 | AF6: 15 | AG6: 15 | AH6: 15 | AI6: 15 | AJ6: 15 | AK6: 15 | AL6: 15 | AM6: 15 | AN6: 20 | AO6: 15 | AP6: 15 | AQ6: 15 | AR6: 15 | AS6: 15 | AT6: 15 | AU6: -
A7: BASE | B7: AF | C7: Trd_bus_bdl | D7: - | E7: UP | F7: ANNUAL | G7: 2019 | H7: - | I7: - | J7: - | K7: - | L7: 35 | M7: 35 | N7: 35 | O7: 35 | P7: 35 | Q7: 35 | R7: 35 | S7: 35 | T7: 35 | U7: 35 | V7: 35 | W7: 35 | X7: 35 | Y7: 35 | Z7: 35 | AA7: 35 | AB7: 35 | AC7: 35 | AD7: 35 | AE7: 35 | AF7: 35 | AG7: 35 | AH7: 35 | AI7: 35 | AJ7: 35 | AK7: 35 | AL7: 35 | AM7: 35 | AN7: 35 | AO7: 35 | AP7: 35 | AQ7: 35 | AR7: 35 | AS7: 35 | AT7: 20 | AU7: -
A8: BASE | B8: AF | C8: Trd_bus_dsl | D8: - | E8: UP | F8: ANNUAL | G8: 2019 | H8: - | I8: - | J8: - | K8: - | L8: 35 | M8: 35 | N8: 35 | O8: 35 | P8: 35 | Q8: 35 | R8: 35 | S8: 35 | T8: 35 | U8: 35 | V8: 35 | W8: 35 | X8: 35 | Y8: 35 | Z8: 35 | AA8: 35 | AB8: 35 | AC8: 35 | AD8: 35 | AE8: 35 | AF8: 35 | AG8: 35 | AH8: 35 | AI8: 35 | AJ8: 35 | AK8: 35 | AL8: 35 | AM8: 35 | AN8: 35 | AO8: 35 | AP8: 35 | AQ8: 35 | AR8: 35 | AS8: 35 | AT8: 20 | AU8: -
A9: BASE | B9: AF | C9: Trd_bus_elc | D9: - | E9: UP | F9: ANNUAL | G9: 2019 | H9: - | I9: - | J9: - | K9: - | L9: 35 | M9: 35 | N9: 35 | O9: 35 | P9: 35 | Q9: 35 | R9: 35 | S9: 35 | T9: 35 | U9: 35 | V9: 35 | W9: 35 | X9: 35 | Y9: 35 | Z9: 35 | AA9: 35 | AB9: 35 | AC9: 35 | AD9: 35 | AE9: 35 | AF9: 35 | AG9: 35 | AH9: 35 | AI9: 35 | AJ9: 35 | AK9: 35 | AL9: 35 | AM9: 35 | AN9: 35 | AO9: 35 | AP9: 35 | AQ9: 35 | AR9: 35 | AS9: 35 | AT9: 20 | AU9: -
A10: BASE | B10: AF | C10: Trd_bus_eth | D10: - | E10: UP | F10: ANNUAL | G10: 2019 | H10: - | I10: - | J10: - | K10: - | L10: 35 | M10: 35 | N10: 35 | O10: 35 | P10: 35 | Q10: 35 | R10: 35 | S10: 35 | T10: 35 | U10: 35 | V10: 35 | W10: 35 | X10: 35 | Y10: 35 | Z10: 35 | AA10: 35 | AB10: 35 | AC10: 35 | AD10: 35 | AE10: 35 | AF10: 35 | AG10: 35 | AH10: 35 | AI10: 35 | AJ10: 35 | AK10: 35 | AL10: 35 | AM10: 35 | AN10: 35 | AO10: 35 | AP10: 35 | AQ10: 35 | AR10: 35 | AS10: 35 | AT10: 20 | AU10: -
A11: BASE | B11: AF | C11: Trd_bus_gsl | D11: - | E11: UP | F11: ANNUAL | G11: 2019 | H11: - | I11: - | J11: - | K11: - | L11: 35 | M11: 35 | N11: 35 | O11: 35 | P11: 35 | Q11: 35 | R11: 35 | S11: 35 | T11: 35 | U11: 35 | V11: 35 | W11: 35 | X11: 35 | Y11: 35 | Z11: 35 | AA11: 35 | AB11: 35 | AC11: 35 | AD11: 35 | AE11: 35 | AF11: 35 | AG11: 35 | AH11: 35 | AI11: 35 | AJ11: 35 | AK11: 35 | AL11: 35 | AM11: 35 | AN11: 35 | AO11: 35 | AP11: 35 | AQ11: 35 | AR11: 35 | AS11: 35 | AT11: 20 | AU11: -
A12: BASE | B12: AF | C12: Trd_bus_lpg | D12: - | E12: UP | F12: ANNUAL | G12: 2019 | H12: - | I12: - | J12: - | K12: - | L12: 35 | M12: 35 | N12: 35 | O12: 35 | P12: 35 | Q12: 35 | R12: 35 | S12: 35 | T12: 35 | U12: 35 | V12: 35 | W12: 35 | X12: 35 | Y12: 35 | Z12: 35 | AA12: 35 | AB12: 35 | AC12: 35 | AD12: 35 | AE12: 35 | AF12: 35 | AG12: 35 | AH12: 35 | AI12: 35 | AJ12: 35 | AK12: 35 | AL12: 35 | AM12: 35 | AN12: 35 | AO12: 35 | AP12: 35 | AQ12: 35 | AR12: 35 | AS12: 35 | AT12: 20 | AU12: -
A13: BASE | B13: AF | C13: Trd_bus_nga | D13: - | E13: UP | F13: ANNUAL | G13: 2019 | H13: - | I13: - | J13: - | K13: - | L13: 35 | M13: 35 | N13: 35 | O13: 35 | P13: 35 | Q13: 35 | R13: 35 | S13: 35 | T13: 35 | U13: 35 | V13: 35 | W13: 35 | X13: 35 | Y13: 35 | Z13: 35 | AA13: 35 | AB13: 35 | AC13: 35 | AD13: 35 | AE13: 35 | AF13: 35 | AG13: 35 | AH13: 35 | AI13: 35 | AJ13: 35 | AK13: 35 | AL13: 35 | AM13: 35 | AN13: 35 | AO13: 35 | AP13: 35 | AQ13: 35 | AR13: 35 | AS13: 35 | AT13: 20 | AU13: -
... A57: BASE | B57: EFF | C57: Trd_lcv_nga | D57: - | E57: - | F57: ANNUAL | G57: 2019 | H57: - | I57: - | J57: - | K57: - | L57: 0.32948443 | M57: 0.32948443 | N57: 0.32948443 | O57: 0.32948443 | P57: 0.32948443 | Q57: 0.32948443 | R57: 0.32948443 | S57: 0.32948443 | T57: 0.32948443 | U57: 0.32948443 | V57: 0.32948443 | W57: 0.32948443 | X57: 0.32948443 | Y57: 0.32948443 | Z57: 0.32948443 | AA57: 0.32948443 | AB57: 0.32948443 | AC57: 0.32948443 | AD57: 0.32948443 | AE57: 0.32948443 | AF57: 0.32948443 | AG57: 0.32948443 | AH57: 0.32948443 | AI57: 0.32948443 | AJ57: 0.32948443 | AK57: 0.32948443 | AL57: 0.32948443 | AM57: 0.32948443 | AN57: 0.32948443 | AO57: 0.32948443 | AP57: 0.32948443 | AQ57: 0.32948443 | AR57: 0.32948443 | AS57: 0.32948443 | AT57: 0.32948443 | AU57: -

Sheet added_EnergyUse_for_Manu
L4: ~TFM_UPD: attribute= INPUT | R4: ~TFM_UPD: attribute= INPUT | X4: ~TFM_UPD: attribute= INPUT | AD4: ~TFM_UPD: attribute= INPUT | AJ4: ~TFM_UPD: attribute= INPUT | AP4: ~TFM_UPD: attribute= INPUT | AV4: ~TFM_UPD: attribute= INPUT
