Workbook

Sheet reporting
E1: ~UC_Sets: R_E: AllRegions
E3: ~UC_T: UC_COMNET~repuc_unity~N
D4: uc_n | E4: region | F4: ='Selected scen drivers'!F1 -> 2019 | G4: ='Selected scen drivers'!G1 -> 2020 | H4: ='Selected scen drivers'!H1 -> 2025 | I4: ='Selected scen drivers'!I1 -> 2030 | J4: ='Selected scen drivers'!J1 -> 2035 | K4: ='Selected scen drivers'!K1 -> 2040 | L4: ='Selected scen drivers'!L1 -> 2045 | M4: ='Selected scen drivers'!M1 -> 2050 | ... AE4: ='Selected scen drivers'!AE1 -> \I: | AF4: uc_rhsrt~0
A5: 1 | B5: 1 | D5: =IFERROR("rep_"&VLOOKUP(B5,Classification!$U$5:$V$14,2,FALSE),"\I:") -> rep_GDP | E5: =IFERROR(VLOOKUP(A5,Classification!$A$4:$B$99,2,FALSE),"\I:") -> Africa_Other | F5: =SUMIFS('Selected scen drivers'!F$2:F$999,'Selected scen drivers'!$A$2:$A$999,reporting!$A5,'Selected scen drivers'!$B$2:$B$999,reporting!$B5) -> 3397.857 | G5: =SUMIFS('Selected scen drivers'!G$2:G$999,'Selected scen drivers'!$A$2:$A$999,reporting!$A5,'Selected scen drivers'!$B$2:$B$999,reporting!$B5) -> 3474.2031 | H5: =SUMIFS('Selected scen drivers'!H$2:H$999,'Selected scen drivers'!$A$2:$A$999,reporting!$A5,'Selected scen drivers'!$B$2:$B$999,reporting!$B5) -> 4245.2248 | I5: =SUMIFS('Selected scen drivers'!I$2:I$999,'Selected scen drivers'!$A$2:$A$999,reporting!$A5,'Selected scen drivers'!$B$2:$B$999,reporting!$B5) -> 5425.0474 | J5: =SUMIFS('Selected scen drivers'!J$2:J$999,'Selected scen drivers'!$A$2:$A$999,reporting!$A5,'Selected scen drivers'!$B$2:$B$999,reporting!$B5) -> 7084.6944 | K5: =SUMIFS('Selected scen drivers'!K$2:K$999,'Selected scen drivers'!$A$2:$A$999,reporting!$A5,'Selected scen drivers'!$B$2:$B$999,reporting!$B5) -> 9117.9122 | L5: =SUMIFS('Selected scen drivers'!L$2:L$999,'Selected scen drivers'!$A$2:$A$999,reporting!$A5,'Selected scen drivers'!$B$2:$B$999,reporting!$B5) -> 11656.747 | M5: =SUMIFS('Selected scen drivers'!M$2:M$999,'Selected scen drivers'!$A$2:$A$999,reporting!$A5,'Selected scen drivers'!$B$2:$B$999,reporting!$B5) -> 14824.248 | ... AE5: =SUMIFS('Selected scen drivers'!AE$2:AE$999,'Selected scen drivers'!$A$2:$A$999,reporting!$A5,'Selected scen drivers'!$B$2:$B$999,reporting!$B5) -> 0 | AF5: 2
A6: 1 | B6: 2 | D6: =IFERROR("rep_"&VLOOKUP(B6,Classification!$U$5:$V$14,2,FALSE),"\I:") -> rep_GDPAGR | E6: =IFERROR(VLOOKUP(A6,Classification!$A$4:$B$99,2,FALSE),"\I:") -> Africa_Other | F6: =SUMIFS('Selected scen drivers'!F$2:F$999,'Selected scen drivers'!$A$2:$A$999,reporting!$A6,'Selected scen drivers'!$B$2:$B$999,reporting!$B6) -> 791.76348 | G6: =SUMIFS('Selected scen drivers'!G$2:G$999,'Selected scen drivers'!$A$2:$A$999,reporting!$A6,'Selected scen drivers'!$B$2:$B$999,reporting!$B6) -> 812.01851 | H6: =SUMIFS('Selected scen drivers'!H$2:H$999,'Selected scen drivers'!$A$2:$A$999,reporting!$A6,'Selected scen drivers'!$B$2:$B$999,reporting!$B6) -> 951.88078 | I6: =SUMIFS('Selected scen drivers'!I$2:I$999,'Selected scen drivers'!$A$2:$A$999,reporting!$A6,'Selected scen drivers'!$B$2:$B$999,reporting!$B6) -> 1175.539 | J6: =SUMIFS('Selected scen drivers'!J$2:J$999,'Selected scen drivers'!$A$2:$A$999,reporting!$A6,'Selected scen drivers'!$B$2:$B$999,reporting!$B6) -> 1475.4991 | K6: =SUMIFS('Selected scen drivers'!K$2:K$999,'Selected scen drivers'!$A$2:$A$999,reporting!$A6,'Selected scen drivers'!$B$2:$B$999,reporting!$B6) -> 1819.0655 | L6: =SUMIFS('Selected scen drivers'!L$2:L$999,'Selected scen drivers'!$A$2:$A$999,reporting!$A6,'Selected scen drivers'!$B$2:$B$999,reporting!$B6) -> 2219.798 | M6: =SUMIFS('Selected scen drivers'!M$2:M$999,'Selected scen drivers'!$A$2:$A$999,reporting!$A6,'Selected scen drivers'!$B$2:$B$999,reporting!$B6) -> 2683.1018 | ... AE6: =SUMIFS('Selected scen drivers'!AE$2:AE$999,'Selected scen drivers'!$A$2:$A$999,reporting!$A6,'Selected scen drivers'!$B$2:$B$999,reporting!$B6) -> 0 | AF6: 2
A7: 1 | B7: 3 | D7: =IFERROR("rep_"&VLOOKUP(B7,Classification!$U$5:$V$14,2,FALSE),"\I:") -> rep_GDPIND | E7: =IFERROR(VLOOKUP(A7,Classification!$A$4:$B$99,2,FALSE),"\I:") -> Africa_Other | F7: =SUMIFS('Selected scen drivers'!F$2:F$999,'Selected scen drivers'!$A$2:$A$999,reporting!$A7,'Selected scen drivers'!$B$2:$B$999,reporting!$B7) -> 923.83924 | G7: =SUMIFS('Selected scen drivers'!G$2:G$999,'Selected scen drivers'!$A$2:$A$999,reporting!$A7,'Selected scen drivers'!$B$2:$B$999,reporting!$B7) -> 941.62527 | H7: =SUMIFS('Selected scen drivers'!H$2:H$999,'Selected scen drivers'!$A$2:$A$999,reporting!$A7,'Selected scen drivers'!$B$2:$B$999,reporting!$B7) -> 1171.0965 | I7: =SUMIFS('Selected scen drivers'!I$2:I$999,'Selected scen drivers'!$A$2:$A$999,reporting!$A7,'Selected scen drivers'!$B$2:$B$999,reporting!$B7) -> 1507.2619 | J7: =SUMIFS('Selected scen drivers'!J$2:J$999,'Selected scen drivers'!$A$2:$A$999,reporting!$A7,'Selected scen drivers'!$B$2:$B$999,reporting!$B7) -> 1985.9926 | K7: =SUMIFS('Selected scen drivers'!K$2:K$999,'Selected scen drivers'!$A$2:$A$999,reporting!$A7,'Selected scen drivers'!$B$2:$B$999,reporting!$B7) -> 2581.9862 | L7: =SUMIFS('Selected scen drivers'!L$2:L$999,'Selected scen drivers'!$A$2:$A$999,reporting!$A7,'Selected scen drivers'!$B$2:$B$999,reporting!$B7) -> 3336.6232 | M7: =SUMIFS('Selected scen drivers'!M$2:M$999,'Selected scen drivers'!$A$2:$A$999,reporting!$A7,'Selected scen drivers'!$B$2:$B$999,reporting!$B7) -> 4290.277 | ... AE7: =SUMIFS('Selected scen drivers'!AE$2:AE$999,'Selected scen drivers'!$A$2:$A$999,reporting!$A7,'Selected scen drivers'!$B$2:$B$999,reporting!$B7) -> 0 | AF7: 2
A8: 1 | B8: 7 | D8: =IFERROR("rep_"&VLOOKUP(B8,Classification!$U$5:$V$14,2,FALSE),"\I:") -> rep_GDPSER | E8: =IFERROR(VLOOKUP(A8,Classification!$A$4:$B$99,2,FALSE),"\I:") -> Africa_Other | F8: =SUMIFS('Selected scen drivers'!F$2:F$999,'Selected scen drivers'!$A$2:$A$999,reporting!$A8,'Selected scen drivers'!$B$2:$B$999,reporting!$B8) -> 1681.2763 | G8: =SUMIFS('Selected scen drivers'!G$2:G$999,'Selected scen drivers'!$A$2:$A$999,reporting!$A8,'Selected scen drivers'!$B$2:$B$999,reporting!$B8) -> 1713.1844 | H8: =SUMIFS('Selected scen drivers'!H$2:H$999,'Selected scen drivers'!$A$2:$A$999,reporting!$A8,'Selected scen drivers'!$B$2:$B$999,reporting!$B8) -> 2110.325 | I8: =SUMIFS('Selected scen drivers'!I$2:I$999,'Selected scen drivers'!$A$2:$A$999,reporting!$A8,'Selected scen drivers'!$B$2:$B$999,reporting!$B8) -> 2724.9262 | J8: =SUMIFS('Selected scen drivers'!J$2:J$999,'Selected scen drivers'!$A$2:$A$999,reporting!$A8,'Selected scen drivers'!$B$2:$B$999,reporting!$B8) -> 3598.6769 | K8: =SUMIFS('Selected scen drivers'!K$2:K$999,'Selected scen drivers'!$A$2:$A$999,reporting!$A8,'Selected scen drivers'!$B$2:$B$999,reporting!$B8) -> 4681.8771 | L8: =SUMIFS('Selected scen drivers'!L$2:L$999,'Selected scen drivers'!$A$2:$A$999,reporting!$A8,'Selected scen drivers'!$B$2:$B$999,reporting!$B8) -> 6050.1115 | M8: =SUMIFS('Selected scen drivers'!M$2:M$999,'Selected scen drivers'!$A$2:$A$999,reporting!$A8,'Selected scen drivers'!$B$2:$B$999,reporting!$B8) -> 7778.8484 | ... AE8: =SUMIFS('Selected scen drivers'!AE$2:AE$999,'Selected scen drivers'!$A$2:$A$999,reporting!$A8,'Selected scen drivers'!$B$2:$B$999,reporting!$B8) -> 0 | AF8: 2
A9: 1 | B9: 8 | D9: =IFERROR("rep_"&VLOOKUP(B9,Classification!$U$5:$V$14,2,FALSE),"\I:") -> rep_HOU | E9: =IFERROR(VLOOKUP(A9,Classification!$A$4:$B$99,2,FALSE),"\I:") -> Africa_Other | F9: =SUMIFS('Selected scen drivers'!F$2:F$999,'Selected scen drivers'!$A$2:$A$999,reporting!$A9,'Selected scen drivers'!$B$2:$B$999,reporting!$B9) -> 229.89291 | G9: =SUMIFS('Selected scen drivers'!G$2:G$999,'Selected scen drivers'!$A$2:$A$999,reporting!$A9,'Selected scen drivers'!$B$2:$B$999,reporting!$B9) -> 237.94849 | H9: =SUMIFS('Selected scen drivers'!H$2:H$999,'Selected scen drivers'!$A$2:$A$999,reporting!$A9,'Selected scen drivers'!$B$2:$B$999,reporting!$B9) -> 278.22643 | I9: =SUMIFS('Selected scen drivers'!I$2:I$999,'Selected scen drivers'!$A$2:$A$999,reporting!$A9,'Selected scen drivers'!$B$2:$B$999,reporting!$B9) -> 324.24794 | J9: =SUMIFS('Selected scen drivers'!J$2:J$999,'Selected scen drivers'!$A$2:$A$999,reporting!$A9,'Selected scen drivers'!$B$2:$B$999,reporting!$B9) -> 375.51842 | K9: =SUMIFS('Selected scen drivers'!K$2:K$999,'Selected scen drivers'!$A$2:$A$999,reporting!$A9,'Selected scen drivers'!$B$2:$B$999,reporting!$B9) -> 430.43821 | L9: =SUMIFS('Selected scen drivers'!L$2:L$999,'Selected scen drivers'!$A$2:$A$999,reporting!$A9,'Selected scen drivers'!$B$2:$B$999,reporting!$B9) -> 487.99063 | M9: =SUMIFS('Selected scen drivers'!M$2:M$999,'Selected scen drivers'!$A$2:$A$999,reporting!$A9,'Selected scen drivers'!$B$2:$B$999,reporting!$B9) -> 547.01868 | ... AE9: =SUMIFS('Selected scen drivers'!AE$2:AE$999,'Selected scen drivers'!$A$2:$A$999,reporting!$A9,'Selected scen drivers'!$B$2:$B$999,reporting!$B9) -> 0 | AF9: 2
A10: 1 | B10: 9 | D10: =IFERROR("rep_"&VLOOKUP(B10,Classification!$U$5:$V$14,2,FALSE),"\I:") -> rep_POP | E10: =IFERROR(VLOOKUP(A10,Classification!$A$4:$B$99,2,FALSE),"\I:") -> Africa_Other | F10: =SUMIFS('Selected scen drivers'!F$2:F$999,'Selected scen drivers'!$A$2:$A$999,reporting!$A10,'Selected scen drivers'!$B$2:$B$999,reporting!$B10) -> 1049.4934 | G10: =SUMIFS('Selected scen drivers'!G$2:G$999,'Selected scen drivers'!$A$2:$A$999,reporting!$A10,'Selected scen drivers'!$B$2:$B$999,reporting!$B10) -> 1079.2567 | H10: =SUMIFS('Selected scen drivers'!H$2:H$999,'Selected scen drivers'!$A$2:$A$999,reporting!$A10,'Selected scen drivers'!$B$2:$B$999,reporting!$B10) -> 1228.073 | I10: =SUMIFS('Selected scen drivers'!I$2:I$999,'Selected scen drivers'!$A$2:$A$999,reporting!$A10,'Selected scen drivers'!$B$2:$B$999,reporting!$B10) -> 1387.2035 | J10: =SUMIFS('Selected scen drivers'!J$2:J$999,'Selected scen drivers'!$A$2:$A$999,reporting!$A10,'Selected scen drivers'!$B$2:$B$999,reporting!$B10) -> 1553.5877 | K10: =SUMIFS('Selected scen drivers'!K$2:K$999,'Selected scen drivers'!$A$2:$A$999,reporting!$A10,'Selected scen drivers'!$B$2:$B$999,reporting!$B10) -> 1724.6084 | L10: =SUMIFS('Selected scen drivers'!L$2:L$999,'Selected scen drivers'!$A$2:$A$999,reporting!$A10,'Selected scen drivers'!$B$2:$B$999,reporting!$B10) -> 1897.3331 | M10: =SUMIFS('Selected scen drivers'!M$2:M$999,'Selected scen drivers'!$A$2:$A$999,reporting!$A10,'Selected scen drivers'!$B$2:$B$999,reporting!$B10) -> 2068.6845 | ... AE10: =SUMIFS('Selected scen drivers'!AE$2:AE$999,'Selected scen drivers'!$A$2:$A$999,reporting!$A10,'Selected scen drivers'!$B$2:$B$999,reporting!$B10) -> 0 | AF10: 2
A11: =A5+1 -> 2 | B11: =B5 -> 1 | D11: =IFERROR("rep_"&VLOOKUP(B11,Classification!$U$5:$V$14,2,FALSE),"\I:") -> rep_GDP | E11: =IFERROR(VLOOKUP(A11,Classification!$A$4:$B$99,2,FALSE),"\I:") -> India | F11: =SUMIFS('Selected scen drivers'!F$2:F$999,'Selected scen drivers'!$A$2:$A$999,reporting!$A11,'Selected scen drivers'!$B$2:$B$999,reporting!$B11) -> 8195.484 | G11: =SUMIFS('Selected scen drivers'!G$2:G$999,'Selected scen drivers'!$A$2:$A$999,reporting!$A11,'Selected scen drivers'!$B$2:$B$999,reporting!$B11) -> 8503.83 | H11: =SUMIFS('Selected scen drivers'!H$2:H$999,'Selected scen drivers'!$A$2:$A$999,reporting!$A11,'Selected scen drivers'!$B$2:$B$999,reporting!$B11) -> 11852.9 | I11: =SUMIFS('Selected scen drivers'!I$2:I$999,'Selected scen drivers'!$A$2:$A$999,reporting!$A11,'Selected scen drivers'!$B$2:$B$999,reporting!$B11) -> 15709.5 | J11: =SUMIFS('Selected scen drivers'!J$2:J$999,'Selected scen drivers'!$A$2:$A$999,reporting!$A11,'Selected scen drivers'!$B$2:$B$999,reporting!$B11) -> 19813.1 | K11: =SUMIFS('Selected scen drivers'!K$2:K$999,'Selected scen drivers'!$A$2:$A$999,reporting!$A11,'Selected scen drivers'!$B$2:$B$999,reporting!$B11) -> 24247.7 | L11: =SUMIFS('Selected scen drivers'!L$2:L$999,'Selected scen drivers'!$A$2:$A$999,reporting!$A11,'Selected scen drivers'!$B$2:$B$999,reporting!$B11) -> 29018.4 | M11: =SUMIFS('Selected scen drivers'!M$2:M$999,'Selected scen drivers'!$A$2:$A$999,reporting!$A11,'Selected scen drivers'!$B$2:$B$999,reporting!$B11) -> 34135.9 | ... AE11: =SUMIFS('Selected scen drivers'!AE$2:AE$999,'Selected scen drivers'!$A$2:$A$999,reporting!$A11,'Selected scen drivers'!$B$2:$B$999,reporting!$B11) -> 0 | AF11: 2
A12: =A6+1 -> 2 | B12: =B6 -> 2 | D12: =IFERROR("rep_"&VLOOKUP(B12,Classification!$U$5:$V$14,2,FALSE),"\I:") -> rep_GDPAGR | E12: =IFERROR(VLOOKUP(A12,Classification!$A$4:$B$99,2,FALSE),"\I:") -> India | F12: =SUMIFS('Selected scen drivers'!F$2:F$999,'Selected scen drivers'!$A$2:$A$999,reporting!$A12,'Selected scen drivers'!$B$2:$B$999,reporting!$B12) -> 1281.0098 | G12: =SUMIFS('Selected scen drivers'!G$2:G$999,'Selected scen drivers'!$A$2:$A$999,reporting!$A12,'Selected scen drivers'!$B$2:$B$999,reporting!$B12) -> 1329.2063 | H12: =SUMIFS('Selected scen drivers'!H$2:H$999,'Selected scen drivers'!$A$2:$A$999,reporting!$A12,'Selected scen drivers'!$B$2:$B$999,reporting!$B12) -> 1792.4561 | I12: =SUMIFS('Selected scen drivers'!I$2:I$999,'Selected scen drivers'!$A$2:$A$999,reporting!$A12,'Selected scen drivers'!$B$2:$B$999,reporting!$B12) -> 2295.8404 | J12: =SUMIFS('Selected scen drivers'!J$2:J$999,'Selected scen drivers'!$A$2:$A$999,reporting!$A12,'Selected scen drivers'!$B$2:$B$999,reporting!$B12) -> 2794.8708 | K12: =SUMIFS('Selected scen drivers'!K$2:K$999,'Selected scen drivers'!$A$2:$A$999,reporting!$A12,'Selected scen drivers'!$B$2:$B$999,reporting!$B12) -> 3297.2044 | L12: =SUMIFS('Selected scen drivers'!L$2:L$999,'Selected scen drivers'!$A$2:$A$999,reporting!$A12,'Selected scen drivers'!$B$2:$B$999,reporting!$B12) -> 3798.4626 | M12: =SUMIFS('Selected scen drivers'!M$2:M$999,'Selected scen drivers'!$A$2:$A$999,reporting!$A12,'Selected scen drivers'!$B$2:$B$999,reporting!$B12) -> 4294.8677 | ... AE12: =SUMIFS('Selected scen drivers'!AE$2:AE$999,'Selected scen drivers'!$A$2:$A$999,reporting!$A12,'Selected scen drivers'!$B$2:$B$999,reporting!$B12) -> 0 | AF12: 2
A13: =A7+1 -> 2 | B13: =B7 -> 3 | D13: =IFERROR("rep_"&VLOOKUP(B13,Classification!$U$5:$V$14,2,FALSE),"\I:") -> rep_GDPIND | E13: =IFERROR(VLOOKUP(A13,Classification!$A$4:$B$99,2,FALSE),"\I:") -> India | F13: =SUMIFS('Selected scen drivers'!F$2:F$999,'Selected scen drivers'!$A$2:$A$999,reporting!$A13,'Selected scen drivers'!$B$2:$B$999,reporting!$B13) -> 2424.8263 | G13: =SUMIFS('Selected scen drivers'!G$2:G$999,'Selected scen drivers'!$A$2:$A$999,reporting!$A13,'Selected scen drivers'!$B$2:$B$999,reporting!$B13) -> 2516.0577 | H13: =SUMIFS('Selected scen drivers'!H$2:H$999,'Selected scen drivers'!$A$2:$A$999,reporting!$A13,'Selected scen drivers'!$B$2:$B$999,reporting!$B13) -> 3510.0156 | I13: =SUMIFS('Selected scen drivers'!I$2:I$999,'Selected scen drivers'!$A$2:$A$999,reporting!$A13,'Selected scen drivers'!$B$2:$B$999,reporting!$B13) -> 4656.1275 | J13: =SUMIFS('Selected scen drivers'!J$2:J$999,'Selected scen drivers'!$A$2:$A$999,reporting!$A13,'Selected scen drivers'!$B$2:$B$999,reporting!$B13) -> 5877.5005 | K13: =SUMIFS('Selected scen drivers'!K$2:K$999,'Selected scen drivers'!$A$2:$A$999,reporting!$A13,'Selected scen drivers'!$B$2:$B$999,reporting!$B13) -> 7199.2658 | L13: =SUMIFS('Selected scen drivers'!L$2:L$999,'Selected scen drivers'!$A$2:$A$999,reporting!$A13,'Selected scen drivers'!$B$2:$B$999,reporting!$B13) -> 8623.1951 | M13: =SUMIFS('Selected scen drivers'!M$2:M$999,'Selected scen drivers'!$A$2:$A$999,reporting!$A13,'Selected scen drivers'!$B$2:$B$999,reporting!$B13) -> 10152.731 | ... AE13: =SUMIFS('Selected scen drivers'!AE$2:AE$999,'Selected scen drivers'!$A$2:$A$999,reporting!$A13,'Selected scen drivers'!$B$2:$B$999,reporting!$B13) -> 0 | AF13: 2
A14: =A8+1 -> 2 | B14: =B8 -> 7 | D14: =IFERROR("rep_"&VLOOKUP(B14,Classification!$U$5:$V$14,2,FALSE),"\I:") -> rep_GDPSER | E14: =IFERROR(VLOOKUP(A14,Classification!$A$4:$B$99,2,FALSE),"\I:") -> India | F14: =SUMIFS('Selected scen drivers'!F$2:F$999,'Selected scen drivers'!$A$2:$A$999,reporting!$A14,'Selected scen drivers'!$B$2:$B$999,reporting!$B14) -> 4489.648 | G14: =SUMIFS('Selected scen drivers'!G$2:G$999,'Selected scen drivers'!$A$2:$A$999,reporting!$A14,'Selected scen drivers'!$B$2:$B$999,reporting!$B14) -> 4658.566 | H14: =SUMIFS('Selected scen drivers'!H$2:H$999,'Selected scen drivers'!$A$2:$A$999,reporting!$A14,'Selected scen drivers'!$B$2:$B$999,reporting!$B14) -> 6550.4283 | I14: =SUMIFS('Selected scen drivers'!I$2:I$999,'Selected scen drivers'!$A$2:$A$999,reporting!$A14,'Selected scen drivers'!$B$2:$B$999,reporting!$B14) -> 8757.5322 | J14: =SUMIFS('Selected scen drivers'!J$2:J$999,'Selected scen drivers'!$A$2:$A$999,reporting!$A14,'Selected scen drivers'!$B$2:$B$999,reporting!$B14) -> 11140.729 | K14: =SUMIFS('Selected scen drivers'!K$2:K$999,'Selected scen drivers'!$A$2:$A$999,reporting!$A14,'Selected scen drivers'!$B$2:$B$999,reporting!$B14) -> 13751.23 | L14: =SUMIFS('Selected scen drivers'!L$2:L$999,'Selected scen drivers'!$A$2:$A$999,reporting!$A14,'Selected scen drivers'!$B$2:$B$999,reporting!$B14) -> 16596.742 | M14: =SUMIFS('Selected scen drivers'!M$2:M$999,'Selected scen drivers'!$A$2:$A$999,reporting!$A14,'Selected scen drivers'!$B$2:$B$999,reporting!$B14) -> 19688.302 | ... AE14: =SUMIFS('Selected scen drivers'!AE$2:AE$999,'Selected scen drivers'!$A$2:$A$999,reporting!$A14,'Selected scen drivers'!$B$2:$B$999,reporting!$B14) -> 0 | AF14: 2
A15: =A9+1 -> 2 | B15: =B9 -> 8 | D15: =IFERROR("rep_"&VLOOKUP(B15,Classification!$U$5:$V$14,2,FALSE),"\I:") -> rep_HOU | E15: =IFERROR(VLOOKUP(A15,Classification!$A$4:$B$99,2,FALSE),"\I:") -> India | F15: =SUMIFS('Selected scen drivers'!F$2:F$999,'Selected scen drivers'!$A$2:$A$999,reporting!$A15,'Selected scen drivers'!$B$2:$B$999,reporting!$B15) -> 400.06803 | G15: =SUMIFS('Selected scen drivers'!G$2:G$999,'Selected scen drivers'!$A$2:$A$999,reporting!$A15,'Selected scen drivers'!$B$2:$B$999,reporting!$B15) -> 405.79446 | H15: =SUMIFS('Selected scen drivers'!H$2:H$999,'Selected scen drivers'!$A$2:$A$999,reporting!$A15,'Selected scen drivers'!$B$2:$B$999,reporting!$B15) -> 434.42666 | I15: =SUMIFS('Selected scen drivers'!I$2:I$999,'Selected scen drivers'!$A$2:$A$999,reporting!$A15,'Selected scen drivers'!$B$2:$B$999,reporting!$B15) -> 461.41704 | J15: =SUMIFS('Selected scen drivers'!J$2:J$999,'Selected scen drivers'!$A$2:$A$999,reporting!$A15,'Selected scen drivers'!$B$2:$B$999,reporting!$B15) -> 482.37817 | K15: =SUMIFS('Selected scen drivers'!K$2:K$999,'Selected scen drivers'!$A$2:$A$999,reporting!$A15,'Selected scen drivers'!$B$2:$B$999,reporting!$B15) -> 496.38372 | L15: =SUMIFS('Selected scen drivers'!L$2:L$999,'Selected scen drivers'!$A$2:$A$999,reporting!$A15,'Selected scen drivers'!$B$2:$B$999,reporting!$B15) -> 504.36066 | M15: =SUMIFS('Selected scen drivers'!M$2:M$999,'Selected scen drivers'!$A$2:$A$999,reporting!$A15,'Selected scen drivers'!$B$2:$B$999,reporting!$B15) -> 504.71485 | ... AE15: =SUMIFS('Selected scen drivers'!AE$2:AE$999,'Selected scen drivers'!$A$2:$A$999,reporting!$A15,'Selected scen drivers'!$B$2:$B$999,reporting!$B15) -> 0 | AF15: 2
A16: =A10+1 -> 2 | B16: =B10 -> 9 | D16: =IFERROR("rep_"&VLOOKUP(B16,Classification!$U$5:$V$14,2,FALSE),"\I:") -> rep_POP | E16: =IFERROR(VLOOKUP(A16,Classification!$A$4:$B$99,2,FALSE),"\I:") -> India | F16: =SUMIFS('Selected scen drivers'!F$2:F$999,'Selected scen drivers'!$A$2:$A$999,reporting!$A16,'Selected scen drivers'!$B$2:$B$999,reporting!$B16) -> 1378.8638 | G16: =SUMIFS('Selected scen drivers'!G$2:G$999,'Selected scen drivers'!$A$2:$A$999,reporting!$A16,'Selected scen drivers'!$B$2:$B$999,reporting!$B16) -> 1389.9664 | H16: =SUMIFS('Selected scen drivers'!H$2:H$999,'Selected scen drivers'!$A$2:$A$999,reporting!$A16,'Selected scen drivers'!$B$2:$B$999,reporting!$B16) -> 1445.4796 | I16: =SUMIFS('Selected scen drivers'!I$2:I$999,'Selected scen drivers'!$A$2:$A$999,reporting!$A16,'Selected scen drivers'!$B$2:$B$999,reporting!$B16) -> 1501.7254 | J16: =SUMIFS('Selected scen drivers'!J$2:J$999,'Selected scen drivers'!$A$2:$A$999,reporting!$A16,'Selected scen drivers'!$B$2:$B$999,reporting!$B16) -> 1548.0675 | K16: =SUMIFS('Selected scen drivers'!K$2:K$999,'Selected scen drivers'!$A$2:$A$999,reporting!$A16,'Selected scen drivers'!$B$2:$B$999,reporting!$B16) -> 1583.687 | L16: =SUMIFS('Selected scen drivers'!L$2:L$999,'Selected scen drivers'!$A$2:$A$999,reporting!$A16,'Selected scen drivers'!$B$2:$B$999,reporting!$B16) -> 1607.6946 | M16: =SUMIFS('Selected scen drivers'!M$2:M$999,'Selected scen drivers'!$A$2:$A$999,reporting!$A16,'Selected scen drivers'!$B$2:$B$999,reporting!$B16) -> 1620.3579 | ... AE16: =SUMIFS('Selected scen drivers'!AE$2:AE$999,'Selected scen drivers'!$A$2:$A$999,reporting!$A16,'Selected scen drivers'!$B$2:$B$999,reporting!$B16) -> 0 | AF16: 2
A17: =A11+1 -> 3 | B17: =B11 -> 1 | D17: =IFERROR("rep_"&VLOOKUP(B17,Classification!$U$5:$V$14,2,FALSE),"\I:") -> rep_GDP | E17: =IFERROR(VLOOKUP(A17,Classification!$A$4:$B$99,2,FALSE),"\I:") -> ROW | F17: =SUMIFS('Selected scen drivers'!F$2:F$999,'Selected scen drivers'!$A$2:$A$999,reporting!$A17,'Selected scen drivers'!$B$2:$B$999,reporting!$B17) -> 15477.272 | G17: =SUMIFS('Selected scen drivers'!G$2:G$999,'Selected scen drivers'!$A$2:$A$999,reporting!$A17,'Selected scen drivers'!$B$2:$B$999,reporting!$B17) -> 15975.795 | H17: =SUMIFS('Selected scen drivers'!H$2:H$999,'Selected scen drivers'!$A$2:$A$999,reporting!$A17,'Selected scen drivers'!$B$2:$B$999,reporting!$B17) -> 19505.512 | I17: =SUMIFS('Selected scen drivers'!I$2:I$999,'Selected scen drivers'!$A$2:$A$999,reporting!$A17,'Selected scen drivers'!$B$2:$B$999,reporting!$B17) -> 23929.64 | J17: =SUMIFS('Selected scen drivers'!J$2:J$999,'Selected scen drivers'!$A$2:$A$999,reporting!$A17,'Selected scen drivers'!$B$2:$B$999,reporting!$B17) -> 28577.615 | K17: =SUMIFS('Selected scen drivers'!K$2:K$999,'Selected scen drivers'!$A$2:$A$999,reporting!$A17,'Selected scen drivers'!$B$2:$B$999,reporting!$B17) -> 33215.021 | L17: =SUMIFS('Selected scen drivers'!L$2:L$999,'Selected scen drivers'!$A$2:$A$999,reporting!$A17,'Selected scen drivers'!$B$2:$B$999,reporting!$B17) -> 37953.093 | M17: =SUMIFS('Selected scen drivers'!M$2:M$999,'Selected scen drivers'!$A$2:$A$999,reporting!$A17,'Selected scen drivers'!$B$2:$B$999,reporting!$B17) -> 42873.651 | ... AE17: =SUMIFS('Selected scen drivers'!AE$2:AE$999,'Selected scen drivers'!$A$2:$A$999,reporting!$A17,'Selected scen drivers'!$B$2:$B$999,reporting!$B17) -> 0 | AF17: 2
A18: =A12+1 -> 3 | B18: =B12 -> 2 | D18: =IFERROR("rep_"&VLOOKUP(B18,Classification!$U$5:$V$14,2,FALSE),"\I:") -> rep_GDPAGR | E18: =IFERROR(VLOOKUP(A18,Classification!$A$4:$B$99,2,FALSE),"\I:") -> ROW | F18: =SUMIFS('Selected scen drivers'!F$2:F$999,'Selected scen drivers'!$A$2:$A$999,reporting!$A18,'Selected scen drivers'!$B$2:$B$999,reporting!$B18) -> 1525.5622 | G18: =SUMIFS('Selected scen drivers'!G$2:G$999,'Selected scen drivers'!$A$2:$A$999,reporting!$A18,'Selected scen drivers'!$B$2:$B$999,reporting!$B18) -> 1580.5538 | H18: =SUMIFS('Selected scen drivers'!H$2:H$999,'Selected scen drivers'!$A$2:$A$999,reporting!$A18,'Selected scen drivers'!$B$2:$B$999,reporting!$B18) -> 1906.7277 | I18: =SUMIFS('Selected scen drivers'!I$2:I$999,'Selected scen drivers'!$A$2:$A$999,reporting!$A18,'Selected scen drivers'!$B$2:$B$999,reporting!$B18) -> 2359.0161 | J18: =SUMIFS('Selected scen drivers'!J$2:J$999,'Selected scen drivers'!$A$2:$A$999,reporting!$A18,'Selected scen drivers'!$B$2:$B$999,reporting!$B18) -> 2838.3421 | K18: =SUMIFS('Selected scen drivers'!K$2:K$999,'Selected scen drivers'!$A$2:$A$999,reporting!$A18,'Selected scen drivers'!$B$2:$B$999,reporting!$B18) -> 3317.9569 | L18: =SUMIFS('Selected scen drivers'!L$2:L$999,'Selected scen drivers'!$A$2:$A$999,reporting!$A18,'Selected scen drivers'!$B$2:$B$999,reporting!$B18) -> 3799.6144 | M18: =SUMIFS('Selected scen drivers'!M$2:M$999,'Selected scen drivers'!$A$2:$A$999,reporting!$A18,'Selected scen drivers'!$B$2:$B$999,reporting!$B18) -> 4282.6153 | ... AE18: =SUMIFS('Selected scen drivers'!AE$2:AE$999,'Selected scen drivers'!$A$2:$A$999,reporting!$A18,'Selected scen drivers'!$B$2:$B$999,reporting!$B18) -> 0 | AF18: 2
A19: =A13+1 -> 3 | B19: =B13 -> 3 | D19: =IFERROR("rep_"&VLOOKUP(B19,Classification!$U$5:$V$14,2,FALSE),"\I:") -> rep_GDPIND | E19: =IFERROR(VLOOKUP(A19,Classification!$A$4:$B$99,2,FALSE),"\I:") -> ROW | F19: =SUMIFS('Selected scen drivers'!F$2:F$999,'Selected scen drivers'!$A$2:$A$999,reporting!$A19,'Selected scen drivers'!$B$2:$B$999,reporting!$B19) -> 4871.5708 | G19: =SUMIFS('Selected scen drivers'!G$2:G$999,'Selected scen drivers'!$A$2:$A$999,reporting!$A19,'Selected scen drivers'!$B$2:$B$999,reporting!$B19) -> 5020.6249 | H19: =SUMIFS('Selected scen drivers'!H$2:H$999,'Selected scen drivers'!$A$2:$A$999,reporting!$A19,'Selected scen drivers'!$B$2:$B$999,reporting!$B19) -> 6179.2946 | I19: =SUMIFS('Selected scen drivers'!I$2:I$999,'Selected scen drivers'!$A$2:$A$999,reporting!$A19,'Selected scen drivers'!$B$2:$B$999,reporting!$B19) -> 7642.0543 | J19: =SUMIFS('Selected scen drivers'!J$2:J$999,'Selected scen drivers'!$A$2:$A$999,reporting!$A19,'Selected scen drivers'!$B$2:$B$999,reporting!$B19) -> 9197.4829 | K19: =SUMIFS('Selected scen drivers'!K$2:K$999,'Selected scen drivers'!$A$2:$A$999,reporting!$A19,'Selected scen drivers'!$B$2:$B$999,reporting!$B19) -> 10770.862 | L19: =SUMIFS('Selected scen drivers'!L$2:L$999,'Selected scen drivers'!$A$2:$A$999,reporting!$A19,'Selected scen drivers'!$B$2:$B$999,reporting!$B19) -> 12380.935 | M19: =SUMIFS('Selected scen drivers'!M$2:M$999,'Selected scen drivers'!$A$2:$A$999,reporting!$A19,'Selected scen drivers'!$B$2:$B$999,reporting!$B19) -> 14045.713 | ... AE19: =SUMIFS('Selected scen drivers'!AE$2:AE$999,'Selected scen drivers'!$A$2:$A$999,reporting!$A19,'Selected scen drivers'!$B$2:$B$999,reporting!$B19) -> 0 | AF19: 2
A20: =A14+1 -> 3 | B20: =B14 -> 7 | D20: =IFERROR("rep_"&VLOOKUP(B20,Classification!$U$5:$V$14,2,FALSE),"\I:") -> rep_GDPSER | E20: =IFERROR(VLOOKUP(A20,Classification!$A$4:$B$99,2,FALSE),"\I:") -> ROW | F20: =SUMIFS('Selected scen drivers'!F$2:F$999,'Selected scen drivers'!$A$2:$A$999,reporting!$A20,'Selected scen drivers'!$B$2:$B$999,reporting!$B20) -> 7848.9724 | G20: =SUMIFS('Selected scen drivers'!G$2:G$999,'Selected scen drivers'!$A$2:$A$999,reporting!$A20,'Selected scen drivers'!$B$2:$B$999,reporting!$B20) -> 8062.1227 | H20: =SUMIFS('Selected scen drivers'!H$2:H$999,'Selected scen drivers'!$A$2:$A$999,reporting!$A20,'Selected scen drivers'!$B$2:$B$999,reporting!$B20) -> 9887.9905 | I20: =SUMIFS('Selected scen drivers'!I$2:I$999,'Selected scen drivers'!$A$2:$A$999,reporting!$A20,'Selected scen drivers'!$B$2:$B$999,reporting!$B20) -> 12200.26 | J20: =SUMIFS('Selected scen drivers'!J$2:J$999,'Selected scen drivers'!$A$2:$A$999,reporting!$A20,'Selected scen drivers'!$B$2:$B$999,reporting!$B20) -> 14683.491 | K20: =SUMIFS('Selected scen drivers'!K$2:K$999,'Selected scen drivers'!$A$2:$A$999,reporting!$A20,'Selected scen drivers'!$B$2:$B$999,reporting!$B20) -> 17220.071 | L20: =SUMIFS('Selected scen drivers'!L$2:L$999,'Selected scen drivers'!$A$2:$A$999,reporting!$A20,'Selected scen drivers'!$B$2:$B$999,reporting!$B20) -> 19864.986 | M20: =SUMIFS('Selected scen drivers'!M$2:M$999,'Selected scen drivers'!$A$2:$A$999,reporting!$A20,'Selected scen drivers'!$B$2:$B$999,reporting!$B20) -> 22658.139 | ... AE20: =SUMIFS('Selected scen drivers'!AE$2:AE$999,'Selected scen drivers'!$A$2:$A$999,reporting!$A20,'Selected scen drivers'!$B$2:$B$999,reporting!$B20) -> 0 | AF20: 2
A21: =A15+1 -> 3 | B21: =B15 -> 8 | D21: =IFERROR("rep_"&VLOOKUP(B21,Classification!$U$5:$V$14,2,FALSE),"\I:") -> rep_HOU | E21: =IFERROR(VLOOKUP(A21,Classification!$A$4:$B$99,2,FALSE),"\I:") -> ROW | F21: =SUMIFS('Selected scen drivers'!F$2:F$999,'Selected scen drivers'!$A$2:$A$999,reporting!$A21,'Selected scen drivers'!$B$2:$B$999,reporting!$B21) -> 386.54955 | G21: =SUMIFS('Selected scen drivers'!G$2:G$999,'Selected scen drivers'!$A$2:$A$999,reporting!$A21,'Selected scen drivers'!$B$2:$B$999,reporting!$B21) -> 391.56712 | H21: =SUMIFS('Selected scen drivers'!H$2:H$999,'Selected scen drivers'!$A$2:$A$999,reporting!$A21,'Selected scen drivers'!$B$2:$B$999,reporting!$B21) -> 416.65495 | I21: =SUMIFS('Selected scen drivers'!I$2:I$999,'Selected scen drivers'!$A$2:$A$999,reporting!$A21,'Selected scen drivers'!$B$2:$B$999,reporting!$B21) -> 439.606 | J21: =SUMIFS('Selected scen drivers'!J$2:J$999,'Selected scen drivers'!$A$2:$A$999,reporting!$A21,'Selected scen drivers'!$B$2:$B$999,reporting!$B21) -> 460.29195 | K21: =SUMIFS('Selected scen drivers'!K$2:K$999,'Selected scen drivers'!$A$2:$A$999,reporting!$A21,'Selected scen drivers'!$B$2:$B$999,reporting!$B21) -> 478.61903 | L21: =SUMIFS('Selected scen drivers'!L$2:L$999,'Selected scen drivers'!$A$2:$A$999,reporting!$A21,'Selected scen drivers'!$B$2:$B$999,reporting!$B21) -> 493.8302 | M21: =SUMIFS('Selected scen drivers'!M$2:M$999,'Selected scen drivers'!$A$2:$A$999,reporting!$A21,'Selected scen drivers'!$B$2:$B$999,reporting!$B21) -> 504.11923 | ... AE21: =SUMIFS('Selected scen drivers'!AE$2:AE$999,'Selected scen drivers'!$A$2:$A$999,reporting!$A21,'Selected scen drivers'!$B$2:$B$999,reporting!$B21) -> 0 | AF21: 2
A22: =A16+1 -> 3 | B22: =B16 -> 9 | D22: =IFERROR("rep_"&VLOOKUP(B22,Classification!$U$5:$V$14,2,FALSE),"\I:") -> rep_POP | E22: =IFERROR(VLOOKUP(A22,Classification!$A$4:$B$99,2,FALSE),"\I:") -> ROW | F22: =SUMIFS('Selected scen drivers'!F$2:F$999,'Selected scen drivers'!$A$2:$A$999,reporting!$A22,'Selected scen drivers'!$B$2:$B$999,reporting!$B22) -> 1354.5919 | G22: =SUMIFS('Selected scen drivers'!G$2:G$999,'Selected scen drivers'!$A$2:$A$999,reporting!$A22,'Selected scen drivers'!$B$2:$B$999,reporting!$B22) -> 1369.7712 | H22: =SUMIFS('Selected scen drivers'!H$2:H$999,'Selected scen drivers'!$A$2:$A$999,reporting!$A22,'Selected scen drivers'!$B$2:$B$999,reporting!$B22) -> 1445.6675 | I22: =SUMIFS('Selected scen drivers'!I$2:I$999,'Selected scen drivers'!$A$2:$A$999,reporting!$A22,'Selected scen drivers'!$B$2:$B$999,reporting!$B22) -> 1518.1914 | J22: =SUMIFS('Selected scen drivers'!J$2:J$999,'Selected scen drivers'!$A$2:$A$999,reporting!$A22,'Selected scen drivers'!$B$2:$B$999,reporting!$B22) -> 1583.2546 | K22: =SUMIFS('Selected scen drivers'!K$2:K$999,'Selected scen drivers'!$A$2:$A$999,reporting!$A22,'Selected scen drivers'!$B$2:$B$999,reporting!$B22) -> 1640.1301 | L22: =SUMIFS('Selected scen drivers'!L$2:L$999,'Selected scen drivers'!$A$2:$A$999,reporting!$A22,'Selected scen drivers'!$B$2:$B$999,reporting!$B22) -> 1688.7147 | M22: =SUMIFS('Selected scen drivers'!M$2:M$999,'Selected scen drivers'!$A$2:$A$999,reporting!$A22,'Selected scen drivers'!$B$2:$B$999,reporting!$B22) -> 1729.377 | ... AE22: =SUMIFS('Selected scen drivers'!AE$2:AE$999,'Selected scen drivers'!$A$2:$A$999,reporting!$A22,'Selected scen drivers'!$B$2:$B$999,reporting!$B22) -> 0 | AF22: 2
... A280: =A274+1 -> 46 | B280: =B274 -> 9 | D280: =IFERROR("rep_"&VLOOKUP(B280,Classification!$U$5:$V$14,2,FALSE),"\I:") -> rep_POP | E280: =IFERROR(VLOOKUP(A280,Classification!$A$4:$B$99,2,FALSE),"\I:") -> \I: | F280: =SUMIFS('Selected scen drivers'!F$2:F$999,'Selected scen drivers'!$A$2:$A$999,reporting!$A280,'Selected scen drivers'!$B$2:$B$999,reporting!$B280) -> 0 | G280: =SUMIFS('Selected scen drivers'!G$2:G$999,'Selected scen drivers'!$A$2:$A$999,reporting!$A280,'Selected scen drivers'!$B$2:$B$999,reporting!$B280) -> 0 | H280: =SUMIFS('Selected scen drivers'!H$2:H$999,'Selected scen drivers'!$A$2:$A$999,reporting!$A280,'Selected scen drivers'!$B$2:$B$999,reporting!$B280) -> 0 | I280: =SUMIFS('Selected scen drivers'!I$2:I$999,'Selected scen drivers'!$A$2:$A$999,reporting!$A280,'Selected scen drivers'!$B$2:$B$999,reporting!$B280) -> 0 | J280: =SUMIFS('Selected scen drivers'!J$2:J$999,'Selected scen drivers'!$A$2:$A$999,reporting!$A280,'Selected scen drivers'!$B$2:$B$999,reporting!$B280) -> 0 | K280: =SUMIFS('Selected scen drivers'!K$2:K$999,'Selected scen drivers'!$A$2:$A$999,reporting!$A280,'Selected scen drivers'!$B$2:$B$999,reporting!$B280) -> 0 | L280: =SUMIFS('Selected scen drivers'!L$2:L$999,'Selected scen drivers'!$A$2:$A$999,reporting!$A280,'Selected scen drivers'!$B$2:$B$999,reporting!$B280) -> 0 | M280: =SUMIFS('Selected scen drivers'!M$2:M$999,'Selected scen drivers'!$A$2:$A$999,reporting!$A280,'Selected scen drivers'!$B$2:$B$999,reporting!$B280) -> 0 | ... AE280: =SUMIFS('Selected scen drivers'!AE$2:AE$999,'Selected scen drivers'!$A$2:$A$999,reporting!$A280,'Selected scen drivers'!$B$2:$B$999,reporting!$B280) -> 0 | AF280: 2

Sheet Classification
B3: ActiveReg | C3: Status | D3: ElastClass
A4: 1 | B4: Africa_Other | C4: Eme | D4: =C4 -> Eme | M4: ~TFM_FILL-R:w=BYDem_tra
A5: =A4+1 -> 2 | B5: India | C5: Eme | D5: =C5 -> Eme | M5: Scenario | N5: Attribute | O5: CSET_Set | P5: Year | Q5: AllRegions | R5: CSET_CN | U5: 1 | V5: GDP
A6: =A5+1 -> 3 | B6: ROW | C6: Eme | D6: =C6 -> Eme | M6: BASE | N6: Demand | O6: DEM | P6: 2019 | Q6: *1 | R6: T* | U6: 2 | V6: GDPAGR
A7: =A6+1 -> 4 | B7: WestBalkans | C7: Eme | D7: =C7 -> Eme | U7: 3 | V7: GDPIND
A8: =A7+1 -> 5 | B8: Brazil | C8: Eme | D8: =C8 -> Eme | U8: 4 | V8: GDPMFG
A9: =A8+1 -> 6 | B9: Africa_North | C9: Eme | D9: =C9 -> Eme | U9: 5 | V9: GDPPCAP
A10: =A9+1 -> 7 | B10: Ukraine | C10: Eme | D10: =C10 -> Eme | U10: 6 | V10: GDPPHOU
A11: =A10+1 -> 8 | B11: SouthAfrica | C11: Eme | D11: Eme | U11: 7 | V11: GDPSER
A12: =A11+1 -> 9 | B12: LatAm | C12: Eme | D12: =C12 -> Eme | U12: 8 | V12: HOU
A13: =A12+1 -> 10 | B13: MidEast | C13: Eme | D13: =C13 -> Eme | U13: 9 | V13: POP
A14: =A13+1 -> 11 | B14: Turkey | C14: Dev | D14: =C14 -> Dev
A15: =A14+1 -> 12 | B15: Russia | C15: Dev | D15: =C15 -> Dev
A16: =A15+1 -> 13 | B16: HunRomBul | C16: Dev | D16: =C16 -> Dev
A17: =A16+1 -> 14 | B17: CroSloven | C17: Dev | D17: =C17 -> Dev
A18: =A17+1 -> 15 | B18: SpainPor | C18: Dev | D18: =C18 -> Dev
A19: =A18+1 -> 16 | B19: GreeceCyp | C19: Dev | D19: =C19 -> Dev
A20: =A19+1 -> 17 | B20: China | C20: Eme | D20: Chi
A21: =A20+1 -> 18 | B21: ItalyMal | C21: Dev | D21: =C21 -> Dev
A22: =A21+1 -> 19 | B22: Poland | C22: Dev | D22: =C22 -> Dev
A23: =A22+1 -> 20 | B23: Baltics | C23: Dev | D23: =C23 -> Dev
A24: =A23+1 -> 21 | B24: France | C24: Dev | D24: =C24 -> Dev
A25: =A24+1 -> 22 | B25: Japan | C25: Dev | D25: =C25 -> Dev
A26: =A25+1 -> 23 | B26: UK | C26: Dev | D26: =C26 -> Dev
A27: =A26+1 -> 24 | B27: SaudiArabia | C27: Dev | D27: =C27 -> Dev
A28: =A27+1 -> 25 | B28: SweFinDen | C28: Dev | D28: =C28 -> Dev
A29: =A28+1 -> 26 | B29: Germany | C29: Dev | D29: =C29 -> Dev
A30: =A29+1 -> 27 | B30: Australia | C30: Dev | D30: =C30 -> Dev
A31: =A30+1 -> 28 | B31: CzechSlovak | C31: Dev | D31: =C31 -> Dev
A32: =A31+1 -> 29 | B32: NorthAm | C32: Dev | D32: =C32 -> Dev
... A38: =A37+1 -> 35 | B38: Ireland | C38: Dev | D38: =C38 -> Dev

Sheet SSP drivers
A1: Model | B1: Scenario | C1: ActiveReg | D1: drvr | E1: 2015 | F1: 2019 | G1: 2020 | H1: 2025 | I1: 2030 | J1: 2035 | K1: 2040 | L1: 2045 | M1: 2050 | N1: 2055 | O1: 2060 | P1: 2065 | Q1: 2070 | R1: 2075 | S1: 2080 | T1: 2085 | U1: 2090 | V1: 2095 | W1: 2100 | X1: \I: | Y1: \I: | Z1: \I: | AA1: \I: | AB1: \I: | AC1: \I: | AD1: \I: | AE1: \I: | AF1: \I:
A2: OECD23 | B2: SSP1 | C2: Africa_North | D2: GDP | F2: 2210.4794 | G2: 2262.425 | H2: 2781.659 | I2: 3473.068 | J2: 4436.465 | K2: 5730.945 | L2: 7368.96 | M2: 9262.532 | N2: 11383.986 | O2: 13731.282 | P2: 16261.404 | Q2: 18844.799 | R2: 21467.312 | S2: 24108.468 | T2: 26758.704 | U2: 29423.216 | V2: 32089.367 | W2: 34706.937
A3: OECD23 | B3: SSP1 | C3: Africa_North | D3: GDPPCAP | F3: 10.951082 | G3: 11.045012 | H3: 12.657175 | I3: 14.908783 | J3: 18.137203 | K3: 22.480366 | L3: 27.884857 | M3: 34.054782 | N3: 40.996313 | O3: 48.820785 | P3: 57.478341 | Q3: 66.603511 | R3: 76.20171 | S3: 86.265851 | T3: 96.842016 | U3: 107.99847 | V3: 119.82143 | W3: 132.30086
A4: OECD23 | B4: SSP1 | C4: Africa_North | D4: GDPPHOU | F4: 39.501721 | G4: 39.778539 | H4: 45.2613 | I4: 52.232334 | J4: 62.043485 | K4: 75.181998 | L4: 92.383772 | M4: 113.35523 | N4: 138.00734 | O4: 165.48178 | P4: 195.35926 | Q4: 227.74622 | R4: 266.03337 | S4: 315.40895 | T4: 375.40723 | U4: 442.89494 | V4: 517.694 | W4: 602.10906
A5: OECD23 | B5: SSP1 | C5: Africa_North | D5: HOU | F5: 55.959065 | G5: 56.875518 | H5: 61.45778 | I5: 66.492683 | J5: 71.505735 | K5: 76.227624 | L5: 79.764658 | M5: 81.712435 | N5: 82.488262 | O5: 82.977605 | P5: 83.238458 | Q5: 82.744727 | R5: 80.694056 | S5: 76.435587 | T5: 71.279139 | U5: 66.43385 | V5: 61.985202 | W5: 57.642277
A6: OECD23 | B6: SSP1 | C6: Africa_North | D6: POP | F6: 201.85031 | G6: 204.83682 | H6: 219.76933 | I6: 232.95449 | J6: 244.6058 | K6: 254.93113 | L6: 264.26387 | M6: 271.98917 | N6: 277.68317 | O6: 281.25893 | P6: 282.91359 | Q6: 282.94003 | R6: 281.71693 | S6: 279.46711 | T6: 276.31296 | U6: 272.44105 | V6: 267.80992 | W6: 262.33342
A7: OECD23 | B7: SSP1 | C7: Africa_Other | D7: GDP | F7: 3397.857 | G7: 3474.2031 | H7: 4245.1513 | I7: 5428.9126 | J7: 7180.8491 | K7: 9469.9322 | L7: 12465.228 | M7: 16193.695 | N7: 20724.532 | O7: 26200.643 | P7: 32733.319 | Q7: 40295.901 | R7: 48887.497 | S7: 58428.786 | T7: 68854.595 | U7: 80133.45 | V7: 92204.605 | W7: 104970.72
A8: OECD23 | B8: SSP1 | C8: Africa_Other | D8: GDPPCAP | F8: 3.2297051 | G8: 3.2190704 | H8: 3.4933217 | I8: 4.0301287 | J8: 4.8679603 | K8: 5.9303511 | L8: 7.2650309 | M8: 8.8591675 | N8: 10.755171 | O8: 13.028152 | P8: 15.72337 | Q8: 18.835822 | R8: 22.39341 | S8: 26.407844 | T8: 30.915259 | U8: 35.978316 | V8: 41.661681 | W8: 48.018676
A9: OECD23 | B9: SSP1 | C9: Africa_Other | D9: GDPPHOU | F9: 14.787091 | G9: 14.600652 | H9: 15.228466 | I9: 16.647331 | J9: 18.931313 | K9: 21.856874 | L9: 25.626689 | M9: 30.256758 | N9: 35.846486 | O9: 42.51389 | P9: 50.582381 | Q9: 60.227105 | R9: 71.897437 | S9: 85.976693 | T9: 103.13024 | U9: 123.08926 | V9: 146.15664 | W9: 173.16005
A10: OECD23 | B10: SSP1 | C10: Africa_Other | D10: HOU | F10: 229.78535 | G10: 237.94849 | H10: 278.7642 | I10: 326.11309 | J10: 379.31067 | K10: 433.27019 | L10: 486.41588 | M10: 535.20919 | N10: 578.14682 | O10: 616.2843 | P10: 647.12886 | Q10: 669.06589 | R10: 679.9616 | S10: 679.58866 | T10: 667.64702 | U10: 651.019 | V10: 630.86154 | W10: 606.20633
A11: OECD23 | B11: SSP1 | C11: Africa_Other | D11: POP | F11: 1052.0642 | G11: 1079.2567 | H11: 1215.2191 | I11: 1347.0817 | J11: 1475.1248 | K11: 1596.8586 | L11: 1715.7847 | M11: 1827.9026 | N11: 1926.9365 | O11: 2011.0791 | P11: 2081.8259 | Q11: 2139.3227 | R11: 2183.1198 | S11: 2212.5542 | T11: 2227.2042 | U11: 2227.2707 | V11: 2213.1754 | W11: 2186.0394
A12: OECD23 | B12: SSP1 | C12: Australia | D12: GDP | F12: 1184.568 | G12: 1202.79 | H12: 1383.38 | I12: 1580.08 | J12: 1821.75 | K12: 2110.36 | L12: 2436.12 | M12: 2764.93 | N12: 3087.05 | O12: 3412.88 | P12: 3743.17 | Q12: 4068.9 | R12: 4380.7 | S12: 4670.58 | T12: 4923.69 | U12: 5125.51 | V12: 5272.3 | W12: 5373.29
A13: OECD23 | B13: SSP1 | C13: Australia | D13: GDPPCAP | F13: 46.747573 | G13: 47.08665 | H13: 52.071847 | I13: 57.348921 | J13: 63.991164 | K13: 71.960585 | L13: 80.732939 | M13: 89.121824 | N13: 97.108006 | O13: 105.14124 | P13: 113.41953 | Q13: 121.70377 | R13: 129.83972 | S13: 137.79732 | T13: 145.70824 | U13: 153.71292 | V13: 161.78679 | W13: 169.69981
... A1576: OECD23 | B1576: SSP5 | C1576: WestBalkans | D1576: GDPSER | F1576: 177.47117 | G1576: 180.83304 | H1576: 218.77463 | I1576: 262.33711 | J1576: 316.45631 | K1576: 376.26555 | L1576: 434.87416 | M1576: 487.71518 | N1576: 538.99024 | O1576: 592.14596 | P1576: 650.56885 | Q1576: 714.14199 | R1576: 780.8252 | S1576: 849.57587 | T1576: 919.65773 | U1576: 991.07662 | V1576: 1063.3631 | W1576: 1135.4984

Sheet Selected scen drivers
C1: region | D1: driver | E1: ='SSP drivers'!E1 -> 2015 | F1: ='SSP drivers'!F1 -> 2019 | G1: ='SSP drivers'!G1 -> 2020 | H1: ='SSP drivers'!H1 -> 2025 | I1: ='SSP drivers'!I1 -> 2030 | J1: ='SSP drivers'!J1 -> 2035 | K1: ='SSP drivers'!K1 -> 2040 | L1: ='SSP drivers'!L1 -> 2045 | ... AE1: ='SSP drivers'!AE1 -> \I: | AH1: =VLOOKUP($AI$10,$AJ$12:$AL$21,2,FALSE) -> OECD23 | AI1: =VLOOKUP($AI$10,$AJ$12:$AL$21,3,FALSE) -> SSP2
A2: 1 | B2: 1 | C2: =IFERROR(VLOOKUP(A2,Classification!$A$4:$B$99,2,FALSE),"") -> Africa_Other | D2: =IFERROR(VLOOKUP(B2,Classification!$U$5:$V$14,2,FALSE),"") -> GDP | E2: =SUMIFS('SSP drivers'!E$2:E$8148,'SSP drivers'!$A$2:$A$8148,'Selected scen drivers'!$AH$1,'SSP drivers'!$B$2:$B$8148,'Selected scen drivers'!$AI$1,'SSP drivers'!$C$2:$C$8148,'Selected scen drivers'!$C2,'SSP drivers'!$D$2:$D$8148,'Selected scen drivers'!$D2) -> 0 | F2: =SUMIFS('SSP drivers'!F$2:F$8148,'SSP drivers'!$A$2:$A$8148,'Selected scen drivers'!$AH$1,'SSP drivers'!$B$2:$B$8148,'Selected scen drivers'!$AI$1,'SSP drivers'!$C$2:$C$8148,'Selected scen drivers'!$C2,'SSP drivers'!$D$2:$D$8148,'Selected scen drivers'!$D2) -> 3397.857 | G2: =SUMIFS('SSP drivers'!G$2:G$8148,'SSP drivers'!$A$2:$A$8148,'Selected scen drivers'!$AH$1,'SSP drivers'!$B$2:$B$8148,'Selected scen drivers'!$AI$1,'SSP drivers'!$C$2:$C$8148,'Selected scen drivers'!$C2,'SSP drivers'!$D$2:$D$8148,'Selected scen drivers'!$D2) -> 3474.2031 | H2: =SUMIFS('SSP drivers'!H$2:H$8148,'SSP drivers'!$A$2:$A$8148,'Selected scen drivers'!$AH$1,'SSP drivers'!$B$2:$B$8148,'Selected scen drivers'!$AI$1,'SSP drivers'!$C$2:$C$8148,'Selected scen drivers'!$C2,'SSP drivers'!$D$2:$D$8148,'Selected scen drivers'!$D2) -> 4245.2248 | I2: =SUMIFS('SSP drivers'!I$2:I$8148,'SSP drivers'!$A$2:$A$8148,'Selected scen drivers'!$AH$1,'SSP drivers'!$B$2:$B$8148,'Selected scen drivers'!$AI$1,'SSP drivers'!$C$2:$C$8148,'Selected scen drivers'!$C2,'SSP drivers'!$D$2:$D$8148,'Selected scen drivers'!$D2) -> 5425.0474 | J2: =SUMIFS('SSP drivers'!J$2:J$8148,'SSP drivers'!$A$2:$A$8148,'Selected scen drivers'!$AH$1,'SSP drivers'!$B$2:$B$8148,'Selected scen drivers'!$AI$1,'SSP drivers'!$C$2:$C$8148,'Selected scen drivers'!$C2,'SSP drivers'!$D$2:$D$8148,'Selected scen drivers'!$D2) -> 7084.6944 | K2: =SUMIFS('SSP drivers'!K$2:K$8148,'SSP drivers'!$A$2:$A$8148,'Selected scen drivers'!$AH$1,'SSP drivers'!$B$2:$B$8148,'Selected scen drivers'!$AI$1,'SSP drivers'!$C$2:$C$8148,'Selected scen drivers'!$C2,'SSP drivers'!$D$2:$D$8148,'Selected scen drivers'!$D2) -> 9117.9122 | L2: =SUMIFS('SSP drivers'!L$2:L$8148,'SSP drivers'!$A$2:$A$8148,'Selected scen drivers'!$AH$1,'SSP drivers'!$B$2:$B$8148,'Selected scen drivers'!$AI$1,'SSP drivers'!$C$2:$C$8148,'Selected scen drivers'!$C2,'SSP drivers'!$D$2:$D$8148,'Selected scen drivers'!$D2) -> 11656.747 | ... AE2: =SUMIFS('SSP drivers'!AE$2:AE$8148,'SSP drivers'!$A$2:$A$8148,'Selected scen drivers'!$AH$1,'SSP drivers'!$B$2:$B$8148,'Selected scen drivers'!$AI$1,'SSP drivers'!$C$2:$C$8148,'Selected scen drivers'!$C2,'SSP drivers'!$D$2:$D$8148,'Selected scen drivers'!$D2) -> 0
A3: 1 | B3: 2 | C3: =IFERROR(VLOOKUP(A3,Classification!$A$4:$B$99,2,FALSE),"") -> Africa_Other | D3: =IFERROR(VLOOKUP(B3,Classification!$U$5:$V$14,2,FALSE),"") -> GDPAGR | E3: =SUMIFS('SSP drivers'!E$2:E$8148,'SSP drivers'!$A$2:$A$8148,'Selected scen drivers'!$AH$1,'SSP drivers'!$B$2:$B$8148,'Selected scen drivers'!$AI$1,'SSP drivers'!$C$2:$C$8148,'Selected scen drivers'!$C3,'SSP drivers'!$D$2:$D$8148,'Selected scen drivers'!$D3) -> 0 | F3: =SUMIFS('SSP drivers'!F$2:F$8148,'SSP drivers'!$A$2:$A$8148,'Selected scen drivers'!$AH$1,'SSP drivers'!$B$2:$B$8148,'Selected scen drivers'!$AI$1,'SSP drivers'!$C$2:$C$8148,'Selected scen drivers'!$C3,'SSP drivers'!$D$2:$D$8148,'Selected scen drivers'!$D3) -> 791.76348 | G3: =SUMIFS('SSP drivers'!G$2:G$8148,'SSP drivers'!$A$2:$A$8148,'Selected scen drivers'!$AH$1,'SSP drivers'!$B$2:$B$8148,'Selected scen drivers'!$AI$1,'SSP drivers'!$C$2:$C$8148,'Selected scen drivers'!$C3,'SSP drivers'!$D$2:$D$8148,'Selected scen drivers'!$D3) -> 812.01851 | H3: =SUMIFS('SSP drivers'!H$2:H$8148,'SSP drivers'!$A$2:$A$8148,'Selected scen drivers'!$AH$1,'SSP drivers'!$B$2:$B$8148,'Selected scen drivers'!$AI$1,'SSP drivers'!$C$2:$C$8148,'Selected scen drivers'!$C3,'SSP drivers'!$D$2:$D$8148,'Selected scen drivers'!$D3) -> 951.88078 | I3: =SUMIFS('SSP drivers'!I$2:I$8148,'SSP drivers'!$A$2:$A$8148,'Selected scen drivers'!$AH$1,'SSP drivers'!$B$2:$B$8148,'Selected scen drivers'!$AI$1,'SSP drivers'!$C$2:$C$8148,'Selected scen drivers'!$C3,'SSP drivers'!$D$2:$D$8148,'Selected scen drivers'!$D3) -> 1175.539 | J3: =SUMIFS('SSP drivers'!J$2:J$8148,'SSP drivers'!$A$2:$A$8148,'Selected scen drivers'!$AH$1,'SSP drivers'!$B$2:$B$8148,'Selected scen drivers'!$AI$1,'SSP drivers'!$C$2:$C$8148,'Selected scen drivers'!$C3,'SSP drivers'!$D$2:$D$8148,'Selected scen drivers'!$D3) -> 1475.4991 | K3: =SUMIFS('SSP drivers'!K$2:K$8148,'SSP drivers'!$A$2:$A$8148,'Selected scen drivers'!$AH$1,'SSP drivers'!$B$2:$B$8148,'Selected scen drivers'!$AI$1,'SSP drivers'!$C$2:$C$8148,'Selected scen drivers'!$C3,'SSP drivers'!$D$2:$D$8148,'Selected scen drivers'!$D3) -> 1819.0655 | L3: =SUMIFS('SSP drivers'!L$2:L$8148,'SSP drivers'!$A$2:$A$8148,'Selected scen drivers'!$AH$1,'SSP drivers'!$B$2:$B$8148,'Selected scen drivers'!$AI$1,'SSP drivers'!$C$2:$C$8148,'Selected scen drivers'!$C3,'SSP drivers'!$D$2:$D$8148,'Selected scen drivers'!$D3) -> 2219.798 | ... AE3: =SUMIFS('SSP drivers'!AE$2:AE$8148,'SSP drivers'!$A$2:$A$8148,'Selected scen drivers'!$AH$1,'SSP drivers'!$B$2:$B$8148,'Selected scen drivers'!$AI$1,'SSP drivers'!$C$2:$C$8148,'Selected scen drivers'!$C3,'SSP drivers'!$D$2:$D$8148,'Selected scen drivers'!$D3) -> 0
A4: 1 | B4: 3 | C4: =IFERROR(VLOOKUP(A4,Classification!$A$4:$B$99,2,FALSE),"") -> Africa_Other | D4: =IFERROR(VLOOKUP(B4,Classification!$U$5:$V$14,2,FALSE),"") -> GDPIND | E4: =SUMIFS('SSP drivers'!E$2:E$8148,'SSP drivers'!$A$2:$A$8148,'Selected scen drivers'!$AH$1,'SSP drivers'!$B$2:$B$8148,'Selected scen drivers'!$AI$1,'SSP drivers'!$C$2:$C$8148,'Selected scen drivers'!$C4,'SSP drivers'!$D$2:$D$8148,'Selected scen drivers'!$D4) -> 0 | F4: =SUMIFS('SSP drivers'!F$2:F$8148,'SSP drivers'!$A$2:$A$8148,'Selected scen drivers'!$AH$1,'SSP drivers'!$B$2:$B$8148,'Selected scen drivers'!$AI$1,'SSP drivers'!$C$2:$C$8148,'Selected scen drivers'!$C4,'SSP drivers'!$D$2:$D$8148,'Selected scen drivers'!$D4) -> 923.83924 | G4: =SUMIFS('SSP drivers'!G$2:G$8148,'SSP drivers'!$A$2:$A$8148,'Selected scen drivers'!$AH$1,'SSP drivers'!$B$2:$B$8148,'Selected scen drivers'!$AI$1,'SSP drivers'!$C$2:$C$8148,'Selected scen drivers'!$C4,'SSP drivers'!$D$2:$D$8148,'Selected scen drivers'!$D4) -> 941.62527 | H4: =SUMIFS('SSP drivers'!H$2:H$8148,'SSP drivers'!$A$2:$A$8148,'Selected scen drivers'!$AH$1,'SSP drivers'!$B$2:$B$8148,'Selected scen drivers'!$AI$1,'SSP drivers'!$C$2:$C$8148,'Selected scen drivers'!$C4,'SSP drivers'!$D$2:$D$8148,'Selected scen drivers'!$D4) -> 1171.0965 | I4: =SUMIFS('SSP drivers'!I$2:I$8148,'SSP drivers'!$A$2:$A$8148,'Selected scen drivers'!$AH$1,'SSP drivers'!$B$2:$B$8148,'Selected scen drivers'!$AI$1,'SSP drivers'!$C$2:$C$8148,'Selected scen drivers'!$C4,'SSP drivers'!$D$2:$D$8148,'Selected scen drivers'!$D4) -> 1507.2619 | J4: =SUMIFS('SSP drivers'!J$2:J$8148,'SSP drivers'!$A$2:$A$8148,'Selected scen drivers'!$AH$1,'SSP drivers'!$B$2:$B$8148,'Selected scen drivers'!$AI$1,'SSP drivers'!$C$2:$C$8148,'Selected scen drivers'!$C4,'SSP drivers'!$D$2:$D$8148,'Selected scen drivers'!$D4) -> 1985.9926 | K4: =SUMIFS('SSP drivers'!K$2:K$8148,'SSP drivers'!$A$2:$A$8148,'Selected scen drivers'!$AH$1,'SSP drivers'!$B$2:$B$8148,'Selected scen drivers'!$AI$1,'SSP drivers'!$C$2:$C$8148,'Selected scen drivers'!$C4,'SSP drivers'!$D$2:$D$8148,'Selected scen drivers'!$D4) -> 2581.9862 | L4: =SUMIFS('SSP drivers'!L$2:L$8148,'SSP drivers'!$A$2:$A$8148,'Selected scen drivers'!$AH$1,'SSP drivers'!$B$2:$B$8148,'Selected scen drivers'!$AI$1,'SSP drivers'!$C$2:$C$8148,'Selected scen drivers'!$C4,'SSP drivers'!$D$2:$D$8148,'Selected scen drivers'!$D4) -> 3336.6232 | ... AE4: =SUMIFS('SSP drivers'!AE$2:AE$8148,'SSP drivers'!$A$2:$A$8148,'Selected scen drivers'!$AH$1,'SSP drivers'!$B$2:$B$8148,'Selected scen drivers'!$AI$1,'SSP drivers'!$C$2:$C$8148,'Selected scen drivers'!$C4,'SSP drivers'!$D$2:$D$8148,'Selected scen drivers'!$D4) -> 0
A5: 1 | B5: 4 | C5: =IFERROR(VLOOKUP(A5,Classification!$A$4:$B$99,2,FALSE),"") -> Africa_Other | D5: =IFERROR(VLOOKUP(B5,Classification!$U$5:$V$14,2,FALSE),"") -> GDPMFG | E5: =SUMIFS('SSP drivers'!E$2:E$8148,'SSP drivers'!$A$2:$A$8148,'Selected scen drivers'!$AH$1,'SSP drivers'!$B$2:$B$8148,'Selected scen drivers'!$AI$1,'SSP drivers'!$C$2:$C$8148,'Selected scen drivers'!$C5,'SSP drivers'!$D$2:$D$8148,'Selected scen drivers'!$D5) -> 0 | F5: =SUMIFS('SSP drivers'!F$2:F$8148,'SSP drivers'!$A$2:$A$8148,'Selected scen drivers'!$AH$1,'SSP drivers'!$B$2:$B$8148,'Selected scen drivers'!$AI$1,'SSP drivers'!$C$2:$C$8148,'Selected scen drivers'!$C5,'SSP drivers'!$D$2:$D$8148,'Selected scen drivers'!$D5) -> 99.687461 | G5: =SUMIFS('SSP drivers'!G$2:G$8148,'SSP drivers'!$A$2:$A$8148,'Selected scen drivers'!$AH$1,'SSP drivers'!$B$2:$B$8148,'Selected scen drivers'!$AI$1,'SSP drivers'!$C$2:$C$8148,'Selected scen drivers'!$C5,'SSP drivers'!$D$2:$D$8148,'Selected scen drivers'!$D5) -> 101.47959 | H5: =SUMIFS('SSP drivers'!H$2:H$8148,'SSP drivers'!$A$2:$A$8148,'Selected scen drivers'!$AH$1,'SSP drivers'!$B$2:$B$8148,'Selected scen drivers'!$AI$1,'SSP drivers'!$C$2:$C$8148,'Selected scen drivers'!$C5,'SSP drivers'!$D$2:$D$8148,'Selected scen drivers'!$D5) -> 136.06685 | I5: =SUMIFS('SSP drivers'!I$2:I$8148,'SSP drivers'!$A$2:$A$8148,'Selected scen drivers'!$AH$1,'SSP drivers'!$B$2:$B$8148,'Selected scen drivers'!$AI$1,'SSP drivers'!$C$2:$C$8148,'Selected scen drivers'!$C5,'SSP drivers'!$D$2:$D$8148,'Selected scen drivers'!$D5) -> 187.38865 | J5: =SUMIFS('SSP drivers'!J$2:J$8148,'SSP drivers'!$A$2:$A$8148,'Selected scen drivers'!$AH$1,'SSP drivers'!$B$2:$B$8148,'Selected scen drivers'!$AI$1,'SSP drivers'!$C$2:$C$8148,'Selected scen drivers'!$C5,'SSP drivers'!$D$2:$D$8148,'Selected scen drivers'!$D5) -> 264.00246 | K5: =SUMIFS('SSP drivers'!K$2:K$8148,'SSP drivers'!$A$2:$A$8148,'Selected scen drivers'!$AH$1,'SSP drivers'!$B$2:$B$8148,'Selected scen drivers'!$AI$1,'SSP drivers'!$C$2:$C$8148,'Selected scen drivers'!$C5,'SSP drivers'!$D$2:$D$8148,'Selected scen drivers'!$D5) -> 365.9454 | L5: =SUMIFS('SSP drivers'!L$2:L$8148,'SSP drivers'!$A$2:$A$8148,'Selected scen drivers'!$AH$1,'SSP drivers'!$B$2:$B$8148,'Selected scen drivers'!$AI$1,'SSP drivers'!$C$2:$C$8148,'Selected scen drivers'!$C5,'SSP drivers'!$D$2:$D$8148,'Selected scen drivers'!$D5) -> 502.46406 | ... AE5: =SUMIFS('SSP drivers'!AE$2:AE$8148,'SSP drivers'!$A$2:$A$8148,'Selected scen drivers'!$AH$1,'SSP drivers'!$B$2:$B$8148,'Selected scen drivers'!$AI$1,'SSP drivers'!$C$2:$C$8148,'Selected scen drivers'!$C5,'SSP drivers'!$D$2:$D$8148,'Selected scen drivers'!$D5) -> 0
A6: 1 | B6: 5 | C6: =IFERROR(VLOOKUP(A6,Classification!$A$4:$B$99,2,FALSE),"") -> Africa_Other | D6: =IFERROR(VLOOKUP(B6,Classification!$U$5:$V$14,2,FALSE),"") -> GDPPCAP | E6: =SUMIFS('SSP drivers'!E$2:E$8148,'SSP drivers'!$A$2:$A$8148,'Selected scen drivers'!$AH$1,'SSP drivers'!$B$2:$B$8148,'Selected scen drivers'!$AI$1,'SSP drivers'!$C$2:$C$8148,'Selected scen drivers'!$C6,'SSP drivers'!$D$2:$D$8148,'Selected scen drivers'!$D6) -> 0 | F6: =SUMIFS('SSP drivers'!F$2:F$8148,'SSP drivers'!$A$2:$A$8148,'Selected scen drivers'!$AH$1,'SSP drivers'!$B$2:$B$8148,'Selected scen drivers'!$AI$1,'SSP drivers'!$C$2:$C$8148,'Selected scen drivers'!$C6,'SSP drivers'!$D$2:$D$8148,'Selected scen drivers'!$D6) -> 3.2376164 | G6: =SUMIFS('SSP drivers'!G$2:G$8148,'SSP drivers'!$A$2:$A$8148,'Selected scen drivers'!$AH$1,'SSP drivers'!$B$2:$B$8148,'Selected scen drivers'!$AI$1,'SSP drivers'!$C$2:$C$8148,'Selected scen drivers'!$C6,'SSP drivers'!$D$2:$D$8148,'Selected scen drivers'!$D6) -> 3.2190704 | H6: =SUMIFS('SSP drivers'!H$2:H$8148,'SSP drivers'!$A$2:$A$8148,'Selected scen drivers'!$AH$1,'SSP drivers'!$B$2:$B$8148,'Selected scen drivers'!$AI$1,'SSP drivers'!$C$2:$C$8148,'Selected scen drivers'!$C6,'SSP drivers'!$D$2:$D$8148,'Selected scen drivers'!$D6) -> 3.4568181 | I6: =SUMIFS('SSP drivers'!I$2:I$8148,'SSP drivers'!$A$2:$A$8148,'Selected scen drivers'!$AH$1,'SSP drivers'!$B$2:$B$8148,'Selected scen drivers'!$AI$1,'SSP drivers'!$C$2:$C$8148,'Selected scen drivers'!$C6,'SSP drivers'!$D$2:$D$8148,'Selected scen drivers'!$D6) -> 3.9107799 | J6: =SUMIFS('SSP drivers'!J$2:J$8148,'SSP drivers'!$A$2:$A$8148,'Selected scen drivers'!$AH$1,'SSP drivers'!$B$2:$B$8148,'Selected scen drivers'!$AI$1,'SSP drivers'!$C$2:$C$8148,'Selected scen drivers'!$C6,'SSP drivers'!$D$2:$D$8148,'Selected scen drivers'!$D6) -> 4.5602152 | K6: =SUMIFS('SSP drivers'!K$2:K$8148,'SSP drivers'!$A$2:$A$8148,'Selected scen drivers'!$AH$1,'SSP drivers'!$B$2:$B$8148,'Selected scen drivers'!$AI$1,'SSP drivers'!$C$2:$C$8148,'Selected scen drivers'!$C6,'SSP drivers'!$D$2:$D$8148,'Selected scen drivers'!$D6) -> 5.2869465 | L6: =SUMIFS('SSP drivers'!L$2:L$8148,'SSP drivers'!$A$2:$A$8148,'Selected scen drivers'!$AH$1,'SSP drivers'!$B$2:$B$8148,'Selected scen drivers'!$AI$1,'SSP drivers'!$C$2:$C$8148,'Selected scen drivers'!$C6,'SSP drivers'!$D$2:$D$8148,'Selected scen drivers'!$D6) -> 6.1437538 | ... AE6: =SUMIFS('SSP drivers'!AE$2:AE$8148,'SSP drivers'!$A$2:$A$8148,'Selected scen drivers'!$AH$1,'SSP drivers'!$B$2:$B$8148,'Selected scen drivers'!$AI$1,'SSP drivers'!$C$2:$C$8148,'Selected scen drivers'!$C6,'SSP drivers'!$D$2:$D$8148,'Selected scen drivers'!$D6) -> 0
A7: 1 | B7: 6 | C7: =IFERROR(VLOOKUP(A7,Classification!$A$4:$B$99,2,FALSE),"") -> Africa_Other | D7: =IFERROR(VLOOKUP(B7,Classification!$U$5:$V$14,2,FALSE),"") -> GDPPHOU | E7: =SUMIFS('SSP drivers'!E$2:E$8148,'SSP drivers'!$A$2:$A$8148,'Selected scen drivers'!$AH$1,'SSP drivers'!$B$2:$B$8148,'Selected scen drivers'!$AI$1,'SSP drivers'!$C$2:$C$8148,'Selected scen drivers'!$C7,'SSP drivers'!$D$2:$D$8148,'Selected scen drivers'!$D7) -> 0 | F7: =SUMIFS('SSP drivers'!F$2:F$8148,'SSP drivers'!$A$2:$A$8148,'Selected scen drivers'!$AH$1,'SSP drivers'!$B$2:$B$8148,'Selected scen drivers'!$AI$1,'SSP drivers'!$C$2:$C$8148,'Selected scen drivers'!$C7,'SSP drivers'!$D$2:$D$8148,'Selected scen drivers'!$D7) -> 14.780173 | G7: =SUMIFS('SSP drivers'!G$2:G$8148,'SSP drivers'!$A$2:$A$8148,'Selected scen drivers'!$AH$1,'SSP drivers'!$B$2:$B$8148,'Selected scen drivers'!$AI$1,'SSP drivers'!$C$2:$C$8148,'Selected scen drivers'!$C7,'SSP drivers'!$D$2:$D$8148,'Selected scen drivers'!$D7) -> 14.600652 | H7: =SUMIFS('SSP drivers'!H$2:H$8148,'SSP drivers'!$A$2:$A$8148,'Selected scen drivers'!$AH$1,'SSP drivers'!$B$2:$B$8148,'Selected scen drivers'!$AI$1,'SSP drivers'!$C$2:$C$8148,'Selected scen drivers'!$C7,'SSP drivers'!$D$2:$D$8148,'Selected scen drivers'!$D7) -> 15.258165 | I7: =SUMIFS('SSP drivers'!I$2:I$8148,'SSP drivers'!$A$2:$A$8148,'Selected scen drivers'!$AH$1,'SSP drivers'!$B$2:$B$8148,'Selected scen drivers'!$AI$1,'SSP drivers'!$C$2:$C$8148,'Selected scen drivers'!$C7,'SSP drivers'!$D$2:$D$8148,'Selected scen drivers'!$D7) -> 16.73117 | J7: =SUMIFS('SSP drivers'!J$2:J$8148,'SSP drivers'!$A$2:$A$8148,'Selected scen drivers'!$AH$1,'SSP drivers'!$B$2:$B$8148,'Selected scen drivers'!$AI$1,'SSP drivers'!$C$2:$C$8148,'Selected scen drivers'!$C7,'SSP drivers'!$D$2:$D$8148,'Selected scen drivers'!$D7) -> 18.866436 | K7: =SUMIFS('SSP drivers'!K$2:K$8148,'SSP drivers'!$A$2:$A$8148,'Selected scen drivers'!$AH$1,'SSP drivers'!$B$2:$B$8148,'Selected scen drivers'!$AI$1,'SSP drivers'!$C$2:$C$8148,'Selected scen drivers'!$C7,'SSP drivers'!$D$2:$D$8148,'Selected scen drivers'!$D7) -> 21.182859 | L7: =SUMIFS('SSP drivers'!L$2:L$8148,'SSP drivers'!$A$2:$A$8148,'Selected scen drivers'!$AH$1,'SSP drivers'!$B$2:$B$8148,'Selected scen drivers'!$AI$1,'SSP drivers'!$C$2:$C$8148,'Selected scen drivers'!$C7,'SSP drivers'!$D$2:$D$8148,'Selected scen drivers'!$D7) -> 23.887236 | ... AE7: =SUMIFS('SSP drivers'!AE$2:AE$8148,'SSP drivers'!$A$2:$A$8148,'Selected scen drivers'!$AH$1,'SSP drivers'!$B$2:$B$8148,'Selected scen drivers'!$AI$1,'SSP drivers'!$C$2:$C$8148,'Selected scen drivers'!$C7,'SSP drivers'!$D$2:$D$8148,'Selected scen drivers'!$D7) -> 0
A8: 1 | B8: 7 | C8: =IFERROR(VLOOKUP(A8,Classification!$A$4:$B$99,2,FALSE),"") -> Africa_Other | D8: =IFERROR(VLOOKUP(B8,Classification!$U$5:$V$14,2,FALSE),"") -> GDPSER | E8: =SUMIFS('SSP drivers'!E$2:E$8148,'SSP drivers'!$A$2:$A$8148,'Selected scen drivers'!$AH$1,'SSP drivers'!$B$2:$B$8148,'Selected scen drivers'!$AI$1,'SSP drivers'!$C$2:$C$8148,'Selected scen drivers'!$C8,'SSP drivers'!$D$2:$D$8148,'Selected scen drivers'!$D8) -> 0 | F8: =SUMIFS('SSP drivers'!F$2:F$8148,'SSP drivers'!$A$2:$A$8148,'Selected scen drivers'!$AH$1,'SSP drivers'!$B$2:$B$8148,'Selected scen drivers'!$AI$1,'SSP drivers'!$C$2:$C$8148,'Selected scen drivers'!$C8,'SSP drivers'!$D$2:$D$8148,'Selected scen drivers'!$D8) -> 1681.2763 | G8: =SUMIFS('SSP drivers'!G$2:G$8148,'SSP drivers'!$A$2:$A$8148,'Selected scen drivers'!$AH$1,'SSP drivers'!$B$2:$B$8148,'Selected scen drivers'!$AI$1,'SSP drivers'!$C$2:$C$8148,'Selected scen drivers'!$C8,'SSP drivers'!$D$2:$D$8148,'Selected scen drivers'!$D8) -> 1713.1844 | H8: =SUMIFS('SSP drivers'!H$2:H$8148,'SSP drivers'!$A$2:$A$8148,'Selected scen drivers'!$AH$1,'SSP drivers'!$B$2:$B$8148,'Selected scen drivers'!$AI$1,'SSP drivers'!$C$2:$C$8148,'Selected scen drivers'!$C8,'SSP drivers'!$D$2:$D$8148,'Selected scen drivers'!$D8) -> 2110.325 | I8: =SUMIFS('SSP drivers'!I$2:I$8148,'SSP drivers'!$A$2:$A$8148,'Selected scen drivers'!$AH$1,'SSP drivers'!$B$2:$B$8148,'Selected scen drivers'!$AI$1,'SSP drivers'!$C$2:$C$8148,'Selected scen drivers'!$C8,'SSP drivers'!$D$2:$D$8148,'Selected scen drivers'!$D8) -> 2724.9262 | J8: =SUMIFS('SSP drivers'!J$2:J$8148,'SSP drivers'!$A$2:$A$8148,'Selected scen drivers'!$AH$1,'SSP drivers'!$B$2:$B$8148,'Selected scen drivers'!$AI$1,'SSP drivers'!$C$2:$C$8148,'Selected scen drivers'!$C8,'SSP drivers'!$D$2:$D$8148,'Selected scen drivers'!$D8) -> 3598.6769 | K8: =SUMIFS('SSP drivers'!K$2:K$8148,'SSP drivers'!$A$2:$A$8148,'Selected scen drivers'!$AH$1,'SSP drivers'!$B$2:$B$8148,'Selected scen drivers'!$AI$1,'SSP drivers'!$C$2:$C$8148,'Selected scen drivers'!$C8,'SSP drivers'!$D$2:$D$8148,'Selected scen drivers'!$D8) -> 4681.8771 | L8: =SUMIFS('SSP drivers'!L$2:L$8148,'SSP drivers'!$A$2:$A$8148,'Selected scen drivers'!$AH$1,'SSP drivers'!$B$2:$B$8148,'Selected scen drivers'!$AI$1,'SSP drivers'!$C$2:$C$8148,'Selected scen drivers'!$C8,'SSP drivers'!$D$2:$D$8148,'Selected scen drivers'!$D8) -> 6050.1115 | ... AE8: =SUMIFS('SSP drivers'!AE$2:AE$8148,'SSP drivers'!$A$2:$A$8148,'Selected scen drivers'!$AH$1,'SSP drivers'!$B$2:$B$8148,'Selected scen drivers'!$AI$1,'SSP drivers'!$C$2:$C$8148,'Selected scen drivers'!$C8,'SSP drivers'!$D$2:$D$8148,'Selected scen drivers'!$D8) -> 0
