Workbook

Sheet drate
M2: ~TFM_INS-TS
B3: ActiveReg | C3: Status | F3: region | G3: attribute | H3: pset_set | I3: pset_co | J3: 2019 | K3: 2050 | M3: region | N3: attribute | O3: pset_set | P3: pset_co | Q3: 2019 | R3: 2050
B4: Africa_Other | C4: Eme | F4: =B4 -> Africa_Other | G4: NCAP_DRATE | H4: DMD | I4: C?? | J4: =Q4-0.1 -> 0.3 | K4: =R4-0.1 -> 0.2 | M4: =F4 -> Africa_Other | N4: NCAP_DRATE | O4: DMD | P4: Trd_* | Q4: =IF(C4="Eme",0.4,0.3) -> 0.4 | R4: =Q4-0.1 -> 0.3
B5: India | C5: Eme | F5: =B5 -> India | G5: NCAP_DRATE | H5: DMD | I5: C?? | J5: =Q5-0.1 -> 0.3 | K5: =R5-0.1 -> 0.2 | M5: =F5 -> India | N5: NCAP_DRATE | O5: DMD | P5: Trd_* | Q5: =IF(C5="Eme",0.4,0.3) -> 0.4 | R5: =Q5-0.1 -> 0.3
B6: ROW | C6: Eme | F6: =B6 -> ROW | G6: NCAP_DRATE | H6: DMD | I6: C?? | J6: =Q6-0.1 -> 0.3 | K6: =R6-0.1 -> 0.2 | M6: =F6 -> ROW | N6: NCAP_DRATE | O6: DMD | P6: Trd_* | Q6: =IF(C6="Eme",0.4,0.3) -> 0.4 | R6: =Q6-0.1 -> 0.3
B7: WestBalkans | C7: Eme | F7: =B7 -> WestBalkans | G7: NCAP_DRATE | H7: DMD | I7: C?? | J7: =Q7-0.1 -> 0.3 | K7: =R7-0.1 -> 0.2 | M7: =F7 -> WestBalkans | N7: NCAP_DRATE | O7: DMD | P7: Trd_* | Q7: =IF(C7="Eme",0.4,0.3) -> 0.4 | R7: =Q7-0.1 -> 0.3
B8: Brazil | C8: Eme | F8: =B8 -> Brazil | G8: NCAP_DRATE | H8: DMD | I8: C?? | J8: =Q8-0.1 -> 0.3 | K8: =R8-0.1 -> 0.2 | M8: =F8 -> Brazil | N8: NCAP_DRATE | O8: DMD | P8: Trd_* | Q8: =IF(C8="Eme",0.4,0.3) -> 0.4 | R8: =Q8-0.1 -> 0.3
B9: Africa_North | C9: Eme | F9: =B9 -> Africa_North | G9: NCAP_DRATE | H9: DMD | I9: C?? | J9: =Q9-0.1 -> 0.3 | K9: =R9-0.1 -> 0.2 | M9: =F9 -> Africa_North | N9: NCAP_DRATE | O9: DMD | P9: Trd_* | Q9: =IF(C9="Eme",0.4,0.3) -> 0.4 | R9: =Q9-0.1 -> 0.3
B10: Ukraine | C10: Eme | F10: =B10 -> Ukraine | G10: NCAP_DRATE | H10: DMD | I10: C?? | J10: =Q10-0.1 -> 0.3 | K10: =R10-0.1 -> 0.2 | M10: =F10 -> Ukraine | N10: NCAP_DRATE | O10: DMD | P10: Trd_* | Q10: =IF(C10="Eme",0.4,0.3) -> 0.4 | R10: =Q10-0.1 -> 0.3
B11: SouthAfrica | C11: Eme | F11: =B11 -> SouthAfrica | G11: NCAP_DRATE | H11: DMD | I11: C?? | J11: =Q11-0.1 -> 0.3 | K11: =R11-0.1 -> 0.2 | M11: =F11 -> SouthAfrica | N11: NCAP_DRATE | O11: DMD | P11: Trd_* | Q11: =IF(C11="Eme",0.4,0.3) -> 0.4 | R11: =Q11-0.1 -> 0.3
B12: LatAm | C12: Eme | F12: =B12 -> LatAm | G12: NCAP_DRATE | H12: DMD | I12: C?? | J12: =Q12-0.1 -> 0.3 | K12: =R12-0.1 -> 0.2 | M12: =F12 -> LatAm | N12: NCAP_DRATE | O12: DMD | P12: Trd_* | Q12: =IF(C12="Eme",0.4,0.3) -> 0.4 | R12: =Q12-0.1 -> 0.3
B13: MidEast | C13: Eme | F13: =B13 -> MidEast | G13: NCAP_DRATE | H13: DMD | I13: C?? | J13: =Q13-0.1 -> 0.3 | K13: =R13-0.1 -> 0.2 | M13: =F13 -> MidEast | N13: NCAP_DRATE | O13: DMD | P13: Trd_* | Q13: =IF(C13="Eme",0.4,0.3) -> 0.4 | R13: =Q13-0.1 -> 0.3
B14: Turkey | C14: Dev | F14: =B14 -> Turkey | G14: NCAP_DRATE | H14: DMD | I14: C?? | J14: =Q14-0.1 -> 0.2 | K14: =R14-0.1 -> 0.1 | M14: =F14 -> Turkey | N14: NCAP_DRATE | O14: DMD | P14: Trd_* | Q14: =IF(C14="Eme",0.4,0.3) -> 0.3 | R14: =Q14-0.1 -> 0.2
B15: Russia | C15: Dev | F15: =B15 -> Russia | G15: NCAP_DRATE | H15: DMD | I15: C?? | J15: =Q15-0.1 -> 0.2 | K15: =R15-0.1 -> 0.1 | M15: =F15 -> Russia | N15: NCAP_DRATE | O15: DMD | P15: Trd_* | Q15: =IF(C15="Eme",0.4,0.3) -> 0.3 | R15: =Q15-0.1 -> 0.2
... B38: Ireland | C38: Dev | F38: =B38 -> Ireland | G38: NCAP_DRATE | H38: DMD | I38: C?? | J38: =Q38-0.1 -> 0.2 | K38: =R38-0.1 -> 0.1 | M38: =F38 -> Ireland | N38: NCAP_DRATE | O38: DMD | P38: Trd_* | Q38: =IF(C38="Eme",0.4,0.3) -> 0.3 | R38: =Q38-0.1 -> 0.2

Sheet BY_TRA
A1: scenario | B1: attribute | C1: process | D1: commodity | E1: lim_type | F1: time_slice | G1: year | H1: commodity_group | I1: currency | J1: stage | K1: sow | L1: Africa_North | M1: Africa_Other | N1: Australia | O1: Austria | P1: Baltics | Q1: BeNeLux | R1: Brazil | S1: China | T1: CroSloven | U1: CzechSlovak | V1: France | W1: Germany | X1: GreeceCyp | Y1: HunRomBul | Z1: Iceland | AA1: India | AB1: Ireland | AC1: ItalyMal | AD1: Japan | AE1: LatAm | AF1: MidEast | AG1: NorthAm | AH1: Norway | AI1: Poland | AJ1: ROW | AK1: Russia | AL1: SaudiArabia | AM1: SouthAfrica | AN1: SpainPor | AO1: SweFinDen | AP1: Switzerland | AQ1: Turkey | AR1: UK | AS1: Ukraine | AT1: WestBalkans | AU1: year2 | BJ1: Dem | BK1: Fuel
A2: BASE | B2: PASTI | C2: Trd_2w_elc | D2: - | E2: - | F2: - | G2: 2000 | H2: - | I2: - | J2: - | K2: - | L2: 0 | M2: 0 | N2: 0.0023586837 | O2: 0.001432058 | P2: 0 | Q2: 0.062757835 | R2: 0 | S2: 5.3148726 | T2: 0 | U2: 0 | V2: 0.031926469 | W2: 0.032768856 | X2: 0.0020217289 | Y2: 0 | Z2: 0.0021902063 | AA2: 0 | AB2: 0.0026113999 | AC2: 0.013478193 | AD2: 0 | AE2: 0.039844908 | AF2: 0 | AG2: 0.75932769 | AH2: 0.14649111 | AI2: 0 | AJ2: 0.047847585 | AK2: 0 | AL2: 0 | AM2: 0 | AN2: 0.017521651 | AO2: 0.036812314 | AP2: 0 | AQ2: 0 | AR2: 0.062505119 | AS2: 0 | AT2: 0 | AU2: - | BJ2: =MID(C2,5,3) -> 2w_ | BK2: =RIGHT(C2,3) -> elc
A3: BASE | B3: PASTI | C3: Trd_2w_elc | D3: - | E3: - | F3: - | G3: 2001 | H3: - | I3: - | J3: - | K3: - | L3: 0 | M3: 0 | N3: 0.0023586837 | O3: 0.001432058 | P3: 0 | Q3: 0.062757835 | R3: 0 | S3: 5.3148726 | T3: 0 | U3: 0 | V3: 0.031926469 | W3: 0.032768856 | X3: 0.0020217289 | Y3: 0 | Z3: 0.0021902063 | AA3: 0 | AB3: 0.0026113999 | AC3: 0.013478193 | AD3: 0 | AE3: 0.039844908 | AF3: 0 | AG3: 0.75932769 | AH3: 0.14649111 | AI3: 0 | AJ3: 0.047847585 | AK3: 0 | AL3: 0 | AM3: 0 | AN3: 0.017521651 | AO3: 0.036812314 | AP3: 0 | AQ3: 0 | AR3: 0.062505119 | AS3: 0 | AT3: 0 | AU3: - | BJ3: =MID(C3,5,3) -> 2w_ | BK3: =RIGHT(C3,3) -> elc
A4: BASE | B4: PASTI | C4: Trd_2w_elc | D4: - | E4: - | F4: - | G4: 2002 | H4: - | I4: - | J4: - | K4: - | L4: 0 | M4: 0 | N4: 0.0023586837 | O4: 0.001432058 | P4: 0 | Q4: 0.062757835 | R4: 0 | S4: 5.3148726 | T4: 0 | U4: 0 | V4: 0.031926469 | W4: 0.032768856 | X4: 0.0020217289 | Y4: 0 | Z4: 0.0021902063 | AA4: 0 | AB4: 0.0026113999 | AC4: 0.013478193 | AD4: 0 | AE4: 0.039844908 | AF4: 0 | AG4: 0.75932769 | AH4: 0.14649111 | AI4: 0 | AJ4: 0.047847585 | AK4: 0 | AL4: 0 | AM4: 0 | AN4: 0.017521651 | AO4: 0.036812314 | AP4: 0 | AQ4: 0 | AR4: 0.062505119 | AS4: 0 | AT4: 0 | AU4: - | BJ4: =MID(C4,5,3) -> 2w_ | BK4: =RIGHT(C4,3) -> elc
A5: BASE | B5: PASTI | C5: Trd_2w_elc | D5: - | E5: - | F5: - | G5: 2003 | H5: - | I5: - | J5: - | K5: - | L5: 0 | M5: 0 | N5: 0.0023586837 | O5: 0.001432058 | P5: 0 | Q5: 0.062757835 | R5: 0 | S5: 5.3148726 | T5: 0 | U5: 0 | V5: 0.031926469 | W5: 0.032768856 | X5: 0.0020217289 | Y5: 0 | Z5: 0.0021902063 | AA5: 0 | AB5: 0.0026113999 | AC5: 0.013478193 | AD5: 0 | AE5: 0.039844908 | AF5: 0 | AG5: 0.75932769 | AH5: 0.14649111 | AI5: 0 | AJ5: 0.047847585 | AK5: 0 | AL5: 0 | AM5: 0 | AN5: 0.017521651 | AO5: 0.036812314 | AP5: 0 | AQ5: 0 | AR5: 0.062505119 | AS5: 0 | AT5: 0 | AU5: - | BJ5: =MID(C5,5,3) -> 2w_ | BK5: =RIGHT(C5,3) -> elc
A6: BASE | B6: PASTI | C6: Trd_2w_elc | D6: - | E6: - | F6: - | G6: 2004 | H6: - | I6: - | J6: - | K6: - | L6: 0 | M6: 0 | N6: 0.0023586837 | O6: 0.001432058 | P6: 0 | Q6: 0.062757835 | R6: 0 | S6: 5.3148726 | T6: 0 | U6: 0 | V6: 0.031926469 | W6: 0.032768856 | X6: 0.0020217289 | Y6: 0 | Z6: 0.0021902063 | AA6: 0 | AB6: 0.0026113999 | AC6: 0.013478193 | AD6: 0 | AE6: 0.039844908 | AF6: 0 | AG6: 0.75932769 | AH6: 0.14649111 | AI6: 0 | AJ6: 0.047847585 | AK6: 0 | AL6: 0 | AM6: 0 | AN6: 0.017521651 | AO6: 0.036812314 | AP6: 0 | AQ6: 0 | AR6: 0.062505119 | AS6: 0 | AT6: 0 | AU6: - | BJ6: =MID(C6,5,3) -> 2w_ | BK6: =RIGHT(C6,3) -> elc
A7: BASE | B7: PASTI | C7: Trd_2w_elc | D7: - | E7: - | F7: - | G7: 2005 | H7: - | I7: - | J7: - | K7: - | L7: 0 | M7: 0 | N7: 0.0023586837 | O7: 0.001432058 | P7: 0 | Q7: 0.062757835 | R7: 0 | S7: 5.3148726 | T7: 0 | U7: 0 | V7: 0.031926469 | W7: 0.032768856 | X7: 0.0020217289 | Y7: 0 | Z7: 0.0021902063 | AA7: 0 | AB7: 0.0026113999 | AC7: 0.013478193 | AD7: 0 | AE7: 0.039844908 | AF7: 0 | AG7: 0.75932769 | AH7: 0.14649111 | AI7: 0 | AJ7: 0.047847585 | AK7: 0 | AL7: 0 | AM7: 0 | AN7: 0.017521651 | AO7: 0.036812314 | AP7: 0 | AQ7: 0 | AR7: 0.062505119 | AS7: 0 | AT7: 0 | AU7: - | BJ7: =MID(C7,5,3) -> 2w_ | BK7: =RIGHT(C7,3) -> elc
A8: BASE | B8: PASTI | C8: Trd_2w_elc | D8: - | E8: - | F8: - | G8: 2006 | H8: - | I8: - | J8: - | K8: - | L8: 0 | M8: 0 | N8: 0.0023586837 | O8: 0.001432058 | P8: 0 | Q8: 0.062757835 | R8: 0 | S8: 5.3148726 | T8: 0 | U8: 0 | V8: 0.031926469 | W8: 0.032768856 | X8: 0.0020217289 | Y8: 0 | Z8: 0.0021902063 | AA8: 0 | AB8: 0.0026113999 | AC8: 0.013478193 | AD8: 0 | AE8: 0.039844908 | AF8: 0 | AG8: 0.75932769 | AH8: 0.14649111 | AI8: 0 | AJ8: 0.047847585 | AK8: 0 | AL8: 0 | AM8: 0 | AN8: 0.017521651 | AO8: 0.036812314 | AP8: 0 | AQ8: 0 | AR8: 0.062505119 | AS8: 0 | AT8: 0 | AU8: - | BJ8: =MID(C8,5,3) -> 2w_ | BK8: =RIGHT(C8,3) -> elc
A9: BASE | B9: PASTI | C9: Trd_2w_elc | D9: - | E9: - | F9: - | G9: 2007 | H9: - | I9: - | J9: - | K9: - | L9: 0 | M9: 0 | N9: 0.0023586837 | O9: 0.001432058 | P9: 0 | Q9: 0.062757835 | R9: 0 | S9: 5.3148726 | T9: 0 | U9: 0 | V9: 0.031926469 | W9: 0.032768856 | X9: 0.0020217289 | Y9: 0 | Z9: 0.0021902063 | AA9: 0 | AB9: 0.0026113999 | AC9: 0.013478193 | AD9: 0 | AE9: 0.039844908 | AF9: 0 | AG9: 0.75932769 | AH9: 0.14649111 | AI9: 0 | AJ9: 0.047847585 | AK9: 0 | AL9: 0 | AM9: 0 | AN9: 0.017521651 | AO9: 0.036812314 | AP9: 0 | AQ9: 0 | AR9: 0.062505119 | AS9: 0 | AT9: 0 | AU9: - | BJ9: =MID(C9,5,3) -> 2w_ | BK9: =RIGHT(C9,3) -> elc
A10: BASE | B10: PASTI | C10: Trd_2w_elc | D10: - | E10: - | F10: - | G10: 2008 | H10: - | I10: - | J10: - | K10: - | L10: 0 | M10: 0 | N10: 0.0023586837 | O10: 0.001432058 | P10: 0 | Q10: 0.062757835 | R10: 0 | S10: 5.3148726 | T10: 0 | U10: 0 | V10: 0.031926469 | W10: 0.032768856 | X10: 0.0020217289 | Y10: 0 | Z10: 0.0021902063 | AA10: 0 | AB10: 0.0026113999 | AC10: 0.013478193 | AD10: 0 | AE10: 0.039844908 | AF10: 0 | AG10: 0.75932769 | AH10: 0.14649111 | AI10: 0 | AJ10: 0.047847585 | AK10: 0 | AL10: 0 | AM10: 0 | AN10: 0.017521651 | AO10: 0.036812314 | AP10: 0 | AQ10: 0 | AR10: 0.062505119 | AS10: 0 | AT10: 0 | AU10: - | BJ10: =MID(C10,5,3) -> 2w_ | BK10: =RIGHT(C10,3) -> elc
A11: BASE | B11: PASTI | C11: Trd_2w_elc | D11: - | E11: - | F11: - | G11: 2009 | H11: - | I11: - | J11: - | K11: - | L11: 0 | M11: 0 | N11: 0.0023586837 | O11: 0.001432058 | P11: 0 | Q11: 0.062757835 | R11: 0 | S11: 5.3148726 | T11: 0 | U11: 0 | V11: 0.031926469 | W11: 0.032768856 | X11: 0.0020217289 | Y11: 0 | Z11: 0.0021902063 | AA11: 0 | AB11: 0.0026113999 | AC11: 0.013478193 | AD11: 0 | AE11: 0.039844908 | AF11: 0 | AG11: 0.75932769 | AH11: 0.14649111 | AI11: 0 | AJ11: 0.047847585 | AK11: 0 | AL11: 0 | AM11: 0 | AN11: 0.017521651 | AO11: 0.036812314 | AP11: 0 | AQ11: 0 | AR11: 0.062505119 | AS11: 0 | AT11: 0 | AU11: - | BJ11: =MID(C11,5,3) -> 2w_ | BK11: =RIGHT(C11,3) -> elc
A12: BASE | B12: PASTI | C12: Trd_2w_elc | D12: - | E12: - | F12: - | G12: 2010 | H12: - | I12: - | J12: - | K12: - | L12: 0 | M12: 0 | N12: 0.0023586837 | O12: 0.001432058 | P12: 0 | Q12: 0.062757835 | R12: 0 | S12: 5.3148726 | T12: 0 | U12: 0 | V12: 0.031926469 | W12: 0.032768856 | X12: 0.0020217289 | Y12: 0 | Z12: 0.0021902063 | AA12: 0 | AB12: 0.0026113999 | AC12: 0.013478193 | AD12: 0 | AE12: 0.039844908 | AF12: 0 | AG12: 0.75932769 | AH12: 0.14649111 | AI12: 0 | AJ12: 0.047847585 | AK12: 0 | AL12: 0 | AM12: 0 | AN12: 0.017521651 | AO12: 0.036812314 | AP12: 0 | AQ12: 0 | AR12: 0.062505119 | AS12: 0 | AT12: 0 | AU12: - | BJ12: =MID(C12,5,3) -> 2w_ | BK12: =RIGHT(C12,3) -> elc
A13: BASE | B13: PASTI | C13: Trd_2w_elc | D13: - | E13: - | F13: - | G13: 2011 | H13: - | I13: - | J13: - | K13: - | L13: 0 | M13: 0 | N13: 0.0023586837 | O13: 0.001432058 | P13: 0 | Q13: 0.062757835 | R13: 0 | S13: 5.3148726 | T13: 0 | U13: 0 | V13: 0.031926469 | W13: 0.032768856 | X13: 0.0020217289 | Y13: 0 | Z13: 0.0021902063 | AA13: 0 | AB13: 0.0026113999 | AC13: 0.013478193 | AD13: 0 | AE13: 0.039844908 | AF13: 0 | AG13: 0.75932769 | AH13: 0.14649111 | AI13: 0 | AJ13: 0.047847585 | AK13: 0 | AL13: 0 | AM13: 0 | AN13: 0.017521651 | AO13: 0.036812314 | AP13: 0 | AQ13: 0 | AR13: 0.062505119 | AS13: 0 | AT13: 0 | AU13: - | BJ13: =MID(C13,5,3) -> 2w_ | BK13: =RIGHT(C13,3) -> elc
... A561: BASE | B561: PASTI | C561: Trd_lcv_nga | D561: - | E561: - | F561: - | G561: 2019 | H561: - | I561: - | J561: - | K561: - | L561: 0.0021059676 | M561: 0 | N561: 0.00033695482 | O561: 0 | P561: 0.00016847741 | Q561: 0 | R561: 0.01170918 | S561: 0.085586525 | T561: 0 | U561: 0 | V561: 0 | W561: 0 | X561: 0 | Y561: 0 | Z561: 0 | AA561: 0.012804283 | AB561: 0 | AC561: 0 | AD561: 8.4238705e-05 | AE561: 0.022491734 | AF561: 0 | AG561: 0.00075814835 | AH561: 0 | AI561: 0 | AJ561: 0.0075814835 | AK561: 0.0018532515 | AL561: 0 | AM561: 0 | AN561: 0 | AO561: 0 | AP561: 0 | AQ561: 0 | AR561: 0 | AS561: 0.00025271612 | AT561: 0 | AU561: - | BJ561: =MID(C561,5,3) -> lcv | BK561: =RIGHT(C561,3) -> nga
A562: Base_KS_setup | B562: PASTI | C562: Trd_car_elc_120 | D562: - | E562: - | F562: - | G562: 2019 | H562: - | I562: - | J562: - | K562: - | N562: 0.0013436 | O562: 0.0016 | Q562: 0.015 | R562: 0.0002 | S562: 0.222 | V562: 0.009 | W562: 0.015 | X562: 0.0002 | Z562: 0.0004 | AA562: 0.000312 | AC562: 0.0012 | AD562: 0.0044 | AE562: 1e-05 | AF562: 0.0005 | AG562: 0.07764 | AH562: 0.0120632 | AI562: 0.0004 | AJ562: 0.00192 | AM562: 2e-05 | AN562: 0.0017 | AO562: 0.008 | AP562: 0.0017 | AQ562: 0.0002 | AR562: 0.0076 | AU562: - | BJ562: =MID(C562,5,3) -> car | BK562: =RIGHT(C562,3) -> 120
A563: Base_KS_setup | B563: PASTI | C563: Trd_car_elc_120 | D563: - | E563: - | F563: - | G563: 2020 | H563: - | I563: - | J563: - | K563: - | N563: 0.00138 | O563: 0.0052 | Q563: 0.0238 | R563: 0.003949 | S563: 0.266 | V563: 0.037 | W563: 0.0796 | X563: 0.0004 | Z563: 0.0008 | AA563: 0.001 | AC563: 0.0064 | AD563: 0.0058 | AE563: 2e-05 | AF563: 0.0016 | AG563: 0.076 | AH563: 0.0212 | AI563: 0.0016 | AJ563: 0.0066 | AM563: 4e-05 | AN563: 0.0066 | AO563: 0.0244 | AP563: 0.0056 | AQ563: 0.0004 | AR563: 0.0352 | AU563: - | BJ563: =MID(C563,5,3) -> car | BK563: =RIGHT(C563,3) -> 120
A564: Base_KS_setup | B564: PASTI | C564: Trd_car_elc_120 | D564: - | E564: - | F564: - | G564: 2021 | H564: - | I564: - | J564: - | K564: - | N564: 0.0042 | O564: 0.0082 | Q564: 0.0402 | R564: 0.0065 | S564: 0.68 | V564: 0.063 | W564: 0.1362 | X564: 0.001 | Z564: 0.0016 | AA564: 0.0032 | AC564: 0.0134 | AD564: 0.0088 | AE564: 6e-05 | AF564: 0.004 | AG564: 0.1512 | AH564: 0.0278 | AI564: 0.0024 | AJ564: 0.0242 | AM564: 8e-05 | AN564: 0.0146 | AO564: 0.0388 | AP564: 0.0096 | AQ564: 0.001 | AR564: 0.0382 | AU564: - | BJ564: =MID(C564,5,3) -> car | BK564: =RIGHT(C564,3) -> 120
A565: Base_KS_setup | B565: PASTI | C565: Trd_car_elc_120 | D565: - | E565: - | F565: - | G565: 2022 | H565: - | I565: - | J565: - | K565: - | N565: 0.013 | O565: 0.011 | Q565: 0.064 | R565: 0.01 | S565: 1.24 | V565: 0.08 | W565: 0.166 | X565: 0.0026 | Z565: 0.0022 | AA565: 0.0102 | AC565: 0.022 | AD565: 0.0184 | AE565: 0.00012 | AF565: 0.008 | AG565: 0.2132 | AH565: 0.027 | AI565: 0.0048 | AJ565: 0.0314 | AM565: 0.00016 | AN565: 0.026 | AO565: 0.0524 | AP565: 0.0124 | AQ565: 0.007 | AR565: 0.074 | AU565: - | BJ565: =MID(C565,5,3) -> car | BK565: =RIGHT(C565,3) -> 120
A566: Base_KS_setup | B566: PASTI | C566: Trd_car_elc_120 | D566: - | E566: - | F566: - | G566: 2023 | H566: - | I566: - | J566: - | K566: - | N566: 0.0196 | O566: 0.013 | Q566: 0.0806 | R566: 0.0104 | S566: 1.62 | V566: 0.094 | W566: 0.14 | X566: 0.0034 | Z566: 0.00248 | AA566: 0.016454 | AC566: 0.0272 | AD566: 0.02806 | AE566: 0.000184 | AF566: 0.013 | AG566: 0.31524 | AH566: 0.022 | AI566: 0.00602 | AJ566: 0.03486 | AM566: 0.000216 | AN566: 0.037 | AO566: 0.0598 | AP566: 0.0152 | AQ566: 0.01374 | AR566: 0.09 | AU566: - | BJ566: =MID(C566,5,3) -> car | BK566: =RIGHT(C566,3) -> 120
A567: Base_KS_setup | B567: PASTI | C567: Trd_car_elc_120 | D567: - | E567: - | F567: - | G567: 2024 | H567: - | I567: - | J567: - | K567: - | N567: 0.0182 | O567: 0 | Q567: 0.0264332 | R567: 0.025 | S567: 2.24 | V567: 0.0582286 | W567: 0.0761218 | X567: 0 | Z567: 0 | AA567: 0 | AC567: 0.0129966 | AD567: 0 | AE567: 0 | AF567: 0 | AG567: 0.26 | AH567: 0.0228818 | AI567: 0 | AJ567: 0 | AM567: 0 | AN567: 0 | AO567: 0.0188664 | AP567: 0 | AQ567: 0 | AR567: 0.076394 | AU567: - | BJ567: =MID(C567,5,3) -> car | BK567: =RIGHT(C567,3) -> 120
A568: Base_KS_setup | B568: PASTI | C568: Trd_car_elc_160 | D568: - | E568: - | F568: - | G568: 2019 | H568: - | I568: - | J568: - | K568: - | N568: 0.0013436 | O568: 0.0016 | Q568: 0.015 | R568: 0.0002 | S568: 0.222 | V568: 0.009 | W568: 0.015 | X568: 0.0002 | Z568: 0.0004 | AA568: 0.000312 | AC568: 0.0012 | AD568: 0.0044 | AE568: 1e-05 | AF568: 0.0005 | AG568: 0.07764 | AH568: 0.0120632 | AI568: 0.0004 | AJ568: 0.00192 | AM568: 2e-05 | AN568: 0.0017 | AO568: 0.008 | AP568: 0.0017 | AQ568: 0.0002 | AR568: 0.0076 | AU568: - | BJ568: =MID(C568,5,3) -> car | BK568: =RIGHT(C568,3) -> 160
A569: Base_KS_setup | B569: PASTI | C569: Trd_car_elc_160 | D569: - | E569: - | F569: - | G569: 2020 | H569: - | I569: - | J569: - | K569: - | N569: 0.00138 | O569: 0.0052 | Q569: 0.0238 | R569: 0.003949 | S569: 0.266 | V569: 0.037 | W569: 0.0796 | X569: 0.0004 | Z569: 0.0008 | AA569: 0.001 | AC569: 0.0064 | AD569: 0.0058 | AE569: 2e-05 | AF569: 0.0016 | AG569: 0.076 | AH569: 0.0212 | AI569: 0.0016 | AJ569: 0.0066 | AM569: 4e-05 | AN569: 0.0066 | AO569: 0.0244 | AP569: 0.0056 | AQ569: 0.0004 | AR569: 0.0352 | AU569: - | BJ569: =MID(C569,5,3) -> car | BK569: =RIGHT(C569,3) -> 160
A570: Base_KS_setup | B570: PASTI | C570: Trd_car_elc_160 | D570: - | E570: - | F570: - | G570: 2021 | H570: - | I570: - | J570: - | K570: - | N570: 0.0042 | O570: 0.0082 | Q570: 0.0402 | R570: 0.0065 | S570: 0.68 | V570: 0.063 | W570: 0.1362 | X570: 0.001 | Z570: 0.0016 | AA570: 0.0032 | AC570: 0.0134 | AD570: 0.0088 | AE570: 6e-05 | AF570: 0.004 | AG570: 0.1512 | AH570: 0.0278 | AI570: 0.0024 | AJ570: 0.0242 | AM570: 8e-05 | AN570: 0.0146 | AO570: 0.0388 | AP570: 0.0096 | AQ570: 0.001 | AR570: 0.0382 | AU570: - | BJ570: =MID(C570,5,3) -> car | BK570: =RIGHT(C570,3) -> 160
A571: Base_KS_setup | B571: PASTI | C571: Trd_car_elc_160 | D571: - | E571: - | F571: - | G571: 2022 | H571: - | I571: - | J571: - | K571: - | N571: 0.013 | O571: 0.011 | Q571: 0.064 | R571: 0.01 | S571: 1.24 | V571: 0.08 | W571: 0.166 | X571: 0.0026 | Z571: 0.0022 | AA571: 0.0102 | AC571: 0.022 | AD571: 0.0184 | AE571: 0.00012 | AF571: 0.008 | AG571: 0.2132 | AH571: 0.027 | AI571: 0.0048 | AJ571: 0.0314 | AM571: 0.00016 | AN571: 0.026 | AO571: 0.0524 | AP571: 0.0124 | AQ571: 0.007 | AR571: 0.074 | AU571: - | BJ571: =MID(C571,5,3) -> car | BK571: =RIGHT(C571,3) -> 160
A572: Base_KS_setup | B572: PASTI | C572: Trd_car_elc_160 | D572: - | E572: - | F572: - | G572: 2023 | H572: - | I572: - | J572: - | K572: - | N572: 0.0196 | O572: 0.013 | Q572: 0.0806 | R572: 0.0104 | S572: 1.62 | V572: 0.094 | W572: 0.14 | X572: 0.0034 | Z572: 0.00248 | AA572: 0.016454 | AC572: 0.0272 | AD572: 0.02806 | AE572: 0.000184 | AF572: 0.013 | AG572: 0.31524 | AH572: 0.022 | AI572: 0.00602 | AJ572: 0.03486 | AM572: 0.000216 | AN572: 0.037 | AO572: 0.0598 | AP572: 0.0152 | AQ572: 0.01374 | AR572: 0.09 | AU572: - | BJ572: =MID(C572,5,3) -> car | BK572: =RIGHT(C572,3) -> 160
A573: Base_KS_setup | B573: PASTI | C573: Trd_car_elc_160 | D573: - | E573: - | F573: - | G573: 2024 | H573: - | I573: - | J573: - | K573: - | N573: 0.0182 | O573: 0 | Q573: 0.0264332 | R573: 0.025 | S573: 2.24 | V573: 0.0582286 | W573: 0.0761218 | X573: 0 | Z573: 0 | AA573: 0 | AC573: 0.0129966 | AD573: 0 | AE573: 0 | AF573: 0 | AG573: 0.26 | AH573: 0.0228818 | AI573: 0 | AJ573: 0 | AM573: 0 | AN573: 0 | AO573: 0.0188664 | AP573: 0 | AQ573: 0 | AR573: 0.076394 | AU573: - | BJ573: =MID(C573,5,3) -> car | BK573: =RIGHT(C573,3) -> 160
... A591: Base_KS_setup | B591: PASTI | C591: Trd_car_elc_300 | D591: - | E591: - | F591: - | G591: 2024 | H591: - | I591: - | J591: - | K591: - | N591: 0.0182 | O591: 0 | Q591: 0.0264332 | R591: 0.025 | S591: 2.24 | V591: 0.0582286 | W591: 0.0761218 | X591: 0 | Z591: 0 | AA591: 0 | AC591: 0.0129966 | AD591: 0 | AE591: 0 | AF591: 0 | AG591: 0.26 | AH591: 0.0228818 | AI591: 0 | AJ591: 0 | AM591: 0 | AN591: 0 | AO591: 0.0188664 | AP591: 0 | AQ591: 0 | AR591: 0.076394 | AU591: - | BJ591: =MID(C591,5,3) -> car | BK591: =RIGHT(C591,3) -> 300
BJ592: =MID(C592,5,3) | BK592: =RIGHT(C592,3)
BJ593: =MID(C593,5,3) | BK593: =RIGHT(C593,3)
BJ594: =MID(C594,5,3) | BK594: =RIGHT(C594,3)
BJ595: =MID(C595,5,3) | BK595: =RIGHT(C595,3)
BJ596: =MID(C596,5,3) | BK596: =RIGHT(C596,3)
BJ597: =MID(C597,5,3) | BK597: =RIGHT(C597,3)
BJ598: =MID(C598,5,3) | BK598: =RIGHT(C598,3)
BJ599: =MID(C599,5,3) | BK599: =RIGHT(C599,3)
BJ600: =MID(C600,5,3) | BK600: =RIGHT(C600,3)
BJ601: =MID(C601,5,3) | BK601: =RIGHT(C601,3)
BJ602: =MID(C602,5,3) | BK602: =RIGHT(C602,3)
BJ603: =MID(C603,5,3) | BK603: =RIGHT(C603,3)
... BJ999: =MID(C999,5,3) | BK999: =RIGHT(C999,3)

Sheet Transport
M1: Africa_North | N1: Africa_Other | O1: Australia_d | P1: Austria_d | Q1: Baltics | R1: BeNeLux | S1: Brazil_d | T1: China_d | U1: CroSloven | V1: CzechSlovak | W1: France_d | X1: Germany_d | Y1: GreeceCyp | Z1: HunRomBul | AA1: Iceland_d | AB1: India_d | AC1: Ireland_d | AD1: ItalyMal | AE1: Japan_d | AF1: LatAm | AG1: MidEast | AH1: NorthAm | AI1: Norway_d | AJ1: Poland_d | AK1: ROW | AL1: Russia_d | AM1: SaudiArabia_d | AN1: SouthAfrica_d | AO1: SpainPor | AP1: SweFinDen | AQ1: Switzerland_d | AR1: Turkey_d | AS1: UK_d | AT1: Ukraine_d | AU1: WestBalkans | AV1: \I: | AW1: \I: | AX1: \I: | AY1: \I: | AZ1: \I: | BA1: \I: | BB1: \I: | BC1: \I: | BD1: \I: | BE1: \I: | BF1: \I: | BG1: WORLD
K2: Road | L2: BGS/GSL | M2: 0 | N2: 0.0015466859 | O2: 0.0093742232 | P2: 0.034163657 | Q2: 0.035360719 | R2: 0.054342222 | S2: 0.26270131 | T2: 0.014288821 | U2: 0.0057869255 | V2: 0.043868688 | W2: 0.083110496 | X2: 0.041650975 | Y2: 0.0093187388 | Z2: 0.052874918 | AA2: 0.032251602 | AB2: 0.02741929 | AC2: 0.034024563 | AD2: 0.0039031349 | AE2: 0.010499493 | AF2: 0.031086675 | AG2: 0 | AH2: 0.078224387 | AI2: 0.063948056 | AJ2: 0.040360023 | AK2: 0.011814845 | AL2: 0 | AM2: 0 | AN2: 0 | AO2: 0.021382632 | AP2: 0.049325171 | AQ2: 0.013407083 | AR2: 0.022423167 | AS2: 0.031073736 | AT2: 0.047815345 | AU2: 0 | BG2: 0.04422043
L3: BDS/DST | M3: 0 | N3: 0 | O3: 6.3932502e-05 | P3: 0.068913369 | Q3: 0.037794493 | R3: 0.067361803 | S3: 0.4533661 | T3: 0.0097656201 | U3: 0.052976033 | V3: 0.064794503 | W3: 0.082169812 | X3: 0.056931929 | Y3: 0.063781721 | Z3: 0.064321857 | AA3: 0.084226754 | AB3: 0.00067262438 | AC3: 0.054982695 | AD3: 0.058451836 | AE3: 0.00056855736 | AF3: 0.050369739 | AG3: 0 | AH3: 0.032418205 | AI3: 0.19799653 | AJ3: 0.059170906 | AK3: 0.070993332 | AL3: 0.00010266272 | AM3: 0 | AN3: 0 | AO3: 0.068502965 | AP3: 0.22224276 | AQ3: 0.055117864 | AR3: 0.0058119995 | AS3: 0.052148255 | AT3: 0 | AU3: 0.026823157 | BG3: 0.045617324
K5: ~UC_Sets: R_E: allregions
M6: ~UC_T: UC_FLO~LO
I8: UC_N | J8: pset_pn | K8: cset_cn | L8: 2018 | M8: =M1 -> Africa_North | N8: =N1 -> Africa_Other | O8: =O1 -> Australia_d | P8: =P1 -> Austria_d | Q8: =Q1 -> Baltics | R8: =R1 -> BeNeLux | S8: =S1 -> Brazil_d | T8: =T1 -> China_d | ... BF8: =BF1 -> \I: | BG8: UC_RHSRT | BH8: UC_RHSRT~0
I9: UCT_shareBGS_LO | J9: Trd* | K9: TRABGS | L9: 1 | BG9: 0 | BH9: 3
J10: Trd* | K10: TRAGSL | M10: =IFERROR(-M2,"") -> 0 | N10: =IFERROR(-N2,"") -> -0.0015466859 | O10: =IFERROR(-O2,"") -> -0.0093742232 | P10: =IFERROR(-P2,"") -> -0.034163657 | Q10: =IFERROR(-Q2,"") -> -0.035360719 | R10: =IFERROR(-R2,"") -> -0.054342222 | S10: =IFERROR(-S2,"") -> -0.26270131 | T10: =IFERROR(-T2,"") -> -0.014288821 | ... BF10: =IFERROR(-BF2,"") -> 0
B11: ONLY 150cc SEGMENT ACTIVE for 2w | I11: UCT_shareBDS_LO | J11: Trd* | K11: TRABDS | L11: 1 | BG11: 0 | BH11: 3
J12: Trd* | K12: TRADST | M12: =IFERROR(-M3,"") -> 0 | N12: =IFERROR(-N3,"") -> 0 | O12: =IFERROR(-O3,"") -> -6.3932502e-05 | P12: =IFERROR(-P3,"") -> -0.068913369 | Q12: =IFERROR(-Q3,"") -> -0.037794493 | R12: =IFERROR(-R3,"") -> -0.067361803 | S12: =IFERROR(-S3,"") -> -0.4533661 | T12: =IFERROR(-T3,"") -> -0.0097656201 | ... BF12: =IFERROR(-BF3,"") -> 0
K26: ~TFM_FILL-R:w=BY_TRA; hcol=region
K27: Scenario | L27: Attribute | M27: PSET_CO | N27: AllRegions
B28: ~TFM_INS | L28: PASTI | M28: Trd[_]* | N28: *1
B29: attribute | C29: PSET_CI | D29: PSET_CO | E29: value
B30: START | C30: TRALPG | D30: Trd* | E30: 2150
B33: Dem | C33: Fuel | D33: =IF(BY_TRA!L1="","\I:",BY_TRA!L1) -> Africa_North | E33: =IF(BY_TRA!M1="","\I:",BY_TRA!M1) -> Africa_Other | F33: =IF(BY_TRA!N1="","\I:",BY_TRA!N1) -> Australia | G33: =IF(BY_TRA!O1="","\I:",BY_TRA!O1) -> Austria | H33: =IF(BY_TRA!P1="","\I:",BY_TRA!P1) -> Baltics | I33: =IF(BY_TRA!Q1="","\I:",BY_TRA!Q1) -> BeNeLux | J33: =IF(BY_TRA!R1="","\I:",BY_TRA!R1) -> Brazil | K33: =IF(BY_TRA!S1="","\I:",BY_TRA!S1) -> China | ... BA33: =IF(BY_TRA!BI1="","\I:",BY_TRA!BI1) -> \I:
B34: 2w_ | C34: eth | D34: =IFERROR(SUMIFS(BY_TRA!L$2:L$999,BY_TRA!$BJ$2:$BJ$999,Transport!$B34,BY_TRA!$BK$2:$BK$999,Transport!$C34)/SUMIFS(BY_TRA!L$2:L$999,BY_TRA!$BJ$2:$BJ$999,Transport!$B34),0) -> 0 | E34: =IFERROR(SUMIFS(BY_TRA!M$2:M$999,BY_TRA!$BJ$2:$BJ$999,Transport!$B34,BY_TRA!$BK$2:$BK$999,Transport!$C34)/SUMIFS(BY_TRA!M$2:M$999,BY_TRA!$BJ$2:$BJ$999,Transport!$B34),0) -> 0 | F34: =IFERROR(SUMIFS(BY_TRA!N$2:N$999,BY_TRA!$BJ$2:$BJ$999,Transport!$B34,BY_TRA!$BK$2:$BK$999,Transport!$C34)/SUMIFS(BY_TRA!N$2:N$999,BY_TRA!$BJ$2:$BJ$999,Transport!$B34),0) -> 0 | G34: =IFERROR(SUMIFS(BY_TRA!O$2:O$999,BY_TRA!$BJ$2:$BJ$999,Transport!$B34,BY_TRA!$BK$2:$BK$999,Transport!$C34)/SUMIFS(BY_TRA!O$2:O$999,BY_TRA!$BJ$2:$BJ$999,Transport!$B34),0) -> 0 | H34: =IFERROR(SUMIFS(BY_TRA!P$2:P$999,BY_TRA!$BJ$2:$BJ$999,Transport!$B34,BY_TRA!$BK$2:$BK$999,Transport!$C34)/SUMIFS(BY_TRA!P$2:P$999,BY_TRA!$BJ$2:$BJ$999,Transport!$B34),0) -> 0 | I34: =IFERROR(SUMIFS(BY_TRA!Q$2:Q$999,BY_TRA!$BJ$2:$BJ$999,Transport!$B34,BY_TRA!$BK$2:$BK$999,Transport!$C34)/SUMIFS(BY_TRA!Q$2:Q$999,BY_TRA!$BJ$2:$BJ$999,Transport!$B34),0) -> 0 | J34: =IFERROR(SUMIFS(BY_TRA!R$2:R$999,BY_TRA!$BJ$2:$BJ$999,Transport!$B34,BY_TRA!$BK$2:$BK$999,Transport!$C34)/SUMIFS(BY_TRA!R$2:R$999,BY_TRA!$BJ$2:$BJ$999,Transport!$B34),0) -> 0 | K34: =IFERROR(SUMIFS(BY_TRA!S$2:S$999,BY_TRA!$BJ$2:$BJ$999,Transport!$B34,BY_TRA!$BK$2:$BK$999,Transport!$C34)/SUMIFS(BY_TRA!S$2:S$999,BY_TRA!$BJ$2:$BJ$999,Transport!$B34),0) -> 0 | ... AY34: =IFERROR(SUMIFS(BY_TRA!BG$2:BG$999,BY_TRA!$BJ$2:$BJ$999,Transport!$B34,BY_TRA!$BK$2:$BK$999,Transport!$C34)/SUMIFS(BY_TRA!BG$2:BG$999,BY_TRA!$BJ$2:$BJ$999,Transport!$B34),0) -> 0
B35: 2w_ | C35: gsl | D35: =IFERROR(SUMIFS(BY_TRA!L$2:L$999,BY_TRA!$BJ$2:$BJ$999,Transport!$B35,BY_TRA!$BK$2:$BK$999,Transport!$C35)/SUMIFS(BY_TRA!L$2:L$999,BY_TRA!$BJ$2:$BJ$999,Transport!$B35),0) -> 1 | E35: =IFERROR(SUMIFS(BY_TRA!M$2:M$999,BY_TRA!$BJ$2:$BJ$999,Transport!$B35,BY_TRA!$BK$2:$BK$999,Transport!$C35)/SUMIFS(BY_TRA!M$2:M$999,BY_TRA!$BJ$2:$BJ$999,Transport!$B35),0) -> 1 | F35: =IFERROR(SUMIFS(BY_TRA!N$2:N$999,BY_TRA!$BJ$2:$BJ$999,Transport!$B35,BY_TRA!$BK$2:$BK$999,Transport!$C35)/SUMIFS(BY_TRA!N$2:N$999,BY_TRA!$BJ$2:$BJ$999,Transport!$B35),0) -> 0.98102981 | G35: =IFERROR(SUMIFS(BY_TRA!O$2:O$999,BY_TRA!$BJ$2:$BJ$999,Transport!$B35,BY_TRA!$BK$2:$BK$999,Transport!$C35)/SUMIFS(BY_TRA!O$2:O$999,BY_TRA!$BJ$2:$BJ$999,Transport!$B35),0) -> 0.734375 | H35: =IFERROR(SUMIFS(BY_TRA!P$2:P$999,BY_TRA!$BJ$2:$BJ$999,Transport!$B35,BY_TRA!$BK$2:$BK$999,Transport!$C35)/SUMIFS(BY_TRA!P$2:P$999,BY_TRA!$BJ$2:$BJ$999,Transport!$B35),0) -> 1 | I35: =IFERROR(SUMIFS(BY_TRA!Q$2:Q$999,BY_TRA!$BJ$2:$BJ$999,Transport!$B35,BY_TRA!$BK$2:$BK$999,Transport!$C35)/SUMIFS(BY_TRA!Q$2:Q$999,BY_TRA!$BJ$2:$BJ$999,Transport!$B35),0) -> 0.19806243 | J35: =IFERROR(SUMIFS(BY_TRA!R$2:R$999,BY_TRA!$BJ$2:$BJ$999,Transport!$B35,BY_TRA!$BK$2:$BK$999,Transport!$C35)/SUMIFS(BY_TRA!R$2:R$999,BY_TRA!$BJ$2:$BJ$999,Transport!$B35),0) -> 1 | K35: =IFERROR(SUMIFS(BY_TRA!S$2:S$999,BY_TRA!$BJ$2:$BJ$999,Transport!$B35,BY_TRA!$BK$2:$BK$999,Transport!$C35)/SUMIFS(BY_TRA!S$2:S$999,BY_TRA!$BJ$2:$BJ$999,Transport!$B35),0) -> 0.54768476 | ... AY35: =IFERROR(SUMIFS(BY_TRA!BG$2:BG$999,BY_TRA!$BJ$2:$BJ$999,Transport!$B35,BY_TRA!$BK$2:$BK$999,Transport!$C35)/SUMIFS(BY_TRA!BG$2:BG$999,BY_TRA!$BJ$2:$BJ$999,Transport!$B35),0) -> 0
B36: 3w_ | C36: bdl | D36: =IFERROR(SUMIFS(BY_TRA!L$2:L$999,BY_TRA!$BJ$2:$BJ$999,Transport!$B36,BY_TRA!$BK$2:$BK$999,Transport!$C36)/SUMIFS(BY_TRA!L$2:L$999,BY_TRA!$BJ$2:$BJ$999,Transport!$B36),0) -> 0 | E36: =IFERROR(SUMIFS(BY_TRA!M$2:M$999,BY_TRA!$BJ$2:$BJ$999,Transport!$B36,BY_TRA!$BK$2:$BK$999,Transport!$C36)/SUMIFS(BY_TRA!M$2:M$999,BY_TRA!$BJ$2:$BJ$999,Transport!$B36),0) -> 0 | F36: =IFERROR(SUMIFS(BY_TRA!N$2:N$999,BY_TRA!$BJ$2:$BJ$999,Transport!$B36,BY_TRA!$BK$2:$BK$999,Transport!$C36)/SUMIFS(BY_TRA!N$2:N$999,BY_TRA!$BJ$2:$BJ$999,Transport!$B36),0) -> 0 | G36: =IFERROR(SUMIFS(BY_TRA!O$2:O$999,BY_TRA!$BJ$2:$BJ$999,Transport!$B36,BY_TRA!$BK$2:$BK$999,Transport!$C36)/SUMIFS(BY_TRA!O$2:O$999,BY_TRA!$BJ$2:$BJ$999,Transport!$B36),0) -> 0 | H36: =IFERROR(SUMIFS(BY_TRA!P$2:P$999,BY_TRA!$BJ$2:$BJ$999,Transport!$B36,BY_TRA!$BK$2:$BK$999,Transport!$C36)/SUMIFS(BY_TRA!P$2:P$999,BY_TRA!$BJ$2:$BJ$999,Transport!$B36),0) -> 0 | I36: =IFERROR(SUMIFS(BY_TRA!Q$2:Q$999,BY_TRA!$BJ$2:$BJ$999,Transport!$B36,BY_TRA!$BK$2:$BK$999,Transport!$C36)/SUMIFS(BY_TRA!Q$2:Q$999,BY_TRA!$BJ$2:$BJ$999,Transport!$B36),0) -> 0 | J36: =IFERROR(SUMIFS(BY_TRA!R$2:R$999,BY_TRA!$BJ$2:$BJ$999,Transport!$B36,BY_TRA!$BK$2:$BK$999,Transport!$C36)/SUMIFS(BY_TRA!R$2:R$999,BY_TRA!$BJ$2:$BJ$999,Transport!$B36),0) -> 0.08372093 | K36: =IFERROR(SUMIFS(BY_TRA!S$2:S$999,BY_TRA!$BJ$2:$BJ$999,Transport!$B36,BY_TRA!$BK$2:$BK$999,Transport!$C36)/SUMIFS(BY_TRA!S$2:S$999,BY_TRA!$BJ$2:$BJ$999,Transport!$B36),0) -> 0.0096718105 | ... AY36: =IFERROR(SUMIFS(BY_TRA!BG$2:BG$999,BY_TRA!$BJ$2:$BJ$999,Transport!$B36,BY_TRA!$BK$2:$BK$999,Transport!$C36)/SUMIFS(BY_TRA!BG$2:BG$999,BY_TRA!$BJ$2:$BJ$999,Transport!$B36),0) -> 0
B37: 3w_ | C37: dsl | D37: =IFERROR(SUMIFS(BY_TRA!L$2:L$999,BY_TRA!$BJ$2:$BJ$999,Transport!$B37,BY_TRA!$BK$2:$BK$999,Transport!$C37)/SUMIFS(BY_TRA!L$2:L$999,BY_TRA!$BJ$2:$BJ$999,Transport!$B37),0) -> 0 | E37: =IFERROR(SUMIFS(BY_TRA!M$2:M$999,BY_TRA!$BJ$2:$BJ$999,Transport!$B37,BY_TRA!$BK$2:$BK$999,Transport!$C37)/SUMIFS(BY_TRA!M$2:M$999,BY_TRA!$BJ$2:$BJ$999,Transport!$B37),0) -> 0 | F37: =IFERROR(SUMIFS(BY_TRA!N$2:N$999,BY_TRA!$BJ$2:$BJ$999,Transport!$B37,BY_TRA!$BK$2:$BK$999,Transport!$C37)/SUMIFS(BY_TRA!N$2:N$999,BY_TRA!$BJ$2:$BJ$999,Transport!$B37),0) -> 0 | G37: =IFERROR(SUMIFS(BY_TRA!O$2:O$999,BY_TRA!$BJ$2:$BJ$999,Transport!$B37,BY_TRA!$BK$2:$BK$999,Transport!$C37)/SUMIFS(BY_TRA!O$2:O$999,BY_TRA!$BJ$2:$BJ$999,Transport!$B37),0) -> 0 | H37: =IFERROR(SUMIFS(BY_TRA!P$2:P$999,BY_TRA!$BJ$2:$BJ$999,Transport!$B37,BY_TRA!$BK$2:$BK$999,Transport!$C37)/SUMIFS(BY_TRA!P$2:P$999,BY_TRA!$BJ$2:$BJ$999,Transport!$B37),0) -> 0 | I37: =IFERROR(SUMIFS(BY_TRA!Q$2:Q$999,BY_TRA!$BJ$2:$BJ$999,Transport!$B37,BY_TRA!$BK$2:$BK$999,Transport!$C37)/SUMIFS(BY_TRA!Q$2:Q$999,BY_TRA!$BJ$2:$BJ$999,Transport!$B37),0) -> 0 | J37: =IFERROR(SUMIFS(BY_TRA!R$2:R$999,BY_TRA!$BJ$2:$BJ$999,Transport!$B37,BY_TRA!$BK$2:$BK$999,Transport!$C37)/SUMIFS(BY_TRA!R$2:R$999,BY_TRA!$BJ$2:$BJ$999,Transport!$B37),0) -> 0.18139535 | K37: =IFERROR(SUMIFS(BY_TRA!S$2:S$999,BY_TRA!$BJ$2:$BJ$999,Transport!$B37,BY_TRA!$BK$2:$BK$999,Transport!$C37)/SUMIFS(BY_TRA!S$2:S$999,BY_TRA!$BJ$2:$BJ$999,Transport!$B37),0) -> 0.99032819 | ... AY37: =IFERROR(SUMIFS(BY_TRA!BG$2:BG$999,BY_TRA!$BJ$2:$BJ$999,Transport!$B37,BY_TRA!$BK$2:$BK$999,Transport!$C37)/SUMIFS(BY_TRA!BG$2:BG$999,BY_TRA!$BJ$2:$BJ$999,Transport!$B37),0) -> 0
B38: 3w_ | C38: eth | D38: =IFERROR(SUMIFS(BY_TRA!L$2:L$999,BY_TRA!$BJ$2:$BJ$999,Transport!$B38,BY_TRA!$BK$2:$BK$999,Transport!$C38)/SUMIFS(BY_TRA!L$2:L$999,BY_TRA!$BJ$2:$BJ$999,Transport!$B38),0) -> 0 | E38: =IFERROR(SUMIFS(BY_TRA!M$2:M$999,BY_TRA!$BJ$2:$BJ$999,Transport!$B38,BY_TRA!$BK$2:$BK$999,Transport!$C38)/SUMIFS(BY_TRA!M$2:M$999,BY_TRA!$BJ$2:$BJ$999,Transport!$B38),0) -> 0 | F38: =IFERROR(SUMIFS(BY_TRA!N$2:N$999,BY_TRA!$BJ$2:$BJ$999,Transport!$B38,BY_TRA!$BK$2:$BK$999,Transport!$C38)/SUMIFS(BY_TRA!N$2:N$999,BY_TRA!$BJ$2:$BJ$999,Transport!$B38),0) -> 0 | G38: =IFERROR(SUMIFS(BY_TRA!O$2:O$999,BY_TRA!$BJ$2:$BJ$999,Transport!$B38,BY_TRA!$BK$2:$BK$999,Transport!$C38)/SUMIFS(BY_TRA!O$2:O$999,BY_TRA!$BJ$2:$BJ$999,Transport!$B38),0) -> 0 | H38: =IFERROR(SUMIFS(BY_TRA!P$2:P$999,BY_TRA!$BJ$2:$BJ$999,Transport!$B38,BY_TRA!$BK$2:$BK$999,Transport!$C38)/SUMIFS(BY_TRA!P$2:P$999,BY_TRA!$BJ$2:$BJ$999,Transport!$B38),0) -> 0 | I38: =IFERROR(SUMIFS(BY_TRA!Q$2:Q$999,BY_TRA!$BJ$2:$BJ$999,Transport!$B38,BY_TRA!$BK$2:$BK$999,Transport!$C38)/SUMIFS(BY_TRA!Q$2:Q$999,BY_TRA!$BJ$2:$BJ$999,Transport!$B38),0) -> 0 | J38: =IFERROR(SUMIFS(BY_TRA!R$2:R$999,BY_TRA!$BJ$2:$BJ$999,Transport!$B38,BY_TRA!$BK$2:$BK$999,Transport!$C38)/SUMIFS(BY_TRA!R$2:R$999,BY_TRA!$BJ$2:$BJ$999,Transport!$B38),0) -> 0 | K38: =IFERROR(SUMIFS(BY_TRA!S$2:S$999,BY_TRA!$BJ$2:$BJ$999,Transport!$B38,BY_TRA!$BK$2:$BK$999,Transport!$C38)/SUMIFS(BY_TRA!S$2:S$999,BY_TRA!$BJ$2:$BJ$999,Transport!$B38),0) -> 0 | ... AY38: =IFERROR(SUMIFS(BY_TRA!BG$2:BG$999,BY_TRA!$BJ$2:$BJ$999,Transport!$B38,BY_TRA!$BK$2:$BK$999,Transport!$C38)/SUMIFS(BY_TRA!BG$2:BG$999,BY_TRA!$BJ$2:$BJ$999,Transport!$B38),0) -> 0
B39: 3w_ | C39: gsl | D39: =IFERROR(SUMIFS(BY_TRA!L$2:L$999,BY_TRA!$BJ$2:$BJ$999,Transport!$B39,BY_TRA!$BK$2:$BK$999,Transport!$C39)/SUMIFS(BY_TRA!L$2:L$999,BY_TRA!$BJ$2:$BJ$999,Transport!$B39),0) -> 1 | E39: =IFERROR(SUMIFS(BY_TRA!M$2:M$999,BY_TRA!$BJ$2:$BJ$999,Transport!$B39,BY_TRA!$BK$2:$BK$999,Transport!$C39)/SUMIFS(BY_TRA!M$2:M$999,BY_TRA!$BJ$2:$BJ$999,Transport!$B39),0) -> 1 | F39: =IFERROR(SUMIFS(BY_TRA!N$2:N$999,BY_TRA!$BJ$2:$BJ$999,Transport!$B39,BY_TRA!$BK$2:$BK$999,Transport!$C39)/SUMIFS(BY_TRA!N$2:N$999,BY_TRA!$BJ$2:$BJ$999,Transport!$B39),0) -> 0 | G39: =IFERROR(SUMIFS(BY_TRA!O$2:O$999,BY_TRA!$BJ$2:$BJ$999,Transport!$B39,BY_TRA!$BK$2:$BK$999,Transport!$C39)/SUMIFS(BY_TRA!O$2:O$999,BY_TRA!$BJ$2:$BJ$999,Transport!$B39),0) -> 1 | H39: =IFERROR(SUMIFS(BY_TRA!P$2:P$999,BY_TRA!$BJ$2:$BJ$999,Transport!$B39,BY_TRA!$BK$2:$BK$999,Transport!$C39)/SUMIFS(BY_TRA!P$2:P$999,BY_TRA!$BJ$2:$BJ$999,Transport!$B39),0) -> 1 | I39: =IFERROR(SUMIFS(BY_TRA!Q$2:Q$999,BY_TRA!$BJ$2:$BJ$999,Transport!$B39,BY_TRA!$BK$2:$BK$999,Transport!$C39)/SUMIFS(BY_TRA!Q$2:Q$999,BY_TRA!$BJ$2:$BJ$999,Transport!$B39),0) -> 1 | J39: =IFERROR(SUMIFS(BY_TRA!R$2:R$999,BY_TRA!$BJ$2:$BJ$999,Transport!$B39,BY_TRA!$BK$2:$BK$999,Transport!$C39)/SUMIFS(BY_TRA!R$2:R$999,BY_TRA!$BJ$2:$BJ$999,Transport!$B39),0) -> 0.73488372 | K39: =IFERROR(SUMIFS(BY_TRA!S$2:S$999,BY_TRA!$BJ$2:$BJ$999,Transport!$B39,BY_TRA!$BK$2:$BK$999,Transport!$C39)/SUMIFS(BY_TRA!S$2:S$999,BY_TRA!$BJ$2:$BJ$999,Transport!$B39),0) -> 0 | ... AY39: =IFERROR(SUMIFS(BY_TRA!BG$2:BG$999,BY_TRA!$BJ$2:$BJ$999,Transport!$B39,BY_TRA!$BK$2:$BK$999,Transport!$C39)/SUMIFS(BY_TRA!BG$2:BG$999,BY_TRA!$BJ$2:$BJ$999,Transport!$B39),0) -> 0
B40: bus | C40: bdl | D40: =IFERROR(SUMIFS(BY_TRA!L$2:L$999,BY_TRA!$BJ$2:$BJ$999,Transport!$B40,BY_TRA!$BK$2:$BK$999,Transport!$C40)/SUMIFS(BY_TRA!L$2:L$999,BY_TRA!$BJ$2:$BJ$999,Transport!$B40),0) -> 0 | E40: =IFERROR(SUMIFS(BY_TRA!M$2:M$999,BY_TRA!$BJ$2:$BJ$999,Transport!$B40,BY_TRA!$BK$2:$BK$999,Transport!$C40)/SUMIFS(BY_TRA!M$2:M$999,BY_TRA!$BJ$2:$BJ$999,Transport!$B40),0) -> 0 | F40: =IFERROR(SUMIFS(BY_TRA!N$2:N$999,BY_TRA!$BJ$2:$BJ$999,Transport!$B40,BY_TRA!$BK$2:$BK$999,Transport!$C40)/SUMIFS(BY_TRA!N$2:N$999,BY_TRA!$BJ$2:$BJ$999,Transport!$B40),0) -> 0 | G40: =IFERROR(SUMIFS(BY_TRA!O$2:O$999,BY_TRA!$BJ$2:$BJ$999,Transport!$B40,BY_TRA!$BK$2:$BK$999,Transport!$C40)/SUMIFS(BY_TRA!O$2:O$999,BY_TRA!$BJ$2:$BJ$999,Transport!$B40),0) -> 0.045454545 | H40: =IFERROR(SUMIFS(BY_TRA!P$2:P$999,BY_TRA!$BJ$2:$BJ$999,Transport!$B40,BY_TRA!$BK$2:$BK$999,Transport!$C40)/SUMIFS(BY_TRA!P$2:P$999,BY_TRA!$BJ$2:$BJ$999,Transport!$B40),0) -> 0.034482759 | I40: =IFERROR(SUMIFS(BY_TRA!Q$2:Q$999,BY_TRA!$BJ$2:$BJ$999,Transport!$B40,BY_TRA!$BK$2:$BK$999,Transport!$C40)/SUMIFS(BY_TRA!Q$2:Q$999,BY_TRA!$BJ$2:$BJ$999,Transport!$B40),0) -> 0.058823529 | J40: =IFERROR(SUMIFS(BY_TRA!R$2:R$999,BY_TRA!$BJ$2:$BJ$999,Transport!$B40,BY_TRA!$BK$2:$BK$999,Transport!$C40)/SUMIFS(BY_TRA!R$2:R$999,BY_TRA!$BJ$2:$BJ$999,Transport!$B40),0) -> 0.26652452 | K40: =IFERROR(SUMIFS(BY_TRA!S$2:S$999,BY_TRA!$BJ$2:$BJ$999,Transport!$B40,BY_TRA!$BK$2:$BK$999,Transport!$C40)/SUMIFS(BY_TRA!S$2:S$999,BY_TRA!$BJ$2:$BJ$999,Transport!$B40),0) -> 0.006503642 | ... AY40: =IFERROR(SUMIFS(BY_TRA!BG$2:BG$999,BY_TRA!$BJ$2:$BJ$999,Transport!$B40,BY_TRA!$BK$2:$BK$999,Transport!$C40)/SUMIFS(BY_TRA!BG$2:BG$999,BY_TRA!$BJ$2:$BJ$999,Transport!$B40),0) -> 0
B41: bus | C41: dsl | D41: =IFERROR(SUMIFS(BY_TRA!L$2:L$999,BY_TRA!$BJ$2:$BJ$999,Transport!$B41,BY_TRA!$BK$2:$BK$999,Transport!$C41)/SUMIFS(BY_TRA!L$2:L$999,BY_TRA!$BJ$2:$BJ$999,Transport!$B41),0) -> 0.95750332 | E41: =IFERROR(SUMIFS(BY_TRA!M$2:M$999,BY_TRA!$BJ$2:$BJ$999,Transport!$B41,BY_TRA!$BK$2:$BK$999,Transport!$C41)/SUMIFS(BY_TRA!M$2:M$999,BY_TRA!$BJ$2:$BJ$999,Transport!$B41),0) -> 1 | F41: =IFERROR(SUMIFS(BY_TRA!N$2:N$999,BY_TRA!$BJ$2:$BJ$999,Transport!$B41,BY_TRA!$BK$2:$BK$999,Transport!$C41)/SUMIFS(BY_TRA!N$2:N$999,BY_TRA!$BJ$2:$BJ$999,Transport!$B41),0) -> 0.85294118 | G41: =IFERROR(SUMIFS(BY_TRA!O$2:O$999,BY_TRA!$BJ$2:$BJ$999,Transport!$B41,BY_TRA!$BK$2:$BK$999,Transport!$C41)/SUMIFS(BY_TRA!O$2:O$999,BY_TRA!$BJ$2:$BJ$999,Transport!$B41),0) -> 0.95454545 | H41: =IFERROR(SUMIFS(BY_TRA!P$2:P$999,BY_TRA!$BJ$2:$BJ$999,Transport!$B41,BY_TRA!$BK$2:$BK$999,Transport!$C41)/SUMIFS(BY_TRA!P$2:P$999,BY_TRA!$BJ$2:$BJ$999,Transport!$B41),0) -> 0.82758621 | I41: =IFERROR(SUMIFS(BY_TRA!Q$2:Q$999,BY_TRA!$BJ$2:$BJ$999,Transport!$B41,BY_TRA!$BK$2:$BK$999,Transport!$C41)/SUMIFS(BY_TRA!Q$2:Q$999,BY_TRA!$BJ$2:$BJ$999,Transport!$B41),0) -> 0.88235294 | J41: =IFERROR(SUMIFS(BY_TRA!R$2:R$999,BY_TRA!$BJ$2:$BJ$999,Transport!$B41,BY_TRA!$BK$2:$BK$999,Transport!$C41)/SUMIFS(BY_TRA!R$2:R$999,BY_TRA!$BJ$2:$BJ$999,Transport!$B41),0) -> 0.58635394 | K41: =IFERROR(SUMIFS(BY_TRA!S$2:S$999,BY_TRA!$BJ$2:$BJ$999,Transport!$B41,BY_TRA!$BK$2:$BK$999,Transport!$C41)/SUMIFS(BY_TRA!S$2:S$999,BY_TRA!$BJ$2:$BJ$999,Transport!$B41),0) -> 0.65504683 | ... AY41: =IFERROR(SUMIFS(BY_TRA!BG$2:BG$999,BY_TRA!$BJ$2:$BJ$999,Transport!$B41,BY_TRA!$BK$2:$BK$999,Transport!$C41)/SUMIFS(BY_TRA!BG$2:BG$999,BY_TRA!$BJ$2:$BJ$999,Transport!$B41),0) -> 0
B42: bus | C42: elc | D42: =IFERROR(SUMIFS(BY_TRA!L$2:L$999,BY_TRA!$BJ$2:$BJ$999,Transport!$B42,BY_TRA!$BK$2:$BK$999,Transport!$C42)/SUMIFS(BY_TRA!L$2:L$999,BY_TRA!$BJ$2:$BJ$999,Transport!$B42),0) -> 0 | E42: =IFERROR(SUMIFS(BY_TRA!M$2:M$999,BY_TRA!$BJ$2:$BJ$999,Transport!$B42,BY_TRA!$BK$2:$BK$999,Transport!$C42)/SUMIFS(BY_TRA!M$2:M$999,BY_TRA!$BJ$2:$BJ$999,Transport!$B42),0) -> 0 | F42: =IFERROR(SUMIFS(BY_TRA!N$2:N$999,BY_TRA!$BJ$2:$BJ$999,Transport!$B42,BY_TRA!$BK$2:$BK$999,Transport!$C42)/SUMIFS(BY_TRA!N$2:N$999,BY_TRA!$BJ$2:$BJ$999,Transport!$B42),0) -> 0 | G42: =IFERROR(SUMIFS(BY_TRA!O$2:O$999,BY_TRA!$BJ$2:$BJ$999,Transport!$B42,BY_TRA!$BK$2:$BK$999,Transport!$C42)/SUMIFS(BY_TRA!O$2:O$999,BY_TRA!$BJ$2:$BJ$999,Transport!$B42),0) -> 0 | H42: =IFERROR(SUMIFS(BY_TRA!P$2:P$999,BY_TRA!$BJ$2:$BJ$999,Transport!$B42,BY_TRA!$BK$2:$BK$999,Transport!$C42)/SUMIFS(BY_TRA!P$2:P$999,BY_TRA!$BJ$2:$BJ$999,Transport!$B42),0) -> 0.10344828 | I42: =IFERROR(SUMIFS(BY_TRA!Q$2:Q$999,BY_TRA!$BJ$2:$BJ$999,Transport!$B42,BY_TRA!$BK$2:$BK$999,Transport!$C42)/SUMIFS(BY_TRA!Q$2:Q$999,BY_TRA!$BJ$2:$BJ$999,Transport!$B42),0) -> 0 | J42: =IFERROR(SUMIFS(BY_TRA!R$2:R$999,BY_TRA!$BJ$2:$BJ$999,Transport!$B42,BY_TRA!$BK$2:$BK$999,Transport!$C42)/SUMIFS(BY_TRA!R$2:R$999,BY_TRA!$BJ$2:$BJ$999,Transport!$B42),0) -> 0 | K42: =IFERROR(SUMIFS(BY_TRA!S$2:S$999,BY_TRA!$BJ$2:$BJ$999,Transport!$B42,BY_TRA!$BK$2:$BK$999,Transport!$C42)/SUMIFS(BY_TRA!S$2:S$999,BY_TRA!$BJ$2:$BJ$999,Transport!$B42),0) -> 0.056971904 | ... AY42: =IFERROR(SUMIFS(BY_TRA!BG$2:BG$999,BY_TRA!$BJ$2:$BJ$999,Transport!$B42,BY_TRA!$BK$2:$BK$999,Transport!$C42)/SUMIFS(BY_TRA!BG$2:BG$999,BY_TRA!$BJ$2:$BJ$999,Transport!$B42),0) -> 0
B43: bus | C43: eth | D43: =IFERROR(SUMIFS(BY_TRA!L$2:L$999,BY_TRA!$BJ$2:$BJ$999,Transport!$B43,BY_TRA!$BK$2:$BK$999,Transport!$C43)/SUMIFS(BY_TRA!L$2:L$999,BY_TRA!$BJ$2:$BJ$999,Transport!$B43),0) -> 0 | E43: =IFERROR(SUMIFS(BY_TRA!M$2:M$999,BY_TRA!$BJ$2:$BJ$999,Transport!$B43,BY_TRA!$BK$2:$BK$999,Transport!$C43)/SUMIFS(BY_TRA!M$2:M$999,BY_TRA!$BJ$2:$BJ$999,Transport!$B43),0) -> 0 | F43: =IFERROR(SUMIFS(BY_TRA!N$2:N$999,BY_TRA!$BJ$2:$BJ$999,Transport!$B43,BY_TRA!$BK$2:$BK$999,Transport!$C43)/SUMIFS(BY_TRA!N$2:N$999,BY_TRA!$BJ$2:$BJ$999,Transport!$B43),0) -> 0 | G43: =IFERROR(SUMIFS(BY_TRA!O$2:O$999,BY_TRA!$BJ$2:$BJ$999,Transport!$B43,BY_TRA!$BK$2:$BK$999,Transport!$C43)/SUMIFS(BY_TRA!O$2:O$999,BY_TRA!$BJ$2:$BJ$999,Transport!$B43),0) -> 0 | H43: =IFERROR(SUMIFS(BY_TRA!P$2:P$999,BY_TRA!$BJ$2:$BJ$999,Transport!$B43,BY_TRA!$BK$2:$BK$999,Transport!$C43)/SUMIFS(BY_TRA!P$2:P$999,BY_TRA!$BJ$2:$BJ$999,Transport!$B43),0) -> 0 | I43: =IFERROR(SUMIFS(BY_TRA!Q$2:Q$999,BY_TRA!$BJ$2:$BJ$999,Transport!$B43,BY_TRA!$BK$2:$BK$999,Transport!$C43)/SUMIFS(BY_TRA!Q$2:Q$999,BY_TRA!$BJ$2:$BJ$999,Transport!$B43),0) -> 0 | J43: =IFERROR(SUMIFS(BY_TRA!R$2:R$999,BY_TRA!$BJ$2:$BJ$999,Transport!$B43,BY_TRA!$BK$2:$BK$999,Transport!$C43)/SUMIFS(BY_TRA!R$2:R$999,BY_TRA!$BJ$2:$BJ$999,Transport!$B43),0) -> 0 | K43: =IFERROR(SUMIFS(BY_TRA!S$2:S$999,BY_TRA!$BJ$2:$BJ$999,Transport!$B43,BY_TRA!$BK$2:$BK$999,Transport!$C43)/SUMIFS(BY_TRA!S$2:S$999,BY_TRA!$BJ$2:$BJ$999,Transport!$B43),0) -> 0 | ... AY43: =IFERROR(SUMIFS(BY_TRA!BG$2:BG$999,BY_TRA!$BJ$2:$BJ$999,Transport!$B43,BY_TRA!$BK$2:$BK$999,Transport!$C43)/SUMIFS(BY_TRA!BG$2:BG$999,BY_TRA!$BJ$2:$BJ$999,Transport!$B43),0) -> 0
B44: bus | C44: gsl | D44: =IFERROR(SUMIFS(BY_TRA!L$2:L$999,BY_TRA!$BJ$2:$BJ$999,Transport!$B44,BY_TRA!$BK$2:$BK$999,Transport!$C44)/SUMIFS(BY_TRA!L$2:L$999,BY_TRA!$BJ$2:$BJ$999,Transport!$B44),0) -> 0 | E44: =IFERROR(SUMIFS(BY_TRA!M$2:M$999,BY_TRA!$BJ$2:$BJ$999,Transport!$B44,BY_TRA!$BK$2:$BK$999,Transport!$C44)/SUMIFS(BY_TRA!M$2:M$999,BY_TRA!$BJ$2:$BJ$999,Transport!$B44),0) -> 0 | F44: =IFERROR(SUMIFS(BY_TRA!N$2:N$999,BY_TRA!$BJ$2:$BJ$999,Transport!$B44,BY_TRA!$BK$2:$BK$999,Transport!$C44)/SUMIFS(BY_TRA!N$2:N$999,BY_TRA!$BJ$2:$BJ$999,Transport!$B44),0) -> 0.034313725 | G44: =IFERROR(SUMIFS(BY_TRA!O$2:O$999,BY_TRA!$BJ$2:$BJ$999,Transport!$B44,BY_TRA!$BK$2:$BK$999,Transport!$C44)/SUMIFS(BY_TRA!O$2:O$999,BY_TRA!$BJ$2:$BJ$999,Transport!$B44),0) -> 0 | H44: =IFERROR(SUMIFS(BY_TRA!P$2:P$999,BY_TRA!$BJ$2:$BJ$999,Transport!$B44,BY_TRA!$BK$2:$BK$999,Transport!$C44)/SUMIFS(BY_TRA!P$2:P$999,BY_TRA!$BJ$2:$BJ$999,Transport!$B44),0) -> 0.034482759 | I44: =IFERROR(SUMIFS(BY_TRA!Q$2:Q$999,BY_TRA!$BJ$2:$BJ$999,Transport!$B44,BY_TRA!$BK$2:$BK$999,Transport!$C44)/SUMIFS(BY_TRA!Q$2:Q$999,BY_TRA!$BJ$2:$BJ$999,Transport!$B44),0) -> 0.019607843 | J44: =IFERROR(SUMIFS(BY_TRA!R$2:R$999,BY_TRA!$BJ$2:$BJ$999,Transport!$B44,BY_TRA!$BK$2:$BK$999,Transport!$C44)/SUMIFS(BY_TRA!R$2:R$999,BY_TRA!$BJ$2:$BJ$999,Transport!$B44),0) -> 0.053304904 | K44: =IFERROR(SUMIFS(BY_TRA!S$2:S$999,BY_TRA!$BJ$2:$BJ$999,Transport!$B44,BY_TRA!$BK$2:$BK$999,Transport!$C44)/SUMIFS(BY_TRA!S$2:S$999,BY_TRA!$BJ$2:$BJ$999,Transport!$B44),0) -> 0.035639958 | ... AY44: =IFERROR(SUMIFS(BY_TRA!BG$2:BG$999,BY_TRA!$BJ$2:$BJ$999,Transport!$B44,BY_TRA!$BK$2:$BK$999,Transport!$C44)/SUMIFS(BY_TRA!BG$2:BG$999,BY_TRA!$BJ$2:$BJ$999,Transport!$B44),0) -> 0
B45: bus | C45: lpg | D45: =IFERROR(SUMIFS(BY_TRA!L$2:L$999,BY_TRA!$BJ$2:$BJ$999,Transport!$B45,BY_TRA!$BK$2:$BK$999,Transport!$C45)/SUMIFS(BY_TRA!L$2:L$999,BY_TRA!$BJ$2:$BJ$999,Transport!$B45),0) -> 0.014608234 | E45: =IFERROR(SUMIFS(BY_TRA!M$2:M$999,BY_TRA!$BJ$2:$BJ$999,Transport!$B45,BY_TRA!$BK$2:$BK$999,Transport!$C45)/SUMIFS(BY_TRA!M$2:M$999,BY_TRA!$BJ$2:$BJ$999,Transport!$B45),0) -> 0 | F45: =IFERROR(SUMIFS(BY_TRA!N$2:N$999,BY_TRA!$BJ$2:$BJ$999,Transport!$B45,BY_TRA!$BK$2:$BK$999,Transport!$C45)/SUMIFS(BY_TRA!N$2:N$999,BY_TRA!$BJ$2:$BJ$999,Transport!$B45),0) -> 0.098039216 | G45: =IFERROR(SUMIFS(BY_TRA!O$2:O$999,BY_TRA!$BJ$2:$BJ$999,Transport!$B45,BY_TRA!$BK$2:$BK$999,Transport!$C45)/SUMIFS(BY_TRA!O$2:O$999,BY_TRA!$BJ$2:$BJ$999,Transport!$B45),0) -> 0 | H45: =IFERROR(SUMIFS(BY_TRA!P$2:P$999,BY_TRA!$BJ$2:$BJ$999,Transport!$B45,BY_TRA!$BK$2:$BK$999,Transport!$C45)/SUMIFS(BY_TRA!P$2:P$999,BY_TRA!$BJ$2:$BJ$999,Transport!$B45),0) -> 0 | I45: =IFERROR(SUMIFS(BY_TRA!Q$2:Q$999,BY_TRA!$BJ$2:$BJ$999,Transport!$B45,BY_TRA!$BK$2:$BK$999,Transport!$C45)/SUMIFS(BY_TRA!Q$2:Q$999,BY_TRA!$BJ$2:$BJ$999,Transport!$B45),0) -> 0 | J45: =IFERROR(SUMIFS(BY_TRA!R$2:R$999,BY_TRA!$BJ$2:$BJ$999,Transport!$B45,BY_TRA!$BK$2:$BK$999,Transport!$C45)/SUMIFS(BY_TRA!R$2:R$999,BY_TRA!$BJ$2:$BJ$999,Transport!$B45),0) -> 0 | K45: =IFERROR(SUMIFS(BY_TRA!S$2:S$999,BY_TRA!$BJ$2:$BJ$999,Transport!$B45,BY_TRA!$BK$2:$BK$999,Transport!$C45)/SUMIFS(BY_TRA!S$2:S$999,BY_TRA!$BJ$2:$BJ$999,Transport!$B45),0) -> 0.021331946 | ... AY45: =IFERROR(SUMIFS(BY_TRA!BG$2:BG$999,BY_TRA!$BJ$2:$BJ$999,Transport!$B45,BY_TRA!$BK$2:$BK$999,Transport!$C45)/SUMIFS(BY_TRA!BG$2:BG$999,BY_TRA!$BJ$2:$BJ$999,Transport!$B45),0) -> 0
... B65: lcv | C65: nga | D65: =IFERROR(SUMIFS(BY_TRA!L$2:L$999,BY_TRA!$BJ$2:$BJ$999,Transport!$B65,BY_TRA!$BK$2:$BK$999,Transport!$C65)/SUMIFS(BY_TRA!L$2:L$999,BY_TRA!$BJ$2:$BJ$999,Transport!$B65),0) -> 0.012153622 | E65: =IFERROR(SUMIFS(BY_TRA!M$2:M$999,BY_TRA!$BJ$2:$BJ$999,Transport!$B65,BY_TRA!$BK$2:$BK$999,Transport!$C65)/SUMIFS(BY_TRA!M$2:M$999,BY_TRA!$BJ$2:$BJ$999,Transport!$B65),0) -> 0 | F65: =IFERROR(SUMIFS(BY_TRA!N$2:N$999,BY_TRA!$BJ$2:$BJ$999,Transport!$B65,BY_TRA!$BK$2:$BK$999,Transport!$C65)/SUMIFS(BY_TRA!N$2:N$999,BY_TRA!$BJ$2:$BJ$999,Transport!$B65),0) -> 0.0024937656 | G65: =IFERROR(SUMIFS(BY_TRA!O$2:O$999,BY_TRA!$BJ$2:$BJ$999,Transport!$B65,BY_TRA!$BK$2:$BK$999,Transport!$C65)/SUMIFS(BY_TRA!O$2:O$999,BY_TRA!$BJ$2:$BJ$999,Transport!$B65),0) -> 0 | H65: =IFERROR(SUMIFS(BY_TRA!P$2:P$999,BY_TRA!$BJ$2:$BJ$999,Transport!$B65,BY_TRA!$BK$2:$BK$999,Transport!$C65)/SUMIFS(BY_TRA!P$2:P$999,BY_TRA!$BJ$2:$BJ$999,Transport!$B65),0) -> 0.010416667 | I65: =IFERROR(SUMIFS(BY_TRA!Q$2:Q$999,BY_TRA!$BJ$2:$BJ$999,Transport!$B65,BY_TRA!$BK$2:$BK$999,Transport!$C65)/SUMIFS(BY_TRA!Q$2:Q$999,BY_TRA!$BJ$2:$BJ$999,Transport!$B65),0) -> 0 | J65: =IFERROR(SUMIFS(BY_TRA!R$2:R$999,BY_TRA!$BJ$2:$BJ$999,Transport!$B65,BY_TRA!$BK$2:$BK$999,Transport!$C65)/SUMIFS(BY_TRA!R$2:R$999,BY_TRA!$BJ$2:$BJ$999,Transport!$B65),0) -> 0.056366586 | K65: =IFERROR(SUMIFS(BY_TRA!S$2:S$999,BY_TRA!$BJ$2:$BJ$999,Transport!$B65,BY_TRA!$BK$2:$BK$999,Transport!$C65)/SUMIFS(BY_TRA!S$2:S$999,BY_TRA!$BJ$2:$BJ$999,Transport!$B65),0) -> 0.10810811 | ... AY65: =IFERROR(SUMIFS(BY_TRA!BG$2:BG$999,BY_TRA!$BJ$2:$BJ$999,Transport!$B65,BY_TRA!$BK$2:$BK$999,Transport!$C65)/SUMIFS(BY_TRA!BG$2:BG$999,BY_TRA!$BJ$2:$BJ$999,Transport!$B65),0) -> 0
A67: ~TFM_INS: attribute=PRC_MARK; limtype=UP
A69: Year | B69: PSET_CO | C69: PSET_CI | D69: =D33 -> Africa_North | E69: =E33 -> Africa_Other | F69: =F33 -> Australia | G69: =G33 -> Austria | H69: =H33 -> Baltics | I69: =I33 -> BeNeLux | J69: =J33 -> Brazil | K69: =K33 -> China | ... BA69: =BA33 -> \I: | BB69: LimType | BC69: CSET_CN | BD69: Other_indexes
A70: 2025 | B70: ="Trd_"&B46 -> Trd_bus | C70: ="*"&C46 -> *nga | D70: =D46*$BF70 -> 0.030677291 | E70: =E46*$BF70 -> 0 | F70: =F46*$BF70 -> 0.016176471 | G70: =G46*$BF70 -> 0 | H70: =H46*$BF70 -> 0 | I70: =I46*$BF70 -> 0.043137255 | J70: =J46*$BF70 -> 0.10319829 | K70: =K46*$BF70 -> 0.2469563 | ... BA70: =BA46*$BF70 -> 0 | BB70: UP | BC70: =B70 -> Trd_bus | BD70: CNGVeh | BF70: 1.1
A71: 2025 | B71: ="Trd_"&B53 -> Trd_car | C71: ="*"&C53 -> *nga | D71: =D53*$BF71 -> 0.0093638915 | E71: =E53*$BF71 -> 3.5605619e-05 | F71: =F53*$BF71 -> 0.0015128214 | G71: =G53*$BF71 -> 0.0040295041 | H71: =H53*$BF71 -> 0.017988553 | I71: =I53*$BF71 -> 0.0063133326 | J71: =J53*$BF71 -> 0.042687801 | K71: =K53*$BF71 -> 0.071696931 | ... BA71: =BA53*$BF71 -> 0 | BB71: UP | BC71: =B71 -> Trd_car | BD71: CNGVeh | BF71: 1.1
A72: 2025 | B72: ="Trd_"&B65 -> Trd_lcv | C72: ="*"&C65 -> *nga | D72: =D65*$BF72 -> 0.013368984 | E72: =E65*$BF72 -> 0 | F72: =F65*$BF72 -> 0.0027431421 | G72: =G65*$BF72 -> 0 | H72: =H65*$BF72 -> 0.011458333 | I72: =I65*$BF72 -> 0 | J72: =J65*$BF72 -> 0.062003244 | K72: =K65*$BF72 -> 0.11891892 | ... BA72: =BA65*$BF72 -> 0 | BB72: UP | BC72: =B72 -> Trd_lcv | BD72: CNGVeh | BF72: 1.1
A73: 2025 | B73: ="Trd_"&B58 -> Trd_hdt | C73: ="*"&C58 -> *nga | D73: =D58*$BF73 -> 0 | E73: =E58*$BF73 -> 0 | F73: =F58*$BF73 -> 0 | G73: =G58*$BF73 -> 0 | H73: =H58*$BF73 -> 0 | I73: =I58*$BF73 -> 0 | J73: =J58*$BF73 -> 0 | K73: =K58*$BF73 -> 0 | ... BA73: =BA58*$BF73 -> 0 | BB73: UP | BC73: =B73 -> Trd_hdt | BD73: CNGVeh | BF73: 1.1
A74: 2050 | B74: =B70 -> Trd_bus | C74: =C70 -> *nga | D74: =D46*$BF74 -> 0.041832669 | E74: =E46*$BF74 -> 0 | F74: =F46*$BF74 -> 0.022058824 | G74: =G46*$BF74 -> 0 | H74: =H46*$BF74 -> 0 | I74: =I46*$BF74 -> 0.058823529 | J74: =J46*$BF74 -> 0.14072495 | K74: =K46*$BF74 -> 0.33675858 | ... BA74: =BA46*$BF74 -> 0 | BB74: UP | BC74: =B74 -> Trd_bus | BD74: =BD70 -> CNGVeh | BF74: 1.5
A75: 2050 | B75: =B71 -> Trd_car | C75: =C71 -> *nga | D75: =D53*$BF75 -> 0.012768943 | E75: =E53*$BF75 -> 4.8553117e-05 | F75: =F53*$BF75 -> 0.0020629383 | G75: =G53*$BF75 -> 0.0054947783 | H75: =H53*$BF75 -> 0.024529845 | I75: =I53*$BF75 -> 0.0086090899 | J75: =J53*$BF75 -> 0.058210638 | K75: =K53*$BF75 -> 0.097768542 | ... BA75: =BA53*$BF75 -> 0 | BB75: UP | BC75: =B75 -> Trd_car | BD75: =BD71 -> CNGVeh | BF75: 1.5
A76: 2050 | B76: =B72 -> Trd_lcv | C76: =C72 -> *nga | D76: =D65*$BF76 -> 0.018230433 | E76: =E65*$BF76 -> 0 | F76: =F65*$BF76 -> 0.0037406484 | G76: =G65*$BF76 -> 0 | H76: =H65*$BF76 -> 0.015625 | I76: =I65*$BF76 -> 0 | J76: =J65*$BF76 -> 0.084549878 | K76: =K65*$BF76 -> 0.16216216 | ... BA76: =BA65*$BF76 -> 0 | BB76: UP | BC76: =B76 -> Trd_lcv | BD76: =BD72 -> CNGVeh | BF76: 1.5
A77: 0 | B77: =B74 -> Trd_bus | C77: =C74 -> *nga | D77: 5 | E77: 5 | F77: 5 | G77: 5 | H77: 5 | I77: 5 | J77: 5 | K77: 5 | L77: 5 | M77: 5 | N77: 5 | O77: 5 | P77: 5 | Q77: 5 | R77: 5 | S77: 5 | T77: 5 | U77: 5 | V77: 5 | W77: 5 | X77: 5 | Y77: 5 | Z77: 5 | AA77: 5 | AB77: 5 | AC77: 5 | AD77: 5 | AE77: 5 | AF77: 5 | AG77: 5 | AH77: 5 | AI77: 5 | AJ77: 5 | AK77: 5 | AL77: 5 | AM77: 5 | AN77: 5 | AO77: 5 | AP77: 5 | AQ77: 5 | AR77: 5 | AS77: 5 | AT77: 5 | AU77: 5 | AV77: 5 | AW77: 5 | AX77: 5 | AY77: 5 | AZ77: 5 | BA77: 5 | BB77: UP | BC77: =B77 -> Trd_bus | BD77: =BD74 -> CNGVeh
A78: 0 | B78: =B75 -> Trd_car | C78: =C75 -> *nga | D78: 5 | E78: 5 | F78: 5 | G78: 5 | H78: 5 | I78: 5 | J78: 5 | K78: 5 | L78: 5 | M78: 5 | N78: 5 | O78: 5 | P78: 5 | Q78: 5 | R78: 5 | S78: 5 | T78: 5 | U78: 5 | V78: 5 | W78: 5 | X78: 5 | Y78: 5 | Z78: 5 | AA78: 5 | AB78: 5 | AC78: 5 | AD78: 5 | AE78: 5 | AF78: 5 | AG78: 5 | AH78: 5 | AI78: 5 | AJ78: 5 | AK78: 5 | AL78: 5 | AM78: 5 | AN78: 5 | AO78: 5 | AP78: 5 | AQ78: 5 | AR78: 5 | AS78: 5 | AT78: 5 | AU78: 5 | AV78: 5 | AW78: 5 | AX78: 5 | AY78: 5 | AZ78: 5 | BA78: 5 | BB78: UP | BC78: =B78 -> Trd_car | BD78: =BD75 -> CNGVeh
...
