Workbook

Sheet Scen_usingStepMining_n_mute_(2)
C4: m_lithium | D4: 12.85 | L4: ~TFM_UPD
C5: m_nickel | D5: 20 | K5: pset_pn | L5: Attribute | M5: AllRegions
C6: m_cobalt | D6: 29.3 | K6: MINBatMaterials_LI | L6: ACT_COST | M6: 99999
C7: m_manganese | D7: 2 | K7: MINBatMaterials_NI | L7: =L6 | M7: =M6
C8: m_aluminum | D8: 2.5 | K8: MINBatMaterials_COB | L8: =L7 | M8: =M7
C9: m_copper | D9: 8 | K9: MINBatMaterials_MN | L9: =L8 | M9: =M8
C10: m_graphite | D10: 1 | K10: MINBatMaterials_AL | L10: =L9 | M10: =M9
K11: MINBatMaterials_COP | L11: =L10 | M11: =M10
K12: MINBatMaterials_GR | L12: =L11 | M12: =M11
K13: MINBatMaterials_COB_byCop | L13: =L12 | M13: =M12
K14: MINBatMaterials_COB_byNI_sulfide | L14: =L13 | M14: =M13
K15: MINBatMaterials_COB_direct | L15: =L14 | M15: =M14
K16: MINBatMaterials_COB_byNI_HPAL | L16: =L15 | M16: =M15
K17: MINBatMaterials_LI | L17: NCAP_FOM | M17: =M16
K18: MINBatMaterials_NI | L18: =L17 | M18: =M17
K19: MINBatMaterials_COB | L19: =L18 | M19: =M18
K20: MINBatMaterials_MN | L20: =L19 | M20: =M19
K21: MINBatMaterials_AL | L21: =L20 | M21: =M20
K22: MINBatMaterials_COP | L22: =L21 | M22: =M21
K23: MINBatMaterials_GR | L23: =L22 | M23: =M22
K24: MINBatMaterials_COB_byCop | L24: =L23 | M24: =M23
K25: MINBatMaterials_COB_byNI_sulfide | L25: =L24 | M25: =M24
K26: MINBatMaterials_COB_direct | L26: =L25 | M26: =M25
K27: MINBatMaterials_COB_byNI_HPAL | L27: =L26 | M27: =M26
C32: Suggested by COde after reading UCD woman paper
C39: ~TFM_INS
C40: pset_pn | D40: Attribute | E40: cset_cn | F40: Africa_North | G40: Africa_Other | H40: Australia | I40: Austria | J40: Baltics | K40: BeNeLux | L40: Brazil | M40: China | N40: CroSloven | O40: CzechSlovak | P40: France | Q40: Germany | R40: GreeceCyp | S40: HunRomBul | T40: Iceland | U40: India | V40: Ireland | W40: ItalyMal | X40: Japan | Y40: LatAm | Z40: MidEast | AA40: NorthAm | AB40: Norway | AC40: Poland | AD40: ROW | AE40: Russia | AF40: SaudiArabia | AG40: SouthAfrica | AH40: SpainPor | AI40: SweFinDen | AJ40: Switzerland | AK40: Turkey | AL40: UK | AM40: Ukraine | AN40: WestBalkans | AO40: year
C41: =Codex_calc!C41 | D41: =Codex_calc!D41 | F41: =Codex_calc!F41 | G41: =Codex_calc!G41 | H41: =Codex_calc!H41 | I41: =Codex_calc!I41 | J41: =Codex_calc!J41 | K41: =Codex_calc!K41 | L41: =Codex_calc!L41 | M41: =Codex_calc!M41 | ... AO41: =Codex_calc!AO41
C42: =Codex_calc!C42 | D42: =Codex_calc!D42 | AO42: =Codex_calc!AO42
C43: =Codex_calc!C43 | D43: =Codex_calc!D43 | E43: =Codex_calc!E43 | F43: =Codex_calc!F43 | G43: =Codex_calc!G43 | H43: =Codex_calc!H43 | I43: =Codex_calc!I43 | J43: =Codex_calc!J43 | ... AO43: =Codex_calc!AO43
C44: =Codex_calc!C44 | D44: =Codex_calc!D44 | F44: =Codex_calc!F44 | G44: =Codex_calc!G44 | H44: =Codex_calc!H44 | I44: =Codex_calc!I44 | J44: =Codex_calc!J44 | K44: =Codex_calc!K44 | L44: =Codex_calc!L44 | M44: =Codex_calc!M44 | ... AO44: =Codex_calc!AO44
C45: =Codex_calc!C45 | D45: =Codex_calc!D45 | AO45: =Codex_calc!AO45
C46: =Codex_calc!C46 | D46: =Codex_calc!D46 | E46: =Codex_calc!E46 | F46: =Codex_calc!F46 | G46: =Codex_calc!G46 | H46: =Codex_calc!H46 | I46: =Codex_calc!I46 | J46: =Codex_calc!J46 | ... AO46: =Codex_calc!AO46
C47: =Codex_calc!C47 | D47: =Codex_calc!D47 | AO47: =Codex_calc!AO47
C48: =Codex_calc!C48 | D48: =Codex_calc!D48 | AO48: =Codex_calc!AO48
C49: =Codex_calc!C49 | D49: =Codex_calc!D49 | E49: =Codex_calc!E49 | F49: =Codex_calc!F49 | G49: =Codex_calc!G49 | H49: =Codex_calc!H49 | I49: =Codex_calc!I49 | J49: =Codex_calc!J49 | ... AO49: =Codex_calc!AO49
C50: * | D50: =Codex_calc!D50 | E50: =Codex_calc!E50 | F50: =Codex_calc!F50 | G50: =Codex_calc!G50 | H50: =Codex_calc!H50 | I50: =Codex_calc!I50 | J50: =Codex_calc!J50 | K50: =Codex_calc!K50 | ... AO50: =Codex_calc!AO50
C51: =Codex_calc!C51 | D51: =Codex_calc!D51 | F51: =Codex_calc!F51 | G51: =Codex_calc!G51 | H51: =Codex_calc!H51 | I51: =Codex_calc!I51 | J51: =Codex_calc!J51 | K51: =Codex_calc!K51 | L51: =Codex_calc!L51 | M51: =Codex_calc!M51 | ... AO51: =Codex_calc!AO51
C52: =Codex_calc!C52 | D52: =Codex_calc!D52 | AO52: =Codex_calc!AO52
C53: =Codex_calc!C53 | D53: =Codex_calc!D53 | E53: =Codex_calc!E53 | F53: =Codex_calc!F53 | G53: =Codex_calc!G53 | H53: =Codex_calc!H53 | I53: =Codex_calc!I53 | J53: =Codex_calc!J53 | ... AO53: =Codex_calc!AO53
...

Sheet NOUSEattache--data--from
A1: Cumulative extraction limits (CUM) from USGS economically recoverable reserves
A2: CUM = reserves x conversion to kt x battery share x step multiplier. All values kt of contained metal.
A4: THREE ISSUES FOUND IN THE SUPPLIED RESERVES TABLE
A5: 1. UNIT INCONSISTENCY. Mn (1,700) and Cu (980) are in Mt; Li, Co, Ni and graphite are in kt. Left uncorrected these two would be 1,000x too small. A conversion factor is applied below - check it matches your source.
A6: 2. ROW IS MISSING and takes the residual. Regional entries sum to less than the world total for every material: Ni 57.5% short, Cu 22.8%, Co 18.8%, Li 9.2%, graphite 8.9%. For nickel this is almost entirely Indonesia, the largest holder, which sits in your ROW region. The residual is assigned to ROW below.
A7: 3. MANGANESE OVERSHOOTS. Listed regions sum to 1,718 Mt against a world total of 1,700 Mt (-1.1%). Small, but it means the regional and world figures come from different vintages. ROW residual is floored at zero.
A8: ALSO: Brazil has no row despite holding significant graphite, manganese and nickel reserves - confirm whether it was folded into LatAm. Aluminium is absent entirely; bauxite reserves must be added separately if m_aluminum is to be constrained.
A10: 1. MATERIAL PARAMETERS
A11: Material | B11: Commodity | C11: Prefix | D11: World reserves (as supplied) | E11: Unit supplied | F11: Factor to kt | G11: World reserves (kt) | H11: Battery share | I11: RSV2 multiplier (resources) | J11: RSV3 multiplier (speculative)
A12: Li | B12: m_lithium | C12: MINLi | D12: 30000 | E12: kt | F12: 0.7 | G12: =D12*F12 | H12: 0.87 | I12: 1 | J12: 10 | M12: 2
A13: Co | B13: m_cobalt | C13: MINCo | D13: 11000 | E13: kt | F13: 0.7 | G13: =D13*F13 | H13: 0.759 | I13: 1 | J13: 10 | M13: 1.8
A14: Ni | B14: m_nickel | C14: MINNi | D14: 130000 | E14: kt | F14: 0.7 | G14: =D14*F14 | H14: 0.154 | I14: 1 | J14: 10 | M14: 1.8
A15: Mn | B15: m_manganese | C15: MINMn | D15: 1700 | E15: Mt | F15: 0.7 | G15: =D15*F15 | H15: 0.01 | I15: 1 | J15: 10 | M15: 2
A16: Cu | B16: m_copper | C16: MINCu | D16: 980 | E16: Mt | F16: 0.7 | G16: =D16*F16 | H16: 0.026 | I16: 1 | J16: 10 | M16: 1.8
A17: Gr | B17: m_graphite | C17: MINGr | D17: 290000 | E17: kt | F17: 0.7 | G17: =D17*F17 | H17: 0.917 | I17: 1 | J17: 10 | M17: 2
A18: Battery share is derived from your own 2024 activity data divided by world mine production, so CUM is on the
A19: same scope as the model. RSV2/RSV3 multiples of reserves approximate the USGS resource hierarchy
A20: (reserves -> identified resources -> undiscovered). These two columns are the least well sourced - verify
A21: against USGS resource figures and report results across a range.
A23: 2. RESERVES BY REGION (as supplied, in the unit given above)
A24: Material | B24: Unit | C24: Listed sum | D24: Africa_North | E24: Africa_Other | F24: Australia | G24: Austria | H24: Baltics | I24: BeNeLux | J24: Brazil | K24: China | L24: CroSloven | M24: CzechSlovak | N24: France | O24: Germany | P24: GreeceCyp | Q24: HunRomBul | R24: Iceland | S24: India | T24: Ireland | U24: ItalyMal | V24: Japan | W24: LatAm | X24: MidEast | Y24: NorthAm | Z24: Norway | AA24: Poland | AB24: ROW | AC24: Russia | AD24: SaudiArabia | AE24: SouthAfrica | AF24: SpainPor | AG24: SweFinDen | AH24: Switzerland | AI24: Turkey | AJ24: UK | AK24: Ukraine | AL24: WestBalkans
A25: Li | B25: kt | C25: =SUM(D25:AL25) | D25: 0 | E25: 494 | F25: 7000 | G25: 0 | H25: 0 | I25: 0 | J25: 0 | K25: 3000 | L25: 0 | M25: 0 | N25: 0 | O25: 0 | P25: 0 | Q25: 0 | R25: 0 | S25: 0 | T25: 0 | U25: 0 | V25: 0 | W25: 13690 | X25: 0 | Y25: 3000 | Z25: 0 | AA25: 0 | AB25: =MAX(0,$D$12-(D25+E25+F25+G25+H25+I25+J25+K25+L25+M25+N25+O25+P25+Q25+R25+S25+T25+U25+V25+W25+X25+Y25+Z25+AA25+AC25+AD25+AE25+AF25+AG25+AH25+AI25+AJ25+AK25+AL25)) | AC25: 0 | AD25: 0 | AE25: 0 | AF25: 60 | AG25: 0 | AH25: 0 | AI25: 0 | AJ25: 0 | AK25: 0 | AL25: 0
A26: Co | B26: kt | C26: =SUM(D26:AL26) | D26: 0 | E26: 6100 | F26: 1700 | G26: 0 | H26: 0 | I26: 0 | J26: 0 | K26: 0 | L26: 0 | M26: 0 | N26: 0 | O26: 0 | P26: 0 | Q26: 0 | R26: 0 | S26: 0 | T26: 0 | U26: 0 | V26: 0 | W26: 500 | X26: 0 | Y26: 290 | Z26: 0 | AA26: 0 | AB26: =MAX(0,$D$13-(D26+E26+F26+G26+H26+I26+J26+K26+L26+M26+N26+O26+P26+Q26+R26+S26+T26+U26+V26+W26+X26+Y26+Z26+AA26+AC26+AD26+AE26+AF26+AG26+AH26+AI26+AJ26+AK26+AL26)) | AC26: 250 | AD26: 0 | AE26: 0 | AF26: 0 | AG26: 0 | AH26: 0 | AI26: 91 | AJ26: 0 | AK26: 0 | AL26: 0
A27: Ni | B27: kt | C27: =SUM(D27:AL27) | D27: 0 | E27: 0 | F27: 24000 | G27: 0 | H27: 0 | I27: 0 | J27: 0 | K27: 4400 | L27: 0 | M27: 0 | N27: 0 | O27: 0 | P27: 0 | Q27: 0 | R27: 0 | S27: 0 | T27: 0 | U27: 0 | V27: 0 | W27: 16000 | X27: 0 | Y27: 2510 | Z27: 0 | AA27: 0 | AB27: =MAX(0,$D$14-(D27+E27+F27+G27+H27+I27+J27+K27+L27+M27+N27+O27+P27+Q27+R27+S27+T27+U27+V27+W27+X27+Y27+Z27+AA27+AC27+AD27+AE27+AF27+AG27+AH27+AI27+AJ27+AK27+AL27)) | AC27: 8300 | AD27: 0 | AE27: 0 | AF27: 0 | AG27: 0 | AH27: 0 | AI27: 0 | AJ27: 0 | AK27: 0 | AL27: 0
A28: Mn | B28: kt | C28: =SUM(D28:AL28) | D28: =D32*1000 | E28: =E32*1000 | F28: =F32*1000 | G28: =G32*1000 | H28: =H32*1000 | I28: =I32*1000 | J28: =J32*1000 | K28: =K32*1000 | ... AL28: =AL32*1000
A29: Cu | B29: kt | C29: =SUM(D29:AL29) | D29: =D33*1000 | E29: =E33*1000 | F29: =F33*1000 | G29: =G33*1000 | H29: =H33*1000 | I29: =I33*1000 | J29: =J33*1000 | K29: =K33*1000 | ... AL29: =AL33*1000
A30: Gr | B30: kt | C30: =SUM(D30:AL30) | D30: 0 | E30: 70000 | F30: 0 | G30: 0 | H30: 0 | I30: 0 | J30: 0 | K30: 81000 | L30: 0 | M30: 0 | N30: 0 | O30: 0 | P30: 0 | Q30: 0 | R30: 0 | S30: 8600 | T30: 0 | U30: 0 | V30: 0 | W30: 77100 | X30: 0 | Y30: 5900 | Z30: 600 | AA30: 0 | AB30: =MAX(0,$D$17-(D30+E30+F30+G30+H30+I30+J30+K30+L30+M30+N30+O30+P30+Q30+R30+S30+T30+U30+V30+W30+X30+Y30+Z30+AA30+AC30+AD30+AE30+AF30+AG30+AH30+AI30+AJ30+AK30+AL30)) | AC30: 14000 | AD30: 0 | AE30: 0 | AF30: 0 | AG30: 0 | AH30: 0 | AI30: 6900 | AJ30: 0 | AK30: 0 | AL30: 0
A31: ROW cell is a formula: world total minus all other regions. It is yellow because it is inferred, not sourced.
A32: 'Listed sum' should now equal the world reserves in section 1 for every material. | D32: 0 | E32: 74 | F32: 500 | G32: 0 | H32: 0 | I32: 0 | J32: 0 | K32: 280 | L32: 0 | M32: 0 | N32: 0 | O32: 0 | P32: 0 | Q32: 0 | R32: 0 | S32: 34 | T32: 0 | U32: 0 | V32: 0 | W32: 270 | X32: 0 | Y32: 0 | Z32: 0 | AA32: 0 | AB32: =MAX(0,$D$15-(D32+E32+F32+G32+H32+I32+J32+K32+L32+M32+N32+O32+P32+Q32+R32+S32+T32+U32+V32+W32+X32+Y32+Z32+AA32+AC32+AD32+AE32+AF32+AG32+AH32+AI32+AJ32+AK32+AL32)) | AC32: 0 | AD32: 0 | AE32: 560 | AF32: 0 | AG32: 0 | AH32: 0 | AI32: 0 | AJ32: 0 | AK32: 0 | AL32: 0
D33: 0 | E33: 101 | F33: 100 | G33: 0 | H33: 0 | I33: 0 | J33: 0 | K33: 41 | L33: 0 | M33: 0 | N33: 0 | O33: 0 | P33: 0 | Q33: 0 | R33: 0 | S33: 2.2 | T33: 0 | U33: 0 | V33: 0 | W33: 290 | X33: 0 | Y33: 108.3 | Z33: 0 | AA33: 34 | AB33: =MAX(0,$D$16-(D33+E33+F33+G33+H33+I33+J33+K33+L33+M33+N33+O33+P33+Q33+R33+S33+T33+U33+V33+W33+X33+Y33+Z33+AA33+AC33+AD33+AE33+AF33+AG33+AH33+AI33+AJ33+AK33+AL33)) | AC33: 80 | AD33: 0 | AE33: 0 | AF33: 0 | AG33: 0 | AH33: 0 | AI33: 0 | AJ33: 0 | AK33: 0 | AL33: 0
A34: 3. CUM TABLE - paste into VEDA
A35: TFM_INS
A36: pset_pn | B36: Attribute | C36: cset_cn | D36: Africa_North | E36: Africa_Other | F36: Australia | G36: Austria | H36: Baltics | I36: BeNeLux | J36: Brazil | K36: China | L36: CroSloven | M36: CzechSlovak | N36: France | O36: Germany | P36: GreeceCyp | Q36: HunRomBul | R36: Iceland | S36: India | T36: Ireland | U36: ItalyMal | V36: Japan | W36: LatAm | X36: MidEast | Y36: NorthAm | Z36: Norway | AA36: Poland | AB36: ROW | AC36: Russia | AD36: SaudiArabia | AE36: SouthAfrica | AF36: SpainPor | AG36: SweFinDen | AH36: Switzerland | AI36: Turkey | AJ36: UK | AK36: Ukraine | AL36: WestBalkans
A37: MINLiRSV1 | B37: CUM | D37: =D25*$F$12*$H$12 | E37: =E25*$F$12*$H$12 | F37: =F25*$F$12*$H$12 | G37: =G25*$F$12*$H$12 | H37: =H25*$F$12*$H$12 | I37: =I25*$F$12*$H$12 | J37: =J25*$F$12*$H$12 | K37: =K25*$F$12*$H$12 | ... AL37: =AL25*$F$12*$H$12
A38: MINLiRSV2 | B38: CUM | D38: =D25*$F$12*$H$12*$I$12 | E38: =E25*$F$12*$H$12*$I$12 | F38: =F25*$F$12*$H$12*$I$12 | G38: =G25*$F$12*$H$12*$I$12 | H38: =H25*$F$12*$H$12*$I$12 | I38: =I25*$F$12*$H$12*$I$12 | J38: =J25*$F$12*$H$12*$I$12 | K38: =K25*$F$12*$H$12*$I$12 | ... AL38: =AL25*$F$12*$H$12*$I$12
A39: MINLiRSV3 | B39: CUM | D39: =D25*$F$12*$H$12*$J$12 | E39: =E25*$F$12*$H$12*$J$12 | F39: =F25*$F$12*$H$12*$J$12 | G39: =G25*$F$12*$H$12*$J$12 | H39: =H25*$F$12*$H$12*$J$12 | I39: =I25*$F$12*$H$12*$J$12 | J39: =J25*$F$12*$H$12*$J$12 | K39: =K25*$F$12*$H$12*$J$12 | ... AL39: =AL25*$F$12*$H$12*$J$12
A41: MINCoRSV1 | B41: CUM | D41: =D26*$F$13*$H$13 | E41: =E26*$F$13*$H$13 | F41: =F26*$F$13*$H$13 | G41: =G26*$F$13*$H$13 | H41: =H26*$F$13*$H$13 | I41: =I26*$F$13*$H$13 | J41: =J26*$F$13*$H$13 | K41: =K26*$F$13*$H$13 | ... AL41: =AL26*$F$13*$H$13
A42: MINCoRSV2 | B42: CUM | D42: =D26*$F$13*$H$13*$I$13 | E42: =E26*$F$13*$H$13*$I$13 | F42: =F26*$F$13*$H$13*$I$13 | G42: =G26*$F$13*$H$13*$I$13 | H42: =H26*$F$13*$H$13*$I$13 | I42: =I26*$F$13*$H$13*$I$13 | J42: =J26*$F$13*$H$13*$I$13 | K42: =K26*$F$13*$H$13*$I$13 | ... AL42: =AL26*$F$13*$H$13*$I$13
A43: MINCoRSV3 | B43: CUM | D43: =D26*$F$13*$H$13*$J$13 | E43: =E26*$F$13*$H$13*$J$13 | F43: =F26*$F$13*$H$13*$J$13 | G43: =G26*$F$13*$H$13*$J$13 | H43: =H26*$F$13*$H$13*$J$13 | I43: =I26*$F$13*$H$13*$J$13 | J43: =J26*$F$13*$H$13*$J$13 | K43: =K26*$F$13*$H$13*$J$13 | ... AL43: =AL26*$F$13*$H$13*$J$13
A45: MINNiRSV1 | B45: CUM | D45: =D27*$F$14*$H$14 | E45: =E27*$F$14*$H$14 | F45: =F27*$F$14*$H$14 | G45: =G27*$F$14*$H$14 | H45: =H27*$F$14*$H$14 | I45: =I27*$F$14*$H$14 | J45: =J27*$F$14*$H$14 | K45: =K27*$F$14*$H$14 | ... AL45: =AL27*$F$14*$H$14
...

Sheet Codex_sources
A1: Auditable source parameters for redesigned mining supply curves
A2: Units: BNDACT kt/yr; CUM kt; COST million USD/kt. Formulas in Codex_calc link to these rows.
A4: Material | B4: Prefix | C4: Commodity | D4: ScopeFactor | E4: Scope numerator kt/yr | F4: World production kt/yr | G4: World reserves kt | H4: Resource total / midpoint kt | I4: Extra high/undiscovered kt | J4: RSV1 multiplier | K4: RSV2 multiplier | L4: RSV3 multiplier | M4: Cost RSV1 | N4: Cost RSV2 | O4: Cost RSV3 | P4: Cost source | Q4: Quantity source | R4: Notes
A5: Li | B5: MINLi | C5: m_lithium | D5: 0.88 | F5: 290 | G5: 37000 | H5: 150000 | J5: stage from deposit data | K5: stage from deposit data | L5: stage from deposit data | M5: 13.86 | N5: 22.45 | O5: 27.69 | P5: Busch et al. 2025 Supplementary Data S2; project extraction costs converted to MUSD/kt Li; RSV1/RSV2/RSV3 use approximately p25/p75/p90. | Q5: Busch et al. 2025 Supplementary Data S2 for deposit reserves/resources/capacity; USGS MCS 2026 for 88% battery end-use share. | R5: CUM uses deposit reserve/demonstrated/inferred stages. BNDACT uses 2030 deposit capacity split 1:2 across RSV1/RSV2.
A6: Ni | B6: MINNi | C6: m_nickel | D6: =E6/F6 | E6: 555 | F6: 3900 | G6: 140000 | H6: 350000 | I6: 0 | J6: 1 | K6: =(H6-G6)/(2*G6) | L6: =(H6-G6)/(2*G6) | M6: 14.288 | N6: 23.139 | O6: =N6*1.1 | P6: Peiseler et al. 2024 Nature Communications Source Data Fig. 4 all-in-cost Q1/Q3/max. | Q6: USGS MCS 2026 nickel production/reserves/resources. | R6: Seabed nickel resources are not included in the base curve.
A7: Co | B7: MINCo | C7: m_cobalt | D7: =E7/F7 | E7: 220.172 | F7: 310 | G7: 12000 | H7: 25000 | I7: 0 | J7: 1 | K7: =(H7-G7)/(2*G7) | L7: =(H7-G7)/(2*G7) | M7: 29.844 | N7: 42.509 | O7: =N7*1.1 | P7: Peiseler et al. 2024 Nature Communications Source Data Fig. 4 all-in-cost Q1/Q3/max. | Q7: USGS MCS 2026 cobalt production/reserves/resources. | R7: Seafloor cobalt is excluded; cobalt by-product coupling is not represented here.
A8: Mn | B8: MINMn | C8: m_manganese | D8: =E8/F8 | E8: 202 | F8: 20000 | G8: 1800000 | H8: 17000000 | I8: 0 | J8: 1 | K8: =(H8-G8)/(2*G8) | L8: =(H8-G8)/(2*G8) | M8: =4.5*100/1000 | N8: =M8*3 | O8: =N8*1.1 | P8: USGS MCS 2026 manganese ore price, 4.50 USD/metric ton unit Mn; tier multipliers are assumptions. | Q8: USGS MCS 2026 manganese production/reserves; USGS Professional Paper 1802-L for 17 billion t land resources. | R8: Cost is a price proxy, not mine-level OPEX.
A9: Al | B9: MINAl | C9: m_aluminum | D9: =E9/F9 | E9: 1486.28 | F9: 74000 | G9: 7250000 | H9: 16250000 | I9: 2500000 | J9: 1 | K9: =(H9-G9)/G9 | L9: =I9/G9 | M9: =180/100*2204.62/1000 | N9: =M9*3 | O9: =N9*1.1 | P9: USGS MCS 2026 aluminum ingot U.S. market spot price, 180 cents/lb; tier multipliers are assumptions. | Q9: USGS MCS 2026 aluminum production; bauxite reserves/resources converted using 4 t bauxite = 1 t Al. | R9: CUM is bauxite-derived aluminum equivalent, while BNDACT uses primary aluminum smelter production.
A10: Cu | B10: MINCu | C10: m_copper | D10: =E10/F10 | E10: 570 | F10: 23000 | G10: 980000 | H10: 1500000 | I10: 3500000 | J10: 1 | K10: =(H10-G10)/G10 | L10: =I10/G10 | M10: =440/100*2204.62/1000 | N10: =M10*3 | O10: =N10*1.1 | P10: USGS MCS 2026 LME grade A cash copper price, 440 cents/lb; tier multipliers are assumptions. | Q10: USGS MCS 2026 copper production/reserves; USGS global copper resource assessment cited by MCS for identified/undiscovered resources. | R10: Copper RSV3 represents undiscovered resources allocated by current reserve geography.
A11: Gr | B11: MINGr | C11: m_graphite | D11: =E11/F11 | E11: 1467.63 | F11: 1800 | G11: 310000 | H11: 800000 | I11: 0 | J11: 1 | K11: =(H11-G11)/(2*G11) | L11: =(H11-G11)/(2*G11) | M11: 1 | N11: 2.6 | O11: =N11*1.1 | P11: USGS MCS 2026 natural graphite import values for flake/lump; Benchmark 2025 article for battery-grade anode graphite high-cost proxy. | Q11: USGS MCS 2026 natural graphite production/reserves/resources. | R11: Synthetic graphite is not a mined reserve; RSV3 cost is a battery-grade anode proxy.
A14: Primary source links
A15: USGS MCS 2026 | B15: https://doi.org/10.3133/mcs2026 | M15: 13.86 | N15: 22.45 | O15: 27.69
A16: Busch et al. 2025 | B16: https://doi.org/10.1038/s41893-025-01561-5 | M16: 14.288 | N16: 23.139 | O16: 73.349
A17: Busch et al. 2025 data/code | B17: https://doi.org/10.5281/zenodo.14532951 | M17: 29.844 | N17: 42.509 | O17: 94.182
A18: Peiseler et al. 2024 | B18: https://doi.org/10.1038/s41467-024-54634-y | M18: 0.45 | N18: 1.35 | O18: 2.25
A19: Benchmark graphite article | B19: https://source.benchmarkminerals.com/article/price-correction-benchmark-to-continue-publication-of-previous-high-energy-anode-grades-and-launch-new-high-charging-rate-for-ev-variants-reversing-15-october-change-to-specifications | M19: 3.968316 | N19: 11.904948 | O19: 19.84158
A20: USGS manganese PP1802-L | B20: https://doi.org/10.3133/pp1802L | M20: 9.700328 | N20: 29.100984 | O20: 48.50164
M21: 1 | N21: 2.6 | O21: 7.245

Sheet Codex_USGS_raw
A1: Material | B1: Country | C1: TIMES region | D1: Production kt/yr | E1: Reserves kt | F1: Source | G1: Notes
A2: Ni | B2: United States | C2: NorthAm | D2: 10 | E2: 340 | F2: USGS Mineral Commodity Summaries 2026; individual commodity chapters.
A3: Ni | B3: Australia | C3: Australia | D3: 45 | E3: 25000 | F3: USGS Mineral Commodity Summaries 2026; individual commodity chapters.
A4: Ni | B4: Brazil | C4: Brazil | D4: 70 | E4: 16000 | F4: USGS Mineral Commodity Summaries 2026; individual commodity chapters.
A5: Ni | B5: Canada | C5: NorthAm | D5: 140 | E5: 2200 | F5: USGS Mineral Commodity Summaries 2026; individual commodity chapters.
A6: Ni | B6: China | C6: China | D6: 120 | E6: 4400 | F6: USGS Mineral Commodity Summaries 2026; individual commodity chapters.
A7: Ni | B7: Indonesia | C7: ROW | D7: 2600 | E7: 62000 | F7: USGS Mineral Commodity Summaries 2026; individual commodity chapters.
A8: Ni | B8: New Caledonia | C8: ROW | D8: 140 | E8: 7100 | F8: USGS Mineral Commodity Summaries 2026; individual commodity chapters.
A9: Ni | B9: Philippines | C9: ROW | D9: 270 | E9: 4800 | F9: USGS Mineral Commodity Summaries 2026; individual commodity chapters.
A10: Ni | B10: Russia | C10: Russia | D10: 200 | E10: 8300 | F10: USGS Mineral Commodity Summaries 2026; individual commodity chapters.
A11: Ni | B11: Other countries | C11: ROW | D11: 290 | E11: 9100 | F11: USGS Mineral Commodity Summaries 2026; individual commodity chapters.
A12: Co | B12: United States | C12: NorthAm | D12: 0.3 | E12: 70 | F12: USGS Mineral Commodity Summaries 2026; individual commodity chapters.
A13: Co | B13: Australia | C13: Australia | D13: 3.7 | E13: 1700 | F13: USGS Mineral Commodity Summaries 2026; individual commodity chapters.
... A71: Gr | B71: Vietnam | C71: ROW | D71: 0.5 | E71: 9700 | F71: USGS Mineral Commodity Summaries 2026; individual commodity chapters.
A72: Al | B72: United States | C72: NorthAm | D72: 660 | E72: 5000 | F72: USGS Mineral Commodity Summaries 2026; individual commodity chapters. | G72: Production is primary Al smelter; reserves are bauxite/4.
A73: Al | B73: Australia | C73: Australia | D73: 1500 | E73: 925000 | F73: USGS Mineral Commodity Summaries 2026; individual commodity chapters. | G73: Australia bauxite reserve is 3.7 billion t in USGS MCS 2026; converted using 4 t bauxite = 1 t Al.
A74: Al | B74: Bahrain | C74: MidEast | D74: 1600 | E74: 0 | F74: USGS Mineral Commodity Summaries 2026; individual commodity chapters.
A75: Al | B75: Brazil | C75: Brazil | D75: 1200 | E75: 425000 | F75: USGS Mineral Commodity Summaries 2026; individual commodity chapters.
A76: Al | B76: Canada | C76: NorthAm | D76: 3300 | E76: 0 | F76: USGS Mineral Commodity Summaries 2026; individual commodity chapters.
A77: Al | B77: China | C77: China | D77: 45000 | E77: 177500 | F77: USGS Mineral Commodity Summaries 2026; individual commodity chapters.
A78: Al | B78: Greece | C78: GreeceCyp | D78: 0 | E78: 0 | F78: USGS Mineral Commodity Summaries 2026; individual commodity chapters.
A79: Al | B79: Guinea | C79: Africa_Other | D79: 0 | E79: 1850000 | F79: USGS Mineral Commodity Summaries 2026; individual commodity chapters.
A80: Al | B80: Iceland | C80: Iceland | D80: 750 | E80: 0 | F80: USGS Mineral Commodity Summaries 2026; individual commodity chapters.
A81: Al | B81: India | C81: India | D81: 4200 | E81: 162500 | F81: USGS Mineral Commodity Summaries 2026; individual commodity chapters.
A82: Al | B82: Indonesia | C82: ROW | D82: 0 | E82: 725000 | F82: USGS Mineral Commodity Summaries 2026; individual commodity chapters.
A83: Al | B83: Ireland | C83: Ireland | D83: 0 | E83: 0 | F83: USGS Mineral Commodity Summaries 2026; individual commodity chapters.
A84: Al | B84: Jamaica | C84: LatAm | D84: 0 | E84: 500000 | F84: USGS Mineral Commodity Summaries 2026; individual commodity chapters.
A85: Al | B85: Kazakhstan | C85: ROW | D85: 0 | E85: 40000 | F85: USGS Mineral Commodity Summaries 2026; individual commodity chapters.
... A94: Al | B94: Other countries | C94: ROW | D94: 7000 | E94: 1325000 | F94: USGS Mineral Commodity Summaries 2026; individual commodity chapters.

Sheet Codex_Li_Busch
A1: Source row in Data S2 | B1: Deposit | C1: Country | D1: TIMES region | E1: Resource type | F1: Resource total kt Li | G1: Reserve kt Li | H1: Demonstrated kt Li | I1: Inferred kt Li | J1: 2030 capacity kt Li/yr | K1: Extraction Cost Original | L1: Extraction Cost Unit | M1: Inflation Adjustment 2022 | N1: Source workbook
A2: 6 | B2: Salar de Atacama (SQM) | C2: Chile | D2: LatAm | E2: Brine | F2: 10800 | G2: 360 | H2: 7840 | I2: 2600 | J2: 39.451437 | K2: 3990 | L2: USD/tonne LCE | M2: 1 | N2: Busch et al. 2025 Supplementary Data S2
A3: 7 | B3: Salar de Uyuni | C3: Bolivia | D3: LatAm | E3: Brine | F3: 10206.52 | G3: 5400 | H3: 4806.52 | I3: 0 | J3: 9.3931993 | M3: 1.1183216 | N3: Busch et al. 2025 Supplementary Data S2
A4: 8 | B4: Salton Sea (All) | C4: United States | D4: NorthAm | E4: Brine | F4: 6760 | G4: 0 | H4: 3360 | I4: 3400 | J4: 0 | M4: 0.9199632 | N4: Busch et al. 2025 Supplementary Data S2
A5: 9 | B5: Upper Rhine Valley | C5: Germany | D5: Germany | E5: Brine | F5: 5210.2604 | G5: 106.8993 | H5: 2006.4754 | I5: 3096.8858 | J5: 3.9676874 | K5: 4223.1 | L5: USD/tonne LHM (LiOH.H2O) | M5: 0.9199632 | N5: Busch et al. 2025 Supplementary Data S2
A6: 10 | B6: Cauchari | C6: Argentina | D6: LatAm | E6: Brine | F6: 4617 | G6: 682.92 | H6: 3046.78 | I6: 887.3 | J6: 7.5145595 | K6: 3579 | L6: USD/tonne LCE | M6: 1.1183216 | N6: Busch et al. 2025 Supplementary Data S2
A7: 11 | B7: Titan | C7: Tanzania | D7: Africa_Other | E7: Volcano-Sedimentary | F7: 4426 | G7: 0 | H7: 0 | I7: 4426 | J7: 0 | M7: 0.9199632 | N7: Busch et al. 2025 Supplementary Data S2
A8: 12 | B8: Salar de Olaroz (Allkem) | C8: Argentina | D8: LatAm | E8: Brine | F8: 4250 | G8: 0 | H8: 2890 | I8: 1360 | J8: 7.9842194 | K8: 4149 | L8: USD/tonne LCE | M8: 0.9199632 | N8: Busch et al. 2025 Supplementary Data S2
A9: 13 | B9: McDermitt | C9: United States | D9: NorthAm | E9: Volcano-Sedimentary | F9: 4039.2528 | G9: 0 | H9: 2085.3817 | I9: 1953.8711 | J9: 0 | M9: 0.9199632 | N9: Busch et al. 2025 Supplementary Data S2
A10: 14 | B10: Thacker Pass | C10: United States | D10: NorthAm | E10: Volcano-Sedimentary | F10: 3588.3595 | G10: 695.12723 | H10: 2329.6156 | I10: 563.61668 | J10: 14.277663 | K10: 7198 | L10: USD/tonne LCE | M10: 1 | N10: Busch et al. 2025 Supplementary Data S2
A11: 15 | B11: Bonnie Claire | C11: United States | D11: NorthAm | E11: Hard Rock | F11: 3452 | G11: 0 | H11: 0 | I11: 3452 | J11: 6.0680068 | K11: 5974 | L11: USD/tonne LCE | M11: 1.047 | N11: Busch et al. 2025 Supplementary Data S2
A12: 16 | B12: Manono-Kitotolo | C12: DR Congo | D12: Africa_Other | E12: Hard Rock | F12: 3065.8635 | G12: 682.85141 | H12: 1378.9418 | I12: 1004.0703 | J12: 19.512681 | K12: 346 | L12: USD/tonne of SC6 | M12: 1.080504 | N12: Busch et al. 2025 Supplementary Data S2
A13: 17 | B13: Salar del Hombre Muerto (POSCO) | C13: Argentina | D13: LatAm | E13: Brine | F13: 2539.4689 | G13: 2539.4689 | H13: 0 | I13: 0 | J13: 0 | K13: 3650 | L13: USD/tonne LCE | M13: 0.9199632 | N13: Busch et al. 2025 Supplementary Data S2
A14: 18 | B14: Greenbushes | C14: Australia | D14: Australia | E14: Hard Rock | F14: 2509.8273 | G14: 1668.573 | H14: 348.4943 | I14: 492.76005 | J14: 70.803119 | K14: 233.1193 | L14: USD2022/ t concentrate SC6 | M14: 1 | N14: Busch et al. 2025 Supplementary Data S2
A15: 19 | B15: Salar del Hombre Muerto (Livent) | C15: Argentina | D15: LatAm | E15: Brine | F15: 2220 | G15: 731 | H15: 597 | I15: 892 | J15: 18.786399 | K15: 4700 | L15: USD/tonne LCE | M15: 0.9199632 | N15: Busch et al. 2025 Supplementary Data S2
A16: 20 | B16: Pilgangoora | C16: Australia | D16: Australia | E16: Hard Rock | F16: 2210.534 | G16: 1184.0643 | H16: 1026.4697 | I16: 0 | J16: 26.481495 | K16: 931 | L16: USD2022/ t spodumene at 5.3% | M16: 0.9199632 | N16: Busch et al. 2025 Supplementary Data S2
A17: 21 | B17: Qaidam Basin (All Projects) | C17: China | D17: China | E17: Brine | F17: 2021.4625 | G17: 0 | H17: 0 | I17: 2021.4625 | J17: 11.37 | M17: 0.9199632 | N17: Busch et al. 2025 Supplementary Data S2
A18: 22 | B18: Kachi | C18: Argentina | D18: LatAm | E18: Brine | F18: 1991.4456 | G18: 117.4 | H18: 1254.0672 | I18: 619.97834 | J18: 6.5752395 | K18: 6047 | L18: USD/tonne LCE | M18: 0.9199632 | N18: Busch et al. 2025 Supplementary Data S2
A19: 23 | B19: Centenario Ratones | C19: Argentina | D19: LatAm | E19: Brine | F19: 1867.0742 | G19: 208.8 | H19: 777.34131 | I19: 880.93286 | J19: 4.5087357 | K19: 3500 | L19: USD/tonne LCE | M19: 1.080504 | N19: Busch et al. 2025 Supplementary Data S2
A20: 24 | B20: TLC | C20: United States | D20: NorthAm | E20: Volcano-Sedimentary | F20: 1660.04 | G20: 0 | H20: 0 | I20: 1660.04 | J20: 6.8570355 | M20: 1 | N20: Busch et al. 2025 Supplementary Data S2
A21: 25 | B21: Salar del Rincon (Rio Tinto) | C21: Argentina | D21: LatAm | E21: Brine | F21: 1559.3395 | G21: 225.44667 | H21: 432.10612 | I21: 901.78668 | J21: 9.3931993 | K21: 2968 | L21: USD/tonne LCE | M21: 0.9199632 | N21: Busch et al. 2025 Supplementary Data S2
A22: 26 | B22: Mariana | C22: Argentina | D22: LatAm | E22: Brine | F22: 1525.5225 | G22: 0 | H22: 0 | I22: 1525.5225 | J22: 3.1936878 | M22: 1 | N22: Busch et al. 2025 Supplementary Data S2
A23: 27 | B23: Salar de Atacama (Albemarle) | C23: Chile | D23: LatAm | E23: Brine | F23: 1491 | G23: 647 | H23: 712 | I23: 132 | J23: 15.780575 | K23: 3552 | L23: USD/tonne LCE | M23: 0.9199632 | N23: Busch et al. 2025 Supplementary Data S2
A24: 28 | B24: Wodgina | C24: Australia | D24: Australia | E24: Hard Rock | F24: 1408.9686 | G24: 825.56735 | H24: 246.11923 | I24: 337.28207 | J24: 20.665039 | M24: 1.1585812 | N24: Busch et al. 2025 Supplementary Data S2
A25: 29 | B25: Cinovec | C25: Czech Republic | D25: CzechSlovak | E25: Hard Rock | F25: 1388.3757 | G25: 0 | H25: 851.06118 | I25: 537.31456 | J25: 4.8581627 | K25: 610.78652 | L25: USD/tonne SC 6% | M25: 0.9199632 | N25: Busch et al. 2025 Supplementary Data S2
A26: 30 | B26: Clayton Valley (Century) | C26: United States | D26: NorthAm | E26: Volcano-Sedimentary | F26: 1359.5 | G26: 240.9 | H26: 939 | I26: 179.6 | J26: 5.1474732 | K26: 3387 | L26: USD/tonne LCE | M26: 1.080504 | N26: Busch et al. 2025 Supplementary Data S2
A27: 31 | B27: Sonora | C27: Mexico | D27: NorthAm | E27: Volcano-Sedimentary | F27: 1353.2436 | G27: 391.33785 | H27: 447.1359 | I27: 514.7699 | J27: 3.7572797 | K27: 2126 | L27: USD/tonne LCE | M27: 1.2291284 | N27: Busch et al. 2025 Supplementary Data S2
A28: 32 | B28: Sal de Vida | C28: Argentina | D28: LatAm | E28: Brine | F28: 1340 | G28: 467 | H28: 753 | I28: 120 | J28: 8.3888785 | K28: 4529 | L28: USD/tonne LCE | M28: 0.9199632 | N28: Busch et al. 2025 Supplementary Data S2
A29: 33 | B29: Mt. Holland/Earl Grey | C29: Australia | D29: Australia | E29: Hard Rock | F29: 1320.5046 | G29: 656.37349 | H29: 576.47523 | I29: 87.655823 | J29: 8.2966372 | K29: 155.4 | L29: USD/t concentrate SC5.5 | M29: 1.1183216 | N29: Busch et al. 2025 Supplementary Data S2
A30: 34 | B30: Tres Quebradas | C30: Argentina | D30: LatAm | E30: Brine | F30: 1315.1056 | G30: 244.23389 | H30: 507.25501 | I30: 563.61668 | J30: 3.7572797 | K30: 2914 | L30: USD/tonne LCE | M30: 1.047 | N30: Busch et al. 2025 Supplementary Data S2
A31: 35 | B31: Hombre Muerto West (Galan) | C31: Argentina | D31: LatAm | E31: Brine | F31: 1237 | G31: 70.2 | H31: 1004.8 | I31: 162 | J31: 0 | K31: 3963 | L31: USD/tonne LCE | M31: 0.9199632 | N31: Busch et al. 2025 Supplementary Data S2
A32: 36 | B32: Jadar | C32: Serbia | D32: WestBalkans | E32: Volcano-Sedimentary | F32: 1199.8675 | G32: 139.57111 | H32: 574.49636 | I32: 485.8 | J32: 9.8065001 | M32: 1 | N32: Busch et al. 2025 Supplementary Data S2
A33: 37 | B33: Praire | C33: Canada | D33: NorthAm | E33: Brine | F33: 1190 | G33: 0 | H33: 850 | I33: 340 | J33: 0 | K33: 2819 | L33: USD/tonne LCE | M33: 0.9199632 | N33: Busch et al. 2025 Supplementary Data S2
A34: 38 | B34: Zeus (Noram) | C34: United States | D34: NorthAm | E34: Volcano-Sedimentary | F34: 1176.757 | G34: 0 | H34: 972.079 | I34: 204.678 | J34: 5.9928612 | K34: 3355 | L34: USD/tonne LCE | M34: 1.047 | N34: Busch et al. 2025 Supplementary Data S2
A35: 39 | B35: Boardwalk | C35: Canada | D35: NorthAm | E35: Brine | F35: 1151 | G35: 0 | H35: 0 | I35: 1151 | J35: 5.1827917 | K35: 4533 | L35: USD/tonne LHM (LiOH.H2O) | M35: 0.86138877 | N35: Busch et al. 2025 Supplementary Data S2
A36: 40 | B36: Salar de Cauchari (Allkem) | C36: Argentina | D36: LatAm | E36: Brine | F36: 1120 | G36: 212 | H36: 623 | I36: 285 | J36: 0 | K36: 4081 | L36: USD/tonne LCE | M36: 0.9199632 | N36: Busch et al. 2025 Supplementary Data S2
A37: 41 | B37: Titan 2 | C37: Tanzania | D37: Africa_Other | E37: Volcano-Sedimentary | F37: 1102 | G37: 0 | H37: 0 | I37: 1102 | J37: 0 | M37: 0.9199632 | N37: Busch et al. 2025 Supplementary Data S2
A38: 42 | B38: Kathleen Valley | C38: Australia | D38: Australia | E38: Hard Rock | F38: 992.68942 | G38: 426.08209 | H38: 405.41724 | I38: 161.19009 | J38: 16.94815 | M38: 1.047 | N38: Busch et al. 2025 Supplementary Data S2
A39: 43 | B39: Nuristan | C39: Afghanistan | D39: ROW | E39: Hard Rock | F39: 987.03365 | G39: 0 | H39: 0 | I39: 987.03365 | J39: 0 | N39: Busch et al. 2025 Supplementary Data S2
A40: 44 | B40: Diablillios/Sal de Los Angeles | C40: Argentina | D40: LatAm | E40: Brine | F40: 930 | G40: 0 | H40: 0 | I40: 930 | J40: 9.3931993 | M40: 1.2291284 | N40: Busch et al. 2025 Supplementary Data S2
...

Sheet Codex_calc
A1: Calculation layer linked by the original scenario sheet
A2: Columns C:AO mirror the scenario table. Region cells contain formulas against Codex_sources, Codex_USGS_raw, and Codex_Li_Busch.
C4: pset_pn | D4: Attribute | E4: cset_cn | F4: Africa_North | G4: Africa_Other | H4: Australia | I4: Austria | J4: Baltics | K4: BeNeLux | L4: Brazil | M4: China | N4: CroSloven | O4: CzechSlovak | P4: France | Q4: Germany | R4: GreeceCyp | S4: HunRomBul | T4: Iceland | U4: India | V4: Ireland | W4: ItalyMal | X4: Japan | Y4: LatAm | Z4: MidEast | AA4: NorthAm | AB4: Norway | AC4: Poland | AD4: ROW | AE4: Russia | AF4: SaudiArabia | AG4: SouthAfrica | AH4: SpainPor | AI4: SweFinDen | AJ4: Switzerland | AK4: Turkey | AL4: UK | AM4: Ukraine | AN4: WestBalkans | AO4: year
C41: MINLiRSV1 | D41: BNDACT | F41: =SUMIFS(Codex_Li_Busch!$J$2:$J$161,Codex_Li_Busch!$D$2:$D$161,F$4)*Codex_sources!$D$5/3 | G41: =SUMIFS(Codex_Li_Busch!$J$2:$J$161,Codex_Li_Busch!$D$2:$D$161,G$4)*Codex_sources!$D$5/3 | H41: =SUMIFS(Codex_Li_Busch!$J$2:$J$161,Codex_Li_Busch!$D$2:$D$161,H$4)*Codex_sources!$D$5/3 | I41: =SUMIFS(Codex_Li_Busch!$J$2:$J$161,Codex_Li_Busch!$D$2:$D$161,I$4)*Codex_sources!$D$5/3 | J41: =SUMIFS(Codex_Li_Busch!$J$2:$J$161,Codex_Li_Busch!$D$2:$D$161,J$4)*Codex_sources!$D$5/3 | K41: =SUMIFS(Codex_Li_Busch!$J$2:$J$161,Codex_Li_Busch!$D$2:$D$161,K$4)*Codex_sources!$D$5/3 | L41: =SUMIFS(Codex_Li_Busch!$J$2:$J$161,Codex_Li_Busch!$D$2:$D$161,L$4)*Codex_sources!$D$5/3 | M41: =SUMIFS(Codex_Li_Busch!$J$2:$J$161,Codex_Li_Busch!$D$2:$D$161,M$4)*Codex_sources!$D$5/3 | ... AN41: =SUMIFS(Codex_Li_Busch!$J$2:$J$161,Codex_Li_Busch!$D$2:$D$161,AN$4)*Codex_sources!$D$5/3 | AO41: 2019, 2130
C42: MINLiRSV1 | D42: CUM | F42: =SUMIFS(Codex_Li_Busch!$G$2:$G$161,Codex_Li_Busch!$D$2:$D$161,F$4)*Codex_sources!$D$5 | G42: =SUMIFS(Codex_Li_Busch!$G$2:$G$161,Codex_Li_Busch!$D$2:$D$161,G$4)*Codex_sources!$D$5 | H42: =SUMIFS(Codex_Li_Busch!$G$2:$G$161,Codex_Li_Busch!$D$2:$D$161,H$4)*Codex_sources!$D$5 | I42: =SUMIFS(Codex_Li_Busch!$G$2:$G$161,Codex_Li_Busch!$D$2:$D$161,I$4)*Codex_sources!$D$5 | J42: =SUMIFS(Codex_Li_Busch!$G$2:$G$161,Codex_Li_Busch!$D$2:$D$161,J$4)*Codex_sources!$D$5 | K42: =SUMIFS(Codex_Li_Busch!$G$2:$G$161,Codex_Li_Busch!$D$2:$D$161,K$4)*Codex_sources!$D$5 | L42: =SUMIFS(Codex_Li_Busch!$G$2:$G$161,Codex_Li_Busch!$D$2:$D$161,L$4)*Codex_sources!$D$5 | M42: =SUMIFS(Codex_Li_Busch!$G$2:$G$161,Codex_Li_Busch!$D$2:$D$161,M$4)*Codex_sources!$D$5 | ... AN42: =SUMIFS(Codex_Li_Busch!$G$2:$G$161,Codex_Li_Busch!$D$2:$D$161,AN$4)*Codex_sources!$D$5 | AO42: =AO41
C43: MINLiRSV1 | D43: COST | E43: m_lithium | F43: =Codex_Regional!F7 | G43: =Codex_Regional!G7 | H43: =Codex_Regional!H7 | I43: =Codex_Regional!I7 | J43: =Codex_Regional!J7 | K43: =Codex_Regional!K7 | L43: =Codex_Regional!L7 | M43: =Codex_Regional!M7 | ... AN43: =Codex_Regional!AN7 | AO43: =AO42
C44: MINLiRSV2 | D44: BNDACT | F44: =SUMIFS(Codex_Li_Busch!$J$2:$J$161,Codex_Li_Busch!$D$2:$D$161,F$4)*Codex_sources!$D$5*2/3 | G44: =SUMIFS(Codex_Li_Busch!$J$2:$J$161,Codex_Li_Busch!$D$2:$D$161,G$4)*Codex_sources!$D$5*2/3 | H44: =SUMIFS(Codex_Li_Busch!$J$2:$J$161,Codex_Li_Busch!$D$2:$D$161,H$4)*Codex_sources!$D$5*2/3 | I44: =SUMIFS(Codex_Li_Busch!$J$2:$J$161,Codex_Li_Busch!$D$2:$D$161,I$4)*Codex_sources!$D$5*2/3 | J44: =SUMIFS(Codex_Li_Busch!$J$2:$J$161,Codex_Li_Busch!$D$2:$D$161,J$4)*Codex_sources!$D$5*2/3 | K44: =SUMIFS(Codex_Li_Busch!$J$2:$J$161,Codex_Li_Busch!$D$2:$D$161,K$4)*Codex_sources!$D$5*2/3 | L44: =SUMIFS(Codex_Li_Busch!$J$2:$J$161,Codex_Li_Busch!$D$2:$D$161,L$4)*Codex_sources!$D$5*2/3 | M44: =SUMIFS(Codex_Li_Busch!$J$2:$J$161,Codex_Li_Busch!$D$2:$D$161,M$4)*Codex_sources!$D$5*2/3 | ... AN44: =SUMIFS(Codex_Li_Busch!$J$2:$J$161,Codex_Li_Busch!$D$2:$D$161,AN$4)*Codex_sources!$D$5*2/3 | AO44: =AO43
C45: MINLiRSV2 | D45: CUM | F45: =SUMIFS(Codex_Li_Busch!$H$2:$H$161,Codex_Li_Busch!$D$2:$D$161,F$4)*Codex_sources!$D$5 | G45: =SUMIFS(Codex_Li_Busch!$H$2:$H$161,Codex_Li_Busch!$D$2:$D$161,G$4)*Codex_sources!$D$5 | H45: =SUMIFS(Codex_Li_Busch!$H$2:$H$161,Codex_Li_Busch!$D$2:$D$161,H$4)*Codex_sources!$D$5 | I45: =SUMIFS(Codex_Li_Busch!$H$2:$H$161,Codex_Li_Busch!$D$2:$D$161,I$4)*Codex_sources!$D$5 | J45: =SUMIFS(Codex_Li_Busch!$H$2:$H$161,Codex_Li_Busch!$D$2:$D$161,J$4)*Codex_sources!$D$5 | K45: =SUMIFS(Codex_Li_Busch!$H$2:$H$161,Codex_Li_Busch!$D$2:$D$161,K$4)*Codex_sources!$D$5 | L45: =SUMIFS(Codex_Li_Busch!$H$2:$H$161,Codex_Li_Busch!$D$2:$D$161,L$4)*Codex_sources!$D$5 | M45: =SUMIFS(Codex_Li_Busch!$H$2:$H$161,Codex_Li_Busch!$D$2:$D$161,M$4)*Codex_sources!$D$5 | ... AN45: =SUMIFS(Codex_Li_Busch!$H$2:$H$161,Codex_Li_Busch!$D$2:$D$161,AN$4)*Codex_sources!$D$5 | AO45: =AO44
C46: MINLiRSV2 | D46: COST | E46: m_lithium | F46: =Codex_Regional!F7*(Codex_sources!$N$5/Codex_sources!$M$5) | G46: =Codex_Regional!G7*(Codex_sources!$N$5/Codex_sources!$M$5) | H46: =Codex_Regional!H7*(Codex_sources!$N$5/Codex_sources!$M$5) | I46: =Codex_Regional!I7*(Codex_sources!$N$5/Codex_sources!$M$5) | J46: =Codex_Regional!J7*(Codex_sources!$N$5/Codex_sources!$M$5) | K46: =Codex_Regional!K7*(Codex_sources!$N$5/Codex_sources!$M$5) | L46: =Codex_Regional!L7*(Codex_sources!$N$5/Codex_sources!$M$5) | M46: =Codex_Regional!M7*(Codex_sources!$N$5/Codex_sources!$M$5) | ... AN46: =Codex_Regional!AN7*(Codex_sources!$N$5/Codex_sources!$M$5) | AO46: =AO45
C47: MINLiRSV3 | D47: BNDACT | AO47: =AO46
C48: MINLiRSV3 | D48: CUM | F48: =SUMIFS(Codex_Li_Busch!$I$2:$I$161,Codex_Li_Busch!$D$2:$D$161,F$4)*Codex_sources!$D$5 | G48: =SUMIFS(Codex_Li_Busch!$I$2:$I$161,Codex_Li_Busch!$D$2:$D$161,G$4)*Codex_sources!$D$5 | H48: =SUMIFS(Codex_Li_Busch!$I$2:$I$161,Codex_Li_Busch!$D$2:$D$161,H$4)*Codex_sources!$D$5 | I48: =SUMIFS(Codex_Li_Busch!$I$2:$I$161,Codex_Li_Busch!$D$2:$D$161,I$4)*Codex_sources!$D$5 | J48: =SUMIFS(Codex_Li_Busch!$I$2:$I$161,Codex_Li_Busch!$D$2:$D$161,J$4)*Codex_sources!$D$5 | K48: =SUMIFS(Codex_Li_Busch!$I$2:$I$161,Codex_Li_Busch!$D$2:$D$161,K$4)*Codex_sources!$D$5 | L48: =SUMIFS(Codex_Li_Busch!$I$2:$I$161,Codex_Li_Busch!$D$2:$D$161,L$4)*Codex_sources!$D$5 | M48: =SUMIFS(Codex_Li_Busch!$I$2:$I$161,Codex_Li_Busch!$D$2:$D$161,M$4)*Codex_sources!$D$5 | ... AN48: =SUMIFS(Codex_Li_Busch!$I$2:$I$161,Codex_Li_Busch!$D$2:$D$161,AN$4)*Codex_sources!$D$5 | AO48: =AO47
C49: MINLiRSV3 | D49: COST | E49: m_lithium | F49: =Codex_Regional!F7*(Codex_sources!$O$5/Codex_sources!$M$5) | G49: =Codex_Regional!G7*(Codex_sources!$O$5/Codex_sources!$M$5) | H49: =Codex_Regional!H7*(Codex_sources!$O$5/Codex_sources!$M$5) | I49: =Codex_Regional!I7*(Codex_sources!$O$5/Codex_sources!$M$5) | J49: =Codex_Regional!J7*(Codex_sources!$O$5/Codex_sources!$M$5) | K49: =Codex_Regional!K7*(Codex_sources!$O$5/Codex_sources!$M$5) | L49: =Codex_Regional!L7*(Codex_sources!$O$5/Codex_sources!$M$5) | M49: =Codex_Regional!M7*(Codex_sources!$O$5/Codex_sources!$M$5) | ... AN49: =Codex_Regional!AN7*(Codex_sources!$O$5/Codex_sources!$M$5) | AO49: =AO48
AO50: =AO49
C51: MINNiRSV1 | D51: BNDACT | F51: =SUMIFS(Codex_USGS_raw!$D$2:$D$94,Codex_USGS_raw!$A$2:$A$94,Codex_sources!$A$6,Codex_USGS_raw!$C$2:$C$94,F$4)*Codex_sources!$D$6*1 | G51: =SUMIFS(Codex_USGS_raw!$D$2:$D$94,Codex_USGS_raw!$A$2:$A$94,Codex_sources!$A$6,Codex_USGS_raw!$C$2:$C$94,G$4)*Codex_sources!$D$6*1 | H51: =SUMIFS(Codex_USGS_raw!$D$2:$D$94,Codex_USGS_raw!$A$2:$A$94,Codex_sources!$A$6,Codex_USGS_raw!$C$2:$C$94,H$4)*Codex_sources!$D$6*1 | I51: =SUMIFS(Codex_USGS_raw!$D$2:$D$94,Codex_USGS_raw!$A$2:$A$94,Codex_sources!$A$6,Codex_USGS_raw!$C$2:$C$94,I$4)*Codex_sources!$D$6*1 | J51: =SUMIFS(Codex_USGS_raw!$D$2:$D$94,Codex_USGS_raw!$A$2:$A$94,Codex_sources!$A$6,Codex_USGS_raw!$C$2:$C$94,J$4)*Codex_sources!$D$6*1 | K51: =SUMIFS(Codex_USGS_raw!$D$2:$D$94,Codex_USGS_raw!$A$2:$A$94,Codex_sources!$A$6,Codex_USGS_raw!$C$2:$C$94,K$4)*Codex_sources!$D$6*1 | L51: =SUMIFS(Codex_USGS_raw!$D$2:$D$94,Codex_USGS_raw!$A$2:$A$94,Codex_sources!$A$6,Codex_USGS_raw!$C$2:$C$94,L$4)*Codex_sources!$D$6*1 | M51: =SUMIFS(Codex_USGS_raw!$D$2:$D$94,Codex_USGS_raw!$A$2:$A$94,Codex_sources!$A$6,Codex_USGS_raw!$C$2:$C$94,M$4)*Codex_sources!$D$6*1 | ... AN51: =SUMIFS(Codex_USGS_raw!$D$2:$D$94,Codex_USGS_raw!$A$2:$A$94,Codex_sources!$A$6,Codex_USGS_raw!$C$2:$C$94,AN$4)*Codex_sources!$D$6*1 | AO51: =AO50
C52: MINNiRSV1 | D52: CUM | F52: =SUMIFS(Codex_USGS_raw!$E$2:$E$94,Codex_USGS_raw!$A$2:$A$94,Codex_sources!$A$6,Codex_USGS_raw!$C$2:$C$94,F$4)*Codex_sources!$D$6*Codex_sources!$J$6 | G52: =SUMIFS(Codex_USGS_raw!$E$2:$E$94,Codex_USGS_raw!$A$2:$A$94,Codex_sources!$A$6,Codex_USGS_raw!$C$2:$C$94,G$4)*Codex_sources!$D$6*Codex_sources!$J$6 | H52: =SUMIFS(Codex_USGS_raw!$E$2:$E$94,Codex_USGS_raw!$A$2:$A$94,Codex_sources!$A$6,Codex_USGS_raw!$C$2:$C$94,H$4)*Codex_sources!$D$6*Codex_sources!$J$6 | I52: =SUMIFS(Codex_USGS_raw!$E$2:$E$94,Codex_USGS_raw!$A$2:$A$94,Codex_sources!$A$6,Codex_USGS_raw!$C$2:$C$94,I$4)*Codex_sources!$D$6*Codex_sources!$J$6 | J52: =SUMIFS(Codex_USGS_raw!$E$2:$E$94,Codex_USGS_raw!$A$2:$A$94,Codex_sources!$A$6,Codex_USGS_raw!$C$2:$C$94,J$4)*Codex_sources!$D$6*Codex_sources!$J$6 | K52: =SUMIFS(Codex_USGS_raw!$E$2:$E$94,Codex_USGS_raw!$A$2:$A$94,Codex_sources!$A$6,Codex_USGS_raw!$C$2:$C$94,K$4)*Codex_sources!$D$6*Codex_sources!$J$6 | L52: =SUMIFS(Codex_USGS_raw!$E$2:$E$94,Codex_USGS_raw!$A$2:$A$94,Codex_sources!$A$6,Codex_USGS_raw!$C$2:$C$94,L$4)*Codex_sources!$D$6*Codex_sources!$J$6 | M52: =SUMIFS(Codex_USGS_raw!$E$2:$E$94,Codex_USGS_raw!$A$2:$A$94,Codex_sources!$A$6,Codex_USGS_raw!$C$2:$C$94,M$4)*Codex_sources!$D$6*Codex_sources!$J$6 | ... AN52: =SUMIFS(Codex_USGS_raw!$E$2:$E$94,Codex_USGS_raw!$A$2:$A$94,Codex_sources!$A$6,Codex_USGS_raw!$C$2:$C$94,AN$4)*Codex_sources!$D$6*Codex_sources!$J$6 | AO52: =AO51
C53: MINNiRSV1 | D53: COST | E53: m_nickel | F53: =Codex_Regional!F10 | G53: =Codex_Regional!G10 | H53: =Codex_Regional!H10 | I53: =Codex_Regional!I10 | J53: =Codex_Regional!J10 | K53: =Codex_Regional!K10 | L53: =Codex_Regional!L10 | M53: =Codex_Regional!M10 | ... AN53: =Codex_Regional!AN10 | AO53: =AO52
C54: MINNiRSV2 | D54: BNDACT | F54: =SUMIFS(Codex_USGS_raw!$D$2:$D$94,Codex_USGS_raw!$A$2:$A$94,Codex_sources!$A$6,Codex_USGS_raw!$C$2:$C$94,F$4)*Codex_sources!$D$6*2 | G54: =SUMIFS(Codex_USGS_raw!$D$2:$D$94,Codex_USGS_raw!$A$2:$A$94,Codex_sources!$A$6,Codex_USGS_raw!$C$2:$C$94,G$4)*Codex_sources!$D$6*2 | H54: =SUMIFS(Codex_USGS_raw!$D$2:$D$94,Codex_USGS_raw!$A$2:$A$94,Codex_sources!$A$6,Codex_USGS_raw!$C$2:$C$94,H$4)*Codex_sources!$D$6*2 | I54: =SUMIFS(Codex_USGS_raw!$D$2:$D$94,Codex_USGS_raw!$A$2:$A$94,Codex_sources!$A$6,Codex_USGS_raw!$C$2:$C$94,I$4)*Codex_sources!$D$6*2 | J54: =SUMIFS(Codex_USGS_raw!$D$2:$D$94,Codex_USGS_raw!$A$2:$A$94,Codex_sources!$A$6,Codex_USGS_raw!$C$2:$C$94,J$4)*Codex_sources!$D$6*2 | K54: =SUMIFS(Codex_USGS_raw!$D$2:$D$94,Codex_USGS_raw!$A$2:$A$94,Codex_sources!$A$6,Codex_USGS_raw!$C$2:$C$94,K$4)*Codex_sources!$D$6*2 | L54: =SUMIFS(Codex_USGS_raw!$D$2:$D$94,Codex_USGS_raw!$A$2:$A$94,Codex_sources!$A$6,Codex_USGS_raw!$C$2:$C$94,L$4)*Codex_sources!$D$6*2 | M54: =SUMIFS(Codex_USGS_raw!$D$2:$D$94,Codex_USGS_raw!$A$2:$A$94,Codex_sources!$A$6,Codex_USGS_raw!$C$2:$C$94,M$4)*Codex_sources!$D$6*2 | ... AN54: =SUMIFS(Codex_USGS_raw!$D$2:$D$94,Codex_USGS_raw!$A$2:$A$94,Codex_sources!$A$6,Codex_USGS_raw!$C$2:$C$94,AN$4)*Codex_sources!$D$6*2 | AO54: =AO53
C55: MINNiRSV2 | D55: CUM | F55: =SUMIFS(Codex_USGS_raw!$E$2:$E$94,Codex_USGS_raw!$A$2:$A$94,Codex_sources!$A$6,Codex_USGS_raw!$C$2:$C$94,F$4)*Codex_sources!$D$6*Codex_sources!$K$6 | G55: =SUMIFS(Codex_USGS_raw!$E$2:$E$94,Codex_USGS_raw!$A$2:$A$94,Codex_sources!$A$6,Codex_USGS_raw!$C$2:$C$94,G$4)*Codex_sources!$D$6*Codex_sources!$K$6 | H55: =SUMIFS(Codex_USGS_raw!$E$2:$E$94,Codex_USGS_raw!$A$2:$A$94,Codex_sources!$A$6,Codex_USGS_raw!$C$2:$C$94,H$4)*Codex_sources!$D$6*Codex_sources!$K$6 | I55: =SUMIFS(Codex_USGS_raw!$E$2:$E$94,Codex_USGS_raw!$A$2:$A$94,Codex_sources!$A$6,Codex_USGS_raw!$C$2:$C$94,I$4)*Codex_sources!$D$6*Codex_sources!$K$6 | J55: =SUMIFS(Codex_USGS_raw!$E$2:$E$94,Codex_USGS_raw!$A$2:$A$94,Codex_sources!$A$6,Codex_USGS_raw!$C$2:$C$94,J$4)*Codex_sources!$D$6*Codex_sources!$K$6 | K55: =SUMIFS(Codex_USGS_raw!$E$2:$E$94,Codex_USGS_raw!$A$2:$A$94,Codex_sources!$A$6,Codex_USGS_raw!$C$2:$C$94,K$4)*Codex_sources!$D$6*Codex_sources!$K$6 | L55: =SUMIFS(Codex_USGS_raw!$E$2:$E$94,Codex_USGS_raw!$A$2:$A$94,Codex_sources!$A$6,Codex_USGS_raw!$C$2:$C$94,L$4)*Codex_sources!$D$6*Codex_sources!$K$6 | M55: =SUMIFS(Codex_USGS_raw!$E$2:$E$94,Codex_USGS_raw!$A$2:$A$94,Codex_sources!$A$6,Codex_USGS_raw!$C$2:$C$94,M$4)*Codex_sources!$D$6*Codex_sources!$K$6 | ... AN55: =SUMIFS(Codex_USGS_raw!$E$2:$E$94,Codex_USGS_raw!$A$2:$A$94,Codex_sources!$A$6,Codex_USGS_raw!$C$2:$C$94,AN$4)*Codex_sources!$D$6*Codex_sources!$K$6 | AO55: =AO54
C56: MINNiRSV2 | D56: COST | E56: m_nickel | F56: =Codex_Regional!F10*(Codex_sources!$N$6/Codex_sources!$M$6) | G56: =Codex_Regional!G10*(Codex_sources!$N$6/Codex_sources!$M$6) | H56: =Codex_Regional!H10*(Codex_sources!$N$6/Codex_sources!$M$6) | I56: =Codex_Regional!I10*(Codex_sources!$N$6/Codex_sources!$M$6) | J56: =Codex_Regional!J10*(Codex_sources!$N$6/Codex_sources!$M$6) | K56: =Codex_Regional!K10*(Codex_sources!$N$6/Codex_sources!$M$6) | L56: =Codex_Regional!L10*(Codex_sources!$N$6/Codex_sources!$M$6) | M56: =Codex_Regional!M10*(Codex_sources!$N$6/Codex_sources!$M$6) | ... AN56: =Codex_Regional!AN10*(Codex_sources!$N$6/Codex_sources!$M$6) | AO56: =AO55
C57: MINNiRSV3 | D57: BNDACT | AO57: =AO56
C58: MINNiRSV3 | D58: CUM | F58: =SUMIFS(Codex_USGS_raw!$E$2:$E$94,Codex_USGS_raw!$A$2:$A$94,Codex_sources!$A$6,Codex_USGS_raw!$C$2:$C$94,F$4)*Codex_sources!$D$6*Codex_sources!$L$6 | G58: =SUMIFS(Codex_USGS_raw!$E$2:$E$94,Codex_USGS_raw!$A$2:$A$94,Codex_sources!$A$6,Codex_USGS_raw!$C$2:$C$94,G$4)*Codex_sources!$D$6*Codex_sources!$L$6 | H58: =SUMIFS(Codex_USGS_raw!$E$2:$E$94,Codex_USGS_raw!$A$2:$A$94,Codex_sources!$A$6,Codex_USGS_raw!$C$2:$C$94,H$4)*Codex_sources!$D$6*Codex_sources!$L$6 | I58: =SUMIFS(Codex_USGS_raw!$E$2:$E$94,Codex_USGS_raw!$A$2:$A$94,Codex_sources!$A$6,Codex_USGS_raw!$C$2:$C$94,I$4)*Codex_sources!$D$6*Codex_sources!$L$6 | J58: =SUMIFS(Codex_USGS_raw!$E$2:$E$94,Codex_USGS_raw!$A$2:$A$94,Codex_sources!$A$6,Codex_USGS_raw!$C$2:$C$94,J$4)*Codex_sources!$D$6*Codex_sources!$L$6 | K58: =SUMIFS(Codex_USGS_raw!$E$2:$E$94,Codex_USGS_raw!$A$2:$A$94,Codex_sources!$A$6,Codex_USGS_raw!$C$2:$C$94,K$4)*Codex_sources!$D$6*Codex_sources!$L$6 | L58: =SUMIFS(Codex_USGS_raw!$E$2:$E$94,Codex_USGS_raw!$A$2:$A$94,Codex_sources!$A$6,Codex_USGS_raw!$C$2:$C$94,L$4)*Codex_sources!$D$6*Codex_sources!$L$6 | M58: =SUMIFS(Codex_USGS_raw!$E$2:$E$94,Codex_USGS_raw!$A$2:$A$94,Codex_sources!$A$6,Codex_USGS_raw!$C$2:$C$94,M$4)*Codex_sources!$D$6*Codex_sources!$L$6 | ... AN58: =SUMIFS(Codex_USGS_raw!$E$2:$E$94,Codex_USGS_raw!$A$2:$A$94,Codex_sources!$A$6,Codex_USGS_raw!$C$2:$C$94,AN$4)*Codex_sources!$D$6*Codex_sources!$L$6 | AO58: =AO57
C59: MINNiRSV3 | D59: COST | E59: m_nickel | F59: =Codex_Regional!F10*(Codex_sources!$O$6/Codex_sources!$M$6) | G59: =Codex_Regional!G10*(Codex_sources!$O$6/Codex_sources!$M$6) | H59: =Codex_Regional!H10*(Codex_sources!$O$6/Codex_sources!$M$6) | I59: =Codex_Regional!I10*(Codex_sources!$O$6/Codex_sources!$M$6) | J59: =Codex_Regional!J10*(Codex_sources!$O$6/Codex_sources!$M$6) | K59: =Codex_Regional!K10*(Codex_sources!$O$6/Codex_sources!$M$6) | L59: =Codex_Regional!L10*(Codex_sources!$O$6/Codex_sources!$M$6) | M59: =Codex_Regional!M10*(Codex_sources!$O$6/Codex_sources!$M$6) | ... AN59: =Codex_Regional!AN10*(Codex_sources!$O$6/Codex_sources!$M$6) | AO59: =AO58
AO60: =AO59
C61: MINCoRSV1 | D61: BNDACT | F61: =SUMIFS(Codex_USGS_raw!$D$2:$D$94,Codex_USGS_raw!$A$2:$A$94,Codex_sources!$A$7,Codex_USGS_raw!$C$2:$C$94,F$4)*Codex_sources!$D$7*1 | G61: =SUMIFS(Codex_USGS_raw!$D$2:$D$94,Codex_USGS_raw!$A$2:$A$94,Codex_sources!$A$7,Codex_USGS_raw!$C$2:$C$94,G$4)*Codex_sources!$D$7*1 | H61: =SUMIFS(Codex_USGS_raw!$D$2:$D$94,Codex_USGS_raw!$A$2:$A$94,Codex_sources!$A$7,Codex_USGS_raw!$C$2:$C$94,H$4)*Codex_sources!$D$7*1 | I61: =SUMIFS(Codex_USGS_raw!$D$2:$D$94,Codex_USGS_raw!$A$2:$A$94,Codex_sources!$A$7,Codex_USGS_raw!$C$2:$C$94,I$4)*Codex_sources!$D$7*1 | J61: =SUMIFS(Codex_USGS_raw!$D$2:$D$94,Codex_USGS_raw!$A$2:$A$94,Codex_sources!$A$7,Codex_USGS_raw!$C$2:$C$94,J$4)*Codex_sources!$D$7*1 | K61: =SUMIFS(Codex_USGS_raw!$D$2:$D$94,Codex_USGS_raw!$A$2:$A$94,Codex_sources!$A$7,Codex_USGS_raw!$C$2:$C$94,K$4)*Codex_sources!$D$7*1 | L61: =SUMIFS(Codex_USGS_raw!$D$2:$D$94,Codex_USGS_raw!$A$2:$A$94,Codex_sources!$A$7,Codex_USGS_raw!$C$2:$C$94,L$4)*Codex_sources!$D$7*1 | M61: =SUMIFS(Codex_USGS_raw!$D$2:$D$94,Codex_USGS_raw!$A$2:$A$94,Codex_sources!$A$7,Codex_USGS_raw!$C$2:$C$94,M$4)*Codex_sources!$D$7*1 | ... AN61: =SUMIFS(Codex_USGS_raw!$D$2:$D$94,Codex_USGS_raw!$A$2:$A$94,Codex_sources!$A$7,Codex_USGS_raw!$C$2:$C$94,AN$4)*Codex_sources!$D$7*1 | AO61: =AO60
C62: MINCoRSV1 | D62: CUM | F62: =SUMIFS(Codex_USGS_raw!$E$2:$E$94,Codex_USGS_raw!$A$2:$A$94,Codex_sources!$A$7,Codex_USGS_raw!$C$2:$C$94,F$4)*Codex_sources!$D$7*Codex_sources!$J$7 | G62: =SUMIFS(Codex_USGS_raw!$E$2:$E$94,Codex_USGS_raw!$A$2:$A$94,Codex_sources!$A$7,Codex_USGS_raw!$C$2:$C$94,G$4)*Codex_sources!$D$7*Codex_sources!$J$7 | H62: =SUMIFS(Codex_USGS_raw!$E$2:$E$94,Codex_USGS_raw!$A$2:$A$94,Codex_sources!$A$7,Codex_USGS_raw!$C$2:$C$94,H$4)*Codex_sources!$D$7*Codex_sources!$J$7 | I62: =SUMIFS(Codex_USGS_raw!$E$2:$E$94,Codex_USGS_raw!$A$2:$A$94,Codex_sources!$A$7,Codex_USGS_raw!$C$2:$C$94,I$4)*Codex_sources!$D$7*Codex_sources!$J$7 | J62: =SUMIFS(Codex_USGS_raw!$E$2:$E$94,Codex_USGS_raw!$A$2:$A$94,Codex_sources!$A$7,Codex_USGS_raw!$C$2:$C$94,J$4)*Codex_sources!$D$7*Codex_sources!$J$7 | K62: =SUMIFS(Codex_USGS_raw!$E$2:$E$94,Codex_USGS_raw!$A$2:$A$94,Codex_sources!$A$7,Codex_USGS_raw!$C$2:$C$94,K$4)*Codex_sources!$D$7*Codex_sources!$J$7 | L62: =SUMIFS(Codex_USGS_raw!$E$2:$E$94,Codex_USGS_raw!$A$2:$A$94,Codex_sources!$A$7,Codex_USGS_raw!$C$2:$C$94,L$4)*Codex_sources!$D$7*Codex_sources!$J$7 | M62: =SUMIFS(Codex_USGS_raw!$E$2:$E$94,Codex_USGS_raw!$A$2:$A$94,Codex_sources!$A$7,Codex_USGS_raw!$C$2:$C$94,M$4)*Codex_sources!$D$7*Codex_sources!$J$7 | ... AN62: =SUMIFS(Codex_USGS_raw!$E$2:$E$94,Codex_USGS_raw!$A$2:$A$94,Codex_sources!$A$7,Codex_USGS_raw!$C$2:$C$94,AN$4)*Codex_sources!$D$7*Codex_sources!$J$7 | AO62: =AO61
C63: MINCoRSV1 | D63: COST | E63: m_cobalt | F63: =Codex_sources!$M$7 | G63: =Codex_sources!$M$7 | H63: =Codex_sources!$M$7 | I63: =Codex_sources!$M$7 | J63: =Codex_sources!$M$7 | K63: =Codex_sources!$M$7 | L63: =Codex_sources!$M$7 | M63: =Codex_sources!$M$7 | ... AN63: =Codex_sources!$M$7 | AO63: =AO62
C64: MINCoRSV2 | D64: BNDACT | F64: =SUMIFS(Codex_USGS_raw!$D$2:$D$94,Codex_USGS_raw!$A$2:$A$94,Codex_sources!$A$7,Codex_USGS_raw!$C$2:$C$94,F$4)*Codex_sources!$D$7*2 | G64: =SUMIFS(Codex_USGS_raw!$D$2:$D$94,Codex_USGS_raw!$A$2:$A$94,Codex_sources!$A$7,Codex_USGS_raw!$C$2:$C$94,G$4)*Codex_sources!$D$7*2 | H64: =SUMIFS(Codex_USGS_raw!$D$2:$D$94,Codex_USGS_raw!$A$2:$A$94,Codex_sources!$A$7,Codex_USGS_raw!$C$2:$C$94,H$4)*Codex_sources!$D$7*2 | I64: =SUMIFS(Codex_USGS_raw!$D$2:$D$94,Codex_USGS_raw!$A$2:$A$94,Codex_sources!$A$7,Codex_USGS_raw!$C$2:$C$94,I$4)*Codex_sources!$D$7*2 | J64: =SUMIFS(Codex_USGS_raw!$D$2:$D$94,Codex_USGS_raw!$A$2:$A$94,Codex_sources!$A$7,Codex_USGS_raw!$C$2:$C$94,J$4)*Codex_sources!$D$7*2 | K64: =SUMIFS(Codex_USGS_raw!$D$2:$D$94,Codex_USGS_raw!$A$2:$A$94,Codex_sources!$A$7,Codex_USGS_raw!$C$2:$C$94,K$4)*Codex_sources!$D$7*2 | L64: =SUMIFS(Codex_USGS_raw!$D$2:$D$94,Codex_USGS_raw!$A$2:$A$94,Codex_sources!$A$7,Codex_USGS_raw!$C$2:$C$94,L$4)*Codex_sources!$D$7*2 | M64: =SUMIFS(Codex_USGS_raw!$D$2:$D$94,Codex_USGS_raw!$A$2:$A$94,Codex_sources!$A$7,Codex_USGS_raw!$C$2:$C$94,M$4)*Codex_sources!$D$7*2 | ... AN64: =SUMIFS(Codex_USGS_raw!$D$2:$D$94,Codex_USGS_raw!$A$2:$A$94,Codex_sources!$A$7,Codex_USGS_raw!$C$2:$C$94,AN$4)*Codex_sources!$D$7*2 | AO64: =AO63
C65: MINCoRSV2 | D65: CUM | F65: =SUMIFS(Codex_USGS_raw!$E$2:$E$94,Codex_USGS_raw!$A$2:$A$94,Codex_sources!$A$7,Codex_USGS_raw!$C$2:$C$94,F$4)*Codex_sources!$D$7*Codex_sources!$K$7 | G65: =SUMIFS(Codex_USGS_raw!$E$2:$E$94,Codex_USGS_raw!$A$2:$A$94,Codex_sources!$A$7,Codex_USGS_raw!$C$2:$C$94,G$4)*Codex_sources!$D$7*Codex_sources!$K$7 | H65: =SUMIFS(Codex_USGS_raw!$E$2:$E$94,Codex_USGS_raw!$A$2:$A$94,Codex_sources!$A$7,Codex_USGS_raw!$C$2:$C$94,H$4)*Codex_sources!$D$7*Codex_sources!$K$7 | I65: =SUMIFS(Codex_USGS_raw!$E$2:$E$94,Codex_USGS_raw!$A$2:$A$94,Codex_sources!$A$7,Codex_USGS_raw!$C$2:$C$94,I$4)*Codex_sources!$D$7*Codex_sources!$K$7 | J65: =SUMIFS(Codex_USGS_raw!$E$2:$E$94,Codex_USGS_raw!$A$2:$A$94,Codex_sources!$A$7,Codex_USGS_raw!$C$2:$C$94,J$4)*Codex_sources!$D$7*Codex_sources!$K$7 | K65: =SUMIFS(Codex_USGS_raw!$E$2:$E$94,Codex_USGS_raw!$A$2:$A$94,Codex_sources!$A$7,Codex_USGS_raw!$C$2:$C$94,K$4)*Codex_sources!$D$7*Codex_sources!$K$7 | L65: =SUMIFS(Codex_USGS_raw!$E$2:$E$94,Codex_USGS_raw!$A$2:$A$94,Codex_sources!$A$7,Codex_USGS_raw!$C$2:$C$94,L$4)*Codex_sources!$D$7*Codex_sources!$K$7 | M65: =SUMIFS(Codex_USGS_raw!$E$2:$E$94,Codex_USGS_raw!$A$2:$A$94,Codex_sources!$A$7,Codex_USGS_raw!$C$2:$C$94,M$4)*Codex_sources!$D$7*Codex_sources!$K$7 | ... AN65: =SUMIFS(Codex_USGS_raw!$E$2:$E$94,Codex_USGS_raw!$A$2:$A$94,Codex_sources!$A$7,Codex_USGS_raw!$C$2:$C$94,AN$4)*Codex_sources!$D$7*Codex_sources!$K$7 | AO65: =AO64
C66: MINCoRSV2 | D66: COST | E66: m_cobalt | F66: =Codex_sources!$N$7 | G66: =Codex_sources!$N$7 | H66: =Codex_sources!$N$7 | I66: =Codex_sources!$N$7 | J66: =Codex_sources!$N$7 | K66: =Codex_sources!$N$7 | L66: =Codex_sources!$N$7 | M66: =Codex_sources!$N$7 | ... AN66: =Codex_sources!$N$7 | AO66: =AO65
C67: MINCoRSV3 | D67: BNDACT | AO67: =AO66
C68: MINCoRSV3 | D68: CUM | F68: =SUMIFS(Codex_USGS_raw!$E$2:$E$94,Codex_USGS_raw!$A$2:$A$94,Codex_sources!$A$7,Codex_USGS_raw!$C$2:$C$94,F$4)*Codex_sources!$D$7*Codex_sources!$L$7 | G68: =SUMIFS(Codex_USGS_raw!$E$2:$E$94,Codex_USGS_raw!$A$2:$A$94,Codex_sources!$A$7,Codex_USGS_raw!$C$2:$C$94,G$4)*Codex_sources!$D$7*Codex_sources!$L$7 | H68: =SUMIFS(Codex_USGS_raw!$E$2:$E$94,Codex_USGS_raw!$A$2:$A$94,Codex_sources!$A$7,Codex_USGS_raw!$C$2:$C$94,H$4)*Codex_sources!$D$7*Codex_sources!$L$7 | I68: =SUMIFS(Codex_USGS_raw!$E$2:$E$94,Codex_USGS_raw!$A$2:$A$94,Codex_sources!$A$7,Codex_USGS_raw!$C$2:$C$94,I$4)*Codex_sources!$D$7*Codex_sources!$L$7 | J68: =SUMIFS(Codex_USGS_raw!$E$2:$E$94,Codex_USGS_raw!$A$2:$A$94,Codex_sources!$A$7,Codex_USGS_raw!$C$2:$C$94,J$4)*Codex_sources!$D$7*Codex_sources!$L$7 | K68: =SUMIFS(Codex_USGS_raw!$E$2:$E$94,Codex_USGS_raw!$A$2:$A$94,Codex_sources!$A$7,Codex_USGS_raw!$C$2:$C$94,K$4)*Codex_sources!$D$7*Codex_sources!$L$7 | L68: =SUMIFS(Codex_USGS_raw!$E$2:$E$94,Codex_USGS_raw!$A$2:$A$94,Codex_sources!$A$7,Codex_USGS_raw!$C$2:$C$94,L$4)*Codex_sources!$D$7*Codex_sources!$L$7 | M68: =SUMIFS(Codex_USGS_raw!$E$2:$E$94,Codex_USGS_raw!$A$2:$A$94,Codex_sources!$A$7,Codex_USGS_raw!$C$2:$C$94,M$4)*Codex_sources!$D$7*Codex_sources!$L$7 | ... AN68: =SUMIFS(Codex_USGS_raw!$E$2:$E$94,Codex_USGS_raw!$A$2:$A$94,Codex_sources!$A$7,Codex_USGS_raw!$C$2:$C$94,AN$4)*Codex_sources!$D$7*Codex_sources!$L$7 | AO68: =AO67
C69: MINCoRSV3 | D69: COST | E69: m_cobalt | F69: =Codex_sources!$O$7 | G69: =Codex_sources!$O$7 | H69: =Codex_sources!$O$7 | I69: =Codex_sources!$O$7 | J69: =Codex_sources!$O$7 | K69: =Codex_sources!$O$7 | L69: =Codex_sources!$O$7 | M69: =Codex_sources!$O$7 | ... AN69: =Codex_sources!$O$7 | AO69: =AO68
AO70: =AO69
C71: MINMnRSV1 | D71: BNDACT | F71: =SUMIFS(Codex_USGS_raw!$D$2:$D$94,Codex_USGS_raw!$A$2:$A$94,Codex_sources!$A$8,Codex_USGS_raw!$C$2:$C$94,F$4)*Codex_sources!$D$8*1 | G71: =SUMIFS(Codex_USGS_raw!$D$2:$D$94,Codex_USGS_raw!$A$2:$A$94,Codex_sources!$A$8,Codex_USGS_raw!$C$2:$C$94,G$4)*Codex_sources!$D$8*1 | H71: =SUMIFS(Codex_USGS_raw!$D$2:$D$94,Codex_USGS_raw!$A$2:$A$94,Codex_sources!$A$8,Codex_USGS_raw!$C$2:$C$94,H$4)*Codex_sources!$D$8*1 | I71: =SUMIFS(Codex_USGS_raw!$D$2:$D$94,Codex_USGS_raw!$A$2:$A$94,Codex_sources!$A$8,Codex_USGS_raw!$C$2:$C$94,I$4)*Codex_sources!$D$8*1 | J71: =SUMIFS(Codex_USGS_raw!$D$2:$D$94,Codex_USGS_raw!$A$2:$A$94,Codex_sources!$A$8,Codex_USGS_raw!$C$2:$C$94,J$4)*Codex_sources!$D$8*1 | K71: =SUMIFS(Codex_USGS_raw!$D$2:$D$94,Codex_USGS_raw!$A$2:$A$94,Codex_sources!$A$8,Codex_USGS_raw!$C$2:$C$94,K$4)*Codex_sources!$D$8*1 | L71: =SUMIFS(Codex_USGS_raw!$D$2:$D$94,Codex_USGS_raw!$A$2:$A$94,Codex_sources!$A$8,Codex_USGS_raw!$C$2:$C$94,L$4)*Codex_sources!$D$8*1 | M71: =SUMIFS(Codex_USGS_raw!$D$2:$D$94,Codex_USGS_raw!$A$2:$A$94,Codex_sources!$A$8,Codex_USGS_raw!$C$2:$C$94,M$4)*Codex_sources!$D$8*1 | ... AN71: =SUMIFS(Codex_USGS_raw!$D$2:$D$94,Codex_USGS_raw!$A$2:$A$94,Codex_sources!$A$8,Codex_USGS_raw!$C$2:$C$94,AN$4)*Codex_sources!$D$8*1 | AO71: =AO70
C72: MINMnRSV1 | D72: CUM | F72: =SUMIFS(Codex_USGS_raw!$E$2:$E$94,Codex_USGS_raw!$A$2:$A$94,Codex_sources!$A$8,Codex_USGS_raw!$C$2:$C$94,F$4)*Codex_sources!$D$8*Codex_sources!$J$8 | G72: =SUMIFS(Codex_USGS_raw!$E$2:$E$94,Codex_USGS_raw!$A$2:$A$94,Codex_sources!$A$8,Codex_USGS_raw!$C$2:$C$94,G$4)*Codex_sources!$D$8*Codex_sources!$J$8 | H72: =SUMIFS(Codex_USGS_raw!$E$2:$E$94,Codex_USGS_raw!$A$2:$A$94,Codex_sources!$A$8,Codex_USGS_raw!$C$2:$C$94,H$4)*Codex_sources!$D$8*Codex_sources!$J$8 | I72: =SUMIFS(Codex_USGS_raw!$E$2:$E$94,Codex_USGS_raw!$A$2:$A$94,Codex_sources!$A$8,Codex_USGS_raw!$C$2:$C$94,I$4)*Codex_sources!$D$8*Codex_sources!$J$8 | J72: =SUMIFS(Codex_USGS_raw!$E$2:$E$94,Codex_USGS_raw!$A$2:$A$94,Codex_sources!$A$8,Codex_USGS_raw!$C$2:$C$94,J$4)*Codex_sources!$D$8*Codex_sources!$J$8 | K72: =SUMIFS(Codex_USGS_raw!$E$2:$E$94,Codex_USGS_raw!$A$2:$A$94,Codex_sources!$A$8,Codex_USGS_raw!$C$2:$C$94,K$4)*Codex_sources!$D$8*Codex_sources!$J$8 | L72: =SUMIFS(Codex_USGS_raw!$E$2:$E$94,Codex_USGS_raw!$A$2:$A$94,Codex_sources!$A$8,Codex_USGS_raw!$C$2:$C$94,L$4)*Codex_sources!$D$8*Codex_sources!$J$8 | M72: =SUMIFS(Codex_USGS_raw!$E$2:$E$94,Codex_USGS_raw!$A$2:$A$94,Codex_sources!$A$8,Codex_USGS_raw!$C$2:$C$94,M$4)*Codex_sources!$D$8*Codex_sources!$J$8 | ... AN72: =SUMIFS(Codex_USGS_raw!$E$2:$E$94,Codex_USGS_raw!$A$2:$A$94,Codex_sources!$A$8,Codex_USGS_raw!$C$2:$C$94,AN$4)*Codex_sources!$D$8*Codex_sources!$J$8 | AO72: =AO71
C73: MINMnRSV1 | D73: COST | E73: m_manganese | F73: =Codex_Regional!F13 | G73: =Codex_Regional!G13 | H73: =Codex_Regional!H13 | I73: =Codex_Regional!I13 | J73: =Codex_Regional!J13 | K73: =Codex_Regional!K13 | L73: =Codex_Regional!L13 | M73: =Codex_Regional!M13 | ... AN73: =Codex_Regional!AN13 | AO73: =AO72
