Workbook

Sheet Constants
B2: ~TFM_INS | Y2: ~TFM_INS
B3: TimeSlice | C3: LimType | D3: Attribute | E3: Year | F3: Other_Indexes | G3: Curr | H3: AllRegions | I3: Cset_CN | Y3: TimeSlice | Z3: LimType | AA3: Attribute | AB3: Year | AC3: Other_Indexes | AD3: Curr | AE3: AllRegions
D4: COM_PKRSV | H4: 0.1 | I4: ELC | T4: varbl | U4: region | V4: year | W4: value | AA4: G_CUREX | AC4: USD20 | AD4: EUR15 | AE4: =1.10926234054354*H39 -> 1.201442
D5: G_Dyear | H5: 2020 | T5: hmacgdpd | U5: USA | V5: 2001 | W5: 0.76282752 | AA5: G_DRATE | AD5: EUR15 | AE5: =O6 -> 0.07
D6: G_OFFTHD | H6: 1 | O6: 0.07 | P6: Discount Rate | T6: hmacgdpd | U6: USA | V6: 2002 | W6: 0.77446032 | AA6: G_CUREX | AC6: USD20 | AD6: USD21_alt | AE6: =H45 -> 0.9896
D7: =IF(F7=G7,"*","")&"G_CUREX" -> G_CUREX | F7: USD20 | G7: ="USD"&RIGHT(O9,2) -> USD83 | H7: =ROUND($P$46/P9,4) -> 2.2201 | T7: hmacgdpd | U7: USA | V7: 2003 | W7: 0.78906536 | AA7: G_DRATE | AD7: USD21_alt | AE7: =AE5 -> 0.07
D8: =IF(F8=G8,"*","")&"G_CUREX" -> G_CUREX | F8: USD20 | G8: ="USD"&RIGHT(O10,2) -> USD84 | H8: =ROUND($P$46/P10,4) -> 2.1427 | P8: Deflator | T8: hmacgdpd | U8: USA | V8: 2004 | W8: 0.81019747
D9: =IF(F9=G9,"*","")&"G_CUREX" -> G_CUREX | F9: USD20 | G9: ="USD"&RIGHT(O11,2) -> USD85 | H9: =ROUND($P$46/P11,4) -> 2.077 | O9: 1983 | P9: =VLOOKUP(O9,$V$5:$W$99,2,FALSE) -> 0.48787263 | T9: hmacgdpd | U9: USA | V9: 2005 | W9: 0.83531958
D10: =IF(F10=G10,"*","")&"G_CUREX" -> G_CUREX | F10: USD20 | G10: ="USD"&RIGHT(O12,2) -> USD86 | H10: =ROUND($P$46/P12,4) -> 2.0358 | O10: 1984 | P10: =VLOOKUP(O10,$V$5:$W$99,2,FALSE) -> 0.50549513 | T10: hmacgdpd | U10: USA | V10: 2006 | W10: 0.86080724
D11: =IF(F11=G11,"*","")&"G_CUREX" -> G_CUREX | F11: USD20 | G11: ="USD"&RIGHT(O13,2) -> USD87 | H11: =ROUND($P$46/P13,4) -> 1.987 | O11: 1985 | P11: =VLOOKUP(O11,$V$5:$W$99,2,FALSE) -> 0.52148581 | T11: hmacgdpd | U11: USA | V11: 2007 | W11: 0.88397014
D12: =IF(F12=G12,"*","")&"G_CUREX" -> G_CUREX | F12: USD20 | G12: ="USD"&RIGHT(O14,2) -> USD88 | H12: =ROUND($P$46/P14,4) -> 1.9192 | O12: 1986 | P12: =VLOOKUP(O12,$V$5:$W$99,2,FALSE) -> 0.53205073 | T12: hmacgdpd | U12: USA | V12: 2008 | W12: 0.90084481
D13: =IF(F13=G13,"*","")&"G_CUREX" -> G_CUREX | F13: USD20 | G13: ="USD"&RIGHT(O15,2) -> USD89 | H13: =ROUND($P$46/P15,4) -> 1.8468 | O13: 1987 | P13: =VLOOKUP(O13,$V$5:$W$99,2,FALSE) -> 0.54511946 | T13: hmacgdpd | U13: USA | V13: 2009 | W13: 0.90787375
D14: =IF(F14=G14,"*","")&"G_CUREX" -> G_CUREX | F14: USD20 | G14: ="USD"&RIGHT(O16,2) -> USD90 | H14: =ROUND($P$46/P16,4) -> 1.7799 | O14: 1988 | P14: =VLOOKUP(O14,$V$5:$W$99,2,FALSE) -> 0.56437135 | T14: hmacgdpd | U14: USA | V14: 2010 | W14: 0.9184792
D15: =IF(F15=G15,"*","")&"G_CUREX" -> G_CUREX | F15: USD20 | G15: ="USD"&RIGHT(O17,2) -> USD91 | H15: =ROUND($P$46/P17,4) -> 1.722 | O15: 1989 | P15: =VLOOKUP(O15,$V$5:$W$99,2,FALSE) -> 0.58649743 | T15: hmacgdpd | U15: USA | V15: 2011 | W15: 0.93761897
D16: =IF(F16=G16,"*","")&"G_CUREX" -> G_CUREX | F16: USD20 | G16: ="USD"&RIGHT(O18,2) -> USD92 | H16: =ROUND($P$46/P18,4) -> 1.6836 | O16: 1990 | P16: =VLOOKUP(O16,$V$5:$W$99,2,FALSE) -> 0.60853273 | T16: hmacgdpd | U16: USA | V16: 2012 | W16: 0.9556666
D17: =IF(F17=G17,"*","")&"G_CUREX" -> G_CUREX | F17: USD20 | G17: ="USD"&RIGHT(O19,2) -> USD93 | H17: =ROUND($P$46/P19,4) -> 1.6446 | O17: 1991 | P17: =VLOOKUP(O17,$V$5:$W$99,2,FALSE) -> 0.62901258 | T17: hmacgdpd | U17: USA | V17: 2013 | W17: 0.97260576
D18: =IF(F18=G18,"*","")&"G_CUREX" -> G_CUREX | F18: USD20 | G18: ="USD"&RIGHT(O20,2) -> USD94 | H18: =ROUND($P$46/P20,4) -> 1.6102 | O18: 1992 | P18: =VLOOKUP(O18,$V$5:$W$99,2,FALSE) -> 0.6433621 | T18: hmacgdpd | U18: USA | V18: 2014 | W18: 0.99051732
D19: =IF(F19=G19,"*","")&"G_CUREX" -> G_CUREX | F19: USD20 | G19: ="USD"&RIGHT(O21,2) -> USD95 | H19: =ROUND($P$46/P21,4) -> 1.5771 | O19: 1993 | P19: =VLOOKUP(O19,$V$5:$W$99,2,FALSE) -> 0.65861923 | T19: hmacgdpd | U19: USA | V19: 2015 | W19: 1
D20: =IF(F20=G20,"*","")&"G_CUREX" -> G_CUREX | F20: USD20 | G20: ="USD"&RIGHT(O22,2) -> USD96 | H20: =ROUND($P$46/P22,4) -> 1.5488 | O20: 1994 | P20: =VLOOKUP(O20,$V$5:$W$99,2,FALSE) -> 0.67265797 | T20: hmacgdpd | U20: USA | V20: 2016 | W20: 1.0104837
... D49: =IF(F49=G49,"*","")&"G_CUREX" -> G_CUREX | F49: USD20 | G49: ="USD"&RIGHT(O51,2) -> USD25 | H49: =ROUND($P$46/P51,4) -> 0.9297 | O49: 2023 | P49: =VLOOKUP(O49,$V$5:$W$99,2,FALSE) -> 1.1224308 | T49: hmacgdpd | U49: USA | V49: 1994 | W49: 0.67265797
D50: G_DRATE | G50: =G7 -> USD83 | H50: =$O$6 -> 0.07 | O50: 2024 | P50: =VLOOKUP(O50,$V$5:$W$99,2,FALSE) -> 1.1412873 | T50: hmacgdpd | U50: USA | V50: 1995 | W50: 0.68678039
D51: G_DRATE | G51: =G8 -> USD84 | H51: =$O$6 -> 0.07 | O51: 2025 | P51: =VLOOKUP(O51,$V$5:$W$99,2,FALSE) -> 1.1650648 | T51: hmacgdpd | U51: USA | V51: 1996 | W51: 0.6993354
D52: G_DRATE | G52: =G9 -> USD85 | H52: =$O$6 -> 0.07 | T52: hmacgdpd | U52: USA | V52: 1997 | W52: 0.71145087
D53: G_DRATE | G53: =G10 -> USD86 | H53: =$O$6 -> 0.07 | T53: hmacgdpd | U53: USA | V53: 1998 | W53: 0.71929687
D54: G_DRATE | G54: =G11 -> USD87 | H54: =$O$6 -> 0.07 | T54: hmacgdpd | U54: USA | V54: 1999 | W54: 0.7296133
D55: G_DRATE | G55: =G12 -> USD88 | H55: =$O$6 -> 0.07 | T55: hmacgdpd | U55: USA | V55: 2000 | W55: 0.74607462
D56: G_DRATE | G56: =G13 -> USD89 | H56: =$O$6 -> 0.07
D57: G_DRATE | G57: =G14 -> USD90 | H57: =$O$6 -> 0.07
D58: G_DRATE | G58: =G15 -> USD91 | H58: =$O$6 -> 0.07
D59: G_DRATE | G59: =G16 -> USD92 | H59: =$O$6 -> 0.07
D60: G_DRATE | G60: =G17 -> USD93 | H60: =$O$6 -> 0.07
D61: G_DRATE | G61: =G18 -> USD94 | H61: =$O$6 -> 0.07
D62: G_DRATE | G62: =G19 -> USD95 | H62: =$O$6 -> 0.07
D63: G_DRATE | G63: =G20 -> USD96 | H63: =$O$6 -> 0.07
D64: G_DRATE | G64: =G21 -> USD97 | H64: =$O$6 -> 0.07
D65: G_DRATE | G65: =G22 -> USD98 | H65: =$O$6 -> 0.07
D66: G_DRATE | G66: =G23 -> USD99 | H66: =$O$6 -> 0.07
D67: G_DRATE | G67: =G24 -> USD00 | H67: =$O$6 -> 0.07
... D92: G_DRATE | G92: =G49 -> USD25 | H92: =$O$6 -> 0.07

Sheet agg cap UC
A1: spv | C1: ~UC_Sets: R_S: Allregions | K1: won | V1: wof
C3: ~UC_T: FX | G3: ~UC_T | M3: ~UC_T: FX | Q3: ~UC_T | X3: ~UC_T: FX | AB3: ~UC_T
A4: * | B4: uc_n | C4: process | D4: uc_cap | E4: uc_rhst~0 | G4: =B4 -> uc_n | H4: =C4 -> process | I4: =D4 -> uc_cap | K4: * | L4: uc_n | M4: process | N4: uc_cap | O4: uc_rhst~0 | Q4: =L4 -> uc_n | R4: =M4 -> process | S4: =N4 -> uc_cap | V4: * | W4: uc_n | X4: process | Y4: uc_cap | Z4: uc_rhst~0 | AB4: =W4 -> uc_n | AC4: =X4 -> process | AD4: =Y4 -> uc_cap
A5: AFG | B5: ="UCE_elcaggCap_"&A$1&"_"&A5 -> UCE_elcaggCap_spv_AFG | C5: ="e?_spv_"&$A5&"*" -> e?_spv_AFG* | D5: 1 | E5: 2 | G5: =B5 -> UCE_elcaggCap_spv_AFG | H5: ="elcagg_spv_"&$A5 -> elcagg_spv_AFG | I5: -1 | K5: AFG | L5: ="UCE_elcaggCap_"&K$1&"_"&K5 -> UCE_elcaggCap_won_AFG | M5: ="e?_won_"&$K5&"*" -> e?_won_AFG* | N5: 1 | O5: 2 | Q5: =L5 -> UCE_elcaggCap_won_AFG | R5: ="elcagg_won_"&$K5 -> elcagg_won_AFG | S5: -1 | V5: AGO | W5: ="UCE_elcaggCap_"&V$1&"_"&V5 -> UCE_elcaggCap_wof_AGO | X5: ="e?_wof_"&$V5&"*" -> e?_wof_AGO* | Y5: 1 | Z5: 2 | AB5: =W5 -> UCE_elcaggCap_wof_AGO | AC5: ="elcagg_wof_"&$V5 -> elcagg_wof_AGO | AD5: -1
A6: AGO | B6: ="UCE_elcaggCap_"&A$1&"_"&A6 -> UCE_elcaggCap_spv_AGO | C6: ="e?_spv_"&$A6&"*" -> e?_spv_AGO* | D6: 1 | E6: 2 | G6: =B6 -> UCE_elcaggCap_spv_AGO | H6: ="elcagg_spv_"&$A6 -> elcagg_spv_AGO | I6: -1 | K6: AGO | L6: ="UCE_elcaggCap_"&K$1&"_"&K6 -> UCE_elcaggCap_won_AGO | M6: ="e?_won_"&$K6&"*" -> e?_won_AGO* | N6: 1 | O6: 2 | Q6: =L6 -> UCE_elcaggCap_won_AGO | R6: ="elcagg_won_"&$K6 -> elcagg_won_AGO | S6: -1 | V6: ALB | W6: ="UCE_elcaggCap_"&V$1&"_"&V6 -> UCE_elcaggCap_wof_ALB | X6: ="e?_wof_"&$V6&"*" -> e?_wof_ALB* | Y6: 1 | Z6: 2 | AB6: =W6 -> UCE_elcaggCap_wof_ALB | AC6: ="elcagg_wof_"&$V6 -> elcagg_wof_ALB | AD6: -1
A7: ALB | B7: ="UCE_elcaggCap_"&A$1&"_"&A7 -> UCE_elcaggCap_spv_ALB | C7: ="e?_spv_"&$A7&"*" -> e?_spv_ALB* | D7: 1 | E7: 2 | G7: =B7 -> UCE_elcaggCap_spv_ALB | H7: ="elcagg_spv_"&$A7 -> elcagg_spv_ALB | I7: -1 | K7: ALB | L7: ="UCE_elcaggCap_"&K$1&"_"&K7 -> UCE_elcaggCap_won_ALB | M7: ="e?_won_"&$K7&"*" -> e?_won_ALB* | N7: 1 | O7: 2 | Q7: =L7 -> UCE_elcaggCap_won_ALB | R7: ="elcagg_won_"&$K7 -> elcagg_won_ALB | S7: -1 | V7: ARE | W7: ="UCE_elcaggCap_"&V$1&"_"&V7 -> UCE_elcaggCap_wof_ARE | X7: ="e?_wof_"&$V7&"*" -> e?_wof_ARE* | Y7: 1 | Z7: 2 | AB7: =W7 -> UCE_elcaggCap_wof_ARE | AC7: ="elcagg_wof_"&$V7 -> elcagg_wof_ARE | AD7: -1
A8: ARE | B8: ="UCE_elcaggCap_"&A$1&"_"&A8 -> UCE_elcaggCap_spv_ARE | C8: ="e?_spv_"&$A8&"*" -> e?_spv_ARE* | D8: 1 | E8: 2 | G8: =B8 -> UCE_elcaggCap_spv_ARE | H8: ="elcagg_spv_"&$A8 -> elcagg_spv_ARE | I8: -1 | K8: ARE | L8: ="UCE_elcaggCap_"&K$1&"_"&K8 -> UCE_elcaggCap_won_ARE | M8: ="e?_won_"&$K8&"*" -> e?_won_ARE* | N8: 1 | O8: 2 | Q8: =L8 -> UCE_elcaggCap_won_ARE | R8: ="elcagg_won_"&$K8 -> elcagg_won_ARE | S8: -1 | V8: ARG | W8: ="UCE_elcaggCap_"&V$1&"_"&V8 -> UCE_elcaggCap_wof_ARG | X8: ="e?_wof_"&$V8&"*" -> e?_wof_ARG* | Y8: 1 | Z8: 2 | AB8: =W8 -> UCE_elcaggCap_wof_ARG | AC8: ="elcagg_wof_"&$V8 -> elcagg_wof_ARG | AD8: -1
A9: ARG | B9: ="UCE_elcaggCap_"&A$1&"_"&A9 -> UCE_elcaggCap_spv_ARG | C9: ="e?_spv_"&$A9&"*" -> e?_spv_ARG* | D9: 1 | E9: 2 | G9: =B9 -> UCE_elcaggCap_spv_ARG | H9: ="elcagg_spv_"&$A9 -> elcagg_spv_ARG | I9: -1 | K9: ARG | L9: ="UCE_elcaggCap_"&K$1&"_"&K9 -> UCE_elcaggCap_won_ARG | M9: ="e?_won_"&$K9&"*" -> e?_won_ARG* | N9: 1 | O9: 2 | Q9: =L9 -> UCE_elcaggCap_won_ARG | R9: ="elcagg_won_"&$K9 -> elcagg_won_ARG | S9: -1 | V9: AUS | W9: ="UCE_elcaggCap_"&V$1&"_"&V9 -> UCE_elcaggCap_wof_AUS | X9: ="e?_wof_"&$V9&"*" -> e?_wof_AUS* | Y9: 1 | Z9: 2 | AB9: =W9 -> UCE_elcaggCap_wof_AUS | AC9: ="elcagg_wof_"&$V9 -> elcagg_wof_AUS | AD9: -1
A10: ARM | B10: ="UCE_elcaggCap_"&A$1&"_"&A10 -> UCE_elcaggCap_spv_ARM | C10: ="e?_spv_"&$A10&"*" -> e?_spv_ARM* | D10: 1 | E10: 2 | G10: =B10 -> UCE_elcaggCap_spv_ARM | H10: ="elcagg_spv_"&$A10 -> elcagg_spv_ARM | I10: -1 | K10: ARM | L10: ="UCE_elcaggCap_"&K$1&"_"&K10 -> UCE_elcaggCap_won_ARM | M10: ="e?_won_"&$K10&"*" -> e?_won_ARM* | N10: 1 | O10: 2 | Q10: =L10 -> UCE_elcaggCap_won_ARM | R10: ="elcagg_won_"&$K10 -> elcagg_won_ARM | S10: -1 | V10: AZE | W10: ="UCE_elcaggCap_"&V$1&"_"&V10 -> UCE_elcaggCap_wof_AZE | X10: ="e?_wof_"&$V10&"*" -> e?_wof_AZE* | Y10: 1 | Z10: 2 | AB10: =W10 -> UCE_elcaggCap_wof_AZE | AC10: ="elcagg_wof_"&$V10 -> elcagg_wof_AZE | AD10: -1
A11: AUS | B11: ="UCE_elcaggCap_"&A$1&"_"&A11 -> UCE_elcaggCap_spv_AUS | C11: ="e?_spv_"&$A11&"*" -> e?_spv_AUS* | D11: 1 | E11: 2 | G11: =B11 -> UCE_elcaggCap_spv_AUS | H11: ="elcagg_spv_"&$A11 -> elcagg_spv_AUS | I11: -1 | K11: AUS | L11: ="UCE_elcaggCap_"&K$1&"_"&K11 -> UCE_elcaggCap_won_AUS | M11: ="e?_won_"&$K11&"*" -> e?_won_AUS* | N11: 1 | O11: 2 | Q11: =L11 -> UCE_elcaggCap_won_AUS | R11: ="elcagg_won_"&$K11 -> elcagg_won_AUS | S11: -1 | V11: BEN | W11: ="UCE_elcaggCap_"&V$1&"_"&V11 -> UCE_elcaggCap_wof_BEN | X11: ="e?_wof_"&$V11&"*" -> e?_wof_BEN* | Y11: 1 | Z11: 2 | AB11: =W11 -> UCE_elcaggCap_wof_BEN | AC11: ="elcagg_wof_"&$V11 -> elcagg_wof_BEN | AD11: -1
A12: AUT | B12: ="UCE_elcaggCap_"&A$1&"_"&A12 -> UCE_elcaggCap_spv_AUT | C12: ="e?_spv_"&$A12&"*" -> e?_spv_AUT* | D12: 1 | E12: 2 | G12: =B12 -> UCE_elcaggCap_spv_AUT | H12: ="elcagg_spv_"&$A12 -> elcagg_spv_AUT | I12: -1 | K12: AUT | L12: ="UCE_elcaggCap_"&K$1&"_"&K12 -> UCE_elcaggCap_won_AUT | M12: ="e?_won_"&$K12&"*" -> e?_won_AUT* | N12: 1 | O12: 2 | Q12: =L12 -> UCE_elcaggCap_won_AUT | R12: ="elcagg_won_"&$K12 -> elcagg_won_AUT | S12: -1 | V12: BGD | W12: ="UCE_elcaggCap_"&V$1&"_"&V12 -> UCE_elcaggCap_wof_BGD | X12: ="e?_wof_"&$V12&"*" -> e?_wof_BGD* | Y12: 1 | Z12: 2 | AB12: =W12 -> UCE_elcaggCap_wof_BGD | AC12: ="elcagg_wof_"&$V12 -> elcagg_wof_BGD | AD12: -1
A13: AZE | B13: ="UCE_elcaggCap_"&A$1&"_"&A13 -> UCE_elcaggCap_spv_AZE | C13: ="e?_spv_"&$A13&"*" -> e?_spv_AZE* | D13: 1 | E13: 2 | G13: =B13 -> UCE_elcaggCap_spv_AZE | H13: ="elcagg_spv_"&$A13 -> elcagg_spv_AZE | I13: -1 | K13: AZE | L13: ="UCE_elcaggCap_"&K$1&"_"&K13 -> UCE_elcaggCap_won_AZE | M13: ="e?_won_"&$K13&"*" -> e?_won_AZE* | N13: 1 | O13: 2 | Q13: =L13 -> UCE_elcaggCap_won_AZE | R13: ="elcagg_won_"&$K13 -> elcagg_won_AZE | S13: -1 | V13: BGR | W13: ="UCE_elcaggCap_"&V$1&"_"&V13 -> UCE_elcaggCap_wof_BGR | X13: ="e?_wof_"&$V13&"*" -> e?_wof_BGR* | Y13: 1 | Z13: 2 | AB13: =W13 -> UCE_elcaggCap_wof_BGR | AC13: ="elcagg_wof_"&$V13 -> elcagg_wof_BGR | AD13: -1
A14: BDI | B14: ="UCE_elcaggCap_"&A$1&"_"&A14 -> UCE_elcaggCap_spv_BDI | C14: ="e?_spv_"&$A14&"*" -> e?_spv_BDI* | D14: 1 | E14: 2 | G14: =B14 -> UCE_elcaggCap_spv_BDI | H14: ="elcagg_spv_"&$A14 -> elcagg_spv_BDI | I14: -1 | K14: BDI | L14: ="UCE_elcaggCap_"&K$1&"_"&K14 -> UCE_elcaggCap_won_BDI | M14: ="e?_won_"&$K14&"*" -> e?_won_BDI* | N14: 1 | O14: 2 | Q14: =L14 -> UCE_elcaggCap_won_BDI | R14: ="elcagg_won_"&$K14 -> elcagg_won_BDI | S14: -1 | V14: BRA | W14: ="UCE_elcaggCap_"&V$1&"_"&V14 -> UCE_elcaggCap_wof_BRA | X14: ="e?_wof_"&$V14&"*" -> e?_wof_BRA* | Y14: 1 | Z14: 2 | AB14: =W14 -> UCE_elcaggCap_wof_BRA | AC14: ="elcagg_wof_"&$V14 -> elcagg_wof_BRA | AD14: -1
A15: BEL | B15: ="UCE_elcaggCap_"&A$1&"_"&A15 -> UCE_elcaggCap_spv_BEL | C15: ="e?_spv_"&$A15&"*" -> e?_spv_BEL* | D15: 1 | E15: 2 | G15: =B15 -> UCE_elcaggCap_spv_BEL | H15: ="elcagg_spv_"&$A15 -> elcagg_spv_BEL | I15: -1 | K15: BEL | L15: ="UCE_elcaggCap_"&K$1&"_"&K15 -> UCE_elcaggCap_won_BEL | M15: ="e?_won_"&$K15&"*" -> e?_won_BEL* | N15: 1 | O15: 2 | Q15: =L15 -> UCE_elcaggCap_won_BEL | R15: ="elcagg_won_"&$K15 -> elcagg_won_BEL | S15: -1 | V15: CAN | W15: ="UCE_elcaggCap_"&V$1&"_"&V15 -> UCE_elcaggCap_wof_CAN | X15: ="e?_wof_"&$V15&"*" -> e?_wof_CAN* | Y15: 1 | Z15: 2 | AB15: =W15 -> UCE_elcaggCap_wof_CAN | AC15: ="elcagg_wof_"&$V15 -> elcagg_wof_CAN | AD15: -1
A16: BEN | B16: ="UCE_elcaggCap_"&A$1&"_"&A16 -> UCE_elcaggCap_spv_BEN | C16: ="e?_spv_"&$A16&"*" -> e?_spv_BEN* | D16: 1 | E16: 2 | G16: =B16 -> UCE_elcaggCap_spv_BEN | H16: ="elcagg_spv_"&$A16 -> elcagg_spv_BEN | I16: -1 | K16: BEN | L16: ="UCE_elcaggCap_"&K$1&"_"&K16 -> UCE_elcaggCap_won_BEN | M16: ="e?_won_"&$K16&"*" -> e?_won_BEN* | N16: 1 | O16: 2 | Q16: =L16 -> UCE_elcaggCap_won_BEN | R16: ="elcagg_won_"&$K16 -> elcagg_won_BEN | S16: -1 | V16: CHL | W16: ="UCE_elcaggCap_"&V$1&"_"&V16 -> UCE_elcaggCap_wof_CHL | X16: ="e?_wof_"&$V16&"*" -> e?_wof_CHL* | Y16: 1 | Z16: 2 | AB16: =W16 -> UCE_elcaggCap_wof_CHL | AC16: ="elcagg_wof_"&$V16 -> elcagg_wof_CHL | AD16: -1
... A120: PRK | B120: ="UCE_elcaggCap_"&A$1&"_"&A120 -> UCE_elcaggCap_spv_PRK | C120: ="e?_spv_"&$A120&"*" -> e?_spv_PRK* | D120: 1 | E120: 2 | G120: =B120 -> UCE_elcaggCap_spv_PRK | H120: ="elcagg_spv_"&$A120 -> elcagg_spv_PRK | I120: -1 | K120: PRI | L120: ="UCE_elcaggCap_"&K$1&"_"&K120 -> UCE_elcaggCap_won_PRI | M120: ="e?_won_"&$K120&"*" -> e?_won_PRI* | N120: 1 | O120: 2 | Q120: =L120 -> UCE_elcaggCap_won_PRI | R120: ="elcagg_won_"&$K120 -> elcagg_won_PRI | S120: -1 | V120: ZAF | W120: ="UCE_elcaggCap_"&V$1&"_"&V120 -> UCE_elcaggCap_wof_ZAF | X120: ="e?_wof_"&$V120&"*" -> e?_wof_ZAF* | Y120: 1 | Z120: 2 | AB120: =W120 -> UCE_elcaggCap_wof_ZAF | AC120: ="elcagg_wof_"&$V120 -> elcagg_wof_ZAF | AD120: -1
A121: PRT | B121: ="UCE_elcaggCap_"&A$1&"_"&A121 -> UCE_elcaggCap_spv_PRT | C121: ="e?_spv_"&$A121&"*" -> e?_spv_PRT* | D121: 1 | E121: 2 | G121: =B121 -> UCE_elcaggCap_spv_PRT | H121: ="elcagg_spv_"&$A121 -> elcagg_spv_PRT | I121: -1 | K121: PRK | L121: ="UCE_elcaggCap_"&K$1&"_"&K121 -> UCE_elcaggCap_won_PRK | M121: ="e?_won_"&$K121&"*" -> e?_won_PRK* | N121: 1 | O121: 2 | Q121: =L121 -> UCE_elcaggCap_won_PRK | R121: ="elcagg_won_"&$K121 -> elcagg_won_PRK | S121: -1
A122: PRY | B122: ="UCE_elcaggCap_"&A$1&"_"&A122 -> UCE_elcaggCap_spv_PRY | C122: ="e?_spv_"&$A122&"*" -> e?_spv_PRY* | D122: 1 | E122: 2 | G122: =B122 -> UCE_elcaggCap_spv_PRY | H122: ="elcagg_spv_"&$A122 -> elcagg_spv_PRY | I122: -1 | K122: PRT | L122: ="UCE_elcaggCap_"&K$1&"_"&K122 -> UCE_elcaggCap_won_PRT | M122: ="e?_won_"&$K122&"*" -> e?_won_PRT* | N122: 1 | O122: 2 | Q122: =L122 -> UCE_elcaggCap_won_PRT | R122: ="elcagg_won_"&$K122 -> elcagg_won_PRT | S122: -1
A123: QAT | B123: ="UCE_elcaggCap_"&A$1&"_"&A123 -> UCE_elcaggCap_spv_QAT | C123: ="e?_spv_"&$A123&"*" -> e?_spv_QAT* | D123: 1 | E123: 2 | G123: =B123 -> UCE_elcaggCap_spv_QAT | H123: ="elcagg_spv_"&$A123 -> elcagg_spv_QAT | I123: -1 | K123: PRY | L123: ="UCE_elcaggCap_"&K$1&"_"&K123 -> UCE_elcaggCap_won_PRY | M123: ="e?_won_"&$K123&"*" -> e?_won_PRY* | N123: 1 | O123: 2 | Q123: =L123 -> UCE_elcaggCap_won_PRY | R123: ="elcagg_won_"&$K123 -> elcagg_won_PRY | S123: -1
A124: ROU | B124: ="UCE_elcaggCap_"&A$1&"_"&A124 -> UCE_elcaggCap_spv_ROU | C124: ="e?_spv_"&$A124&"*" -> e?_spv_ROU* | D124: 1 | E124: 2 | G124: =B124 -> UCE_elcaggCap_spv_ROU | H124: ="elcagg_spv_"&$A124 -> elcagg_spv_ROU | I124: -1 | K124: QAT | L124: ="UCE_elcaggCap_"&K$1&"_"&K124 -> UCE_elcaggCap_won_QAT | M124: ="e?_won_"&$K124&"*" -> e?_won_QAT* | N124: 1 | O124: 2 | Q124: =L124 -> UCE_elcaggCap_won_QAT | R124: ="elcagg_won_"&$K124 -> elcagg_won_QAT | S124: -1
A125: RUS | B125: ="UCE_elcaggCap_"&A$1&"_"&A125 -> UCE_elcaggCap_spv_RUS | C125: ="e?_spv_"&$A125&"*" -> e?_spv_RUS* | D125: 1 | E125: 2 | G125: =B125 -> UCE_elcaggCap_spv_RUS | H125: ="elcagg_spv_"&$A125 -> elcagg_spv_RUS | I125: -1 | K125: ROU | L125: ="UCE_elcaggCap_"&K$1&"_"&K125 -> UCE_elcaggCap_won_ROU | M125: ="e?_won_"&$K125&"*" -> e?_won_ROU* | N125: 1 | O125: 2 | Q125: =L125 -> UCE_elcaggCap_won_ROU | R125: ="elcagg_won_"&$K125 -> elcagg_won_ROU | S125: -1
A126: RWA | B126: ="UCE_elcaggCap_"&A$1&"_"&A126 -> UCE_elcaggCap_spv_RWA | C126: ="e?_spv_"&$A126&"*" -> e?_spv_RWA* | D126: 1 | E126: 2 | G126: =B126 -> UCE_elcaggCap_spv_RWA | H126: ="elcagg_spv_"&$A126 -> elcagg_spv_RWA | I126: -1 | K126: RUS | L126: ="UCE_elcaggCap_"&K$1&"_"&K126 -> UCE_elcaggCap_won_RUS | M126: ="e?_won_"&$K126&"*" -> e?_won_RUS* | N126: 1 | O126: 2 | Q126: =L126 -> UCE_elcaggCap_won_RUS | R126: ="elcagg_won_"&$K126 -> elcagg_won_RUS | S126: -1
A127: SAU | B127: ="UCE_elcaggCap_"&A$1&"_"&A127 -> UCE_elcaggCap_spv_SAU | C127: ="e?_spv_"&$A127&"*" -> e?_spv_SAU* | D127: 1 | E127: 2 | G127: =B127 -> UCE_elcaggCap_spv_SAU | H127: ="elcagg_spv_"&$A127 -> elcagg_spv_SAU | I127: -1 | K127: RWA | L127: ="UCE_elcaggCap_"&K$1&"_"&K127 -> UCE_elcaggCap_won_RWA | M127: ="e?_won_"&$K127&"*" -> e?_won_RWA* | N127: 1 | O127: 2 | Q127: =L127 -> UCE_elcaggCap_won_RWA | R127: ="elcagg_won_"&$K127 -> elcagg_won_RWA | S127: -1
A128: SDN | B128: ="UCE_elcaggCap_"&A$1&"_"&A128 -> UCE_elcaggCap_spv_SDN | C128: ="e?_spv_"&$A128&"*" -> e?_spv_SDN* | D128: 1 | E128: 2 | G128: =B128 -> UCE_elcaggCap_spv_SDN | H128: ="elcagg_spv_"&$A128 -> elcagg_spv_SDN | I128: -1 | K128: SAU | L128: ="UCE_elcaggCap_"&K$1&"_"&K128 -> UCE_elcaggCap_won_SAU | M128: ="e?_won_"&$K128&"*" -> e?_won_SAU* | N128: 1 | O128: 2 | Q128: =L128 -> UCE_elcaggCap_won_SAU | R128: ="elcagg_won_"&$K128 -> elcagg_won_SAU | S128: -1
A129: SEN | B129: ="UCE_elcaggCap_"&A$1&"_"&A129 -> UCE_elcaggCap_spv_SEN | C129: ="e?_spv_"&$A129&"*" -> e?_spv_SEN* | D129: 1 | E129: 2 | G129: =B129 -> UCE_elcaggCap_spv_SEN | H129: ="elcagg_spv_"&$A129 -> elcagg_spv_SEN | I129: -1 | K129: SDN | L129: ="UCE_elcaggCap_"&K$1&"_"&K129 -> UCE_elcaggCap_won_SDN | M129: ="e?_won_"&$K129&"*" -> e?_won_SDN* | N129: 1 | O129: 2 | Q129: =L129 -> UCE_elcaggCap_won_SDN | R129: ="elcagg_won_"&$K129 -> elcagg_won_SDN | S129: -1
A130: SGP | B130: ="UCE_elcaggCap_"&A$1&"_"&A130 -> UCE_elcaggCap_spv_SGP | C130: ="e?_spv_"&$A130&"*" -> e?_spv_SGP* | D130: 1 | E130: 2 | G130: =B130 -> UCE_elcaggCap_spv_SGP | H130: ="elcagg_spv_"&$A130 -> elcagg_spv_SGP | I130: -1 | K130: SEN | L130: ="UCE_elcaggCap_"&K$1&"_"&K130 -> UCE_elcaggCap_won_SEN | M130: ="e?_won_"&$K130&"*" -> e?_won_SEN* | N130: 1 | O130: 2 | Q130: =L130 -> UCE_elcaggCap_won_SEN | R130: ="elcagg_won_"&$K130 -> elcagg_won_SEN | S130: -1
A131: SLE | B131: ="UCE_elcaggCap_"&A$1&"_"&A131 -> UCE_elcaggCap_spv_SLE | C131: ="e?_spv_"&$A131&"*" -> e?_spv_SLE* | D131: 1 | E131: 2 | G131: =B131 -> UCE_elcaggCap_spv_SLE | H131: ="elcagg_spv_"&$A131 -> elcagg_spv_SLE | I131: -1 | K131: SGP | L131: ="UCE_elcaggCap_"&K$1&"_"&K131 -> UCE_elcaggCap_won_SGP | M131: ="e?_won_"&$K131&"*" -> e?_won_SGP* | N131: 1 | O131: 2 | Q131: =L131 -> UCE_elcaggCap_won_SGP | R131: ="elcagg_won_"&$K131 -> elcagg_won_SGP | S131: -1
A132: SLV | B132: ="UCE_elcaggCap_"&A$1&"_"&A132 -> UCE_elcaggCap_spv_SLV | C132: ="e?_spv_"&$A132&"*" -> e?_spv_SLV* | D132: 1 | E132: 2 | G132: =B132 -> UCE_elcaggCap_spv_SLV | H132: ="elcagg_spv_"&$A132 -> elcagg_spv_SLV | I132: -1 | K132: SLE | L132: ="UCE_elcaggCap_"&K$1&"_"&K132 -> UCE_elcaggCap_won_SLE | M132: ="e?_won_"&$K132&"*" -> e?_won_SLE* | N132: 1 | O132: 2 | Q132: =L132 -> UCE_elcaggCap_won_SLE | R132: ="elcagg_won_"&$K132 -> elcagg_won_SLE | S132: -1
... A160: ZWE | B160: ="UCE_elcaggCap_"&A$1&"_"&A160 -> UCE_elcaggCap_spv_ZWE | C160: ="e?_spv_"&$A160&"*" -> e?_spv_ZWE* | D160: 1 | E160: 2 | G160: =B160 -> UCE_elcaggCap_spv_ZWE | H160: ="elcagg_spv_"&$A160 -> elcagg_spv_ZWE | I160: -1 | K160: ZAF | L160: ="UCE_elcaggCap_"&K$1&"_"&K160 -> UCE_elcaggCap_won_ZAF | M160: ="e?_won_"&$K160&"*" -> e?_won_ZAF* | N160: 1 | O160: 2 | Q160: =L160 -> UCE_elcaggCap_won_ZAF | R160: ="elcagg_won_"&$K160 -> elcagg_won_ZAF | S160: -1
K161: ZMB | L161: ="UCE_elcaggCap_"&K$1&"_"&K161 -> UCE_elcaggCap_won_ZMB | M161: ="e?_won_"&$K161&"*" -> e?_won_ZMB* | N161: 1 | O161: 2 | Q161: =L161 -> UCE_elcaggCap_won_ZMB | R161: ="elcagg_won_"&$K161 -> elcagg_won_ZMB | S161: -1
K162: ZWE | L162: ="UCE_elcaggCap_"&K$1&"_"&K162 -> UCE_elcaggCap_won_ZWE | M162: ="e?_won_"&$K162&"*" -> e?_won_ZWE* | N162: 1 | O162: 2 | Q162: =L162 -> UCE_elcaggCap_won_ZWE | R162: ="elcagg_won_"&$K162 -> elcagg_won_ZWE | S162: -1

Sheet nuclear
A1: Current capacities | J1: ~UC_SETS: R_E: AllRegions
A3: Region | B3: GW (2022) | C3: GW (after 2022) | E3: Region | F3: 0.5 | G3: 0.25 | H3: 0.1 | L3: ~UC_T: UC_RHSRT~UP | S3: ~TFM_INS
A4: Africa_North | B4: 0 | C4: 4.8 | E4: Africa_North | F4: 82.6 | G4: 41.3 | H4: 16.5 | J4: UC_N | K4: pset_set | L4: Region | M4: *2018 | N4: 2020 | O4: 0 | P4: UC_CAP | S4: attribute | T4: pset_set | U4: Region | V4: value
A5: BeNeLux | B5: 5.35 | C5: 0 | E5: Africa_Other | F5: 132.5 | G5: 66.2 | H5: 26.5 | J5: UCE_NucLimit | K5: E_Nuclear | N5: 0 | O5: 3 | P5: 1 | S5: START | T5: =K5 -> E_Nuclear | V5: 2150
A6: Brazil | B6: 1.99 | C6: 1.4 | E6: Australia | F6: 22 | G6: 11 | H6: 4.4 | L6: =IF(A4="","\I:",A4) -> Africa_North | M6: =B4*1.1 -> 0 | N6: =MAX(VLOOKUP(L6,$E$4:$G$40,3,FALSE),M6*1.5) -> 41.3 | S6: START | T6: =T5 -> E_Nuclear | U6: =L6 -> Africa_North | V6: 2030
A7: China | B7: 55.53 | C7: 29.16 | E7: Austria | F7: 6 | G7: 3 | H7: 1.2 | L7: =IF(A5="","\I:",A5) -> BeNeLux | M7: =B5*1.1 -> 5.885 | N7: =MAX(VLOOKUP(L7,$E$4:$G$40,3,FALSE),M7*1.5) -> 8.8275 | S7: START | T7: =T6 -> E_Nuclear | U7: =L7 -> BeNeLux | V7: 2030
A8: CroSloven | B8: 0.69 | C8: 0 | E8: Baltics | F8: 2.3 | G8: 1.1 | H8: 0.5 | L8: =IF(A6="","\I:",A6) -> Brazil | M8: =B6*1.1 -> 2.189 | N8: =MAX(VLOOKUP(L8,$E$4:$G$40,3,FALSE),M8*1.5) -> 29.2 | S8: START | T8: =T7 -> E_Nuclear | U8: =L8 -> Brazil | V8: 2030
A9: CzechSlovak | B9: 6.29 | C9: 0.94 | E9: BeNeLux | F9: 16.3 | G9: 8.1 | H9: 3.3 | L9: =IF(A7="","\I:",A7) -> China | M9: =B7*1.1 -> 61.083 | N9: =MAX(VLOOKUP(L9,$E$4:$G$40,3,FALSE),M9*1.5) -> 628.9 | S9: START | T9: =T8 -> E_Nuclear | U9: =L9 -> China | V9: 2030
A10: France | B10: 61.4 | C10: 1.65 | E10: Brazil | F10: 58.4 | G10: 29.2 | H10: 11.7 | L10: =IF(A8="","\I:",A8) -> CroSloven | M10: =B8*1.1 -> 0.759 | N10: =MAX(VLOOKUP(L10,$E$4:$G$40,3,FALSE),M10*1.5) -> 1.1385 | S10: START | T10: =T9 -> E_Nuclear | U10: =L10 -> CroSloven | V10: 2030
A11: Germany | B11: 4.2 | C11: 0 | E11: China | F11: 1257.8 | G11: 628.9 | H11: 251.6 | L11: =IF(A9="","\I:",A9) -> CzechSlovak | M11: =B9*1.1 -> 6.919 | N11: =MAX(VLOOKUP(L11,$E$4:$G$40,3,FALSE),M11*1.5) -> 10.3785 | S11: START | T11: =T10 -> E_Nuclear | U11: =L11 -> CzechSlovak | V11: 2030
A12: HunRomBul | B12: 5.34 | C12: 0 | E12: CroSloven | F12: 2 | G12: 1 | H12: 0.4 | L12: =IF(A10="","\I:",A10) -> France | M12: =B10*1.1 -> 67.54 | N12: =MAX(VLOOKUP(L12,$E$4:$G$40,3,FALSE),M12*1.5) -> 101.31 | S12: START | T12: =T11 -> E_Nuclear | U12: =L12 -> France | V12: 2030
A13: India | B13: 6.78 | C13: 7.3 | E13: CzechSlovak | F13: 6.1 | G13: 3 | H13: 1.2 | L13: =IF(A11="","\I:",A11) -> Germany | M13: =B11*1.1 -> 4.62 | N13: =MAX(VLOOKUP(L13,$E$4:$G$40,3,FALSE),M13*1.5) -> 19.3 | S13: START | T13: =T12 -> E_Nuclear | U13: =L13 -> Germany | V13: 2030
A14: Japan | B14: 33.08 | C14: 6.84 | E14: France | F14: 34 | G14: 17 | H14: 6.8 | L14: =IF(A12="","\I:",A12) -> HunRomBul | M14: =B12*1.1 -> 5.874 | N14: =MAX(VLOOKUP(L14,$E$4:$G$40,3,FALSE),M14*1.5) -> 8.811 | S14: START | T14: =T13 -> E_Nuclear | U14: =L14 -> HunRomBul | V14: 2030
A15: LatAm | B15: 1.75 | C15: 0 | E15: Germany | F15: 38.5 | G15: 19.3 | H15: 7.7 | L15: =IF(A13="","\I:",A13) -> India | M15: =B13*1.1 -> 7.458 | N15: =MAX(VLOOKUP(L15,$E$4:$G$40,3,FALSE),M15*1.5) -> 196 | S15: START | T15: =T14 -> E_Nuclear | U15: =L15 -> India | V15: 2030
A16: MidEast | B16: 3.8 | C16: 4.19 | E16: GreeceCyp | F16: 4.4 | G16: 2.2 | H16: 0.9 | L16: =IF(A14="","\I:",A14) -> Japan | M16: =B14*1.1 -> 36.388 | N16: =MAX(VLOOKUP(L16,$E$4:$G$40,3,FALSE),M16*1.5) -> 54.582 | S16: START | T16: =T15 -> E_Nuclear | U16: =L16 -> Japan | V16: 2030
A17: NorthAm | B17: 109.61 | C17: 2.9 | E17: HunRomBul | F17: 7.4 | G17: 3.7 | H17: 1.5 | L17: =IF(A15="","\I:",A15) -> LatAm | M17: =B15*1.1 -> 1.925 | N17: =MAX(VLOOKUP(L17,$E$4:$G$40,3,FALSE),M17*1.5) -> 46.1 | S17: START | T17: =T16 -> E_Nuclear | U17: =L17 -> LatAm | V17: 2030
... A26: Ukraine | B26: 13.84 | C26: 0 | E26: Poland | F26: 10.6 | G26: 5.3 | H26: 2.1 | L26: =IF(A24="","\I:",A24) -> Turkey | M26: =B24*1.1 -> 0 | N26: =MAX(VLOOKUP(L26,$E$4:$G$40,3,FALSE),M26*1.5) -> 16.4 | S26: START | T26: =T25 -> E_Nuclear | U26: =L26 -> Turkey | V26: 2030
E27: ROW | F27: 320.2 | G27: 160.1 | H27: 64 | L27: =IF(A25="","\I:",A25) -> UK | M27: =B25*1.1 -> 8.613 | N27: =MAX(VLOOKUP(L27,$E$4:$G$40,3,FALSE),M27*1.5) -> 13.2 | S27: START | T27: =T26 -> E_Nuclear | U27: =L27 -> UK | V27: 2030
E28: Russia | F28: 78.5 | G28: 39.3 | H28: 15.7 | L28: =IF(A26="","\I:",A26) -> Ukraine | M28: =B26*1.1 -> 15.224 | N28: =MAX(VLOOKUP(L28,$E$4:$G$40,3,FALSE),M28*1.5) -> 22.836 | S28: START | T28: =T27 -> E_Nuclear | U28: =L28 -> Ukraine | V28: 2030
E29: SaudiArabia | F29: 46.5 | G29: 23.3 | H29: 9.3
E30: SouthAfrica | F30: 20.6 | G30: 10.3 | H30: 4.1
E31: SpainPor | F31: 22.1 | G31: 11 | H31: 4.4
E32: SweFinDen | F32: 18.9 | G32: 9.5 | H32: 3.8 | M32: =SUM(M6:M29) -> 441.661 | N32: =SUM(N6:N29) -> 1704.8755
E33: Switzerland | F33: 5.1 | G33: 2.6 | H33: 1
E34: Turkey | F34: 32.9 | G34: 16.4 | H34: 6.6
E35: UK | F35: 26.4 | G35: 13.2 | H35: 5.3
E36: Ukraine | F36: 8.8 | G36: 4.4 | H36: 1.8
E37: WestBalkans | F37: 6.1 | G37: 3.1 | H37: 1.2

Sheet CHP and Losses
A1: TABLE 1: CHP HEAT-TO-POWER RATIO (2022, aggregated by KiNESYS_CEA)
A2: Metric | B2: Africa_North | C2: Africa_Other | D2: Australia | E2: Austria | F2: Baltics | G2: BeNeLux | H2: Brazil | I2: China | J2: CroSloven | K2: CzechSlovak | L2: France | M2: Germany | N2: GreeceCyp | O2: HunRomBul | P2: Iceland | Q2: India | R2: Ireland | S2: ItalyMal | T2: Japan | U2: LatAm | V2: MidEast | W2: NorthAm | X2: Norway | Y2: Poland | Z2: ROW | AA2: Russia | AB2: SaudiArabia | AC2: SouthAfrica | AD2: SpainPor | AE2: SweFinDen | AF2: Switzerland | AG2: Turkey | AH2: UK | AI2: Ukraine | AJ2: WestBalkans
A3: Main CHP Electricity Output (PJ) | D3: 8.42 | E3: 22.28 | F3: 15.65 | G3: 93.81 | I3: 8197.59 | J3: 28.9 | K3: 43.71 | L3: 49.07 | M3: 291.13 | N3: 12.5 | O3: 66.02 | P3: 16.78 | S3: 237.38 | U3: 1.27 | V3: 10.27 | W3: 538.85 | X3: 1.7 | Y3: 462.11 | Z3: 730.98 | AA3: 2357.01 | AD3: 0.76 | AE3: 117.72 | AF3: 2.53 | AG3: 13.26 | AI3: 36.85 | AJ3: 19.04
A4: Auto CHP Electricity Output (PJ) | B4: 2.76 | C4: 0.09 | D4: 46.99 | E4: 16.55 | F4: 3.2 | G4: 112.19 | H4: 302.07 | J4: 1.83 | K4: 32.65 | L4: 36.48 | M4: 116.8 | N4: 10.61 | O4: 12.77 | Q4: 145.17 | R4: 7.46 | S4: 142.24 | U4: 40.88 | V4: 11.95 | W4: 610.03 | X4: 4.77 | Y4: 50.12 | Z4: 218.17 | AA4: 225.82 | AC4: 0.22 | AD4: 100.25 | AE4: 61.97 | AF4: 10.63 | AG4: 30.7 | AH4: 125.56 | AI4: 7.19 | AJ4: 1.95
A5: Total CHP Electricity Output (PJ) | B5: 2.76 | C5: 0.09 | D5: 55.41 | E5: 38.83 | F5: 18.84 | G5: 206 | H5: 302.07 | I5: 8197.59 | J5: 30.73 | K5: 76.37 | L5: 85.54 | M5: 407.93 | N5: 23.11 | O5: 78.79 | P5: 16.78 | Q5: 145.17 | R5: 7.46 | S5: 379.62 | U5: 42.15 | V5: 22.21 | W5: 1148.88 | X5: 6.47 | Y5: 512.23 | Z5: 949.15 | AA5: 2582.82 | AC5: 0.22 | AD5: 101.01 | AE5: 179.69 | AF5: 13.16 | AG5: 43.96 | AH5: 125.56 | AI5: 44.04 | AJ5: 20.99
A6: Main CHP Heat Output (PJ) | D6: 0 | E6: 38.39 | F6: 36.27 | G6: 59.34 | I6: 7418.86 | J6: 19.6 | K6: 91.89 | L6: 84.07 | M6: 318.83 | N6: 1.22 | O6: 83.51 | P6: 2.87 | S6: 57.14 | V6: 0 | W6: 437.62 | X6: 7.71 | Y6: 163.53 | Z6: 410.1 | AA6: 2612.31 | AD6: 0.04 | AE6: 269.78 | AF6: 5.77 | AG6: 18.09 | AI6: 54.8 | AJ6: 6.28
A7: Auto CHP Heat Output (PJ) | D7: 0 | E7: 9.86 | F7: 1.4 | G7: 37.01 | J7: 0.08 | K7: 8.49 | L7: 25.29 | N7: 0.32 | O7: 1.06 | S7: 13.59 | V7: 0 | W7: 0.1 | Y7: 17.64 | Z7: 284.4 | AA7: 542.6 | AD7: 11.5 | AE7: 53.39 | AF7: 14.54 | AG7: 21.24 | AI7: 34.75 | AJ7: 6.86
A8: Total CHP Heat Output (PJ) | D8: 0 | E8: 48.25 | F8: 37.67 | G8: 96.35 | I8: 7418.86 | J8: 19.68 | K8: 100.38 | L8: 109.36 | M8: 318.83 | N8: 1.55 | O8: 84.56 | P8: 2.87 | S8: 70.73 | V8: 0 | W8: 437.72 | X8: 7.71 | Y8: 181.17 | Z8: 694.5 | AA8: 3154.91 | AD8: 11.54 | AE8: 323.17 | AF8: 20.31 | AG8: 39.33 | AI8: 89.55 | AJ8: 13.14
A9: Heat-to-Power Ratio (Main CHP) | D9: 0 | E9: 1.72 | F9: 2.32 | G9: 0.63 | I9: 0.91 | J9: 0.68 | K9: 2.1 | L9: 1.71 | M9: 1.1 | N9: 0.1 | O9: 1.26 | P9: 0.17 | S9: 0.24 | V9: 0 | W9: 0.81 | X9: 4.53 | Y9: 0.35 | Z9: 0.56 | AA9: 1.11 | AD9: 0.05 | AE9: 2.29 | AF9: 2.28 | AG9: 1.36 | AI9: 1.49 | AJ9: 0.33
A10: Heat-to-Power Ratio (Auto CHP) | D10: 0 | E10: 0.6 | F10: 0.44 | G10: 0.33 | J10: 0.04 | K10: 0.26 | L10: 0.69 | N10: 0.03 | O10: 0.08 | S10: 0.1 | V10: 0 | W10: 0 | Y10: 0.35 | Z10: 1.3 | AA10: 2.4 | AD10: 0.11 | AE10: 0.86 | AF10: 1.37 | AG10: 0.69 | AI10: 4.83 | AJ10: 3.52
A11: Heat-to-Power Ratio (All CHP) | D11: 0 | E11: 1.24 | F11: 2 | G11: 0.47 | I11: 0.91 | J11: 0.64 | K11: 1.31 | L11: 1.28 | M11: 0.78 | N11: 0.07 | O11: 1.07 | P11: 0.17 | S11: 0.19 | V11: 0 | W11: 0.38 | X11: 1.19 | Y11: 0.35 | Z11: 0.73 | AA11: 1.22 | AD11: 0.11 | AE11: 1.8 | AF11: 1.54 | AG11: 0.89 | AI11: 2.03 | AJ11: 0.63
A12: CHP Share of Total Electricity (%) | B12: 0.19 | C12: 0 | D12: 5.68 | E12: 16.68 | F12: 28.87 | G12: 26.38 | H12: 12.4 | I12: 25.58 | J12: 31.07 | K12: 19.22 | L12: 5.08 | M12: 19.78 | N12: 11.11 | O12: 15.43 | P12: 23.17 | Q12: 2.21 | R12: 6.13 | S12: 37.08 | U12: 1.4 | V12: 0.61 | W12: 5.81 | X12: 1.24 | Y12: 79.65 | Z12: 8.08 | AA12: 60.36 | AC12: 0.03 | AD12: 8.39 | AE12: 17.82 | AF12: 5.92 | AG12: 3.72 | AH12: 10.78 | AI12: 10.54 | AJ12: 8.5
A13: Total Electricity Generation (PJ) | B13: 1432.93 | C13: 2330.8 | D13: 974.94 | E13: 232.8 | F13: 65.27 | G13: 781.03 | H13: 2436.83 | I13: 32042.76 | J13: 98.89 | K13: 397.33 | L13: 1685.32 | M13: 2062.79 | N13: 208.06 | O13: 510.71 | P13: 72.43 | Q13: 6558.72 | R13: 121.67 | S13: 1023.7 | T13: 3631.3 | U13: 3005.89 | V13: 3625.06 | W13: 19785.88 | X13: 522.5 | Y13: 643.09 | Z13: 11745.45 | AA13: 4278.75 | AB13: 1508.46 | AC13: 839.13 | AD13: 1204.01 | AE13: 1008.51 | AF13: 222.21 | AG13: 1182.17 | AH13: 1164.78 | AI13: 417.73 | AJ13: 246.83
A17: TABLE 2: DISTRIBUTION LOSS + OWN CONSUMPTION (2022, aggregated by KiNESYS_CEA)
A18: Metric | B18: Africa_North | C18: Africa_Other | D18: Australia | E18: Austria | F18: Baltics | G18: BeNeLux | H18: Brazil | I18: China | J18: CroSloven | K18: CzechSlovak | L18: France | M18: Germany | N18: GreeceCyp | O18: HunRomBul | P18: Iceland | Q18: India | R18: Ireland | S18: ItalyMal | T18: Japan | U18: LatAm | V18: MidEast | W18: NorthAm | X18: Norway | Y18: Poland | Z18: ROW | AA18: Russia | AB18: SaudiArabia | AC18: SouthAfrica | AD18: SpainPor | AE18: SweFinDen | AF18: Switzerland | AG18: Turkey | AH18: UK | AI18: Ukraine | AJ18: WestBalkans
A19: Electricity T&D Losses (PJ) | B19: 251.01 | C19: 380.17 | D19: 48.01 | E19: 11.68 | F19: 8.77 | G19: 30.15 | H19: 374.38 | I19: 1102.64 | J19: 9.02 | K19: 17.05 | L19: 126.83 | M19: 94.75 | N19: 21.15 | O19: 38.71 | P19: 1.94 | Q19: 977.62 | R19: 8.86 | S19: 69.61 | T19: 150.1 | U19: 397.59 | V19: 551.53 | W19: 981.03 | X19: 23.97 | Y19: 37.54 | Z19: 761.13 | AA19: 364.29 | AB19: 136.79 | AC19: 85.96 | AD19: 108.47 | AE19: 52.18 | AF19: 17.6 | AG19: 104.64 | AH19: 99.95 | AI19: 42.48 | AJ19: 27.91
A20: Electricity Own Use in Power Plants (PJ) | B20: 62.73 | C20: 81.77 | D20: 48.31 | E20: 7.95 | F20: 6.94 | G20: 28.56 | H20: 20.84 | I20: 2090.08 | J20: 4.86 | K20: 33.11 | L20: 75.06 | M20: 103.71 | N20: 4.74 | O20: 41.51 | P20: 1.45 | Q20: 509.64 | R20: 3.63 | S20: 33.83 | T20: 150.27 | U20: 77.09 | V20: 132.55 | W20: 766.87 | X20: 2.35 | Y20: 45.56 | Z20: 471.58 | AA20: 268.67 | AB20: 66.99 | AC20: 44.96 | AD20: 35.74 | AE20: 26 | AF20: 5.61 | AG20: 55.66 | AH20: 17.28 | AI20: 29.78 | AJ20: 16.57
A21: Electricity Total Losses (PJ) | B21: 313.75 | C21: 461.95 | D21: 96.32 | E21: 19.63 | F21: 15.71 | G21: 58.7 | H21: 395.22 | I21: 3192.72 | J21: 13.88 | K21: 50.16 | L21: 201.89 | M21: 198.46 | N21: 25.88 | O21: 80.22 | P21: 3.39 | Q21: 1487.26 | R21: 12.49 | S21: 103.44 | T21: 300.37 | U21: 474.67 | V21: 684.09 | W21: 1747.89 | X21: 26.32 | Y21: 83.1 | Z21: 1232.71 | AA21: 632.96 | AB21: 203.78 | AC21: 130.92 | AD21: 144.21 | AE21: 78.18 | AF21: 23.21 | AG21: 160.3 | AH21: 117.22 | AI21: 72.26 | AJ21: 44.48
A22: Total Electricity Generation (PJ) | B22: 1432.93 | C22: 2330.8 | D22: 974.94 | E22: 232.8 | F22: 65.27 | G22: 781.03 | H22: 2436.83 | I22: 32042.76 | J22: 98.89 | K22: 397.33 | L22: 1685.32 | M22: 2062.79 | N22: 208.06 | O22: 510.71 | P22: 72.43 | Q22: 6558.72 | R22: 121.67 | S22: 1023.7 | T22: 3631.3 | U22: 3005.89 | V22: 3625.06 | W22: 19785.88 | X22: 522.5 | Y22: 643.09 | Z22: 11745.45 | AA22: 4278.75 | AB22: 1508.46 | AC22: 839.13 | AD22: 1204.01 | AE22: 1008.51 | AF22: 222.21 | AG22: 1182.17 | AH22: 1164.78 | AI22: 417.73 | AJ22: 246.83
A23: Electricity T&D Loss Ratio (%) | B23: 17.52 | C23: 16.31 | D23: 4.92 | E23: 5.02 | F23: 13.43 | G23: 3.86 | H23: 15.36 | I23: 3.44 | J23: 9.12 | K23: 4.29 | L23: 7.53 | M23: 4.59 | N23: 10.16 | O23: 7.58 | P23: 2.68 | Q23: 14.91 | R23: 7.29 | S23: 6.8 | T23: 4.13 | U23: 13.23 | V23: 15.21 | W23: 4.96 | X23: 4.59 | Y23: 5.84 | Z23: 6.48 | AA23: 8.51 | AB23: 9.07 | AC23: 10.24 | AD23: 9.01 | AE23: 5.17 | AF23: 7.92 | AG23: 8.85 | AH23: 8.58 | AI23: 10.17 | AJ23: 11.31
A24: Electricity Own Use Ratio (%) | B24: 4.38 | C24: 3.51 | D24: 4.96 | E24: 3.42 | F24: 10.64 | G24: 3.66 | H24: 0.86 | I24: 6.52 | J24: 4.91 | K24: 8.33 | L24: 4.45 | M24: 5.03 | N24: 2.28 | O24: 8.13 | P24: 2 | Q24: 7.77 | R24: 2.98 | S24: 3.3 | T24: 4.14 | U24: 2.56 | V24: 3.66 | W24: 3.88 | X24: 0.45 | Y24: 7.08 | Z24: 4.01 | AA24: 6.28 | AB24: 4.44 | AC24: 5.36 | AD24: 2.97 | AE24: 2.58 | AF24: 2.52 | AG24: 4.71 | AH24: 1.48 | AI24: 7.13 | AJ24: 6.71
A25: Electricity Total Loss Ratio (%) | B25: 21.9 | C25: 19.82 | D25: 9.88 | E25: 8.43 | F25: 24.07 | G25: 7.52 | H25: 16.22 | I25: 9.96 | J25: 14.03 | K25: 12.62 | L25: 11.98 | M25: 9.62 | N25: 12.44 | O25: 15.71 | P25: 4.68 | Q25: 22.68 | R25: 10.27 | S25: 10.1 | T25: 8.27 | U25: 15.79 | V25: 18.87 | W25: 8.83 | X25: 5.04 | Y25: 12.92 | Z25: 10.5 | AA25: 14.79 | AB25: 13.51 | AC25: 15.6 | AD25: 11.98 | AE25: 7.75 | AF25: 10.44 | AG25: 13.56 | AH25: 10.06 | AI25: 17.3 | AJ25: 18.02
A27: Heat Distribution Losses (PJ) | D27: 0 | E27: 12.04 | F27: 9.88 | G27: 9.83 | I27: 61.81 | J27: 2.9 | K27: 8.88 | L27: 17.41 | M27: 43.43 | N27: 0.36 | O27: 19.24 | P27: 3.41 | S27: 8.16 | W27: 50.27 | X27: 2.77 | Y27: 26.62 | Z27: 57.54 | AA27: 563.99 | AE27: 63.58 | AF27: 2.35 | AI27: 29.97 | AJ27: 3.32
A28: Heat Own Use in Heat Plants (PJ) | D28: 0 | F28: 1.4 | G28: 0 | I28: 102.25 | J28: 2.53 | K28: 20.13 | O28: 9.94 | S28: 0.21 | W28: 83.78 | X28: 0.53 | Y28: 5.25 | Z28: 39.7 | AE28: 0.91 | AI28: 17.24 | AJ28: 1.44
A29: Heat Total Losses (PJ) | D29: 0 | E29: 12.04 | F29: 11.28 | G29: 9.83 | I29: 164.05 | J29: 5.43 | K29: 29.01 | L29: 17.41 | M29: 43.43 | N29: 0.36 | O29: 29.18 | P29: 3.41 | S29: 8.38 | W29: 134.05 | X29: 3.31 | Y29: 31.88 | Z29: 97.23 | AA29: 563.99 | AE29: 64.49 | AF29: 2.35 | AI29: 47.21 | AJ29: 4.75
A30: Total Heat Production (PJ) | B30: 3.14 | C30: 0.39 | D30: 0 | E30: 82.28 | F30: 80.74 | G30: 95.4 | H30: 4.04 | I30: 8329.62 | J30: 23.36 | K30: 137.38 | L30: 178.46 | M30: 428.91 | N30: 1.55 | O30: 129.46 | P30: 35.81 | S30: 85.74 | T30: 21.54 | V30: 0 | W30: 443.9 | X30: 13.74 | Y30: 285.36 | Z30: 966.43 | AA30: 5742.94 | AD30: 11.54 | AE30: 465.2 | AF30: 24 | AG30: 60.29 | AH30: 64.91 | AI30: 270.13 | AJ30: 39.25
A31: Heat Total Loss Ratio (%) | E31: 14.63 | F31: 13.98 | G31: 10.31 | I31: 1.97 | J31: 23.25 | K31: 21.12 | L31: 9.76 | M31: 10.13 | N31: 23.32 | O31: 22.54 | P31: 9.51 | S31: 9.77 | W31: 30.2 | X31: 24.09 | Y31: 11.17 | Z31: 10.06 | AA31: 9.82 | AE31: 13.86 | AF31: 9.79 | AI31: 17.48 | AJ31: 12.11
A36: ~tfm_ins: pset_set=CHP
A37: attribute | B37: allregions | C37: =B18 -> Africa_North | D37: =C18 -> Africa_Other | E37: =D18 -> Australia | F37: =E18 -> Austria | G37: =F18 -> Baltics | H37: =G18 -> BeNeLux | I37: =H18 -> Brazil | J37: =I18 -> China | ... AK37: =AJ18 -> WestBalkans | AL37: process | AM37: commodity | AN37: year
A38: ncap_chpr | B38: 0.5 | C38: =IF(B9>0,B9,"") | D38: =IF(C9>0,C9,"") | E38: =IF(D9>0,D9,"") | F38: =IF(E9>0,E9,"") -> 1.72 | G38: =IF(F9>0,F9,"") -> 2.32 | H38: =IF(G9>0,G9,"") -> 0.63 | I38: =IF(H9>0,H9,"") | J38: =IF(I9>0,I9,"") -> 0.91 | ... AK38: =IF(AJ9>0,AJ9,"") -> 0.33
A39: ncap_chpr | B39: 0.5 | C39: =IF(B10>0,B10,"") | D39: =IF(C10>0,C10,"") | E39: =IF(D10>0,D10,"") | F39: =IF(E10>0,E10,"") -> 0.6 | G39: =IF(F10>0,F10,"") -> 0.44 | H39: =IF(G10>0,G10,"") -> 0.33 | I39: =IF(H10>0,H10,"") | J39: =IF(I10>0,I10,"") | ... AK39: =IF(AJ10>0,AJ10,"") -> 3.52 | AL39: EA*
A40: *
A41: com_ie | C41: =1-B25/100 -> 0.781 | D41: =1-C25/100 -> 0.8018 | E41: =1-D25/100 -> 0.9012 | F41: =1-E25/100 -> 0.9157 | G41: =1-F25/100 -> 0.7593 | H41: =1-G25/100 -> 0.9248 | I41: =1-H25/100 -> 0.8378 | J41: =1-I25/100 -> 0.9004 | ... AK41: =1-AJ25/100 -> 0.8198 | AM41: ELC | AN41: 2020
A42: com_ie | C42: =MAX($C$41:$AL$41) -> 0.9532 | D42: =MAX($C$41:$AL$41) -> 0.9532 | E42: =MAX($C$41:$AL$41) -> 0.9532 | F42: =MAX($C$41:$AL$41) -> 0.9532 | G42: =MAX($C$41:$AL$41) -> 0.9532 | H42: =MAX($C$41:$AL$41) -> 0.9532 | I42: =MAX($C$41:$AL$41) -> 0.9532 | J42: =MAX($C$41:$AL$41) -> 0.9532 | ... AK42: =MAX($C$41:$AL$41) -> 0.9532 | AM42: ELC | AN42: 2070

Sheet Thermal UF
C1: fuel | D1: metric | E1: Africa_North | F1: Africa_Other | G1: Australia | H1: Austria | I1: Baltics | J1: BeNeLux | K1: Brazil | L1: China | M1: CroSloven | N1: CzechSlovak | O1: France | P1: Germany | Q1: GreeceCyp | R1: HunRomBul | S1: Iceland | T1: India | U1: Ireland | V1: ItalyMal | W1: Japan | X1: LatAm | Y1: MidEast | Z1: NorthAm | AA1: Norway | AB1: Poland | AC1: ROW | AD1: Russia | AE1: SaudiArabia | AF1: SouthAfrica | AG1: SpainPor | AH1: SweFinDen | AI1: Switzerland | AJ1: Turkey | AK1: UK | AL1: Ukraine | AM1: WestBalkans
B2: elcbsl,indbio | C2: bioenergy | D2: Latest | E2: 0.033 | F2: 0.266 | G2: 0.406 | H2: 0.429 | I2: 0.556 | J2: 0.95 | K2: 0.363 | L2: 0.95 | M2: 0.588 | N2: 0.702 | O2: 0.695 | P2: 0.589 | Q2: 0.514 | R2: 0.677 | T2: 0.407 | U2: 0.95 | V2: 0.624 | W2: 0.896 | X2: 0.462 | Y2: 0.95 | Z2: 0.547 | AA2: 0.913 | AB2: 0.78 | AC2: 0.564 | AD2: 0.071 | AF2: 0.18 | AG2: 0.604 | AH2: 0.385 | AI2: 0.95 | AJ2: 0.481 | AK2: 0.579 | AL2: 0.171 | AM2: 0.639
B3: ???coa,elccob | C3: coal | D3: Latest | E3: 0.733 | F3: 0 | G3: 0.627 | H3: 0.95 | J3: 0.278 | K3: 0.509 | L3: 0.576 | M3: 0.368 | N3: 0.457 | O3: 0.098 | P3: 0.382 | Q3: 0.187 | R3: 0.277 | T3: 0.707 | U3: 0.132 | V3: 0.257 | W3: 0.674 | X3: 0.498 | Y3: 0.95 | Z3: 0.395 | AA3: 0.95 | AB3: 0.412 | AC3: 0.565 | AD3: 0.637 | AF3: 0.474 | AG3: 0.151 | AH3: 0.166 | AJ3: 0.646 | AK3: 0.184 | AL3: 0 | AM3: 0.59
B4: ???nga | C4: gas | D4: Latest | E4: 0.387 | F4: 0.327 | G4: 0.197 | H4: 0.158 | I4: 0.077 | J4: 0.312 | K4: 0.232 | L4: 0.259 | M4: 0.688 | N4: 0.145 | O4: 0.194 | P4: 0.261 | Q4: 0.283 | R4: 0.199 | T4: 0.185 | U4: 0.411 | V4: 0.238 | W4: 0.465 | X4: 0.4 | Y4: 0.437 | Z4: 0.393 | AA4: 0.263 | AB4: 0.482 | AC4: 0.457 | AD4: 0.537 | AE4: 0.432 | AF4: 0 | AG4: 0.269 | AH4: 0.048 | AI4: 0.248 | AJ4: 0.275 | AK4: 0.301 | AL4: 0.495 | AM4: 0.262
B5: ???nuc | C5: nuclear | D5: Latest | J5: 0.95 | K5: 0.832 | L5: 0.872 | M5: 0.933 | N5: 0.885 | O5: 0.624 | P5: 0.95 | R5: 0.925 | T5: 0.736 | W5: 0.267 | X5: 0.584 | Y5: 0.856 | Z5: 0.903 | AC5: 0.835 | AD5: 0.84 | AF5: 0.526 | AG5: 0.911 | AH5: 0.832 | AI5: 0.933 | AK5: 0.791
B6: ???oil* | C6: oil | D6: Latest | E6: 0.95 | F6: 0.146 | G6: 0.262 | H6: 0.573 | I6: 0.369 | J6: 0.95 | K6: 0.166 | L6: 0.582 | M6: 0.017 | N6: 0.95 | O6: 0.571 | P6: 0.95 | Q6: 0.312 | R6: 0.088 | T6: 0.026 | U6: 0.111 | V6: 0.95 | W6: 0.194 | X6: 0.221 | Y6: 0.895 | Z6: 0.135 | AA6: 0.72 | AB6: 0.95 | AC6: 0.2 | AD6: 0.95 | AE6: 0.64 | AF6: 0.231 | AG6: 0.374 | AH6: 0.1 | AI6: 0.279 | AJ6: 0.163 | AK6: 0.425 | AL6: 0.95 | AM6: 0.95
B7: =B2 -> elcbsl,indbio | C7: bioenergy | D7: Min_10yr | E7: 0.014 | F7: 0.175 | G7: 0.406 | H7: 0.429 | I7: 0.556 | J7: 0.885 | K7: 0.363 | L7: 0.95 | M7: 0.55 | N7: 0.702 | O7: 0.695 | P7: 0.589 | Q7: 0.469 | R7: 0.489 | T7: 0.307 | U7: 0.913 | V7: 0.624 | W7: 0.896 | X7: 0.348 | Y7: 0.294 | Z7: 0.547 | AA7: 0.285 | AB7: 0.744 | AC7: 0.416 | AD7: 0.051 | AF7: 0.145 | AG7: 0.604 | AH7: 0.385 | AI7: 0.95 | AJ7: 0.45 | AK7: 0.579 | AL7: 0.171 | AM7: 0.228
B8: =B3 -> ???coa,elccob | C8: coal | D8: Min_10yr | E8: 0.57 | F8: 0 | G8: 0.605 | H8: 0.277 | I8: 0.95 | J8: 0.251 | K8: 0.509 | L8: 0.515 | M8: 0.368 | N8: 0.428 | O8: 0.094 | P8: 0.328 | Q8: 0.187 | R8: 0.268 | T8: 0.578 | U8: 0.063 | V8: 0.197 | W8: 0.674 | X8: 0.498 | Y8: 0.385 | Z8: 0.384 | AA8: 0.95 | AB8: 0.412 | AC8: 0.557 | AD8: 0.42 | AF8: 0.474 | AG8: 0.125 | AH8: 0.166 | AJ8: 0.568 | AK8: 0.082 | AL8: 0 | AM8: 0.59
B9: =B4 -> ???nga | C9: gas | D9: Min_10yr | E9: 0.373 | F9: 0.318 | G9: 0.197 | H9: 0.127 | I9: 0.063 | J9: 0.312 | K9: 0.232 | L9: 0.259 | M9: 0.29 | N9: 0.088 | O9: 0.063 | P9: 0.254 | Q9: 0.154 | R9: 0.164 | T9: 0.165 | U9: 0.322 | V9: 0.158 | W9: 0.465 | X9: 0.352 | Y9: 0.389 | Z9: 0.314 | AA9: 0.046 | AB9: 0.372 | AC9: 0.457 | AD9: 0.475 | AE9: 0.386 | AF9: 0 | AG9: 0.195 | AH9: 0.048 | AI9: 0.238 | AJ9: 0.227 | AK9: 0.301 | AL9: 0.14 | AM9: 0.062
B10: =B5 -> ???nuc | C10: nuclear | D10: Min_10yr | J10: 0.537 | K10: 0.806 | L10: 0.72 | M10: 0.928 | N10: 0.712 | O10: 0.548 | P10: 0.803 | R10: 0.925 | T10: 0.63 | W10: 0 | X10: 0.397 | Y10: 0.377 | Z10: 0.903 | AC10: 0.705 | AD10: 0.786 | AF10: 0.526 | AG10: 0.882 | AH10: 0.73 | AI10: 0.699 | AK10: 0.62 | AL10: 0.512
B11: =B6 -> ???oil* | C11: oil | D11: Min_10yr | E11: 0.367 | F11: 0.146 | G11: 0.21 | H11: 0.463 | I11: 0.21 | J11: 0.95 | K11: 0.16 | L11: 0.52 | M11: 0.003 | N11: 0.95 | O11: 0.571 | P11: 0.95 | Q11: 0.301 | R11: 0.07 | S11: 0 | T11: 0.021 | U11: 0.111 | V11: 0.782 | W11: 0.089 | X11: 0.221 | Y11: 0.616 | Z11: 0.117 | AA11: 0.632 | AB11: 0.95 | AC11: 0.2 | AD11: 0.95 | AE11: 0.629 | AF11: 0.001 | AG11: 0.374 | AH11: 0.1 | AI11: 0.26 | AJ11: 0.059 | AK11: 0.22 | AL11: 0.95 | AM11: 0.103
B12: =B7 -> elcbsl,indbio | C12: bioenergy | D12: Max_10yr | E12: 0.057 | F12: 0.287 | G12: 0.506 | H12: 0.564 | I12: 0.842 | J12: 0.95 | K12: 0.436 | L12: 0.95 | M12: 0.711 | N12: 0.77 | O12: 0.834 | P12: 0.769 | Q12: 0.587 | R12: 0.879 | T12: 0.655 | U12: 0.95 | V12: 0.751 | W12: 0.95 | X12: 0.462 | Y12: 0.95 | Z12: 0.644 | AA12: 0.95 | AB12: 0.95 | AC12: 0.564 | AD12: 0.107 | AF12: 0.189 | AG12: 0.727 | AH12: 0.476 | AI12: 0.95 | AJ12: 0.56 | AK12: 0.77 | AL12: 0.41 | AM12: 0.95
B13: =B8 -> ???coa,elccob | C13: coal | D13: Max_10yr | E13: 0.777 | F13: 0.47 | G13: 0.724 | H13: 0.95 | I13: 0.95 | J13: 0.95 | K13: 0.922 | L13: 0.587 | M13: 0.578 | N13: 0.544 | O13: 0.391 | P13: 0.625 | Q13: 0.597 | R13: 0.431 | T13: 0.707 | U13: 0.604 | V13: 0.509 | W13: 0.9 | X13: 0.777 | Y13: 0.95 | Z13: 0.568 | AA13: 0.95 | AB13: 0.522 | AC13: 0.7 | AD13: 0.637 | AF13: 0.671 | AG13: 0.575 | AH13: 0.351 | AJ13: 0.679 | AK13: 0.539 | AL13: 0.319 | AM13: 0.695
B14: =B9 -> ???nga | C14: gas | D14: Max_10yr | E14: 0.505 | F14: 0.399 | G14: 0.324 | H14: 0.268 | I14: 0.149 | J14: 0.495 | K14: 0.675 | L14: 0.324 | M14: 0.787 | N14: 0.352 | O14: 0.294 | P14: 0.352 | Q14: 0.468 | R14: 0.256 | T14: 0.267 | U14: 0.442 | V14: 0.298 | W14: 0.665 | X14: 0.479 | Y14: 0.441 | Z14: 0.393 | AA14: 0.268 | AB14: 0.757 | AC14: 0.53 | AD14: 0.576 | AE14: 0.467 | AF14: 0.95 | AG14: 0.375 | AH14: 0.229 | AI14: 0.427 | AJ14: 0.617 | AK14: 0.466 | AL14: 0.495 | AM14: 0.266
B15: =B10 -> ???nuc | C15: nuclear | D15: Max_10yr | J15: 0.95 | K15: 0.925 | L15: 0.873 | M15: 0.95 | N15: 0.885 | O15: 0.791 | P15: 0.95 | R15: 0.948 | T15: 0.778 | W15: 0.267 | X15: 0.663 | Y15: 0.856 | Z15: 0.93 | AC15: 0.868 | AD15: 0.95 | AF15: 0.884 | AG15: 0.939 | AH15: 0.911 | AI15: 0.95 | AK15: 0.884 | AL15: 0.729
B16: =B11 -> ???oil* | C16: oil | D16: Max_10yr | E16: 0.95 | F16: 0.402 | G16: 0.344 | H16: 0.574 | I16: 0.689 | J16: 0.95 | K16: 0.458 | L16: 0.95 | M16: 0.017 | N16: 0.95 | O16: 0.732 | P16: 0.95 | Q16: 0.359 | R16: 0.106 | S16: 0 | T16: 0.1 | U16: 0.404 | V16: 0.95 | W16: 0.332 | X16: 0.364 | Y16: 0.902 | Z16: 0.16 | AA16: 0.95 | AB16: 0.95 | AC16: 0.557 | AD16: 0.95 | AE16: 0.95 | AF16: 0.231 | AG16: 0.616 | AH16: 0.182 | AI16: 0.311 | AJ16: 0.474 | AK16: 0.644 | AL16: 0.95 | AM16: 0.95
A18: ~UC_SETS: R_E: AllRegions
D20: ~UC_T: UC_CAP
A21: * | B21: UC_N | C21: limtype | D21: Year | E21: =E1 -> Africa_North | F21: =F1 -> Africa_Other | G21: =G1 -> Australia | H21: =H1 -> Austria | I21: =I1 -> Baltics | J21: =J1 -> BeNeLux | K21: =K1 -> Brazil | L21: =L1 -> China | ... AM21: =AM1 -> WestBalkans | AN21: UC_ACT | AO21: PSET_SET | AP21: PSET_CI | AQ21: UC_RHSRT~0 | AR21: pset_co | AS21: pset_pn | AT21: t_neg_andor
A22: 0.95 | B22: ="UCE_utilization_"&C2&"_"&C22 -> UCE_utilization_bioenergy_LO | C22: LO | D22: 2023 | E22: =IF(E2="","",-MIN(E2,0.8)*$A22) -> -0.03135 | F22: =IF(F2="","",-MIN(F2,0.8)*$A22) -> -0.2527 | G22: =IF(G2="","",-MIN(G2,0.8)*$A22) -> -0.3857 | H22: =IF(H2="","",-MIN(H2,0.8)*$A22) -> -0.40755 | I22: =IF(I2="","",-MIN(I2,0.8)*$A22) -> -0.5282 | J22: =IF(J2="","",-MIN(J2,0.8)*$A22) -> -0.76 | K22: =IF(K2="","",-MIN(K2,0.8)*$A22) -> -0.34485 | L22: =IF(L2="","",-MIN(L2,0.8)*$A22) -> -0.76 | ... AM22: =IF(AM2="","",-MIN(AM2,0.8)*$A22) -> -0.60705 | AN22: =1/31.536 -> 0.031709792 | AO22: ELE,CHP | AP22: =B2 -> elcbsl,indbio | AQ22: 2 | AR22: -CO2Cap*
A23: 0.8 | B23: ="UCE_utilization_"&C3&"_"&C23 -> UCE_utilization_coal_LO | C23: LO | D23: =D22 -> 2023 | E23: =IF(E3="","",-MIN(E3,0.8)*$A23) -> -0.5864 | F23: =IF(F3="","",-MIN(F3,0.8)*$A23) -> 0 | G23: =IF(G3="","",-MIN(G3,0.8)*$A23) -> -0.5016 | H23: =IF(H3="","",-MIN(H3,0.8)*$A23) -> -0.64 | I23: =IF(I3="","",-MIN(I3,0.8)*$A23) | J23: =IF(J3="","",-MIN(J3,0.8)*$A23) -> -0.2224 | K23: =IF(K3="","",-MIN(K3,0.8)*$A23) -> -0.4072 | L23: =IF(L3="","",-MIN(L3,0.8)*$A23) -> -0.4608 | ... AM23: =IF(AM3="","",-MIN(AM3,0.8)*$A23) -> -0.472 | AN23: =1/31.536 -> 0.031709792 | AO23: ELE,CHP | AP23: =B3 -> ???coa,elccob | AQ23: 2 | AR23: -CO2Cap*
A24: 0.95 | B24: ="UCE_utilization_"&C4&"_"&C24 -> UCE_utilization_gas_LO | C24: LO | D24: =D23 -> 2023 | E24: =IF(E4="","",-MIN(E4,0.8)*$A24) -> -0.36765 | F24: =IF(F4="","",-MIN(F4,0.8)*$A24) -> -0.31065 | G24: =IF(G4="","",-MIN(G4,0.8)*$A24) -> -0.18715 | H24: =IF(H4="","",-MIN(H4,0.8)*$A24) -> -0.1501 | I24: =IF(I4="","",-MIN(I4,0.8)*$A24) -> -0.07315 | J24: =IF(J4="","",-MIN(J4,0.8)*$A24) -> -0.2964 | K24: =IF(K4="","",-MIN(K4,0.8)*$A24) -> -0.2204 | L24: =IF(L4="","",-MIN(L4,0.8)*$A24) -> -0.24605 | ... AM24: =IF(AM4="","",-MIN(AM4,0.8)*$A24) -> -0.2489 | AN24: =1/31.536 -> 0.031709792 | AO24: ELE,CHP | AP24: =B4 -> ???nga | AQ24: 2 | AR24: -CO2Cap* | AS24: -*turbine | AT24: OR
A25: 0.95 | B25: ="UCE_utilization_"&C5&"_"&C25 -> UCE_utilization_nuclear_LO | C25: LO | D25: =D24 -> 2023 | E25: =IF(E5="","",-MIN(E5,0.8)*$A25) | F25: =IF(F5="","",-MIN(F5,0.8)*$A25) | G25: =IF(G5="","",-MIN(G5,0.8)*$A25) | H25: =IF(H5="","",-MIN(H5,0.8)*$A25) | I25: =IF(I5="","",-MIN(I5,0.8)*$A25) | J25: =IF(J5="","",-MIN(J5,0.8)*$A25) -> -0.76 | K25: =IF(K5="","",-MIN(K5,0.8)*$A25) -> -0.76 | L25: =IF(L5="","",-MIN(L5,0.8)*$A25) -> -0.76 | ... AM25: =IF(AM5="","",-MIN(AM5,0.8)*$A25) | AN25: =1/31.536 -> 0.031709792 | AO25: ELE,CHP | AP25: =B5 -> ???nuc | AQ25: 2 | AR25: -CO2Cap*
A26: 0.95 | B26: ="UCE_utilization_"&C6&"_"&C26 -> UCE_utilization_oil_\I: LO | C26: \I: LO | D26: =D25 -> 2023 | E26: =IF(E6="","",-MIN(E6,0.8)*$A26) -> -0.76 | F26: =IF(F6="","",-MIN(F6,0.8)*$A26) -> -0.1387 | G26: =IF(G6="","",-MIN(G6,0.8)*$A26) -> -0.2489 | H26: =IF(H6="","",-MIN(H6,0.8)*$A26) -> -0.54435 | I26: =IF(I6="","",-MIN(I6,0.8)*$A26) -> -0.35055 | J26: =IF(J6="","",-MIN(J6,0.8)*$A26) -> -0.76 | K26: =IF(K6="","",-MIN(K6,0.8)*$A26) -> -0.1577 | L26: =IF(L6="","",-MIN(L6,0.8)*$A26) -> -0.5529 | ... AM26: =IF(AM6="","",-MIN(AM6,0.8)*$A26) -> -0.76 | AN26: =1/31.536 -> 0.031709792 | AO26: ELE,CHP | AP26: =B6 -> ???oil* | AQ26: 2 | AR26: -CO2Cap*
A27: 1.05 | B27: ="UCE_utilization_"&C2&"_"&C27 -> UCE_utilization_bioenergy_UP | C27: UP | D27: =D26 -> 2023 | E27: =IF(E2="","",-E2*$A27) -> -0.03465 | F27: =IF(F2="","",-F2*$A27) -> -0.2793 | G27: =IF(G2="","",-G2*$A27) -> -0.4263 | H27: =IF(H2="","",-H2*$A27) -> -0.45045 | I27: =IF(I2="","",-I2*$A27) -> -0.5838 | J27: =IF(J2="","",-J2*$A27) -> -0.9975 | K27: =IF(K2="","",-K2*$A27) -> -0.38115 | L27: =IF(L2="","",-L2*$A27) -> -0.9975 | ... AM27: =IF(AM2="","",-AM2*$A27) -> -0.67095 | AN27: =1/31.536 -> 0.031709792 | AO27: ELE,CHP | AP27: =AP22 -> elcbsl,indbio | AQ27: 2 | AR27: -CO2Cap*
A28: 1.05 | B28: ="UCE_utilization_"&C3&"_"&C28 -> UCE_utilization_coal_UP | C28: UP | D28: =D27 -> 2023 | E28: =IF(E3="","",-E3*$A28) -> -0.76965 | F28: =IF(F3="","",-F3*$A28) -> 0 | G28: =IF(G3="","",-G3*$A28) -> -0.65835 | H28: =IF(H3="","",-H3*$A28) -> -0.9975 | I28: =IF(I3="","",-I3*$A28) | J28: =IF(J3="","",-J3*$A28) -> -0.2919 | K28: =IF(K3="","",-K3*$A28) -> -0.53445 | L28: =IF(L3="","",-L3*$A28) -> -0.6048 | ... AM28: =IF(AM3="","",-AM3*$A28) -> -0.6195 | AN28: =1/31.536 -> 0.031709792 | AO28: ELE,CHP | AP28: =AP23 -> ???coa,elccob | AQ28: 2 | AR28: -CO2Cap*
A29: 1.05 | B29: ="UCE_utilization_"&C4&"_"&C29 -> UCE_utilization_gas_UP | C29: UP | D29: =D28 -> 2023 | E29: =IF(E4="","",-E4*$A29) -> -0.40635 | F29: =IF(F4="","",-F4*$A29) -> -0.34335 | G29: =IF(G4="","",-G4*$A29) -> -0.20685 | H29: =IF(H4="","",-H4*$A29) -> -0.1659 | I29: =IF(I4="","",-I4*$A29) -> -0.08085 | J29: =IF(J4="","",-J4*$A29) -> -0.3276 | K29: =IF(K4="","",-K4*$A29) -> -0.2436 | L29: =IF(L4="","",-L4*$A29) -> -0.27195 | ... AM29: =IF(AM4="","",-AM4*$A29) -> -0.2751 | AN29: =1/31.536 -> 0.031709792 | AO29: ELE,CHP | AP29: =AP24 -> ???nga | AQ29: 2 | AR29: -CO2Cap*
A30: 1.05 | B30: ="UCE_utilization_"&C5&"_"&C30 -> UCE_utilization_nuclear_UP | C30: UP | D30: =D29 -> 2023 | E30: =IF(E5="","",-E5*$A30) | F30: =IF(F5="","",-F5*$A30) | G30: =IF(G5="","",-G5*$A30) | H30: =IF(H5="","",-H5*$A30) | I30: =IF(I5="","",-I5*$A30) | J30: =IF(J5="","",-J5*$A30) -> -0.9975 | K30: =IF(K5="","",-K5*$A30) -> -0.8736 | L30: =IF(L5="","",-L5*$A30) -> -0.9156 | ... AM30: =IF(AM5="","",-AM5*$A30) | AN30: =1/31.536 -> 0.031709792 | AO30: ELE,CHP | AP30: =AP25 -> ???nuc | AQ30: 2 | AR30: -CO2Cap*
A31: 1.05 | B31: ="UCE_utilization_"&C6&"_"&C31 -> UCE_utilization_oil_UP | C31: UP | D31: =D30 -> 2023 | E31: =IF(E6="","",-E6*$A31) -> -0.9975 | F31: =IF(F6="","",-F6*$A31) -> -0.1533 | G31: =IF(G6="","",-G6*$A31) -> -0.2751 | H31: =IF(H6="","",-H6*$A31) -> -0.60165 | I31: =IF(I6="","",-I6*$A31) -> -0.38745 | J31: =IF(J6="","",-J6*$A31) -> -0.9975 | K31: =IF(K6="","",-K6*$A31) -> -0.1743 | L31: =IF(L6="","",-L6*$A31) -> -0.6111 | ... AM31: =IF(AM6="","",-AM6*$A31) -> -0.9975 | AN31: =1/31.536 -> 0.031709792 | AO31: ELE,CHP | AP31: =AP26 -> ???oil* | AQ31: 2 | AR31: -CO2Cap*
B32: *
A33: 0.3 | B33: =B22 -> UCE_utilization_bioenergy_LO | C33: =C22 -> LO | D33: =D22+7 -> 2030 | E33: =IF(E7="","",-MIN(E7,E2,0.8)*$A33) -> -0.0042 | F33: =IF(F7="","",-MIN(F7,F2,0.8)*$A33) -> -0.0525 | G33: =IF(G7="","",-MIN(G7,G2,0.8)*$A33) -> -0.1218 | H33: =IF(H7="","",-MIN(H7,H2,0.8)*$A33) -> -0.1287 | I33: =IF(I7="","",-MIN(I7,I2,0.8)*$A33) -> -0.1668 | J33: =IF(J7="","",-MIN(J7,J2,0.8)*$A33) -> -0.24 | K33: =IF(K7="","",-MIN(K7,K2,0.8)*$A33) -> -0.1089 | L33: =IF(L7="","",-MIN(L7,L2,0.8)*$A33) -> -0.24 | ... AM33: =IF(AM7="","",-MIN(AM7,AM2,0.8)*$A33) -> -0.0684 | AO33: =AO22 -> ELE,CHP | AP33: =AP22 -> elcbsl,indbio | AR33: -CO2Cap*
A34: 0.3 | B34: =B23 -> UCE_utilization_coal_LO | C34: =C23 -> LO | D34: =D23+7 -> 2030 | E34: =IF(E8="","",-MIN(E8,E3,0.8)*$A34) -> -0.171 | F34: =IF(F8="","",-MIN(F8,F3,0.8)*$A34) -> 0 | G34: =IF(G8="","",-MIN(G8,G3,0.8)*$A34) -> -0.1815 | H34: =IF(H8="","",-MIN(H8,H3,0.8)*$A34) -> -0.0831 | I34: =IF(I8="","",-MIN(I8,I3,0.8)*$A34) -> -0.24 | J34: =IF(J8="","",-MIN(J8,J3,0.8)*$A34) -> -0.0753 | K34: =IF(K8="","",-MIN(K8,K3,0.8)*$A34) -> -0.1527 | L34: =IF(L8="","",-MIN(L8,L3,0.8)*$A34) -> -0.1545 | ... AM34: =IF(AM8="","",-MIN(AM8,AM3,0.8)*$A34) -> -0.177 | AO34: =AO23 -> ELE,CHP | AP34: =AP23 -> ???coa,elccob | AR34: -CO2Cap*
A35: 0.3 | B35: =B24 -> UCE_utilization_gas_LO | C35: =C24 -> LO | D35: =D24+7 -> 2030 | E35: =IF(E9="","",-MIN(E9,E4,0.8)*$A35) -> -0.1119 | F35: =IF(F9="","",-MIN(F9,F4,0.8)*$A35) -> -0.0954 | G35: =IF(G9="","",-MIN(G9,G4,0.8)*$A35) -> -0.0591 | H35: =IF(H9="","",-MIN(H9,H4,0.8)*$A35) -> -0.0381 | I35: =IF(I9="","",-MIN(I9,I4,0.8)*$A35) -> -0.0189 | J35: =IF(J9="","",-MIN(J9,J4,0.8)*$A35) -> -0.0936 | K35: =IF(K9="","",-MIN(K9,K4,0.8)*$A35) -> -0.0696 | L35: =IF(L9="","",-MIN(L9,L4,0.8)*$A35) -> -0.0777 | ... AM35: =IF(AM9="","",-MIN(AM9,AM4,0.8)*$A35) -> -0.0186 | AO35: =AO24 -> ELE,CHP | AP35: =AP24 -> ???nga | AR35: -CO2Cap* | AS35: -*turbine | AT35: OR
B36: =B25 -> UCE_utilization_nuclear_LO | C36: =C25 -> LO | D36: =D25+7 -> 2030 | E36: =IF(E10="","",-MIN(E10,E5,0.8)*$A36) | F36: =IF(F10="","",-MIN(F10,F5,0.8)*$A36) | G36: =IF(G10="","",-MIN(G10,G5,0.8)*$A36) | H36: =IF(H10="","",-MIN(H10,H5,0.8)*$A36) | I36: =IF(I10="","",-MIN(I10,I5,0.8)*$A36) | J36: =IF(J10="","",-MIN(J10,J5,0.8)*$A36) -> 0 | K36: =IF(K10="","",-MIN(K10,K5,0.8)*$A36) -> 0 | L36: =IF(L10="","",-MIN(L10,L5,0.8)*$A36) -> 0 | ... AM36: =IF(AM10="","",-MIN(AM10,AM5,0.8)*$A36) | AO36: =AO25 -> ELE,CHP | AP36: =AP25 -> ???nuc | AR36: -CO2Cap*
B37: =B26 -> UCE_utilization_oil_\I: LO | C37: =C26 -> \I: LO | D37: =D26+7 -> 2030 | E37: =IF(E11="","",-MIN(E11,E6,0.8)*$A37) -> 0 | F37: =IF(F11="","",-MIN(F11,F6,0.8)*$A37) -> 0 | G37: =IF(G11="","",-MIN(G11,G6,0.8)*$A37) -> 0 | H37: =IF(H11="","",-MIN(H11,H6,0.8)*$A37) -> 0 | I37: =IF(I11="","",-MIN(I11,I6,0.8)*$A37) -> 0 | J37: =IF(J11="","",-MIN(J11,J6,0.8)*$A37) -> 0 | K37: =IF(K11="","",-MIN(K11,K6,0.8)*$A37) -> 0 | L37: =IF(L11="","",-MIN(L11,L6,0.8)*$A37) -> 0 | ... AM37: =IF(AM11="","",-MIN(AM11,AM6,0.8)*$A37) -> 0 | AO37: =AO26 -> ELE,CHP | AP37: =AP26 -> ???oil* | AR37: -CO2Cap*
B38: =B27 -> UCE_utilization_bioenergy_UP | C38: =C27 -> UP | D38: =D27+7 -> 2030 | E38: =IF(E12="","",-E12) -> -0.057 | F38: =IF(F12="","",-F12) -> -0.287 | G38: =IF(G12="","",-G12) -> -0.506 | H38: =IF(H12="","",-H12) -> -0.564 | I38: =IF(I12="","",-I12) -> -0.842 | J38: =IF(J12="","",-J12) -> -0.95 | K38: =IF(K12="","",-K12) -> -0.436 | L38: =IF(L12="","",-L12) -> -0.95 | ... AM38: =IF(AM12="","",-AM12) -> -0.95 | AO38: =AO27 -> ELE,CHP | AP38: =AP27 -> elcbsl,indbio | AR38: -CO2Cap*
B39: =B28 -> UCE_utilization_coal_UP | C39: =C28 -> UP | D39: =D28+7 -> 2030 | E39: =IF(E13="","",-E13) -> -0.777 | F39: =IF(F13="","",-F13) -> -0.47 | G39: =IF(G13="","",-G13) -> -0.724 | H39: =IF(H13="","",-H13) -> -0.95 | I39: =IF(I13="","",-I13) -> -0.95 | J39: =IF(J13="","",-J13) -> -0.95 | K39: =IF(K13="","",-K13) -> -0.922 | L39: =IF(L13="","",-L13) -> -0.587 | ... AM39: =IF(AM13="","",-AM13) -> -0.695 | AO39: =AO28 -> ELE,CHP | AP39: =AP28 -> ???coa,elccob | AR39: -CO2Cap*
A40: 0.8 | B40: =B29 -> UCE_utilization_gas_UP | C40: =C29 -> UP | D40: =D29+7 -> 2030 | E40: =-$A40 -> -0.8 | F40: =-$A40 -> -0.8 | G40: =-$A40 -> -0.8 | H40: =-$A40 -> -0.8 | I40: =-$A40 -> -0.8 | J40: =-$A40 -> -0.8 | K40: =-$A40 -> -0.8 | L40: =-$A40 -> -0.8 | ... AM40: =-$A40 -> -0.8 | AO40: =AO29 -> ELE,CHP | AP40: =AP29 -> ???nga | AR40: -CO2Cap*
A41: 0.95 | B41: =B30 -> UCE_utilization_nuclear_UP | C41: =C30 -> UP | D41: =D30+7 -> 2030 | E41: =-$A41 -> -0.95 | F41: =-$A41 -> -0.95 | G41: =-$A41 -> -0.95 | H41: =-$A41 -> -0.95 | I41: =-$A41 -> -0.95 | J41: =-$A41 -> -0.95 | K41: =-$A41 -> -0.95 | L41: =-$A41 -> -0.95 | ... AM41: =-$A41 -> -0.95 | AO41: =AO30 -> ELE,CHP | AP41: =AP30 -> ???nuc | AR41: -CO2Cap*
A42: 0.8 | B42: =B31 -> UCE_utilization_oil_UP | C42: =C31 -> UP | D42: =D31+7 -> 2030 | E42: =-$A42 -> -0.8 | F42: =-$A42 -> -0.8 | G42: =-$A42 -> -0.8 | H42: =-$A42 -> -0.8 | I42: =-$A42 -> -0.8 | J42: =-$A42 -> -0.8 | K42: =-$A42 -> -0.8 | L42: =-$A42 -> -0.8 | ... AM42: =-$A42 -> -0.8 | AO42: =AO31 -> ELE,CHP | AP42: =AP31 -> ???oil* | AR42: -CO2Cap*

Sheet Build Rates
C1: bound | D1: tech | E1: Africa_North | F1: Africa_Other | G1: Australia | H1: Austria | I1: Baltics | J1: BeNeLux | K1: Brazil | L1: China | M1: CroSloven | N1: CzechSlovak | O1: France | P1: Germany | Q1: GreeceCyp | R1: HunRomBul | S1: India | T1: Ireland | U1: ItalyMal | V1: Japan | W1: LatAm | X1: MidEast | Y1: NorthAm | Z1: Norway | AA1: Poland | AB1: ROW | AC1: Russia | AD1: SaudiArabia | AE1: SouthAfrica | AF1: SpainPor | AG1: SweFinDen | AH1: Switzerland | AI1: Turkey | AJ1: UK | AK1: WestBalkans
C2: Low | D2: Hydro | E2: 0.2 | F2: 4.2 | G2: 0.2 | H2: 0.1 | I2: 0 | J2: 0 | K2: 3 | L2: 8 | M2: 0.1 | N2: 0 | O2: 0.2 | P2: 0 | Q2: 0 | R2: 0.2 | S2: 3 | T2: 0 | U2: 0.1 | V2: 0.2 | W2: 3.2 | X2: 0.1 | Y2: 4.5 | Z2: 0.2 | AA2: 0 | AB2: 7.4 | AC2: 0.5 | AD2: 0 | AE2: 0 | AF2: 0.2 | AG2: 0.2 | AH2: 0.1 | AI2: 1.5 | AJ2: 0.1 | AK2: 0.1
C3: Low | D3: Nuclear | E3: 2 | F3: 0 | G3: 0 | H3: 0 | I3: 0 | J3: 0 | K3: 1 | L3: 10 | M3: 0 | N3: 2 | O3: 2 | P3: 0 | Q3: 0 | R3: 2 | S3: 3 | T3: 0 | U3: 0 | V3: 2 | W3: 1 | X3: 3 | Y3: 5 | Z3: 1 | AA3: 2 | AB3: 9 | AC3: 3 | AD3: 2 | AE3: 0 | AF3: 0 | AG3: 2 | AH3: 0 | AI3: 2 | AJ3: 2 | AK3: 0
C4: Low | D4: Solar | E4: 19 | F4: 27 | G4: 20 | H4: 3 | I4: 1 | J4: 7 | K4: 25 | L4: 120 | M4: 2 | N4: 5 | O4: 12 | P4: 15 | Q4: 3.6 | R4: 9 | S4: 80 | T4: 2 | U4: 10 | V4: 25 | W4: 31.8 | X4: 20.8 | Y4: 107 | Z4: 4 | AA4: 8 | AB4: 90 | AC4: 16 | AD4: 15 | AE4: 4 | AF4: 13 | AG4: 9 | AH4: 3 | AI4: 12 | AJ4: 10 | AK4: 1
C5: Low | D5: Wind | E5: 9.8 | F5: 12.1 | G5: 12 | H5: 2 | I5: 1 | J5: 6 | K5: 15 | L5: 60 | M5: 1.5 | N5: 3 | O5: 8 | P5: 8 | Q5: 2.3 | R5: 6 | S5: 30 | T5: 2 | U5: 6 | V5: 10 | W5: 17.8 | X5: 8.3 | Y5: 48 | Z5: 4 | AA5: 5 | AB5: 42.6 | AC5: 8.8 | AD5: 5 | AE5: 2 | AF5: 8 | AG5: 10 | AH5: 2 | AI5: 6 | AJ5: 8 | AK5: 0.8
C6: High | D6: Hydro | E6: 0.4 | F6: 7.3 | G6: 0.5 | H6: 0.2 | I6: 0 | J6: 0 | K6: 5 | L6: 15 | M6: 0.2 | N6: 0.1 | O6: 0.5 | P6: 0.1 | Q6: 0.1 | R6: 0.3 | S6: 6 | T6: 0 | U6: 0.3 | V6: 0.5 | W6: 6.2 | X6: 0.2 | Y6: 9 | Z6: 0.4 | AA6: 0.1 | AB6: 14.2 | AC6: 1.5 | AD6: 0 | AE6: 0.1 | AF6: 0.5 | AG6: 0.5 | AH6: 0.2 | AI6: 3 | AJ6: 0.3 | AK6: 0.2
